{
  "version": 8,
  "blockIdVersion": 11,
  "anchorX": 0,
  "anchorY": 0,
  "anchorZ": 0,
  "blocks": [
    {
      "x": -28,
      "y": 0,
      "z": 0,
      "name": "OrbisGalactic_Block_Imperial_Panel_Black_Brick_Horizontal",
      "rotation": 2
    },
    {
      "x": -27,
      "y": 0,
      "z": -1,
      "name": "OrbisGalactic_Block_Imperial_Panel_Black_Brick_Horizontal",
      "rotation": 2
    },
    {
      "x": -27,
      "y": 0,
      "z": 0,
      "name": "OrbisGalactic_Block_Imperial_Panel_Black_Brick_Vertical",
      "rotation": 3
    },
    {
      "x": -27,
      "y": 0,
      "z": 1,
      "name": "OrbisGalactic_Block_Imperial_Panel_Black_Brick_Horizontal"
    },
    {
      "x": -26,
      "y": 0,
      "z": -2,
      "name": "OrbisGalactic_Block_Imperial_Panel_Black_Brick_Horizontal",
      "rotation": 2
    },
    {
      "x": -26,
      "y": 0,
      "z": -1,
      "name": "OrbisGalactic_Block_Imperial_Panel_Black_Brick_Vertical",
      "rotation": 3
    },
    {
      "x": -26,
      "y": 0,
      "z": 0,
      "name": "OrbisGalactic_Block_Imperial_Panel_Gray_Brick_Horizontal",
      "rotation": 2
    },
    {
      "x": -26,
      "y": 0,
      "z": 1,
      "name": "OrbisGalactic_Block_Imperial_Panel_Black_Brick_Vertical",
      "rotation": 3
    },
    {
      "x": -26,
      "y": 0,
      "z": 2,
      "name": "OrbisGalactic_Block_Imperial_Panel_Black_Brick_Horizontal"
    },
    {
      "x": -25,
      "y": 0,
      "z": -2,
      "name": "OrbisGalactic_Block_Imperial_Panel_Black_Brick_Horizontal",
      "rotation": 2
    },
    {
      "x": -25,
      "y": 0,
      "z": -1,
      "name": "OrbisGalactic_Block_Imperial_Panel_Black_Brick_Vertical",
      "rotation": 3
    },
    {
      "x": -25,
      "y": 0,
      "z": 0,
      "name": "OrbisGalactic_Block_Imperial_Panel_Gray_Brick_Horizontal",
      "rotation": 2
    },
    {
      "x": -25,
      "y": 0,
      "z": 1,
      "name": "OrbisGalactic_Block_Imperial_Panel_Black_Brick_Vertical",
      "rotation": 3
    },
    {
      "x": -25,
      "y": 0,
      "z": 2,
      "name": "OrbisGalactic_Block_Imperial_Panel_Black_Brick_Horizontal"
    },
    {
      "x": -24,
      "y": 0,
      "z": -3,
      "name": "OrbisGalactic_Block_Imperial_Panel_Black_Brick_Horizontal",
      "rotation": 2
    },
    {
      "x": -24,
      "y": 0,
      "z": -2,
      "name": "OrbisGalactic_Block_Imperial_Panel_Black_Brick_Vertical",
      "rotation": 3
    },
    {
      "x": -24,
      "y": 0,
      "z": -1,
      "name": "OrbisGalactic_Block_Imperial_Panel_Gray_Brick_Horizontal",
      "rotation": 2
    },
    {
      "x": -24,
      "y": 0,
      "z": 0,
      "name": "OrbisGalactic_Block_Imperial_Panel_Gray_Brick_Horizontal",
      "rotation": 2
    },
    {
      "x": -24,
      "y": 0,
      "z": 1,
      "name": "OrbisGalactic_Block_Imperial_Panel_Gray_Brick_Horizontal",
      "rotation": 2
    },
    {
      "x": -24,
      "y": 0,
      "z": 2,
      "name": "OrbisGalactic_Block_Imperial_Panel_Black_Brick_Vertical",
      "rotation": 3
    },
    {
      "x": -24,
      "y": 0,
      "z": 3,
      "name": "OrbisGalactic_Block_Imperial_Panel_Black_Brick_Horizontal"
    },
    {
      "x": -23,
      "y": 0,
      "z": -3,
      "name": "OrbisGalactic_Block_Imperial_Panel_Black_Brick_Horizontal",
      "rotation": 2
    },
    {
      "x": -23,
      "y": 0,
      "z": -2,
      "name": "OrbisGalactic_Block_Imperial_Panel_Black_Brick_Vertical",
      "rotation": 3
    },
    {
      "x": -23,
      "y": 0,
      "z": -1,
      "name": "OrbisGalactic_Block_Imperial_Panel_Gray_Brick_Horizontal",
      "rotation": 2
    },
    {
      "x": -23,
      "y": 0,
      "z": 0,
      "name": "OrbisGalactic_Block_Imperial_Panel_Gray_Brick_Horizontal",
      "rotation": 2
    },
    {
      "x": -23,
      "y": 0,
      "z": 1,
      "name": "OrbisGalactic_Block_Imperial_Panel_Gray_Brick_Horizontal",
      "rotation": 2
    },
    {
      "x": -23,
      "y": 0,
      "z": 2,
      "name": "OrbisGalactic_Block_Imperial_Panel_Black_Brick_Vertical",
      "rotation": 3
    },
    {
      "x": -23,
      "y": 0,
      "z": 3,
      "name": "OrbisGalactic_Block_Imperial_Panel_Black_Brick_Horizontal"
    },
    {
      "x": -22,
      "y": 0,
      "z": -3,
      "name": "OrbisGalactic_Block_Imperial_Panel_Black_Brick_Horizontal",
      "rotation": 2
    },
    {
      "x": -22,
      "y": 0,
      "z": -2,
      "name": "OrbisGalactic_Block_Imperial_Panel_Black_Brick_Vertical",
      "rotation": 3
    },
    {
      "x": -22,
      "y": 0,
      "z": -1,
      "name": "OrbisGalactic_Block_Imperial_Panel_Gray_Brick_Horizontal",
      "rotation": 2
    },
    {
      "x": -22,
      "y": 0,
      "z": 0,
      "name": "OrbisGalactic_Block_Imperial_Panel_Gray_Brick_Horizontal",
      "rotation": 2
    },
    {
      "x": -22,
      "y": 0,
      "z": 1,
      "name": "OrbisGalactic_Block_Imperial_Panel_Gray_Brick_Horizontal",
      "rotation": 2
    },
    {
      "x": -22,
      "y": 0,
      "z": 2,
      "name": "OrbisGalactic_Block_Imperial_Panel_Black_Brick_Vertical",
      "rotation": 3
    },
    {
      "x": -22,
      "y": 0,
      "z": 3,
      "name": "OrbisGalactic_Block_Imperial_Panel_Black_Brick_Horizontal"
    },
    {
      "x": -21,
      "y": 1,
      "z": -4,
      "name": "OrbisGalactic_Block_Imperial_Panel_Black_Brick_Horizontal",
      "rotation": 2
    },
    {
      "x": -21,
      "y": 1,
      "z": -3,
      "name": "OrbisGalactic_Block_Imperial_Panel_Black_Brick_Vertical",
      "rotation": 3
    },
    {
      "x": -21,
      "y": 1,
      "z": -2,
      "name": "OrbisGalactic_Block_Imperial_Panel_Gray_Brick_Horizontal",
      "rotation": 2
    },
    {
      "x": -21,
      "y": 1,
      "z": -1,
      "name": "OrbisGalactic_Block_Imperial_Panel_Gray_Brick_Horizontal",
      "rotation": 2
    },
    {
      "x": -21,
      "y": 1,
      "z": 0,
      "name": "OrbisGalactic_Block_Imperial_Panel_Gray_Brick_Horizontal",
      "rotation": 2
    },
    {
      "x": -21,
      "y": 1,
      "z": 1,
      "name": "OrbisGalactic_Block_Imperial_Panel_Gray_Brick_Horizontal",
      "rotation": 2
    },
    {
      "x": -21,
      "y": 1,
      "z": 2,
      "name": "OrbisGalactic_Block_Imperial_Panel_Gray_Brick_Horizontal",
      "rotation": 2
    },
    {
      "x": -21,
      "y": 1,
      "z": 3,
      "name": "OrbisGalactic_Block_Imperial_Panel_Black_Brick_Vertical",
      "rotation": 3
    },
    {
      "x": -21,
      "y": 1,
      "z": 4,
      "name": "OrbisGalactic_Block_Imperial_Panel_Black_Brick_Horizontal"
    },
    {
      "x": -20,
      "y": 1,
      "z": -4,
      "name": "OrbisGalactic_Block_Imperial_Panel_Black_Brick_Horizontal",
      "rotation": 2
    },
    {
      "x": -20,
      "y": 1,
      "z": -3,
      "name": "OrbisGalactic_Block_Imperial_Panel_Black_Brick_Vertical",
      "rotation": 3
    },
    {
      "x": -20,
      "y": 1,
      "z": -2,
      "name": "OrbisGalactic_Block_Imperial_Panel_Gray_Brick_Horizontal",
      "rotation": 2
    },
    {
      "x": -20,
      "y": 1,
      "z": -1,
      "name": "OrbisGalactic_Block_Imperial_Panel_Gray_Brick_Horizontal",
      "rotation": 2
    },
    {
      "x": -20,
      "y": 1,
      "z": 0,
      "name": "OrbisGalactic_Block_Imperial_Panel_Gray_Brick_Horizontal",
      "rotation": 2
    },
    {
      "x": -20,
      "y": 1,
      "z": 1,
      "name": "OrbisGalactic_Block_Imperial_Panel_Gray_Brick_Horizontal",
      "rotation": 2
    },
    {
      "x": -20,
      "y": 1,
      "z": 2,
      "name": "OrbisGalactic_Block_Imperial_Panel_Gray_Brick_Horizontal",
      "rotation": 2
    },
    {
      "x": -20,
      "y": 1,
      "z": 3,
      "name": "OrbisGalactic_Block_Imperial_Panel_Black_Brick_Vertical",
      "rotation": 3
    },
    {
      "x": -20,
      "y": 1,
      "z": 4,
      "name": "OrbisGalactic_Block_Imperial_Panel_Black_Brick_Horizontal"
    },
    {
      "x": -19,
      "y": 1,
      "z": -5,
      "name": "OrbisGalactic_Block_Imperial_Panel_Black_Brick_Horizontal",
      "rotation": 2
    },
    {
      "x": -19,
      "y": 1,
      "z": -4,
      "name": "OrbisGalactic_Block_Imperial_Panel_Black_Brick_Vertical",
      "rotation": 3
    },
    {
      "x": -19,
      "y": 1,
      "z": -3,
      "name": "OrbisGalactic_Block_Imperial_Panel_Gray_Brick_Horizontal",
      "rotation": 2
    },
    {
      "x": -19,
      "y": 1,
      "z": -2,
      "name": "OrbisGalactic_Block_Imperial_Panel_Gray_Brick_Horizontal",
      "rotation": 2
    },
    {
      "x": -19,
      "y": 1,
      "z": -1,
      "name": "OrbisGalactic_Block_Imperial_Panel_Gray_Brick_Horizontal",
      "rotation": 2
    },
    {
      "x": -19,
      "y": 1,
      "z": 0,
      "name": "OrbisGalactic_Block_Imperial_Panel_Gray_Brick_Horizontal",
      "rotation": 2
    },
    {
      "x": -19,
      "y": 1,
      "z": 1,
      "name": "OrbisGalactic_Block_Imperial_Panel_Gray_Brick_Horizontal",
      "rotation": 2
    },
    {
      "x": -19,
      "y": 1,
      "z": 2,
      "name": "OrbisGalactic_Block_Imperial_Panel_Gray_Brick_Horizontal",
      "rotation": 2
    },
    {
      "x": -19,
      "y": 1,
      "z": 3,
      "name": "OrbisGalactic_Block_Imperial_Panel_Gray_Brick_Horizontal",
      "rotation": 2
    },
    {
      "x": -19,
      "y": 1,
      "z": 4,
      "name": "OrbisGalactic_Block_Imperial_Panel_Black_Brick_Vertical",
      "rotation": 3
    },
    {
      "x": -19,
      "y": 1,
      "z": 5,
      "name": "OrbisGalactic_Block_Imperial_Panel_Black_Brick_Horizontal"
    },
    {
      "x": -18,
      "y": 1,
      "z": -5,
      "name": "OrbisGalactic_Block_Imperial_Panel_Black_Brick_Horizontal",
      "rotation": 2
    },
    {
      "x": -18,
      "y": 1,
      "z": -4,
      "name": "OrbisGalactic_Block_Imperial_Panel_Black_Brick_Vertical",
      "rotation": 3
    },
    {
      "x": -18,
      "y": 1,
      "z": -3,
      "name": "OrbisGalactic_Block_Imperial_Panel_Gray_Brick_Horizontal",
      "rotation": 2
    },
    {
      "x": -18,
      "y": 1,
      "z": -2,
      "name": "OrbisGalactic_Block_Imperial_Panel_Gray_Brick_Horizontal",
      "rotation": 2
    },
    {
      "x": -18,
      "y": 1,
      "z": -1,
      "name": "OrbisGalactic_Block_Imperial_Panel_Gray_Brick_Horizontal",
      "rotation": 2
    },
    {
      "x": -18,
      "y": 1,
      "z": 0,
      "name": "OrbisGalactic_Block_Imperial_Panel_Gray_Brick_Horizontal",
      "rotation": 2
    },
    {
      "x": -18,
      "y": 1,
      "z": 1,
      "name": "OrbisGalactic_Block_Imperial_Panel_Gray_Brick_Horizontal",
      "rotation": 2
    },
    {
      "x": -18,
      "y": 1,
      "z": 2,
      "name": "OrbisGalactic_Block_Imperial_Panel_Gray_Brick_Horizontal",
      "rotation": 2
    },
    {
      "x": -18,
      "y": 1,
      "z": 3,
      "name": "OrbisGalactic_Block_Imperial_Panel_Gray_Brick_Horizontal",
      "rotation": 2
    },
    {
      "x": -18,
      "y": 1,
      "z": 4,
      "name": "OrbisGalactic_Block_Imperial_Panel_Black_Brick_Vertical",
      "rotation": 3
    },
    {
      "x": -18,
      "y": 1,
      "z": 5,
      "name": "OrbisGalactic_Block_Imperial_Panel_Black_Brick_Horizontal"
    },
    {
      "x": -17,
      "y": 1,
      "z": -5,
      "name": "OrbisGalactic_Block_Imperial_Panel_Black_Brick_Horizontal",
      "rotation": 2
    },
    {
      "x": -17,
      "y": 1,
      "z": -4,
      "name": "OrbisGalactic_Block_Imperial_Panel_Black_Brick_Vertical",
      "rotation": 3
    },
    {
      "x": -17,
      "y": 1,
      "z": -3,
      "name": "OrbisGalactic_Block_Imperial_Panel_Gray_Brick_Horizontal",
      "rotation": 2
    },
    {
      "x": -17,
      "y": 1,
      "z": -2,
      "name": "OrbisGalactic_Block_Imperial_Panel_Gray_Brick_Horizontal",
      "rotation": 2
    },
    {
      "x": -17,
      "y": 1,
      "z": -1,
      "name": "OrbisGalactic_Block_Imperial_Panel_Gray_Brick_Horizontal",
      "rotation": 2
    },
    {
      "x": -17,
      "y": 1,
      "z": 0,
      "name": "OrbisGalactic_Block_Imperial_Panel_Gray_Brick_Horizontal",
      "rotation": 2
    },
    {
      "x": -17,
      "y": 1,
      "z": 1,
      "name": "OrbisGalactic_Block_Imperial_Panel_Gray_Brick_Horizontal",
      "rotation": 2
    },
    {
      "x": -17,
      "y": 1,
      "z": 2,
      "name": "OrbisGalactic_Block_Imperial_Panel_Gray_Brick_Horizontal",
      "rotation": 2
    },
    {
      "x": -17,
      "y": 1,
      "z": 3,
      "name": "OrbisGalactic_Block_Imperial_Panel_Gray_Brick_Horizontal",
      "rotation": 2
    },
    {
      "x": -17,
      "y": 1,
      "z": 4,
      "name": "OrbisGalactic_Block_Imperial_Panel_Black_Brick_Vertical",
      "rotation": 3
    },
    {
      "x": -17,
      "y": 1,
      "z": 5,
      "name": "OrbisGalactic_Block_Imperial_Panel_Black_Brick_Horizontal"
    },
    {
      "x": -16,
      "y": 2,
      "z": -6,
      "name": "OrbisGalactic_Block_Imperial_Panel_Black_Brick_Horizontal",
      "rotation": 2
    },
    {
      "x": -16,
      "y": 2,
      "z": -5,
      "name": "OrbisGalactic_Block_Imperial_Panel_Black_Brick_Vertical",
      "rotation": 3
    },
    {
      "x": -16,
      "y": 2,
      "z": -4,
      "name": "OrbisGalactic_Block_Imperial_Panel_Gray_Brick_Horizontal",
      "rotation": 2
    },
    {
      "x": -16,
      "y": 2,
      "z": -3,
      "name": "OrbisGalactic_Block_Imperial_Panel_Gray_Brick_Horizontal",
      "rotation": 2
    },
    {
      "x": -16,
      "y": 2,
      "z": -2,
      "name": "OrbisGalactic_Block_Imperial_Panel_Gray_Brick_Horizontal",
      "rotation": 2
    },
    {
      "x": -16,
      "y": 2,
      "z": -1,
      "name": "OrbisGalactic_Block_Imperial_Panel_Gray_Brick_Horizontal",
      "rotation": 2
    },
    {
      "x": -16,
      "y": 2,
      "z": 0,
      "name": "OrbisGalactic_Block_Imperial_Panel_Gray_Brick_Horizontal",
      "rotation": 2
    },
    {
      "x": -16,
      "y": 2,
      "z": 1,
      "name": "OrbisGalactic_Block_Imperial_Panel_Gray_Brick_Horizontal",
      "rotation": 2
    },
    {
      "x": -16,
      "y": 2,
      "z": 2,
      "name": "OrbisGalactic_Block_Imperial_Panel_Gray_Brick_Horizontal",
      "rotation": 2
    },
    {
      "x": -16,
      "y": 2,
      "z": 3,
      "name": "OrbisGalactic_Block_Imperial_Panel_Gray_Brick_Horizontal",
      "rotation": 2
    },
    {
      "x": -16,
      "y": 2,
      "z": 4,
      "name": "OrbisGalactic_Block_Imperial_Panel_Gray_Brick_Horizontal",
      "rotation": 2
    },
    {
      "x": -16,
      "y": 2,
      "z": 5,
      "name": "OrbisGalactic_Block_Imperial_Panel_Black_Brick_Vertical",
      "rotation": 3
    },
    {
      "x": -16,
      "y": 2,
      "z": 6,
      "name": "OrbisGalactic_Block_Imperial_Panel_Black_Brick_Horizontal"
    },
    {
      "x": -15,
      "y": 2,
      "z": -6,
      "name": "OrbisGalactic_Block_Imperial_Panel_Black_Brick_Horizontal",
      "rotation": 2
    },
    {
      "x": -15,
      "y": 2,
      "z": -5,
      "name": "OrbisGalactic_Block_Imperial_Panel_Gray_Brick_Horizontal",
      "rotation": 2
    },
    {
      "x": -15,
      "y": 2,
      "z": -4,
      "name": "OrbisGalactic_Block_Imperial_Panel_Gray_Brick_Horizontal",
      "rotation": 2
    },
    {
      "x": -15,
      "y": 2,
      "z": -3,
      "name": "OrbisGalactic_Block_Imperial_Panel_Gray_Brick_Horizontal",
      "rotation": 2
    },
    {
      "x": -15,
      "y": 2,
      "z": -2,
      "name": "OrbisGalactic_Block_Imperial_Panel_Gray_Brick_Horizontal",
      "rotation": 2
    },
    {
      "x": -15,
      "y": 2,
      "z": -1,
      "name": "OrbisGalactic_Block_Imperial_Panel_Gray_Brick_Horizontal",
      "rotation": 2
    },
    {
      "x": -15,
      "y": 2,
      "z": 0,
      "name": "OrbisGalactic_Block_Imperial_Panel_Gray_Brick_Horizontal",
      "rotation": 2
    },
    {
      "x": -15,
      "y": 2,
      "z": 1,
      "name": "OrbisGalactic_Block_Imperial_Panel_Gray_Brick_Horizontal",
      "rotation": 2
    },
    {
      "x": -15,
      "y": 2,
      "z": 2,
      "name": "OrbisGalactic_Block_Imperial_Panel_Gray_Brick_Horizontal",
      "rotation": 2
    },
    {
      "x": -15,
      "y": 2,
      "z": 3,
      "name": "OrbisGalactic_Block_Imperial_Panel_Gray_Brick_Horizontal",
      "rotation": 2
    },
    {
      "x": -15,
      "y": 2,
      "z": 4,
      "name": "OrbisGalactic_Block_Imperial_Panel_Gray_Brick_Horizontal",
      "rotation": 2
    },
    {
      "x": -15,
      "y": 2,
      "z": 5,
      "name": "OrbisGalactic_Block_Imperial_Panel_Gray_Brick_Horizontal",
      "rotation": 2
    },
    {
      "x": -15,
      "y": 2,
      "z": 6,
      "name": "OrbisGalactic_Block_Imperial_Panel_Black_Brick_Horizontal"
    },
    {
      "x": -14,
      "y": 2,
      "z": -7,
      "name": "OrbisGalactic_Block_Imperial_Panel_Black_Brick_Horizontal",
      "rotation": 2
    },
    {
      "x": -14,
      "y": 2,
      "z": -6,
      "name": "OrbisGalactic_Block_Imperial_Panel_Black_Brick_Vertical",
      "rotation": 3
    },
    {
      "x": -14,
      "y": 2,
      "z": -5,
      "name": "OrbisGalactic_Block_Imperial_Panel_Gray_Brick_Horizontal",
      "rotation": 2
    },
    {
      "x": -14,
      "y": 2,
      "z": -4,
      "name": "OrbisGalactic_Block_Imperial_Panel_Gray_Brick_Horizontal",
      "rotation": 2
    },
    {
      "x": -14,
      "y": 2,
      "z": -3,
      "name": "OrbisGalactic_Block_Imperial_Panel_Gray_Brick_Horizontal",
      "rotation": 2
    },
    {
      "x": -14,
      "y": 2,
      "z": -2,
      "name": "OrbisGalactic_Block_Imperial_Panel_Gray_Brick_Horizontal",
      "rotation": 2
    },
    {
      "x": -14,
      "y": 2,
      "z": -1,
      "name": "OrbisGalactic_Block_Imperial_Panel_Gray_Brick_Horizontal",
      "rotation": 2
    },
    {
      "x": -14,
      "y": 2,
      "z": 0,
      "name": "OrbisGalactic_Block_Imperial_Panel_Gray_Brick_Horizontal",
      "rotation": 2
    },
    {
      "x": -14,
      "y": 2,
      "z": 1,
      "name": "OrbisGalactic_Block_Imperial_Panel_Gray_Brick_Horizontal",
      "rotation": 2
    },
    {
      "x": -14,
      "y": 2,
      "z": 2,
      "name": "OrbisGalactic_Block_Imperial_Panel_Gray_Brick_Horizontal",
      "rotation": 2
    },
    {
      "x": -14,
      "y": 2,
      "z": 3,
      "name": "OrbisGalactic_Block_Imperial_Panel_Gray_Brick_Horizontal",
      "rotation": 2
    },
    {
      "x": -14,
      "y": 2,
      "z": 4,
      "name": "OrbisGalactic_Block_Imperial_Panel_Gray_Brick_Horizontal",
      "rotation": 2
    },
    {
      "x": -14,
      "y": 2,
      "z": 5,
      "name": "OrbisGalactic_Block_Imperial_Panel_Gray_Brick_Horizontal",
      "rotation": 2
    },
    {
      "x": -14,
      "y": 2,
      "z": 6,
      "name": "OrbisGalactic_Block_Imperial_Panel_Black_Brick_Vertical",
      "rotation": 3
    },
    {
      "x": -14,
      "y": 2,
      "z": 7,
      "name": "OrbisGalactic_Block_Imperial_Panel_Black_Brick_Horizontal",
      "rotation": 2
    },
    {
      "x": -13,
      "y": 3,
      "z": -7,
      "name": "OrbisGalactic_Block_Imperial_Panel_Black_Brick_Horizontal",
      "rotation": 2
    },
    {
      "x": -13,
      "y": 3,
      "z": -6,
      "name": "OrbisGalactic_Block_Imperial_Panel_Black_Brick_Vertical",
      "rotation": 3
    },
    {
      "x": -13,
      "y": 3,
      "z": -5,
      "name": "OrbisGalactic_Block_Imperial_Panel_Black_Brick_Vertical"
    },
    {
      "x": -13,
      "y": 3,
      "z": -4,
      "name": "OrbisGalactic_Block_Imperial_Panel_Black_Brick_Vertical"
    },
    {
      "x": -13,
      "y": 4,
      "z": -4,
      "name": "OrbisGalactic_Block_Imperial_Ship_Window_Right_Center",
      "rotation": 1
    },
    {
      "x": -13,
      "y": 5,
      "z": -4,
      "name": "OrbisGalactic_Block_Imperial_Ship_Window_Top_Right",
      "rotation": 1
    },
    {
      "x": -13,
      "y": 3,
      "z": -3,
      "name": "OrbisGalactic_Block_Imperial_Panel_Black_Brick_Vertical",
      "rotation": 3
    },
    {
      "x": -13,
      "y": 4,
      "z": -3,
      "name": "OrbisGalactic_Block_Imperial_Ship_Window_Center",
      "rotation": 1
    },
    {
      "x": -13,
      "y": 5,
      "z": -3,
      "name": "OrbisGalactic_Block_Imperial_Ship_Window_Center",
      "rotation": 1
    },
    {
      "x": -13,
      "y": 6,
      "z": -3,
      "name": "OrbisGalactic_Block_Imperial_Ship_Window_Top_Right",
      "rotation": 1
    },
    {
      "x": -13,
      "y": 3,
      "z": -2,
      "name": "OrbisGalactic_Block_Imperial_Panel_Black_Brick_Vertical",
      "rotation": 3
    },
    {
      "x": -13,
      "y": 4,
      "z": -2,
      "name": "OrbisGalactic_Block_Imperial_Ship_Window_Center",
      "rotation": 2
    },
    {
      "x": -13,
      "y": 5,
      "z": -2,
      "name": "OrbisGalactic_Block_Imperial_Ship_Window_Center",
      "rotation": 2
    },
    {
      "x": -13,
      "y": 6,
      "z": -2,
      "name": "OrbisGalactic_Block_Imperial_Ship_Window_Top_Center",
      "rotation": 1
    },
    {
      "x": -13,
      "y": 7,
      "z": -2,
      "name": "OrbisGalactic_Block_Imperial_Ship_Window_Center",
      "rotation": 1
    },
    {
      "x": -13,
      "y": 3,
      "z": -1,
      "name": "OrbisGalactic_Block_Imperial_Panel_Black_Brick_Vertical",
      "rotation": 3
    },
    {
      "x": -13,
      "y": 4,
      "z": -1,
      "name": "OrbisGalactic_Block_Imperial_Ship_Window_Center",
      "rotation": 2
    },
    {
      "x": -13,
      "y": 5,
      "z": -1,
      "name": "OrbisGalactic_Block_Imperial_Ship_Window_Center",
      "rotation": 2
    },
    {
      "x": -13,
      "y": 6,
      "z": -1,
      "name": "OrbisGalactic_Block_Imperial_Ship_Window_Top_Center",
      "rotation": 1
    },
    {
      "x": -13,
      "y": 7,
      "z": -1,
      "name": "OrbisGalactic_Block_Imperial_Ship_Window_Center",
      "rotation": 1
    },
    {
      "x": -13,
      "y": 3,
      "z": 0,
      "name": "OrbisGalactic_Block_Imperial_Panel_Black_Brick_Vertical",
      "rotation": 3
    },
    {
      "x": -13,
      "y": 4,
      "z": 0,
      "name": "OrbisGalactic_Block_Imperial_Ship_Window_Center",
      "rotation": 3
    },
    {
      "x": -13,
      "y": 5,
      "z": 0,
      "name": "OrbisGalactic_Block_Imperial_Ship_Window_Center",
      "rotation": 2
    },
    {
      "x": -13,
      "y": 6,
      "z": 0,
      "name": "OrbisGalactic_Block_Imperial_Ship_Window_Top_Center",
      "rotation": 1
    },
    {
      "x": -13,
      "y": 7,
      "z": 0,
      "name": "OrbisGalactic_Block_Imperial_Ship_Window_Center",
      "rotation": 1
    },
    {
      "x": -13,
      "y": 3,
      "z": 1,
      "name": "OrbisGalactic_Block_Imperial_Panel_Black_Brick_Vertical",
      "rotation": 3
    },
    {
      "x": -13,
      "y": 4,
      "z": 1,
      "name": "OrbisGalactic_Block_Imperial_Ship_Window_Center",
      "rotation": 3
    },
    {
      "x": -13,
      "y": 5,
      "z": 1,
      "name": "OrbisGalactic_Block_Imperial_Ship_Window_Center"
    },
    {
      "x": -13,
      "y": 6,
      "z": 1,
      "name": "OrbisGalactic_Block_Imperial_Ship_Window_Top_Center",
      "rotation": 1
    },
    {
      "x": -13,
      "y": 7,
      "z": 1,
      "name": "OrbisGalactic_Block_Imperial_Ship_Window_Center",
      "rotation": 1
    },
    {
      "x": -13,
      "y": 3,
      "z": 2,
      "name": "OrbisGalactic_Block_Imperial_Panel_Black_Brick_Vertical",
      "rotation": 3
    },
    {
      "x": -13,
      "y": 4,
      "z": 2,
      "name": "OrbisGalactic_Block_Imperial_Ship_Window_Center",
      "rotation": 1
    },
    {
      "x": -13,
      "y": 5,
      "z": 2,
      "name": "OrbisGalactic_Block_Imperial_Ship_Window_Center",
      "rotation": 1
    },
    {
      "x": -13,
      "y": 6,
      "z": 2,
      "name": "OrbisGalactic_Block_Imperial_Ship_Window_Top_Center",
      "rotation": 1
    },
    {
      "x": -13,
      "y": 7,
      "z": 2,
      "name": "OrbisGalactic_Block_Imperial_Ship_Window_Center",
      "rotation": 1
    },
    {
      "x": -13,
      "y": 3,
      "z": 3,
      "name": "OrbisGalactic_Block_Imperial_Panel_Black_Brick_Vertical",
      "rotation": 3
    },
    {
      "x": -13,
      "y": 4,
      "z": 3,
      "name": "OrbisGalactic_Block_Imperial_Ship_Window_Center",
      "rotation": 1
    },
    {
      "x": -13,
      "y": 5,
      "z": 3,
      "name": "OrbisGalactic_Block_Imperial_Ship_Window_Center",
      "rotation": 1
    },
    {
      "x": -13,
      "y": 6,
      "z": 3,
      "name": "OrbisGalactic_Block_Imperial_Ship_Window_Top_Center",
      "rotation": 1
    },
    {
      "x": -13,
      "y": 3,
      "z": 4,
      "name": "OrbisGalactic_Block_Imperial_Panel_Black_Brick_Vertical",
      "rotation": 3
    },
    {
      "x": -13,
      "y": 4,
      "z": 4,
      "name": "OrbisGalactic_Block_Imperial_Ship_Window_Right_Center",
      "rotation": 3
    },
    {
      "x": -13,
      "y": 5,
      "z": 4,
      "name": "OrbisGalactic_Block_Imperial_Ship_Window_Right_Center",
      "rotation": 3
    },
    {
      "x": -13,
      "y": 6,
      "z": 4,
      "name": "OrbisGalactic_Block_Imperial_Ship_Window_Bottom_Right",
      "rotation": 1
    },
    {
      "x": -13,
      "y": 3,
      "z": 5,
      "name": "OrbisGalactic_Block_Imperial_Panel_Black_Brick_Vertical",
      "rotation": 1
    },
    {
      "x": -13,
      "y": 3,
      "z": 6,
      "name": "OrbisGalactic_Block_Imperial_Panel_Black_Brick_Vertical",
      "rotation": 3
    },
    {
      "x": -13,
      "y": 3,
      "z": 7,
      "name": "OrbisGalactic_Block_Imperial_Panel_Black_Brick_Horizontal"
    },
    {
      "x": -12,
      "y": 3,
      "z": -7,
      "name": "OrbisGalactic_Block_Imperial_Panel_Black_Brick_Horizontal",
      "rotation": 2
    },
    {
      "x": -12,
      "y": 3,
      "z": -6,
      "name": "OrbisGalactic_Block_Imperial_Panel_Black_Brick_Vertical",
      "rotation": 3
    },
    {
      "x": -12,
      "y": 3,
      "z": -5,
      "name": "OrbisGalactic_Block_Imperial_Panel_Black_Brick_Vertical",
      "rotation": 3
    },
    {
      "x": -12,
      "y": 4,
      "z": -5,
      "name": "OrbisGalactic_Block_Imperial_Ship_Window_Right_Center",
      "rotation": 1
    },
    {
      "x": -12,
      "y": 5,
      "z": -5,
      "name": "OrbisGalactic_Block_Imperial_Ship_Window_Right_Center",
      "rotation": 1
    },
    {
      "x": -12,
      "y": 6,
      "z": -5,
      "name": "OrbisGalactic_Block_Imperial_Ship_Window_Top_Right",
      "rotation": 1
    },
    {
      "x": -12,
      "y": 3,
      "z": -4,
      "name": "OrbisGalactic_Block_Imperial_Panel_Black_Brick_Vertical"
    },
    {
      "x": -12,
      "y": 7,
      "z": -4,
      "name": "OrbisGalactic_Block_Imperial_Ship_Window_Top_Right",
      "rotation": 1
    },
    {
      "x": -12,
      "y": 3,
      "z": -3,
      "name": "OrbisGalactic_Block_Imperial_Panel_Black_Brick_Vertical"
    },
    {
      "x": -12,
      "y": 7,
      "z": -3,
      "name": "OrbisGalactic_Block_Imperial_Ship_Window_Top_Center",
      "rotation": 1
    },
    {
      "x": -12,
      "y": 3,
      "z": -2,
      "name": "OrbisGalactic_Block_Imperial_Panel_Black_Brick_Vertical"
    },
    {
      "x": -12,
      "y": 8,
      "z": -2,
      "name": "OrbisGalactic_Block_Imperial_Ship_Window_Top_Right",
      "rotation": 1
    },
    {
      "x": -12,
      "y": 3,
      "z": -1,
      "name": "OrbisGalactic_Block_Imperial_Panel_Black_Brick_Vertical",
      "rotation": 3
    },
    {
      "x": -12,
      "y": 8,
      "z": -1,
      "name": "OrbisGalactic_Block_Imperial_Ship_Window_Top_Center",
      "rotation": 1
    },
    {
      "x": -12,
      "y": 9,
      "z": -1,
      "name": "OrbisGalactic_Block_Imperial_Ship_Window_Center",
      "rotation": 1
    },
    {
      "x": -12,
      "y": 10,
      "z": -1,
      "name": "OrbisGalactic_Block_Imperial_Panel_Black_Brick_Horizontal",
      "rotation": 1
    },
    {
      "x": -12,
      "y": 3,
      "z": 0,
      "name": "OrbisGalactic_Block_Imperial_Panel_Black_Brick_Vertical",
      "rotation": 3
    },
    {
      "x": -12,
      "y": 8,
      "z": 0,
      "name": "OrbisGalactic_Block_Imperial_Ship_Window_Top_Center",
      "rotation": 1
    },
    {
      "x": -12,
      "y": 9,
      "z": 0,
      "name": "OrbisGalactic_Block_Imperial_Ship_Window_Center",
      "rotation": 1
    },
    {
      "x": -12,
      "y": 10,
      "z": 0,
      "name": "OrbisGalactic_Block_Imperial_Panel_Black_Brick_Horizontal",
      "rotation": 1
    },
    {
      "x": -12,
      "y": 3,
      "z": 1,
      "name": "OrbisGalactic_Block_Imperial_Panel_Black_Brick_Vertical",
      "rotation": 3
    },
    {
      "x": -12,
      "y": 8,
      "z": 1,
      "name": "OrbisGalactic_Block_Imperial_Ship_Window_Top_Center",
      "rotation": 1
    },
    {
      "x": -12,
      "y": 9,
      "z": 1,
      "name": "OrbisGalactic_Block_Imperial_Ship_Window_Center",
      "rotation": 1
    },
    {
      "x": -12,
      "y": 10,
      "z": 1,
      "name": "OrbisGalactic_Block_Imperial_Panel_Black_Brick_Horizontal",
      "rotation": 1
    },
    {
      "x": -12,
      "y": 3,
      "z": 2,
      "name": "OrbisGalactic_Block_Imperial_Panel_Black_Brick_Vertical",
      "rotation": 2
    },
    {
      "x": -12,
      "y": 8,
      "z": 2,
      "name": "OrbisGalactic_Block_Imperial_Ship_Window_Top_Right",
      "rotation": 3
    },
    {
      "x": -12,
      "y": 3,
      "z": 3,
      "name": "OrbisGalactic_Block_Imperial_Panel_Black_Brick_Vertical",
      "rotation": 2
    },
    {
      "x": -12,
      "y": 7,
      "z": 3,
      "name": "OrbisGalactic_Block_Imperial_Ship_Window_Top_Center",
      "rotation": 1
    },
    {
      "x": -12,
      "y": 8,
      "z": 3,
      "name": "OrbisGalactic_Block_Imperial_Ship_Window_Center",
      "rotation": 1
    },
    {
      "x": -12,
      "y": 9,
      "z": 3,
      "name": "OrbisGalactic_Block_Imperial_Ship_Window_Center",
      "rotation": 1
    },
    {
      "x": -12,
      "y": 3,
      "z": 4,
      "name": "OrbisGalactic_Block_Imperial_Panel_Black_Brick_Vertical",
      "rotation": 2
    },
    {
      "x": -12,
      "y": 7,
      "z": 4,
      "name": "OrbisGalactic_Block_Imperial_Ship_Window_Top_Right",
      "rotation": 3
    },
    {
      "x": -12,
      "y": 3,
      "z": 5,
      "name": "OrbisGalactic_Block_Imperial_Panel_Black_Brick_Vertical",
      "rotation": 3
    },
    {
      "x": -12,
      "y": 4,
      "z": 5,
      "name": "OrbisGalactic_Block_Imperial_Ship_Window_Left_Center",
      "rotation": 1
    },
    {
      "x": -12,
      "y": 5,
      "z": 5,
      "name": "OrbisGalactic_Block_Imperial_Ship_Window_Left_Center",
      "rotation": 1
    },
    {
      "x": -12,
      "y": 6,
      "z": 5,
      "name": "OrbisGalactic_Block_Imperial_Ship_Window_Top_Right",
      "rotation": 3
    },
    {
      "x": -12,
      "y": 3,
      "z": 6,
      "name": "OrbisGalactic_Block_Imperial_Panel_Black_Brick_Vertical",
      "rotation": 3
    },
    {
      "x": -12,
      "y": 3,
      "z": 7,
      "name": "OrbisGalactic_Block_Imperial_Panel_Black_Brick_Horizontal"
    },
    {
      "x": -11,
      "y": 3,
      "z": -8,
      "name": "OrbisGalactic_Block_Imperial_Panel_Black_Brick_Horizontal",
      "rotation": 2
    },
    {
      "x": -11,
      "y": 3,
      "z": -7,
      "name": "OrbisGalactic_Block_Imperial_Panel_Black_Brick_Vertical",
      "rotation": 3
    },
    {
      "x": -11,
      "y": 3,
      "z": -6,
      "name": "OrbisGalactic_Block_Imperial_Panel_Black_Brick_Vertical"
    },
    {
      "x": -11,
      "y": 4,
      "z": -6,
      "name": "OrbisGalactic_Block_Imperial_Ship_Window_Right_Center",
      "rotation": 1
    },
    {
      "x": -11,
      "y": 5,
      "z": -6,
      "name": "OrbisGalactic_Block_Imperial_Ship_Window_Right_Center",
      "rotation": 1
    },
    {
      "x": -11,
      "y": 6,
      "z": -6,
      "name": "OrbisGalactic_Block_Imperial_Ship_Window_Right_Center",
      "rotation": 1
    },
    {
      "x": -11,
      "y": 7,
      "z": -6,
      "name": "OrbisGalactic_Block_Imperial_Ship_Window_Top_Right",
      "rotation": 1
    },
    {
      "x": -11,
      "y": 8,
      "z": -6,
      "name": "OrbisGalactic_Block_Imperial_Panel_Black_Brick_Horizontal",
      "rotation": 1
    },
    {
      "x": -11,
      "y": 3,
      "z": -5,
      "name": "OrbisGalactic_Block_Imperial_Panel_Black_Brick_Vertical"
    },
    {
      "x": -11,
      "y": 7,
      "z": -5,
      "name": "OrbisGalactic_Block_Imperial_Ship_Window_Center",
      "rotation": 1
    },
    {
      "x": -11,
      "y": 8,
      "z": -5,
      "name": "OrbisGalactic_Block_Imperial_Ship_Window_Top_Right",
      "rotation": 1
    },
    {
      "x": -11,
      "y": 9,
      "z": -5,
      "name": "OrbisGalactic_Block_Imperial_Panel_Black_Brick_Horizontal",
      "rotation": 1
    },
    {
      "x": -11,
      "y": 3,
      "z": -4,
      "name": "OrbisGalactic_Block_Imperial_Panel_Black_Brick_Vertical"
    },
    {
      "x": -11,
      "y": 8,
      "z": -4,
      "name": "OrbisGalactic_Block_Imperial_Ship_Window_Top_Center",
      "rotation": 1
    },
    {
      "x": -11,
      "y": 9,
      "z": -4,
      "name": "OrbisGalactic_Block_Imperial_Panel_Black_Brick_Horizontal",
      "rotation": 1
    },
    {
      "x": -11,
      "y": 3,
      "z": -3,
      "name": "OrbisGalactic_Block_Imperial_Panel_Black_Brick_Vertical"
    },
    {
      "x": -11,
      "y": 9,
      "z": -3,
      "name": "OrbisGalactic_Block_Imperial_Ship_Window_Top_Right",
      "rotation": 1
    },
    {
      "x": -11,
      "y": 10,
      "z": -3,
      "name": "OrbisGalactic_Block_Imperial_Panel_Black_Brick_Horizontal",
      "rotation": 1
    },
    {
      "x": -11,
      "y": 3,
      "z": -2,
      "name": "OrbisGalactic_Block_Imperial_Panel_Black_Brick_Vertical"
    },
    {
      "x": -11,
      "y": 9,
      "z": -2,
      "name": "OrbisGalactic_Block_Imperial_Ship_Window_Top_Center",
      "rotation": 1
    },
    {
      "x": -11,
      "y": 10,
      "z": -2,
      "name": "OrbisGalactic_Block_Imperial_Panel_Black_Brick_Horizontal",
      "rotation": 1
    },
    {
      "x": -11,
      "y": 3,
      "z": -1,
      "name": "OrbisGalactic_Block_Imperial_Panel_Black_Brick_Horizontal",
      "rotation": 1
    },
    {
      "x": -11,
      "y": 4,
      "z": -1,
      "name": "OrbisGalactic_Block_Imperial_Panel_Black_Brick_Horizontal",
      "rotation": 1
    },
    {
      "x": -11,
      "y": 10,
      "z": -1,
      "name": "OrbisGalactic_Block_Imperial_Panel_Black_Brick_Horizontal",
      "rotation": 1
    },
    {
      "x": -11,
      "y": 11,
      "z": -1,
      "name": "OrbisGalactic_Block_Imperial_Panel_Black_Smooth",
      "rotation": 2
    },
    {
      "x": -11,
      "y": 3,
      "z": 0,
      "name": "OrbisGalactic_Block_Imperial_Panel_Black_Brick_Horizontal",
      "rotation": 1
    },
    {
      "x": -11,
      "y": 4,
      "z": 0,
      "name": "OrbisGalactic_Block_Imperial_Panel_Black_Brick_Horizontal",
      "rotation": 1
    },
    {
      "x": -11,
      "y": 10,
      "z": 0,
      "name": "OrbisGalactic_Block_Imperial_Panel_Black_Brick_Horizontal",
      "rotation": 1
    },
    {
      "x": -11,
      "y": 11,
      "z": 0,
      "name": "OrbisGalactic_Block_Imperial_Panel_Black_Brick_Vertical",
      "rotation": 2
    },
    {
      "x": -11,
      "y": 3,
      "z": 1,
      "name": "OrbisGalactic_Block_Imperial_Panel_Black_Brick_Horizontal",
      "rotation": 1
    },
    {
      "x": -11,
      "y": 4,
      "z": 1,
      "name": "OrbisGalactic_Block_Imperial_Panel_Black_Brick_Horizontal",
      "rotation": 1
    },
    {
      "x": -11,
      "y": 10,
      "z": 1,
      "name": "OrbisGalactic_Block_Imperial_Panel_Black_Brick_Horizontal",
      "rotation": 1
    },
    {
      "x": -11,
      "y": 11,
      "z": 1,
      "name": "OrbisGalactic_Block_Imperial_Panel_Black_Smooth",
      "rotation": 3
    },
    {
      "x": -11,
      "y": 3,
      "z": 2,
      "name": "OrbisGalactic_Block_Imperial_Panel_Black_Brick_Vertical"
    },
    {
      "x": -11,
      "y": 10,
      "z": 2,
      "name": "OrbisGalactic_Block_Imperial_Panel_Black_Brick_Horizontal",
      "rotation": 1
    },
    {
      "x": -11,
      "y": 3,
      "z": 3,
      "name": "OrbisGalactic_Block_Imperial_Panel_Black_Brick_Vertical",
      "rotation": 2
    },
    {
      "x": -11,
      "y": 10,
      "z": 3,
      "name": "OrbisGalactic_Block_Imperial_Panel_Black_Brick_Horizontal",
      "rotation": 1
    },
    {
      "x": -11,
      "y": 3,
      "z": 4,
      "name": "OrbisGalactic_Block_Imperial_Panel_Black_Brick_Vertical",
      "rotation": 2
    },
    {
      "x": -11,
      "y": 8,
      "z": 4,
      "name": "OrbisGalactic_Block_Imperial_Ship_Window_Top_Center",
      "rotation": 1
    },
    {
      "x": -11,
      "y": 9,
      "z": 4,
      "name": "OrbisGalactic_Block_Imperial_Panel_Black_Brick_Horizontal"
    },
    {
      "x": -11,
      "y": 3,
      "z": 5,
      "name": "OrbisGalactic_Block_Imperial_Panel_Black_Brick_Vertical",
      "rotation": 2
    },
    {
      "x": -11,
      "y": 7,
      "z": 5,
      "name": "OrbisGalactic_Block_Imperial_Ship_Window_Center",
      "rotation": 1
    },
    {
      "x": -11,
      "y": 8,
      "z": 5,
      "name": "OrbisGalactic_Block_Imperial_Ship_Window_Top_Left",
      "rotation": 1
    },
    {
      "x": -11,
      "y": 9,
      "z": 5,
      "name": "OrbisGalactic_Block_Imperial_Panel_Black_Brick_Horizontal"
    },
    {
      "x": -11,
      "y": 3,
      "z": 6,
      "name": "OrbisGalactic_Block_Imperial_Panel_Black_Brick_Vertical",
      "rotation": 2
    },
    {
      "x": -11,
      "y": 4,
      "z": 6,
      "name": "OrbisGalactic_Block_Imperial_Ship_Window_Left_Center",
      "rotation": 1
    },
    {
      "x": -11,
      "y": 5,
      "z": 6,
      "name": "OrbisGalactic_Block_Imperial_Ship_Window_Left_Center",
      "rotation": 1
    },
    {
      "x": -11,
      "y": 6,
      "z": 6,
      "name": "OrbisGalactic_Block_Imperial_Ship_Window_Left_Center",
      "rotation": 1
    },
    {
      "x": -11,
      "y": 7,
      "z": 6,
      "name": "OrbisGalactic_Block_Imperial_Ship_Window_Top_Left",
      "rotation": 1
    },
    {
      "x": -11,
      "y": 8,
      "z": 6,
      "name": "OrbisGalactic_Block_Imperial_Panel_Black_Brick_Horizontal",
      "rotation": 1
    },
    {
      "x": -11,
      "y": 3,
      "z": 7,
      "name": "OrbisGalactic_Block_Imperial_Panel_Black_Brick_Vertical",
      "rotation": 3
    },
    {
      "x": -11,
      "y": 3,
      "z": 8,
      "name": "OrbisGalactic_Block_Imperial_Panel_Black_Brick_Horizontal"
    },
    {
      "x": -10,
      "y": 3,
      "z": -8,
      "name": "OrbisGalactic_Block_Imperial_Panel_Black_Brick_Vertical",
      "rotation": 1
    },
    {
      "x": -10,
      "y": 4,
      "z": -8,
      "name": "OrbisGalactic_Block_Imperial_Panel_Black_Brick_Vertical",
      "rotation": 1
    },
    {
      "x": -10,
      "y": 5,
      "z": -8,
      "name": "OrbisGalactic_Block_Imperial_Panel_Black_Brick_Vertical",
      "rotation": 1
    },
    {
      "x": -10,
      "y": 6,
      "z": -8,
      "name": "OrbisGalactic_Block_Imperial_Panel_Black_Brick_Vertical",
      "rotation": 1
    },
    {
      "x": -10,
      "y": 7,
      "z": -8,
      "name": "OrbisGalactic_Block_Imperial_Panel_Black_Brick_Vertical",
      "rotation": 1
    },
    {
      "x": -10,
      "y": 8,
      "z": -8,
      "name": "OrbisGalactic_Block_Imperial_Panel_Black_Brick_Horizontal",
      "rotation": 1
    },
    {
      "x": -10,
      "y": 3,
      "z": -7,
      "name": "OrbisGalactic_Block_Imperial_Panel_Black_Brick_Vertical",
      "rotation": 1
    },
    {
      "x": -10,
      "y": 4,
      "z": -7,
      "name": "OrbisGalactic_Block_Imperial_Panel_Black_Brick_Vertical"
    },
    {
      "x": -10,
      "y": 5,
      "z": -7,
      "name": "OrbisGalactic_Block_Imperial_Panel_Black_Brick_Vertical"
    },
    {
      "x": -10,
      "y": 6,
      "z": -7,
      "name": "OrbisGalactic_Block_Imperial_Panel_Black_Brick_Vertical"
    },
    {
      "x": -10,
      "y": 7,
      "z": -7,
      "name": "OrbisGalactic_Block_Imperial_Panel_Black_Brick_Vertical"
    },
    {
      "x": -10,
      "y": 8,
      "z": -7,
      "name": "OrbisGalactic_Block_Imperial_Panel_Black_Brick_Horizontal",
      "rotation": 1
    },
    {
      "x": -10,
      "y": 3,
      "z": -6,
      "name": "*OrbisGalactic_Block_Imperial_Lamp3_Connected_State_Definitions_On",
      "rotation": 2
    },
    {
      "x": -10,
      "y": 9,
      "z": -6,
      "name": "OrbisGalactic_Block_Imperial_Panel_Black_Smooth",
      "rotation": 3
    },
    {
      "x": -10,
      "y": 3,
      "z": -5,
      "name": "*OrbisGalactic_Block_Imperial_Lamp3_Connected_State_Definitions_On",
      "rotation": 2
    },
    {
      "x": -10,
      "y": 10,
      "z": -5,
      "name": "OrbisGalactic_Block_Imperial_Panel_Black_Smooth",
      "rotation": 2
    },
    {
      "x": -10,
      "y": 3,
      "z": -4,
      "name": "*OrbisGalactic_Block_Imperial_Lamp3_Connected_State_Definitions_On",
      "rotation": 2
    },
    {
      "x": -10,
      "y": 10,
      "z": -4,
      "name": "OrbisGalactic_Block_Imperial_Panel_Black_Smooth",
      "rotation": 1
    },
    {
      "x": -10,
      "y": 3,
      "z": -3,
      "name": "*OrbisGalactic_Block_Imperial_Lamp3_Connected_State_Definitions_On",
      "rotation": 2
    },
    {
      "x": -10,
      "y": 11,
      "z": -3,
      "name": "OrbisGalactic_Block_Imperial_Panel_Black_Smooth",
      "rotation": 2
    },
    {
      "x": -10,
      "y": 3,
      "z": -2,
      "name": "*OrbisGalactic_Block_Imperial_Lamp3_Connected_State_Definitions_On",
      "rotation": 2
    },
    {
      "x": -10,
      "y": 9,
      "z": -2,
      "name": "OrbisGalactic_Block_Imperial_Ship_Window_Top_Center",
      "rotation": 1
    },
    {
      "x": -10,
      "y": 11,
      "z": -2,
      "name": "OrbisGalactic_Block_Imperial_Panel_Black_Smooth",
      "rotation": 2
    },
    {
      "x": -10,
      "y": 3,
      "z": -1,
      "name": "OrbisGalactic_Block_Imperial_Panel_Black_Brick_Vertical",
      "rotation": 3
    },
    {
      "x": -10,
      "y": 4,
      "z": -1,
      "name": "*OrbisGalactic_Block_Imperial_Lamp3_Connected_State_Definitions_On",
      "rotation": 2
    },
    {
      "x": -10,
      "y": 11,
      "z": -1,
      "name": "OrbisGalactic_Block_Imperial_Panel_Black_Brick_Vertical",
      "rotation": 1
    },
    {
      "x": -10,
      "y": 3,
      "z": 0,
      "name": "OrbisGalactic_Block_Imperial_Panel_Black_Brick_Vertical",
      "rotation": 3
    },
    {
      "x": -10,
      "y": 4,
      "z": 0,
      "name": "*OrbisGalactic_Block_Imperial_Lamp3_Connected_State_Definitions_On",
      "rotation": 2
    },
    {
      "x": -10,
      "y": 11,
      "z": 0,
      "name": "OrbisGalactic_Block_Imperial_Panel_Black_Brick_Vertical",
      "rotation": 1
    },
    {
      "x": -10,
      "y": 3,
      "z": 1,
      "name": "OrbisGalactic_Block_Imperial_Panel_Black_Brick_Vertical",
      "rotation": 3
    },
    {
      "x": -10,
      "y": 4,
      "z": 1,
      "name": "*OrbisGalactic_Block_Imperial_Lamp3_Connected_State_Definitions_On",
      "rotation": 2
    },
    {
      "x": -10,
      "y": 11,
      "z": 1,
      "name": "OrbisGalactic_Block_Imperial_Panel_Black_Brick_Vertical",
      "rotation": 1
    },
    {
      "x": -10,
      "y": 3,
      "z": 2,
      "name": "*OrbisGalactic_Block_Imperial_Lamp3_Connected_State_Definitions_On",
      "rotation": 2
    },
    {
      "x": -10,
      "y": 11,
      "z": 2,
      "name": "OrbisGalactic_Block_Imperial_Panel_Black_Smooth",
      "rotation": 2
    },
    {
      "x": -10,
      "y": 3,
      "z": 3,
      "name": "*OrbisGalactic_Block_Imperial_Lamp3_Connected_State_Definitions_On",
      "rotation": 2
    },
    {
      "x": -10,
      "y": 11,
      "z": 3,
      "name": "OrbisGalactic_Block_Imperial_Panel_Black_Smooth",
      "rotation": 3
    },
    {
      "x": -10,
      "y": 3,
      "z": 4,
      "name": "*OrbisGalactic_Block_Imperial_Lamp3_Connected_State_Definitions_On",
      "rotation": 2
    },
    {
      "x": -10,
      "y": 10,
      "z": 4,
      "name": "OrbisGalactic_Block_Imperial_Panel_Black_Smooth",
      "rotation": 2
    },
    {
      "x": -10,
      "y": 3,
      "z": 5,
      "name": "*OrbisGalactic_Block_Imperial_Lamp3_Connected_State_Definitions_On",
      "rotation": 2
    },
    {
      "x": -10,
      "y": 10,
      "z": 5,
      "name": "OrbisGalactic_Block_Imperial_Panel_Black_Smooth",
      "rotation": 3
    },
    {
      "x": -10,
      "y": 3,
      "z": 6,
      "name": "*OrbisGalactic_Block_Imperial_Lamp3_Connected_State_Definitions_On",
      "rotation": 2
    },
    {
      "x": -10,
      "y": 9,
      "z": 6,
      "name": "OrbisGalactic_Block_Imperial_Panel_Black_Smooth",
      "rotation": 2
    },
    {
      "x": -10,
      "y": 3,
      "z": 7,
      "name": "OrbisGalactic_Block_Imperial_Panel_Black_Brick_Vertical",
      "rotation": 3
    },
    {
      "x": -10,
      "y": 4,
      "z": 7,
      "name": "OrbisGalactic_Block_Imperial_Panel_Black_Brick_Vertical",
      "rotation": 3
    },
    {
      "x": -10,
      "y": 5,
      "z": 7,
      "name": "OrbisGalactic_Block_Imperial_Panel_Black_Brick_Vertical",
      "rotation": 3
    },
    {
      "x": -10,
      "y": 6,
      "z": 7,
      "name": "OrbisGalactic_Block_Imperial_Panel_Black_Brick_Vertical",
      "rotation": 2
    },
    {
      "x": -10,
      "y": 7,
      "z": 7,
      "name": "OrbisGalactic_Block_Imperial_Panel_Black_Brick_Vertical",
      "rotation": 2
    },
    {
      "x": -10,
      "y": 8,
      "z": 7,
      "name": "OrbisGalactic_Block_Imperial_Panel_Black_Brick_Horizontal",
      "rotation": 1
    },
    {
      "x": -10,
      "y": 3,
      "z": 8,
      "name": "OrbisGalactic_Block_Imperial_Panel_Black_Brick_Vertical"
    },
    {
      "x": -10,
      "y": 4,
      "z": 8,
      "name": "OrbisGalactic_Block_Imperial_Panel_Black_Brick_Vertical"
    },
    {
      "x": -10,
      "y": 5,
      "z": 8,
      "name": "OrbisGalactic_Block_Imperial_Panel_Black_Brick_Vertical"
    },
    {
      "x": -10,
      "y": 6,
      "z": 8,
      "name": "OrbisGalactic_Block_Imperial_Panel_Black_Brick_Vertical"
    },
    {
      "x": -10,
      "y": 7,
      "z": 8,
      "name": "OrbisGalactic_Block_Imperial_Panel_Black_Brick_Vertical"
    },
    {
      "x": -10,
      "y": 8,
      "z": 8,
      "name": "OrbisGalactic_Block_Imperial_Panel_Black_Brick_Vertical"
    },
    {
      "x": -9,
      "y": 3,
      "z": -8,
      "name": "OrbisGalactic_Block_Imperial_Panel_Black_Brick_Vertical",
      "rotation": 3
    },
    {
      "x": -9,
      "y": 4,
      "z": -8,
      "name": "OrbisGalactic_Block_Imperial_Ship_Window_Bottom_Left"
    },
    {
      "x": -9,
      "y": 5,
      "z": -8,
      "name": "OrbisGalactic_Block_Imperial_Ship_Window_Left_Center"
    },
    {
      "x": -9,
      "y": 6,
      "z": -8,
      "name": "OrbisGalactic_Block_Imperial_Ship_Window_Left_Center"
    },
    {
      "x": -9,
      "y": 7,
      "z": -8,
      "name": "OrbisGalactic_Block_Imperial_Ship_Window_Top_Left"
    },
    {
      "x": -9,
      "y": 8,
      "z": -8,
      "name": "OrbisGalactic_Block_Imperial_Panel_Black_Brick_Horizontal",
      "rotation": 3
    },
    {
      "x": -9,
      "y": 3,
      "z": -7,
      "name": "OrbisGalactic_Block_Imperial_Panel_Gray_Brick_Vertical",
      "rotation": 1
    },
    {
      "x": -9,
      "y": 9,
      "z": -7,
      "name": "OrbisGalactic_Block_Imperial_Panel_Black_Smooth",
      "rotation": 3
    },
    {
      "x": -9,
      "y": 2,
      "z": -6,
      "name": "OrbisGalactic_Block_Imperial_Panel_Gray_Brick_Vertical",
      "rotation": 2
    },
    {
      "x": -9,
      "y": 3,
      "z": -6,
      "name": "OrbisGalactic_Block_Imperial_Panel_Gray_Brick_Vertical"
    },
    {
      "x": -9,
      "y": 4,
      "z": -6,
      "name": "OrbisGalactic_Imperial_Railing_Gray",
      "support": 15,
      "rotation": 3
    },
    {
      "x": -9,
      "y": 10,
      "z": -6,
      "name": "OrbisGalactic_Block_Imperial_Panel_Black_Smooth",
      "rotation": 2
    },
    {
      "x": -9,
      "y": 2,
      "z": -5,
      "name": "OrbisGalactic_Block_Imperial_Panel_Gray_Brick_Vertical",
      "rotation": 2
    },
    {
      "x": -9,
      "y": 3,
      "z": -5,
      "name": "OrbisGalactic_Block_Imperial_Panel_Gray_Brick_Vertical",
      "rotation": 2
    },
    {
      "x": -9,
      "y": 4,
      "z": -5,
      "name": "OrbisGalactic_Imperial_Railing_Gray",
      "support": 15,
      "rotation": 3
    },
    {
      "x": -9,
      "y": 11,
      "z": -5,
      "name": "OrbisGalactic_Block_Imperial_Panel_Black_Smooth",
      "rotation": 2
    },
    {
      "x": -9,
      "y": 2,
      "z": -4,
      "name": "OrbisGalactic_Block_Imperial_Panel_Gray_Brick_Vertical",
      "rotation": 2
    },
    {
      "x": -9,
      "y": 3,
      "z": -4,
      "name": "OrbisGalactic_Block_Imperial_Panel_Gray_Brick_Vertical",
      "rotation": 2
    },
    {
      "x": -9,
      "y": 4,
      "z": -4,
      "name": "OrbisGalactic_Imperial_Railing_Gray",
      "support": 15,
      "rotation": 3
    },
    {
      "x": -9,
      "y": 11,
      "z": -4,
      "name": "OrbisGalactic_Block_Imperial_Panel_Black_Smooth",
      "rotation": 2
    },
    {
      "x": -9,
      "y": 2,
      "z": -3,
      "name": "OrbisGalactic_Block_Imperial_Panel_Gray_Brick_Vertical",
      "rotation": 2
    },
    {
      "x": -9,
      "y": 3,
      "z": -3,
      "name": "OrbisGalactic_Block_Imperial_Panel_Gray_Brick_Vertical",
      "rotation": 2
    },
    {
      "x": -9,
      "y": 4,
      "z": -3,
      "name": "OrbisGalactic_Imperial_Railing_Gray",
      "support": 15,
      "rotation": 3
    },
    {
      "x": -9,
      "y": 11,
      "z": -3,
      "name": "OrbisGalactic_Block_Imperial_Panel_Black_Brick_Vertical",
      "rotation": 1
    },
    {
      "x": -9,
      "y": 2,
      "z": -2,
      "name": "OrbisGalactic_Block_Imperial_Panel_Gray_Brick_Vertical",
      "rotation": 2
    },
    {
      "x": -9,
      "y": 3,
      "z": -2,
      "name": "OrbisGalactic_Block_Imperial_Panel_Gray_Brick_Vertical",
      "rotation": 2
    },
    {
      "x": -9,
      "y": 4,
      "z": -2,
      "name": "OrbisGalactic_Imperial_Railing_Gray",
      "support": 15,
      "rotation": 3
    },
    {
      "x": -9,
      "y": 11,
      "z": -2,
      "name": "OrbisGalactic_Block_Imperial_Panel_Black_Brick_Vertical",
      "rotation": 1
    },
    {
      "x": -9,
      "y": 3,
      "z": -1,
      "name": "OrbisGalactic_Block_Imperial_Panel_Gray_Brick_Vertical",
      "rotation": 3
    },
    {
      "x": -9,
      "y": 4,
      "z": -1,
      "name": "OrbisGalactic_Block_Imperial_Panel_Gray_Brick_Vertical",
      "rotation": 3
    },
    {
      "x": -9,
      "y": 5,
      "z": -1,
      "name": "OrbisGalactic_Imperial_Railing_Gray",
      "support": 15,
      "rotation": 3
    },
    {
      "x": -9,
      "y": 11,
      "z": -1,
      "name": "OrbisGalactic_Block_Imperial_Panel_Black_Brick_Vertical",
      "rotation": 1
    },
    {
      "x": -9,
      "y": 2,
      "z": 0,
      "name": "OrbisGalactic_Block_Imperial_Panel_Gray",
      "rotation": 1
    },
    {
      "x": -9,
      "y": 3,
      "z": 0,
      "name": "OrbisGalactic_Block_Imperial_Panel_Gray",
      "rotation": 1
    },
    {
      "x": -9,
      "y": 4,
      "z": 0,
      "name": "OrbisGalactic_Block_Imperial_Panel_Gray_Brick_Horizontal",
      "rotation": 3
    },
    {
      "x": -9,
      "y": 5,
      "z": 0,
      "name": "OrbisGalactic_Imperial_Railing_Gray",
      "support": 15,
      "rotation": 3
    },
    {
      "x": -9,
      "y": 11,
      "z": 0,
      "name": "OrbisGalactic_Block_Imperial_Panel_Black_Brick_Vertical",
      "rotation": 1
    },
    {
      "x": -9,
      "y": 3,
      "z": 1,
      "name": "OrbisGalactic_Block_Imperial_Panel_Gray_Brick_Vertical"
    },
    {
      "x": -9,
      "y": 4,
      "z": 1,
      "name": "OrbisGalactic_Block_Imperial_Panel_Gray_Brick_Vertical"
    },
    {
      "x": -9,
      "y": 5,
      "z": 1,
      "name": "OrbisGalactic_Imperial_Railing_Gray",
      "support": 15,
      "rotation": 3
    },
    {
      "x": -9,
      "y": 11,
      "z": 1,
      "name": "OrbisGalactic_Block_Imperial_Panel_Black_Brick_Vertical",
      "rotation": 1
    },
    {
      "x": -9,
      "y": 3,
      "z": 2,
      "name": "OrbisGalactic_Block_Imperial_Panel_Gray_Brick_Vertical",
      "rotation": 2
    },
    {
      "x": -9,
      "y": 4,
      "z": 2,
      "name": "OrbisGalactic_Imperial_Railing_Gray",
      "support": 15,
      "rotation": 3
    },
    {
      "x": -9,
      "y": 11,
      "z": 2,
      "name": "OrbisGalactic_Block_Imperial_Panel_Black_Brick_Vertical",
      "rotation": 1
    },
    {
      "x": -9,
      "y": 3,
      "z": 3,
      "name": "OrbisGalactic_Block_Imperial_Panel_Gray_Brick_Vertical",
      "rotation": 2
    },
    {
      "x": -9,
      "y": 4,
      "z": 3,
      "name": "OrbisGalactic_Imperial_Railing_Gray",
      "support": 15,
      "rotation": 3
    },
    {
      "x": -9,
      "y": 11,
      "z": 3,
      "name": "OrbisGalactic_Block_Imperial_Panel_Black_Brick_Vertical",
      "rotation": 1
    },
    {
      "x": -9,
      "y": 3,
      "z": 4,
      "name": "OrbisGalactic_Block_Imperial_Panel_Gray_Brick_Vertical",
      "rotation": 2
    },
    {
      "x": -9,
      "y": 4,
      "z": 4,
      "name": "OrbisGalactic_Imperial_Railing_Gray",
      "support": 15,
      "rotation": 3
    },
    {
      "x": -9,
      "y": 11,
      "z": 4,
      "name": "OrbisGalactic_Block_Imperial_Panel_Black_Smooth",
      "rotation": 2
    },
    {
      "x": -9,
      "y": 3,
      "z": 5,
      "name": "OrbisGalactic_Block_Imperial_Panel_Gray_Brick_Vertical",
      "rotation": 2
    },
    {
      "x": -9,
      "y": 4,
      "z": 5,
      "name": "OrbisGalactic_Imperial_Railing_Gray",
      "support": 15,
      "rotation": 3
    },
    {
      "x": -9,
      "y": 11,
      "z": 5,
      "name": "OrbisGalactic_Block_Imperial_Panel_Black_Smooth",
      "rotation": 3
    },
    {
      "x": -9,
      "y": 3,
      "z": 6,
      "name": "OrbisGalactic_Block_Imperial_Panel_Gray_Brick_Vertical",
      "rotation": 2
    },
    {
      "x": -9,
      "y": 4,
      "z": 6,
      "name": "OrbisGalactic_Imperial_Railing_Gray",
      "support": 15,
      "rotation": 3
    },
    {
      "x": -9,
      "y": 10,
      "z": 6,
      "name": "OrbisGalactic_Block_Imperial_Panel_Black_Smooth",
      "rotation": 3
    },
    {
      "x": -9,
      "y": 3,
      "z": 7,
      "name": "OrbisGalactic_Block_Imperial_Panel_Gray_Brick_Vertical",
      "rotation": 2
    },
    {
      "x": -9,
      "y": 9,
      "z": 7,
      "name": "OrbisGalactic_Block_Imperial_Panel_Black_Smooth",
      "rotation": 3
    },
    {
      "x": -9,
      "y": 3,
      "z": 8,
      "name": "OrbisGalactic_Block_Imperial_Panel_Black_Brick_Vertical",
      "rotation": 1
    },
    {
      "x": -9,
      "y": 4,
      "z": 8,
      "name": "OrbisGalactic_Block_Imperial_Ship_Window_Bottom_Right",
      "rotation": 2
    },
    {
      "x": -9,
      "y": 5,
      "z": 8,
      "name": "OrbisGalactic_Block_Imperial_Ship_Window_Right_Center",
      "rotation": 2
    },
    {
      "x": -9,
      "y": 6,
      "z": 8,
      "name": "OrbisGalactic_Block_Imperial_Ship_Window_Right_Center",
      "rotation": 2
    },
    {
      "x": -9,
      "y": 7,
      "z": 8,
      "name": "OrbisGalactic_Block_Imperial_Ship_Window_Top_Right",
      "rotation": 2
    },
    {
      "x": -9,
      "y": 8,
      "z": 8,
      "name": "OrbisGalactic_Block_Imperial_Panel_Black_Brick_Horizontal",
      "rotation": 3
    },
    {
      "x": -8,
      "y": 3,
      "z": -8,
      "name": "OrbisGalactic_Block_Imperial_Panel_Black_Brick_Vertical",
      "rotation": 3
    },
    {
      "x": -8,
      "y": 4,
      "z": -8,
      "name": "OrbisGalactic_Block_Imperial_Ship_Window_Bottom_Center"
    },
    {
      "x": -8,
      "y": 5,
      "z": -8,
      "name": "OrbisGalactic_Block_Imperial_Ship_Window_Center"
    },
    {
      "x": -8,
      "y": 6,
      "z": -8,
      "name": "OrbisGalactic_Block_Imperial_Ship_Window_Center"
    },
    {
      "x": -8,
      "y": 7,
      "z": -8,
      "name": "OrbisGalactic_Block_Imperial_Ship_Window_Top_Center"
    },
    {
      "x": -8,
      "y": 8,
      "z": -8,
      "name": "OrbisGalactic_Block_Imperial_Panel_Black_Brick_Horizontal",
      "rotation": 3
    },
    {
      "x": -8,
      "y": 3,
      "z": -7,
      "name": "OrbisGalactic_Block_Imperial_Panel_Gray_Brick_Vertical",
      "rotation": 1
    },
    {
      "x": -8,
      "y": 4,
      "z": -7,
      "name": "OrbisGalactic_Imperial_Railing_Gray",
      "support": 15,
      "rotation": 2
    },
    {
      "x": -8,
      "y": 9,
      "z": -7,
      "name": "OrbisGalactic_Block_Imperial_Panel_Black_Brick_Vertical",
      "rotation": 3
    },
    {
      "x": -8,
      "y": 2,
      "z": -6,
      "name": "OrbisGalactic_Block_Imperial_Panel_Gray_Brick_Vertical",
      "rotation": 2
    },
    {
      "x": -8,
      "y": 10,
      "z": -6,
      "name": "OrbisGalactic_Block_Imperial_Panel_Black_Brick_Vertical",
      "rotation": 1
    },
    {
      "x": -8,
      "y": 2,
      "z": -5,
      "name": "OrbisGalactic_Block_Imperial_Panel_Gray_Brick_Vertical",
      "rotation": 2
    },
    {
      "x": -8,
      "y": 11,
      "z": -5,
      "name": "OrbisGalactic_Block_Imperial_Panel_Black_Smooth",
      "rotation": 2
    },
    {
      "x": -8,
      "y": 2,
      "z": -4,
      "name": "OrbisGalactic_Block_Imperial_Panel_Gray_Brick_Vertical",
      "rotation": 2
    },
    {
      "x": -8,
      "y": 11,
      "z": -4,
      "name": "OrbisGalactic_Block_Imperial_Panel_Black_Brick_Vertical",
      "rotation": 1
    },
    {
      "x": -8,
      "y": 2,
      "z": -3,
      "name": "OrbisGalactic_Block_Imperial_Panel_Gray_Brick_Vertical",
      "rotation": 2
    },
    {
      "x": -8,
      "y": 11,
      "z": -3,
      "name": "OrbisGalactic_Block_Imperial_Panel_Black_Brick_Vertical",
      "rotation": 1
    },
    {
      "x": -8,
      "y": 2,
      "z": -2,
      "name": "OrbisGalactic_Block_Imperial_Panel_Gray_Brick_Vertical",
      "rotation": 2
    },
    {
      "x": -8,
      "y": 5,
      "z": -2,
      "name": "OrbisGalactic_Imperial_Railing_Gray",
      "support": 15,
      "rotation": 2
    },
    {
      "x": -8,
      "y": 11,
      "z": -2,
      "name": "OrbisGalactic_Block_Imperial_Panel_Black_Brick_Vertical",
      "rotation": 1
    },
    {
      "x": -8,
      "y": 3,
      "z": -1,
      "name": "OrbisGalactic_Block_Imperial_Panel_Gray",
      "rotation": 1
    },
    {
      "x": -8,
      "y": 4,
      "z": -1,
      "name": "OrbisGalactic_Block_Imperial_Panel_Gray_Brick_Horizontal",
      "rotation": 1
    },
    {
      "x": -8,
      "y": 11,
      "z": -1,
      "name": "OrbisGalactic_Block_Imperial_Panel_Black_Brick_Vertical",
      "rotation": 1
    },
    {
      "x": -8,
      "y": 3,
      "z": 0,
      "name": "OrbisGalactic_Block_Imperial_Panel_Gray",
      "rotation": 1
    },
    {
      "x": -8,
      "y": 4,
      "z": 0,
      "name": "OrbisGalactic_Block_Imperial_Panel_Gray",
      "rotation": 1
    },
    {
      "x": -8,
      "y": 5,
      "z": 0,
      "name": "OrbisGalactic_Ship_Controls",
      "rotation": 1
    },
    {
      "x": -8,
      "y": 11,
      "z": 0,
      "name": "OrbisGalactic_Block_Imperial_Panel_Black_Brick_Vertical",
      "rotation": 1
    },
    {
      "x": -8,
      "y": 3,
      "z": 1,
      "name": "OrbisGalactic_Block_Imperial_Panel_Gray",
      "rotation": 1
    },
    {
      "x": -8,
      "y": 4,
      "z": 1,
      "name": "OrbisGalactic_Block_Imperial_Panel_Gray_Brick_Horizontal"
    },
    {
      "x": -8,
      "y": 11,
      "z": 1,
      "name": "OrbisGalactic_Block_Imperial_Panel_Black_Brick_Vertical",
      "rotation": 1
    },
    {
      "x": -8,
      "y": 2,
      "z": 2,
      "name": "OrbisGalactic_Block_Imperial_Panel_Gray",
      "rotation": 3
    },
    {
      "x": -8,
      "y": 11,
      "z": 2,
      "name": "OrbisGalactic_Block_Imperial_Panel_Black_Brick_Vertical",
      "rotation": 1
    },
    {
      "x": -8,
      "y": 2,
      "z": 3,
      "name": "OrbisGalactic_Block_Imperial_Panel_Gray",
      "rotation": 3
    },
    {
      "x": -8,
      "y": 11,
      "z": 3,
      "name": "OrbisGalactic_Block_Imperial_Panel_Black_Brick_Vertical",
      "rotation": 1
    },
    {
      "x": -8,
      "y": 2,
      "z": 4,
      "name": "OrbisGalactic_Block_Imperial_Panel_Gray",
      "rotation": 3
    },
    {
      "x": -8,
      "y": 11,
      "z": 4,
      "name": "OrbisGalactic_Block_Imperial_Panel_Black_Brick_Vertical",
      "rotation": 1
    },
    {
      "x": -8,
      "y": 2,
      "z": 5,
      "name": "OrbisGalactic_Block_Imperial_Panel_Gray",
      "rotation": 3
    },
    {
      "x": -8,
      "y": 11,
      "z": 5,
      "name": "OrbisGalactic_Block_Imperial_Panel_Black_Brick_Vertical",
      "rotation": 3
    },
    {
      "x": -8,
      "y": 2,
      "z": 6,
      "name": "OrbisGalactic_Block_Imperial_Panel_Gray",
      "rotation": 3
    },
    {
      "x": -8,
      "y": 10,
      "z": 6,
      "name": "OrbisGalactic_Block_Imperial_Panel_Black_Brick_Vertical",
      "rotation": 3
    },
    {
      "x": -8,
      "y": 3,
      "z": 7,
      "name": "OrbisGalactic_Block_Imperial_Panel_Gray_Brick_Vertical",
      "rotation": 3
    },
    {
      "x": -8,
      "y": 4,
      "z": 7,
      "name": "OrbisGalactic_Imperial_Railing_Gray",
      "support": 15
    },
    {
      "x": -8,
      "y": 9,
      "z": 7,
      "name": "OrbisGalactic_Block_Imperial_Panel_Black_Brick_Vertical",
      "rotation": 3
    },
    {
      "x": -8,
      "y": 3,
      "z": 8,
      "name": "OrbisGalactic_Block_Imperial_Panel_Black_Brick_Vertical",
      "rotation": 1
    },
    {
      "x": -8,
      "y": 4,
      "z": 8,
      "name": "OrbisGalactic_Block_Imperial_Ship_Window_Bottom_Center",
      "rotation": 2
    },
    {
      "x": -8,
      "y": 5,
      "z": 8,
      "name": "OrbisGalactic_Block_Imperial_Ship_Window_Center",
      "rotation": 2
    },
    {
      "x": -8,
      "y": 6,
      "z": 8,
      "name": "OrbisGalactic_Block_Imperial_Ship_Window_Center",
      "rotation": 2
    },
    {
      "x": -8,
      "y": 7,
      "z": 8,
      "name": "OrbisGalactic_Block_Imperial_Ship_Window_Top_Center",
      "rotation": 2
    },
    {
      "x": -8,
      "y": 8,
      "z": 8,
      "name": "OrbisGalactic_Block_Imperial_Panel_Black_Brick_Horizontal",
      "rotation": 3
    },
    {
      "x": -7,
      "y": 3,
      "z": -8,
      "name": "OrbisGalactic_Block_Imperial_Panel_Black_Brick_Vertical",
      "rotation": 3
    },
    {
      "x": -7,
      "y": 4,
      "z": -8,
      "name": "OrbisGalactic_Block_Imperial_Ship_Window_Bottom_Center"
    },
    {
      "x": -7,
      "y": 5,
      "z": -8,
      "name": "OrbisGalactic_Block_Imperial_Ship_Window_Center"
    },
    {
      "x": -7,
      "y": 6,
      "z": -8,
      "name": "OrbisGalactic_Block_Imperial_Ship_Window_Center"
    },
    {
      "x": -7,
      "y": 7,
      "z": -8,
      "name": "OrbisGalactic_Block_Imperial_Ship_Window_Top_Center"
    },
    {
      "x": -7,
      "y": 8,
      "z": -8,
      "name": "OrbisGalactic_Block_Imperial_Panel_Black_Brick_Horizontal",
      "rotation": 3
    },
    {
      "x": -7,
      "y": 3,
      "z": -7,
      "name": "OrbisGalactic_Block_Imperial_Panel_Gray_Brick_Vertical",
      "rotation": 1
    },
    {
      "x": -7,
      "y": 4,
      "z": -7,
      "name": "OrbisGalactic_Imperial_Railing_Gray",
      "support": 15,
      "rotation": 2
    },
    {
      "x": -7,
      "y": 9,
      "z": -7,
      "name": "OrbisGalactic_Block_Imperial_Panel_Black_Brick_Vertical",
      "rotation": 3
    },
    {
      "x": -7,
      "y": 2,
      "z": -6,
      "name": "OrbisGalactic_Block_Imperial_Panel_Gray_Brick_Horizontal",
      "rotation": 2
    },
    {
      "x": -7,
      "y": 10,
      "z": -6,
      "name": "OrbisGalactic_Block_Imperial_Panel_Black_Brick_Vertical",
      "rotation": 1
    },
    {
      "x": -7,
      "y": 2,
      "z": -5,
      "name": "OrbisGalactic_Block_Imperial_Panel_Gray",
      "rotation": 2
    },
    {
      "x": -7,
      "y": 11,
      "z": -5,
      "name": "OrbisGalactic_Block_Imperial_Panel_Black_Brick_Vertical",
      "rotation": 1
    },
    {
      "x": -7,
      "y": 2,
      "z": -4,
      "name": "OrbisGalactic_Block_Imperial_Panel_Gray",
      "rotation": 1
    },
    {
      "x": -7,
      "y": 3,
      "z": -4,
      "name": "OrbisGalactic_Ship_Controls",
      "rotation": 1
    },
    {
      "x": -7,
      "y": 11,
      "z": -4,
      "name": "OrbisGalactic_Block_Imperial_Panel_Black_Brick_Vertical",
      "rotation": 1
    },
    {
      "x": -7,
      "y": 2,
      "z": -3,
      "name": "OrbisGalactic_Block_Imperial_Panel_Gray",
      "rotation": 1
    },
    {
      "x": -7,
      "y": 11,
      "z": -3,
      "name": "OrbisGalactic_Block_Imperial_Panel_Black_Brick_Vertical",
      "rotation": 1
    },
    {
      "x": -7,
      "y": 2,
      "z": -2,
      "name": "OrbisGalactic_Block_Imperial_Panel_Gray_Brick_Vertical",
      "rotation": 1
    },
    {
      "x": -7,
      "y": 5,
      "z": -2,
      "name": "OrbisGalactic_Imperial_Railing_Gray",
      "support": 15,
      "rotation": 2
    },
    {
      "x": -7,
      "y": 11,
      "z": -2,
      "name": "OrbisGalactic_Block_Imperial_Panel_Black_Brick_Vertical",
      "rotation": 1
    },
    {
      "x": -7,
      "y": 3,
      "z": -1,
      "name": "OrbisGalactic_Block_Imperial_Panel_Gray",
      "rotation": 1
    },
    {
      "x": -7,
      "y": 4,
      "z": -1,
      "name": "OrbisGalactic_Block_Imperial_Panel_Gray_Brick_Horizontal",
      "rotation": 2
    },
    {
      "x": -7,
      "y": 11,
      "z": -1,
      "name": "OrbisGalactic_Block_Imperial_Panel_Black_Brick_Vertical",
      "rotation": 1
    },
    {
      "x": -7,
      "y": 3,
      "z": 0,
      "name": "Ship_Ambience_Player"
    },
    {
      "x": -7,
      "y": 4,
      "z": 0,
      "name": "OrbisGalactic_Block_Imperial_Panel_White_Smooth",
      "rotation": 1
    },
    {
      "x": -7,
      "y": 11,
      "z": 0,
      "name": "OrbisGalactic_Block_Imperial_Panel_Black_Brick_Vertical",
      "rotation": 1
    },
    {
      "x": -7,
      "y": 3,
      "z": 1,
      "name": "OrbisGalactic_Block_Imperial_Panel_Gray",
      "rotation": 1
    },
    {
      "x": -7,
      "y": 4,
      "z": 1,
      "name": "OrbisGalactic_Block_Imperial_Panel_Gray_Brick_Horizontal"
    },
    {
      "x": -7,
      "y": 5,
      "z": 1,
      "name": "OrbisGalactic_Imperial_Railing_Gray",
      "support": 15,
      "rotation": 2
    },
    {
      "x": -7,
      "y": 11,
      "z": 1,
      "name": "OrbisGalactic_Block_Imperial_Panel_Black_Brick_Vertical",
      "rotation": 1
    },
    {
      "x": -7,
      "y": 2,
      "z": 2,
      "name": "OrbisGalactic_Block_Imperial_Panel_Gray",
      "rotation": 1
    },
    {
      "x": -7,
      "y": 11,
      "z": 2,
      "name": "OrbisGalactic_Block_Imperial_Panel_Black_Brick_Vertical",
      "rotation": 1
    },
    {
      "x": -7,
      "y": 2,
      "z": 3,
      "name": "OrbisGalactic_Block_Imperial_Panel_Gray",
      "rotation": 1
    },
    {
      "x": -7,
      "y": 11,
      "z": 3,
      "name": "OrbisGalactic_Block_Imperial_Panel_Black_Brick_Vertical",
      "rotation": 1
    },
    {
      "x": -7,
      "y": 2,
      "z": 4,
      "name": "OrbisGalactic_Block_Imperial_Panel_Gray",
      "rotation": 1
    },
    {
      "x": -7,
      "y": 3,
      "z": 4,
      "name": "OrbisGalactic_Ship_Controls",
      "rotation": 1
    },
    {
      "x": -7,
      "y": 11,
      "z": 4,
      "name": "OrbisGalactic_Block_Imperial_Panel_Black_Brick_Vertical",
      "rotation": 1
    },
    {
      "x": -7,
      "y": 2,
      "z": 5,
      "name": "OrbisGalactic_Block_Imperial_Panel_Gray",
      "rotation": 1
    },
    {
      "x": -7,
      "y": 11,
      "z": 5,
      "name": "OrbisGalactic_Block_Imperial_Panel_Black_Brick_Vertical",
      "rotation": 3
    },
    {
      "x": -7,
      "y": 2,
      "z": 6,
      "name": "OrbisGalactic_Block_Imperial_Panel_Gray",
      "rotation": 3
    },
    {
      "x": -7,
      "y": 10,
      "z": 6,
      "name": "OrbisGalactic_Block_Imperial_Panel_Black_Brick_Vertical",
      "rotation": 3
    },
    {
      "x": -7,
      "y": 3,
      "z": 7,
      "name": "OrbisGalactic_Block_Imperial_Panel_Gray_Brick_Vertical",
      "rotation": 3
    },
    {
      "x": -7,
      "y": 4,
      "z": 7,
      "name": "OrbisGalactic_Imperial_Railing_Gray",
      "support": 15
    },
    {
      "x": -7,
      "y": 9,
      "z": 7,
      "name": "OrbisGalactic_Block_Imperial_Panel_Black_Brick_Vertical",
      "rotation": 3
    },
    {
      "x": -7,
      "y": 3,
      "z": 8,
      "name": "OrbisGalactic_Block_Imperial_Panel_Black_Brick_Vertical",
      "rotation": 3
    },
    {
      "x": -7,
      "y": 4,
      "z": 8,
      "name": "OrbisGalactic_Block_Imperial_Ship_Window_Bottom_Center",
      "rotation": 2
    },
    {
      "x": -7,
      "y": 5,
      "z": 8,
      "name": "OrbisGalactic_Block_Imperial_Ship_Window_Center",
      "rotation": 2
    },
    {
      "x": -7,
      "y": 6,
      "z": 8,
      "name": "OrbisGalactic_Block_Imperial_Ship_Window_Center",
      "rotation": 2
    },
    {
      "x": -7,
      "y": 7,
      "z": 8,
      "name": "OrbisGalactic_Block_Imperial_Ship_Window_Top_Center",
      "rotation": 2
    },
    {
      "x": -7,
      "y": 8,
      "z": 8,
      "name": "OrbisGalactic_Block_Imperial_Panel_Black_Brick_Horizontal",
      "rotation": 3
    },
    {
      "x": -6,
      "y": 3,
      "z": -8,
      "name": "OrbisGalactic_Block_Imperial_Panel_Black_Brick_Vertical",
      "rotation": 3
    },
    {
      "x": -6,
      "y": 4,
      "z": -8,
      "name": "OrbisGalactic_Block_Imperial_Ship_Window_Bottom_Center"
    },
    {
      "x": -6,
      "y": 5,
      "z": -8,
      "name": "OrbisGalactic_Block_Imperial_Ship_Window_Center"
    },
    {
      "x": -6,
      "y": 6,
      "z": -8,
      "name": "OrbisGalactic_Block_Imperial_Ship_Window_Center"
    },
    {
      "x": -6,
      "y": 7,
      "z": -8,
      "name": "OrbisGalactic_Block_Imperial_Ship_Window_Top_Center"
    },
    {
      "x": -6,
      "y": 8,
      "z": -8,
      "name": "OrbisGalactic_Block_Imperial_Panel_Black_Brick_Horizontal",
      "rotation": 3
    },
    {
      "x": -6,
      "y": 3,
      "z": -7,
      "name": "OrbisGalactic_Block_Imperial_Panel_Gray_Brick_Vertical",
      "rotation": 1
    },
    {
      "x": -6,
      "y": 4,
      "z": -7,
      "name": "OrbisGalactic_Imperial_Railing_Gray",
      "support": 15,
      "rotation": 2
    },
    {
      "x": -6,
      "y": 9,
      "z": -7,
      "name": "OrbisGalactic_Block_Imperial_Panel_Black_Brick_Vertical",
      "rotation": 3
    },
    {
      "x": -6,
      "y": 2,
      "z": -6,
      "name": "OrbisGalactic_Block_Imperial_Panel_Gray_Brick_Horizontal",
      "rotation": 2
    },
    {
      "x": -6,
      "y": 10,
      "z": -6,
      "name": "OrbisGalactic_Block_Imperial_Panel_Black_Brick_Vertical",
      "rotation": 1
    },
    {
      "x": -6,
      "y": 2,
      "z": -5,
      "name": "OrbisGalactic_Block_Imperial_Panel_Gray",
      "rotation": 2
    },
    {
      "x": -6,
      "y": 11,
      "z": -5,
      "name": "OrbisGalactic_Block_Imperial_Panel_Black_Brick_Vertical",
      "rotation": 1
    },
    {
      "x": -6,
      "y": 2,
      "z": -4,
      "name": "OrbisGalactic_Block_Imperial_Panel_Gray",
      "rotation": 1
    },
    {
      "x": -6,
      "y": 11,
      "z": -4,
      "name": "OrbisGalactic_Block_Imperial_Panel_Black_Brick_Vertical",
      "rotation": 1
    },
    {
      "x": -6,
      "y": 2,
      "z": -3,
      "name": "OrbisGalactic_Block_Imperial_Panel_Gray",
      "rotation": 1
    },
    {
      "x": -6,
      "y": 11,
      "z": -3,
      "name": "OrbisGalactic_Block_Imperial_Panel_Black_Brick_Vertical",
      "rotation": 1
    },
    {
      "x": -6,
      "y": 2,
      "z": -2,
      "name": "OrbisGalactic_Block_Imperial_Panel_Gray_Brick_Vertical",
      "rotation": 1
    },
    {
      "x": -6,
      "y": 5,
      "z": -2,
      "name": "OrbisGalactic_Imperial_Railing_Gray",
      "support": 15,
      "rotation": 2
    },
    {
      "x": -6,
      "y": 11,
      "z": -2,
      "name": "OrbisGalactic_Block_Imperial_Panel_Black_Brick_Vertical",
      "rotation": 1
    },
    {
      "x": -6,
      "y": 3,
      "z": -1,
      "name": "OrbisGalactic_Block_Imperial_Panel_Gray_Brick_Vertical",
      "rotation": 2
    },
    {
      "x": -6,
      "y": 4,
      "z": -1,
      "name": "OrbisGalactic_Block_Imperial_Panel_Gray_Brick_Horizontal",
      "rotation": 2
    },
    {
      "x": -6,
      "y": 11,
      "z": -1,
      "name": "OrbisGalactic_Block_Imperial_Panel_Black_Brick_Vertical",
      "rotation": 1
    },
    {
      "x": -6,
      "y": 3,
      "z": 0,
      "name": "OrbisGalactic_Block_Imperial_Panel_Gray",
      "rotation": 1
    },
    {
      "x": -6,
      "y": 4,
      "z": 0,
      "name": "OrbisGalactic_Block_Imperial_Panel_White_Smooth",
      "rotation": 1
    },
    {
      "x": -6,
      "y": 11,
      "z": 0,
      "name": "OrbisGalactic_Block_Imperial_Panel_Black_Brick_Vertical",
      "rotation": 1
    },
    {
      "x": -6,
      "y": 3,
      "z": 1,
      "name": "OrbisGalactic_Block_Imperial_Panel_Gray",
      "rotation": 1
    },
    {
      "x": -6,
      "y": 4,
      "z": 1,
      "name": "OrbisGalactic_Block_Imperial_Panel_Gray_Brick_Horizontal"
    },
    {
      "x": -6,
      "y": 5,
      "z": 1,
      "name": "OrbisGalactic_Imperial_Railing_Gray",
      "support": 15,
      "rotation": 2
    },
    {
      "x": -6,
      "y": 11,
      "z": 1,
      "name": "OrbisGalactic_Block_Imperial_Panel_Black_Brick_Vertical",
      "rotation": 1
    },
    {
      "x": -6,
      "y": 2,
      "z": 2,
      "name": "OrbisGalactic_Block_Imperial_Panel_Gray",
      "rotation": 1
    },
    {
      "x": -6,
      "y": 11,
      "z": 2,
      "name": "OrbisGalactic_Block_Imperial_Panel_Black_Brick_Vertical",
      "rotation": 1
    },
    {
      "x": -6,
      "y": 2,
      "z": 3,
      "name": "OrbisGalactic_Block_Imperial_Panel_Gray",
      "rotation": 1
    },
    {
      "x": -6,
      "y": 11,
      "z": 3,
      "name": "OrbisGalactic_Block_Imperial_Panel_Black_Brick_Vertical",
      "rotation": 1
    },
    {
      "x": -6,
      "y": 2,
      "z": 4,
      "name": "OrbisGalactic_Block_Imperial_Panel_Gray",
      "rotation": 1
    },
    {
      "x": -6,
      "y": 11,
      "z": 4,
      "name": "OrbisGalactic_Block_Imperial_Panel_Black_Brick_Vertical",
      "rotation": 1
    },
    {
      "x": -6,
      "y": 2,
      "z": 5,
      "name": "OrbisGalactic_Block_Imperial_Panel_Gray",
      "rotation": 1
    },
    {
      "x": -6,
      "y": 11,
      "z": 5,
      "name": "OrbisGalactic_Block_Imperial_Panel_Black_Brick_Vertical",
      "rotation": 3
    },
    {
      "x": -6,
      "y": 2,
      "z": 6,
      "name": "OrbisGalactic_Block_Imperial_Panel_Gray",
      "rotation": 3
    },
    {
      "x": -6,
      "y": 10,
      "z": 6,
      "name": "OrbisGalactic_Block_Imperial_Panel_Black_Brick_Vertical",
      "rotation": 3
    },
    {
      "x": -6,
      "y": 3,
      "z": 7,
      "name": "OrbisGalactic_Block_Imperial_Panel_Gray_Brick_Vertical",
      "rotation": 3
    },
    {
      "x": -6,
      "y": 4,
      "z": 7,
      "name": "OrbisGalactic_Imperial_Railing_Gray",
      "support": 15
    },
    {
      "x": -6,
      "y": 9,
      "z": 7,
      "name": "OrbisGalactic_Block_Imperial_Panel_Black_Brick_Vertical",
      "rotation": 3
    },
    {
      "x": -6,
      "y": 3,
      "z": 8,
      "name": "OrbisGalactic_Block_Imperial_Panel_Black_Brick_Vertical",
      "rotation": 3
    },
    {
      "x": -6,
      "y": 4,
      "z": 8,
      "name": "OrbisGalactic_Block_Imperial_Ship_Window_Bottom_Center",
      "rotation": 2
    },
    {
      "x": -6,
      "y": 5,
      "z": 8,
      "name": "OrbisGalactic_Block_Imperial_Ship_Window_Center",
      "rotation": 2
    },
    {
      "x": -6,
      "y": 6,
      "z": 8,
      "name": "OrbisGalactic_Block_Imperial_Ship_Window_Center",
      "rotation": 2
    },
    {
      "x": -6,
      "y": 7,
      "z": 8,
      "name": "OrbisGalactic_Block_Imperial_Ship_Window_Top_Center",
      "rotation": 2
    },
    {
      "x": -6,
      "y": 8,
      "z": 8,
      "name": "OrbisGalactic_Block_Imperial_Panel_Black_Brick_Horizontal",
      "rotation": 3
    },
    {
      "x": -5,
      "y": 3,
      "z": -8,
      "name": "OrbisGalactic_Block_Imperial_Panel_Black_Brick_Vertical",
      "rotation": 3
    },
    {
      "x": -5,
      "y": 4,
      "z": -8,
      "name": "OrbisGalactic_Block_Imperial_Ship_Window_Bottom_Right"
    },
    {
      "x": -5,
      "y": 5,
      "z": -8,
      "name": "OrbisGalactic_Block_Imperial_Ship_Window_Right_Center"
    },
    {
      "x": -5,
      "y": 6,
      "z": -8,
      "name": "OrbisGalactic_Block_Imperial_Ship_Window_Right_Center"
    },
    {
      "x": -5,
      "y": 7,
      "z": -8,
      "name": "OrbisGalactic_Block_Imperial_Ship_Window_Top_Right"
    },
    {
      "x": -5,
      "y": 8,
      "z": -8,
      "name": "OrbisGalactic_Block_Imperial_Panel_Black_Brick_Horizontal",
      "rotation": 3
    },
    {
      "x": -5,
      "y": 3,
      "z": -7,
      "name": "OrbisGalactic_Block_Imperial_Panel_Gray_Brick_Vertical",
      "rotation": 1
    },
    {
      "x": -5,
      "y": 4,
      "z": -7,
      "name": "OrbisGalactic_Imperial_Railing_Gray",
      "support": 15,
      "rotation": 2
    },
    {
      "x": -5,
      "y": 9,
      "z": -7,
      "name": "OrbisGalactic_Block_Imperial_Panel_Black_Brick_Vertical",
      "rotation": 3
    },
    {
      "x": -5,
      "y": 2,
      "z": -6,
      "name": "OrbisGalactic_Block_Imperial_Panel_Gray_Brick_Horizontal",
      "rotation": 2
    },
    {
      "x": -5,
      "y": 10,
      "z": -6,
      "name": "OrbisGalactic_Block_Imperial_Panel_Black_Smooth",
      "rotation": 1
    },
    {
      "x": -5,
      "y": 2,
      "z": -5,
      "name": "OrbisGalactic_Block_Imperial_Panel_Gray",
      "rotation": 2
    },
    {
      "x": -5,
      "y": 11,
      "z": -5,
      "name": "OrbisGalactic_Block_Imperial_Panel_Black_Smooth",
      "rotation": 1
    },
    {
      "x": -5,
      "y": 2,
      "z": -4,
      "name": "OrbisGalactic_Block_Imperial_Panel_Gray",
      "rotation": 1
    },
    {
      "x": -5,
      "y": 3,
      "z": -4,
      "name": "OrbisGalactic_Spaceship_Chair",
      "rotation": 3
    },
    {
      "x": -5,
      "y": 11,
      "z": -4,
      "name": "OrbisGalactic_Block_Imperial_Panel_Black_Brick_Vertical",
      "rotation": 1
    },
    {
      "x": -5,
      "y": 2,
      "z": -3,
      "name": "OrbisGalactic_Block_Imperial_Panel_Gray",
      "rotation": 1
    },
    {
      "x": -5,
      "y": 11,
      "z": -3,
      "name": "OrbisGalactic_Block_Imperial_Panel_Black_Brick_Vertical",
      "rotation": 1
    },
    {
      "x": -5,
      "y": 2,
      "z": -2,
      "name": "OrbisGalactic_Block_Imperial_Panel_Gray_Brick_Horizontal"
    },
    {
      "x": -5,
      "y": 5,
      "z": -2,
      "name": "OrbisGalactic_Imperial_Railing_Gray",
      "support": 15,
      "rotation": 2
    },
    {
      "x": -5,
      "y": 11,
      "z": -2,
      "name": "OrbisGalactic_Block_Imperial_Panel_Black_Brick_Vertical",
      "rotation": 1
    },
    {
      "x": -5,
      "y": 3,
      "z": -1,
      "name": "OrbisGalactic_Block_Imperial_Panel_Gray",
      "rotation": 2
    },
    {
      "x": -5,
      "y": 4,
      "z": -1,
      "name": "OrbisGalactic_Block_Imperial_Panel_Gray_Brick_Horizontal"
    },
    {
      "x": -5,
      "y": 11,
      "z": -1,
      "name": "OrbisGalactic_Block_Imperial_Panel_Black_Brick_Vertical",
      "rotation": 1
    },
    {
      "x": -5,
      "y": 3,
      "z": 0,
      "name": "OrbisGalactic_Block_Imperial_Panel_Gray",
      "rotation": 1
    },
    {
      "x": -5,
      "y": 4,
      "z": 0,
      "name": "OrbisGalactic_Block_Imperial_Panel_White_Smooth",
      "rotation": 1
    },
    {
      "x": -5,
      "y": 11,
      "z": 0,
      "name": "OrbisGalactic_Block_Imperial_Panel_Black_Brick_Vertical",
      "rotation": 1
    },
    {
      "x": -5,
      "y": 3,
      "z": 1,
      "name": "OrbisGalactic_Block_Imperial_Panel_Gray",
      "rotation": 1
    },
    {
      "x": -5,
      "y": 4,
      "z": 1,
      "name": "OrbisGalactic_Block_Imperial_Panel_Gray_Brick_Horizontal"
    },
    {
      "x": -5,
      "y": 5,
      "z": 1,
      "name": "OrbisGalactic_Imperial_Railing_Gray",
      "support": 15,
      "rotation": 2
    },
    {
      "x": -5,
      "y": 11,
      "z": 1,
      "name": "OrbisGalactic_Block_Imperial_Panel_Black_Brick_Vertical",
      "rotation": 1
    },
    {
      "x": -5,
      "y": 2,
      "z": 2,
      "name": "OrbisGalactic_Block_Imperial_Panel_Gray",
      "rotation": 1
    },
    {
      "x": -5,
      "y": 11,
      "z": 2,
      "name": "OrbisGalactic_Block_Imperial_Panel_Black_Brick_Vertical",
      "rotation": 1
    },
    {
      "x": -5,
      "y": 2,
      "z": 3,
      "name": "OrbisGalactic_Block_Imperial_Panel_Gray",
      "rotation": 1
    },
    {
      "x": -5,
      "y": 11,
      "z": 3,
      "name": "OrbisGalactic_Block_Imperial_Panel_Black_Brick_Vertical",
      "rotation": 1
    },
    {
      "x": -5,
      "y": 2,
      "z": 4,
      "name": "OrbisGalactic_Block_Imperial_Panel_Gray",
      "rotation": 1
    },
    {
      "x": -5,
      "y": 3,
      "z": 4,
      "name": "OrbisGalactic_Spaceship_Chair",
      "rotation": 3
    },
    {
      "x": -5,
      "y": 11,
      "z": 4,
      "name": "OrbisGalactic_Block_Imperial_Panel_Black_Brick_Vertical",
      "rotation": 1
    },
    {
      "x": -5,
      "y": 2,
      "z": 5,
      "name": "OrbisGalactic_Block_Imperial_Panel_Gray",
      "rotation": 1
    },
    {
      "x": -5,
      "y": 11,
      "z": 5,
      "name": "OrbisGalactic_Block_Imperial_Panel_Black_Smooth",
      "rotation": 3
    },
    {
      "x": -5,
      "y": 2,
      "z": 6,
      "name": "OrbisGalactic_Block_Imperial_Panel_Gray",
      "rotation": 3
    },
    {
      "x": -5,
      "y": 10,
      "z": 6,
      "name": "OrbisGalactic_Block_Imperial_Panel_Black_Smooth",
      "rotation": 3
    },
    {
      "x": -5,
      "y": 3,
      "z": 7,
      "name": "OrbisGalactic_Block_Imperial_Panel_Gray_Brick_Vertical",
      "rotation": 3
    },
    {
      "x": -5,
      "y": 4,
      "z": 7,
      "name": "OrbisGalactic_Imperial_Railing_Gray",
      "support": 15
    },
    {
      "x": -5,
      "y": 9,
      "z": 7,
      "name": "OrbisGalactic_Block_Imperial_Panel_Black_Brick_Vertical",
      "rotation": 3
    },
    {
      "x": -5,
      "y": 3,
      "z": 8,
      "name": "OrbisGalactic_Block_Imperial_Panel_Black_Brick_Vertical",
      "rotation": 3
    },
    {
      "x": -5,
      "y": 4,
      "z": 8,
      "name": "OrbisGalactic_Block_Imperial_Ship_Window_Bottom_Left",
      "rotation": 2
    },
    {
      "x": -5,
      "y": 5,
      "z": 8,
      "name": "OrbisGalactic_Block_Imperial_Ship_Window_Left_Center",
      "rotation": 2
    },
    {
      "x": -5,
      "y": 6,
      "z": 8,
      "name": "OrbisGalactic_Block_Imperial_Ship_Window_Left_Center",
      "rotation": 2
    },
    {
      "x": -5,
      "y": 7,
      "z": 8,
      "name": "OrbisGalactic_Block_Imperial_Ship_Window_Top_Left",
      "rotation": 2
    },
    {
      "x": -5,
      "y": 8,
      "z": 8,
      "name": "OrbisGalactic_Block_Imperial_Panel_Black_Brick_Horizontal",
      "rotation": 3
    },
    {
      "x": -4,
      "y": 3,
      "z": -8,
      "name": "OrbisGalactic_Block_Imperial_Panel_Black_Brick_Vertical",
      "rotation": 2
    },
    {
      "x": -4,
      "y": 4,
      "z": -8,
      "name": "OrbisGalactic_Block_Imperial_Panel_Black_Brick_Vertical",
      "rotation": 2
    },
    {
      "x": -4,
      "y": 5,
      "z": -8,
      "name": "OrbisGalactic_Block_Imperial_Panel_Black_Brick_Vertical",
      "rotation": 2
    },
    {
      "x": -4,
      "y": 6,
      "z": -8,
      "name": "OrbisGalactic_Block_Imperial_Panel_Black_Brick_Vertical",
      "rotation": 2
    },
    {
      "x": -4,
      "y": 7,
      "z": -8,
      "name": "OrbisGalactic_Block_Imperial_Panel_Black_Brick_Vertical",
      "rotation": 2
    },
    {
      "x": -4,
      "y": 8,
      "z": -8,
      "name": "OrbisGalactic_Block_Imperial_Panel_Black_Brick_Vertical",
      "rotation": 2
    },
    {
      "x": -4,
      "y": 3,
      "z": -7,
      "name": "*OrbisGalactic_Block_Imperial_Lamp1_State_Definitions_On",
      "rotation": 1
    },
    {
      "x": -4,
      "y": 4,
      "z": -7,
      "name": "OrbisGalactic_Imperial_Railing_Gray",
      "support": 15,
      "rotation": 2
    },
    {
      "x": -4,
      "y": 9,
      "z": -7,
      "name": "OrbisGalactic_Block_Imperial_Panel_Black_Brick_Vertical",
      "rotation": 3
    },
    {
      "x": -4,
      "y": 2,
      "z": -6,
      "name": "*OrbisGalactic_Block_Imperial_Lamp1_State_Definitions_On"
    },
    {
      "x": -4,
      "y": 4,
      "z": -6,
      "name": "OrbisGalactic_Imperial_Railing_Gray",
      "filler": 32,
      "rotation": 2
    },
    {
      "x": -4,
      "y": 9,
      "z": -6,
      "name": "OrbisGalactic_Block_Imperial_Panel_Black_Smooth"
    },
    {
      "x": -4,
      "y": 2,
      "z": -5,
      "name": "*OrbisGalactic_Block_Imperial_Lamp3_Connected_State_Definitions_On"
    },
    {
      "x": -4,
      "y": 10,
      "z": -5,
      "name": "OrbisGalactic_Block_Imperial_Panel_Black_Smooth"
    },
    {
      "x": -4,
      "y": 2,
      "z": -4,
      "name": "*OrbisGalactic_Block_Imperial_Lamp3_Connected_State_Definitions_On"
    },
    {
      "x": -4,
      "y": 11,
      "z": -4,
      "name": "OrbisGalactic_Block_Imperial_Panel_Black_Smooth",
      "rotation": 1
    },
    {
      "x": -4,
      "y": 2,
      "z": -3,
      "name": "*OrbisGalactic_Block_Imperial_Lamp3_Connected_State_Definitions_On"
    },
    {
      "x": -4,
      "y": 11,
      "z": -3,
      "name": "OrbisGalactic_Block_Imperial_Panel_Black_Brick_Vertical",
      "rotation": 1
    },
    {
      "x": -4,
      "y": 2,
      "z": -2,
      "name": "*OrbisGalactic_Block_Imperial_Lamp1_State_Definitions_On",
      "rotation": 2
    },
    {
      "x": -4,
      "y": 5,
      "z": -2,
      "name": "OrbisGalactic_Imperial_Railing_Gray",
      "support": 15,
      "rotation": 2
    },
    {
      "x": -4,
      "y": 11,
      "z": -2,
      "name": "OrbisGalactic_Block_Imperial_Panel_Black_Brick_Vertical",
      "rotation": 1
    },
    {
      "x": -4,
      "y": 3,
      "z": -1,
      "name": "OrbisGalactic_Block_Imperial_Panel_Gray",
      "rotation": 1
    },
    {
      "x": -4,
      "y": 4,
      "z": -1,
      "name": "OrbisGalactic_Block_Imperial_Panel_Gray",
      "rotation": 1
    },
    {
      "x": -4,
      "y": 11,
      "z": -1,
      "name": "OrbisGalactic_Block_Imperial_Panel_Black_Brick_Vertical",
      "rotation": 1
    },
    {
      "x": -4,
      "y": 3,
      "z": 0,
      "name": "OrbisGalactic_Block_Imperial_Panel_Gray",
      "rotation": 1
    },
    {
      "x": -4,
      "y": 4,
      "z": 0,
      "name": "OrbisGalactic_Block_Imperial_Panel_White_Smooth",
      "rotation": 1
    },
    {
      "x": -4,
      "y": 11,
      "z": 0,
      "name": "OrbisGalactic_Block_Imperial_Panel_Black_Brick_Vertical",
      "rotation": 1
    },
    {
      "x": -4,
      "y": 3,
      "z": 1,
      "name": "OrbisGalactic_Block_Imperial_Panel_Gray",
      "rotation": 1
    },
    {
      "x": -4,
      "y": 4,
      "z": 1,
      "name": "OrbisGalactic_Block_Imperial_Panel_Gray",
      "rotation": 1
    },
    {
      "x": -4,
      "y": 5,
      "z": 1,
      "name": "OrbisGalactic_Imperial_Railing_Gray",
      "support": 15,
      "rotation": 2
    },
    {
      "x": -4,
      "y": 11,
      "z": 1,
      "name": "OrbisGalactic_Block_Imperial_Panel_Black_Brick_Vertical",
      "rotation": 1
    },
    {
      "x": -4,
      "y": 2,
      "z": 2,
      "name": "*OrbisGalactic_Block_Imperial_Lamp1_State_Definitions_On"
    },
    {
      "x": -4,
      "y": 11,
      "z": 2,
      "name": "OrbisGalactic_Block_Imperial_Panel_Black_Brick_Vertical",
      "rotation": 1
    },
    {
      "x": -4,
      "y": 2,
      "z": 3,
      "name": "*OrbisGalactic_Block_Imperial_Lamp3_Connected_State_Definitions_On",
      "rotation": 2
    },
    {
      "x": -4,
      "y": 11,
      "z": 3,
      "name": "OrbisGalactic_Block_Imperial_Panel_Black_Brick_Vertical",
      "rotation": 1
    },
    {
      "x": -4,
      "y": 2,
      "z": 4,
      "name": "*OrbisGalactic_Block_Imperial_Lamp3_Connected_State_Definitions_On",
      "rotation": 2
    },
    {
      "x": -4,
      "y": 11,
      "z": 4,
      "name": "OrbisGalactic_Block_Imperial_Panel_Black_Smooth"
    },
    {
      "x": -4,
      "y": 2,
      "z": 5,
      "name": "*OrbisGalactic_Block_Imperial_Lamp3_Connected_State_Definitions_On",
      "rotation": 2
    },
    {
      "x": -4,
      "y": 10,
      "z": 5,
      "name": "OrbisGalactic_Block_Imperial_Panel_Black_Smooth",
      "rotation": 3
    },
    {
      "x": -4,
      "y": 2,
      "z": 6,
      "name": "*OrbisGalactic_Block_Imperial_Lamp1_State_Definitions_On",
      "rotation": 2
    },
    {
      "x": -4,
      "y": 4,
      "z": 6,
      "name": "OrbisGalactic_Imperial_Railing_Gray",
      "filler": 992
    },
    {
      "x": -4,
      "y": 9,
      "z": 6,
      "name": "OrbisGalactic_Block_Imperial_Panel_Black_Smooth",
      "rotation": 3
    },
    {
      "x": -4,
      "y": 3,
      "z": 7,
      "name": "*OrbisGalactic_Block_Imperial_Lamp1_State_Definitions_On",
      "rotation": 1
    },
    {
      "x": -4,
      "y": 4,
      "z": 7,
      "name": "OrbisGalactic_Imperial_Railing_Gray",
      "support": 15
    },
    {
      "x": -4,
      "y": 9,
      "z": 7,
      "name": "OrbisGalactic_Block_Imperial_Panel_Black_Brick_Vertical",
      "rotation": 3
    },
    {
      "x": -4,
      "y": 3,
      "z": 8,
      "name": "OrbisGalactic_Block_Imperial_Panel_Black_Brick_Vertical"
    },
    {
      "x": -4,
      "y": 4,
      "z": 8,
      "name": "OrbisGalactic_Block_Imperial_Panel_Black_Brick_Vertical"
    },
    {
      "x": -4,
      "y": 5,
      "z": 8,
      "name": "OrbisGalactic_Block_Imperial_Panel_Black_Brick_Vertical"
    },
    {
      "x": -4,
      "y": 6,
      "z": 8,
      "name": "OrbisGalactic_Block_Imperial_Panel_Black_Brick_Vertical"
    },
    {
      "x": -4,
      "y": 7,
      "z": 8,
      "name": "OrbisGalactic_Block_Imperial_Panel_Black_Brick_Vertical"
    },
    {
      "x": -4,
      "y": 8,
      "z": 8,
      "name": "OrbisGalactic_Block_Imperial_Panel_Black_Brick_Vertical"
    },
    {
      "x": -3,
      "y": 3,
      "z": -8,
      "name": "OrbisGalactic_Block_Imperial_Panel_Light_Gray_Brick_Vertical",
      "rotation": 1
    },
    {
      "x": -3,
      "y": 4,
      "z": -8,
      "name": "OrbisGalactic_Block_Imperial_Panel_Light_Gray_Brick_Vertical",
      "rotation": 1
    },
    {
      "x": -3,
      "y": 5,
      "z": -8,
      "name": "OrbisGalactic_Block_Imperial_Panel_Light_Gray_Brick_Vertical",
      "rotation": 1
    },
    {
      "x": -3,
      "y": 6,
      "z": -8,
      "name": "OrbisGalactic_Block_Imperial_Panel_Light_Gray_Brick_Vertical",
      "rotation": 1
    },
    {
      "x": -3,
      "y": 7,
      "z": -8,
      "name": "OrbisGalactic_Block_Imperial_Panel_Light_Gray_Brick_Vertical",
      "rotation": 1
    },
    {
      "x": -3,
      "y": 8,
      "z": -8,
      "name": "OrbisGalactic_Block_Imperial_Panel_Light_Gray_Brick_Vertical",
      "rotation": 1
    },
    {
      "x": -3,
      "y": 3,
      "z": -7,
      "name": "OrbisGalactic_Block_Imperial_Panel_Gray_Brick_Vertical",
      "rotation": 1
    },
    {
      "x": -3,
      "y": 4,
      "z": -7,
      "name": "*OrbisGalactic_Block_Imperial_Lamp3_Connected_State_Definitions_On"
    },
    {
      "x": -3,
      "y": 5,
      "z": -7,
      "name": "*OrbisGalactic_Block_Imperial_Lamp3_Connected_State_Definitions_On"
    },
    {
      "x": -3,
      "y": 6,
      "z": -7,
      "name": "*OrbisGalactic_Block_Imperial_Lamp3_Connected_State_Definitions_On"
    },
    {
      "x": -3,
      "y": 7,
      "z": -7,
      "name": "*OrbisGalactic_Block_Imperial_Lamp3_Connected_State_Definitions_On"
    },
    {
      "x": -3,
      "y": 8,
      "z": -7,
      "name": "*OrbisGalactic_Block_Imperial_Lamp3_Connected_State_Definitions_On"
    },
    {
      "x": -3,
      "y": 9,
      "z": -7,
      "name": "OrbisGalactic_Block_Imperial_Panel_Black_Smooth",
      "rotation": 2
    },
    {
      "x": -3,
      "y": 3,
      "z": -6,
      "name": "OrbisGalactic_Block_Imperial_Panel_Gray_Smooth"
    },
    {
      "x": -3,
      "y": 4,
      "z": -6,
      "name": "OrbisGalactic_Imperial_Railing_Gray",
      "support": 15,
      "rotation": 1
    },
    {
      "x": -3,
      "y": 9,
      "z": -6,
      "name": "OrbisGalactic_Block_Imperial_Panel_Black_Brick_Vertical",
      "rotation": 2
    },
    {
      "x": -3,
      "y": 3,
      "z": -5,
      "name": "OrbisGalactic_Block_Imperial_Panel_Gray_Brick_Vertical",
      "rotation": 2
    },
    {
      "x": -3,
      "y": 4,
      "z": -5,
      "name": "OrbisGalactic_Imperial_Railing_Gray",
      "support": 15,
      "rotation": 1
    },
    {
      "x": -3,
      "y": 9,
      "z": -5,
      "name": "OrbisGalactic_Block_Imperial_Panel_Black_Smooth",
      "rotation": 3
    },
    {
      "x": -3,
      "y": 2,
      "z": -4,
      "name": "OrbisGalactic_Block_Imperial_Panel_Gray",
      "rotation": 1
    },
    {
      "x": -3,
      "y": 3,
      "z": -4,
      "name": "OrbisGalactic_Block_Imperial_Panel_Gray_Smooth",
      "rotation": 3
    },
    {
      "x": -3,
      "y": 4,
      "z": -4,
      "name": "OrbisGalactic_Imperial_Railing_Gray",
      "support": 15,
      "rotation": 1
    },
    {
      "x": -3,
      "y": 10,
      "z": -4,
      "name": "OrbisGalactic_Block_Imperial_Panel_Black_Smooth",
      "rotation": 3
    },
    {
      "x": -3,
      "y": 2,
      "z": -3,
      "name": "OrbisGalactic_Block_Imperial_Panel_Gray",
      "rotation": 1
    },
    {
      "x": -3,
      "y": 3,
      "z": -3,
      "name": "OrbisGalactic_Block_Imperial_Panel_Gray_Half",
      "rotation": 1
    },
    {
      "x": -3,
      "y": 11,
      "z": -3,
      "name": "OrbisGalactic_Block_Imperial_Panel_Black_Smooth",
      "rotation": 1
    },
    {
      "x": -3,
      "y": 2,
      "z": -2,
      "name": "OrbisGalactic_Block_Imperial_Panel_Gray",
      "rotation": 1
    },
    {
      "x": -3,
      "y": 3,
      "z": -2,
      "name": "OrbisGalactic_Block_Imperial_Panel_Gray_Half",
      "rotation": 1
    },
    {
      "x": -3,
      "y": 11,
      "z": -2,
      "name": "OrbisGalactic_Block_Imperial_Panel_Black_Brick_Vertical",
      "rotation": 1
    },
    {
      "x": -3,
      "y": 3,
      "z": -1,
      "name": "OrbisGalactic_Block_Imperial_Panel_Gray",
      "rotation": 1
    },
    {
      "x": -3,
      "y": 4,
      "z": -1,
      "name": "OrbisGalactic_Block_Imperial_Panel_Gray_Half",
      "rotation": 2
    },
    {
      "x": -3,
      "y": 11,
      "z": -1,
      "name": "OrbisGalactic_Block_Imperial_Panel_Black_Brick_Vertical",
      "rotation": 1
    },
    {
      "x": -3,
      "y": 3,
      "z": 0,
      "name": "OrbisGalactic_Block_Imperial_Panel_Gray",
      "rotation": 1
    },
    {
      "x": -3,
      "y": 4,
      "z": 0,
      "name": "OrbisGalactic_Block_Imperial_Panel_White_Smooth_Half",
      "rotation": 1
    },
    {
      "x": -3,
      "y": 11,
      "z": 0,
      "name": "OrbisGalactic_Block_Imperial_Panel_Black_Brick_Vertical",
      "rotation": 1
    },
    {
      "x": -3,
      "y": 3,
      "z": 1,
      "name": "OrbisGalactic_Block_Imperial_Panel_Gray",
      "rotation": 1
    },
    {
      "x": -3,
      "y": 4,
      "z": 1,
      "name": "OrbisGalactic_Block_Imperial_Panel_Gray_Half",
      "rotation": 2
    },
    {
      "x": -3,
      "y": 11,
      "z": 1,
      "name": "OrbisGalactic_Block_Imperial_Panel_Black_Brick_Vertical",
      "rotation": 1
    },
    {
      "x": -3,
      "y": 2,
      "z": 2,
      "name": "OrbisGalactic_Block_Imperial_Panel_Gray",
      "rotation": 1
    },
    {
      "x": -3,
      "y": 3,
      "z": 2,
      "name": "OrbisGalactic_Block_Imperial_Panel_Gray_Half",
      "rotation": 2
    },
    {
      "x": -3,
      "y": 11,
      "z": 2,
      "name": "OrbisGalactic_Block_Imperial_Panel_Black_Brick_Vertical",
      "rotation": 1
    },
    {
      "x": -3,
      "y": 2,
      "z": 3,
      "name": "OrbisGalactic_Block_Imperial_Panel_Gray",
      "rotation": 1
    },
    {
      "x": -3,
      "y": 3,
      "z": 3,
      "name": "OrbisGalactic_Block_Imperial_Panel_Gray_Half",
      "rotation": 2
    },
    {
      "x": -3,
      "y": 11,
      "z": 3,
      "name": "OrbisGalactic_Block_Imperial_Panel_Black_Smooth",
      "rotation": 3
    },
    {
      "x": -3,
      "y": 2,
      "z": 4,
      "name": "OrbisGalactic_Block_Imperial_Panel_Gray",
      "rotation": 1
    },
    {
      "x": -3,
      "y": 3,
      "z": 4,
      "name": "OrbisGalactic_Block_Imperial_Panel_Gray_Smooth",
      "rotation": 1
    },
    {
      "x": -3,
      "y": 4,
      "z": 4,
      "name": "OrbisGalactic_Imperial_Railing_Gray",
      "support": 15,
      "rotation": 1
    },
    {
      "x": -3,
      "y": 10,
      "z": 4,
      "name": "OrbisGalactic_Block_Imperial_Panel_Black_Brick_Vertical",
      "rotation": 3
    },
    {
      "x": -3,
      "y": 2,
      "z": 5,
      "name": "OrbisGalactic_Block_Imperial_Panel_Gray",
      "rotation": 1
    },
    {
      "x": -3,
      "y": 3,
      "z": 5,
      "name": "OrbisGalactic_Block_Imperial_Panel_Gray_Brick_Horizontal",
      "rotation": 1
    },
    {
      "x": -3,
      "y": 4,
      "z": 5,
      "name": "OrbisGalactic_Imperial_Railing_Gray",
      "support": 15,
      "rotation": 1
    },
    {
      "x": -3,
      "y": 9,
      "z": 5,
      "name": "OrbisGalactic_Block_Imperial_Panel_Black_Smooth",
      "rotation": 3
    },
    {
      "x": -3,
      "y": 2,
      "z": 6,
      "name": "OrbisGalactic_Block_Imperial_Panel_Gray",
      "rotation": 1
    },
    {
      "x": -3,
      "y": 3,
      "z": 6,
      "name": "OrbisGalactic_Block_Imperial_Panel_Gray_Smooth",
      "rotation": 1
    },
    {
      "x": -3,
      "y": 4,
      "z": 6,
      "name": "OrbisGalactic_Imperial_Railing_Gray",
      "support": 15,
      "rotation": 1
    },
    {
      "x": -3,
      "y": 9,
      "z": 6,
      "name": "OrbisGalactic_Block_Imperial_Panel_Black_Brick_Vertical"
    },
    {
      "x": -3,
      "y": 3,
      "z": 7,
      "name": "OrbisGalactic_Block_Imperial_Panel_Gray_Brick_Vertical",
      "rotation": 3
    },
    {
      "x": -3,
      "y": 4,
      "z": 7,
