{
  "version": 8,
  "blockIdVersion": 11,
  "anchorX": 0,
  "anchorY": 0,
  "anchorZ": 0,
  "blocks": [
    {
      "x": -35,
      "y": 1,
      "z": 22,
      "name": "OrbisGalactic_Block_ShipHull",
      "rotation": 1
    },
    {
      "x": -35,
      "y": 2,
      "z": 22,
      "name": "OrbisGalactic_Block_ShipHull",
      "rotation": 1
    },
    {
      "x": -35,
      "y": 3,
      "z": 22,
      "name": "OrbisGalactic_Block_ShipHull",
      "rotation": 1
    },
    {
      "x": -35,
      "y": 4,
      "z": 22,
      "name": "OrbisGalactic_Block_ShipHull",
      "rotation": 1
    },
    {
      "x": -35,
      "y": 5,
      "z": 22,
      "name": "OrbisGalactic_Block_ShipHull",
      "rotation": 1
    },
    {
      "x": -35,
      "y": 6,
      "z": 22,
      "name": "OrbisGalactic_Block_ShipHull",
      "rotation": 1
    },
    {
      "x": -35,
      "y": 7,
      "z": 22,
      "name": "OrbisGalactic_Block_ShipHull",
      "rotation": 1
    },
    {
      "x": -35,
      "y": 1,
      "z": 23,
      "name": "OrbisGalactic_Block_ShipHull",
      "rotation": 1
    },
    {
      "x": -35,
      "y": 2,
      "z": 23,
      "name": "OrbisGalactic_Block_ShipHull",
      "rotation": 1
    },
    {
      "x": -35,
      "y": 3,
      "z": 23,
      "name": "OrbisGalactic_Block_ShipHull",
      "rotation": 1
    },
    {
      "x": -35,
      "y": 4,
      "z": 23,
      "name": "OrbisGalactic_Block_ShipHull",
      "rotation": 1
    },
    {
      "x": -35,
      "y": 5,
      "z": 23,
      "name": "OrbisGalactic_Block_ShipHull",
      "rotation": 1
    },
    {
      "x": -35,
      "y": 6,
      "z": 23,
      "name": "OrbisGalactic_Block_ShipHull",
      "rotation": 1
    },
    {
      "x": -35,
      "y": 7,
      "z": 23,
      "name": "OrbisGalactic_Block_ShipHull",
      "rotation": 1
    },
    {
      "x": -35,
      "y": 1,
      "z": 24,
      "name": "OrbisGalactic_Block_ShipHull",
      "rotation": 1
    },
    {
      "x": -35,
      "y": 2,
      "z": 24,
      "name": "OrbisGalactic_Block_ShipHull",
      "rotation": 1
    },
    {
      "x": -35,
      "y": 3,
      "z": 24,
      "name": "OrbisGalactic_Block_ShipHull",
      "rotation": 1
    },
    {
      "x": -35,
      "y": 4,
      "z": 24,
      "name": "OrbisGalactic_Block_ShipHull",
      "rotation": 1
    },
    {
      "x": -35,
      "y": 5,
      "z": 24,
      "name": "OrbisGalactic_Block_ShipHull",
      "rotation": 1
    },
    {
      "x": -35,
      "y": 6,
      "z": 24,
      "name": "OrbisGalactic_Block_ShipHull",
      "rotation": 1
    },
    {
      "x": -35,
      "y": 7,
      "z": 24,
      "name": "OrbisGalactic_Block_ShipHull",
      "rotation": 1
    },
    {
      "x": -35,
      "y": 0,
      "z": 25,
      "name": "OrbisGalactic_Block_ShipHull",
      "rotation": 1
    },
    {
      "x": -35,
      "y": 1,
      "z": 25,
      "name": "OrbisGalactic_Block_ShipHull",
      "rotation": 1
    },
    {
      "x": -35,
      "y": 2,
      "z": 25,
      "name": "OrbisGalactic_Block_ShipHull",
      "rotation": 1
    },
    {
      "x": -35,
      "y": 3,
      "z": 25,
      "name": "OrbisGalactic_Block_ShipHull",
      "rotation": 1
    },
    {
      "x": -35,
      "y": 4,
      "z": 25,
      "name": "OrbisGalactic_Block_ShipHull",
      "rotation": 1
    },
    {
      "x": -35,
      "y": 5,
      "z": 25,
      "name": "OrbisGalactic_Block_ShipHull",
      "rotation": 1
    },
    {
      "x": -35,
      "y": 6,
      "z": 25,
      "name": "OrbisGalactic_Block_ShipHull",
      "rotation": 1
    },
    {
      "x": -35,
      "y": 7,
      "z": 25,
      "name": "OrbisGalactic_Block_ShipHull",
      "rotation": 1
    },
    {
      "x": -35,
      "y": 0,
      "z": 26,
      "name": "OrbisGalactic_Block_ShipHull",
      "rotation": 1
    },
    {
      "x": -35,
      "y": 1,
      "z": 26,
      "name": "OrbisGalactic_Block_ShipHull",
      "rotation": 1
    },
    {
      "x": -35,
      "y": 6,
      "z": 26,
      "name": "OrbisGalactic_Block_ShipHull",
      "rotation": 1
    },
    {
      "x": -35,
      "y": 7,
      "z": 26,
      "name": "OrbisGalactic_Block_ShipHull",
      "rotation": 1
    },
    {
      "x": -35,
      "y": 0,
      "z": 27,
      "name": "OrbisGalactic_Block_ShipHull",
      "rotation": 1
    },
    {
      "x": -35,
      "y": 1,
      "z": 27,
      "name": "OrbisGalactic_Block_ShipHull",
      "rotation": 1
    },
    {
      "x": -35,
      "y": 6,
      "z": 27,
      "name": "OrbisGalactic_Block_ShipHull",
      "rotation": 1
    },
    {
      "x": -35,
      "y": 7,
      "z": 27,
      "name": "OrbisGalactic_Block_ShipHull",
      "rotation": 1
    },
    {
      "x": -35,
      "y": 0,
      "z": 28,
      "name": "OrbisGalactic_Block_ShipHull",
      "rotation": 1
    },
    {
      "x": -35,
      "y": 1,
      "z": 28,
      "name": "OrbisGalactic_Block_ShipHull",
      "rotation": 1
    },
    {
      "x": -35,
      "y": 6,
      "z": 28,
      "name": "OrbisGalactic_Block_ShipHull",
      "rotation": 1
    },
    {
      "x": -35,
      "y": 7,
      "z": 28,
      "name": "OrbisGalactic_Block_ShipHull",
      "rotation": 1
    },
    {
      "x": -35,
      "y": 0,
      "z": 29,
      "name": "OrbisGalactic_Block_ShipHull",
      "rotation": 1
    },
    {
      "x": -35,
      "y": 1,
      "z": 29,
      "name": "OrbisGalactic_Block_ShipHull",
      "rotation": 1
    },
    {
      "x": -35,
      "y": 2,
      "z": 29,
      "name": "OrbisGalactic_Block_ShipHull",
      "rotation": 1
    },
    {
      "x": -35,
      "y": 3,
      "z": 29,
      "name": "OrbisGalactic_Block_ShipHull",
      "rotation": 1
    },
    {
      "x": -35,
      "y": 4,
      "z": 29,
      "name": "OrbisGalactic_Block_ShipHull",
      "rotation": 1
    },
    {
      "x": -35,
      "y": 5,
      "z": 29,
      "name": "OrbisGalactic_Block_ShipHull",
      "rotation": 1
    },
    {
      "x": -35,
      "y": 6,
      "z": 29,
      "name": "OrbisGalactic_Block_ShipHull",
      "rotation": 1
    },
    {
      "x": -35,
      "y": 7,
      "z": 29,
      "name": "OrbisGalactic_Block_ShipHull",
      "rotation": 1
    },
    {
      "x": -35,
      "y": 0,
      "z": 30,
      "name": "OrbisGalactic_Block_ShipHull",
      "rotation": 1
    },
    {
      "x": -35,
      "y": 1,
      "z": 30,
      "name": "OrbisGalactic_Block_ShipHull",
      "rotation": 1
    },
    {
      "x": -35,
      "y": 6,
      "z": 30,
      "name": "OrbisGalactic_Block_ShipHull",
      "rotation": 1
    },
    {
      "x": -35,
      "y": 7,
      "z": 30,
      "name": "OrbisGalactic_Block_ShipHull",
      "rotation": 1
    },
    {
      "x": -35,
      "y": 0,
      "z": 31,
      "name": "OrbisGalactic_Block_ShipHull",
      "rotation": 1
    },
    {
      "x": -35,
      "y": 1,
      "z": 31,
      "name": "OrbisGalactic_Block_ShipHull",
      "rotation": 1
    },
    {
      "x": -35,
      "y": 6,
      "z": 31,
      "name": "OrbisGalactic_Block_ShipHull",
      "rotation": 1
    },
    {
      "x": -35,
      "y": 7,
      "z": 31,
      "name": "OrbisGalactic_Block_ShipHull",
      "rotation": 1
    },
    {
      "x": -35,
      "y": 0,
      "z": 32,
      "name": "OrbisGalactic_Block_ShipHull",
      "rotation": 1
    },
    {
      "x": -35,
      "y": 1,
      "z": 32,
      "name": "OrbisGalactic_Block_ShipHull",
      "rotation": 1
    },
    {
      "x": -35,
      "y": 6,
      "z": 32,
      "name": "OrbisGalactic_Block_ShipHull",
      "rotation": 1
    },
    {
      "x": -35,
      "y": 7,
      "z": 32,
      "name": "OrbisGalactic_Block_ShipHull",
      "rotation": 1
    },
    {
      "x": -35,
      "y": 0,
      "z": 33,
      "name": "OrbisGalactic_Block_ShipHull",
      "rotation": 1
    },
    {
      "x": -35,
      "y": 1,
      "z": 33,
      "name": "OrbisGalactic_Block_ShipHull",
      "rotation": 1
    },
    {
      "x": -35,
      "y": 2,
      "z": 33,
      "name": "OrbisGalactic_Block_ShipHull",
      "rotation": 1
    },
    {
      "x": -35,
      "y": 3,
      "z": 33,
      "name": "OrbisGalactic_Block_ShipHull",
      "rotation": 1
    },
    {
      "x": -35,
      "y": 4,
      "z": 33,
      "name": "OrbisGalactic_Block_ShipHull",
      "rotation": 1
    },
    {
      "x": -35,
      "y": 5,
      "z": 33,
      "name": "OrbisGalactic_Block_ShipHull",
      "rotation": 1
    },
    {
      "x": -35,
      "y": 6,
      "z": 33,
      "name": "OrbisGalactic_Block_ShipHull",
      "rotation": 1
    },
    {
      "x": -35,
      "y": 7,
      "z": 33,
      "name": "OrbisGalactic_Block_ShipHull",
      "rotation": 1
    },
    {
      "x": -35,
      "y": 0,
      "z": 39,
      "name": "OrbisGalactic_Block_ShipHull",
      "rotation": 1
    },
    {
      "x": -35,
      "y": 1,
      "z": 39,
      "name": "OrbisGalactic_Block_ShipHull",
      "rotation": 1
    },
    {
      "x": -35,
      "y": 2,
      "z": 39,
      "name": "OrbisGalactic_Block_ShipHull",
      "rotation": 1
    },
    {
      "x": -35,
      "y": 3,
      "z": 39,
      "name": "OrbisGalactic_Block_ShipHull",
      "rotation": 1
    },
    {
      "x": -35,
      "y": 4,
      "z": 39,
      "name": "OrbisGalactic_Block_ShipHull",
      "rotation": 1
    },
    {
      "x": -35,
      "y": 5,
      "z": 39,
      "name": "OrbisGalactic_Block_ShipHull",
      "rotation": 1
    },
    {
      "x": -35,
      "y": 6,
      "z": 39,
      "name": "OrbisGalactic_Block_ShipHull",
      "rotation": 1
    },
    {
      "x": -35,
      "y": 7,
      "z": 39,
      "name": "OrbisGalactic_Block_ShipHull",
      "rotation": 1
    },
    {
      "x": -35,
      "y": 0,
      "z": 40,
      "name": "OrbisGalactic_Block_ShipHull",
      "rotation": 1
    },
    {
      "x": -35,
      "y": 1,
      "z": 40,
      "name": "OrbisGalactic_Block_ShipHull",
      "rotation": 1
    },
    {
      "x": -35,
      "y": 2,
      "z": 40,
      "name": "OrbisGalactic_Block_ShipHull",
      "rotation": 1
    },
    {
      "x": -35,
      "y": 3,
      "z": 40,
      "name": "OrbisGalactic_Block_ShipHull",
      "rotation": 1
    },
    {
      "x": -35,
      "y": 4,
      "z": 40,
      "name": "OrbisGalactic_Block_ShipHull",
      "rotation": 1
    },
    {
      "x": -35,
      "y": 5,
      "z": 40,
      "name": "OrbisGalactic_Block_ShipHull",
      "rotation": 1
    },
    {
      "x": -35,
      "y": 6,
      "z": 40,
      "name": "OrbisGalactic_Block_ShipHull",
      "rotation": 1
    },
    {
      "x": -35,
      "y": 7,
      "z": 40,
      "name": "OrbisGalactic_Block_ShipHull",
      "rotation": 1
    },
    {
      "x": -35,
      "y": 0,
      "z": 41,
      "name": "OrbisGalactic_Block_ShipHull",
      "rotation": 1
    },
    {
      "x": -35,
      "y": 1,
      "z": 41,
      "name": "OrbisGalactic_Block_ShipHull",
      "rotation": 1
    },
    {
      "x": -35,
      "y": 2,
      "z": 41,
      "name": "OrbisGalactic_Block_Imperial_Ship_Window_Bottom_Right",
      "rotation": 1
    },
    {
      "x": -35,
      "y": 3,
      "z": 41,
      "name": "OrbisGalactic_Block_Imperial_Ship_Window_Right_Center",
      "rotation": 1
    },
    {
      "x": -35,
      "y": 4,
      "z": 41,
      "name": "OrbisGalactic_Block_Imperial_Ship_Window_Right_Center",
      "rotation": 1
    },
    {
      "x": -35,
      "y": 5,
      "z": 41,
      "name": "OrbisGalactic_Block_Imperial_Ship_Window_Top_Right",
      "rotation": 1
    },
    {
      "x": -35,
      "y": 6,
      "z": 41,
      "name": "OrbisGalactic_Block_ShipHull",
      "rotation": 1
    },
    {
      "x": -35,
      "y": 7,
      "z": 41,
      "name": "OrbisGalactic_Block_ShipHull",
      "rotation": 1
    },
    {
      "x": -35,
      "y": 0,
      "z": 42,
      "name": "OrbisGalactic_Block_ShipHull",
      "rotation": 1
    },
    {
      "x": -35,
      "y": 1,
      "z": 42,
      "name": "OrbisGalactic_Block_ShipHull",
      "rotation": 1
    },
    {
      "x": -35,
      "y": 2,
      "z": 42,
      "name": "OrbisGalactic_Block_Imperial_Ship_Window_Bottom_Center",
      "rotation": 1
    },
    {
      "x": -35,
      "y": 3,
      "z": 42,
      "name": "OrbisGalactic_Block_Imperial_Ship_Window_Center",
      "rotation": 1
    },
    {
      "x": -35,
      "y": 4,
      "z": 42,
      "name": "OrbisGalactic_Block_Imperial_Ship_Window_Center",
      "rotation": 1
    },
    {
      "x": -35,
      "y": 5,
      "z": 42,
      "name": "OrbisGalactic_Block_Imperial_Ship_Window_Top_Center",
      "rotation": 1
    },
    {
      "x": -35,
      "y": 6,
      "z": 42,
      "name": "OrbisGalactic_Block_ShipHull",
      "rotation": 1
    },
    {
      "x": -35,
      "y": 7,
      "z": 42,
      "name": "OrbisGalactic_Block_ShipHull",
      "rotation": 1
    },
    {
      "x": -35,
      "y": 0,
      "z": 43,
      "name": "OrbisGalactic_Block_ShipHull",
      "rotation": 1
    },
    {
      "x": -35,
      "y": 1,
      "z": 43,
      "name": "OrbisGalactic_Block_ShipHull",
      "rotation": 1
    },
    {
      "x": -35,
      "y": 2,
      "z": 43,
      "name": "OrbisGalactic_Block_Imperial_Ship_Window_Bottom_Center",
      "rotation": 1
    },
    {
      "x": -35,
      "y": 3,
      "z": 43,
      "name": "OrbisGalactic_Block_Imperial_Ship_Window_Center",
      "rotation": 1
    },
    {
      "x": -35,
      "y": 4,
      "z": 43,
      "name": "OrbisGalactic_Block_Imperial_Ship_Window_Center",
      "rotation": 1
    },
    {
      "x": -35,
      "y": 5,
      "z": 43,
      "name": "OrbisGalactic_Block_Imperial_Ship_Window_Top_Center",
      "rotation": 1
    },
    {
      "x": -35,
      "y": 6,
      "z": 43,
      "name": "OrbisGalactic_Block_ShipHull",
      "rotation": 1
    },
    {
      "x": -35,
      "y": 7,
      "z": 43,
      "name": "OrbisGalactic_Block_ShipHull",
      "rotation": 1
    },
    {
      "x": -35,
      "y": 0,
      "z": 44,
      "name": "OrbisGalactic_Block_ShipHull",
      "rotation": 1
    },
    {
      "x": -35,
      "y": 1,
      "z": 44,
      "name": "OrbisGalactic_Block_ShipHull",
      "rotation": 1
    },
    {
      "x": -35,
      "y": 2,
      "z": 44,
      "name": "OrbisGalactic_Block_Imperial_Ship_Window_Bottom_Center",
      "rotation": 1
    },
    {
      "x": -35,
      "y": 3,
      "z": 44,
      "name": "OrbisGalactic_Block_Imperial_Ship_Window_Center",
      "rotation": 1
    },
    {
      "x": -35,
      "y": 4,
      "z": 44,
      "name": "OrbisGalactic_Block_Imperial_Ship_Window_Center",
      "rotation": 1
    },
    {
      "x": -35,
      "y": 5,
      "z": 44,
      "name": "OrbisGalactic_Block_Imperial_Ship_Window_Top_Center",
      "rotation": 1
    },
    {
      "x": -35,
      "y": 6,
      "z": 44,
      "name": "OrbisGalactic_Block_ShipHull",
      "rotation": 1
    },
    {
      "x": -35,
      "y": 7,
      "z": 44,
      "name": "OrbisGalactic_Block_ShipHull",
      "rotation": 1
    },
    {
      "x": -35,
      "y": 0,
      "z": 45,
      "name": "OrbisGalactic_Block_ShipHull",
      "rotation": 1
    },
    {
      "x": -35,
      "y": 1,
      "z": 45,
      "name": "OrbisGalactic_Block_ShipHull",
      "rotation": 1
    },
    {
      "x": -35,
      "y": 2,
      "z": 45,
      "name": "OrbisGalactic_Block_Imperial_Ship_Window_Bottom_Left",
      "rotation": 1
    },
    {
      "x": -35,
      "y": 3,
      "z": 45,
      "name": "OrbisGalactic_Block_Imperial_Ship_Window_Left_Center",
      "rotation": 1
    },
    {
      "x": -35,
      "y": 4,
      "z": 45,
      "name": "OrbisGalactic_Block_Imperial_Ship_Window_Left_Center",
      "rotation": 1
    },
    {
      "x": -35,
      "y": 5,
      "z": 45,
      "name": "OrbisGalactic_Block_Imperial_Ship_Window_Top_Left",
      "rotation": 1
    },
    {
      "x": -35,
      "y": 6,
      "z": 45,
      "name": "OrbisGalactic_Block_ShipHull",
      "rotation": 1
    },
    {
      "x": -35,
      "y": 7,
      "z": 45,
      "name": "OrbisGalactic_Block_ShipHull",
      "rotation": 1
    },
    {
      "x": -35,
      "y": 0,
      "z": 46,
      "name": "OrbisGalactic_Block_ShipHull",
      "rotation": 1
    },
    {
      "x": -35,
      "y": 1,
      "z": 46,
      "name": "OrbisGalactic_Block_ShipHull",
      "rotation": 1
    },
    {
      "x": -35,
      "y": 2,
      "z": 46,
      "name": "OrbisGalactic_Block_ShipHull",
      "rotation": 1
    },
    {
      "x": -35,
      "y": 3,
      "z": 46,
      "name": "OrbisGalactic_Block_ShipHull",
      "rotation": 1
    },
    {
      "x": -35,
      "y": 4,
      "z": 46,
      "name": "OrbisGalactic_Block_ShipHull",
      "rotation": 1
    },
    {
      "x": -35,
      "y": 5,
      "z": 46,
      "name": "OrbisGalactic_Block_ShipHull",
      "rotation": 1
    },
    {
      "x": -35,
      "y": 6,
      "z": 46,
      "name": "OrbisGalactic_Block_ShipHull",
      "rotation": 1
    },
    {
      "x": -35,
      "y": 7,
      "z": 46,
      "name": "OrbisGalactic_Block_ShipHull",
      "rotation": 1
    },
    {
      "x": -35,
      "y": 0,
      "z": 47,
      "name": "OrbisGalactic_Block_ShipHull",
      "rotation": 1
    },
    {
      "x": -35,
      "y": 1,
      "z": 47,
      "name": "OrbisGalactic_Block_ShipHull",
      "rotation": 1
    },
    {
      "x": -35,
      "y": 1,
      "z": 48,
      "name": "OrbisGalactic_Block_ShipHull",
      "rotation": 1
    },
    {
      "x": -34,
      "y": 2,
      "z": 15,
      "name": "OrbisGalactic_Block_ShipHull",
      "rotation": 1
    },
    {
      "x": -34,
      "y": 3,
      "z": 15,
      "name": "OrbisGalactic_Block_ShipHull",
      "rotation": 1
    },
    {
      "x": -34,
      "y": 4,
      "z": 15,
      "name": "OrbisGalactic_Block_ShipHull",
      "rotation": 1
    },
    {
      "x": -34,
      "y": 5,
      "z": 15,
      "name": "OrbisGalactic_Block_ShipHull",
      "rotation": 1
    },
    {
      "x": -34,
      "y": 2,
      "z": 16,
      "name": "OrbisGalactic_Block_ShipHull",
      "rotation": 1
    },
    {
      "x": -34,
      "y": 3,
      "z": 16,
      "name": "OrbisGalactic_Block_ShipHull",
      "rotation": 1
    },
    {
      "x": -34,
      "y": 4,
      "z": 16,
      "name": "OrbisGalactic_Block_ShipHull",
      "rotation": 1
    },
    {
      "x": -34,
      "y": 5,
      "z": 16,
      "name": "OrbisGalactic_Block_ShipHull",
      "rotation": 1
    },
    {
      "x": -34,
      "y": 2,
      "z": 17,
      "name": "OrbisGalactic_Block_ShipHull",
      "rotation": 1
    },
    {
      "x": -34,
      "y": 3,
      "z": 17,
      "name": "OrbisGalactic_Block_ShipHull",
      "rotation": 1
    },
    {
      "x": -34,
      "y": 4,
      "z": 17,
      "name": "OrbisGalactic_Block_ShipHull",
      "rotation": 1
    },
    {
      "x": -34,
      "y": 5,
      "z": 17,
      "name": "OrbisGalactic_Block_ShipHull",
      "rotation": 1
    },
    {
      "x": -34,
      "y": 0,
      "z": 21,
      "name": "OrbisGalactic_Block_ShipHull",
      "rotation": 1
    },
    {
      "x": -34,
      "y": 1,
      "z": 21,
      "name": "OrbisGalactic_Block_ShipHull",
      "rotation": 1
    },
    {
      "x": -34,
      "y": 2,
      "z": 21,
      "name": "OrbisGalactic_Block_ShipHull",
      "rotation": 1
    },
    {
      "x": -34,
      "y": 3,
      "z": 21,
      "name": "OrbisGalactic_Block_ShipHull",
      "rotation": 1
    },
    {
      "x": -34,
      "y": 4,
      "z": 21,
      "name": "OrbisGalactic_Block_ShipHull",
      "rotation": 1
    },
    {
      "x": -34,
      "y": 5,
      "z": 21,
      "name": "OrbisGalactic_Block_ShipHull",
      "rotation": 1
    },
    {
      "x": -34,
      "y": 6,
      "z": 21,
      "name": "OrbisGalactic_Block_ShipHull",
      "rotation": 1
    },
    {
      "x": -34,
      "y": 7,
      "z": 21,
      "name": "OrbisGalactic_Block_ShipHull",
      "rotation": 1
    },
    {
      "x": -34,
      "y": 0,
      "z": 22,
      "name": "OrbisGalactic_Block_ShipHull",
      "rotation": 1
    },
    {
      "x": -34,
      "y": 1,
      "z": 22,
      "name": "OrbisGalactic_Block_Imperial_Panel_Gray_Brick_Vertical"
    },
    {
      "x": -34,
      "y": 2,
      "z": 22,
      "name": "OrbisGalactic_Block_Imperial_Panel_Light_Gray_Brick_Vertical",
      "rotation": 1
    },
    {
      "x": -34,
      "y": 3,
      "z": 22,
      "name": "OrbisGalactic_Block_Imperial_Panel_Light_Gray_Brick_Vertical",
      "rotation": 1
    },
    {
      "x": -34,
      "y": 4,
      "z": 22,
      "name": "OrbisGalactic_Block_Imperial_Panel_Light_Gray_Brick_Vertical",
      "rotation": 1
    },
    {
      "x": -34,
      "y": 5,
      "z": 22,
      "name": "OrbisGalactic_Block_Imperial_Panel_Light_Gray_Brick_Vertical",
      "rotation": 1
    },
    {
      "x": -34,
      "y": 6,
      "z": 22,
      "name": "OrbisGalactic_Block_Imperial_Panel_Black_Brick_Horizontal",
      "rotation": 1
    },
    {
      "x": -34,
      "y": 7,
      "z": 22,
      "name": "OrbisGalactic_Block_ShipHull",
      "rotation": 1
    },
    {
      "x": -34,
      "y": 0,
      "z": 23,
      "name": "OrbisGalactic_Block_ShipHull",
      "rotation": 1
    },
    {
      "x": -34,
      "y": 1,
      "z": 23,
      "name": "OrbisGalactic_Block_Imperial_Panel_Gray_Brick_Vertical"
    },
    {
      "x": -34,
      "y": 2,
      "z": 23,
      "name": "OrbisGalactic_Block_Imperial_Panel_White_Brick_Vertical",
      "rotation": 1
    },
    {
      "x": -34,
      "y": 3,
      "z": 23,
      "name": "OrbisGalactic_Block_Imperial_Panel_White_Brick_Vertical",
      "rotation": 1
    },
    {
      "x": -34,
      "y": 4,
      "z": 23,
      "name": "OrbisGalactic_Block_Imperial_Panel_White_Brick_Vertical",
      "rotation": 1
    },
    {
      "x": -34,
      "y": 5,
      "z": 23,
      "name": "OrbisGalactic_Block_Imperial_Panel_White_Brick_Vertical",
      "rotation": 1
    },
    {
      "x": -34,
      "y": 6,
      "z": 23,
      "name": "OrbisGalactic_Block_Imperial_Panel_Black_Brick_Horizontal",
      "rotation": 1
    },
    {
      "x": -34,
      "y": 7,
      "z": 23,
      "name": "OrbisGalactic_Block_ShipHull",
      "rotation": 1
    },
    {
      "x": -34,
      "y": 0,
      "z": 24,
      "name": "OrbisGalactic_Block_ShipHull",
      "rotation": 1
    },
    {
      "x": -34,
      "y": 1,
      "z": 24,
      "name": "OrbisGalactic_Block_Imperial_Panel_Gray_Brick_Vertical"
    },
    {
      "x": -34,
      "y": 2,
      "z": 24,
      "name": "OrbisGalactic_Block_Imperial_Panel_Light_Gray_Brick_Vertical",
      "rotation": 1
    },
    {
      "x": -34,
      "y": 3,
      "z": 24,
      "name": "OrbisGalactic_Block_Imperial_Panel_Light_Gray_Brick_Vertical",
      "rotation": 1
    },
    {
      "x": -34,
      "y": 4,
      "z": 24,
      "name": "OrbisGalactic_Block_Imperial_Panel_Light_Gray_Brick_Vertical",
      "rotation": 1
    },
    {
      "x": -34,
      "y": 5,
      "z": 24,
      "name": "OrbisGalactic_Block_Imperial_Panel_Light_Gray_Brick_Vertical",
      "rotation": 1
    },
    {
      "x": -34,
      "y": 6,
      "z": 24,
      "name": "OrbisGalactic_Block_Imperial_Panel_Black_Brick_Horizontal",
      "rotation": 1
    },
    {
      "x": -34,
      "y": 7,
      "z": 24,
      "name": "OrbisGalactic_Block_ShipHull",
      "rotation": 1
    },
    {
      "x": -34,
      "y": 0,
      "z": 25,
      "name": "OrbisGalactic_Block_ShipHull",
      "rotation": 1
    },
    {
      "x": -34,
      "y": 1,
      "z": 25,
      "name": "OrbisGalactic_Block_Imperial_Panel_Black_Brick_Horizontal",
      "rotation": 3
    },
    {
      "x": -34,
      "y": 2,
      "z": 25,
      "name": "*OrbisGalactic_Block_Imperial_Lamp3_Connected_State_Definitions_On",
      "rotation": 1
    },
    {
      "x": -34,
      "y": 3,
      "z": 25,
      "name": "*OrbisGalactic_Block_Imperial_Lamp3_Connected_State_Definitions_On",
      "rotation": 1
    },
    {
      "x": -34,
      "y": 4,
      "z": 25,
      "name": "*OrbisGalactic_Block_Imperial_Lamp3_Connected_State_Definitions_On",
      "rotation": 1
    },
    {
      "x": -34,
      "y": 5,
      "z": 25,
      "name": "*OrbisGalactic_Block_Imperial_Lamp2_State_Definitions_On",
      "rotation": 1
    },
    {
      "x": -34,
      "y": 6,
      "z": 25,
      "name": "OrbisGalactic_Block_Imperial_Panel_Black_Smooth",
      "rotation": 1
    },
    {
      "x": -34,
      "y": 7,
      "z": 25,
      "name": "OrbisGalactic_Block_ShipHull",
      "rotation": 1
    },
    {
      "x": -34,
      "y": 0,
      "z": 26,
      "name": "OrbisGalactic_Block_ShipHull",
      "rotation": 1
    },
    {
      "x": -34,
      "y": 1,
      "z": 26,
      "name": "OrbisGalactic_Block_Imperial_Panel_Black_Brick_Horizontal",
      "rotation": 3
    },
    {
      "x": -34,
      "y": 2,
      "z": 26,
      "name": "OrbisGalactic_Block_Imperial_Ship_Window_Bottom_Right",
      "rotation": 1
    },
    {
      "x": -34,
      "y": 3,
      "z": 26,
      "name": "OrbisGalactic_Block_Imperial_Ship_Window_Right_Center",
      "rotation": 1
    },
    {
      "x": -34,
      "y": 4,
      "z": 26,
      "name": "OrbisGalactic_Block_Imperial_Ship_Window_Right_Center",
      "rotation": 1
    },
    {
      "x": -34,
      "y": 5,
      "z": 26,
      "name": "OrbisGalactic_Block_Imperial_Ship_Window_Top_Right",
      "rotation": 1
    },
    {
      "x": -34,
      "y": 6,
      "z": 26,
      "name": "OrbisGalactic_Block_Imperial_Panel_Black_Brick_Horizontal",
      "rotation": 1
    },
    {
      "x": -34,
      "y": 7,
      "z": 26,
      "name": "OrbisGalactic_Block_ShipHull",
      "rotation": 1
    },
    {
      "x": -34,
      "y": 0,
      "z": 27,
      "name": "OrbisGalactic_Block_ShipHull",
      "rotation": 1
    },
    {
      "x": -34,
      "y": 1,
      "z": 27,
      "name": "OrbisGalactic_Block_Imperial_Panel_Black_Brick_Horizontal",
      "rotation": 3
    },
    {
      "x": -34,
      "y": 2,
      "z": 27,
      "name": "OrbisGalactic_Block_Imperial_Ship_Window_Bottom_Center",
      "rotation": 1
    },
    {
      "x": -34,
      "y": 3,
      "z": 27,
      "name": "OrbisGalactic_Block_Imperial_Ship_Window_Center",
      "rotation": 1
    },
    {
      "x": -34,
      "y": 4,
      "z": 27,
      "name": "OrbisGalactic_Block_Imperial_Ship_Window_Center",
      "rotation": 1
    },
    {
      "x": -34,
      "y": 5,
      "z": 27,
      "name": "OrbisGalactic_Block_Imperial_Ship_Window_Top_Center",
      "rotation": 1
    },
    {
      "x": -34,
      "y": 6,
      "z": 27,
      "name": "OrbisGalactic_Block_Imperial_Panel_Black_Brick_Horizontal",
      "rotation": 1
    },
    {
      "x": -34,
      "y": 7,
      "z": 27,
      "name": "OrbisGalactic_Block_ShipHull",
      "rotation": 1
    },
    {
      "x": -34,
      "y": 0,
      "z": 28,
      "name": "OrbisGalactic_Block_ShipHull",
      "rotation": 1
    },
    {
      "x": -34,
      "y": 1,
      "z": 28,
      "name": "OrbisGalactic_Block_Imperial_Panel_Black_Brick_Horizontal",
      "rotation": 3
    },
    {
      "x": -34,
      "y": 2,
      "z": 28,
      "name": "OrbisGalactic_Block_Imperial_Ship_Window_Bottom_Left",
      "rotation": 1
    },
    {
      "x": -34,
      "y": 3,
      "z": 28,
      "name": "OrbisGalactic_Block_Imperial_Ship_Window_Left_Center",
      "rotation": 1
    },
    {
      "x": -34,
      "y": 4,
      "z": 28,
      "name": "OrbisGalactic_Block_Imperial_Ship_Window_Left_Center",
      "rotation": 1
    },
    {
      "x": -34,
      "y": 5,
      "z": 28,
      "name": "OrbisGalactic_Block_Imperial_Ship_Window_Top_Left",
      "rotation": 1
    },
    {
      "x": -34,
      "y": 6,
      "z": 28,
      "name": "OrbisGalactic_Block_Imperial_Panel_Black_Brick_Horizontal",
      "rotation": 1
    },
    {
      "x": -34,
      "y": 7,
      "z": 28,
      "name": "OrbisGalactic_Block_ShipHull",
      "rotation": 1
    },
    {
      "x": -34,
      "y": 0,
      "z": 29,
      "name": "OrbisGalactic_Block_ShipHull",
      "rotation": 1
    },
    {
      "x": -34,
      "y": 1,
      "z": 29,
      "name": "OrbisGalactic_Block_Imperial_Panel_Black_Brick_Horizontal",
      "rotation": 3
    },
    {
      "x": -34,
      "y": 2,
      "z": 29,
      "name": "*OrbisGalactic_Block_Imperial_Lamp2_State_Definitions_On",
      "rotation": 1
    },
    {
      "x": -34,
      "y": 3,
      "z": 29,
      "name": "*OrbisGalactic_Block_Imperial_Lamp3_Connected_State_Definitions_On",
      "rotation": 1
    },
    {
      "x": -34,
      "y": 4,
      "z": 29,
      "name": "*OrbisGalactic_Block_Imperial_Lamp3_Connected_State_Definitions_On",
      "rotation": 1
    },
    {
      "x": -34,
      "y": 5,
      "z": 29,
      "name": "*OrbisGalactic_Block_Imperial_Lamp2_State_Definitions_On",
      "rotation": 1
    },
    {
      "x": -34,
      "y": 6,
      "z": 29,
      "name": "OrbisGalactic_Block_Imperial_Panel_Black_Smooth",
      "rotation": 1
    },
    {
      "x": -34,
      "y": 7,
      "z": 29,
      "name": "OrbisGalactic_Block_ShipHull",
      "rotation": 1
    },
    {
      "x": -34,
      "y": 0,
      "z": 30,
      "name": "OrbisGalactic_Block_ShipHull",
      "rotation": 1
    },
    {
      "x": -34,
      "y": 1,
      "z": 30,
      "name": "OrbisGalactic_Block_Imperial_Panel_Black_Brick_Horizontal",
      "rotation": 3
    },
    {
      "x": -34,
      "y": 2,
      "z": 30,
      "name": "OrbisGalactic_Block_Imperial_Ship_Window_Bottom_Right",
      "rotation": 1
    },
    {
      "x": -34,
      "y": 3,
      "z": 30,
      "name": "OrbisGalactic_Block_Imperial_Ship_Window_Right_Center",
      "rotation": 1
    },
    {
      "x": -34,
      "y": 4,
      "z": 30,
      "name": "OrbisGalactic_Block_Imperial_Ship_Window_Right_Center",
      "rotation": 1
    },
    {
      "x": -34,
      "y": 5,
      "z": 30,
      "name": "OrbisGalactic_Block_Imperial_Ship_Window_Top_Right",
      "rotation": 1
    },
    {
      "x": -34,
      "y": 6,
      "z": 30,
      "name": "OrbisGalactic_Block_Imperial_Panel_Black_Brick_Horizontal",
      "rotation": 1
    },
    {
      "x": -34,
      "y": 7,
      "z": 30,
      "name": "OrbisGalactic_Block_ShipHull",
      "rotation": 1
    },
    {
      "x": -34,
      "y": 0,
      "z": 31,
      "name": "OrbisGalactic_Block_ShipHull",
      "rotation": 1
    },
    {
      "x": -34,
      "y": 1,
      "z": 31,
      "name": "OrbisGalactic_Block_Imperial_Panel_Black_Brick_Horizontal",
      "rotation": 3
    },
    {
      "x": -34,
      "y": 2,
      "z": 31,
      "name": "OrbisGalactic_Block_Imperial_Ship_Window_Bottom_Center",
      "rotation": 1
    },
    {
      "x": -34,
      "y": 3,
      "z": 31,
      "name": "OrbisGalactic_Block_Imperial_Ship_Window_Center",
      "rotation": 1
    },
    {
      "x": -34,
      "y": 4,
      "z": 31,
      "name": "OrbisGalactic_Block_Imperial_Ship_Window_Center",
      "rotation": 1
    },
    {
      "x": -34,
      "y": 5,
      "z": 31,
      "name": "OrbisGalactic_Block_Imperial_Ship_Window_Top_Center",
      "rotation": 1
    },
    {
      "x": -34,
      "y": 6,
      "z": 31,
      "name": "OrbisGalactic_Block_Imperial_Panel_Black_Brick_Horizontal",
      "rotation": 1
    },
    {
      "x": -34,
      "y": 7,
      "z": 31,
      "name": "OrbisGalactic_Block_ShipHull",
      "rotation": 1
    },
    {
      "x": -34,
      "y": 0,
      "z": 32,
      "name": "OrbisGalactic_Block_ShipHull",
      "rotation": 1
    },
    {
      "x": -34,
      "y": 1,
      "z": 32,
      "name": "OrbisGalactic_Block_Imperial_Panel_Black_Brick_Horizontal",
      "rotation": 3
    },
    {
      "x": -34,
      "y": 2,
      "z": 32,
      "name": "OrbisGalactic_Block_Imperial_Ship_Window_Bottom_Left",
      "rotation": 1
    },
    {
      "x": -34,
      "y": 3,
      "z": 32,
      "name": "OrbisGalactic_Block_Imperial_Ship_Window_Left_Center",
      "rotation": 1
    },
    {
      "x": -34,
      "y": 4,
      "z": 32,
      "name": "OrbisGalactic_Block_Imperial_Ship_Window_Left_Center",
      "rotation": 1
    },
    {
      "x": -34,
      "y": 5,
      "z": 32,
      "name": "OrbisGalactic_Block_Imperial_Ship_Window_Top_Left",
      "rotation": 1
    },
    {
      "x": -34,
      "y": 6,
      "z": 32,
      "name": "OrbisGalactic_Block_Imperial_Panel_Black_Brick_Horizontal",
      "rotation": 1
    },
    {
      "x": -34,
      "y": 7,
      "z": 32,
      "name": "OrbisGalactic_Block_ShipHull",
      "rotation": 1
    },
    {
      "x": -34,
      "y": 0,
      "z": 33,
      "name": "OrbisGalactic_Block_ShipHull",
      "rotation": 1
    },
    {
      "x": -34,
      "y": 1,
      "z": 33,
      "name": "OrbisGalactic_Block_Imperial_Panel_Black_Brick_Vertical",
      "rotation": 3
    },
    {
      "x": -34,
      "y": 2,
      "z": 33,
      "name": "OrbisGalactic_Block_Imperial_Panel_Black_Brick_Vertical",
      "rotation": 3
    },
    {
      "x": -34,
      "y": 3,
      "z": 33,
      "name": "OrbisGalactic_Block_Imperial_Panel_Black_Brick_Vertical",
      "rotation": 3
    },
    {
      "x": -34,
      "y": 4,
      "z": 33,
      "name": "OrbisGalactic_Block_Imperial_Panel_Black_Brick_Vertical",
      "rotation": 3
    },
    {
      "x": -34,
      "y": 5,
      "z": 33,
      "name": "OrbisGalactic_Block_Imperial_Panel_Black_Brick_Vertical",
      "rotation": 3
    },
    {
      "x": -34,
      "y": 6,
      "z": 33,
      "name": "OrbisGalactic_Block_Imperial_Panel_Black_Brick_Vertical",
      "rotation": 3
    },
    {
      "x": -34,
      "y": 7,
      "z": 33,
      "name": "OrbisGalactic_Block_ShipHull",
      "rotation": 1
    },
    {
      "x": -34,
      "y": 0,
      "z": 34,
      "name": "OrbisGalactic_Block_ShipHull",
      "rotation": 1
    },
    {
      "x": -34,
      "y": 1,
      "z": 34,
      "name": "OrbisGalactic_Block_ShipHull",
      "rotation": 1
    },
    {
      "x": -34,
      "y": 2,
      "z": 34,
      "name": "OrbisGalactic_Block_ShipHull",
      "rotation": 1
    },
    {
      "x": -34,
      "y": 3,
      "z": 34,
      "name": "OrbisGalactic_Block_ShipHull",
      "rotation": 1
    },
    {
      "x": -34,
      "y": 4,
      "z": 34,
      "name": "OrbisGalactic_Block_ShipHull",
      "rotation": 1
    },
    {
      "x": -34,
      "y": 5,
      "z": 34,
      "name": "OrbisGalactic_Block_ShipHull",
      "rotation": 1
    },
    {
      "x": -34,
      "y": 6,
      "z": 34,
      "name": "OrbisGalactic_Block_ShipHull",
      "rotation": 1
    },
    {
      "x": -34,
      "y": 7,
      "z": 34,
      "name": "OrbisGalactic_Block_ShipHull",
      "rotation": 1
    },
    {
      "x": -34,
      "y": 0,
      "z": 35,
      "name": "OrbisGalactic_Block_ShipHull",
      "rotation": 1
    },
    {
      "x": -34,
      "y": 1,
      "z": 35,
      "name": "OrbisGalactic_Block_ShipHull",
      "rotation": 1
    },
    {
      "x": -34,
      "y": 6,
      "z": 35,
      "name": "OrbisGalactic_Block_ShipHull",
      "rotation": 1
    },
    {
      "x": -34,
      "y": 7,
      "z": 35,
      "name": "OrbisGalactic_Block_ShipHull",
      "rotation": 1
    },
    {
      "x": -34,
      "y": 0,
      "z": 36,
      "name": "OrbisGalactic_Block_ShipHull",
      "rotation": 1
    },
    {
      "x": -34,
      "y": 1,
      "z": 36,
      "name": "OrbisGalactic_Block_ShipHull",
      "rotation": 1
    },
    {
      "x": -34,
      "y": 6,
      "z": 36,
      "name": "OrbisGalactic_Block_ShipHull",
      "rotation": 1
    },
    {
      "x": -34,
      "y": 7,
      "z": 36,
      "name": "OrbisGalactic_Block_ShipHull",
      "rotation": 1
    },
    {
      "x": -34,
      "y": 0,
      "z": 37,
      "name": "OrbisGalactic_Block_ShipHull",
      "rotation": 1
    },
    {
      "x": -34,
      "y": 1,
      "z": 37,
      "name": "OrbisGalactic_Block_ShipHull",
      "rotation": 1
    },
    {
      "x": -34,
      "y": 6,
      "z": 37,
      "name": "OrbisGalactic_Block_ShipHull",
      "rotation": 1
    },
    {
      "x": -34,
      "y": 7,
      "z": 37,
      "name": "OrbisGalactic_Block_ShipHull",
      "rotation": 1
    },
    {
      "x": -34,
      "y": -1,
      "z": 38,
      "name": "OrbisGalactic_Block_ShipHull",
      "rotation": 1
    },
    {
      "x": -34,
      "y": 0,
      "z": 38,
      "name": "OrbisGalactic_Block_ShipHull",
      "rotation": 1
    },
    {
      "x": -34,
      "y": 1,
      "z": 38,
      "name": "OrbisGalactic_Block_ShipHull",
      "rotation": 1
    },
    {
      "x": -34,
      "y": 2,
      "z": 38,
      "name": "OrbisGalactic_Block_ShipHull",
      "rotation": 1
    },
    {
      "x": -34,
      "y": 3,
      "z": 38,
      "name": "OrbisGalactic_Block_ShipHull",
      "rotation": 1
    },
    {
      "x": -34,
      "y": 4,
      "z": 38,
      "name": "OrbisGalactic_Block_ShipHull",
      "rotation": 1
    },
    {
      "x": -34,
      "y": 5,
      "z": 38,
      "name": "OrbisGalactic_Block_ShipHull",
      "rotation": 1
    },
    {
      "x": -34,
      "y": 6,
      "z": 38,
      "name": "OrbisGalactic_Block_ShipHull",
      "rotation": 1
    },
    {
      "x": -34,
      "y": 7,
      "z": 38,
      "name": "OrbisGalactic_Block_ShipHull",
      "rotation": 1
    },
    {
      "x": -34,
      "y": -1,
      "z": 39,
      "name": "OrbisGalactic_Block_ShipHull",
      "rotation": 1
    },
    {
      "x": -34,
      "y": 0,
      "z": 39,
      "name": "OrbisGalactic_Block_ShipHull",
      "rotation": 1
    },
    {
      "x": -34,
      "y": 1,
      "z": 39,
      "name": "OrbisGalactic_Block_Imperial_Panel_Gray_Brick_Vertical",
      "rotation": 2
    },
    {
      "x": -34,
      "y": 2,
      "z": 39,
      "name": "*OrbisGalactic_Block_Imperial_Lamp3_Connected_State_Definitions_On",
      "rotation": 1
    },
    {
      "x": -34,
      "y": 3,
      "z": 39,
      "name": "*OrbisGalactic_Block_Imperial_Lamp3_Connected_State_Definitions_On",
      "rotation": 1
    },
    {
      "x": -34,
      "y": 4,
      "z": 39,
      "name": "*OrbisGalactic_Block_Imperial_Lamp3_Connected_State_Definitions_On",
      "rotation": 1
    },
    {
      "x": -34,
      "y": 5,
      "z": 39,
      "name": "*OrbisGalactic_Block_Imperial_Lamp3_Connected_State_Definitions_On",
      "rotation": 1
    },
    {
      "x": -34,
      "y": 6,
      "z": 39,
      "name": "*OrbisGalactic_Block_Imperial_Lamp3_Connected_State_Definitions_On",
      "rotation": 1
    },
    {
      "x": -34,
      "y": 7,
      "z": 39,
      "name": "OrbisGalactic_Block_Imperial_Panel_Black_Smooth",
      "rotation": 3
    },
    {
      "x": -34,
      "y": 8,
      "z": 39,
      "name": "OrbisGalactic_Block_ShipHull",
      "rotation": 1
    },
    {
      "x": -34,
      "y": -1,
      "z": 40,
      "name": "OrbisGalactic_Block_ShipHull",
      "rotation": 1
    },
    {
      "x": -34,
      "y": 0,
      "z": 40,
      "name": "OrbisGalactic_Block_ShipHull",
      "rotation": 1
    },
    {
      "x": -34,
      "y": 1,
      "z": 40,
      "name": "*OrbisGalactic_Block_Imperial_Lamp1_State_Definitions_On",
      "rotation": 2
    },
    {
      "x": -34,
      "y": 2,
      "z": 40,
      "name": "OrbisGalactic_Imperial_Railing_Gray",
      "support": 15,
      "rotation": 3
    },
    {
      "x": -34,
      "y": 7,
      "z": 40,
      "name": "OrbisGalactic_Block_Imperial_Panel_Black_Brick_Vertical"
    },
    {
      "x": -34,
      "y": 8,
      "z": 40,
      "name": "OrbisGalactic_Block_ShipHull",
      "rotation": 1
    },
    {
      "x": -34,
      "y": -1,
      "z": 41,
      "name": "OrbisGalactic_Block_ShipHull",
      "rotation": 1
    },
    {
      "x": -34,
      "y": 0,
      "z": 41,
      "name": "OrbisGalactic_Block_ShipHull",
      "rotation": 1
    },
    {
      "x": -34,
      "y": 1,
      "z": 41,
      "name": "OrbisGalactic_Block_Imperial_Panel_Gray_Brick_Vertical",
      "rotation": 2
    },
    {
      "x": -34,
      "y": 2,
      "z": 41,
      "name": "OrbisGalactic_Imperial_Railing_Gray",
      "support": 15,
      "rotation": 3
    },
    {
      "x": -34,
      "y": 7,
      "z": 41,
      "name": "OrbisGalactic_Block_Imperial_Panel_Black_Brick_Vertical"
    },
    {
      "x": -34,
      "y": 8,
      "z": 41,
      "name": "OrbisGalactic_Block_ShipHull",
      "rotation": 1
    },
    {
      "x": -34,
      "y": -1,
      "z": 42,
      "name": "OrbisGalactic_Block_ShipHull",
      "rotation": 1
    },
    {
      "x": -34,
      "y": 0,
      "z": 42,
      "name": "OrbisGalactic_Block_ShipHull",
      "rotation": 1
    },
    {
      "x": -34,
      "y": 1,
      "z": 42,
      "name": "OrbisGalactic_Block_Imperial_Panel_Gray_Brick_Vertical",
      "rotation": 2
    },
    {
      "x": -34,
      "y": 2,
      "z": 42,
      "name": "OrbisGalactic_Imperial_Railing_Gray",
      "support": 15,
      "rotation": 3
    },
    {
      "x": -34,
      "y": 7,
      "z": 42,
      "name": "OrbisGalactic_Block_Imperial_Panel_Black_Brick_Vertical"
    },
    {
      "x": -34,
      "y": 8,
      "z": 42,
      "name": "OrbisGalactic_Block_ShipHull",
      "rotation": 1
    },
    {
      "x": -34,
      "y": -1,
      "z": 43,
      "name": "OrbisGalactic_Block_ShipHull",
      "rotation": 1
    },
    {
      "x": -34,
      "y": 0,
      "z": 43,
      "name": "OrbisGalactic_Block_ShipHull",
      "rotation": 1
    },
    {
      "x": -34,
      "y": 1,
      "z": 43,
      "name": "OrbisGalactic_Block_Imperial_Panel_Gray_Brick_Vertical",
      "rotation": 2
    },
    {
      "x": -34,
      "y": 2,
      "z": 43,
      "name": "OrbisGalactic_Imperial_Railing_Gray",
      "support": 15,
      "rotation": 3
    },
    {
      "x": -34,
      "y": 7,
      "z": 43,
      "name": "OrbisGalactic_Block_Imperial_Panel_Black_Brick_Vertical"
    },
    {
      "x": -34,
      "y": 8,
      "z": 43,
      "name": "OrbisGalactic_Block_ShipHull",
      "rotation": 1
    },
    {
      "x": -34,
      "y": -1,
      "z": 44,
      "name": "OrbisGalactic_Block_ShipHull",
      "rotation": 1
    },
    {
      "x": -34,
      "y": 0,
      "z": 44,
      "name": "OrbisGalactic_Block_ShipHull",
      "rotation": 1
    },
    {
      "x": -34,
      "y": 1,
      "z": 44,
      "name": "OrbisGalactic_Block_Imperial_Panel_Gray_Brick_Vertical",
      "rotation": 2
    },
    {
      "x": -34,
      "y": 2,
      "z": 44,
      "name": "OrbisGalactic_Imperial_Railing_Gray",
      "support": 15,
      "rotation": 3
    },
    {
      "x": -34,
      "y": 7,
      "z": 44,
      "name": "OrbisGalactic_Block_Imperial_Panel_Black_Brick_Vertical"
    },
    {
      "x": -34,
      "y": 8,
      "z": 44,
      "name": "OrbisGalactic_Block_ShipHull",
      "rotation": 1
    },
    {
      "x": -34,
      "y": -1,
      "z": 45,
      "name": "OrbisGalactic_Block_ShipHull",
      "rotation": 1
    },
    {
      "x": -34,
      "y": 0,
      "z": 45,
      "name": "OrbisGalactic_Block_ShipHull",
      "rotation": 1
    },
    {
      "x": -34,
      "y": 1,
      "z": 45,
      "name": "OrbisGalactic_Block_Imperial_Panel_Gray_Brick_Vertical",
      "rotation": 2
    },
    {
      "x": -34,
      "y": 7,
      "z": 45,
      "name": "OrbisGalactic_Block_Imperial_Panel_Black_Smooth"
    },
    {
      "x": -34,
      "y": 8,
      "z": 45,
      "name": "OrbisGalactic_Block_ShipHull",
      "rotation": 1
    },
    {
      "x": -34,
      "y": -1,
      "z": 46,
      "name": "OrbisGalactic_Block_ShipHull",
      "rotation": 1
    },
    {
      "x": -34,
      "y": 0,
      "z": 46,
      "name": "OrbisGalactic_Block_ShipHull",
      "rotation": 1
    },
    {
      "x": -34,
      "y": 1,
      "z": 46,
      "name": "OrbisGalactic_Block_Imperial_Panel_Black_Brick_Vertical",
      "rotation": 2
    },
    {
      "x": -34,
      "y": 2,
      "z": 46,
      "name": "OrbisGalactic_Block_Imperial_Panel_Black_Brick_Vertical",
      "rotation": 1
    },
    {
      "x": -34,
      "y": 3,
      "z": 46,
      "name": "OrbisGalactic_Block_Imperial_Panel_Black_Brick_Vertical",
      "rotation": 1
    },
    {
      "x": -34,
      "y": 4,
      "z": 46,
      "name": "OrbisGalactic_Block_Imperial_Panel_Black_Brick_Vertical",
      "rotation": 1
    },
    {
      "x": -34,
      "y": 5,
      "z": 46,
      "name": "OrbisGalactic_Block_Imperial_Panel_Black_Brick_Vertical",
      "rotation": 1
    },
    {
      "x": -34,
      "y": 6,
      "z": 46,
      "name": "OrbisGalactic_Block_Imperial_Panel_Black_Brick_Horizontal",
      "rotation": 2
    },
    {
      "x": -34,
      "y": 7,
      "z": 46,
      "name": "OrbisGalactic_Block_ShipHull",
      "rotation": 1
    },
    {
      "x": -34,
      "y": 8,
      "z": 46,
      "name": "OrbisGalactic_Block_ShipHull",
      "rotation": 1
    },
    {
      "x": -34,
      "y": -1,
      "z": 47,
      "name": "OrbisGalactic_Block_ShipHull",
      "rotation": 1
    },
    {
      "x": -34,
      "y": 0,
      "z": 47,
      "name": "OrbisGalactic_Block_ShipHull",
      "rotation": 1
    },
    {
      "x": -34,
      "y": 1,
      "z": 47,
      "name": "OrbisGalactic_Block_Imperial_Panel_Black_Brick_Vertical"
    },
    {
      "x": -34,
      "y": 2,
      "z": 47,
      "name": "OrbisGalactic_Block_ShipHull",
      "rotation": 1
    },
    {
      "x": -34,
      "y": 3,
      "z": 47,
      "name": "OrbisGalactic_Block_ShipHull",
      "rotation": 1
    },
    {
      "x": -34,
      "y": 4,
      "z": 47,
      "name": "OrbisGalactic_Block_ShipHull",
      "rotation": 1
    },
    {
      "x": -34,
      "y": 5,
      "z": 47,
      "name": "OrbisGalactic_Block_ShipHull",
      "rotation": 1
    },
    {
      "x": -34,
      "y": 6,
      "z": 47,
      "name": "OrbisGalactic_Block_ShipHull",
      "rotation": 1
    },
    {
      "x": -34,
      "y": 7,
      "z": 47,
      "name": "OrbisGalactic_Block_ShipHull",
      "rotation": 1
    },
    {
      "x": -34,
      "y": -1,
      "z": 48,
      "name": "OrbisGalactic_Block_ShipHull",
      "rotation": 1
    },
    {
      "x": -34,
      "y": 0,
      "z": 48,
      "name": "OrbisGalactic_Block_ShipHull",
      "rotation": 1
    },
    {
      "x": -34,
      "y": 1,
      "z": 48,
      "name": "OrbisGalactic_Block_Imperial_Panel_Black_Brick_Vertical"
    },
    {
      "x": -34,
      "y": 0,
      "z": 49,
      "name": "OrbisGalactic_Block_ShipHull",
      "rotation": 1
    },
    {
      "x": -34,
      "y": 1,
      "z": 49,
      "name": "OrbisGalactic_Block_ShipHull",
      "rotation": 1
    },
    {
      "x": -34,
      "y": 0,
      "z": 50,
      "name": "OrbisGalactic_Block_Imperial_Panel_Black_Brick_Horizontal",
      "rotation": 3
    },
    {
      "x": -33,
      "y": 1,
      "z": 11,
      "name": "OrbisGalactic_Block_ShipHull",
      "rotation": 1
    },
    {
      "x": -33,
      "y": 2,
      "z": 11,
      "name": "OrbisGalactic_Block_ShipHull",
      "rotation": 1
    },
    {
      "x": -33,
      "y": 3,
      "z": 11,
      "name": "OrbisGalactic_Block_ShipHull",
      "rotation": 1
    },
    {
      "x": -33,
      "y": 4,
      "z": 11,
      "name": "OrbisGalactic_Block_ShipHull",
      "rotation": 1
    },
    {
      "x": -33,
      "y": 5,
      "z": 11,
      "name": "OrbisGalactic_Block_ShipHull",
      "rotation": 1
    },
    {
      "x": -33,
      "y": 6,
      "z": 11,
      "name": "OrbisGalactic_Block_ShipHull",
      "rotation": 1
    },
    {
      "x": -33,
      "y": 7,
      "z": 11,
      "name": "OrbisGalactic_Block_ShipHull",
      "rotation": 1
    },
    {
      "x": -33,
      "y": 1,
      "z": 12,
      "name": "OrbisGalactic_Block_ShipHull",
      "rotation": 1
    },
    {
      "x": -33,
      "y": 2,
      "z": 12,
      "name": "OrbisGalactic_Block_ShipHull",
      "rotation": 1
    },
    {
      "x": -33,
      "y": 3,
      "z": 12,
      "name": "OrbisGalactic_Block_ShipHull",
      "rotation": 1
    },
    {
      "x": -33,
      "y": 4,
      "z": 12,
      "name": "OrbisGalactic_Block_ShipHull",
      "rotation": 1
    },
    {
      "x": -33,
      "y": 5,
      "z": 12,
      "name": "OrbisGalactic_Block_ShipHull",
      "rotation": 1
    },
    {
      "x": -33,
      "y": 6,
      "z": 12,
      "name": "OrbisGalactic_Block_ShipHull",
      "rotation": 1
    },
    {
      "x": -33,
      "y": 7,
      "z": 12,
      "name": "OrbisGalactic_Block_ShipHull",
      "rotation": 1
    },
    {
      "x": -33,
      "y": 1,
      "z": 13,
      "name": "OrbisGalactic_Block_ShipHull",
      "rotation": 1
    },
    {
      "x": -33,
      "y": 2,
      "z": 13,
      "name": "OrbisGalactic_Block_ShipHull",
      "rotation": 1
    },
    {
      "x": -33,
      "y": 3,
      "z": 13,
      "name": "OrbisGalactic_Block_ShipHull",
      "rotation": 1
    },
    {
      "x": -33,
      "y": 4,
      "z": 13,
      "name": "OrbisGalactic_Block_ShipHull",
      "rotation": 1
    },
    {
      "x": -33,
      "y": 5,
      "z": 13,
      "name": "OrbisGalactic_Block_ShipHull",
      "rotation": 1
    },
    {
      "x": -33,
      "y": 6,
      "z": 13,
      "name": "OrbisGalactic_Block_ShipHull",
      "rotation": 1
    },
    {
      "x": -33,
      "y": 7,
      "z": 13,
      "name": "OrbisGalactic_Block_ShipHull",
      "rotation": 1
    },
    {
      "x": -33,
      "y": 1,
      "z": 14,
      "name": "OrbisGalactic_Block_ShipHull",
      "rotation": 1
    },
    {
      "x": -33,
      "y": 2,
      "z": 14,
      "name": "OrbisGalactic_Block_ShipHull",
      "rotation": 1
    },
    {
      "x": -33,
      "y": 3,
      "z": 14,
      "name": "OrbisGalactic_Block_ShipHull",
      "rotation": 1
    },
    {
      "x": -33,
      "y": 4,
      "z": 14,
      "name": "OrbisGalactic_Block_ShipHull",
      "rotation": 1
    },
    {
      "x": -33,
      "y": 5,
      "z": 14,
      "name": "OrbisGalactic_Block_ShipHull",
      "rotation": 1
    },
    {
      "x": -33,
      "y": 6,
      "z": 14,
      "name": "OrbisGalactic_Block_ShipHull",
      "rotation": 1
    },
    {
      "x": -33,
      "y": 7,
      "z": 14,
      "name": "OrbisGalactic_Block_ShipHull",
      "rotation": 1
    },
    {
      "x": -33,
      "y": 1,
      "z": 15,
      "name": "OrbisGalactic_Block_ShipHull",
      "rotation": 1
    },
    {
      "x": -33,
      "y": 2,
      "z": 15,
      "name": "OrbisGalactic_Block_Imperial_Panel_Black_Brick_Vertical",
      "rotation": 3
    },
    {
      "x": -33,
      "y": 3,
      "z": 15,
      "name": "OrbisGalactic_Block_Imperial_Panel_Black_Brick_Vertical",
      "rotation": 1
    },
    {
      "x": -33,
      "y": 4,
      "z": 15,
      "name": "OrbisGalactic_Block_Imperial_Panel_Black_Brick_Vertical",
      "rotation": 1
    },
    {
      "x": -33,
      "y": 5,
      "z": 15,
      "name": "OrbisGalactic_Block_ShipHull",
      "rotation": 1
    },
    {
      "x": -33,
      "y": 6,
      "z": 15,
      "name": "OrbisGalactic_Block_ShipHull",
      "rotation": 1
    },
    {
      "x": -33,
      "y": 7,
      "z": 15,
      "name": "OrbisGalactic_Block_ShipHull",
      "rotation": 1
    },
    {
      "x": -33,
      "y": 1,
      "z": 16,
      "name": "OrbisGalactic_Block_ShipHull",
      "rotation": 1
    },
    {
      "x": -33,
      "y": 2,
      "z": 16,
      "name": "OrbisGalactic_Block_Imperial_Panel_Black_Brick_Vertical",
      "rotation": 3
    },
    {
      "x": -33,
      "y": 3,
      "z": 16,
      "name": "OrbisGalactic_Block_Imperial_Panel_Black_Brick_Vertical",
      "rotation": 3
    },
    {
      "x": -33,
      "y": 4,
      "z": 16,
      "name": "OrbisGalactic_Block_Imperial_Panel_Black_Brick_Vertical",
      "rotation": 3
    },
    {
      "x": -33,
      "y": 5,
      "z": 16,
      "name": "OrbisGalactic_Block_ShipHull",
      "rotation": 1
    },
    {
      "x": -33,
      "y": 6,
      "z": 16,
      "name": "OrbisGalactic_Block_ShipHull",
      "rotation": 1
    },
    {
      "x": -33,
      "y": 7,
      "z": 16,
      "name": "OrbisGalactic_Block_ShipHull",
      "rotation": 1
    },
    {
      "x": -33,
      "y": 1,
      "z": 17,
      "name": "OrbisGalactic_Block_ShipHull",
      "rotation": 1
    },
    {
      "x": -33,
      "y": 2,
      "z": 17,
      "name": "OrbisGalactic_Block_Imperial_Panel_Black_Brick_Vertical",
      "rotation": 3
    },
    {
      "x": -33,
      "y": 3,
      "z": 17,
      "name": "OrbisGalactic_Block_Imperial_Panel_Black_Brick_Vertical",
      "rotation": 3
    },
    {
      "x": -33,
      "y": 4,
      "z": 17,
      "name": "OrbisGalactic_Block_Imperial_Panel_Black_Brick_Vertical",
      "rotation": 3
    },
    {
      "x": -33,
      "y": 5,
      "z": 17,
      "name": "OrbisGalactic_Block_ShipHull",
      "rotation": 1
    },
    {
      "x": -33,
      "y": 6,
      "z": 17,
      "name": "OrbisGalactic_Block_ShipHull",
      "rotation": 1
    },
    {
      "x": -33,
      "y": 7,
      "z": 17,
      "name": "OrbisGalactic_Block_ShipHull",
      "rotation": 1
    },
    {
      "x": -33,
      "y": 1,
      "z": 18,
      "name": "OrbisGalactic_Block_ShipHull",
      "rotation": 1
    },
    {
      "x": -33,
      "y": 2,
      "z": 18,
      "name": "OrbisGalactic_Block_ShipHull",
      "rotation": 1
    },
    {
      "x": -33,
      "y": 3,
      "z": 18,
      "name": "OrbisGalactic_Block_ShipHull",
      "rotation": 1
    },
    {
      "x": -33,
      "y": 4,
      "z": 18,
      "name": "OrbisGalactic_Block_ShipHull",
      "rotation": 1
    },
    {
      "x": -33,
      "y": 5,
      "z": 18,
      "name": "OrbisGalactic_Block_ShipHull",
      "rotation": 1
    },
    {
      "x": -33,
      "y": 6,
      "z": 18,
      "name": "OrbisGalactic_Block_ShipHull",
      "rotation": 1
    },
    {
      "x": -33,
      "y": 7,
      "z": 18,
      "name": "OrbisGalactic_Block_ShipHull",
      "rotation": 1
    },
    {
      "x": -33,
      "y": 1,
      "z": 19,
      "name": "OrbisGalactic_Block_ShipHull",
      "rotation": 1
    },
    {
      "x": -33,
      "y": 2,
      "z": 19,
      "name": "OrbisGalactic_Block_ShipHull",
      "rotation": 1
    },
    {
      "x": -33,
      "y": 3,
      "z": 19,
      "name": "OrbisGalactic_Block_ShipHull",
      "rotation": 1
    },
    {
      "x": -33,
      "y": 4,
      "z": 19,
      "name": "OrbisGalactic_Block_ShipHull",
      "rotation": 1
    },
    {
      "x": -33,
      "y": 5,
      "z": 19,
      "name": "OrbisGalactic_Block_ShipHull",
      "rotation": 1
    },
    {
      "x": -33,
      "y": 6,
      "z": 19,
      "name": "OrbisGalactic_Block_ShipHull",
      "rotation": 1
    },
    {
      "x": -33,
      "y": 7,
      "z": 19,
      "name": "OrbisGalactic_Block_ShipHull",
      "rotation": 1
    },
    {
      "x": -33,
      "y": 0,
      "z": 20,
      "name": "OrbisGalactic_Block_ShipHull",
      "rotation": 1
    },
    {
      "x": -33,
      "y": 1,
      "z": 20,
      "name": "OrbisGalactic_Block_ShipHull",
      "rotation": 1
    },
    {
      "x": -33,
      "y": 2,
      "z": 20,
      "name": "OrbisGalactic_Block_ShipHull",
      "rotation": 1
    },
    {
      "x": -33,
      "y": 3,
      "z": 20,
      "name": "OrbisGalactic_Block_ShipHull",
      "rotation": 1
    },
    {
      "x": -33,
      "y": 4,
      "z": 20,
      "name": "OrbisGalactic_Block_ShipHull",
      "rotation": 1
    },
    {
      "x": -33,
      "y": 5,
      "z": 20,
      "name": "OrbisGalactic_Block_ShipHull",
      "rotation": 1
    },
    {
      "x": -33,
      "y": 6,
      "z": 20,
      "name": "OrbisGalactic_Block_ShipHull",
      "rotation": 1
    },
    {
      "x": -33,
      "y": 7,
      "z": 20,
      "name": "OrbisGalactic_Block_ShipHull",
      "rotation": 1
    },
    {
      "x": -33,
      "y": 0,
      "z": 21,
      "name": "OrbisGalactic_Block_ShipHull",
      "rotation": 1
    },
    {
      "x": -33,
      "y": 1,
      "z": 21,
      "name": "OrbisGalactic_Block_Imperial_Panel_Gray_Brick_Vertical",
      "rotation": 3
    },
    {
      "x": -33,
      "y": 2,
      "z": 21,
      "name": "OrbisGalactic_Block_Imperial_Panel_Light_Gray_Brick_Vertical"
    },
    {
      "x": -33,
      "y": 3,
      "z": 21,
      "name": "OrbisGalactic_Block_Imperial_Panel_Light_Gray_Brick_Vertical"
    },
    {
      "x": -33,
      "y": 4,
      "z": 21,
      "name": "OrbisGalactic_Block_Imperial_Panel_Light_Gray_Brick_Vertical"
    },
    {
      "x": -33,
      "y": 5,
      "z": 21,
      "name": "OrbisGalactic_Block_Imperial_Panel_Light_Gray_Brick_Vertical"
    },
    {
      "x": -33,
      "y": 6,
      "z": 21,
      "name": "OrbisGalactic_Block_Imperial_Panel_Black_Brick_Horizontal"
    },
    {
      "x": -33,
      "y": 7,
      "z": 21,
      "name": "OrbisGalactic_Block_ShipHull",
      "rotation": 1
    },
    {
      "x": -33,
      "y": 0,
      "z": 22,
      "name": "OrbisGalactic_Block_ShipHull",
      "rotation": 1
    },
    {
      "x": -33,
      "y": 1,
      "z": 22,
      "name": "OrbisGalactic_Block_Imperial_Floor_Pattern_Bar_Corner_Inverted"
    },
    {
      "x": -33,
      "y": 7,
      "z": 22,
      "name": "OrbisGalactic_Block_Imperial_Panel_Black_Smooth",
      "rotation": 1
    },
    {
      "x": -33,
      "y": 8,
      "z": 22,
      "name": "OrbisGalactic_Block_ShipHull",
      "rotation": 1
    },
    {
      "x": -33,
      "y": 0,
      "z": 23,
      "name": "OrbisGalactic_Block_ShipHull",
      "rotation": 1
    },
    {
      "x": -33,
      "y": 1,
      "z": 23,
      "name": "OrbisGalactic_Block_Imperial_Floor_Pattern_Bar_Top",
      "rotation": 3
    },
    {
      "x": -33,
      "y": 7,
      "z": 23,
      "name": "OrbisGalactic_Block_Imperial_Panel_Black_Brick_Vertical",
      "rotation": 2
    },
    {
      "x": -33,
      "y": 8,
      "z": 23,
      "name": "OrbisGalactic_Block_ShipHull",
      "rotation": 1
    },
    {
      "x": -33,
      "y": 0,
      "z": 24,
      "name": "OrbisGalactic_Block_ShipHull",
      "rotation": 1
    },
    {
      "x": -33,
      "y": 1,
      "z": 24,
      "name": "OrbisGalactic_Block_Imperial_Floor_Pattern_Bar_Top",
      "rotation": 3
    },
    {
      "x": -33,
      "y": 7,
      "z": 24,
      "name": "OrbisGalactic_Block_Imperial_Panel_Black_Brick_Vertical",
      "rotation": 2
    },
    {
      "x": -33,
      "y": 8,
      "z": 24,
      "name": "OrbisGalactic_Block_ShipHull",
      "rotation": 1
    },
    {
      "x": -33,
      "y": 0,
      "z": 25,
      "name": "OrbisGalactic_Block_ShipHull",
      "rotation": 1
    },
    {
      "x": -33,
      "y": 1,
      "z": 25,
      "name": "OrbisGalactic_Block_Imperial_Floor_Pattern_Bar_Top",
      "rotation": 3
    },
    {
      "x": -33,
      "y": 7,
      "z": 25,
      "name": "OrbisGalactic_Block_Imperial_Panel_Black_Brick_Vertical",
      "rotation": 2
    },
    {
      "x": -33,
      "y": 8,
      "z": 25,
      "name": "OrbisGalactic_Block_ShipHull",
      "rotation": 1
    },
    {
      "x": -33,
      "y": 0,
      "z": 26,
      "name": "OrbisGalactic_Block_ShipHull",
      "rotation": 1
    },
    {
      "x": -33,
      "y": 1,
      "z": 26,
      "name": "OrbisGalactic_Block_Imperial_Floor_Pattern_Bar_Top",
      "rotation": 3
    },
    {
      "x": -33,
      "y": 7,
      "z": 26,
      "name": "OrbisGalactic_Block_Imperial_Panel_Black_Brick_Vertical",
      "rotation": 2
    },
    {
      "x": -33,
      "y": 8,
      "z": 26,
      "name": "OrbisGalactic_Block_ShipHull",
      "rotation": 1
    },
    {
      "x": -33,
      "y": 0,
      "z": 27,
      "name": "OrbisGalactic_Block_ShipHull",
      "rotation": 1
    },
    {
      "x": -33,
      "y": 1,
      "z": 27,
      "name": "OrbisGalactic_Block_Imperial_Floor_Pattern_Bar_Top",
      "rotation": 3
    },
    {
      "x": -33,
      "y": 7,
      "z": 27,
      "name": "OrbisGalactic_Block_Imperial_Panel_Black_Brick_Vertical",
      "rotation": 2
    },
    {
      "x": -33,
      "y": 8,
      "z": 27,
      "name": "OrbisGalactic_Block_ShipHull",
      "rotation": 1
    },
    {
      "x": -33,
      "y": 0,
      "z": 28,
      "name": "OrbisGalactic_Block_ShipHull",
      "rotation": 1
    },
    {
      "x": -33,
      "y": 1,
      "z": 28,
      "name": "OrbisGalactic_Block_Imperial_Floor_Pattern_Bar_Top",
      "rotation": 3
    },
    {
      "x": -33,
      "y": 7,
      "z": 28,
      "name": "OrbisGalactic_Block_Imperial_Panel_Black_Brick_Vertical",
      "rotation": 2
    },
    {
      "x": -33,
      "y": 8,
      "z": 28,
      "name": "OrbisGalactic_Block_ShipHull",
      "rotation": 1
    },
    {
      "x": -33,
      "y": 0,
      "z": 29,
      "name": "OrbisGalactic_Block_ShipHull",
      "rotation": 1
    },
    {
      "x": -33,
      "y": 1,
      "z": 29,
      "name": "OrbisGalactic_Block_Imperial_Floor_Pattern_Bar_Top",
      "rotation": 3
    },
    {
      "x": -33,
      "y": 7,
      "z": 29,
      "name": "OrbisGalactic_Block_Imperial_Panel_Black_Brick_Vertical",
      "rotation": 2
    },
    {
      "x": -33,
      "y": 8,
      "z": 29,
      "name": "OrbisGalactic_Block_ShipHull",
      "rotation": 1
    },
    {
      "x": -33,
      "y": 0,
      "z": 30,
      "name": "OrbisGalactic_Block_ShipHull",
      "rotation": 1
    },
    {
      "x": -33,
      "y": 1,
      "z": 30,
      "name": "OrbisGalactic_Block_Imperial_Floor_Pattern_Bar_Top",
      "rotation": 3
    },
    {
      "x": -33,
      "y": 7,
      "z": 30,
      "name": "OrbisGalactic_Block_Imperial_Panel_Black_Brick_Vertical",
      "rotation": 2
    },
    {
      "x": -33,
      "y": 8,
      "z": 30,
      "name": "OrbisGalactic_Block_ShipHull",
      "rotation": 1
    },
    {
      "x": -33,
      "y": 0,
      "z": 31,
      "name": "OrbisGalactic_Block_ShipHull",
      "rotation": 1
    },
    {
      "x": -33,
      "y": 1,
      "z": 31,
      "name": "OrbisGalactic_Block_Imperial_Floor_Pattern_Bar_Top",
      "rotation": 3
    },
    {
      "x": -33,
      "y": 7,
      "z": 31,
      "name": "OrbisGalactic_Block_Imperial_Panel_Black_Brick_Vertical",
      "rotation": 2
    },
    {
      "x": -33,
      "y": 8,
      "z": 31,
      "name": "OrbisGalactic_Block_ShipHull",
      "rotation": 1
    },
    {
      "x": -33,
      "y": 0,
      "z": 32,
      "name": "OrbisGalactic_Block_ShipHull",
      "rotation": 1
    },
    {
      "x": -33,
      "y": 1,
      "z": 32,
      "name": "OrbisGalactic_Block_Imperial_Floor_Pattern_Bar_Corner_Inverted",
      "rotation": 3
    },
    {
      "x": -33,
      "y": 7,
      "z": 32,
      "name": "OrbisGalactic_Block_Imperial_Panel_Black_Brick_Vertical",
      "rotation": 2
    },
    {
      "x": -33,
      "y": 8,
      "z": 32,
      "name": "OrbisGalactic_Block_ShipHull",
      "rotation": 1
    },
    {
      "x": -33,
      "y": 0,
      "z": 33,
      "name": "OrbisGalactic_Block_ShipHull",
      "rotation": 1
    },
    {
      "x": -33,
      "y": 1,
      "z": 33,
      "name": "OrbisGalactic_Block_Imperial_Panel_Black_Brick_Horizontal"
    },
    {
      "x": -33,
      "y": 2,
      "z": 33,
      "name": "OrbisGalactic_Block_Imperial_Panel_Light_Gray_Brick_Vertical"
    },
    {
      "x": -33,
      "y": 3,
      "z": 33,
      "name": "OrbisGalactic_Block_Imperial_Panel_Light_Gray_Brick_Vertical"
    },
    {
      "x": -33,
      "y": 4,
      "z": 33,
      "name": "OrbisGalactic_Block_Imperial_Panel_Light_Gray_Brick_Vertical"
    },
    {
      "x": -33,
      "y": 5,
      "z": 33,
      "name": "OrbisGalactic_Block_Imperial_Panel_Light_Gray_Brick_Vertical"
    },
    {
      "x": -33,
      "y": 6,
      "z": 33,
      "name": "OrbisGalactic_Block_Imperial_Panel_Black_Brick_Horizontal",
      "rotation": 2
    },
    {
      "x": -33,
      "y": 7,
      "z": 33,
      "name": "OrbisGalactic_Block_Imperial_Panel_Black_Smooth",
      "rotation": 1
    },
    {
      "x": -33,
      "y": 8,
      "z": 33,
      "name": "OrbisGalactic_Block_ShipHull",
      "rotation": 1
    },
    {
      "x": -33,
      "y": 0,
      "z": 34,
      "name": "OrbisGalactic_Block_ShipHull",
      "rotation": 1
    },
    {
      "x": -33,
      "y": 1,
      "z": 34,
      "name": "OrbisGalactic_Block_Imperial_Panel_Black_Brick_Vertical",
      "rotation": 3
    },
    {
      "x": -33,
      "y": 2,
      "z": 34,
      "name": "OrbisGalactic_Block_Imperial_Panel_Black_Brick_Vertical",
      "rotation": 3
    },
    {
      "x": -33,
      "y": 3,
      "z": 34,
      "name": "OrbisGalactic_Block_Imperial_Panel_Black_Brick_Vertical",
      "rotation": 3
    },
    {
      "x": -33,
      "y": 4,
      "z": 34,
      "name": "OrbisGalactic_Block_Imperial_Panel_Black_Brick_Vertical",
      "rotation": 3
    },
    {
      "x": -33,
      "y": 5,
      "z": 34,
      "name": "OrbisGalactic_Block_Imperial_Panel_Black_Brick_Vertical",
      "rotation": 3
    },
    {
      "x": -33,
      "y": 6,
      "z": 34,
      "name": "OrbisGalactic_Block_Imperial_Panel_Black_Brick_Vertical",
      "rotation": 3
    },
    {
      "x": -33,
      "y": 7,
      "z": 34,
      "name": "OrbisGalactic_Block_ShipHull",
      "rotation": 1
    },
    {
      "x": -33,
      "y": 8,
      "z": 34,
      "name": "OrbisGalactic_Block_ShipHull",
      "rotation": 1
    },
    {
      "x": -33,
      "y": 0,
      "z": 35,
      "name": "OrbisGalactic_Block_ShipHull",
      "rotation": 1
    },
    {
      "x": -33,
      "y": 1,
      "z": 35,
      "name": "OrbisGalactic_Block_Imperial_Panel_Black_Brick_Vertical"
    },
    {
      "x": -33,
      "y": 2,
      "z": 35,
      "name": "OrbisGalactic_Block_Imperial_Ship_Window_Bottom_Right",
      "rotation": 1
    },
    {
      "x": -33,
      "y": 3,
      "z": 35,
      "name": "OrbisGalactic_Block_Imperial_Ship_Window_Right_Center",
      "rotation": 1
    },
    {
      "x": -33,
      "y": 4,
      "z": 35,
      "name": "OrbisGalactic_Block_Imperial_Ship_Window_Right_Center",
      "rotation": 1
    },
    {
      "x": -33,
      "y": 5,
      "z": 35,
      "name": "OrbisGalactic_Block_Imperial_Ship_Window_Top_Right",
      "rotation": 1
    },
    {
      "x": -33,
      "y": 6,
      "z": 35,
      "name": "OrbisGalactic_Block_Imperial_Panel_Black_Brick_Horizontal",
      "rotation": 1
    },
    {
      "x": -33,
      "y": 7,
      "z": 35,
      "name": "OrbisGalactic_Block_ShipHull",
      "rotation": 1
    },
    {
      "x": -33,
      "y": 8,
      "z": 35,
      "name": "OrbisGalactic_Block_ShipHull",
      "rotation": 1
    },
    {
      "x": -33,
      "y": 0,
      "z": 36,
      "name": "OrbisGalactic_Block_ShipHull",
      "rotation": 1
    },
    {
      "x": -33,
      "y": 1,
      "z": 36,
      "name": "OrbisGalactic_Block_Imperial_Panel_Black_Brick_Vertical"
    },
    {
      "x": -33,
      "y": 2,
      "z": 36,
      "name": "OrbisGalactic_Block_Imperial_Ship_Window_Bottom_Center",
      "rotation": 1
    },
    {
      "x": -33,
      "y": 3,
      "z": 36,
      "name": "OrbisGalactic_Block_Imperial_Ship_Window_Center",
      "rotation": 1
    },
    {
      "x": -33,
      "y": 4,
      "z": 36,
      "name": "OrbisGalactic_Block_Imperial_Ship_Window_Center",
      "rotation": 1
    },
    {
      "x": -33,
      "y": 5,
      "z": 36,
      "name": "OrbisGalactic_Block_Imperial_Ship_Window_Top_Center",
      "rotation": 1
    },
    {
      "x": -33,
      "y": 6,
      "z": 36,
      "name": "OrbisGalactic_Block_Imperial_Panel_Black_Brick_Horizontal",
      "rotation": 1
    },
    {
      "x": -33,
      "y": 7,
      "z": 36,
      "name": "OrbisGalactic_Block_ShipHull",
      "rotation": 1
    },
    {
      "x": -33,
      "y": 8,
      "z": 36,
      "name": "OrbisGalactic_Block_ShipHull",
      "rotation": 1
    },
    {
      "x": -33,
      "y": 0,
      "z": 37,
      "name": "OrbisGalactic_Block_ShipHull",
      "rotation": 1
    },
    {
      "x": -33,
      "y": 1,
      "z": 37,
      "name": "OrbisGalactic_Block_Imperial_Panel_Black_Brick_Vertical"
    },
    {
      "x": -33,
      "y": 2,
      "z": 37,
      "name": "OrbisGalactic_Block_Imperial_Ship_Window_Bottom_Left",
      "rotation": 1
    },
    {
      "x": -33,
      "y": 3,
      "z": 37,
      "name": "OrbisGalactic_Block_Imperial_Ship_Window_Left_Center",
      "rotation": 1
    },
    {
      "x": -33,
      "y": 4,
      "z": 37,
      "name": "OrbisGalactic_Block_Imperial_Ship_Window_Left_Center",
      "rotation": 1
    },
    {
      "x": -33,
      "y": 5,
      "z": 37,
      "name": "OrbisGalactic_Block_Imperial_Ship_Window_Top_Left",
      "rotation": 1
    },
    {
      "x": -33,
      "y": 6,
      "z": 37,
      "name": "OrbisGalactic_Block_Imperial_Panel_Black_Brick_Horizontal",
      "rotation": 1
    },
    {
      "x": -33,
      "y": 7,
      "z": 37,
      "name": "OrbisGalactic_Block_ShipHull",
      "rotation": 1
    },
    {
      "x": -33,
      "y": 8,
      "z": 37,
      "name": "OrbisGalactic_Block_ShipHull",
      "rotation": 1
    },
    {
      "x": -33,
      "y": -1,
      "z": 38,
      "name": "OrbisGalactic_Block_ShipHull",
      "rotation": 1
    },
    {
      "x": -33,
      "y": 0,
      "z": 38,
      "name": "OrbisGalactic_Block_ShipHull",
      "rotation": 1
    },
    {
      "x": -33,
      "y": 1,
      "z": 38,
      "name": "OrbisGalactic_Block_Imperial_Panel_Black_Brick_Vertical",
      "rotation": 3
    },
    {
      "x": -33,
      "y": 2,
      "z": 38,
      "name": "OrbisGalactic_Block_Imperial_Panel_Black_Brick_Vertical",
      "rotation": 3
    },
    {
      "x": -33,
      "y": 3,
      "z": 38,
      "name": "OrbisGalactic_Block_Imperial_Panel_Black_Brick_Vertical",
      "rotation": 3
    },
    {
      "x": -33,
      "y": 4,
      "z": 38,
      "name": "OrbisGalactic_Block_Imperial_Panel_Black_Brick_Vertical",
      "rotation": 3
    },
    {
      "x": -33,
      "y": 5,
      "z": 38,
      "name": "OrbisGalactic_Block_Imperial_Panel_Black_Brick_Vertical",
      "rotation": 3
    },
    {
      "x": -33,
      "y": 6,
      "z": 38,
      "name": "OrbisGalactic_Block_Imperial_Panel_Black_Brick_Vertical",
      "rotation": 3
    },
    {
      "x": -33,
      "y": 7,
      "z": 38,
      "name": "OrbisGalactic_Block_ShipHull",
      "rotation": 1
    },
    {
      "x": -33,
      "y": 8,
      "z": 38,
      "name": "OrbisGalactic_Block_ShipHull",
      "rotation": 1
    },
    {
      "x": -33,
      "y": -1,
      "z": 39,
      "name": "OrbisGalactic_Block_ShipHull",
      "rotation": 1
    },
    {
      "x": -33,
      "y": 0,
      "z": 39,
      "name": "OrbisGalactic_Block_ShipHull",
      "rotation": 1
    },
    {
      "x": -33,
      "y": 1,
      "z": 39,
      "name": "OrbisGalactic_Block_Imperial_Panel_Gray_Smooth",
      "rotation": 1
    },
    {
      "x": -33,
      "y": 2,
      "z": 39,
      "name": "OrbisGalactic_Imperial_Railing_Gray",
      "support": 15,
      "rotation": 2
    },
    {
      "x": -33,
      "y": 7,
      "z": 39,
      "name": "OrbisGalactic_Block_Imperial_Panel_Black_Brick_Vertical",
      "rotation": 3
    },
    {
      "x": -33,
      "y": 8,
      "z": 39,
      "name": "OrbisGalactic_Block_ShipHull",
      "rotation": 1
    },
    {
      "x": -33,
      "y": -1,
      "z": 40,
      "name": "OrbisGalactic_Block_ShipHull",
      "rotation": 1
    },
    {
      "x": -33,
      "y": 0,
      "z": 40,
      "name": "*OrbisGalactic_Block_Imperial_Lamp1_State_Definitions_On",
      "rotation": 1
    },
    {
      "x": -33,
      "y": 7,
      "z": 40,
      "name": "OrbisGalactic_Block_Imperial_Panel_Black_Smooth",
      "rotation": 1
    },
    {
      "x": -33,
      "y": 8,
      "z": 40,
      "name": "OrbisGalactic_Block_ShipHull",
      "rotation": 1
    },
    {
      "x": -33,
      "y": 9,
      "z": 40,
      "name": "OrbisGalactic_Block_ShipHull",
      "rotation": 1
    },
    {
      "x": -33,
      "y": -1,
      "z": 41,
      "name": "OrbisGalactic_Block_ShipHull",
      "rotation": 1
    },
    {
      "x": -33,
      "y": 0,
      "z": 41,
      "name": "OrbisGalactic_Block_Imperial_Panel_Gray_Brick_Horizontal",
      "rotation": 3
    },
    {
      "x": -33,
      "y": 2,
      "z": 41,
      "name": "OrbisGalactic_Imperial_Railing_Gray",
      "filler": 1,
      "rotation": 3
    },
    {
      "x": -33,
      "y": 8,
      "z": 41,
      "name": "OrbisGalactic_Block_Imperial_Panel_Black_Smooth",
      "rotation": 2
    },
    {
      "x": -33,
      "y": 9,
      "z": 41,
      "name": "OrbisGalactic_Block_ShipHull",
      "rotation": 1
    },
    {
      "x": -33,
      "y": -1,
      "z": 42,
      "name": "OrbisGalactic_Block_ShipHull",
      "rotation": 1
    },
    {
      "x": -33,
      "y": 0,
      "z": 42,
      "name": "OrbisGalactic_Block_Imperial_Panel_Gray_Brick_Horizontal",
      "rotation": 3
    },
    {
      "x": -33,
      "y": 2,
      "z": 42,
      "name": "OrbisGalactic_Imperial_Railing_Gray",
      "filler": 1,
      "rotation": 3
    },
    {
      "x": -33,
      "y": 8,
      "z": 42,
      "name": "OrbisGalactic_Block_Imperial_Panel_Black_Brick_Vertical",
      "rotation": 2
    },
    {
      "x": -33,
      "y": 9,
      "z": 42,
      "name": "OrbisGalactic_Block_ShipHull",
      "rotation": 1
    },
    {
      "x": -33,
      "y": -1,
      "z": 43,
      "name": "OrbisGalactic_Block_ShipHull",
      "rotation": 1
    },
    {
      "x": -33,
      "y": 0,
      "z": 43,
      "name": "OrbisGalactic_Block_Imperial_Panel_Gray_Brick_Horizontal",
      "rotation": 3
    },
    {
      "x": -33,
      "y": 2,
      "z": 43,
      "name": "OrbisGalactic_Imperial_Railing_Gray",
      "filler": 1,
      "rotation": 3
    },
    {
      "x": -33,
      "y": 8,
      "z": 43,
      "name": "OrbisGalactic_Block_Imperial_Panel_Black_Brick_Vertical",
      "rotation": 2
    },
    {
      "x": -33,
      "y": 9,
      "z": 43,
      "name": "OrbisGalactic_Block_ShipHull",
      "rotation": 1
    },
    {
      "x": -33,
      "y": -1,
      "z": 44,
      "name": "OrbisGalactic_Block_ShipHull",
      "rotation": 1
    },
    {
      "x": -33,
      "y": 0,
      "z": 44,
      "name": "OrbisGalactic_Block_Imperial_Panel_Gray_Brick_Vertical",
      "rotation": 3
    },
    {
      "x": -33,
      "y": 8,
      "z": 44,
      "name": "OrbisGalactic_Block_Imperial_Panel_Black_Brick_Vertical",
      "rotation": 2
    },
    {
      "x": -33,
      "y": 9,
      "z": 44,
      "name": "OrbisGalactic_Block_ShipHull",
      "rotation": 1
    },
    {
      "x": -33,
      "y": -1,
      "z": 45,
      "name": "OrbisGalactic_Block_ShipHull",
      "rotation": 1
    },
    {
      "x": -33,
      "y": 0,
      "z": 45,
      "name": "OrbisGalactic_Block_Imperial_Panel_Gray_Brick_Vertical",
      "rotation": 3
    },
    {
      "x": -33,
      "y": 1,
      "z": 45,
      "name": "OrbisGalactic_Block_Imperial_Panel_Gray_Brick_Vertical",
      "rotation": 1
    },
    {
      "x": -33,
      "y": 2,
      "z": 45,
      "name": "OrbisGalactic_Imperial_Railing_Gray",
      "support": 15
    },
    {
      "x": -33,
      "y": 8,
      "z": 45,
      "name": "OrbisGalactic_Block_Imperial_Panel_Black_Smooth",
      "rotation": 3
    },
    {
      "x": -33,
      "y": 9,
      "z": 45,
      "name": "OrbisGalactic_Block_ShipHull",
      "rotation": 1
    },
    {
      "x": -33,
      "y": -1,
      "z": 46,
      "name": "OrbisGalactic_Block_ShipHull",
      "rotation": 1
    },
    {
      "x": -33,
      "y": 0,
      "z": 46,
      "name": "OrbisGalactic_Block_ShipHull",
      "rotation": 1
    },
    {
      "x": -33,
      "y": 1,
      "z": 46,
      "name": "*OrbisGalactic_Block_Imperial_Lamp3_Connected_State_Definitions_On",
      "rotation": 3
    },
    {
      "x": -33,
      "y": 7,
      "z": 46,
      "name": "OrbisGalactic_Block_Imperial_Panel_Black_Smooth"
    },
    {
      "x": -33,
      "y": 8,
      "z": 46,
      "name": "OrbisGalactic_Block_ShipHull",
      "rotation": 1
    },
    {
      "x": -33,
      "y": 9,
      "z": 46,
      "name": "OrbisGalactic_Block_ShipHull",
      "rotation": 1
    },
    {
      "x": -33,
      "y": -1,
      "z": 47,
      "name": "OrbisGalactic_Block_ShipHull",
      "rotation": 1
    },
    {
      "x": -33,
      "y": 0,
      "z": 47,
      "name": "OrbisGalactic_Block_ShipHull",
      "rotation": 1
    },
    {
      "x": -33,
      "y": 1,
      "z": 47,
      "name": "OrbisGalactic_Block_Imperial_Panel_Black_Brick_Vertical",
      "rotation": 1
    },
    {
      "x": -33,
      "y": 2,
      "z": 47,
      "name": "OrbisGalactic_Block_Imperial_Ship_Window_Right_Center",
      "rotation": 2
    },
    {
      "x": -33,
      "y": 3,
      "z": 47,
      "name": "OrbisGalactic_Block_Imperial_Ship_Window_Right_Center",
      "rotation": 2
    },
    {
      "x": -33,
      "y": 4,
      "z": 47,
      "name": "OrbisGalactic_Block_Imperial_Ship_Window_Right_Center",
      "rotation": 2
    },
    {
      "x": -33,
      "y": 5,
      "z": 47,
      "name": "OrbisGalactic_Block_Imperial_Ship_Window_Top_Right",
      "rotation": 2
    },
    {
      "x": -33,
      "y": 6,
      "z": 47,
      "name": "OrbisGalactic_Block_ShipHull",
      "rotation": 1
    },
    {
      "x": -33,
      "y": 7,
      "z": 47,
      "name": "OrbisGalactic_Block_ShipHull",
      "rotation": 1
    },
    {
      "x": -33,
      "y": -1,
      "z": 48,
      "name": "OrbisGalactic_Block_ShipHull",
      "rotation": 1
    },
    {
      "x": -33,
      "y": 0,
      "z": 48,
      "name": "OrbisGalactic_Block_ShipHull",
      "rotation": 1
    },
    {
      "x": -33,
      "y": 1,
      "z": 48,
      "name": "OrbisGalactic_Block_Imperial_Panel_Black_Brick_Vertical"
    },
    {
      "x": -33,
      "y": 0,
      "z": 49,
      "name": "OrbisGalactic_Block_ShipHull",
      "rotation": 1
    },
    {
      "x": -33,
      "y": 1,
      "z": 49,
      "name": "OrbisGalactic_Block_Imperial_Panel_Black_Brick_Vertical"
    },
    {
      "x": -33,
      "y": 0,
      "z": 50,
      "name": "OrbisGalactic_Block_Imperial_Panel_Black_Brick_Vertical"
    },
    {
      "x": -33,
      "y": 0,
      "z": 51,
      "name": "OrbisGalactic_Block_Imperial_Panel_Black_Brick_Horizontal",
      "rotation": 3
    },
    {
      "x": -33,
      "y": 0,
      "z": 52,
      "name": "OrbisGalactic_Block_Imperial_Panel_Black_Brick_Horizontal",
      "rotation": 3
    },
    {
      "x": -32,
      "y": 1,
      "z": 10,
      "name": "OrbisGalactic_Block_ShipHull",
      "rotation": 1
    },
    {
      "x": -32,
      "y": 2,
      "z": 10,
      "name": "OrbisGalactic_Block_ShipHull",
      "rotation": 1
    },
    {
      "x": -32,
      "y": 3,
      "z": 10,
      "name": "OrbisGalactic_Block_ShipHull",
      "rotation": 1
    },
    {
      "x": -32,
      "y": 4,
      "z": 10,
      "name": "OrbisGalactic_Block_ShipHull",
      "rotation": 1
    },
    {
      "x": -32,
      "y": 5,
      "z": 10,
      "name": "OrbisGalactic_Block_ShipHull",
      "rotation": 1
    },
    {
      "x": -32,
      "y": 6,
      "z": 10,
      "name": "OrbisGalactic_Block_ShipHull",
      "rotation": 1
    },
    {
      "x": -32,
      "y": 7,
      "z": 10,
      "name": "OrbisGalactic_Block_ShipHull",
      "rotation": 1
    },
    {
      "x": -32,
      "y": 0,
      "z": 11,
      "name": "OrbisGalactic_Block_ShipHull",
      "rotation": 1
    },
    {
      "x": -32,
      "y": 1,
      "z": 11,
      "name": "OrbisGalactic_Block_Imperial_Panel_Black",
      "rotation": 1
    },
    {
      "x": -32,
      "y": 2,
      "z": 11,
      "name": "OrbisGalactic_Block_Imperial_Panel_White_Brick_Vertical",
      "rotation": 1
    },
    {
      "x": -32,
      "y": 3,
      "z": 11,
      "name": "OrbisGalactic_Block_Imperial_Panel_White_Brick_Vertical",
      "rotation": 1
    },
    {
      "x": -32,
      "y": 4,
      "z": 11,
      "name": "OrbisGalactic_Block_Imperial_Panel_White_Brick_Vertical",
      "rotation": 1
    },
    {
      "x": -32,
      "y": 5,
      "z": 11,
      "name": "OrbisGalactic_Block_Imperial_Panel_White_Brick_Vertical",
      "rotation": 1
    },
    {
      "x": -32,
      "y": 6,
      "z": 11,
      "name": "OrbisGalactic_Block_Imperial_Panel_Black_Brick_Horizontal",
      "rotation": 1
    },
    {
      "x": -32,
      "y": 7,
      "z": 11,
      "name": "OrbisGalactic_Block_ShipHull",
      "rotation": 1
    },
    {
      "x": -32,
      "y": 8,
      "z": 11,
      "name": "OrbisGalactic_Block_ShipHull",
      "rotation": 1
    },
    {
      "x": -32,
      "y": 0,
      "z": 12,
      "name": "OrbisGalactic_Block_ShipHull",
      "rotation": 1
    },
    {
      "x": -32,
      "y": 1,
      "z": 12,
      "name": "OrbisGalactic_Block_Imperial_Panel_Black",
      "rotation": 1
    },
    {
      "x": -32,
      "y": 2,
      "z": 12,
      "name": "OrbisGalactic_Block_Imperial_Panel_Gray_Brick_Vertical",
      "rotation": 1
    },
    {
      "x": -32,
      "y": 3,
      "z": 12,
      "name": "OrbisGalactic_Block_Imperial_Panel_Gray_Brick_Vertical",
      "rotation": 1
    },
    {
      "x": -32,
      "y": 4,
      "z": 12,
      "name": "OrbisGalactic_Block_Imperial_Panel_Gray_Brick_Vertical",
      "rotation": 1
    },
    {
      "x": -32,
      "y": 5,
      "z": 12,
      "name": "OrbisGalactic_Block_Imperial_Panel_Gray_Brick_Vertical",
      "rotation": 1
    },
    {
      "x": -32,
      "y": 6,
      "z": 12,
      "name": "OrbisGalactic_Block_Imperial_Panel_Black_Brick_Horizontal",
      "rotation": 1
    },
    {
      "x": -32,
      "y": 7,
      "z": 12,
      "name": "OrbisGalactic_Block_ShipHull",
      "rotation": 1
    },
    {
      "x": -32,
      "y": 8,
      "z": 12,
      "name": "OrbisGalactic_Block_ShipHull",
      "rotation": 1
    },
    {
      "x": -32,
      "y": 0,
      "z": 13,
      "name": "OrbisGalactic_Block_ShipHull",
      "rotation": 1
    },
    {
      "x": -32,
      "y": 1,
      "z": 13,
      "name": "OrbisGalactic_Block_Imperial_Panel_Black",
      "rotation": 1
    },
    {
      "x": -32,
      "y": 2,
      "z": 13,
      "name": "*OrbisGalactic_Block_Imperial_Lamp2_State_Definitions_On",
      "rotation": 1
    },
    {
      "x": -32,
      "y": 3,
      "z": 13,
      "name": "*OrbisGalactic_Block_Imperial_Lamp3_Connected_State_Definitions_On",
      "rotation": 1
    },
    {
      "x": -32,
      "y": 4,
      "z": 13,
      "name": "*OrbisGalactic_Block_Imperial_Lamp3_Connected_State_Definitions_On",
      "rotation": 1
    },
    {
      "x": -32,
      "y": 5,
      "z": 13,
      "name": "*OrbisGalactic_Block_Imperial_Lamp2_State_Definitions_On",
      "rotation": 1
    },
    {
      "x": -32,
      "y": 6,
      "z": 13,
      "name": "OrbisGalactic_Block_Imperial_Panel_Black_Brick_Horizontal",
      "rotation": 1
    },
    {
      "x": -32,
      "y": 7,
      "z": 13,
      "name": "OrbisGalactic_Block_ShipHull",
      "rotation": 1
    },
    {
      "x": -32,
      "y": 8,
      "z": 13,
      "name": "OrbisGalactic_Block_ShipHull",
      "rotation": 1
    },
    {
      "x": -32,
      "y": 0,
      "z": 14,
      "name": "OrbisGalactic_Block_ShipHull",
      "rotation": 1
    },
    {
      "x": -32,
      "y": 1,
      "z": 14,
      "name": "OrbisGalactic_Block_Imperial_Panel_Black",
      "rotation": 1
    },
    {
      "x": -32,
      "y": 2,
      "z": 14,
      "name": "OrbisGalactic_Block_Imperial_Panel_White_Brick_Vertical",
      "rotation": 3
    },
    {
      "x": -32,
      "y": 3,
      "z": 14,
      "name": "OrbisGalactic_Block_Imperial_Panel_White_Brick_Vertical",
      "rotation": 3
    },
    {
      "x": -32,
      "y": 4,
      "z": 14,
      "name": "OrbisGalactic_Block_Imperial_Panel_White_Brick_Vertical",
      "rotation": 3
    },
    {
      "x": -32,
      "y": 5,
      "z": 14,
      "name": "OrbisGalactic_Block_Imperial_Panel_White_Brick_Vertical",
      "rotation": 3
    },
    {
      "x": -32,
      "y": 6,
      "z": 14,
      "name": "OrbisGalactic_Block_Imperial_Panel_Black_Brick_Horizontal",
      "rotation": 1
    },
    {
      "x": -32,
      "y": 7,
      "z": 14,
      "name": "OrbisGalactic_Block_ShipHull",
      "rotation": 1
    },
    {
      "x": -32,
      "y": 8,
      "z": 14,
      "name": "OrbisGalactic_Block_ShipHull",
      "rotation": 1
    },
    {
      "x": -32,
      "y": 0,
      "z": 15,
      "name": "OrbisGalactic_Block_ShipHull",
      "rotation": 1
    },
    {
      "x": -32,
      "y": 1,
      "z": 15,
      "name": "OrbisGalactic_Block_Imperial_Panel_Black_Brick_Horizontal",
      "rotation": 3
    },
    {
      "x": -32,
      "y": 5,
      "z": 15,
      "name": "OrbisGalactic_Block_Imperial_Panel_White_Brick_Horizontal",
      "rotation": 3
    },
    {
      "x": -32,
      "y": 6,
      "z": 15,
      "name": "OrbisGalactic_Block_Imperial_Panel_Black_Brick_Horizontal",
      "rotation": 1
    },
    {
      "x": -32,
      "y": 7,
      "z": 15,
      "name": "OrbisGalactic_Block_ShipHull",
      "rotation": 1
    },
    {
      "x": -32,
      "y": 8,
      "z": 15,
      "name": "OrbisGalactic_Block_ShipHull",
      "rotation": 1
    },
    {
      "x": -32,
      "y": 0,
      "z": 16,
      "name": "OrbisGalactic_Block_ShipHull",
      "rotation": 1
    },
    {
      "x": -32,
      "y": 1,
      "z": 16,
      "name": "OrbisGalactic_Block_Imperial_Panel_Black_Brick_Horizontal",
      "rotation": 3
    },
    {
      "x": -32,
      "y": 2,
      "z": 16,
      "name": "Furniture_Construction_Sign",
      "rotation": 1
    },
    {
      "x": -32,
      "y": 3,
      "z": 16,
      "name": "Furniture_Construction_Sign",
      "filler": 1024,
      "rotation": 1
    },
    {
      "x": -32,
      "y": 5,
      "z": 16,
      "name": "OrbisGalactic_Block_Imperial_Panel_White_Brick_Horizontal",
      "rotation": 3
    },
    {
      "x": -32,
      "y": 6,
      "z": 16,
      "name": "OrbisGalactic_Block_Imperial_Panel_Black_Brick_Horizontal"
    },
    {
      "x": -32,
      "y": 7,
      "z": 16,
      "name": "OrbisGalactic_Block_ShipHull",
      "rotation": 1
    },
    {
      "x": -32,
      "y": 8,
      "z": 16,
      "name": "OrbisGalactic_Block_ShipHull",
      "rotation": 1
    },
    {
      "x": -32,
      "y": 0,
      "z": 17,
      "name": "OrbisGalactic_Block_ShipHull",
      "rotation": 1
    },
    {
      "x": -32,
      "y": 1,
      "z": 17,
      "name": "OrbisGalactic_Block_Imperial_Panel_Black_Brick_Horizontal",
      "rotation": 3
    },
    {
      "x": -32,
      "y": 5,
      "z": 17,
      "name": "OrbisGalactic_Block_Imperial_Panel_White_Brick_Horizontal",
      "rotation": 3
    },
    {
      "x": -32,
      "y": 6,
      "z": 17,
      "name": "OrbisGalactic_Block_Imperial_Panel_Black_Brick_Horizontal",
      "rotation": 1
    },
    {
      "x": -32,
      "y": 7,
      "z": 17,
      "name": "OrbisGalactic_Block_ShipHull",
      "rotation": 1
    },
    {
      "x": -32,
      "y": 8,
      "z": 17,
      "name": "OrbisGalactic_Block_ShipHull",
      "rotation": 1
    },
    {
      "x": -32,
      "y": 0,
      "z": 18,
      "name": "OrbisGalactic_Block_ShipHull",
      "rotation": 1
    },
    {
      "x": -32,
      "y": 1,
      "z": 18,
      "name": "OrbisGalactic_Block_Imperial_Panel_Black",
      "rotation": 1
    },
    {
      "x": -32,
      "y": 2,
      "z": 18,
      "name": "OrbisGalactic_Block_Imperial_Panel_White_Brick_Vertical",
      "rotation": 3
    },
    {
      "x": -32,
      "y": 3,
      "z": 18,
      "name": "OrbisGalactic_Block_Imperial_Panel_White_Brick_Vertical",
      "rotation": 3
    },
    {
      "x": -32,
      "y": 4,
      "z": 18,
      "name": "OrbisGalactic_Block_Imperial_Panel_White_Brick_Vertical",
      "rotation": 3
    },
    {
      "x": -32,
      "y": 5,
      "z": 18,
      "name": "OrbisGalactic_Block_Imperial_Panel_White_Brick_Vertical",
      "rotation": 3
    },
    {
      "x": -32,
      "y": 6,
      "z": 18,
      "name": "OrbisGalactic_Block_Imperial_Panel_Black_Brick_Horizontal",
      "rotation": 1
    },
    {
      "x": -32,
      "y": 7,
      "z": 18,
      "name": "OrbisGalactic_Block_ShipHull",
      "rotation": 1
    },
    {
      "x": -32,
      "y": 8,
      "z": 18,
      "name": "OrbisGalactic_Block_ShipHull",
      "rotation": 1
    },
    {
      "x": -32,
      "y": 0,
      "z": 19,
      "name": "OrbisGalactic_Block_ShipHull",
      "rotation": 1
    },
    {
      "x": -32,
      "y": 1,
      "z": 19,
      "name": "OrbisGalactic_Block_Imperial_Panel_Black",
      "rotation": 1
    },
    {
      "x": -32,
      "y": 2,
      "z": 19,
      "name": "*OrbisGalactic_Block_Imperial_Lamp2_State_Definitions_On",
      "rotation": 1
    },
    {
      "x": -32,
      "y": 3,
      "z": 19,
      "name": "*OrbisGalactic_Block_Imperial_Lamp3_Connected_State_Definitions_On",
      "rotation": 1
    },
    {
      "x": -32,
      "y": 4,
      "z": 19,
      "name": "*OrbisGalactic_Block_Imperial_Lamp3_Connected_State_Definitions_On",
      "rotation": 1
    },
    {
      "x": -32,
      "y": 5,
      "z": 19,
      "name": "*OrbisGalactic_Block_Imperial_Lamp2_State_Definitions_On",
      "rotation": 1
    },
    {
      "x": -32,
      "y": 6,
      "z": 19,
      "name": "OrbisGalactic_Block_Imperial_Panel_Black_Brick_Horizontal",
      "rotation": 1
    },
    {
      "x": -32,
      "y": 7,
      "z": 19,
      "name": "OrbisGalactic_Block_ShipHull",
      "rotation": 1
    },
    {
      "x": -32,
      "y": 8,
      "z": 19,
      "name": "OrbisGalactic_Block_ShipHull",
      "rotation": 1
    },
    {
      "x": -32,
      "y": 0,
      "z": 20,
      "name": "OrbisGalactic_Block_ShipHull",
      "rotation": 1
    },
    {
      "x": -32,
      "y": 1,
      "z": 20,
      "name": "OrbisGalactic_Block_Imperial_Panel_Black",
      "rotation": 1
    },
    {
      "x": -32,
      "y": 2,
      "z": 20,
      "name": "OrbisGalactic_Block_Imperial_Panel_White_Brick_Vertical",
      "rotation": 1
    },
    {
      "x": -32,
      "y": 3,
      "z": 20,
      "name": "OrbisGalactic_Block_Imperial_Panel_White_Brick_Vertical",
      "rotation": 1
    },
    {
      "x": -32,
      "y": 4,
      "z": 20,
      "name": "OrbisGalactic_Block_Imperial_Panel_White_Brick_Vertical",
      "rotation": 1
    },
    {
      "x": -32,
      "y": 5,
      "z": 20,
      "name": "OrbisGalactic_Block_Imperial_Panel_White_Brick_Vertical",
      "rotation": 1
    },
    {
      "x": -32,
      "y": 6,
      "z": 20,
      "name": "OrbisGalactic_Block_Imperial_Panel_Black_Brick_Horizontal",
      "rotation": 1
    },
    {
      "x": -32,
      "y": 7,
      "z": 20,
      "name": "OrbisGalactic_Block_ShipHull",
      "rotation": 1
    },
    {
      "x": -32,
      "y": 8,
      "z": 20,
      "name": "OrbisGalactic_Block_ShipHull",
      "rotation": 1
    },
    {
      "x": -32,
      "y": 0,
      "z": 21,
      "name": "OrbisGalactic_Block_ShipHull",
      "rotation": 1
    },
    {
      "x": -32,
      "y": 1,
      "z": 21,
      "name": "OrbisGalactic_Block_Imperial_Panel_Black"
    },
    {
      "x": -32,
      "y": 2,
      "z": 21,
      "name": "OrbisGalactic_Block_Imperial_Panel_White_Brick_Vertical",
      "rotation": 1
    },
    {
      "x": -32,
      "y": 3,
      "z": 21,
      "name": "OrbisGalactic_Block_Imperial_Panel_White_Brick_Vertical",
      "rotation": 1
    },
    {
      "x": -32,
      "y": 4,
      "z": 21,
      "name": "OrbisGalactic_Block_Imperial_Panel_White_Brick_Vertical",
      "rotation": 1
    },
    {
      "x": -32,
      "y": 5,
      "z": 21,
      "name": "OrbisGalactic_Block_Imperial_Panel_White_Brick_Vertical",
      "rotation": 1
    },
    {
      "x": -32,
      "y": 6,
      "z": 21,
      "name": "OrbisGalactic_Block_Imperial_Panel_Black_Smooth",
      "rotation": 1
    },
    {
      "x": -32,
      "y": 7,
      "z": 21,
      "name": "OrbisGalactic_Block_ShipHull",
      "rotation": 1
    },
    {
      "x": -32,
      "y": 8,
      "z": 21,
      "name": "OrbisGalactic_Block_ShipHull",
      "rotation": 1
    },
    {
      "x": -32,
      "y": 0,
      "z": 22,
      "name": "OrbisGalactic_Block_ShipHull",
      "rotation": 1
    },
    {
      "x": -32,
      "y": 1,
      "z": 22,
      "name": "OrbisGalactic_Block_Imperial_Floor_Pattern_Bar_Top"
    },
    {
      "x": -32,
      "y": 7,
      "z": 22,
      "name": "OrbisGalactic_Block_Imperial_Panel_Black_Brick_Vertical",
      "rotation": 1
    },
    {
      "x": -32,
      "y": 8,
      "z": 22,
      "name": "OrbisGalactic_Block_ShipHull",
      "rotation": 1
    },
    {
      "x": -32,
      "y": 0,
      "z": 23,
      "name": "OrbisGalactic_Block_ShipHull",
      "rotation": 1
    },
    {
      "x": -32,
      "y": 1,
      "z": 23,
      "name": "*OrbisGalactic_Block_Imperial_Lamp2_State_Definitions_On",
      "rotation": 1
    },
    {
      "x": -32,
      "y": 7,
      "z": 23,
      "name": "OrbisGalactic_Block_Imperial_Panel_Black_Smooth",
      "rotation": 3
    },
    {
      "x": -32,
      "y": 8,
      "z": 23,
      "name": "OrbisGalactic_Block_ShipHull",
      "rotation": 1
    },
    {
      "x": -32,
      "y": 0,
      "z": 24,
      "name": "OrbisGalactic_Block_ShipHull",
      "rotation": 1
    },
    {
      "x": -32,
      "y": 1,
      "z": 24,
      "name": "OrbisGalactic_Block_Imperial_Panel_Gray_Brick_Vertical"
    },
    {
      "x": -32,
      "y": 7,
      "z": 24,
      "name": "OrbisGalactic_Block_Imperial_Panel_Black_Smooth",
      "rotation": 3
    },
    {
      "x": -32,
      "y": 8,
      "z": 24,
      "name": "OrbisGalactic_Block_ShipHull",
      "rotation": 1
    },
    {
      "x": -32,
      "y": 0,
      "z": 25,
      "name": "OrbisGalactic_Block_ShipHull",
      "rotation": 1
    },
    {
      "x": -32,
      "y": 1,
      "z": 25,
      "name": "OrbisGalactic_Block_Imperial_Panel_Gray_Brick_Vertical"
    },
    {
      "x": -32,
      "y": 7,
      "z": 25,
      "name": "OrbisGalactic_Block_Imperial_Panel_Black_Smooth",
      "rotation": 3
    },
    {
      "x": -32,
      "y": 8,
      "z": 25,
      "name": "OrbisGalactic_Block_ShipHull",
      "rotation": 1
    },
    {
      "x": -32,
      "y": 0,
      "z": 26,
      "name": "OrbisGalactic_Block_ShipHull",
      "rotation": 1
    },
    {
      "x": -32,
      "y": 1,
      "z": 26,
      "name": "*OrbisGalactic_Block_Imperial_Lamp2_State_Definitions_On",
      "rotation": 1
    },
    {
      "x": -32,
      "y": 7,
      "z": 26,
      "name": "OrbisGalactic_Block_Imperial_Panel_Black_Smooth",
      "rotation": 3
    },
    {
      "x": -32,
      "y": 8,
      "z": 26,
      "name": "OrbisGalactic_Block_ShipHull",
      "rotation": 1
    },
    {
      "x": -32,
      "y": 0,
      "z": 27,
      "name": "OrbisGalactic_Block_ShipHull",
      "rotation": 1
    },
    {
      "x": -32,
      "y": 1,
      "z": 27,
      "name": "OrbisGalactic_Block_Imperial_Panel_Gray_Brick_Vertical"
    },
    {
      "x": -32,
      "y": 7,
      "z": 27,
      "name": "OrbisGalactic_Block_Imperial_Panel_Black_Smooth",
      "rotation": 3
    },
    {
      "x": -32,
      "y": 8,
      "z": 27,
      "name": "OrbisGalactic_Block_ShipHull",
      "rotation": 1
    },
    {
      "x": -32,
      "y": 0,
      "z": 28,
      "name": "OrbisGalactic_Block_ShipHull",
      "rotation": 1
    },
    {
      "x": -32,
      "y": 1,
      "z": 28,
      "name": "*OrbisGalactic_Block_Imperial_Lamp2_State_Definitions_On",
      "rotation": 1
    },
    {
      "x": -32,
      "y": 7,
      "z": 28,
      "name": "OrbisGalactic_Block_Imperial_Panel_Black_Smooth",
      "rotation": 3
    },
    {
      "x": -32,
      "y": 8,
      "z": 28,
      "name": "OrbisGalactic_Block_ShipHull",
      "rotation": 1
    },
    {
      "x": -32,
      "y": 0,
      "z": 29,
      "name": "OrbisGalactic_Block_ShipHull",
      "rotation": 1
    },
    {
      "x": -32,
      "y": 1,
      "z": 29,
      "name": "OrbisGalactic_Block_Imperial_Panel_Gray_Brick_Vertical"
    },
    {
      "x": -32,
      "y": 7,
      "z": 29,
      "name": "OrbisGalactic_Block_Imperial_Panel_Black_Smooth",
      "rotation": 3
    },
    {
      "x": -32,
      "y": 8,
      "z": 29,
      "name": "OrbisGalactic_Block_ShipHull",
      "rotation": 1
    },
    {
      "x": -32,
      "y": 0,
      "z": 30,
      "name": "OrbisGalactic_Block_ShipHull",
      "rotation": 1
    },
    {
      "x": -32,
      "y": 1,
      "z": 30,
      "name": "OrbisGalactic_Block_Imperial_Panel_Gray_Brick_Vertical"
    },
    {
      "x": -32,
      "y": 7,
      "z": 30,
      "name": "OrbisGalactic_Block_Imperial_Panel_Black_Smooth",
      "rotation": 3
    },
    {
      "x": -32,
      "y": 8,
      "z": 30,
      "name": "OrbisGalactic_Block_ShipHull",
      "rotation": 1
    },
    {
      "x": -32,
      "y": 0,
      "z": 31,
      "name": "OrbisGalactic_Block_ShipHull",
      "rotation": 1
    },
    {
      "x": -32,
      "y": 1,
      "z": 31,
      "name": "*OrbisGalactic_Block_Imperial_Lamp2_State_Definitions_On",
      "rotation": 1
    },
    {
      "x": -32,
      "y": 7,
      "z": 31,
      "name": "OrbisGalactic_Block_Imperial_Panel_Black_Smooth",
      "rotation": 3
    },
    {
      "x": -32,
      "y": 8,
      "z": 31,
      "name": "OrbisGalactic_Block_ShipHull",
      "rotation": 1
    },
    {
      "x": -32,
      "y": 0,
      "z": 32,
      "name": "OrbisGalactic_Block_ShipHull",
      "rotation": 1
    },
    {
      "x": -32,
      "y": 1,
      "z": 32,
      "name": "OrbisGalactic_Block_Imperial_Floor_Pattern_Bar_Top",
      "rotation": 2
    },
    {
      "x": -32,
      "y": 7,
      "z": 32,
      "name": "OrbisGalactic_Block_Imperial_Panel_Black_Smooth",
      "rotation": 3
    },
    {
      "x": -32,
      "y": 8,
      "z": 32,
      "name": "OrbisGalactic_Block_ShipHull",
      "rotation": 1
    },
    {
      "x": -32,
      "y": 0,
      "z": 33,
      "name": "OrbisGalactic_Block_ShipHull",
      "rotation": 1
    },
    {
      "x": -32,
      "y": 1,
      "z": 33,
      "name": "OrbisGalactic_Block_Imperial_Floor_Pattern_Bar_Top",
      "rotation": 3
    },
    {
      "x": -32,
      "y": 2,
      "z": 33,
      "name": "OrbisGalactic_Block_Imperial_Panel_White_Brick_Vertical",
      "rotation": 2
    },
    {
      "x": -32,
      "y": 3,
      "z": 33,
      "name": "OrbisGalactic_Block_Imperial_Panel_White_Brick_Vertical",
      "rotation": 2
    },
    {
      "x": -32,
      "y": 4,
      "z": 33,
      "name": "OrbisGalactic_Block_Imperial_Panel_White_Brick_Vertical",
      "rotation": 2
    },
    {
      "x": -32,
      "y": 5,
      "z": 33,
      "name": "OrbisGalactic_Block_Imperial_Panel_White_Brick_Vertical",
      "rotation": 2
    },
    {
      "x": -32,
      "y": 6,
      "z": 33,
      "name": "OrbisGalactic_Block_Imperial_Panel_Black_Brick_Horizontal",
      "rotation": 2
    },
    {
      "x": -32,
      "y": 7,
      "z": 33,
      "name": "OrbisGalactic_Block_Imperial_Panel_Black_Brick_Horizontal",
      "rotation": 2
    },
    {
      "x": -32,
      "y": 8,
      "z": 33,
      "name": "OrbisGalactic_Block_ShipHull",
      "rotation": 1
    },
    {
      "x": -32,
      "y": 0,
      "z": 34,
      "name": "OrbisGalactic_Block_ShipHull",
      "rotation": 1
    },
    {
      "x": -32,
      "y": 1,
      "z": 34,
      "name": "OrbisGalactic_Block_Imperial_Panel_Gray_Brick_Vertical",
      "rotation": 2
    },
    {
      "x": -32,
      "y": 7,
      "z": 34,
      "name": "OrbisGalactic_Block_Imperial_Panel_Black",
      "rotation": 2
    },
    {
      "x": -32,
      "y": 8,
      "z": 34,
      "name": "OrbisGalactic_Block_ShipHull",
      "rotation": 1
    },
    {
      "x": -32,
      "y": 0,
