{
  "version": 8,
  "blockIdVersion": 11,
  "anchorX": 0,
  "anchorY": 0,
  "anchorZ": 0,
  "blocks": [
    {
      "x": -8,
      "y": -1,
      "z": 6,
      "name": "OrbisGalactic_Block_ShipHull",
      "rotation": 1
    },
    {
      "x": -8,
      "y": 0,
      "z": 6,
      "name": "OrbisGalactic_Block_ShipHull",
      "rotation": 1
    },
    {
      "x": -8,
      "y": 1,
      "z": 6,
      "name": "OrbisGalactic_Block_ShipHull",
      "rotation": 1
    },
    {
      "x": -8,
      "y": 2,
      "z": 6,
      "name": "OrbisGalactic_Block_ShipHull",
      "rotation": 1
    },
    {
      "x": -8,
      "y": 3,
      "z": 6,
      "name": "OrbisGalactic_Block_ShipHull",
      "rotation": 1
    },
    {
      "x": -8,
      "y": 4,
      "z": 6,
      "name": "OrbisGalactic_Block_ShipHull",
      "rotation": 1
    },
    {
      "x": -8,
      "y": 5,
      "z": 6,
      "name": "OrbisGalactic_Block_ShipHull",
      "rotation": 1
    },
    {
      "x": -8,
      "y": -1,
      "z": 7,
      "name": "OrbisGalactic_Block_ShipHull",
      "rotation": 1
    },
    {
      "x": -8,
      "y": 0,
      "z": 7,
      "name": "OrbisGalactic_Block_ShipHull",
      "rotation": 1
    },
    {
      "x": -8,
      "y": 1,
      "z": 7,
      "name": "OrbisGalactic_Block_ShipHull",
      "rotation": 1
    },
    {
      "x": -8,
      "y": 2,
      "z": 7,
      "name": "OrbisGalactic_Block_ShipHull",
      "rotation": 1
    },
    {
      "x": -8,
      "y": 3,
      "z": 7,
      "name": "OrbisGalactic_Block_ShipHull",
      "rotation": 1
    },
    {
      "x": -8,
      "y": 4,
      "z": 7,
      "name": "OrbisGalactic_Block_ShipHull",
      "rotation": 1
    },
    {
      "x": -8,
      "y": 5,
      "z": 7,
      "name": "OrbisGalactic_Block_ShipHull",
      "rotation": 1
    },
    {
      "x": -8,
      "y": -1,
      "z": 8,
      "name": "OrbisGalactic_Block_ShipHull",
      "rotation": 1
    },
    {
      "x": -8,
      "y": 0,
      "z": 8,
      "name": "OrbisGalactic_Block_ShipHull",
      "rotation": 1
    },
    {
      "x": -8,
      "y": 1,
      "z": 8,
      "name": "OrbisGalactic_Block_ShipHull",
      "rotation": 1
    },
    {
      "x": -8,
      "y": 2,
      "z": 8,
      "name": "OrbisGalactic_Block_ShipHull",
      "rotation": 1
    },
    {
      "x": -8,
      "y": 3,
      "z": 8,
      "name": "OrbisGalactic_Block_ShipHull",
      "rotation": 1
    },
    {
      "x": -8,
      "y": 4,
      "z": 8,
      "name": "OrbisGalactic_Block_ShipHull",
      "rotation": 1
    },
    {
      "x": -8,
      "y": 5,
      "z": 8,
      "name": "OrbisGalactic_Block_ShipHull",
      "rotation": 1
    },
    {
      "x": -8,
      "y": -2,
      "z": 9,
      "name": "OrbisGalactic_Block_ShipHull",
      "rotation": 1
    },
    {
      "x": -8,
      "y": -1,
      "z": 9,
      "name": "OrbisGalactic_Block_ShipHull",
      "rotation": 1
    },
    {
      "x": -8,
      "y": 0,
      "z": 9,
      "name": "OrbisGalactic_Block_ShipHull",
      "rotation": 1
    },
    {
      "x": -8,
      "y": 1,
      "z": 9,
      "name": "OrbisGalactic_Block_ShipHull",
      "rotation": 1
    },
    {
      "x": -8,
      "y": 2,
      "z": 9,
      "name": "OrbisGalactic_Block_ShipHull",
      "rotation": 1
    },
    {
      "x": -8,
      "y": 3,
      "z": 9,
      "name": "OrbisGalactic_Block_ShipHull",
      "rotation": 1
    },
    {
      "x": -8,
      "y": 4,
      "z": 9,
      "name": "OrbisGalactic_Block_ShipHull",
      "rotation": 1
    },
    {
      "x": -8,
      "y": 5,
      "z": 9,
      "name": "OrbisGalactic_Block_ShipHull",
      "rotation": 1
    },
    {
      "x": -8,
      "y": -2,
      "z": 10,
      "name": "OrbisGalactic_Block_ShipHull",
      "rotation": 1
    },
    {
      "x": -8,
      "y": -1,
      "z": 10,
      "name": "OrbisGalactic_Block_ShipHull",
      "rotation": 1
    },
    {
      "x": -8,
      "y": 4,
      "z": 10,
      "name": "OrbisGalactic_Block_ShipHull",
      "rotation": 1
    },
    {
      "x": -8,
      "y": 5,
      "z": 10,
      "name": "OrbisGalactic_Block_ShipHull",
      "rotation": 1
    },
    {
      "x": -8,
      "y": -2,
      "z": 11,
      "name": "OrbisGalactic_Block_ShipHull",
      "rotation": 1
    },
    {
      "x": -8,
      "y": -1,
      "z": 11,
      "name": "OrbisGalactic_Block_ShipHull",
      "rotation": 1
    },
    {
      "x": -8,
      "y": 4,
      "z": 11,
      "name": "OrbisGalactic_Block_ShipHull",
      "rotation": 1
    },
    {
      "x": -8,
      "y": 5,
      "z": 11,
      "name": "OrbisGalactic_Block_ShipHull",
      "rotation": 1
    },
    {
      "x": -8,
      "y": -2,
      "z": 12,
      "name": "OrbisGalactic_Block_ShipHull",
      "rotation": 1
    },
    {
      "x": -8,
      "y": -1,
      "z": 12,
      "name": "OrbisGalactic_Block_ShipHull",
      "rotation": 1
    },
    {
      "x": -8,
      "y": 4,
      "z": 12,
      "name": "OrbisGalactic_Block_ShipHull",
      "rotation": 1
    },
    {
      "x": -8,
      "y": 5,
      "z": 12,
      "name": "OrbisGalactic_Block_ShipHull",
      "rotation": 1
    },
    {
      "x": -8,
      "y": -2,
      "z": 13,
      "name": "OrbisGalactic_Block_ShipHull",
      "rotation": 1
    },
    {
      "x": -8,
      "y": -1,
      "z": 13,
      "name": "OrbisGalactic_Block_ShipHull",
      "rotation": 1
    },
    {
      "x": -8,
      "y": 0,
      "z": 13,
      "name": "OrbisGalactic_Block_ShipHull",
      "rotation": 1
    },
    {
      "x": -8,
      "y": 1,
      "z": 13,
      "name": "OrbisGalactic_Block_ShipHull",
      "rotation": 1
    },
    {
      "x": -8,
      "y": 2,
      "z": 13,
      "name": "OrbisGalactic_Block_ShipHull",
      "rotation": 1
    },
    {
      "x": -8,
      "y": 3,
      "z": 13,
      "name": "OrbisGalactic_Block_ShipHull",
      "rotation": 1
    },
    {
      "x": -8,
      "y": 4,
      "z": 13,
      "name": "OrbisGalactic_Block_ShipHull",
      "rotation": 1
    },
    {
      "x": -8,
      "y": 5,
      "z": 13,
      "name": "OrbisGalactic_Block_ShipHull",
      "rotation": 1
    },
    {
      "x": -8,
      "y": -2,
      "z": 14,
      "name": "OrbisGalactic_Block_ShipHull",
      "rotation": 1
    },
    {
      "x": -8,
      "y": -1,
      "z": 14,
      "name": "OrbisGalactic_Block_ShipHull",
      "rotation": 1
    },
    {
      "x": -8,
      "y": 4,
      "z": 14,
      "name": "OrbisGalactic_Block_ShipHull",
      "rotation": 1
    },
    {
      "x": -8,
      "y": 5,
      "z": 14,
      "name": "OrbisGalactic_Block_ShipHull",
      "rotation": 1
    },
    {
      "x": -8,
      "y": -2,
      "z": 15,
      "name": "OrbisGalactic_Block_ShipHull",
      "rotation": 1
    },
    {
      "x": -8,
      "y": -1,
      "z": 15,
      "name": "OrbisGalactic_Block_ShipHull",
      "rotation": 1
    },
    {
      "x": -8,
      "y": 4,
      "z": 15,
      "name": "OrbisGalactic_Block_ShipHull",
      "rotation": 1
    },
    {
      "x": -8,
      "y": 5,
      "z": 15,
      "name": "OrbisGalactic_Block_ShipHull",
      "rotation": 1
    },
    {
      "x": -8,
      "y": -2,
      "z": 16,
      "name": "OrbisGalactic_Block_ShipHull",
      "rotation": 1
    },
    {
      "x": -8,
      "y": -1,
      "z": 16,
      "name": "OrbisGalactic_Block_ShipHull",
      "rotation": 1
    },
    {
      "x": -8,
      "y": 4,
      "z": 16,
      "name": "OrbisGalactic_Block_ShipHull",
      "rotation": 1
    },
    {
      "x": -8,
      "y": 5,
      "z": 16,
      "name": "OrbisGalactic_Block_ShipHull",
      "rotation": 1
    },
    {
      "x": -8,
      "y": -2,
      "z": 17,
      "name": "OrbisGalactic_Block_ShipHull",
      "rotation": 1
    },
    {
      "x": -8,
      "y": -1,
      "z": 17,
      "name": "OrbisGalactic_Block_ShipHull",
      "rotation": 1
    },
    {
      "x": -8,
      "y": 0,
      "z": 17,
      "name": "OrbisGalactic_Block_ShipHull",
      "rotation": 1
    },
    {
      "x": -8,
      "y": 1,
      "z": 17,
      "name": "OrbisGalactic_Block_ShipHull",
      "rotation": 1
    },
    {
      "x": -8,
      "y": 2,
      "z": 17,
      "name": "OrbisGalactic_Block_ShipHull",
      "rotation": 1
    },
    {
      "x": -8,
      "y": 3,
      "z": 17,
      "name": "OrbisGalactic_Block_ShipHull",
      "rotation": 1
    },
    {
      "x": -8,
      "y": 4,
      "z": 17,
      "name": "OrbisGalactic_Block_ShipHull",
      "rotation": 1
    },
    {
      "x": -8,
      "y": 5,
      "z": 17,
      "name": "OrbisGalactic_Block_ShipHull",
      "rotation": 1
    },
    {
      "x": -8,
      "y": -2,
      "z": 23,
      "name": "OrbisGalactic_Block_ShipHull",
      "rotation": 1
    },
    {
      "x": -8,
      "y": -1,
      "z": 23,
      "name": "OrbisGalactic_Block_ShipHull",
      "rotation": 1
    },
    {
      "x": -8,
      "y": 0,
      "z": 23,
      "name": "OrbisGalactic_Block_ShipHull",
      "rotation": 1
    },
    {
      "x": -8,
      "y": 1,
      "z": 23,
      "name": "OrbisGalactic_Block_ShipHull",
      "rotation": 1
    },
    {
      "x": -8,
      "y": 2,
      "z": 23,
      "name": "OrbisGalactic_Block_ShipHull",
      "rotation": 1
    },
    {
      "x": -8,
      "y": 3,
      "z": 23,
      "name": "OrbisGalactic_Block_ShipHull",
      "rotation": 1
    },
    {
      "x": -8,
      "y": 4,
      "z": 23,
      "name": "OrbisGalactic_Block_ShipHull",
      "rotation": 1
    },
    {
      "x": -8,
      "y": 5,
      "z": 23,
      "name": "OrbisGalactic_Block_ShipHull",
      "rotation": 1
    },
    {
      "x": -8,
      "y": -2,
      "z": 24,
      "name": "OrbisGalactic_Block_ShipHull",
      "rotation": 1
    },
    {
      "x": -8,
      "y": -1,
      "z": 24,
      "name": "OrbisGalactic_Block_ShipHull",
      "rotation": 1
    },
    {
      "x": -8,
      "y": 0,
      "z": 24,
      "name": "OrbisGalactic_Block_ShipHull",
      "rotation": 1
    },
    {
      "x": -8,
      "y": 1,
      "z": 24,
      "name": "OrbisGalactic_Block_ShipHull",
      "rotation": 1
    },
    {
      "x": -8,
      "y": 2,
      "z": 24,
      "name": "OrbisGalactic_Block_ShipHull",
      "rotation": 1
    },
    {
      "x": -8,
      "y": 3,
      "z": 24,
      "name": "OrbisGalactic_Block_ShipHull",
      "rotation": 1
    },
    {
      "x": -8,
      "y": 4,
      "z": 24,
      "name": "OrbisGalactic_Block_ShipHull",
      "rotation": 1
    },
    {
      "x": -8,
      "y": 5,
      "z": 24,
      "name": "OrbisGalactic_Block_ShipHull",
      "rotation": 1
    },
    {
      "x": -8,
      "y": -2,
      "z": 25,
      "name": "OrbisGalactic_Block_ShipHull",
      "rotation": 1
    },
    {
      "x": -8,
      "y": -1,
      "z": 25,
      "name": "OrbisGalactic_Block_ShipHull",
      "rotation": 1
    },
    {
      "x": -8,
      "y": 0,
      "z": 25,
      "name": "OrbisGalactic_Block_Imperial_Ship_Window_Bottom_Right",
      "rotation": 1
    },
    {
      "x": -8,
      "y": 1,
      "z": 25,
      "name": "OrbisGalactic_Block_Imperial_Ship_Window_Right_Center",
      "rotation": 1
    },
    {
      "x": -8,
      "y": 2,
      "z": 25,
      "name": "OrbisGalactic_Block_Imperial_Ship_Window_Right_Center",
      "rotation": 1
    },
    {
      "x": -8,
      "y": 3,
      "z": 25,
      "name": "OrbisGalactic_Block_Imperial_Ship_Window_Top_Right",
      "rotation": 1
    },
    {
      "x": -8,
      "y": 4,
      "z": 25,
      "name": "OrbisGalactic_Block_ShipHull",
      "rotation": 1
    },
    {
      "x": -8,
      "y": 5,
      "z": 25,
      "name": "OrbisGalactic_Block_ShipHull",
      "rotation": 1
    },
    {
      "x": -8,
      "y": -2,
      "z": 26,
      "name": "OrbisGalactic_Block_ShipHull",
      "rotation": 1
    },
    {
      "x": -8,
      "y": -1,
      "z": 26,
      "name": "OrbisGalactic_Block_ShipHull",
      "rotation": 1
    },
    {
      "x": -8,
      "y": 0,
      "z": 26,
      "name": "OrbisGalactic_Block_Imperial_Ship_Window_Bottom_Center",
      "rotation": 1
    },
    {
      "x": -8,
      "y": 1,
      "z": 26,
      "name": "OrbisGalactic_Block_Imperial_Ship_Window_Center",
      "rotation": 1
    },
    {
      "x": -8,
      "y": 2,
      "z": 26,
      "name": "OrbisGalactic_Block_Imperial_Ship_Window_Center",
      "rotation": 1
    },
    {
      "x": -8,
      "y": 3,
      "z": 26,
      "name": "OrbisGalactic_Block_Imperial_Ship_Window_Top_Center",
      "rotation": 1
    },
    {
      "x": -8,
      "y": 4,
      "z": 26,
      "name": "OrbisGalactic_Block_ShipHull",
      "rotation": 1
    },
    {
      "x": -8,
      "y": 5,
      "z": 26,
      "name": "OrbisGalactic_Block_ShipHull",
      "rotation": 1
    },
    {
      "x": -8,
      "y": -2,
      "z": 27,
      "name": "OrbisGalactic_Block_ShipHull",
      "rotation": 1
    },
    {
      "x": -8,
      "y": -1,
      "z": 27,
      "name": "OrbisGalactic_Block_ShipHull",
      "rotation": 1
    },
    {
      "x": -8,
      "y": 0,
      "z": 27,
      "name": "OrbisGalactic_Block_Imperial_Ship_Window_Bottom_Center",
      "rotation": 1
    },
    {
      "x": -8,
      "y": 1,
      "z": 27,
      "name": "OrbisGalactic_Block_Imperial_Ship_Window_Center",
      "rotation": 1
    },
    {
      "x": -8,
      "y": 2,
      "z": 27,
      "name": "OrbisGalactic_Block_Imperial_Ship_Window_Center",
      "rotation": 1
    },
    {
      "x": -8,
      "y": 3,
      "z": 27,
      "name": "OrbisGalactic_Block_Imperial_Ship_Window_Top_Center",
      "rotation": 1
    },
    {
      "x": -8,
      "y": 4,
      "z": 27,
      "name": "OrbisGalactic_Block_ShipHull",
      "rotation": 1
    },
    {
      "x": -8,
      "y": 5,
      "z": 27,
      "name": "OrbisGalactic_Block_ShipHull",
      "rotation": 1
    },
    {
      "x": -8,
      "y": -2,
      "z": 28,
      "name": "OrbisGalactic_Block_ShipHull",
      "rotation": 1
    },
    {
      "x": -8,
      "y": -1,
      "z": 28,
      "name": "OrbisGalactic_Block_ShipHull",
      "rotation": 1
    },
    {
      "x": -8,
      "y": 0,
      "z": 28,
      "name": "OrbisGalactic_Block_Imperial_Ship_Window_Bottom_Center",
      "rotation": 1
    },
    {
      "x": -8,
      "y": 1,
      "z": 28,
      "name": "OrbisGalactic_Block_Imperial_Ship_Window_Center",
      "rotation": 1
    },
    {
      "x": -8,
      "y": 2,
      "z": 28,
      "name": "OrbisGalactic_Block_Imperial_Ship_Window_Center",
      "rotation": 1
    },
    {
      "x": -8,
      "y": 3,
      "z": 28,
      "name": "OrbisGalactic_Block_Imperial_Ship_Window_Top_Center",
      "rotation": 1
    },
    {
      "x": -8,
      "y": 4,
      "z": 28,
      "name": "OrbisGalactic_Block_ShipHull",
      "rotation": 1
    },
    {
      "x": -8,
      "y": 5,
      "z": 28,
      "name": "OrbisGalactic_Block_ShipHull",
      "rotation": 1
    },
    {
      "x": -8,
      "y": -2,
      "z": 29,
      "name": "OrbisGalactic_Block_ShipHull",
      "rotation": 1
    },
    {
      "x": -8,
      "y": -1,
      "z": 29,
      "name": "OrbisGalactic_Block_ShipHull",
      "rotation": 1
    },
    {
      "x": -8,
      "y": 0,
      "z": 29,
      "name": "OrbisGalactic_Block_Imperial_Ship_Window_Bottom_Left",
      "rotation": 1
    },
    {
      "x": -8,
      "y": 1,
      "z": 29,
      "name": "OrbisGalactic_Block_Imperial_Ship_Window_Left_Center",
      "rotation": 1
    },
    {
      "x": -8,
      "y": 2,
      "z": 29,
      "name": "OrbisGalactic_Block_Imperial_Ship_Window_Left_Center",
      "rotation": 1
    },
    {
      "x": -8,
      "y": 3,
      "z": 29,
      "name": "OrbisGalactic_Block_Imperial_Ship_Window_Top_Left",
      "rotation": 1
    },
    {
      "x": -8,
      "y": 4,
      "z": 29,
      "name": "OrbisGalactic_Block_ShipHull",
      "rotation": 1
    },
    {
      "x": -8,
      "y": 5,
      "z": 29,
      "name": "OrbisGalactic_Block_ShipHull",
      "rotation": 1
    },
    {
      "x": -8,
      "y": -2,
      "z": 30,
      "name": "OrbisGalactic_Block_ShipHull",
      "rotation": 1
    },
    {
      "x": -8,
      "y": -1,
      "z": 30,
      "name": "OrbisGalactic_Block_ShipHull",
      "rotation": 1
    },
    {
      "x": -8,
      "y": 0,
      "z": 30,
      "name": "OrbisGalactic_Block_ShipHull",
      "rotation": 1
    },
    {
      "x": -8,
      "y": 1,
      "z": 30,
      "name": "OrbisGalactic_Block_ShipHull",
      "rotation": 1
    },
    {
      "x": -8,
      "y": 2,
      "z": 30,
      "name": "OrbisGalactic_Block_ShipHull",
      "rotation": 1
    },
    {
      "x": -8,
      "y": 3,
      "z": 30,
      "name": "OrbisGalactic_Block_ShipHull",
      "rotation": 1
    },
    {
      "x": -8,
      "y": 4,
      "z": 30,
      "name": "OrbisGalactic_Block_ShipHull",
      "rotation": 1
    },
    {
      "x": -8,
      "y": 5,
      "z": 30,
      "name": "OrbisGalactic_Block_ShipHull",
      "rotation": 1
    },
    {
      "x": -8,
      "y": -2,
      "z": 31,
      "name": "OrbisGalactic_Block_ShipHull",
      "rotation": 1
    },
    {
      "x": -8,
      "y": -1,
      "z": 31,
      "name": "OrbisGalactic_Block_ShipHull",
      "rotation": 1
    },
    {
      "x": -8,
      "y": -1,
      "z": 32,
      "name": "OrbisGalactic_Block_ShipHull",
      "rotation": 1
    },
    {
      "x": -7,
      "y": 0,
      "z": -1,
      "name": "OrbisGalactic_Block_ShipHull",
      "rotation": 1
    },
    {
      "x": -7,
      "y": 1,
      "z": -1,
      "name": "OrbisGalactic_Block_ShipHull",
      "rotation": 1
    },
    {
      "x": -7,
      "y": 2,
      "z": -1,
      "name": "OrbisGalactic_Block_ShipHull",
      "rotation": 1
    },
    {
      "x": -7,
      "y": 3,
      "z": -1,
      "name": "OrbisGalactic_Block_ShipHull",
      "rotation": 1
    },
    {
      "x": -7,
      "y": 0,
      "z": 0,
      "name": "OrbisGalactic_Block_ShipHull",
      "rotation": 1
    },
    {
      "x": -7,
      "y": 1,
      "z": 0,
      "name": "OrbisGalactic_Block_ShipHull",
      "rotation": 1
    },
    {
      "x": -7,
      "y": 2,
      "z": 0,
      "name": "OrbisGalactic_Block_ShipHull",
      "rotation": 1
    },
    {
      "x": -7,
      "y": 3,
      "z": 0,
      "name": "OrbisGalactic_Block_ShipHull",
      "rotation": 1
    },
    {
      "x": -7,
      "y": 0,
      "z": 1,
      "name": "OrbisGalactic_Block_ShipHull",
      "rotation": 1
    },
    {
      "x": -7,
      "y": 1,
      "z": 1,
      "name": "OrbisGalactic_Block_ShipHull",
      "rotation": 1
    },
    {
      "x": -7,
      "y": 2,
      "z": 1,
      "name": "OrbisGalactic_Block_ShipHull",
      "rotation": 1
    },
    {
      "x": -7,
      "y": 3,
      "z": 1,
      "name": "OrbisGalactic_Block_ShipHull",
      "rotation": 1
    },
    {
      "x": -7,
      "y": -2,
      "z": 5,
      "name": "OrbisGalactic_Block_ShipHull",
      "rotation": 1
    },
    {
      "x": -7,
      "y": -1,
      "z": 5,
      "name": "OrbisGalactic_Block_ShipHull",
      "rotation": 1
    },
    {
      "x": -7,
      "y": 0,
      "z": 5,
      "name": "OrbisGalactic_Block_ShipHull",
      "rotation": 1
    },
    {
      "x": -7,
      "y": 1,
      "z": 5,
      "name": "OrbisGalactic_Block_ShipHull",
      "rotation": 1
    },
    {
      "x": -7,
      "y": 2,
      "z": 5,
      "name": "OrbisGalactic_Block_ShipHull",
      "rotation": 1
    },
    {
      "x": -7,
      "y": 3,
      "z": 5,
      "name": "OrbisGalactic_Block_ShipHull",
      "rotation": 1
    },
    {
      "x": -7,
      "y": 4,
      "z": 5,
      "name": "OrbisGalactic_Block_ShipHull",
      "rotation": 1
    },
    {
      "x": -7,
      "y": 5,
      "z": 5,
      "name": "OrbisGalactic_Block_ShipHull",
      "rotation": 1
    },
    {
      "x": -7,
      "y": -2,
      "z": 6,
      "name": "OrbisGalactic_Block_ShipHull",
      "rotation": 1
    },
    {
      "x": -7,
      "y": -1,
      "z": 6,
      "name": "OrbisGalactic_Block_Imperial_Panel_Gray_Brick_Vertical"
    },
    {
      "x": -7,
      "y": 0,
      "z": 6,
      "name": "OrbisGalactic_Block_Imperial_Panel_Light_Gray_Brick_Vertical",
      "rotation": 1
    },
    {
      "x": -7,
      "y": 1,
      "z": 6,
      "name": "OrbisGalactic_Block_Imperial_Panel_Light_Gray_Brick_Vertical",
      "rotation": 1
    },
    {
      "x": -7,
      "y": 2,
      "z": 6,
      "name": "OrbisGalactic_Block_Imperial_Panel_Light_Gray_Brick_Vertical",
      "rotation": 1
    },
    {
      "x": -7,
      "y": 3,
      "z": 6,
      "name": "OrbisGalactic_Block_Imperial_Panel_Light_Gray_Brick_Vertical",
      "rotation": 1
    },
    {
      "x": -7,
      "y": 4,
      "z": 6,
      "name": "OrbisGalactic_Block_Imperial_Panel_Black_Brick_Horizontal",
      "rotation": 1
    },
    {
      "x": -7,
      "y": 5,
      "z": 6,
      "name": "OrbisGalactic_Block_ShipHull",
      "rotation": 1
    },
    {
      "x": -7,
      "y": -2,
      "z": 7,
      "name": "OrbisGalactic_Block_ShipHull",
      "rotation": 1
    },
    {
      "x": -7,
      "y": -1,
      "z": 7,
      "name": "OrbisGalactic_Block_Imperial_Panel_Gray_Brick_Vertical"
    },
    {
      "x": -7,
      "y": 0,
      "z": 7,
      "name": "OrbisGalactic_Block_Imperial_Panel_White_Brick_Vertical",
      "rotation": 1
    },
    {
      "x": -7,
      "y": 1,
      "z": 7,
      "name": "OrbisGalactic_Block_Imperial_Panel_White_Brick_Vertical",
      "rotation": 1
    },
    {
      "x": -7,
      "y": 2,
      "z": 7,
      "name": "OrbisGalactic_Block_Imperial_Panel_White_Brick_Vertical",
      "rotation": 1
    },
    {
      "x": -7,
      "y": 3,
      "z": 7,
      "name": "OrbisGalactic_Block_Imperial_Panel_White_Brick_Vertical",
      "rotation": 1
    },
    {
      "x": -7,
      "y": 4,
      "z": 7,
      "name": "OrbisGalactic_Block_Imperial_Panel_Black_Brick_Horizontal",
      "rotation": 1
    },
    {
      "x": -7,
      "y": 5,
      "z": 7,
      "name": "OrbisGalactic_Block_ShipHull",
      "rotation": 1
    },
    {
      "x": -7,
      "y": -2,
      "z": 8,
      "name": "OrbisGalactic_Block_ShipHull",
      "rotation": 1
    },
    {
      "x": -7,
      "y": -1,
      "z": 8,
      "name": "OrbisGalactic_Block_Imperial_Panel_Gray_Brick_Vertical"
    },
    {
      "x": -7,
      "y": 0,
      "z": 8,
      "name": "OrbisGalactic_Block_Imperial_Panel_Light_Gray_Brick_Vertical",
      "rotation": 1
    },
    {
      "x": -7,
      "y": 1,
      "z": 8,
      "name": "OrbisGalactic_Block_Imperial_Panel_Light_Gray_Brick_Vertical",
      "rotation": 1
    },
    {
      "x": -7,
      "y": 2,
      "z": 8,
      "name": "OrbisGalactic_Block_Imperial_Panel_Light_Gray_Brick_Vertical",
      "rotation": 1
    },
    {
      "x": -7,
      "y": 3,
      "z": 8,
      "name": "OrbisGalactic_Block_Imperial_Panel_Light_Gray_Brick_Vertical",
      "rotation": 1
    },
    {
      "x": -7,
      "y": 4,
      "z": 8,
      "name": "OrbisGalactic_Block_Imperial_Panel_Black_Brick_Horizontal",
      "rotation": 1
    },
    {
      "x": -7,
      "y": 5,
      "z": 8,
      "name": "OrbisGalactic_Block_ShipHull",
      "rotation": 1
    },
    {
      "x": -7,
      "y": -2,
      "z": 9,
      "name": "OrbisGalactic_Block_ShipHull",
      "rotation": 1
    },
    {
      "x": -7,
      "y": -1,
      "z": 9,
      "name": "OrbisGalactic_Block_Imperial_Panel_Black_Brick_Horizontal",
      "rotation": 3
    },
    {
      "x": -7,
      "y": 0,
      "z": 9,
      "name": "*OrbisGalactic_Block_Imperial_Lamp3_Connected_State_Definitions_On",
      "rotation": 1
    },
    {
      "x": -7,
      "y": 1,
      "z": 9,
      "name": "*OrbisGalactic_Block_Imperial_Lamp3_Connected_State_Definitions_On",
      "rotation": 1
    },
    {
      "x": -7,
      "y": 2,
      "z": 9,
      "name": "*OrbisGalactic_Block_Imperial_Lamp3_Connected_State_Definitions_On",
      "rotation": 1
    },
    {
      "x": -7,
      "y": 3,
      "z": 9,
      "name": "*OrbisGalactic_Block_Imperial_Lamp2_State_Definitions_On",
      "rotation": 1
    },
    {
      "x": -7,
      "y": 4,
      "z": 9,
      "name": "OrbisGalactic_Block_Imperial_Panel_Black_Smooth",
      "rotation": 1
    },
    {
      "x": -7,
      "y": 5,
      "z": 9,
      "name": "OrbisGalactic_Block_ShipHull",
      "rotation": 1
    },
    {
      "x": -7,
      "y": -2,
      "z": 10,
      "name": "OrbisGalactic_Block_ShipHull",
      "rotation": 1
    },
    {
      "x": -7,
      "y": -1,
      "z": 10,
      "name": "OrbisGalactic_Block_Imperial_Panel_Black_Brick_Horizontal",
      "rotation": 3
    },
    {
      "x": -7,
      "y": 0,
      "z": 10,
      "name": "OrbisGalactic_Block_Imperial_Ship_Window_Bottom_Right",
      "rotation": 1
    },
    {
      "x": -7,
      "y": 1,
      "z": 10,
      "name": "OrbisGalactic_Block_Imperial_Ship_Window_Right_Center",
      "rotation": 1
    },
    {
      "x": -7,
      "y": 2,
      "z": 10,
      "name": "OrbisGalactic_Block_Imperial_Ship_Window_Right_Center",
      "rotation": 1
    },
    {
      "x": -7,
      "y": 3,
      "z": 10,
      "name": "OrbisGalactic_Block_Imperial_Ship_Window_Top_Right",
      "rotation": 1
    },
    {
      "x": -7,
      "y": 4,
      "z": 10,
      "name": "OrbisGalactic_Block_Imperial_Panel_Black_Brick_Horizontal",
      "rotation": 1
    },
    {
      "x": -7,
      "y": 5,
      "z": 10,
      "name": "OrbisGalactic_Block_ShipHull",
      "rotation": 1
    },
    {
      "x": -7,
      "y": -2,
      "z": 11,
      "name": "OrbisGalactic_Block_ShipHull",
      "rotation": 1
    },
    {
      "x": -7,
      "y": -1,
      "z": 11,
      "name": "OrbisGalactic_Block_Imperial_Panel_Black_Brick_Horizontal",
      "rotation": 3
    },
    {
      "x": -7,
      "y": 0,
      "z": 11,
      "name": "OrbisGalactic_Block_Imperial_Ship_Window_Bottom_Center",
      "rotation": 1
    },
    {
      "x": -7,
      "y": 1,
      "z": 11,
      "name": "OrbisGalactic_Block_Imperial_Ship_Window_Center",
      "rotation": 1
    },
    {
      "x": -7,
      "y": 2,
      "z": 11,
      "name": "OrbisGalactic_Block_Imperial_Ship_Window_Center",
      "rotation": 1
    },
    {
      "x": -7,
      "y": 3,
      "z": 11,
      "name": "OrbisGalactic_Block_Imperial_Ship_Window_Top_Center",
      "rotation": 1
    },
    {
      "x": -7,
      "y": 4,
      "z": 11,
      "name": "OrbisGalactic_Block_Imperial_Panel_Black_Brick_Horizontal",
      "rotation": 1
    },
    {
      "x": -7,
      "y": 5,
      "z": 11,
      "name": "OrbisGalactic_Block_ShipHull",
      "rotation": 1
    },
    {
      "x": -7,
      "y": -2,
      "z": 12,
      "name": "OrbisGalactic_Block_ShipHull",
      "rotation": 1
    },
    {
      "x": -7,
      "y": -1,
      "z": 12,
      "name": "OrbisGalactic_Block_Imperial_Panel_Black_Brick_Horizontal",
      "rotation": 3
    },
    {
      "x": -7,
      "y": 0,
      "z": 12,
      "name": "OrbisGalactic_Block_Imperial_Ship_Window_Bottom_Left",
      "rotation": 1
    },
    {
      "x": -7,
      "y": 1,
      "z": 12,
      "name": "OrbisGalactic_Block_Imperial_Ship_Window_Left_Center",
      "rotation": 1
    },
    {
      "x": -7,
      "y": 2,
      "z": 12,
      "name": "OrbisGalactic_Block_Imperial_Ship_Window_Left_Center",
      "rotation": 1
    },
    {
      "x": -7,
      "y": 3,
      "z": 12,
      "name": "OrbisGalactic_Block_Imperial_Ship_Window_Top_Left",
      "rotation": 1
    },
    {
      "x": -7,
      "y": 4,
      "z": 12,
      "name": "OrbisGalactic_Block_Imperial_Panel_Black_Brick_Horizontal",
      "rotation": 1
    },
    {
      "x": -7,
      "y": 5,
      "z": 12,
      "name": "OrbisGalactic_Block_ShipHull",
      "rotation": 1
    },
    {
      "x": -7,
      "y": -2,
      "z": 13,
      "name": "OrbisGalactic_Block_ShipHull",
      "rotation": 1
    },
    {
      "x": -7,
      "y": -1,
      "z": 13,
      "name": "OrbisGalactic_Block_Imperial_Panel_Black_Brick_Horizontal",
      "rotation": 3
    },
    {
      "x": -7,
      "y": 0,
      "z": 13,
      "name": "*OrbisGalactic_Block_Imperial_Lamp2_State_Definitions_On",
      "rotation": 1
    },
    {
      "x": -7,
      "y": 1,
      "z": 13,
      "name": "*OrbisGalactic_Block_Imperial_Lamp3_Connected_State_Definitions_On",
      "rotation": 1
    },
    {
      "x": -7,
      "y": 2,
      "z": 13,
      "name": "*OrbisGalactic_Block_Imperial_Lamp3_Connected_State_Definitions_On",
      "rotation": 1
    },
    {
      "x": -7,
      "y": 3,
      "z": 13,
      "name": "*OrbisGalactic_Block_Imperial_Lamp2_State_Definitions_On",
      "rotation": 1
    },
    {
      "x": -7,
      "y": 4,
      "z": 13,
      "name": "OrbisGalactic_Block_Imperial_Panel_Black_Smooth",
      "rotation": 1
    },
    {
      "x": -7,
      "y": 5,
      "z": 13,
      "name": "OrbisGalactic_Block_ShipHull",
      "rotation": 1
    },
    {
      "x": -7,
      "y": -2,
      "z": 14,
      "name": "OrbisGalactic_Block_ShipHull",
      "rotation": 1
    },
    {
      "x": -7,
      "y": -1,
      "z": 14,
      "name": "OrbisGalactic_Block_Imperial_Panel_Black_Brick_Horizontal",
      "rotation": 3
    },
    {
      "x": -7,
      "y": 0,
      "z": 14,
      "name": "OrbisGalactic_Block_Imperial_Ship_Window_Bottom_Right",
      "rotation": 1
    },
    {
      "x": -7,
      "y": 1,
      "z": 14,
      "name": "OrbisGalactic_Block_Imperial_Ship_Window_Right_Center",
      "rotation": 1
    },
    {
      "x": -7,
      "y": 2,
      "z": 14,
      "name": "OrbisGalactic_Block_Imperial_Ship_Window_Right_Center",
      "rotation": 1
    },
    {
      "x": -7,
      "y": 3,
      "z": 14,
      "name": "OrbisGalactic_Block_Imperial_Ship_Window_Top_Right",
      "rotation": 1
    },
    {
      "x": -7,
      "y": 4,
      "z": 14,
      "name": "OrbisGalactic_Block_Imperial_Panel_Black_Brick_Horizontal",
      "rotation": 1
    },
    {
      "x": -7,
      "y": 5,
      "z": 14,
      "name": "OrbisGalactic_Block_ShipHull",
      "rotation": 1
    },
    {
      "x": -7,
      "y": -2,
      "z": 15,
      "name": "OrbisGalactic_Block_ShipHull",
      "rotation": 1
    },
    {
      "x": -7,
      "y": -1,
      "z": 15,
      "name": "OrbisGalactic_Block_Imperial_Panel_Black_Brick_Horizontal",
      "rotation": 3
    },
    {
      "x": -7,
      "y": 0,
      "z": 15,
      "name": "OrbisGalactic_Block_Imperial_Ship_Window_Bottom_Center",
      "rotation": 1
    },
    {
      "x": -7,
      "y": 1,
      "z": 15,
      "name": "OrbisGalactic_Block_Imperial_Ship_Window_Center",
      "rotation": 1
    },
    {
      "x": -7,
      "y": 2,
      "z": 15,
      "name": "OrbisGalactic_Block_Imperial_Ship_Window_Center",
      "rotation": 1
    },
    {
      "x": -7,
      "y": 3,
      "z": 15,
      "name": "OrbisGalactic_Block_Imperial_Ship_Window_Top_Center",
      "rotation": 1
    },
    {
      "x": -7,
      "y": 4,
      "z": 15,
      "name": "OrbisGalactic_Block_Imperial_Panel_Black_Brick_Horizontal",
      "rotation": 1
    },
    {
      "x": -7,
      "y": 5,
      "z": 15,
      "name": "OrbisGalactic_Block_ShipHull",
      "rotation": 1
    },
    {
      "x": -7,
      "y": -2,
      "z": 16,
      "name": "OrbisGalactic_Block_ShipHull",
      "rotation": 1
    },
    {
      "x": -7,
      "y": -1,
      "z": 16,
      "name": "OrbisGalactic_Block_Imperial_Panel_Black_Brick_Horizontal",
      "rotation": 3
    },
    {
      "x": -7,
      "y": 0,
      "z": 16,
      "name": "OrbisGalactic_Block_Imperial_Ship_Window_Bottom_Left",
      "rotation": 1
    },
    {
      "x": -7,
      "y": 1,
      "z": 16,
      "name": "OrbisGalactic_Block_Imperial_Ship_Window_Left_Center",
      "rotation": 1
    },
    {
      "x": -7,
      "y": 2,
      "z": 16,
      "name": "OrbisGalactic_Block_Imperial_Ship_Window_Left_Center",
      "rotation": 1
    },
    {
      "x": -7,
      "y": 3,
      "z": 16,
      "name": "OrbisGalactic_Block_Imperial_Ship_Window_Top_Left",
      "rotation": 1
    },
    {
      "x": -7,
      "y": 4,
      "z": 16,
      "name": "OrbisGalactic_Block_Imperial_Panel_Black_Brick_Horizontal",
      "rotation": 1
    },
    {
      "x": -7,
      "y": 5,
      "z": 16,
      "name": "OrbisGalactic_Block_ShipHull",
      "rotation": 1
    },
    {
      "x": -7,
      "y": -2,
      "z": 17,
      "name": "OrbisGalactic_Block_ShipHull",
      "rotation": 1
    },
    {
      "x": -7,
      "y": -1,
      "z": 17,
      "name": "OrbisGalactic_Block_Imperial_Panel_Black_Brick_Vertical",
      "rotation": 3
    },
    {
      "x": -7,
      "y": 0,
      "z": 17,
      "name": "OrbisGalactic_Block_Imperial_Panel_Black_Brick_Vertical",
      "rotation": 3
    },
    {
      "x": -7,
      "y": 1,
      "z": 17,
      "name": "OrbisGalactic_Block_Imperial_Panel_Black_Brick_Vertical",
      "rotation": 3
    },
    {
      "x": -7,
      "y": 2,
      "z": 17,
      "name": "OrbisGalactic_Block_Imperial_Panel_Black_Brick_Vertical",
      "rotation": 3
    },
    {
      "x": -7,
      "y": 3,
      "z": 17,
      "name": "OrbisGalactic_Block_Imperial_Panel_Black_Brick_Vertical",
      "rotation": 3
    },
    {
      "x": -7,
      "y": 4,
      "z": 17,
      "name": "OrbisGalactic_Block_Imperial_Panel_Black_Brick_Vertical",
      "rotation": 3
    },
    {
      "x": -7,
      "y": 5,
      "z": 17,
      "name": "OrbisGalactic_Block_ShipHull",
      "rotation": 1
    },
    {
      "x": -7,
      "y": -2,
      "z": 18,
      "name": "OrbisGalactic_Block_ShipHull",
      "rotation": 1
    },
    {
      "x": -7,
      "y": -1,
      "z": 18,
      "name": "OrbisGalactic_Block_ShipHull",
      "rotation": 1
    },
    {
      "x": -7,
      "y": 0,
      "z": 18,
      "name": "OrbisGalactic_Block_ShipHull",
      "rotation": 1
    },
    {
      "x": -7,
      "y": 1,
      "z": 18,
      "name": "OrbisGalactic_Block_ShipHull",
      "rotation": 1
    },
    {
      "x": -7,
      "y": 2,
      "z": 18,
      "name": "OrbisGalactic_Block_ShipHull",
      "rotation": 1
    },
    {
      "x": -7,
      "y": 3,
      "z": 18,
      "name": "OrbisGalactic_Block_ShipHull",
      "rotation": 1
    },
    {
      "x": -7,
      "y": 4,
      "z": 18,
      "name": "OrbisGalactic_Block_ShipHull",
      "rotation": 1
    },
    {
      "x": -7,
      "y": 5,
      "z": 18,
      "name": "OrbisGalactic_Block_ShipHull",
      "rotation": 1
    },
    {
      "x": -7,
      "y": -2,
      "z": 19,
      "name": "OrbisGalactic_Block_ShipHull",
      "rotation": 1
    },
    {
      "x": -7,
      "y": -1,
      "z": 19,
      "name": "OrbisGalactic_Block_ShipHull",
      "rotation": 1
    },
    {
      "x": -7,
      "y": 4,
      "z": 19,
      "name": "OrbisGalactic_Block_ShipHull",
      "rotation": 1
    },
    {
      "x": -7,
      "y": 5,
      "z": 19,
      "name": "OrbisGalactic_Block_ShipHull",
      "rotation": 1
    },
    {
      "x": -7,
      "y": -2,
      "z": 20,
      "name": "OrbisGalactic_Block_ShipHull",
      "rotation": 1
    },
    {
      "x": -7,
      "y": -1,
      "z": 20,
      "name": "OrbisGalactic_Block_ShipHull",
      "rotation": 1
    },
    {
      "x": -7,
      "y": 4,
      "z": 20,
      "name": "OrbisGalactic_Block_ShipHull",
      "rotation": 1
    },
    {
      "x": -7,
      "y": 5,
      "z": 20,
      "name": "OrbisGalactic_Block_ShipHull",
      "rotation": 1
    },
    {
      "x": -7,
      "y": -2,
      "z": 21,
      "name": "OrbisGalactic_Block_ShipHull",
      "rotation": 1
    },
    {
      "x": -7,
      "y": -1,
      "z": 21,
      "name": "OrbisGalactic_Block_ShipHull",
      "rotation": 1
    },
    {
      "x": -7,
      "y": 4,
      "z": 21,
      "name": "OrbisGalactic_Block_ShipHull",
      "rotation": 1
    },
    {
      "x": -7,
      "y": 5,
      "z": 21,
      "name": "OrbisGalactic_Block_ShipHull",
      "rotation": 1
    },
    {
      "x": -7,
      "y": -3,
      "z": 22,
      "name": "OrbisGalactic_Block_ShipHull",
      "rotation": 1
    },
    {
      "x": -7,
      "y": -2,
      "z": 22,
      "name": "OrbisGalactic_Block_ShipHull",
      "rotation": 1
    },
    {
      "x": -7,
      "y": -1,
      "z": 22,
      "name": "OrbisGalactic_Block_ShipHull",
      "rotation": 1
    },
    {
      "x": -7,
      "y": 0,
      "z": 22,
      "name": "OrbisGalactic_Block_ShipHull",
      "rotation": 1
    },
    {
      "x": -7,
      "y": 1,
      "z": 22,
      "name": "OrbisGalactic_Block_ShipHull",
      "rotation": 1
    },
    {
      "x": -7,
      "y": 2,
      "z": 22,
      "name": "OrbisGalactic_Block_ShipHull",
      "rotation": 1
    },
    {
      "x": -7,
      "y": 3,
      "z": 22,
      "name": "OrbisGalactic_Block_ShipHull",
      "rotation": 1
    },
    {
      "x": -7,
      "y": 4,
      "z": 22,
      "name": "OrbisGalactic_Block_ShipHull",
      "rotation": 1
    },
    {
      "x": -7,
      "y": 5,
      "z": 22,
      "name": "OrbisGalactic_Block_ShipHull",
      "rotation": 1
    },
    {
      "x": -7,
      "y": -3,
      "z": 23,
      "name": "OrbisGalactic_Block_ShipHull",
      "rotation": 1
    },
    {
      "x": -7,
      "y": -2,
      "z": 23,
      "name": "OrbisGalactic_Block_ShipHull",
      "rotation": 1
    },
    {
      "x": -7,
      "y": -1,
      "z": 23,
      "name": "OrbisGalactic_Block_Imperial_Panel_Gray_Brick_Vertical",
      "rotation": 2
    },
    {
      "x": -7,
      "y": 0,
      "z": 23,
      "name": "*OrbisGalactic_Block_Imperial_Lamp3_Connected_State_Definitions_On",
      "rotation": 1
    },
    {
      "x": -7,
      "y": 1,
      "z": 23,
      "name": "*OrbisGalactic_Block_Imperial_Lamp3_Connected_State_Definitions_On",
      "rotation": 1
    },
    {
      "x": -7,
      "y": 2,
      "z": 23,
      "name": "*OrbisGalactic_Block_Imperial_Lamp3_Connected_State_Definitions_On",
      "rotation": 1
    },
    {
      "x": -7,
      "y": 3,
      "z": 23,
      "name": "*OrbisGalactic_Block_Imperial_Lamp3_Connected_State_Definitions_On",
      "rotation": 1
    },
    {
      "x": -7,
      "y": 4,
      "z": 23,
      "name": "*OrbisGalactic_Block_Imperial_Lamp3_Connected_State_Definitions_On",
      "rotation": 1
    },
    {
      "x": -7,
      "y": 5,
      "z": 23,
      "name": "OrbisGalactic_Block_Imperial_Panel_Black_Smooth",
      "rotation": 3
    },
    {
      "x": -7,
      "y": 6,
      "z": 23,
      "name": "OrbisGalactic_Block_ShipHull",
      "rotation": 1
    },
    {
      "x": -7,
      "y": -3,
      "z": 24,
      "name": "OrbisGalactic_Block_ShipHull",
      "rotation": 1
    },
    {
      "x": -7,
      "y": -2,
      "z": 24,
      "name": "OrbisGalactic_Block_ShipHull",
      "rotation": 1
    },
    {
      "x": -7,
      "y": -1,
      "z": 24,
      "name": "*OrbisGalactic_Block_Imperial_Lamp1_State_Definitions_On",
      "rotation": 2
    },
    {
      "x": -7,
      "y": 0,
      "z": 24,
      "name": "OrbisGalactic_Imperial_Railing_Gray",
      "support": 15,
      "rotation": 3
    },
    {
      "x": -7,
      "y": 5,
      "z": 24,
      "name": "OrbisGalactic_Block_Imperial_Panel_Black_Brick_Vertical"
    },
    {
      "x": -7,
      "y": 6,
      "z": 24,
      "name": "OrbisGalactic_Block_ShipHull",
      "rotation": 1
    },
    {
      "x": -7,
      "y": -3,
      "z": 25,
      "name": "OrbisGalactic_Block_ShipHull",
      "rotation": 1
    },
    {
      "x": -7,
      "y": -2,
      "z": 25,
      "name": "OrbisGalactic_Block_ShipHull",
      "rotation": 1
    },
    {
      "x": -7,
      "y": -1,
      "z": 25,
      "name": "OrbisGalactic_Block_Imperial_Panel_Gray_Brick_Vertical",
      "rotation": 2
    },
    {
      "x": -7,
      "y": 0,
      "z": 25,
      "name": "OrbisGalactic_Imperial_Railing_Gray",
      "support": 15,
      "rotation": 3
    },
    {
      "x": -7,
      "y": 5,
      "z": 25,
      "name": "OrbisGalactic_Block_Imperial_Panel_Black_Brick_Vertical"
    },
    {
      "x": -7,
      "y": 6,
      "z": 25,
      "name": "OrbisGalactic_Block_ShipHull",
      "rotation": 1
    },
    {
      "x": -7,
      "y": -3,
      "z": 26,
      "name": "OrbisGalactic_Block_ShipHull",
      "rotation": 1
    },
    {
      "x": -7,
      "y": -2,
      "z": 26,
      "name": "OrbisGalactic_Block_ShipHull",
      "rotation": 1
    },
    {
      "x": -7,
      "y": -1,
      "z": 26,
      "name": "OrbisGalactic_Block_Imperial_Panel_Gray_Brick_Vertical",
      "rotation": 2
    },
    {
      "x": -7,
      "y": 0,
      "z": 26,
      "name": "OrbisGalactic_Imperial_Railing_Gray",
      "support": 15,
      "rotation": 3
    },
    {
      "x": -7,
      "y": 5,
      "z": 26,
      "name": "OrbisGalactic_Block_Imperial_Panel_Black_Brick_Vertical"
    },
    {
      "x": -7,
      "y": 6,
      "z": 26,
      "name": "OrbisGalactic_Block_ShipHull",
      "rotation": 1
    },
    {
      "x": -7,
      "y": -3,
      "z": 27,
      "name": "OrbisGalactic_Block_ShipHull",
      "rotation": 1
    },
    {
      "x": -7,
      "y": -2,
      "z": 27,
      "name": "OrbisGalactic_Block_ShipHull",
      "rotation": 1
    },
    {
      "x": -7,
      "y": -1,
      "z": 27,
      "name": "OrbisGalactic_Block_Imperial_Panel_Gray_Brick_Vertical",
      "rotation": 2
    },
    {
      "x": -7,
      "y": 0,
      "z": 27,
      "name": "OrbisGalactic_Imperial_Railing_Gray",
      "support": 15,
      "rotation": 3
    },
    {
      "x": -7,
      "y": 5,
      "z": 27,
      "name": "OrbisGalactic_Block_Imperial_Panel_Black_Brick_Vertical"
    },
    {
      "x": -7,
      "y": 6,
      "z": 27,
      "name": "OrbisGalactic_Block_ShipHull",
      "rotation": 1
    },
    {
      "x": -7,
      "y": -3,
      "z": 28,
      "name": "OrbisGalactic_Block_ShipHull",
      "rotation": 1
    },
    {
      "x": -7,
      "y": -2,
      "z": 28,
      "name": "OrbisGalactic_Block_ShipHull",
      "rotation": 1
    },
    {
      "x": -7,
      "y": -1,
      "z": 28,
      "name": "OrbisGalactic_Block_Imperial_Panel_Gray_Brick_Vertical",
      "rotation": 2
    },
    {
      "x": -7,
      "y": 0,
      "z": 28,
      "name": "OrbisGalactic_Imperial_Railing_Gray",
      "support": 15,
      "rotation": 3
    },
    {
      "x": -7,
      "y": 5,
      "z": 28,
      "name": "OrbisGalactic_Block_Imperial_Panel_Black_Brick_Vertical"
    },
    {
      "x": -7,
      "y": 6,
      "z": 28,
      "name": "OrbisGalactic_Block_ShipHull",
      "rotation": 1
    },
    {
      "x": -7,
      "y": -3,
      "z": 29,
      "name": "OrbisGalactic_Block_ShipHull",
      "rotation": 1
    },
    {
      "x": -7,
      "y": -2,
      "z": 29,
      "name": "OrbisGalactic_Block_ShipHull",
      "rotation": 1
    },
    {
      "x": -7,
      "y": -1,
      "z": 29,
      "name": "OrbisGalactic_Block_Imperial_Panel_Gray_Brick_Vertical",
      "rotation": 2
    },
    {
      "x": -7,
      "y": 5,
      "z": 29,
      "name": "OrbisGalactic_Block_Imperial_Panel_Black_Smooth"
    },
    {
      "x": -7,
      "y": 6,
      "z": 29,
      "name": "OrbisGalactic_Block_ShipHull",
      "rotation": 1
    },
    {
      "x": -7,
      "y": -3,
      "z": 30,
      "name": "OrbisGalactic_Block_ShipHull",
      "rotation": 1
    },
    {
      "x": -7,
      "y": -2,
      "z": 30,
      "name": "OrbisGalactic_Block_ShipHull",
      "rotation": 1
    },
    {
      "x": -7,
      "y": -1,
      "z": 30,
      "name": "OrbisGalactic_Block_Imperial_Panel_Black_Brick_Vertical",
      "rotation": 2
    },
    {
      "x": -7,
      "y": 0,
      "z": 30,
      "name": "OrbisGalactic_Block_Imperial_Panel_Black_Brick_Vertical",
      "rotation": 1
    },
    {
      "x": -7,
      "y": 1,
      "z": 30,
      "name": "OrbisGalactic_Block_Imperial_Panel_Black_Brick_Vertical",
      "rotation": 1
    },
    {
      "x": -7,
      "y": 2,
      "z": 30,
      "name": "OrbisGalactic_Block_Imperial_Panel_Black_Brick_Vertical",
      "rotation": 1
    },
    {
      "x": -7,
      "y": 3,
      "z": 30,
      "name": "OrbisGalactic_Block_Imperial_Panel_Black_Brick_Vertical",
      "rotation": 1
    },
    {
      "x": -7,
      "y": 4,
      "z": 30,
      "name": "OrbisGalactic_Block_Imperial_Panel_Black_Brick_Horizontal",
      "rotation": 2
    },
    {
      "x": -7,
      "y": 5,
      "z": 30,
      "name": "OrbisGalactic_Block_ShipHull",
      "rotation": 1
    },
    {
      "x": -7,
      "y": 6,
      "z": 30,
      "name": "OrbisGalactic_Block_ShipHull",
      "rotation": 1
    },
    {
      "x": -7,
      "y": -3,
      "z": 31,
      "name": "OrbisGalactic_Block_ShipHull",
      "rotation": 1
    },
    {
      "x": -7,
      "y": -2,
      "z": 31,
      "name": "OrbisGalactic_Block_ShipHull",
      "rotation": 1
    },
    {
      "x": -7,
      "y": -1,
      "z": 31,
      "name": "OrbisGalactic_Block_Imperial_Panel_Black_Brick_Vertical"
    },
    {
      "x": -7,
      "y": 0,
      "z": 31,
      "name": "OrbisGalactic_Block_ShipHull",
      "rotation": 1
    },
    {
      "x": -7,
      "y": 1,
      "z": 31,
      "name": "OrbisGalactic_Block_ShipHull",
      "rotation": 1
    },
    {
      "x": -7,
      "y": 2,
      "z": 31,
      "name": "OrbisGalactic_Block_ShipHull",
      "rotation": 1
    },
    {
      "x": -7,
      "y": 3,
      "z": 31,
      "name": "OrbisGalactic_Block_ShipHull",
      "rotation": 1
    },
    {
      "x": -7,
      "y": 4,
      "z": 31,
      "name": "OrbisGalactic_Block_ShipHull",
      "rotation": 1
    },
    {
      "x": -7,
      "y": 5,
      "z": 31,
      "name": "OrbisGalactic_Block_ShipHull",
      "rotation": 1
    },
    {
      "x": -7,
      "y": -3,
      "z": 32,
      "name": "OrbisGalactic_Block_ShipHull",
      "rotation": 1
    },
    {
      "x": -7,
      "y": -2,
      "z": 32,
      "name": "OrbisGalactic_Block_ShipHull",
      "rotation": 1
    },
    {
      "x": -7,
      "y": -1,
      "z": 32,
      "name": "OrbisGalactic_Block_Imperial_Panel_Black_Brick_Vertical"
    },
    {
      "x": -7,
      "y": -2,
      "z": 33,
      "name": "OrbisGalactic_Block_ShipHull",
      "rotation": 1
    },
    {
      "x": -7,
      "y": -1,
      "z": 33,
      "name": "OrbisGalactic_Block_ShipHull",
      "rotation": 1
    },
    {
      "x": -7,
      "y": -2,
      "z": 34,
      "name": "OrbisGalactic_Block_Imperial_Panel_Black_Brick_Horizontal",
      "rotation": 3
    },
    {
      "x": -6,
      "y": -1,
      "z": -5,
      "name": "OrbisGalactic_Block_ShipHull",
      "rotation": 1
    },
    {
      "x": -6,
      "y": 0,
      "z": -5,
      "name": "OrbisGalactic_Block_ShipHull",
      "rotation": 1
    },
    {
      "x": -6,
      "y": 1,
      "z": -5,
      "name": "OrbisGalactic_Block_ShipHull",
      "rotation": 1
    },
    {
      "x": -6,
      "y": 2,
      "z": -5,
      "name": "OrbisGalactic_Block_ShipHull",
      "rotation": 1
    },
    {
      "x": -6,
      "y": 3,
      "z": -5,
      "name": "OrbisGalactic_Block_ShipHull",
      "rotation": 1
    },
    {
      "x": -6,
      "y": 4,
      "z": -5,
      "name": "OrbisGalactic_Block_ShipHull",
      "rotation": 1
    },
    {
      "x": -6,
      "y": 5,
      "z": -5,
      "name": "OrbisGalactic_Block_ShipHull",
      "rotation": 1
    },
    {
      "x": -6,
      "y": -1,
      "z": -4,
      "name": "OrbisGalactic_Block_ShipHull",
      "rotation": 1
    },
    {
      "x": -6,
      "y": 0,
      "z": -4,
      "name": "OrbisGalactic_Block_ShipHull",
      "rotation": 1
    },
    {
      "x": -6,
      "y": 1,
      "z": -4,
      "name": "OrbisGalactic_Block_ShipHull",
      "rotation": 1
    },
    {
      "x": -6,
      "y": 2,
      "z": -4,
      "name": "OrbisGalactic_Block_ShipHull",
      "rotation": 1
    },
    {
      "x": -6,
      "y": 3,
      "z": -4,
      "name": "OrbisGalactic_Block_ShipHull",
      "rotation": 1
    },
    {
      "x": -6,
      "y": 4,
      "z": -4,
      "name": "OrbisGalactic_Block_ShipHull",
      "rotation": 1
    },
    {
      "x": -6,
      "y": 5,
      "z": -4,
      "name": "OrbisGalactic_Block_ShipHull",
      "rotation": 1
    },
    {
      "x": -6,
      "y": -1,
      "z": -3,
      "name": "OrbisGalactic_Block_ShipHull",
      "rotation": 1
    },
    {
      "x": -6,
      "y": 0,
      "z": -3,
      "name": "OrbisGalactic_Block_ShipHull",
      "rotation": 1
    },
    {
      "x": -6,
      "y": 1,
      "z": -3,
      "name": "OrbisGalactic_Block_ShipHull",
      "rotation": 1
    },
    {
      "x": -6,
      "y": 2,
      "z": -3,
      "name": "OrbisGalactic_Block_ShipHull",
      "rotation": 1
    },
    {
      "x": -6,
      "y": 3,
      "z": -3,
      "name": "OrbisGalactic_Block_ShipHull",
      "rotation": 1
    },
    {
      "x": -6,
      "y": 4,
      "z": -3,
      "name": "OrbisGalactic_Block_ShipHull",
      "rotation": 1
    },
    {
      "x": -6,
      "y": 5,
      "z": -3,
      "name": "OrbisGalactic_Block_ShipHull",
      "rotation": 1
    },
    {
      "x": -6,
      "y": -1,
      "z": -2,
      "name": "OrbisGalactic_Block_ShipHull",
      "rotation": 1
    },
    {
      "x": -6,
      "y": 0,
      "z": -2,
      "name": "OrbisGalactic_Block_ShipHull",
      "rotation": 1
    },
    {
      "x": -6,
      "y": 1,
      "z": -2,
      "name": "OrbisGalactic_Block_ShipHull",
      "rotation": 1
    },
    {
      "x": -6,
      "y": 2,
      "z": -2,
      "name": "OrbisGalactic_Block_ShipHull",
      "rotation": 1
    },
    {
      "x": -6,
      "y": 3,
      "z": -2,
      "name": "OrbisGalactic_Block_ShipHull",
      "rotation": 1
    },
    {
      "x": -6,
      "y": 4,
      "z": -2,
      "name": "OrbisGalactic_Block_ShipHull",
      "rotation": 1
    },
    {
      "x": -6,
      "y": 5,
      "z": -2,
      "name": "OrbisGalactic_Block_ShipHull",
      "rotation": 1
    },
    {
      "x": -6,
      "y": -1,
      "z": -1,
      "name": "OrbisGalactic_Block_ShipHull",
      "rotation": 1
    },
    {
      "x": -6,
      "y": 0,
      "z": -1,
      "name": "OrbisGalactic_Block_Imperial_Panel_Black_Brick_Vertical",
      "rotation": 3
    },
    {
      "x": -6,
      "y": 1,
      "z": -1,
      "name": "OrbisGalactic_Block_Imperial_Panel_Black_Brick_Vertical",
      "rotation": 1
    },
    {
      "x": -6,
      "y": 2,
      "z": -1,
      "name": "OrbisGalactic_Block_Imperial_Panel_Black_Brick_Vertical",
      "rotation": 1
    },
    {
      "x": -6,
      "y": 3,
      "z": -1,
      "name": "OrbisGalactic_Block_ShipHull",
      "rotation": 1
    },
    {
      "x": -6,
      "y": 4,
      "z": -1,
      "name": "OrbisGalactic_Block_ShipHull",
      "rotation": 1
    },
    {
      "x": -6,
      "y": 5,
      "z": -1,
      "name": "OrbisGalactic_Block_ShipHull",
      "rotation": 1
    },
    {
      "x": -6,
      "y": -1,
      "z": 0,
      "name": "OrbisGalactic_Block_ShipHull",
      "rotation": 1
    },
    {
      "x": -6,
      "y": 0,
      "z": 0,
      "name": "OrbisGalactic_Block_Imperial_Panel_Black_Brick_Vertical",
      "rotation": 3
    },
    {
      "x": -6,
      "y": 1,
      "z": 0,
      "name": "OrbisGalactic_Block_Imperial_Panel_Black_Brick_Vertical",
      "rotation": 3
    },
    {
      "x": -6,
      "y": 2,
      "z": 0,
      "name": "OrbisGalactic_Block_Imperial_Panel_Black_Brick_Vertical",
      "rotation": 3
    },
    {
      "x": -6,
      "y": 3,
      "z": 0,
      "name": "OrbisGalactic_Block_ShipHull",
      "rotation": 1
    },
    {
      "x": -6,
      "y": 4,
      "z": 0,
      "name": "OrbisGalactic_Block_ShipHull",
      "rotation": 1
    },
    {
      "x": -6,
      "y": 5,
      "z": 0,
      "name": "OrbisGalactic_Block_ShipHull",
      "rotation": 1
    },
    {
      "x": -6,
      "y": -1,
      "z": 1,
      "name": "OrbisGalactic_Block_ShipHull",
      "rotation": 1
    },
    {
      "x": -6,
      "y": 0,
      "z": 1,
      "name": "OrbisGalactic_Block_Imperial_Panel_Black_Brick_Vertical",
      "rotation": 3
    },
    {
      "x": -6,
      "y": 1,
      "z": 1,
      "name": "OrbisGalactic_Block_Imperial_Panel_Black_Brick_Vertical",
      "rotation": 3
    },
    {
      "x": -6,
      "y": 2,
      "z": 1,
      "name": "OrbisGalactic_Block_Imperial_Panel_Black_Brick_Vertical",
      "rotation": 3
    },
    {
      "x": -6,
      "y": 3,
      "z": 1,
      "name": "OrbisGalactic_Block_ShipHull",
      "rotation": 1
    },
    {
      "x": -6,
      "y": 4,
      "z": 1,
      "name": "OrbisGalactic_Block_ShipHull",
      "rotation": 1
    },
    {
      "x": -6,
      "y": 5,
      "z": 1,
      "name": "OrbisGalactic_Block_ShipHull",
      "rotation": 1
    },
    {
      "x": -6,
      "y": -1,
      "z": 2,
      "name": "OrbisGalactic_Block_ShipHull",
      "rotation": 1
    },
    {
      "x": -6,
      "y": 0,
      "z": 2,
      "name": "OrbisGalactic_Block_ShipHull",
      "rotation": 1
    },
    {
      "x": -6,
      "y": 1,
      "z": 2,
      "name": "OrbisGalactic_Block_ShipHull",
      "rotation": 1
    },
    {
      "x": -6,
      "y": 2,
      "z": 2,
      "name": "OrbisGalactic_Block_ShipHull",
      "rotation": 1
    },
    {
      "x": -6,
      "y": 3,
      "z": 2,
      "name": "OrbisGalactic_Block_ShipHull",
      "rotation": 1
    },
    {
      "x": -6,
      "y": 4,
      "z": 2,
      "name": "OrbisGalactic_Block_ShipHull",
      "rotation": 1
    },
    {
      "x": -6,
      "y": 5,
      "z": 2,
      "name": "OrbisGalactic_Block_ShipHull",
      "rotation": 1
    },
    {
      "x": -6,
      "y": -1,
      "z": 3,
      "name": "OrbisGalactic_Block_ShipHull",
      "rotation": 1
    },
    {
      "x": -6,
      "y": 0,
      "z": 3,
      "name": "OrbisGalactic_Block_ShipHull",
      "rotation": 1
    },
    {
      "x": -6,
      "y": 1,
      "z": 3,
      "name": "OrbisGalactic_Block_ShipHull",
      "rotation": 1
    },
    {
      "x": -6,
      "y": 2,
      "z": 3,
      "name": "OrbisGalactic_Block_ShipHull",
      "rotation": 1
    },
    {
      "x": -6,
      "y": 3,
      "z": 3,
      "name": "OrbisGalactic_Block_ShipHull",
      "rotation": 1
    },
    {
      "x": -6,
      "y": 4,
      "z": 3,
      "name": "OrbisGalactic_Block_ShipHull",
      "rotation": 1
    },
    {
      "x": -6,
      "y": 5,
      "z": 3,
      "name": "OrbisGalactic_Block_ShipHull",
      "rotation": 1
    },
    {
      "x": -6,
      "y": -2,
      "z": 4,
      "name": "OrbisGalactic_Block_ShipHull",
      "rotation": 1
    },
    {
      "x": -6,
      "y": -1,
      "z": 4,
      "name": "OrbisGalactic_Block_ShipHull",
      "rotation": 1
    },
    {
      "x": -6,
      "y": 0,
      "z": 4,
      "name": "OrbisGalactic_Block_ShipHull",
      "rotation": 1
    },
    {
      "x": -6,
      "y": 1,
      "z": 4,
      "name": "OrbisGalactic_Block_ShipHull",
      "rotation": 1
    },
    {
      "x": -6,
      "y": 2,
      "z": 4,
      "name": "OrbisGalactic_Block_ShipHull",
      "rotation": 1
    },
    {
      "x": -6,
      "y": 3,
      "z": 4,
      "name": "OrbisGalactic_Block_ShipHull",
      "rotation": 1
    },
    {
      "x": -6,
      "y": 4,
      "z": 4,
      "name": "OrbisGalactic_Block_ShipHull",
      "rotation": 1
    },
    {
      "x": -6,
      "y": 5,
      "z": 4,
      "name": "OrbisGalactic_Block_ShipHull",
      "rotation": 1
    },
    {
      "x": -6,
      "y": -2,
      "z": 5,
      "name": "OrbisGalactic_Block_ShipHull",
      "rotation": 1
    },
    {
      "x": -6,
      "y": -1,
      "z": 5,
      "name": "OrbisGalactic_Block_Imperial_Panel_Gray_Brick_Vertical",
      "rotation": 3
    },
    {
      "x": -6,
      "y": 0,
      "z": 5,
      "name": "OrbisGalactic_Block_Imperial_Panel_Light_Gray_Brick_Vertical"
    },
    {
      "x": -6,
      "y": 1,
      "z": 5,
      "name": "OrbisGalactic_Block_Imperial_Panel_Light_Gray_Brick_Vertical"
    },
    {
      "x": -6,
      "y": 2,
      "z": 5,
      "name": "OrbisGalactic_Block_Imperial_Panel_Light_Gray_Brick_Vertical"
    },
    {
      "x": -6,
      "y": 3,
      "z": 5,
      "name": "OrbisGalactic_Block_Imperial_Panel_Light_Gray_Brick_Vertical"
    },
    {
      "x": -6,
      "y": 4,
      "z": 5,
      "name": "OrbisGalactic_Block_Imperial_Panel_Black_Brick_Horizontal"
    },
    {
      "x": -6,
      "y": 5,
      "z": 5,
      "name": "OrbisGalactic_Block_ShipHull",
      "rotation": 1
    },
    {
      "x": -6,
      "y": -2,
      "z": 6,
      "name": "OrbisGalactic_Block_ShipHull",
      "rotation": 1
    },
    {
      "x": -6,
      "y": -1,
      "z": 6,
      "name": "OrbisGalactic_Block_Imperial_Floor_Pattern_Bar_Corner_Inverted"
    },
    {
      "x": -6,
      "y": 5,
      "z": 6,
      "name": "OrbisGalactic_Block_Imperial_Panel_Black_Smooth",
      "rotation": 1
    },
    {
      "x": -6,
      "y": 6,
      "z": 6,
      "name": "OrbisGalactic_Block_ShipHull",
      "rotation": 1
    },
    {
      "x": -6,
      "y": -2,
      "z": 7,
      "name": "OrbisGalactic_Block_ShipHull",
      "rotation": 1
    },
    {
      "x": -6,
      "y": -1,
      "z": 7,
      "name": "OrbisGalactic_Block_Imperial_Floor_Pattern_Bar_Top",
      "rotation": 3
    },
    {
      "x": -6,
      "y": 5,
      "z": 7,
      "name": "OrbisGalactic_Block_Imperial_Panel_Black_Brick_Vertical",
      "rotation": 2
    },
    {
      "x": -6,
      "y": 6,
      "z": 7,
      "name": "OrbisGalactic_Block_ShipHull",
      "rotation": 1
    },
    {
      "x": -6,
      "y": -2,
      "z": 8,
      "name": "OrbisGalactic_Block_ShipHull",
      "rotation": 1
    },
    {
      "x": -6,
      "y": -1,
      "z": 8,
      "name": "OrbisGalactic_Block_Imperial_Floor_Pattern_Bar_Top",
      "rotation": 3
    },
    {
      "x": -6,
      "y": 5,
      "z": 8,
      "name": "OrbisGalactic_Block_Imperial_Panel_Black_Brick_Vertical",
      "rotation": 2
    },
    {
      "x": -6,
      "y": 6,
      "z": 8,
      "name": "OrbisGalactic_Block_ShipHull",
      "rotation": 1
    },
    {
      "x": -6,
      "y": -2,
      "z": 9,
      "name": "OrbisGalactic_Block_ShipHull",
      "rotation": 1
    },
    {
      "x": -6,
      "y": -1,
      "z": 9,
      "name": "OrbisGalactic_Block_Imperial_Floor_Pattern_Bar_Top",
      "rotation": 3
    },
    {
      "x": -6,
      "y": 5,
      "z": 9,
      "name": "OrbisGalactic_Block_Imperial_Panel_Black_Brick_Vertical",
      "rotation": 2
    },
    {
      "x": -6,
      "y": 6,
      "z": 9,
      "name": "OrbisGalactic_Block_ShipHull",
      "rotation": 1
    },
    {
      "x": -6,
      "y": -2,
      "z": 10,
      "name": "OrbisGalactic_Block_ShipHull",
      "rotation": 1
    },
    {
      "x": -6,
      "y": -1,
      "z": 10,
      "name": "OrbisGalactic_Block_Imperial_Floor_Pattern_Bar_Top",
      "rotation": 3
    },
    {
      "x": -6,
      "y": 5,
      "z": 10,
      "name": "OrbisGalactic_Block_Imperial_Panel_Black_Brick_Vertical",
      "rotation": 2
    },
    {
      "x": -6,
      "y": 6,
      "z": 10,
      "name": "OrbisGalactic_Block_ShipHull",
      "rotation": 1
    },
    {
      "x": -6,
      "y": -2,
      "z": 11,
      "name": "OrbisGalactic_Block_ShipHull",
      "rotation": 1
    },
    {
      "x": -6,
      "y": -1,
      "z": 11,
      "name": "OrbisGalactic_Block_Imperial_Floor_Pattern_Bar_Top",
      "rotation": 3
    },
    {
      "x": -6,
      "y": 5,
      "z": 11,
      "name": "OrbisGalactic_Block_Imperial_Panel_Black_Brick_Vertical",
      "rotation": 2
    },
    {
      "x": -6,
      "y": 6,
      "z": 11,
      "name": "OrbisGalactic_Block_ShipHull",
      "rotation": 1
    },
    {
      "x": -6,
      "y": -2,
      "z": 12,
      "name": "OrbisGalactic_Block_ShipHull",
      "rotation": 1
    },
    {
      "x": -6,
      "y": -1,
      "z": 12,
      "name": "OrbisGalactic_Block_Imperial_Floor_Pattern_Bar_Top",
      "rotation": 3
    },
    {
      "x": -6,
      "y": 5,
      "z": 12,
      "name": "OrbisGalactic_Block_Imperial_Panel_Black_Brick_Vertical",
      "rotation": 2
    },
    {
      "x": -6,
      "y": 6,
      "z": 12,
      "name": "OrbisGalactic_Block_ShipHull",
      "rotation": 1
    },
    {
      "x": -6,
      "y": -2,
      "z": 13,
      "name": "OrbisGalactic_Block_ShipHull",
      "rotation": 1
    },
    {
      "x": -6,
      "y": -1,
      "z": 13,
      "name": "OrbisGalactic_Block_Imperial_Floor_Pattern_Bar_Top",
      "rotation": 3
    },
    {
      "x": -6,
      "y": 5,
      "z": 13,
      "name": "OrbisGalactic_Block_Imperial_Panel_Black_Brick_Vertical",
      "rotation": 2
    },
    {
      "x": -6,
      "y": 6,
      "z": 13,
      "name": "OrbisGalactic_Block_ShipHull",
      "rotation": 1
    },
    {
      "x": -6,
      "y": -2,
      "z": 14,
      "name": "OrbisGalactic_Block_ShipHull",
      "rotation": 1
    },
    {
      "x": -6,
      "y": -1,
      "z": 14,
      "name": "OrbisGalactic_Block_Imperial_Floor_Pattern_Bar_Top",
      "rotation": 3
    },
    {
      "x": -6,
      "y": 5,
      "z": 14,
      "name": "OrbisGalactic_Block_Imperial_Panel_Black_Brick_Vertical",
      "rotation": 2
    },
    {
      "x": -6,
      "y": 6,
      "z": 14,
      "name": "OrbisGalactic_Block_ShipHull",
      "rotation": 1
    },
    {
      "x": -6,
      "y": -2,
      "z": 15,
      "name": "OrbisGalactic_Block_ShipHull",
      "rotation": 1
    },
    {
      "x": -6,
      "y": -1,
      "z": 15,
      "name": "OrbisGalactic_Block_Imperial_Floor_Pattern_Bar_Top",
      "rotation": 3
    },
    {
      "x": -6,
      "y": 5,
      "z": 15,
      "name": "OrbisGalactic_Block_Imperial_Panel_Black_Brick_Vertical",
      "rotation": 2
    },
    {
      "x": -6,
      "y": 6,
      "z": 15,
      "name": "OrbisGalactic_Block_ShipHull",
      "rotation": 1
    },
    {
      "x": -6,
      "y": -2,
      "z": 16,
      "name": "OrbisGalactic_Block_ShipHull",
      "rotation": 1
    },
    {
      "x": -6,
      "y": -1,
      "z": 16,
      "name": "OrbisGalactic_Block_Imperial_Floor_Pattern_Bar_Corner_Inverted",
      "rotation": 3
    },
    {
      "x": -6,
      "y": 5,
      "z": 16,
      "name": "OrbisGalactic_Block_Imperial_Panel_Black_Brick_Vertical",
      "rotation": 2
    },
    {
      "x": -6,
      "y": 6,
      "z": 16,
      "name": "OrbisGalactic_Block_ShipHull",
      "rotation": 1
    },
    {
      "x": -6,
      "y": -2,
      "z": 17,
      "name": "OrbisGalactic_Block_ShipHull",
      "rotation": 1
    },
    {
      "x": -6,
      "y": -1,
      "z": 17,
      "name": "OrbisGalactic_Block_Imperial_Panel_Black_Brick_Horizontal"
    },
    {
      "x": -6,
      "y": 0,
      "z": 17,
      "name": "OrbisGalactic_Block_Imperial_Panel_Light_Gray_Brick_Vertical"
    },
    {
      "x": -6,
      "y": 1,
      "z": 17,
      "name": "OrbisGalactic_Block_Imperial_Panel_Light_Gray_Brick_Vertical"
    },
    {
      "x": -6,
      "y": 2,
      "z": 17,
      "name": "OrbisGalactic_Block_Imperial_Panel_Light_Gray_Brick_Vertical"
    },
    {
      "x": -6,
      "y": 3,
      "z": 17,
      "name": "OrbisGalactic_Block_Imperial_Panel_Light_Gray_Brick_Vertical"
    },
    {
      "x": -6,
      "y": 4,
      "z": 17,
      "name": "OrbisGalactic_Block_Imperial_Panel_Black_Brick_Horizontal",
      "rotation": 2
    },
    {
      "x": -6,
      "y": 5,
      "z": 17,
      "name": "OrbisGalactic_Block_Imperial_Panel_Black_Smooth",
      "rotation": 1
    },
    {
      "x": -6,
      "y": 6,
      "z": 17,
      "name": "OrbisGalactic_Block_ShipHull",
      "rotation": 1
    },
    {
      "x": -6,
      "y": -2,
      "z": 18,
      "name": "OrbisGalactic_Block_ShipHull",
      "rotation": 1
    },
    {
      "x": -6,
      "y": -1,
      "z": 18,
      "name": "OrbisGalactic_Block_Imperial_Panel_Black_Brick_Vertical",
      "rotation": 3
    },
    {
      "x": -6,
      "y": 0,
      "z": 18,
      "name": "OrbisGalactic_Block_Imperial_Panel_Black_Brick_Vertical",
      "rotation": 3
    },
    {
      "x": -6,
      "y": 1,
      "z": 18,
      "name": "OrbisGalactic_Block_Imperial_Panel_Black_Brick_Vertical",
      "rotation": 3
    },
    {
      "x": -6,
      "y": 2,
      "z": 18,
      "name": "OrbisGalactic_Block_Imperial_Panel_Black_Brick_Vertical",
      "rotation": 3
    },
    {
      "x": -6,
      "y": 3,
      "z": 18,
      "name": "OrbisGalactic_Block_Imperial_Panel_Black_Brick_Vertical",
      "rotation": 3
    },
    {
      "x": -6,
      "y": 4,
      "z": 18,
      "name": "OrbisGalactic_Block_Imperial_Panel_Black_Brick_Vertical",
      "rotation": 3
    },
    {
      "x": -6,
      "y": 5,
      "z": 18,
      "name": "OrbisGalactic_Block_ShipHull",
      "rotation": 1
    },
    {
      "x": -6,
      "y": 6,
      "z": 18,
      "name": "OrbisGalactic_Block_ShipHull",
      "rotation": 1
    },
    {
      "x": -6,
      "y": -2,
      "z": 19,
      "name": "OrbisGalactic_Block_ShipHull",
      "rotation": 1
    },
    {
      "x": -6,
      "y": -1,
      "z": 19,
      "name": "OrbisGalactic_Block_Imperial_Panel_Black_Brick_Vertical"
    },
    {
      "x": -6,
      "y": 0,
      "z": 19,
      "name": "OrbisGalactic_Block_Imperial_Ship_Window_Bottom_Right",
      "rotation": 1
    },
    {
      "x": -6,
      "y": 1,
      "z": 19,
      "name": "OrbisGalactic_Block_Imperial_Ship_Window_Right_Center",
      "rotation": 1
    },
    {
      "x": -6,
      "y": 2,
      "z": 19,
      "name": "OrbisGalactic_Block_Imperial_Ship_Window_Right_Center",
      "rotation": 1
    },
    {
      "x": -6,
      "y": 3,
      "z": 19,
      "name": "OrbisGalactic_Block_Imperial_Ship_Window_Top_Right",
      "rotation": 1
    },
    {
      "x": -6,
      "y": 4,
      "z": 19,
      "name": "OrbisGalactic_Block_Imperial_Panel_Black_Brick_Horizontal",
      "rotation": 1
    },
    {
      "x": -6,
      "y": 5,
      "z": 19,
      "name": "OrbisGalactic_Block_ShipHull",
      "rotation": 1
    },
    {
      "x": -6,
      "y": 6,
      "z": 19,
      "name": "OrbisGalactic_Block_ShipHull",
      "rotation": 1
    },
    {
      "x": -6,
      "y": -2,
      "z": 20,
      "name": "OrbisGalactic_Block_ShipHull",
      "rotation": 1
    },
    {
      "x": -6,
      "y": -1,
      "z": 20,
      "name": "OrbisGalactic_Block_Imperial_Panel_Black_Brick_Vertical"
    },
    {
      "x": -6,
      "y": 0,
      "z": 20,
      "name": "OrbisGalactic_Block_Imperial_Ship_Window_Bottom_Center",
      "rotation": 1
    },
    {
      "x": -6,
      "y": 1,
      "z": 20,
      "name": "OrbisGalactic_Block_Imperial_Ship_Window_Center",
      "rotation": 1
    },
    {
      "x": -6,
      "y": 2,
      "z": 20,
      "name": "OrbisGalactic_Block_Imperial_Ship_Window_Center",
      "rotation": 1
    },
    {
      "x": -6,
      "y": 3,
      "z": 20,
      "name": "OrbisGalactic_Block_Imperial_Ship_Window_Top_Center",
      "rotation": 1
    },
    {
      "x": -6,
      "y": 4,
      "z": 20,
      "name": "OrbisGalactic_Block_Imperial_Panel_Black_Brick_Horizontal",
      "rotation": 1
    },
    {
      "x": -6,
      "y": 5,
      "z": 20,
      "name": "OrbisGalactic_Block_ShipHull",
      "rotation": 1
    },
    {
      "x": -6,
      "y": 6,
      "z": 20,
      "name": "OrbisGalactic_Block_ShipHull",
      "rotation": 1
    },
    {
      "x": -6,
      "y": -2,
      "z": 21,
      "name": "OrbisGalactic_Block_ShipHull",
      "rotation": 1
    },
    {
      "x": -6,
      "y": -1,
      "z": 21,
      "name": "OrbisGalactic_Block_Imperial_Panel_Black_Brick_Vertical"
    },
    {
      "x": -6,
      "y": 0,
      "z": 21,
      "name": "OrbisGalactic_Block_Imperial_Ship_Window_Bottom_Left",
      "rotation": 1
    },
    {
      "x": -6,
      "y": 1,
      "z": 21,
      "name": "OrbisGalactic_Block_Imperial_Ship_Window_Left_Center",
      "rotation": 1
    },
    {
      "x": -6,
      "y": 2,
      "z": 21,
      "name": "OrbisGalactic_Block_Imperial_Ship_Window_Left_Center",
      "rotation": 1
    },
    {
      "x": -6,
      "y": 3,
      "z": 21,
      "name": "OrbisGalactic_Block_Imperial_Ship_Window_Top_Left",
      "rotation": 1
    },
    {
      "x": -6,
      "y": 4,
      "z": 21,
      "name": "OrbisGalactic_Block_Imperial_Panel_Black_Brick_Horizontal",
      "rotation": 1
    },
    {
      "x": -6,
      "y": 5,
      "z": 21,
      "name": "OrbisGalactic_Block_ShipHull",
      "rotation": 1
    },
    {
      "x": -6,
      "y": 6,
      "z": 21,
      "name": "OrbisGalactic_Block_ShipHull",
      "rotation": 1
    },
    {
      "x": -6,
      "y": -3,
      "z": 22,
      "name": "OrbisGalactic_Block_ShipHull",
      "rotation": 1
    },
    {
      "x": -6,
      "y": -2,
      "z": 22,
      "name": "OrbisGalactic_Block_ShipHull",
      "rotation": 1
    },
    {
      "x": -6,
      "y": -1,
      "z": 22,
      "name": "OrbisGalactic_Block_Imperial_Panel_Black_Brick_Vertical",
      "rotation": 3
    },
    {
      "x": -6,
      "y": 0,
      "z": 22,
      "name": "OrbisGalactic_Block_Imperial_Panel_Black_Brick_Vertical",
      "rotation": 3
    },
    {
      "x": -6,
      "y": 1,
      "z": 22,
      "name": "OrbisGalactic_Block_Imperial_Panel_Black_Brick_Vertical",
      "rotation": 3
    },
    {
      "x": -6,
      "y": 2,
      "z": 22,
      "name": "OrbisGalactic_Block_Imperial_Panel_Black_Brick_Vertical",
      "rotation": 3
    },
    {
      "x": -6,
      "y": 3,
      "z": 22,
      "name": "OrbisGalactic_Block_Imperial_Panel_Black_Brick_Vertical",
      "rotation": 3
    },
    {
      "x": -6,
      "y": 4,
      "z": 22,
      "name": "OrbisGalactic_Block_Imperial_Panel_Black_Brick_Vertical",
      "rotation": 3
    },
    {
      "x": -6,
      "y": 5,
      "z": 22,
      "name": "OrbisGalactic_Block_ShipHull",
      "rotation": 1
    },
    {
      "x": -6,
      "y": 6,
      "z": 22,
      "name": "OrbisGalactic_Block_ShipHull",
      "rotation": 1
    },
    {
      "x": -6,
      "y": -3,
      "z": 23,
      "name": "OrbisGalactic_Block_ShipHull",
      "rotation": 1
    },
    {
      "x": -6,
      "y": -2,
      "z": 23,
      "name": "OrbisGalactic_Block_ShipHull",
      "rotation": 1
    },
    {
      "x": -6,
      "y": -1,
      "z": 23,
      "name": "OrbisGalactic_Block_Imperial_Panel_Gray_Smooth",
      "rotation": 1
    },
    {
      "x": -6,
      "y": 0,
      "z": 23,
      "name": "OrbisGalactic_Imperial_Railing_Gray",
      "support": 15,
      "rotation": 2
    },
    {
      "x": -6,
      "y": 5,
      "z": 23,
      "name": "OrbisGalactic_Block_Imperial_Panel_Black_Brick_Vertical",
      "rotation": 3
    },
    {
      "x": -6,
      "y": 6,
      "z": 23,
      "name": "OrbisGalactic_Block_ShipHull",
      "rotation": 1
    },
    {
      "x": -6,
      "y": -3,
      "z": 24,
      "name": "OrbisGalactic_Block_ShipHull",
      "rotation": 1
    },
    {
      "x": -6,
      "y": -2,
      "z": 24,
      "name": "*OrbisGalactic_Block_Imperial_Lamp1_State_Definitions_On",
      "rotation": 1
    },
    {
      "x": -6,
      "y": 5,
      "z": 24,
      "name": "OrbisGalactic_Block_Imperial_Panel_Black_Smooth",
      "rotation": 1
    },
    {
      "x": -6,
      "y": 6,
      "z": 24,
      "name": "OrbisGalactic_Block_ShipHull",
      "rotation": 1
    },
    {
      "x": -6,
      "y": 7,
      "z": 24,
      "name": "OrbisGalactic_Block_ShipHull",
      "rotation": 1
    },
    {
      "x": -6,
      "y": -3,
      "z": 25,
      "name": "OrbisGalactic_Block_ShipHull",
      "rotation": 1
    },
    {
      "x": -6,
      "y": -2,
      "z": 25,
      "name": "OrbisGalactic_Block_Imperial_Panel_Gray_Brick_Horizontal",
      "rotation": 3
    },
    {
      "x": -6,
      "y": 0,
      "z": 25,
      "name": "OrbisGalactic_Imperial_Railing_Gray",
      "filler": 1,
      "rotation": 3
    },
    {
      "x": -6,
      "y": 6,
      "z": 25,
      "name": "OrbisGalactic_Block_Imperial_Panel_Black_Smooth",
      "rotation": 2
    },
    {
      "x": -6,
      "y": 7,
      "z": 25,
      "name": "OrbisGalactic_Block_ShipHull",
      "rotation": 1
    },
    {
      "x": -6,
      "y": -3,
      "z": 26,
      "name": "OrbisGalactic_Block_ShipHull",
      "rotation": 1
    },
    {
      "x": -6,
      "y": -2,
      "z": 26,
      "name": "OrbisGalactic_Block_Imperial_Panel_Gray_Brick_Horizontal",
      "rotation": 3
    },
    {
      "x": -6,
      "y": 0,
      "z": 26,
      "name": "OrbisGalactic_Imperial_Railing_Gray",
      "filler": 1,
      "rotation": 3
    },
    {
      "x": -6,
      "y": 6,
      "z": 26,
      "name": "OrbisGalactic_Block_Imperial_Panel_Black_Brick_Vertical",
      "rotation": 2
    },
    {
      "x": -6,
      "y": 7,
      "z": 26,
      "name": "OrbisGalactic_Block_ShipHull",
      "rotation": 1
    },
    {
      "x": -6,
      "y": -3,
      "z": 27,
      "name": "OrbisGalactic_Block_ShipHull",
      "rotation": 1
    },
    {
      "x": -6,
      "y": -2,
      "z": 27,
      "name": "OrbisGalactic_Block_Imperial_Panel_Gray_Brick_Horizontal",
      "rotation": 3
    },
    {
      "x": -6,
      "y": 0,
      "z": 27,
      "name": "OrbisGalactic_Imperial_Railing_Gray",
      "filler": 1,
      "rotation": 3
    },
    {
      "x": -6,
      "y": 6,
      "z": 27,
      "name": "OrbisGalactic_Block_Imperial_Panel_Black_Brick_Vertical",
      "rotation": 2
    },
    {
      "x": -6,
      "y": 7,
      "z": 27,
      "name": "OrbisGalactic_Block_ShipHull",
      "rotation": 1
    },
    {
      "x": -6,
      "y": -3,
      "z": 28,
      "name": "OrbisGalactic_Block_ShipHull",
      "rotation": 1
    },
    {
      "x": -6,
      "y": -2,
      "z": 28,
      "name": "OrbisGalactic_Block_Imperial_Panel_Gray_Brick_Vertical",
      "rotation": 3
    },
    {
      "x": -6,
      "y": 6,
      "z": 28,
      "name": "OrbisGalactic_Block_Imperial_Panel_Black_Brick_Vertical",
      "rotation": 2
    },
    {
      "x": -6,
      "y": 7,
      "z": 28,
      "name": "OrbisGalactic_Block_ShipHull",
      "rotation": 1
    },
    {
      "x": -6,
      "y": -3,
      "z": 29,
      "name": "OrbisGalactic_Block_ShipHull",
      "rotation": 1
    },
    {
      "x": -6,
      "y": -2,
      "z": 29,
      "name": "OrbisGalactic_Block_Imperial_Panel_Gray_Brick_Vertical",
      "rotation": 3
    },
    {
      "x": -6,
      "y": -1,
      "z": 29,
      "name": "OrbisGalactic_Block_Imperial_Panel_Gray_Brick_Vertical",
      "rotation": 1
    },
    {
      "x": -6,
      "y": 0,
      "z": 29,
      "name": "OrbisGalactic_Imperial_Railing_Gray",
      "support": 15
    },
    {
      "x": -6,
      "y": 6,
      "z": 29,
      "name": "OrbisGalactic_Block_Imperial_Panel_Black_Smooth",
      "rotation": 3
    },
    {
      "x": -6,
      "y": 7,
      "z": 29,
      "name": "OrbisGalactic_Block_ShipHull",
      "rotation": 1
    },
    {
      "x": -6,
      "y": -3,
      "z": 30,
      "name": "OrbisGalactic_Block_ShipHull",
      "rotation": 1
    },
    {
      "x": -6,
      "y": -2,
      "z": 30,
      "name": "OrbisGalactic_Block_ShipHull",
      "rotation": 1
    },
    {
      "x": -6,
      "y": -1,
      "z": 30,
      "name": "*OrbisGalactic_Block_Imperial_Lamp3_Connected_State_Definitions_On",
      "rotation": 3
    },
    {
      "x": -6,
      "y": 5,
      "z": 30,
      "name": "OrbisGalactic_Block_Imperial_Panel_Black_Smooth"
    },
    {
      "x": -6,
      "y": 6,
      "z": 30,
      "name": "OrbisGalactic_Block_ShipHull",
      "rotation": 1
    },
    {
      "x": -6,
      "y": 7,
      "z": 30,
      "name": "OrbisGalactic_Block_ShipHull",
      "rotation": 1
    },
    {
      "x": -6,
      "y": -3,
      "z": 31,
      "name": "OrbisGalactic_Block_ShipHull",
      "rotation": 1
    },
    {
      "x": -6,
      "y": -2,
      "z": 31,
      "name": "OrbisGalactic_Block_ShipHull",
      "rotation": 1
    },
    {
      "x": -6,
      "y": -1,
      "z": 31,
      "name": "OrbisGalactic_Block_Imperial_Panel_Black_Brick_Vertical",
      "rotation": 1
    },
    {
      "x": -6,
      "y": 0,
      "z": 31,
      "name": "OrbisGalactic_Block_Imperial_Ship_Window_Right_Center",
      "rotation": 2
    },
    {
      "x": -6,
      "y": 1,
      "z": 31,
      "name": "OrbisGalactic_Block_Imperial_Ship_Window_Right_Center",
      "rotation": 2
    },
    {
      "x": -6,
      "y": 2,
      "z": 31,
      "name": "OrbisGalactic_Block_Imperial_Ship_Window_Right_Center",
      "rotation": 2
    },
    {
      "x": -6,
      "y": 3,
      "z": 31,
      "name": "OrbisGalactic_Block_Imperial_Ship_Window_Top_Right",
      "rotation": 2
    },
    {
      "x": -6,
      "y": 4,
      "z": 31,
      "name": "OrbisGalactic_Block_ShipHull",
      "rotation": 1
    },
    {
      "x": -6,
      "y": 5,
      "z": 31,
      "name": "OrbisGalactic_Block_ShipHull",
      "rotation": 1
    },
    {
      "x": -6,
      "y": -3,
      "z": 32,
      "name": "OrbisGalactic_Block_ShipHull",
      "rotation": 1
    },
    {
      "x": -6,
      "y": -2,
      "z": 32,
      "name": "OrbisGalactic_Block_ShipHull",
      "rotation": 1
    },
    {
      "x": -6,
      "y": -1,
      "z": 32,
      "name": "OrbisGalactic_Block_Imperial_Panel_Black_Brick_Vertical"
    },
    {
      "x": -6,
      "y": -2,
      "z": 33,
      "name": "OrbisGalactic_Block_ShipHull",
      "rotation": 1
    },
    {
      "x": -6,
      "y": -1,
      "z": 33,
      "name": "OrbisGalactic_Block_Imperial_Panel_Black_Brick_Vertical"
    },
    {
      "x": -6,
      "y": -2,
      "z": 34,
      "name": "OrbisGalactic_Block_Imperial_Panel_Black_Brick_Vertical"
    },
    {
      "x": -6,
      "y": -2,
      "z": 35,
      "name": "OrbisGalactic_Block_Imperial_Panel_Black_Brick_Horizontal",
      "rotation": 3
    },
    {
      "x": -6,
      "y": -2,
      "z": 36,
      "name": "OrbisGalactic_Block_Imperial_Panel_Black_Brick_Horizontal",
      "rotation": 3
    },
    {
      "x": -5,
      "y": -1,
      "z": -6,
      "name": "OrbisGalactic_Block_ShipHull",
      "rotation": 1
    },
    {
      "x": -5,
      "y": 0,
      "z": -6,
      "name": "OrbisGalactic_Block_ShipHull",
      "rotation": 1
    },
    {
      "x": -5,
      "y": 1,
      "z": -6,
      "name": "OrbisGalactic_Block_ShipHull",
      "rotation": 1
    },
    {
      "x": -5,
      "y": 2,
      "z": -6,
      "name": "OrbisGalactic_Block_ShipHull",
      "rotation": 1
    },
    {
      "x": -5,
      "y": 3,
      "z": -6,
      "name": "OrbisGalactic_Block_ShipHull",
      "rotation": 1
    },
    {
      "x": -5,
      "y": 4,
      "z": -6,
      "name": "OrbisGalactic_Block_ShipHull",
      "rotation": 1
    },
    {
      "x": -5,
      "y": 5,
      "z": -6,
      "name": "OrbisGalactic_Block_ShipHull",
      "rotation": 1
    },
    {
      "x": -5,
      "y": -2,
      "z": -5,
      "name": "OrbisGalactic_Block_ShipHull",
      "rotation": 1
    },
    {
      "x": -5,
      "y": -1,
      "z": -5,
      "name": "OrbisGalactic_Block_Imperial_Panel_Black",
      "rotation": 1
    },
    {
      "x": -5,
      "y": 0,
      "z": -5,
      "name": "OrbisGalactic_Block_Imperial_Panel_White_Brick_Vertical",
      "rotation": 1
    },
    {
      "x": -5,
      "y": 1,
      "z": -5,
      "name": "OrbisGalactic_Block_Imperial_Panel_White_Brick_Vertical",
      "rotation": 1
    },
    {
      "x": -5,
      "y": 2,
      "z": -5,
      "name": "OrbisGalactic_Block_Imperial_Panel_White_Brick_Vertical",
      "rotation": 1
    },
    {
      "x": -5,
      "y": 3,
      "z": -5,
      "name": "OrbisGalactic_Block_Imperial_Panel_White_Brick_Vertical",
      "rotation": 1
    },
    {
      "x": -5,
      "y": 4,
      "z": -5,
      "name": "OrbisGalactic_Block_Imperial_Panel_Black_Brick_Horizontal",
      "rotation": 1
    },
    {
      "x": -5,
      "y": 5,
      "z": -5,
      "name": "OrbisGalactic_Block_ShipHull",
      "rotation": 1
    },
    {
      "x": -5,
      "y": 6,
      "z": -5,
      "name": "OrbisGalactic_Block_ShipHull",
      "rotation": 1
    },
    {
      "x": -5,
      "y": -2,
      "z": -4,
      "name": "OrbisGalactic_Block_ShipHull",
      "rotation": 1
    },
    {
      "x": -5,
      "y": -1,
      "z": -4,
      "name": "OrbisGalactic_Block_Imperial_Panel_Black",
      "rotation": 1
    },
    {
      "x": -5,
      "y": 0,
      "z": -4,
      "name": "OrbisGalactic_Block_Imperial_Panel_Gray_Brick_Vertical",
      "rotation": 1
    },
    {
      "x": -5,
      "y": 1,
      "z": -4,
      "name": "OrbisGalactic_Block_Imperial_Panel_Gray_Brick_Vertical",
      "rotation": 1
    },
    {
      "x": -5,
      "y": 2,
      "z": -4,
      "name": "OrbisGalactic_Block_Imperial_Panel_Gray_Brick_Vertical",
      "rotation": 1
    },
    {
      "x": -5,
      "y": 3,
      "z": -4,
      "name": "OrbisGalactic_Block_Imperial_Panel_Gray_Brick_Vertical",
      "rotation": 1
    },
    {
      "x": -5,
      "y": 4,
      "z": -4,
      "name": "OrbisGalactic_Block_Imperial_Panel_Black_Brick_Horizontal",
      "rotation": 1
    },
    {
      "x": -5,
      "y": 5,
      "z": -4,
      "name": "OrbisGalactic_Block_ShipHull",
      "rotation": 1
    },
    {
      "x": -5,
      "y": 6,
      "z": -4,
      "name": "OrbisGalactic_Block_ShipHull",
      "rotation": 1
    },
    {
      "x": -5,
      "y": -2,
      "z": -3,
      "name": "OrbisGalactic_Block_ShipHull",
      "rotation": 1
    },
    {
      "x": -5,
      "y": -1,
      "z": -3,
      "name": "OrbisGalactic_Block_Imperial_Panel_Black",
      "rotation": 1
    },
    {
      "x": -5,
      "y": 0,
      "z": -3,
      "name": "*OrbisGalactic_Block_Imperial_Lamp2_State_Definitions_On",
      "rotation": 1
    },
    {
      "x": -5,
      "y": 1,
      "z": -3,
      "name": "*OrbisGalactic_Block_Imperial_Lamp3_Connected_State_Definitions_On",
      "rotation": 1
    },
    {
      "x": -5,
      "y": 2,
      "z": -3,
      "name": "*OrbisGalactic_Block_Imperial_Lamp3_Connected_State_Definitions_On",
      "rotation": 1
    },
    {
      "x": -5,
      "y": 3,
      "z": -3,
      "name": "*OrbisGalactic_Block_Imperial_Lamp2_State_Definitions_On",
      "rotation": 1
    },
    {
      "x": -5,
      "y": 4,
      "z": -3,
      "name": "OrbisGalactic_Block_Imperial_Panel_Black_Brick_Horizontal",
      "rotation": 1
    },
    {
      "x": -5,
      "y": 5,
      "z": -3,
      "name": "OrbisGalactic_Block_ShipHull",
      "rotation": 1
    },
    {
      "x": -5,
      "y": 6,
      "z": -3,
      "name": "OrbisGalactic_Block_ShipHull",
      "rotation": 1
    },
    {
      "x": -5,
      "y": -2,
      "z": -2,
      "name": "OrbisGalactic_Block_ShipHull",
      "rotation": 1
    },
    {
      "x": -5,
      "y": -1,
      "z": -2,
      "name": "OrbisGalactic_Block_Imperial_Panel_Black",
      "rotation": 1
    },
    {
      "x": -5,
      "y": 0,
      "z": -2,
      "name": "OrbisGalactic_Block_Imperial_Panel_White_Brick_Vertical",
      "rotation": 3
    },
    {
      "x": -5,
      "y": 1,
      "z": -2,
      "name": "OrbisGalactic_Block_Imperial_Panel_White_Brick_Vertical",
      "rotation": 3
    },
    {
      "x": -5,
      "y": 2,
      "z": -2,
      "name": "OrbisGalactic_Block_Imperial_Panel_White_Brick_Vertical",
      "rotation": 3
    },
    {
      "x": -5,
      "y": 3,
      "z": -2,
      "name": "OrbisGalactic_Block_Imperial_Panel_White_Brick_Vertical",
      "rotation": 3
    },
    {
      "x": -5,
      "y": 4,
      "z": -2,
      "name": "OrbisGalactic_Block_Imperial_Panel_Black_Brick_Horizontal",
      "rotation": 1
    },
    {
      "x": -5,
      "y": 5,
      "z": -2,
      "name": "OrbisGalactic_Block_ShipHull",
      "rotation": 1
    },
    {
      "x": -5,
      "y": 6,
      "z": -2,
      "name": "OrbisGalactic_Block_ShipHull",
      "rotation": 1
    },
    {
      "x": -5,
      "y": -2,
      "z": -1,
      "name": "OrbisGalactic_Block_ShipHull",
      "rotation": 1
    },
    {
      "x": -5,
      "y": -1,
      "z": -1,
      "name": "OrbisGalactic_Block_Imperial_Panel_Black_Brick_Horizontal",
      "rotation": 3
    },
    {
      "x": -5,
      "y": 3,
      "z": -1,
      "name": "OrbisGalactic_Block_Imperial_Panel_White_Brick_Horizontal",
      "rotation": 3
    },
    {
      "x": -5,
      "y": 4,
      "z": -1,
      "name": "OrbisGalactic_Block_Imperial_Panel_Black_Brick_Horizontal",
      "rotation": 1
    },
    {
      "x": -5,
      "y": 5,
      "z": -1,
      "name": "OrbisGalactic_Block_ShipHull",
      "rotation": 1
    },
    {
      "x": -5,
      "y": 6,
      "z": -1,
      "name": "OrbisGalactic_Block_ShipHull",
      "rotation": 1
    },
    {
      "x": -5,
      "y": -2,
      "z": 0,
      "name": "OrbisGalactic_Block_ShipHull",
      "rotation": 1
    },
    {
      "x": -5,
      "y": -1,
      "z": 0,
      "name": "OrbisGalactic_Block_Imperial_Panel_Black_Brick_Horizontal",
      "rotation": 3
    },
    {
      "x": -5,
      "y": 0,
      "z": 0,
      "name": "Furniture_Construction_Sign",
      "rotation": 1
    },
    {
      "x": -5,
      "y": 1,
      "z": 0,
      "name": "Furniture_Construction_Sign",
      "filler": 1024,
      "rotation": 1
    },
    {
      "x": -5,
      "y": 3,
      "z": 0,
      "name": "OrbisGalactic_Block_Imperial_Panel_White_Brick_Horizontal",
      "rotation": 3
    },
    {
      "x": -5,
      "y": 4,
      "z": 0,
      "name": "OrbisGalactic_Block_Imperial_Panel_Black_Brick_Horizontal"
    },
    {
      "x": -5,
      "y": 5,
      "z": 0,
      "name": "OrbisGalactic_Block_ShipHull",
      "rotation": 1
    },
    {
      "x": -5,
      "y": 6,
      "z": 0,
      "name": "OrbisGalactic_Block_ShipHull",
      "rotation": 1
    },
    {
      "x": -5,
      "y": -2,
      "z": 1,
      "name": "OrbisGalactic_Block_ShipHull",
      "rotation": 1
    },
    {
      "x": -5,
      "y": -1,
      "z": 1,
      "name": "OrbisGalactic_Block_Imperial_Panel_Black_Brick_Horizontal",
      "rotation": 3
    },
    {
      "x": -5,
      "y": 3,
      "z": 1,
      "name": "OrbisGalactic_Block_Imperial_Panel_White_Brick_Horizontal",
      "rotation": 3
    },
    {
      "x": -5,
      "y": 4,
      "z": 1,
      "name": "OrbisGalactic_Block_Imperial_Panel_Black_Brick_Horizontal",
      "rotation": 1
    },
    {
      "x": -5,
      "y": 5,
      "z": 1,
      "name": "OrbisGalactic_Block_ShipHull",
      "rotation": 1
    },
    {
      "x": -5,
      "y": 6,
      "z": 1,
      "name": "OrbisGalactic_Block_ShipHull",
      "rotation": 1
    },
    {
      "x": -5,
      "y": -2,
      "z": 2,
      "name": "OrbisGalactic_Block_ShipHull",
      "rotation": 1
    },
    {
      "x": -5,
      "y": -1,
      "z": 2,
      "name": "OrbisGalactic_Block_Imperial_Panel_Black",
      "rotation": 1
    },
    {
      "x": -5,
      "y": 0,
      "z": 2,
      "name": "OrbisGalactic_Block_Imperial_Panel_White_Brick_Vertical",
      "rotation": 3
    },
    {
      "x": -5,
      "y": 1,
      "z": 2,
      "name": "OrbisGalactic_Block_Imperial_Panel_White_Brick_Vertical",
      "rotation": 3
    },
    {
      "x": -5,
      "y": 2,
      "z": 2,
      "name": "OrbisGalactic_Block_Imperial_Panel_White_Brick_Vertical",
      "rotation": 3
    },
    {
      "x": -5,
      "y": 3,
      "z": 2,
      "name": "OrbisGalactic_Block_Imperial_Panel_White_Brick_Vertical",
      "rotation": 3
    },
    {
      "x": -5,
      "y": 4,
      "z": 2,
      "name": "OrbisGalactic_Block_Imperial_Panel_Black_Brick_Horizontal",
      "rotation": 1
    },
    {
      "x": -5,
      "y": 5,
      "z": 2,
      "name": "OrbisGalactic_Block_ShipHull",
      "rotation": 1
    },
    {
      "x": -5,
      "y": 6,
      "z": 2,
      "name": "OrbisGalactic_Block_ShipHull",
      "rotation": 1
    },
    {
      "x": -5,
      "y": -2,
      "z": 3,
      "name": "OrbisGalactic_Block_ShipHull",
      "rotation": 1
    },
    {
      "x": -5,
      "y": -1,
      "z": 3,
      "name": "OrbisGalactic_Block_Imperial_Panel_Black",
      "rotation": 1
    },
    {
      "x": -5,
      "y": 0,
      "z": 3,
      "name": "*OrbisGalactic_Block_Imperial_Lamp2_State_Definitions_On",
      "rotation": 1
    },
    {
      "x": -5,
      "y": 1,
      "z": 3,
      "name": "*OrbisGalactic_Block_Imperial_Lamp3_Connected_State_Definitions_On",
      "rotation": 1
    },
    {
      "x": -5,
      "y": 2,
      "z": 3,
      "name": "*OrbisGalactic_Block_Imperial_Lamp3_Connected_State_Definitions_On",
      "rotation": 1
    },
    {
      "x": -5,
      "y": 3,
      "z": 3,
      "name": "*OrbisGalactic_Block_Imperial_Lamp2_State_Definitions_On",
      "rotation": 1
    },
    {
      "x": -5,
      "y": 4,
      "z": 3,
      "name": "OrbisGalactic_Block_Imperial_Panel_Black_Brick_Horizontal",
      "rotation": 1
    },
    {
      "x": -5,
      "y": 5,
      "z": 3,
      "name": "OrbisGalactic_Block_ShipHull",
      "rotation": 1
    },
    {
      "x": -5,
      "y": 6,
      "z": 3,
      "name": "OrbisGalactic_Block_ShipHull",
      "rotation": 1
    },
    {
      "x": -5,
      "y": -2,
      "z": 4,
      "name": "OrbisGalactic_Block_ShipHull",
      "rotation": 1
    },
    {
      "x": -5,
      "y": -1,
      "z": 4,
      "name": "OrbisGalactic_Block_Imperial_Panel_Black",
      "rotation": 1
    },
    {
      "x": -5,
      "y": 0,
      "z": 4,
      "name": "OrbisGalactic_Block_Imperial_Panel_White_Brick_Vertical",
      "rotation": 1
    },
    {
      "x": -5,
      "y": 1,
      "z": 4,
      "name": "OrbisGalactic_Block_Imperial_Panel_White_Brick_Vertical",
      "rotation": 1
    },
    {
      "x": -5,
      "y": 2,
      "z": 4,
      "name": "OrbisGalactic_Block_Imperial_Panel_White_Brick_Vertical",
      "rotation": 1
    },
    {
      "x": -5,
      "y": 3,
      "z": 4,
      "name": "OrbisGalactic_Block_Imperial_Panel_White_Brick_Vertical",
      "rotation": 1
    },
    {
      "x": -5,
      "y": 4,
      "z": 4,
      "name": "OrbisGalactic_Block_Imperial_Panel_Black_Brick_Horizontal",
      "rotation": 1
    },
    {
      "x": -5,
      "y": 5,
      "z": 4,
      "name": "OrbisGalactic_Block_ShipHull",
      "rotation": 1
    },
    {
      "x": -5,
      "y": 6,
      "z": 4,
      "name": "OrbisGalactic_Block_ShipHull",
      "rotation": 1
    },
    {
      "x": -5,
      "y": -2,
      "z": 5,
      "name": "OrbisGalactic_Block_ShipHull",
      "rotation": 1
    },
    {
      "x": -5,
      "y": -1,
      "z": 5,
      "name": "OrbisGalactic_Block_Imperial_Panel_Black"
    },
    {
      "x": -5,
      "y": 0,
      "z": 5,
      "name": "OrbisGalactic_Block_Imperial_Panel_White_Brick_Vertical",
      "rotation": 1
    },
    {
      "x": -5,
      "y": 1,
      "z": 5,
      "name": "OrbisGalactic_Block_Imperial_Panel_White_Brick_Vertical",
      "rotation": 1
    },
    {
      "x": -5,
      "y": 2,
      "z": 5,
      "name": "OrbisGalactic_Block_Imperial_Panel_White_Brick_Vertical",
      "rotation": 1
    },
    {
      "x": -5,
      "y": 3,
      "z": 5,
      "name": "OrbisGalactic_Block_Imperial_Panel_White_Brick_Vertical",
      "rotation": 1
    },
    {
      "x": -5,
      "y": 4,
      "z": 5,
      "name": "OrbisGalactic_Block_Imperial_Panel_Black_Smooth",
      "rotation": 1
    },
    {
      "x": -5,
      "y": 5,
      "z": 5,
      "name": "OrbisGalactic_Block_ShipHull",
      "rotation": 1
    },
    {
      "x": -5,
      "y": 6,
      "z": 5,
      "name": "OrbisGalactic_Block_ShipHull",
      "rotation": 1
    },
    {
      "x": -5,
      "y": -2,
      "z": 6,
      "name": "OrbisGalactic_Block_ShipHull",
      "rotation": 1
    },
    {
      "x": -5,
      "y": -1,
      "z": 6,
      "name": "OrbisGalactic_Block_Imperial_Floor_Pattern_Bar_Top"
    },
    {
      "x": -5,
      "y": 5,
      "z": 6,
      "name": "OrbisGalactic_Block_Imperial_Panel_Black_Brick_Vertical",
      "rotation": 1
    },
    {
      "x": -5,
      "y": 6,
      "z": 6,
      "name": "OrbisGalactic_Block_ShipHull",
      "rotation": 1
    },
    {
      "x": -5,
      "y": -2,
      "z": 7,
      "name": "OrbisGalactic_Block_ShipHull",
      "rotation": 1
    },
    {
      "x": -5,
      "y": -1,
      "z": 7,
      "name": "*OrbisGalactic_Block_Imperial_Lamp2_State_Definitions_On",
      "rotation": 1
    },
    {
      "x": -5,
      "y": 5,
      "z": 7,
      "name": "OrbisGalactic_Block_Imperial_Panel_Black_Smooth",
      "rotation": 3
    },
    {
      "x": -5,
      "y": 6,
      "z": 7,
      "name": "OrbisGalactic_Block_ShipHull",
      "rotation": 1
    },
    {
      "x": -5,
      "y": -2,
      "z": 8,
      "name": "OrbisGalactic_Block_ShipHull",
      "rotation": 1
    },
    {
      "x": -5,
      "y": -1,
      "z": 8,
      "name": "OrbisGalactic_Block_Imperial_Panel_Gray_Brick_Vertical"
    },
    {
      "x": -5,
      "y": 5,
      "z": 8,
      "name": "OrbisGalactic_Block_Imperial_Panel_Black_Smooth",
      "rotation": 3
    },
    {
      "x": -5,
      "y": 6,
      "z": 8,
      "name": "OrbisGalactic_Block_ShipHull",
      "rotation": 1
    },
    {
      "x": -5,
      "y": -2,
      "z": 9,
      "name": "OrbisGalactic_Block_ShipHull",
      "rotation": 1
    },
    {
      "x": -5,
      "y": -1,
      "z": 9,
      "name": "OrbisGalactic_Block_Imperial_Panel_Gray_Brick_Vertical"
    },
    {
      "x": -5,
      "y": 5,
      "z": 9,
      "name": "OrbisGalactic_Block_Imperial_Panel_Black_Smooth",
      "rotation": 3
    },
    {
      "x": -5,
      "y": 6,
      "z": 9,
      "name": "OrbisGalactic_Block_ShipHull",
      "rotation": 1
    },
    {
      "x": -5,
      "y": -2,
      "z": 10,
      "name": "OrbisGalactic_Block_ShipHull",
      "rotation": 1
    },
    {
      "x": -5,
      "y": -1,
      "z": 10,
      "name": "*OrbisGalactic_Block_Imperial_Lamp2_State_Definitions_On",
      "rotation": 1
    },
    {
      "x": -5,
      "y": 5,
      "z": 10,
      "name": "OrbisGalactic_Block_Imperial_Panel_Black_Smooth",
      "rotation": 3
    },
    {
      "x": -5,
      "y": 6,
      "z": 10,
      "name": "OrbisGalactic_Block_ShipHull",
      "rotation": 1
    },
    {
      "x": -5,
      "y": -2,
      "z": 11,
      "name": "OrbisGalactic_Block_ShipHull",
      "rotation": 1
    },
    {
      "x": -5,
      "y": -1,
      "z": 11,
      "name": "OrbisGalactic_Block_Imperial_Panel_Gray_Brick_Vertical"
    },
    {
      "x": -5,
      "y": 5,
      "z": 11,
      "name": "OrbisGalactic_Block_Imperial_Panel_Black_Smooth",
      "rotation": 3
    },
    {
      "x": -5,
      "y": 6,
      "z": 11,
      "name": "OrbisGalactic_Block_ShipHull",
      "rotation": 1
    },
    {
      "x": -5,
      "y": -2,
      "z": 12,
      "name": "OrbisGalactic_Block_ShipHull",
      "rotation": 1
    },
    {
      "x": -5,
      "y": -1,
      "z": 12,
      "name": "*OrbisGalactic_Block_Imperial_Lamp2_State_Definitions_On",
      "rotation": 1
    },
    {
      "x": -5,
      "y": 5,
      "z": 12,
      "name": "OrbisGalactic_Block_Imperial_Panel_Black_Smooth",
      "rotation": 3
    },
    {
      "x": -5,
      "y": 6,
      "z": 12,
      "name": "OrbisGalactic_Block_ShipHull",
      "rotation": 1
    },
    {
      "x": -5,
      "y": -2,
      "z": 13,
      "name": "OrbisGalactic_Block_ShipHull",
      "rotation": 1
    },
    {
      "x": -5,
      "y": -1,
      "z": 13,
      "name": "OrbisGalactic_Block_Imperial_Panel_Gray_Brick_Vertical"
    },
    {
      "x": -5,
      "y": 5,
      "z": 13,
      "name": "OrbisGalactic_Block_Imperial_Panel_Black_Smooth",
      "rotation": 3
    },
    {
      "x": -5,
      "y": 6,
      "z": 13,
      "name": "OrbisGalactic_Block_ShipHull",
      "rotation": 1
    },
    {
      "x": -5,
      "y": -2,
      "z": 14,
      "name": "OrbisGalactic_Block_ShipHull",
      "rotation": 1
    },
    {
      "x": -5,
      "y": -1,
      "z": 14,
      "name": "OrbisGalactic_Block_Imperial_Panel_Gray_Brick_Vertical"
    },
    {
      "x": -5,
      "y": 5,
      "z": 14,
      "name": "OrbisGalactic_Block_Imperial_Panel_Black_Smooth",
      "rotation": 3
    },
    {
      "x": -5,
      "y": 6,
      "z": 14,
      "name": "OrbisGalactic_Block_ShipHull",
      "rotation": 1
    },
    {
      "x": -5,
      "y": -2,
      "z": 15,
      "name": "OrbisGalactic_Block_ShipHull",
      "rotation": 1
    },
    {
      "x": -5,
      "y": -1,
      "z": 15,
      "name": "*OrbisGalactic_Block_Imperial_Lamp2_State_Definitions_On",
      "rotation": 1
    },
    {
      "x": -5,
      "y": 5,
      "z": 15,
      "name": "OrbisGalactic_Block_Imperial_Panel_Black_Smooth",
      "rotation": 3
    },
    {
      "x": -5,
      "y": 6,
      "z": 15,
      "name": "OrbisGalactic_Block_ShipHull",
      "rotation": 1
    },
    {
      "x": -5,
      "y": -2,
      "z": 16,
      "name": "OrbisGalactic_Block_ShipHull",
      "rotation": 1
    },
    {
      "x": -5,
      "y": -1,
      "z": 16,
      "name": "OrbisGalactic_Block_Imperial_Floor_Pattern_Bar_Top",
      "rotation": 2
    },
    {
      "x": -5,
      "y": 5,
      "z": 16,
      "name": "OrbisGalactic_Block_Imperial_Panel_Black_Smooth",
      "rotation": 3
    },
    {
      "x": -5,
      "y": 6,
      "z": 16,
      "name": "OrbisGalactic_Block_ShipHull",
      "rotation": 1
    },
    {
      "x": -5,
      "y": -2,
      "z": 17,
      "name": "OrbisGalactic_Block_ShipHull",
      "rotation": 1
    },
    {
      "x": -5,
      "y": -1,
      "z": 17,
      "name": "OrbisGalactic_Block_Imperial_Floor_Pattern_Bar_Top",
      "rotation": 3
    },
    {
      "x": -5,
      "y": 0,
      "z": 17,
      "name": "OrbisGalactic_Block_Imperial_Panel_White_Brick_Vertical",
      "rotation": 2
    },
    {
      "x": -5,
      "y": 1,
      "z": 17,
      "name": "OrbisGalactic_Block_Imperial_Panel_White_Brick_Vertical",
      "rotation": 2
    },
    {
      "x": -5,
      "y": 2,
      "z": 17,
      "name": "OrbisGalactic_Block_Imperial_Panel_White_Brick_Vertical",
      "rotation": 2
    },
    {
      "x": -5,
      "y": 3,
      "z": 17,
      "name": "OrbisGalactic_Block_Imperial_Panel_White_Brick_Vertical",
      "rotation": 2
    },
    {
      "x": -5,
      "y": 4,
      "z": 17,
      "name": "OrbisGalactic_Block_Imperial_Panel_Black_Brick_Horizontal",
      "rotation": 2
    },
    {
      "x": -5,
      "y": 5,
      "z": 17,
      "name": "OrbisGalactic_Block_Imperial_Panel_Black_Brick_Horizontal",
      "rotation": 2
    },
    {
      "x": -5,
      "y": 6,
      "z": 17,
      "name": "OrbisGalactic_Block_ShipHull",
      "rotation": 1
    },
    {
      "x": -5,
      "y": -2,
      "z": 18,
      "name": "OrbisGalactic_Block_ShipHull",
      "rotation": 1
    },
    {
      "x": -5,
      "y": -1,
      "z": 18,
      "name": "OrbisGalactic_Block_Imperial_Panel_Gray_Brick_Vertical",
      "rotation": 2
    },
    {
      "x": -5,
      "y": 5,
      "z": 18,
      "name": "OrbisGalactic_Block_Imperial_Panel_Black",
      "rotation": 2
    },
    {
      "x": -5,
      "y": 6,
      "z": 18,
      "name": "OrbisGalactic_Block_ShipHull",
      "rotation": 1
    },
    {
      "x": -5,
      "y": -2,
      "z": 19,
      "name": "OrbisGalactic_Block_ShipHull",
      "rotation": 1
    },
    {
      "x": -5,
      "y": -1,
      "z": 19,
      "name": "OrbisGalactic_Block_Imperial_Panel_Gray_Brick_Vertical",
      "rotation": 2
    },
    {
      "x": -5,
      "y": 5,
      "z": 19,
      "name": "OrbisGalactic_Block_Imperial_Panel_Black_Brick_Vertical"
    },
    {
      "x": -5,
      "y": 6,
      "z": 19,
      "name": "OrbisGalactic_Block_ShipHull",
      "rotation": 1
    },
    {
      "x": -5,
      "y": 7,
      "z": 19,
      "name": "OrbisGalactic_Block_ShipHull",
      "rotation": 1
    },
    {
      "x": -5,
      "y": -2,
      "z": 20,
      "name": "OrbisGalactic_Block_ShipHull",
      "rotation": 1
    },
    {
