{
  "version": 8,
  "blockIdVersion": 11,
  "anchorX": 0,
  "anchorY": 0,
  "anchorZ": 0,
  "blocks": [
    {
      "x": -27,
      "y": -1,
      "z": -6,
      "name": "Rock_Ice",
      "rotation": 1
    },
    {
      "x": -27,
      "y": 0,
      "z": -6,
      "name": "Soil_Snow_Half"
    },
    {
      "x": -27,
      "y": -1,
      "z": -5,
      "name": "Rock_Ice",
      "rotation": 1
    },
    {
      "x": -27,
      "y": 0,
      "z": -5,
      "name": "Soil_Snow_Half"
    },
    {
      "x": -27,
      "y": -1,
      "z": -4,
      "name": "Rock_Ice",
      "rotation": 1
    },
    {
      "x": -27,
      "y": 0,
      "z": -4,
      "name": "Soil_Snow_Half"
    },
    {
      "x": -27,
      "y": -1,
      "z": -3,
      "name": "Rock_Ice",
      "rotation": 1
    },
    {
      "x": -27,
      "y": 0,
      "z": -3,
      "name": "Soil_Snow_Half"
    },
    {
      "x": -27,
      "y": -1,
      "z": -2,
      "name": "Rock_Ice",
      "rotation": 1
    },
    {
      "x": -27,
      "y": 0,
      "z": -2,
      "name": "Soil_Snow_Half"
    },
    {
      "x": -27,
      "y": -1,
      "z": -1,
      "name": "Rock_Ice",
      "rotation": 1
    },
    {
      "x": -27,
      "y": 0,
      "z": -1,
      "name": "Soil_Snow_Half"
    },
    {
      "x": -27,
      "y": -1,
      "z": 0,
      "name": "Rock_Ice",
      "rotation": 1
    },
    {
      "x": -27,
      "y": 0,
      "z": 0,
      "name": "Soil_Snow_Half"
    },
    {
      "x": -27,
      "y": -1,
      "z": 1,
      "name": "Rock_Ice",
      "rotation": 1
    },
    {
      "x": -27,
      "y": 0,
      "z": 1,
      "name": "Soil_Snow_Half"
    },
    {
      "x": -27,
      "y": -1,
      "z": 2,
      "name": "Rock_Ice",
      "rotation": 1
    },
    {
      "x": -27,
      "y": 0,
      "z": 2,
      "name": "Soil_Snow_Half"
    },
    {
      "x": -27,
      "y": -1,
      "z": 3,
      "name": "Rock_Ice",
      "rotation": 1
    },
    {
      "x": -27,
      "y": 0,
      "z": 3,
      "name": "Soil_Snow_Half"
    },
    {
      "x": -27,
      "y": -1,
      "z": 4,
      "name": "Rock_Ice",
      "rotation": 1
    },
    {
      "x": -27,
      "y": 0,
      "z": 4,
      "name": "Soil_Snow_Half"
    },
    {
      "x": -27,
      "y": -1,
      "z": 5,
      "name": "Rock_Ice",
      "rotation": 1
    },
    {
      "x": -27,
      "y": 0,
      "z": 5,
      "name": "Soil_Snow_Half"
    },
    {
      "x": -27,
      "y": -1,
      "z": 6,
      "name": "Rock_Ice",
      "rotation": 1
    },
    {
      "x": -27,
      "y": 0,
      "z": 6,
      "name": "Soil_Snow_Half"
    },
    {
      "x": -27,
      "y": -1,
      "z": 7,
      "name": "Rock_Ice",
      "rotation": 1
    },
    {
      "x": -27,
      "y": 0,
      "z": 7,
      "name": "Soil_Snow_Half"
    },
    {
      "x": -27,
      "y": -1,
      "z": 8,
      "name": "Rock_Ice",
      "rotation": 1
    },
    {
      "x": -27,
      "y": 0,
      "z": 8,
      "name": "Soil_Snow_Half"
    },
    {
      "x": -26,
      "y": -1,
      "z": -7,
      "name": "Rock_Ice",
      "rotation": 1
    },
    {
      "x": -26,
      "y": 0,
      "z": -7,
      "name": "Soil_Snow_Half"
    },
    {
      "x": -26,
      "y": -1,
      "z": -6,
      "name": "Rock_Ice",
      "rotation": 1
    },
    {
      "x": -26,
      "y": 0,
      "z": -6,
      "name": "Soil_Snow_Half"
    },
    {
      "x": -26,
      "y": -1,
      "z": -5,
      "name": "Rock_Ice",
      "rotation": 1
    },
    {
      "x": -26,
      "y": 0,
      "z": -5,
      "name": "Soil_Snow_Half"
    },
    {
      "x": -26,
      "y": -1,
      "z": -4,
      "name": "Rock_Ice",
      "rotation": 1
    },
    {
      "x": -26,
      "y": 0,
      "z": -4,
      "name": "Soil_Snow_Half"
    },
    {
      "x": -26,
      "y": -1,
      "z": -3,
      "name": "Rock_Ice",
      "rotation": 1
    },
    {
      "x": -26,
      "y": 0,
      "z": -3,
      "name": "Soil_Snow_Half"
    },
    {
      "x": -26,
      "y": 0,
      "z": -2,
      "name": "Soil_Snow_Half"
    },
    {
      "x": -26,
      "y": 0,
      "z": -1,
      "name": "Soil_Snow_Half"
    },
    {
      "x": -26,
      "y": 0,
      "z": 0,
      "name": "Rock_Ice_Permafrost"
    },
    {
      "x": -26,
      "y": 1,
      "z": 0,
      "name": "Soil_Snow_Half"
    },
    {
      "x": -26,
      "y": 0,
      "z": 1,
      "name": "Rock_Ice",
      "rotation": 1
    },
    {
      "x": -26,
      "y": 1,
      "z": 1,
      "name": "Soil_Snow_Half"
    },
    {
      "x": -26,
      "y": 0,
      "z": 2,
      "name": "Rock_Ice",
      "rotation": 1
    },
    {
      "x": -26,
      "y": 1,
      "z": 2,
      "name": "Soil_Snow_Half"
    },
    {
      "x": -26,
      "y": -1,
      "z": 3,
      "name": "Rock_Ice",
      "rotation": 1
    },
    {
      "x": -26,
      "y": 0,
      "z": 3,
      "name": "Soil_Snow_Half"
    },
    {
      "x": -26,
      "y": -1,
      "z": 4,
      "name": "Rock_Ice",
      "rotation": 1
    },
    {
      "x": -26,
      "y": 0,
      "z": 4,
      "name": "Soil_Snow_Half"
    },
    {
      "x": -26,
      "y": -1,
      "z": 5,
      "name": "Rock_Ice",
      "rotation": 1
    },
    {
      "x": -26,
      "y": 0,
      "z": 5,
      "name": "Soil_Snow_Half"
    },
    {
      "x": -26,
      "y": -1,
      "z": 6,
      "name": "Rock_Ice",
      "rotation": 1
    },
    {
      "x": -26,
      "y": 0,
      "z": 6,
      "name": "Soil_Snow_Half"
    },
    {
      "x": -26,
      "y": -11,
      "z": 7,
      "name": "Rock_Shale_Cobble"
    },
    {
      "x": -26,
      "y": -10,
      "z": 7,
      "name": "Rock_Shale_Cobble"
    },
    {
      "x": -26,
      "y": -9,
      "z": 7,
      "name": "Rock_Shale_Cobble"
    },
    {
      "x": -26,
      "y": -1,
      "z": 7,
      "name": "Rock_Ice",
      "rotation": 1
    },
    {
      "x": -26,
      "y": 0,
      "z": 7,
      "name": "Soil_Snow_Half"
    },
    {
      "x": -26,
      "y": -11,
      "z": 8,
      "name": "Rock_Shale_Cobble"
    },
    {
      "x": -26,
      "y": -10,
      "z": 8,
      "name": "Rock_Shale_Cobble"
    },
    {
      "x": -26,
      "y": -9,
      "z": 8,
      "name": "Rock_Shale_Cobble"
    },
    {
      "x": -26,
      "y": -8,
      "z": 8,
      "name": "Rock_Shale_Cobble"
    },
    {
      "x": -26,
      "y": -1,
      "z": 8,
      "name": "Rock_Ice",
      "rotation": 1
    },
    {
      "x": -26,
      "y": 0,
      "z": 8,
      "name": "Soil_Snow_Half"
    },
    {
      "x": -26,
      "y": -11,
      "z": 9,
      "name": "Rock_Shale_Cobble"
    },
    {
      "x": -26,
      "y": -10,
      "z": 9,
      "name": "Rock_Shale_Cobble"
    },
    {
      "x": -26,
      "y": -9,
      "z": 9,
      "name": "Rock_Shale_Cobble"
    },
    {
      "x": -26,
      "y": -8,
      "z": 9,
      "name": "Rock_Shale_Cobble"
    },
    {
      "x": -26,
      "y": -1,
      "z": 9,
      "name": "Rock_Ice",
      "rotation": 1
    },
    {
      "x": -26,
      "y": 0,
      "z": 9,
      "name": "Soil_Snow_Half"
    },
    {
      "x": -26,
      "y": -11,
      "z": 10,
      "name": "Rock_Shale_Cobble"
    },
    {
      "x": -26,
      "y": -10,
      "z": 10,
      "name": "Rock_Shale_Cobble"
    },
    {
      "x": -26,
      "y": -9,
      "z": 10,
      "name": "Rock_Shale_Cobble"
    },
    {
      "x": -26,
      "y": -8,
      "z": 10,
      "name": "Rock_Shale_Cobble"
    },
    {
      "x": -26,
      "y": -1,
      "z": 10,
      "name": "Rock_Ice",
      "rotation": 1
    },
    {
      "x": -26,
      "y": 0,
      "z": 10,
      "name": "Soil_Snow_Half"
    },
    {
      "x": -26,
      "y": -11,
      "z": 11,
      "name": "Rock_Shale_Cobble"
    },
    {
      "x": -26,
      "y": -10,
      "z": 11,
      "name": "Rock_Shale_Cobble"
    },
    {
      "x": -26,
      "y": -9,
      "z": 11,
      "name": "Rock_Shale_Cobble"
    },
    {
      "x": -26,
      "y": -8,
      "z": 11,
      "name": "Rock_Shale_Cobble"
    },
    {
      "x": -26,
      "y": -11,
      "z": 12,
      "name": "Rock_Shale_Cobble"
    },
    {
      "x": -26,
      "y": -10,
      "z": 12,
      "name": "Rock_Shale_Cobble"
    },
    {
      "x": -26,
      "y": -9,
      "z": 12,
      "name": "Rock_Shale_Cobble"
    },
    {
      "x": -26,
      "y": -8,
      "z": 12,
      "name": "Rock_Shale_Cobble"
    },
    {
      "x": -26,
      "y": -11,
      "z": 13,
      "name": "Rock_Shale_Cobble"
    },
    {
      "x": -26,
      "y": -10,
      "z": 13,
      "name": "Rock_Shale_Cobble"
    },
    {
      "x": -26,
      "y": -9,
      "z": 13,
      "name": "Rock_Shale_Cobble"
    },
    {
      "x": -25,
      "y": -1,
      "z": -8,
      "name": "Rock_Ice",
      "rotation": 1
    },
    {
      "x": -25,
      "y": 0,
      "z": -8,
      "name": "Soil_Snow_Half"
    },
    {
      "x": -25,
      "y": -1,
      "z": -7,
      "name": "Rock_Ice",
      "rotation": 1
    },
    {
      "x": -25,
      "y": 0,
      "z": -7,
      "name": "Soil_Snow_Half"
    },
    {
      "x": -25,
      "y": -1,
      "z": -6,
      "name": "Rock_Ice",
      "rotation": 1
    },
    {
      "x": -25,
      "y": 0,
      "z": -6,
      "name": "Soil_Snow_Half"
    },
    {
      "x": -25,
      "y": -1,
      "z": -5,
      "name": "Rock_Ice",
      "rotation": 1
    },
    {
      "x": -25,
      "y": 0,
      "z": -5,
      "name": "Soil_Snow_Half"
    },
    {
      "x": -25,
      "y": 0,
      "z": -4,
      "name": "Rock_Shale_Brick_Smooth"
    },
    {
      "x": -25,
      "y": 1,
      "z": -4,
      "name": "Rock_Shale_Brick_Smooth"
    },
    {
      "x": -25,
      "y": 2,
      "z": -4,
      "name": "Rock_Shale_Brick_Pillar_Base"
    },
    {
      "x": -25,
      "y": 3,
      "z": -4,
      "name": "Rock_Shale_Brick_Pillar_Middle"
    },
    {
      "x": -25,
      "y": 4,
      "z": -4,
      "name": "Rock_Shale_Brick_Pillar_Middle"
    },
    {
      "x": -25,
      "y": 5,
      "z": -4,
      "name": "Rock_Shale_Brick_Pillar_Base",
      "rotation": 8
    },
    {
      "x": -25,
      "y": 6,
      "z": -4,
      "name": "Rock_Shale_Brick_Smooth",
      "rotation": 1
    },
    {
      "x": -25,
      "y": 0,
      "z": -3,
      "name": "Rock_Shale_Brick_Smooth"
    },
    {
      "x": -25,
      "y": 1,
      "z": -3,
      "name": "Rock_Shale_Brick_Smooth"
    },
    {
      "x": -25,
      "y": 2,
      "z": -3,
      "name": "Rock_Ice",
      "rotation": 1
    },
    {
      "x": -25,
      "y": 3,
      "z": -3,
      "name": "Rock_Ice_Permafrost",
      "rotation": 1
    },
    {
      "x": -25,
      "y": 4,
      "z": -3,
      "name": "Rock_Shale_Brick_Pillar_Middle"
    },
    {
      "x": -25,
      "y": 5,
      "z": -3,
      "name": "Rock_Shale_Brick_Pillar_Base",
      "rotation": 8
    },
    {
      "x": -25,
      "y": 6,
      "z": -3,
      "name": "Rock_Shale_Brick_Smooth",
      "rotation": 1
    },
    {
      "x": -25,
      "y": 0,
      "z": -2,
      "name": "Rock_Ice_Permafrost"
    },
    {
      "x": -25,
      "y": 1,
      "z": -2,
      "name": "Rock_Ice",
      "rotation": 1
    },
    {
      "x": -25,
      "y": 7,
      "z": -2,
      "name": "Rock_Ice",
      "rotation": 1
    },
    {
      "x": -25,
      "y": 0,
      "z": -1,
      "name": "Rock_Ice",
      "rotation": 1
    },
    {
      "x": -25,
      "y": 1,
      "z": -1,
      "name": "Rock_Ice_Permafrost"
    },
    {
      "x": -25,
      "y": 6,
      "z": -1,
      "name": "Rock_Ice"
    },
    {
      "x": -25,
      "y": 7,
      "z": -1,
      "name": "Rock_Ice",
      "rotation": 1
    },
    {
      "x": -25,
      "y": 0,
      "z": 0,
      "name": "Rock_Stone",
      "rotation": 1
    },
    {
      "x": -25,
      "y": 1,
      "z": 0,
      "name": "Rock_Ice_Permafrost"
    },
    {
      "x": -25,
      "y": 7,
      "z": 0,
      "name": "Rock_Ice",
      "rotation": 1
    },
    {
      "x": -25,
      "y": 0,
      "z": 1,
      "name": "Rock_Stone",
      "rotation": 1
    },
    {
      "x": -25,
      "y": 1,
      "z": 1,
      "name": "Rock_Ice",
      "rotation": 1
    },
    {
      "x": -25,
      "y": 6,
      "z": 1,
      "name": "Rock_Ice"
    },
    {
      "x": -25,
      "y": 7,
      "z": 1,
      "name": "Rock_Ice",
      "rotation": 1
    },
    {
      "x": -25,
      "y": 8,
      "z": 1,
      "name": "Soil_Snow_Half"
    },
    {
      "x": -25,
      "y": -11,
      "z": 2,
      "name": "Rock_Shale_Cobble",
      "rotation": 1
    },
    {
      "x": -25,
      "y": -10,
      "z": 2,
      "name": "Rock_Shale_Cobble",
      "rotation": 1
    },
    {
      "x": -25,
      "y": -9,
      "z": 2,
      "name": "Rock_Shale_Brick_Smooth"
    },
    {
      "x": -25,
      "y": -8,
      "z": 2,
      "name": "Rock_Shale_Cobble"
    },
    {
      "x": -25,
      "y": -7,
      "z": 2,
      "name": "Rock_Shale_Cobble"
    },
    {
      "x": -25,
      "y": 0,
      "z": 2,
      "name": "Rock_Stone",
      "rotation": 1
    },
    {
      "x": -25,
      "y": 1,
      "z": 2,
      "name": "Rock_Ice",
      "rotation": 1
    },
    {
      "x": -25,
      "y": 5,
      "z": 2,
      "name": "Rock_Ice"
    },
    {
      "x": -25,
      "y": 6,
      "z": 2,
      "name": "Rock_Ice"
    },
    {
      "x": -25,
      "y": 7,
      "z": 2,
      "name": "Rock_Ice",
      "rotation": 1
    },
    {
      "x": -25,
      "y": 8,
      "z": 2,
      "name": "Soil_Snow_Half"
    },
    {
      "x": -25,
      "y": -11,
      "z": 3,
      "name": "Rock_Shale_Cobble",
      "rotation": 1
    },
    {
      "x": -25,
      "y": -10,
      "z": 3,
      "name": "Rock_Shale_Cobble",
      "rotation": 1
    },
    {
      "x": -25,
      "y": -9,
      "z": 3,
      "name": "Rock_Shale_Brick_Smooth"
    },
    {
      "x": -25,
      "y": -8,
      "z": 3,
      "name": "Rock_Shale_Cobble",
      "rotation": 1
    },
    {
      "x": -25,
      "y": -7,
      "z": 3,
      "name": "Rock_Shale_Cobble",
      "rotation": 1
    },
    {
      "x": -25,
      "y": 0,
      "z": 3,
      "name": "Rock_Shale_Brick_Smooth"
    },
    {
      "x": -25,
      "y": 1,
      "z": 3,
      "name": "Rock_Shale_Brick_Smooth"
    },
    {
      "x": -25,
      "y": 2,
      "z": 3,
      "name": "Rock_Shale_Brick_Pillar_Base"
    },
    {
      "x": -25,
      "y": 3,
      "z": 3,
      "name": "Rock_Shale_Brick_Pillar_Middle"
    },
    {
      "x": -25,
      "y": 4,
      "z": 3,
      "name": "Rock_Shale_Brick_Pillar_Middle",
      "rotation": 8
    },
    {
      "x": -25,
      "y": 5,
      "z": 3,
      "name": "Rock_Shale_Brick_Pillar_Base",
      "rotation": 8
    },
    {
      "x": -25,
      "y": 6,
      "z": 3,
      "name": "Rock_Shale_Brick_Smooth",
      "rotation": 1
    },
    {
      "x": -25,
      "y": -11,
      "z": 4,
      "name": "Rock_Shale_Cobble",
      "rotation": 1
    },
    {
      "x": -25,
      "y": -10,
      "z": 4,
      "name": "Rock_Shale_Cobble",
      "rotation": 1
    },
    {
      "x": -25,
      "y": -9,
      "z": 4,
      "name": "Rock_Shale_Brick_Smooth"
    },
    {
      "x": -25,
      "y": -8,
      "z": 4,
      "name": "Rock_Shale_Cobble",
      "rotation": 1
    },
    {
      "x": -25,
      "y": -7,
      "z": 4,
      "name": "Rock_Shale_Cobble",
      "rotation": 1
    },
    {
      "x": -25,
      "y": 0,
      "z": 4,
      "name": "Rock_Shale_Brick_Smooth"
    },
    {
      "x": -25,
      "y": 1,
      "z": 4,
      "name": "Rock_Shale_Brick_Smooth"
    },
    {
      "x": -25,
      "y": 2,
      "z": 4,
      "name": "Rock_Shale_Brick_Pillar_Base"
    },
    {
      "x": -25,
      "y": 3,
      "z": 4,
      "name": "Rock_Shale_Brick_Pillar_Middle"
    },
    {
      "x": -25,
      "y": 4,
      "z": 4,
      "name": "Rock_Shale_Brick_Pillar_Middle",
      "rotation": 8
    },
    {
      "x": -25,
      "y": 5,
      "z": 4,
      "name": "Rock_Ice_Permafrost",
      "rotation": 1
    },
    {
      "x": -25,
      "y": 6,
      "z": 4,
      "name": "Rock_Ice_Permafrost",
      "rotation": 1
    },
    {
      "x": -25,
      "y": 7,
      "z": 4,
      "name": "Rock_Ice_Stalactite_Large"
    },
    {
      "x": -25,
      "y": 8,
      "z": 4,
      "name": "Rock_Ice_Stalactite_Large",
      "filler": 1024
    },
    {
      "x": -25,
      "y": -11,
      "z": 5,
      "name": "Rock_Shale_Cobble",
      "rotation": 1
    },
    {
      "x": -25,
      "y": -10,
      "z": 5,
      "name": "Rock_Shale_Cobble",
      "rotation": 1
    },
    {
      "x": -25,
      "y": -9,
      "z": 5,
      "name": "Rock_Shale_Cobble",
      "rotation": 1
    },
    {
      "x": -25,
      "y": -8,
      "z": 5,
      "name": "Rock_Shale_Cobble",
      "rotation": 1
    },
    {
      "x": -25,
      "y": -7,
      "z": 5,
      "name": "Rock_Shale_Cobble",
      "rotation": 1
    },
    {
      "x": -25,
      "y": -1,
      "z": 5,
      "name": "Rock_Ice",
      "rotation": 1
    },
    {
      "x": -25,
      "y": 0,
      "z": 5,
      "name": "Soil_Snow_Half"
    },
    {
      "x": -25,
      "y": -11,
      "z": 6,
      "name": "Rock_Shale_Cobble",
      "rotation": 1
    },
    {
      "x": -25,
      "y": -10,
      "z": 6,
      "name": "Rock_Shale_Cobble",
      "rotation": 1
    },
    {
      "x": -25,
      "y": -9,
      "z": 6,
      "name": "Rock_Shale_Cobble",
      "rotation": 1
    },
    {
      "x": -25,
      "y": -8,
      "z": 6,
      "name": "Rock_Shale_Cobble",
      "rotation": 1
    },
    {
      "x": -25,
      "y": -7,
      "z": 6,
      "name": "Rock_Shale_Cobble",
      "rotation": 1
    },
    {
      "x": -25,
      "y": -1,
      "z": 6,
      "name": "Rock_Ice",
      "rotation": 1
    },
    {
      "x": -25,
      "y": 0,
      "z": 6,
      "name": "Soil_Snow_Half"
    },
    {
      "x": -25,
      "y": -12,
      "z": 7,
      "name": "Rock_Shale_Cobble"
    },
    {
      "x": -25,
      "y": -11,
      "z": 7,
      "name": "Rock_Shale_Brick_Pillar_Base"
    },
    {
      "x": -25,
      "y": -10,
      "z": 7,
      "name": "Rock_Shale_Brick_Pillar_Middle",
      "rotation": 1
    },
    {
      "x": -25,
      "y": -9,
      "z": 7,
      "name": "Rock_Shale_Brick_Pillar_Base",
      "rotation": 8
    },
    {
      "x": -25,
      "y": -8,
      "z": 7,
      "name": "Rock_Shale_Cobble",
      "rotation": 1
    },
    {
      "x": -25,
      "y": -7,
      "z": 7,
      "name": "Rock_Shale_Brick"
    },
    {
      "x": -25,
      "y": -1,
      "z": 7,
      "name": "Rock_Ice",
      "rotation": 1
    },
    {
      "x": -25,
      "y": 0,
      "z": 7,
      "name": "Soil_Snow_Half"
    },
    {
      "x": -25,
      "y": -12,
      "z": 8,
      "name": "Rock_Shale_Cobble"
    },
    {
      "x": -25,
      "y": -11,
      "z": 8,
      "name": "Empty"
    },
    {
      "x": -25,
      "y": -10,
      "z": 8,
      "name": "Empty"
    },
    {
      "x": -25,
      "y": -9,
      "z": 8,
      "name": "Empty"
    },
    {
      "x": -25,
      "y": -8,
      "z": 8,
      "name": "Rock_Shale_Brick_Stairs",
      "rotation": 10
    },
    {
      "x": -25,
      "y": -7,
      "z": 8,
      "name": "Rock_Shale_Brick"
    },
    {
      "x": -25,
      "y": -1,
      "z": 8,
      "name": "Rock_Ice",
      "rotation": 1
    },
    {
      "x": -25,
      "y": 0,
      "z": 8,
      "name": "Soil_Snow_Half"
    },
    {
      "x": -25,
      "y": -12,
      "z": 9,
      "name": "Rock_Shale_Cobble",
      "rotation": 1
    },
    {
      "x": -25,
      "y": -11,
      "z": 9,
      "name": "OrbisGalactic_Ilum_Temple_Light"
    },
    {
      "x": -25,
      "y": -10,
      "z": 9,
      "name": "Empty"
    },
    {
      "x": -25,
      "y": -9,
      "z": 9,
      "name": "Empty"
    },
    {
      "x": -25,
      "y": -8,
      "z": 9,
      "name": "Rock_Shale_Brick_Stairs",
      "rotation": 8
    },
    {
      "x": -25,
      "y": -7,
      "z": 9,
      "name": "Rock_Shale_Brick"
    },
    {
      "x": -25,
      "y": -1,
      "z": 9,
      "name": "Rock_Ice",
      "rotation": 1
    },
    {
      "x": -25,
      "y": 0,
      "z": 9,
      "name": "Soil_Snow_Half"
    },
    {
      "x": -25,
      "y": -12,
      "z": 10,
      "name": "Rock_Shale_Cobble",
      "rotation": 1
    },
    {
      "x": -25,
      "y": -11,
      "z": 10,
      "name": "Rock_Shale_Brick_Pillar_Base"
    },
    {
      "x": -25,
      "y": -10,
      "z": 10,
      "name": "Rock_Shale_Brick_Pillar_Middle",
      "rotation": 1
    },
    {
      "x": -25,
      "y": -9,
      "z": 10,
      "name": "Rock_Shale_Brick_Pillar_Base",
      "rotation": 8
    },
    {
      "x": -25,
      "y": -8,
      "z": 10,
      "name": "Rock_Shale_Cobble",
      "rotation": 1
    },
    {
      "x": -25,
      "y": -7,
      "z": 10,
      "name": "Rock_Shale_Brick"
    },
    {
      "x": -25,
      "y": -1,
      "z": 10,
      "name": "Rock_Ice",
      "rotation": 1
    },
    {
      "x": -25,
      "y": 0,
      "z": 10,
      "name": "Soil_Snow_Half"
    },
    {
      "x": -25,
      "y": -12,
      "z": 11,
      "name": "Rock_Shale_Cobble",
      "rotation": 1
    },
    {
      "x": -25,
      "y": -11,
      "z": 11,
      "name": "OrbisGalactic_Ilum_Temple_Light"
    },
    {
      "x": -25,
      "y": -10,
      "z": 11,
      "name": "Empty"
    },
    {
      "x": -25,
      "y": -9,
      "z": 11,
      "name": "Empty"
    },
    {
      "x": -25,
      "y": -8,
      "z": 11,
      "name": "Rock_Shale_Brick_Stairs",
      "rotation": 10
    },
    {
      "x": -25,
      "y": -7,
      "z": 11,
      "name": "Rock_Shale_Brick"
    },
    {
      "x": -25,
      "y": -1,
      "z": 11,
      "name": "Rock_Ice",
      "rotation": 1
    },
    {
      "x": -25,
      "y": 0,
      "z": 11,
      "name": "Soil_Snow_Half"
    },
    {
      "x": -25,
      "y": -12,
      "z": 12,
      "name": "Rock_Shale_Cobble",
      "rotation": 1
    },
    {
      "x": -25,
      "y": -11,
      "z": 12,
      "name": "Empty"
    },
    {
      "x": -25,
      "y": -10,
      "z": 12,
      "name": "Empty"
    },
    {
      "x": -25,
      "y": -9,
      "z": 12,
      "name": "Empty"
    },
    {
      "x": -25,
      "y": -8,
      "z": 12,
      "name": "Rock_Shale_Brick_Stairs",
      "rotation": 8
    },
    {
      "x": -25,
      "y": -7,
      "z": 12,
      "name": "Rock_Shale_Brick"
    },
    {
      "x": -25,
      "y": -12,
      "z": 13,
      "name": "Rock_Shale_Cobble",
      "rotation": 1
    },
    {
      "x": -25,
      "y": -11,
      "z": 13,
      "name": "Rock_Shale_Brick_Pillar_Base"
    },
    {
      "x": -25,
      "y": -10,
      "z": 13,
      "name": "Rock_Shale_Brick_Pillar_Middle",
      "rotation": 1
    },
    {
      "x": -25,
      "y": -9,
      "z": 13,
      "name": "Rock_Shale_Brick_Pillar_Base",
      "rotation": 8
    },
    {
      "x": -25,
      "y": -8,
      "z": 13,
      "name": "Rock_Shale_Cobble",
      "rotation": 1
    },
    {
      "x": -25,
      "y": -7,
      "z": 13,
      "name": "Rock_Shale_Brick"
    },
    {
      "x": -25,
      "y": -12,
      "z": 14,
      "name": "Rock_Shale_Cobble",
      "rotation": 1
    },
    {
      "x": -25,
      "y": -11,
      "z": 14,
      "name": "Rock_Shale_Cobble",
      "rotation": 1
    },
    {
      "x": -25,
      "y": -10,
      "z": 14,
      "name": "Rock_Shale_Cobble",
      "rotation": 1
    },
    {
      "x": -25,
      "y": -9,
      "z": 14,
      "name": "Rock_Shale_Cobble",
      "rotation": 1
    },
    {
      "x": -25,
      "y": -8,
      "z": 14,
      "name": "Rock_Shale_Cobble",
      "rotation": 1
    },
    {
      "x": -25,
      "y": -7,
      "z": 14,
      "name": "Rock_Shale_Brick"
    },
    {
      "x": -25,
      "y": -11,
      "z": 15,
      "name": "Rock_Shale_Brick"
    },
    {
      "x": -25,
      "y": -10,
      "z": 15,
      "name": "Rock_Shale_Brick"
    },
    {
      "x": -25,
      "y": -9,
      "z": 15,
      "name": "Rock_Shale_Brick"
    },
    {
      "x": -24,
      "y": -1,
      "z": -9,
      "name": "Rock_Ice",
      "rotation": 1
    },
    {
      "x": -24,
      "y": 0,
      "z": -9,
      "name": "Soil_Snow_Half"
    },
    {
      "x": -24,
      "y": -1,
      "z": -8,
      "name": "Rock_Ice",
      "rotation": 1
    },
    {
      "x": -24,
      "y": 0,
      "z": -8,
      "name": "Soil_Snow_Half"
    },
    {
      "x": -24,
      "y": -1,
      "z": -7,
      "name": "Rock_Ice",
      "rotation": 1
    },
    {
      "x": -24,
      "y": 0,
      "z": -7,
      "name": "Soil_Snow_Half"
    },
    {
      "x": -24,
      "y": 0,
      "z": -6,
      "name": "Rock_Ice",
      "rotation": 1
    },
    {
      "x": -24,
      "y": 1,
      "z": -6,
      "name": "Soil_Snow_Half"
    },
    {
      "x": -24,
      "y": 0,
      "z": -5,
      "name": "Rock_Ice",
      "rotation": 1
    },
    {
      "x": -24,
      "y": 0,
      "z": -4,
      "name": "Rock_Shale_Brick_Smooth"
    },
    {
      "x": -24,
      "y": 1,
      "z": -4,
      "name": "Rock_Shale_Brick_Smooth"
    },
    {
      "x": -24,
      "y": 2,
      "z": -4,
      "name": "Rock_Shale_Brick_Smooth",
      "rotation": 1
    },
    {
      "x": -24,
      "y": 3,
      "z": -4,
      "name": "Rock_Shale_Brick_Smooth",
      "rotation": 1
    },
    {
      "x": -24,
      "y": 4,
      "z": -4,
      "name": "Rock_Shale_Brick_Smooth",
      "rotation": 1
    },
    {
      "x": -24,
      "y": 5,
      "z": -4,
      "name": "Rock_Shale_Brick_Smooth",
      "rotation": 1
    },
    {
      "x": -24,
      "y": 6,
      "z": -4,
      "name": "Rock_Shale_Brick_Smooth",
      "rotation": 1
    },
    {
      "x": -24,
      "y": 7,
      "z": -4,
      "name": "Rock_Ice",
      "rotation": 1
    },
    {
      "x": -24,
      "y": 0,
      "z": -3,
      "name": "Rock_Shale_Brick_Smooth"
    },
    {
      "x": -24,
      "y": 1,
      "z": -3,
      "name": "Rock_Stone",
      "rotation": 1
    },
    {
      "x": -24,
      "y": 2,
      "z": -3,
      "name": "Rock_Shale_Brick_Smooth",
      "rotation": 1
    },
    {
      "x": -24,
      "y": 3,
      "z": -3,
      "name": "Rock_Shale_Brick_Smooth",
      "rotation": 1
    },
    {
      "x": -24,
      "y": 4,
      "z": -3,
      "name": "Rock_Shale_Brick_Smooth",
      "rotation": 1
    },
    {
      "x": -24,
      "y": 5,
      "z": -3,
      "name": "Rock_Shale_Brick_Smooth",
      "rotation": 1
    },
    {
      "x": -24,
      "y": 6,
      "z": -3,
      "name": "Rock_Shale_Brick_Smooth",
      "rotation": 1
    },
    {
      "x": -24,
      "y": 7,
      "z": -3,
      "name": "Rock_Ice",
      "rotation": 1
    },
    {
      "x": -24,
      "y": 8,
      "z": -3,
      "name": "Soil_Snow_Half"
    },
    {
      "x": -24,
      "y": 0,
      "z": -2,
      "name": "Rock_Stone",
      "rotation": 1
    },
    {
      "x": -24,
      "y": 1,
      "z": -2,
      "name": "Rock_Stone",
      "rotation": 1
    },
    {
      "x": -24,
      "y": 2,
      "z": -2,
      "name": "Rock_Runic_Brick",
      "rotation": 1
    },
    {
      "x": -24,
      "y": 3,
      "z": -2,
      "name": "Rock_Runic_Brick",
      "rotation": 1
    },
    {
      "x": -24,
      "y": 4,
      "z": -2,
      "name": "Rock_Calcite_Brick",
      "rotation": 1
    },
    {
      "x": -24,
      "y": 5,
      "z": -2,
      "name": "Rock_Runic_Brick",
      "rotation": 1
    },
    {
      "x": -24,
      "y": 6,
      "z": -2,
      "name": "Rock_Runic_Brick",
      "rotation": 1
    },
    {
      "x": -24,
      "y": 7,
      "z": -2,
      "name": "Rock_Runic_Brick",
      "rotation": 1
    },
    {
      "x": -24,
      "y": 8,
      "z": -2,
      "name": "Rock_Shale_Brick_Pillar_Base"
    },
    {
      "x": -24,
      "y": 9,
      "z": -2,
      "name": "Rock_Shale_Cobble_Half"
    },
    {
      "x": -24,
      "y": 0,
      "z": -1,
      "name": "Rock_Stone",
      "rotation": 1
    },
    {
      "x": -24,
      "y": 1,
      "z": -1,
      "name": "Rock_Stone",
      "rotation": 1
    },
    {
      "x": -24,
      "y": 2,
      "z": -1,
      "name": "Rock_Runic_Brick",
      "rotation": 1
    },
    {
      "x": -24,
      "y": 3,
      "z": -1,
      "name": "Rock_Runic_Brick",
      "rotation": 1
    },
    {
      "x": -24,
      "y": 4,
      "z": -1,
      "name": "Rock_Calcite_Brick",
      "rotation": 1
    },
    {
      "x": -24,
      "y": 5,
      "z": -1,
      "name": "Rock_Calcite_Brick",
      "rotation": 1
    },
    {
      "x": -24,
      "y": 6,
      "z": -1,
      "name": "Rock_Calcite_Brick",
      "rotation": 1
    },
    {
      "x": -24,
      "y": 7,
      "z": -1,
      "name": "Rock_Runic_Brick",
      "rotation": 1
    },
    {
      "x": -24,
      "y": 9,
      "z": -1,
      "name": "Rock_Shale_Cobble_Half"
    },
    {
      "x": -24,
      "y": -11,
      "z": 0,
      "name": "Rock_Shale_Cobble",
      "rotation": 1
    },
    {
      "x": -24,
      "y": -10,
      "z": 0,
      "name": "Rock_Shale_Cobble",
      "rotation": 1
    },
    {
      "x": -24,
      "y": -9,
      "z": 0,
      "name": "Rock_Shale_Cobble",
      "rotation": 1
    },
    {
      "x": -24,
      "y": -8,
      "z": 0,
      "name": "Rock_Shale_Cobble",
      "rotation": 1
    },
    {
      "x": -24,
      "y": -7,
      "z": 0,
      "name": "Rock_Shale_Cobble",
      "rotation": 1
    },
    {
      "x": -24,
      "y": 0,
      "z": 0,
      "name": "Rock_Stone",
      "rotation": 1
    },
    {
      "x": -24,
      "y": 1,
      "z": 0,
      "name": "Rock_Stone",
      "rotation": 1
    },
    {
      "x": -24,
      "y": 2,
      "z": 0,
      "name": "Rock_Runic_Brick",
      "rotation": 1
    },
    {
      "x": -24,
      "y": 3,
      "z": 0,
      "name": "Rock_Runic_Brick",
      "rotation": 1
    },
    {
      "x": -24,
      "y": 4,
      "z": 0,
      "name": "Rock_Calcite_Brick",
      "rotation": 1
    },
    {
      "x": -24,
      "y": 5,
      "z": 0,
      "name": "Rock_Runic_Brick",
      "rotation": 1
    },
    {
      "x": -24,
      "y": 6,
      "z": 0,
      "name": "Rock_Runic_Brick",
      "rotation": 1
    },
    {
      "x": -24,
      "y": 7,
      "z": 0,
      "name": "Rock_Runic_Brick",
      "rotation": 1
    },
    {
      "x": -24,
      "y": 9,
      "z": 0,
      "name": "Rock_Shale_Cobble_Half"
    },
    {
      "x": -24,
      "y": -12,
      "z": 1,
      "name": "Rock_Shale_Cobble",
      "rotation": 1
    },
    {
      "x": -24,
      "y": -11,
      "z": 1,
      "name": "Rock_Shale_Cobble",
      "rotation": 1
    },
    {
      "x": -24,
      "y": -10,
      "z": 1,
      "name": "Rock_Shale_Cobble",
      "rotation": 1
    },
    {
      "x": -24,
      "y": -9,
      "z": 1,
      "name": "Rock_Shale_Brick_Smooth"
    },
    {
      "x": -24,
      "y": -8,
      "z": 1,
      "name": "Rock_Shale_Brick_Smooth"
    },
    {
      "x": -24,
      "y": -7,
      "z": 1,
      "name": "Rock_Shale_Cobble",
      "rotation": 1
    },
    {
      "x": -24,
      "y": 0,
      "z": 1,
      "name": "Rock_Stone",
      "rotation": 1
    },
    {
      "x": -24,
      "y": 1,
      "z": 1,
      "name": "Rock_Stone",
      "rotation": 1
    },
    {
      "x": -24,
      "y": 2,
      "z": 1,
      "name": "Rock_Calcite_Brick",
      "rotation": 1
    },
    {
      "x": -24,
      "y": 3,
      "z": 1,
      "name": "Rock_Calcite_Brick",
      "rotation": 1
    },
    {
      "x": -24,
      "y": 4,
      "z": 1,
      "name": "Rock_Calcite_Brick",
      "rotation": 1
    },
    {
      "x": -24,
      "y": 5,
      "z": 1,
      "name": "Rock_Runic_Brick",
      "rotation": 1
    },
    {
      "x": -24,
      "y": 6,
      "z": 1,
      "name": "Rock_Runic_Brick",
      "rotation": 1
    },
    {
      "x": -24,
      "y": 7,
      "z": 1,
      "name": "Rock_Runic_Brick",
      "rotation": 1
    },
    {
      "x": -24,
      "y": 9,
      "z": 1,
      "name": "Rock_Shale_Cobble_Half"
    },
    {
      "x": -24,
      "y": -12,
      "z": 2,
      "name": "Rock_Ice_Permafrost"
    },
    {
      "x": -24,
      "y": -11,
      "z": 2,
      "name": "Rock_Ice_Stalactite_Large"
    },
    {
      "x": -24,
      "y": -10,
      "z": 2,
      "name": "Rock_Ice_Stalactite_Large",
      "filler": 1024
    },
    {
      "x": -24,
      "y": -9,
      "z": 2,
      "name": "Empty"
    },
    {
      "x": -24,
      "y": -8,
      "z": 2,
      "name": "Empty"
    },
    {
      "x": -24,
      "y": -7,
      "z": 2,
      "name": "Rock_Shale_Brick"
    },
    {
      "x": -24,
      "y": 0,
      "z": 2,
      "name": "Rock_Stone",
      "rotation": 1
    },
    {
      "x": -24,
      "y": 1,
      "z": 2,
      "name": "Rock_Stone",
      "rotation": 1
    },
    {
      "x": -24,
      "y": 2,
      "z": 2,
      "name": "Rock_Runic_Brick",
      "rotation": 1
    },
    {
      "x": -24,
      "y": 3,
      "z": 2,
      "name": "Rock_Runic_Brick",
      "rotation": 1
    },
    {
      "x": -24,
      "y": 4,
      "z": 2,
      "name": "Rock_Calcite_Brick",
      "rotation": 1
    },
    {
      "x": -24,
      "y": 5,
      "z": 2,
      "name": "Rock_Runic_Brick",
      "rotation": 1
    },
    {
      "x": -24,
      "y": 6,
      "z": 2,
      "name": "Rock_Runic_Brick",
      "rotation": 1
    },
    {
      "x": -24,
      "y": 7,
      "z": 2,
      "name": "Rock_Runic_Brick",
      "rotation": 1
    },
    {
      "x": -24,
      "y": 8,
      "z": 2,
      "name": "Rock_Shale_Brick_Pillar_Base"
    },
    {
      "x": -24,
      "y": 9,
      "z": 2,
      "name": "Rock_Shale_Cobble_Half"
    },
    {
      "x": -24,
      "y": -12,
      "z": 3,
      "name": "Rock_Ice_Permafrost"
    },
    {
      "x": -24,
      "y": -11,
      "z": 3,
      "name": "Empty"
    },
    {
      "x": -24,
      "y": -10,
      "z": 3,
      "name": "Empty"
    },
    {
      "x": -24,
      "y": -9,
      "z": 3,
      "name": "Empty"
    },
    {
      "x": -24,
      "y": -8,
      "z": 3,
      "name": "Empty"
    },
    {
      "x": -24,
      "y": -7,
      "z": 3,
      "name": "Rock_Shale_Brick"
    },
    {
      "x": -24,
      "y": -6,
      "z": 3,
      "name": "Rock_Stone"
    },
    {
      "x": -24,
      "y": 0,
      "z": 3,
      "name": "Rock_Shale_Brick_Smooth"
    },
    {
      "x": -24,
      "y": 1,
      "z": 3,
      "name": "Rock_Stone",
      "rotation": 1
    },
    {
      "x": -24,
      "y": 2,
      "z": 3,
      "name": "Rock_Shale_Brick_Smooth",
      "rotation": 1
    },
    {
      "x": -24,
      "y": 3,
      "z": 3,
      "name": "Rock_Shale_Brick_Smooth",
      "rotation": 1
    },
    {
      "x": -24,
      "y": 4,
      "z": 3,
      "name": "Rock_Shale_Brick_Smooth",
      "rotation": 1
    },
    {
      "x": -24,
      "y": 5,
      "z": 3,
      "name": "Rock_Shale_Brick_Smooth",
      "rotation": 1
    },
    {
      "x": -24,
      "y": 6,
      "z": 3,
      "name": "Rock_Shale_Brick_Smooth",
      "rotation": 1
    },
    {
      "x": -24,
      "y": 7,
      "z": 3,
      "name": "Rock_Ice",
      "rotation": 1
    },
    {
      "x": -24,
      "y": 9,
      "z": 3,
      "name": "Rock_Shale_Cobble_Half"
    },
    {
      "x": -24,
      "y": -12,
      "z": 4,
      "name": "Rock_Shale_Cobble",
      "rotation": 1
    },
    {
      "x": -24,
      "y": -11,
      "z": 4,
      "name": "Empty"
    },
    {
      "x": -24,
      "y": -10,
      "z": 4,
      "name": "Empty"
    },
    {
      "x": -24,
      "y": -9,
      "z": 4,
      "name": "Empty"
    },
    {
      "x": -24,
      "y": -8,
      "z": 4,
      "name": "Empty"
    },
    {
      "x": -24,
      "y": -7,
      "z": 4,
      "name": "Rock_Shale_Brick"
    },
    {
      "x": -24,
      "y": -6,
      "z": 4,
      "name": "Rock_Stone"
    },
    {
      "x": -24,
      "y": 0,
      "z": 4,
      "name": "Rock_Shale_Brick_Smooth"
    },
    {
      "x": -24,
      "y": 1,
      "z": 4,
      "name": "Rock_Shale_Brick_Smooth"
    },
    {
      "x": -24,
      "y": 2,
      "z": 4,
      "name": "Rock_Shale_Brick_Smooth"
    },
    {
      "x": -24,
      "y": 3,
      "z": 4,
      "name": "Rock_Shale_Brick_Smooth",
      "rotation": 1
    },
    {
      "x": -24,
      "y": 4,
      "z": 4,
      "name": "Rock_Shale_Brick_Smooth",
      "rotation": 1
    },
    {
      "x": -24,
      "y": 5,
      "z": 4,
      "name": "Rock_Shale_Brick_Smooth"
    },
    {
      "x": -24,
      "y": 6,
      "z": 4,
      "name": "Rock_Stone",
      "rotation": 1
    },
    {
      "x": -24,
      "y": 7,
      "z": 4,
      "name": "Rock_Ice",
      "rotation": 1
    },
    {
      "x": -24,
      "y": -12,
      "z": 5,
      "name": "Rock_Ice",
      "rotation": 1
    },
    {
      "x": -24,
      "y": -11,
      "z": 5,
      "name": "Rock_Shale_Brick_Smooth"
    },
    {
      "x": -24,
      "y": -10,
      "z": 5,
      "name": "Rock_Stone",
      "rotation": 1
    },
    {
      "x": -24,
      "y": -9,
      "z": 5,
      "name": "Rock_Stone",
      "rotation": 1
    },
    {
      "x": -24,
      "y": -8,
      "z": 5,
      "name": "Rock_Stone",
      "rotation": 1
    },
    {
      "x": -24,
      "y": -7,
      "z": 5,
      "name": "Rock_Shale_Brick"
    },
    {
      "x": -24,
      "y": -6,
      "z": 5,
      "name": "Rock_Stone"
    },
    {
      "x": -24,
      "y": 0,
      "z": 5,
      "name": "Rock_Ice",
      "rotation": 1
    },
    {
      "x": -24,
      "y": 6,
      "z": 5,
      "name": "Rock_Ice"
    },
    {
      "x": -24,
      "y": -12,
      "z": 6,
      "name": "Rock_Shale_Cobble",
      "rotation": 1
    },
    {
      "x": -24,
      "y": -11,
      "z": 6,
      "name": "Rock_Shale_Brick_Smooth"
    },
    {
      "x": -24,
      "y": -10,
      "z": 6,
      "name": "Rock_Stone",
      "rotation": 1
    },
    {
      "x": -24,
      "y": -9,
      "z": 6,
      "name": "Rock_Shale_Brick_Pillar_Middle"
    },
    {
      "x": -24,
      "y": -8,
      "z": 6,
      "name": "Rock_Shale_Brick_Pillar_Middle"
    },
    {
      "x": -24,
      "y": -7,
      "z": 6,
      "name": "Rock_Shale_Brick_Pillar_Base",
      "rotation": 8
    },
    {
      "x": -24,
      "y": -6,
      "z": 6,
      "name": "Rock_Ice_Permafrost"
    },
    {
      "x": -24,
      "y": 0,
      "z": 6,
      "name": "Rock_Ice",
      "rotation": 1
    },
    {
      "x": -24,
      "y": -12,
      "z": 7,
      "name": "Rock_Shale_Cobble",
      "rotation": 1
    },
    {
      "x": -24,
      "y": -11,
      "z": 7,
      "name": "Empty"
    },
    {
      "x": -24,
      "y": -10,
      "z": 7,
      "name": "Empty"
    },
    {
      "x": -24,
      "y": -9,
      "z": 7,
      "name": "Empty"
    },
    {
      "x": -24,
      "y": -8,
      "z": 7,
      "name": "Empty"
    },
    {
      "x": -24,
      "y": -7,
      "z": 7,
      "name": "Empty"
    },
    {
      "x": -24,
      "y": -6,
      "z": 7,
      "name": "Rock_Ice"
    },
    {
      "x": -24,
      "y": -1,
      "z": 7,
      "name": "Rock_Ice",
      "rotation": 1
    },
    {
      "x": -24,
      "y": 0,
      "z": 7,
      "name": "Soil_Snow_Half"
    },
    {
      "x": -24,
      "y": -12,
      "z": 8,
      "name": "Rock_Shale_Brick_Smooth"
    },
    {
      "x": -24,
      "y": -11,
      "z": 8,
      "name": "Empty"
    },
    {
      "x": -24,
      "y": -10,
      "z": 8,
      "name": "Empty"
    },
    {
      "x": -24,
      "y": -9,
      "z": 8,
      "name": "Empty"
    },
    {
      "x": -24,
      "y": -8,
      "z": 8,
      "name": "Empty"
    },
    {
      "x": -24,
      "y": -7,
      "z": 8,
      "name": "Empty"
    },
    {
      "x": -24,
      "y": -6,
      "z": 8,
      "name": "Rock_Stone"
    },
    {
      "x": -24,
      "y": -1,
      "z": 8,
      "name": "Rock_Ice",
      "rotation": 1
    },
    {
      "x": -24,
      "y": 0,
      "z": 8,
      "name": "Soil_Snow_Half"
    },
    {
      "x": -24,
      "y": -12,
      "z": 9,
      "name": "Rock_Shale_Cobble",
      "rotation": 1
    },
    {
      "x": -24,
      "y": -11,
      "z": 9,
      "name": "Empty"
    },
    {
      "x": -24,
      "y": -10,
      "z": 9,
      "name": "Empty"
    },
    {
      "x": -24,
      "y": -9,
      "z": 9,
      "name": "Empty"
    },
    {
      "x": -24,
      "y": -8,
      "z": 9,
      "name": "Empty"
    },
    {
      "x": -24,
      "y": -7,
      "z": 9,
      "name": "Empty"
    },
    {
      "x": -24,
      "y": -6,
      "z": 9,
      "name": "Rock_Stone"
    },
    {
      "x": -24,
      "y": -1,
      "z": 9,
      "name": "Rock_Ice",
      "rotation": 1
    },
    {
      "x": -24,
      "y": 0,
      "z": 9,
      "name": "Soil_Snow_Half"
    },
    {
      "x": -24,
      "y": -12,
      "z": 10,
      "name": "Rock_Shale_Cobble",
      "rotation": 1
    },
    {
      "x": -24,
      "y": -11,
      "z": 10,
      "name": "Empty"
    },
    {
      "x": -24,
      "y": -10,
      "z": 10,
      "name": "Empty"
    },
    {
      "x": -24,
      "y": -9,
      "z": 10,
      "name": "Empty"
    },
    {
      "x": -24,
      "y": -8,
      "z": 10,
      "name": "Rock_Ice_Stalactite_Large",
      "filler": 31744,
      "rotation": 8
    },
    {
      "x": -24,
      "y": -7,
      "z": 10,
      "name": "Rock_Ice_Stalactite_Large",
      "rotation": 8
    },
    {
      "x": -24,
      "y": -6,
      "z": 10,
      "name": "Rock_Ice_Permafrost"
    },
    {
      "x": -24,
      "y": -1,
      "z": 10,
      "name": "Rock_Ice",
      "rotation": 1
    },
    {
      "x": -24,
      "y": 0,
      "z": 10,
      "name": "Soil_Snow_Half"
    },
    {
      "x": -24,
      "y": -12,
      "z": 11,
      "name": "Rock_Shale_Cobble",
      "rotation": 1
    },
    {
      "x": -24,
      "y": -11,
      "z": 11,
      "name": "Empty"
    },
    {
      "x": -24,
      "y": -10,
      "z": 11,
      "name": "Empty"
    },
    {
      "x": -24,
      "y": -9,
      "z": 11,
      "name": "Empty"
    },
    {
      "x": -24,
      "y": -8,
      "z": 11,
      "name": "Empty"
    },
    {
      "x": -24,
      "y": -7,
      "z": 11,
      "name": "Empty"
    },
    {
      "x": -24,
      "y": -6,
      "z": 11,
      "name": "Rock_Ice"
    },
    {
      "x": -24,
      "y": -1,
      "z": 11,
      "name": "Rock_Ice",
      "rotation": 1
    },
    {
      "x": -24,
      "y": 0,
      "z": 11,
      "name": "Soil_Snow_Half"
    },
    {
      "x": -24,
      "y": -12,
      "z": 12,
      "name": "Rock_Shale_Brick_Smooth"
    },
    {
      "x": -24,
      "y": -11,
      "z": 12,
      "name": "Empty"
    },
    {
      "x": -24,
      "y": -10,
      "z": 12,
      "name": "Empty"
    },
    {
      "x": -24,
      "y": -9,
      "z": 12,
      "name": "Empty"
    },
    {
      "x": -24,
      "y": -8,
      "z": 12,
      "name": "Empty"
    },
    {
      "x": -24,
      "y": -7,
      "z": 12,
      "name": "Empty"
    },
    {
      "x": -24,
      "y": -6,
      "z": 12,
      "name": "Rock_Ice"
    },
    {
      "x": -24,
      "y": -1,
      "z": 12,
      "name": "Rock_Ice",
      "rotation": 1
    },
    {
      "x": -24,
      "y": 0,
      "z": 12,
      "name": "Soil_Snow_Half"
    },
    {
      "x": -24,
      "y": -12,
      "z": 13,
      "name": "Rock_Shale_Cobble",
      "rotation": 1
    },
    {
      "x": -24,
      "y": -11,
      "z": 13,
      "name": "Empty"
    },
    {
      "x": -24,
      "y": -10,
      "z": 13,
      "name": "Empty"
    },
    {
      "x": -24,
      "y": -9,
      "z": 13,
      "name": "Empty"
    },
    {
      "x": -24,
      "y": -8,
      "z": 13,
      "name": "Empty"
    },
    {
      "x": -24,
      "y": -6,
      "z": 13,
      "name": "Rock_Ice_Permafrost"
    },
    {
      "x": -24,
      "y": -12,
      "z": 14,
      "name": "Rock_Ice",
      "rotation": 1
    },
    {
      "x": -24,
      "y": -11,
      "z": 14,
      "name": "Rock_Ice_Stalactite_Large"
    },
    {
      "x": -24,
      "y": -10,
      "z": 14,
      "name": "Rock_Ice_Stalactite_Large",
      "filler": 1024
    },
    {
      "x": -24,
      "y": -9,
      "z": 14,
      "name": "Empty"
    },
    {
      "x": -24,
      "y": -8,
      "z": 14,
      "name": "Empty"
    },
    {
      "x": -24,
      "y": -7,
      "z": 14,
      "name": "Rock_Shale_Brick_Pillar_Base",
      "rotation": 8
    },
    {
      "x": -24,
      "y": -12,
      "z": 15,
      "name": "Rock_Ice",
      "rotation": 1
    },
    {
      "x": -24,
      "y": -11,
      "z": 15,
      "name": "Rock_Shale_Brick_Pillar_Base"
    },
    {
      "x": -24,
      "y": -10,
      "z": 15,
      "name": "Rock_Shale_Brick_Pillar_Middle",
      "rotation": 2
    },
    {
      "x": -24,
      "y": -9,
      "z": 15,
      "name": "Rock_Shale_Brick_Pillar_Base",
      "rotation": 8
    },
    {
      "x": -24,
      "y": -8,
      "z": 15,
      "name": "Rock_Shale_Cobble",
      "rotation": 2
    },
    {
      "x": -24,
      "y": -7,
      "z": 15,
      "name": "Rock_Shale_Brick"
    },
    {
      "x": -24,
      "y": -11,
      "z": 16,
      "name": "Rock_Stone"
    },
    {
      "x": -24,
      "y": -10,
      "z": 16,
      "name": "Rock_Ice_Permafrost"
    },
    {
      "x": -24,
      "y": -9,
      "z": 16,
      "name": "Rock_Stone"
    },
    {
      "x": -23,
      "y": -1,
      "z": -10,
      "name": "Rock_Ice",
      "rotation": 1
    },
    {
      "x": -23,
      "y": 0,
      "z": -10,
      "name": "Soil_Snow_Half"
    },
    {
      "x": -23,
      "y": -1,
      "z": -9,
      "name": "Rock_Ice",
      "rotation": 1
    },
    {
      "x": -23,
      "y": 0,
      "z": -9,
      "name": "Soil_Snow_Half"
    },
    {
      "x": -23,
      "y": -1,
      "z": -8,
      "name": "Rock_Ice",
      "rotation": 1
    },
    {
      "x": -23,
      "y": 0,
      "z": -8,
      "name": "Soil_Snow_Half"
    },
    {
      "x": -23,
      "y": 0,
      "z": -7,
      "name": "Rock_Ice"
    },
    {
      "x": -23,
      "y": 1,
      "z": -7,
      "name": "Soil_Snow_Half"
    },
    {
      "x": -23,
      "y": 1,
      "z": -6,
      "name": "Rock_Ice",
      "rotation": 1
    },
    {
      "x": -23,
      "y": 6,
      "z": -6,
      "name": "Rock_Ice"
    },
    {
      "x": -23,
      "y": 7,
      "z": -6,
      "name": "Rock_Ice",
      "rotation": 1
    },
    {
      "x": -23,
      "y": 8,
      "z": -6,
      "name": "Soil_Snow_Half"
    },
    {
      "x": -23,
      "y": 0,
      "z": -5,
      "name": "Rock_Stone",
      "rotation": 1
    },
    {
      "x": -23,
      "y": 1,
      "z": -5,
      "name": "Rock_Ice",
      "rotation": 1
    },
    {
      "x": -23,
      "y": 2,
      "z": -5,
      "name": "Soil_Snow_Half"
    },
    {
      "x": -23,
      "y": 5,
      "z": -5,
      "name": "Rock_Ice"
    },
    {
      "x": -23,
      "y": 6,
      "z": -5,
      "name": "Rock_Ice"
    },
    {
      "x": -23,
      "y": 7,
      "z": -5,
      "name": "Rock_Ice",
      "rotation": 1
    },
    {
      "x": -23,
      "y": 8,
      "z": -5,
      "name": "Soil_Snow_Half"
    },
    {
      "x": -23,
      "y": 0,
      "z": -4,
      "name": "Rock_Stone",
      "rotation": 1
    },
    {
      "x": -23,
      "y": 1,
      "z": -4,
      "name": "Rock_Stone",
      "rotation": 1
    },
    {
      "x": -23,
      "y": 2,
      "z": -4,
      "name": "Rock_Runic_Brick",
      "rotation": 1
    },
    {
      "x": -23,
      "y": 3,
      "z": -4,
      "name": "Rock_Runic_Brick",
      "rotation": 1
    },
    {
      "x": -23,
      "y": 4,
      "z": -4,
      "name": "Rock_Calcite_Brick",
      "rotation": 1
    },
    {
      "x": -23,
      "y": 5,
      "z": -4,
      "name": "Rock_Runic_Brick",
      "rotation": 1
    },
    {
      "x": -23,
      "y": 6,
      "z": -4,
      "name": "Rock_Runic_Brick",
      "rotation": 1
    },
    {
      "x": -23,
      "y": 7,
      "z": -4,
      "name": "Rock_Runic_Brick",
      "rotation": 1
    },
    {
      "x": -23,
      "y": 8,
      "z": -4,
      "name": "Rock_Shale_Brick_Pillar_Base"
    },
    {
      "x": -23,
      "y": 9,
      "z": -4,
      "name": "Rock_Shale_Cobble_Half"
    },
    {
      "x": -23,
      "y": 0,
      "z": -3,
      "name": "Rock_Stone",
      "rotation": 1
    },
    {
      "x": -23,
      "y": 1,
      "z": -3,
      "name": "Rock_Stone",
      "rotation": 1
    },
    {
      "x": -23,
      "y": 2,
      "z": -3,
      "name": "Rock_Marble",
      "rotation": 1
    },
    {
      "x": -23,
      "y": 3,
      "z": -3,
      "name": "Rock_Marble",
      "rotation": 1
    },
    {
      "x": -23,
      "y": 4,
      "z": -3,
      "name": "Rock_Marble",
      "rotation": 1
    },
    {
      "x": -23,
      "y": 5,
      "z": -3,
      "name": "Rock_Marble",
      "rotation": 1
    },
    {
      "x": -23,
      "y": 6,
      "z": -3,
      "name": "Rock_Marble",
      "rotation": 1
    },
    {
      "x": -23,
      "y": 7,
      "z": -3,
      "name": "Rock_Runic_Brick",
      "rotation": 1
    },
    {
      "x": -23,
      "y": 9,
      "z": -3,
      "name": "Rock_Shale_Cobble_Half"
    },
    {
      "x": -23,
      "y": 0,
      "z": -2,
      "name": "Rock_Stone",
      "rotation": 1
    },
    {
      "x": -23,
      "y": 1,
      "z": -2,
      "name": "Rock_Stone",
      "rotation": 1
    },
    {
      "x": -23,
      "y": 2,
      "z": -2,
      "name": "Rock_Marble",
      "rotation": 1
    },
    {
      "x": -23,
      "y": 3,
      "z": -2,
      "name": "Rock_Runic_Brick",
      "rotation": 1
    },
    {
      "x": -23,
      "y": 4,
      "z": -2,
      "name": "Rock_Runic_Brick",
      "rotation": 1
    },
    {
      "x": -23,
      "y": 5,
      "z": -2,
      "name": "Rock_Runic_Brick",
      "rotation": 1
    },
    {
      "x": -23,
      "y": 6,
      "z": -2,
      "name": "Rock_Runic_Brick",
      "rotation": 1
    },
    {
      "x": -23,
      "y": 7,
      "z": -2,
      "name": "Rock_Runic_Brick",
      "rotation": 1
    },
    {
      "x": -23,
      "y": 8,
      "z": -2,
      "name": "Rock_Runic_Brick"
    },
    {
      "x": -23,
      "y": 9,
      "z": -2,
      "name": "Rock_Shale_Brick_Smooth",
      "rotation": 1
    },
    {
      "x": -23,
      "y": -11,
      "z": -1,
      "name": "Rock_Shale_Cobble",
      "rotation": 1
    },
    {
      "x": -23,
      "y": -10,
      "z": -1,
      "name": "Rock_Shale_Cobble",
      "rotation": 1
    },
    {
      "x": -23,
      "y": -9,
      "z": -1,
      "name": "Rock_Shale_Cobble",
      "rotation": 1
    },
    {
      "x": -23,
      "y": -8,
      "z": -1,
      "name": "Rock_Shale_Cobble",
      "rotation": 1
    },
    {
      "x": -23,
      "y": -7,
      "z": -1,
      "name": "Rock_Shale_Cobble",
      "rotation": 1
    },
    {
      "x": -23,
      "y": 0,
      "z": -1,
      "name": "Rock_Stone",
      "rotation": 1
    },
    {
      "x": -23,
      "y": 1,
      "z": -1,
      "name": "Rock_Stone",
      "rotation": 1
    },
    {
      "x": -23,
      "y": 2,
      "z": -1,
      "name": "Rock_Marble",
      "rotation": 1
    },
    {
      "x": -23,
      "y": 3,
      "z": -1,
      "name": "Rock_Runic_Brick",
      "rotation": 1
    },
    {
      "x": -23,
      "y": 4,
      "z": -1,
      "name": "Rock_Runic_Brick",
      "rotation": 1
    },
    {
      "x": -23,
      "y": 5,
      "z": -1,
      "name": "Rock_Runic_Brick",
      "rotation": 1
    },
    {
      "x": -23,
      "y": 6,
      "z": -1,
      "name": "Rock_Runic_Brick",
      "rotation": 1
    },
    {
      "x": -23,
      "y": 7,
      "z": -1,
      "name": "Rock_Runic_Brick",
      "rotation": 1
    },
    {
      "x": -23,
      "y": 8,
      "z": -1,
      "name": "Rock_Runic_Brick"
    },
    {
      "x": -23,
      "y": 9,
      "z": -1,
      "name": "Rock_Shale_Brick_Smooth",
      "rotation": 1
    },
    {
      "x": -23,
      "y": 10,
      "z": -1,
      "name": "Rock_Ice",
      "rotation": 1
    },
    {
      "x": -23,
      "y": -12,
      "z": 0,
      "name": "Rock_Shale_Cobble",
      "rotation": 1
    },
    {
      "x": -23,
      "y": -11,
      "z": 0,
      "name": "Rock_Shale_Cobble",
      "rotation": 1
    },
    {
      "x": -23,
      "y": -10,
      "z": 0,
      "name": "Rock_Shale_Cobble",
      "rotation": 1
    },
    {
      "x": -23,
      "y": -9,
      "z": 0,
      "name": "Rock_Shale_Brick_Smooth"
    },
    {
      "x": -23,
      "y": -8,
      "z": 0,
      "name": "Rock_Shale_Cobble",
      "rotation": 1
    },
    {
      "x": -23,
      "y": -7,
      "z": 0,
      "name": "Rock_Shale_Cobble",
      "rotation": 1
    },
    {
      "x": -23,
      "y": 0,
      "z": 0,
      "name": "Rock_Stone",
      "rotation": 1
    },
    {
      "x": -23,
      "y": 1,
      "z": 0,
      "name": "Rock_Stone",
      "rotation": 1
    },
    {
      "x": -23,
      "y": 2,
      "z": 0,
      "name": "Rock_Marble",
      "rotation": 1
    },
    {
      "x": -23,
      "y": 3,
      "z": 0,
      "name": "Rock_Runic_Brick",
      "rotation": 1
    },
    {
      "x": -23,
      "y": 4,
      "z": 0,
      "name": "Rock_Runic_Brick",
      "rotation": 1
    },
    {
      "x": -23,
      "y": 5,
      "z": 0,
      "name": "Rock_Runic_Brick",
      "rotation": 1
    },
    {
      "x": -23,
      "y": 6,
      "z": 0,
      "name": "Rock_Runic_Brick",
      "rotation": 1
    },
    {
      "x": -23,
      "y": 7,
      "z": 0,
      "name": "Rock_Runic_Brick",
      "rotation": 1
    },
    {
      "x": -23,
      "y": 8,
      "z": 0,
      "name": "Rock_Runic_Brick"
    },
    {
      "x": -23,
      "y": 9,
      "z": 0,
      "name": "Rock_Shale_Brick_Smooth",
      "rotation": 1
    },
    {
      "x": -23,
      "y": 10,
      "z": 0,
      "name": "Rock_Ice",
      "rotation": 1
    },
    {
      "x": -23,
      "y": -12,
      "z": 1,
      "name": "Rock_Ice_Permafrost",
      "rotation": 1
    },
    {
      "x": -23,
      "y": -11,
      "z": 1,
      "name": "Rock_Ice_Icicles"
    },
    {
      "x": -23,
      "y": -10,
      "z": 1,
      "name": "Empty"
    },
    {
      "x": -23,
      "y": -9,
      "z": 1,
      "name": "Empty"
    },
    {
      "x": -23,
      "y": -8,
      "z": 1,
      "name": "Empty"
    },
    {
      "x": -23,
      "y": -7,
      "z": 1,
      "name": "Rock_Shale_Brick"
    },
    {
      "x": -23,
      "y": 0,
      "z": 1,
      "name": "Rock_Stone",
      "rotation": 1
    },
    {
      "x": -23,
      "y": 1,
      "z": 1,
      "name": "Rock_Stone",
      "rotation": 1
    },
    {
      "x": -23,
      "y": 2,
      "z": 1,
      "name": "Rock_Marble",
      "rotation": 1
    },
    {
      "x": -23,
      "y": 3,
      "z": 1,
      "name": "Rock_Runic_Brick",
      "rotation": 1
    },
    {
      "x": -23,
      "y": 4,
      "z": 1,
      "name": "Rock_Runic_Brick",
      "rotation": 1
    },
    {
      "x": -23,
      "y": 5,
      "z": 1,
      "name": "Rock_Runic_Brick",
      "rotation": 1
    },
    {
      "x": -23,
      "y": 6,
      "z": 1,
      "name": "Rock_Runic_Brick",
      "rotation": 1
    },
    {
      "x": -23,
      "y": 7,
      "z": 1,
      "name": "Rock_Runic_Brick",
      "rotation": 1
    },
    {
      "x": -23,
      "y": 8,
      "z": 1,
      "name": "Rock_Runic_Brick"
    },
    {
      "x": -23,
      "y": 9,
      "z": 1,
      "name": "Rock_Shale_Brick_Smooth",
      "rotation": 1
    },
    {
      "x": -23,
      "y": 10,
      "z": 1,
      "name": "Rock_Ice",
      "rotation": 1
    },
    {
      "x": -23,
      "y": -12,
      "z": 2,
      "name": "Rock_Ice"
    },
    {
      "x": -23,
      "y": -11,
      "z": 2,
      "name": "Rock_Ice_Icicles"
    },
    {
      "x": -23,
      "y": -10,
      "z": 2,
      "name": "Empty"
    },
    {
      "x": -23,
      "y": -9,
      "z": 2,
      "name": "Empty"
    },
    {
      "x": -23,
      "y": -8,
      "z": 2,
      "name": "Empty"
    },
    {
      "x": -23,
      "y": -7,
      "z": 2,
      "name": "Empty"
    },
    {
      "x": -23,
      "y": -6,
      "z": 2,
      "name": "Rock_Shale_Brick_Smooth"
    },
    {
      "x": -23,
      "y": 0,
      "z": 2,
      "name": "Rock_Stone",
      "rotation": 1
    },
    {
      "x": -23,
      "y": 1,
      "z": 2,
      "name": "Rock_Stone",
      "rotation": 1
    },
    {
      "x": -23,
      "y": 2,
      "z": 2,
      "name": "Rock_Marble",
      "rotation": 1
    },
    {
      "x": -23,
      "y": 3,
      "z": 2,
      "name": "Rock_Runic_Brick",
      "rotation": 1
    },
    {
      "x": -23,
      "y": 4,
      "z": 2,
      "name": "Rock_Runic_Brick",
      "rotation": 1
    },
    {
      "x": -23,
      "y": 5,
      "z": 2,
      "name": "Rock_Runic_Brick",
      "rotation": 1
    },
    {
      "x": -23,
      "y": 6,
      "z": 2,
      "name": "Rock_Runic_Brick",
      "rotation": 1
    },
    {
      "x": -23,
      "y": 7,
      "z": 2,
      "name": "Rock_Runic_Brick",
      "rotation": 1
    },
    {
      "x": -23,
      "y": 8,
      "z": 2,
      "name": "Rock_Runic_Brick"
    },
    {
      "x": -23,
      "y": 9,
      "z": 2,
      "name": "Rock_Shale_Brick_Smooth",
      "rotation": 1
    },
    {
      "x": -23,
      "y": -12,
      "z": 3,
      "name": "Rock_Ice"
    },
    {
      "x": -23,
      "y": -11,
      "z": 3,
      "name": "Empty"
    },
    {
      "x": -23,
      "y": -10,
      "z": 3,
      "name": "Empty"
    },
    {
      "x": -23,
      "y": -9,
      "z": 3,
      "name": "Empty"
    },
    {
      "x": -23,
      "y": -8,
      "z": 3,
      "name": "Empty"
    },
    {
      "x": -23,
      "y": -7,
      "z": 3,
      "name": "Empty"
    },
    {
      "x": -23,
      "y": -6,
      "z": 3,
      "name": "Rock_Stone"
    },
    {
      "x": -23,
      "y": 0,
      "z": 3,
      "name": "Rock_Stone",
      "rotation": 1
    },
    {
      "x": -23,
      "y": 1,
      "z": 3,
      "name": "Rock_Stone",
      "rotation": 1
    },
    {
      "x": -23,
      "y": 2,
      "z": 3,
      "name": "Rock_Marble",
      "rotation": 1
    },
    {
      "x": -23,
      "y": 3,
      "z": 3,
      "name": "Rock_Marble",
      "rotation": 1
    },
    {
      "x": -23,
      "y": 4,
      "z": 3,
      "name": "Rock_Marble",
      "rotation": 1
    },
    {
      "x": -23,
      "y": 5,
      "z": 3,
      "name": "Rock_Marble",
      "rotation": 1
    },
    {
      "x": -23,
      "y": 6,
      "z": 3,
      "name": "Rock_Marble",
      "rotation": 1
    },
    {
      "x": -23,
      "y": 7,
      "z": 3,
      "name": "Rock_Runic_Brick",
      "rotation": 1
    },
    {
      "x": -23,
      "y": 9,
      "z": 3,
      "name": "Rock_Shale_Cobble_Half"
    },
    {
      "x": -23,
      "y": -12,
      "z": 4,
      "name": "Rock_Shale_Cobble",
      "rotation": 1
    },
    {
      "x": -23,
      "y": -11,
      "z": 4,
      "name": "Empty"
    },
    {
      "x": -23,
      "y": -10,
      "z": 4,
      "name": "Empty"
    },
    {
      "x": -23,
      "y": -9,
      "z": 4,
      "name": "Empty"
    },
    {
      "x": -23,
      "y": -8,
      "z": 4,
      "name": "Empty"
    },
    {
      "x": -23,
      "y": -7,
      "z": 4,
      "name": "Empty"
    },
    {
      "x": -23,
      "y": -6,
      "z": 4,
      "name": "Rock_Stone"
    },
    {
      "x": -23,
      "y": 0,
      "z": 4,
      "name": "Rock_Stone",
      "rotation": 1
    },
    {
      "x": -23,
      "y": 1,
      "z": 4,
      "name": "Rock_Stone",
      "rotation": 1
    },
    {
      "x": -23,
      "y": 2,
      "z": 4,
      "name": "Rock_Runic_Brick",
      "rotation": 1
    },
    {
      "x": -23,
      "y": 3,
      "z": 4,
      "name": "Rock_Runic_Brick",
      "rotation": 1
    },
    {
      "x": -23,
      "y": 4,
      "z": 4,
      "name": "Rock_Calcite_Brick",
      "rotation": 1
    },
    {
      "x": -23,
      "y": 5,
      "z": 4,
      "name": "Rock_Runic_Brick",
      "rotation": 1
    },
    {
      "x": -23,
      "y": 6,
      "z": 4,
      "name": "Rock_Runic_Brick",
      "rotation": 1
    },
    {
      "x": -23,
      "y": 7,
      "z": 4,
      "name": "Rock_Runic_Brick",
      "rotation": 1
    },
    {
      "x": -23,
      "y": 8,
      "z": 4,
      "name": "Rock_Shale_Brick_Pillar_Base"
    },
    {
      "x": -23,
      "y": 9,
      "z": 4,
      "name": "Rock_Shale_Cobble_Half"
    },
    {
      "x": -23,
      "y": -12,
      "z": 5,
      "name": "Rock_Stone",
      "rotation": 1
    },
    {
      "x": -23,
      "y": -11,
      "z": 5,
      "name": "Rock_Shale_Brick_Smooth"
    },
    {
      "x": -23,
      "y": -10,
      "z": 5,
      "name": "Rock_Shale_Brick_Pillar_Base"
    },
    {
      "x": -23,
      "y": -9,
      "z": 5,
      "name": "Rock_Shale_Brick_Pillar_Middle"
    },
    {
      "x": -23,
      "y": -8,
      "z": 5,
      "name": "Rock_Stone",
      "rotation": 1
    },
    {
      "x": -23,
      "y": -7,
      "z": 5,
      "name": "Rock_Stone",
      "rotation": 1
    },
    {
      "x": -23,
      "y": -6,
      "z": 5,
      "name": "Rock_Ice_Permafrost"
    },
    {
      "x": -23,
      "y": 0,
      "z": 5,
      "name": "Rock_Stone",
      "rotation": 1
    },
    {
      "x": -23,
      "y": 1,
      "z": 5,
      "name": "Rock_Ice",
      "rotation": 1
    },
    {
      "x": -23,
      "y": 5,
      "z": 5,
      "name": "Rock_Ice"
    },
    {
      "x": -23,
      "y": 6,
      "z": 5,
      "name": "Rock_Ice"
    },
    {
      "x": -23,
      "y": 7,
      "z": 5,
      "name": "Rock_Ice",
      "rotation": 1
    },
    {
      "x": -23,
      "y": 8,
      "z": 5,
      "name": "Soil_Snow_Half"
    },
    {
      "x": -23,
      "y": -12,
      "z": 6,
      "name": "Rock_Shale_Cobble",
      "rotation": 1
    },
    {
      "x": -23,
      "y": -11,
      "z": 6,
      "name": "Rock_Shale_Brick_Smooth"
    },
    {
      "x": -23,
      "y": -10,
      "z": 6,
      "name": "Rock_Shale_Brick_Pillar_Base"
    },
    {
      "x": -23,
      "y": -9,
      "z": 6,
      "name": "Rock_Shale_Brick_Pillar_Middle"
    },
    {
      "x": -23,
      "y": -8,
      "z": 6,
      "name": "Rock_Shale_Brick_Pillar_Middle",
      "rotation": 8
    },
    {
      "x": -23,
      "y": -7,
      "z": 6,
      "name": "Rock_Ice",
      "rotation": 1
    },
    {
      "x": -23,
      "y": -6,
      "z": 6,
      "name": "Rock_Ice_Permafrost"
    },
    {
      "x": -23,
      "y": 0,
      "z": 6,
      "name": "Rock_Stone",
      "rotation": 1
    },
    {
      "x": -23,
      "y": 1,
      "z": 6,
      "name": "Rock_Ice_Permafrost"
    },
    {
      "x": -23,
      "y": 7,
      "z": 6,
      "name": "Rock_Ice",
      "rotation": 1
    },
    {
      "x": -23,
      "y": -12,
      "z": 7,
      "name": "Rock_Shale_Cobble",
      "rotation": 1
    },
    {
      "x": -23,
      "y": -11,
      "z": 7,
      "name": "Rock_Ice_Icicles"
    },
    {
      "x": -23,
      "y": -10,
      "z": 7,
      "name": "Empty"
    },
    {
      "x": -23,
      "y": -9,
      "z": 7,
      "name": "Empty"
    },
    {
      "x": -23,
      "y": -8,
      "z": 7,
      "name": "Empty"
    },
    {
      "x": -23,
      "y": -7,
      "z": 7,
      "name": "Empty"
    },
    {
      "x": -23,
      "y": -6,
      "z": 7,
      "name": "Rock_Stone"
    },
    {
      "x": -23,
      "y": 0,
      "z": 7,
      "name": "Rock_Ice_Permafrost"
    },
    {
      "x": -23,
      "y": -12,
      "z": 8,
      "name": "Rock_Shale_Cobble",
      "rotation": 1
    },
    {
      "x": -23,
      "y": -11,
      "z": 8,
      "name": "Empty"
    },
    {
      "x": -23,
      "y": -10,
      "z": 8,
      "name": "Empty"
    },
    {
      "x": -23,
      "y": -9,
      "z": 8,
      "name": "Empty"
    },
    {
      "x": -23,
      "y": -8,
      "z": 8,
      "name": "Empty"
    },
    {
      "x": -23,
      "y": -7,
      "z": 8,
      "name": "Empty"
    },
    {
      "x": -23,
      "y": -6,
      "z": 8,
      "name": "Rock_Stone"
    },
    {
      "x": -23,
      "y": -1,
      "z": 8,
      "name": "Rock_Ice",
      "rotation": 1
    },
    {
      "x": -23,
      "y": 0,
      "z": 8,
      "name": "Soil_Snow_Half"
    },
    {
      "x": -23,
      "y": -12,
      "z": 9,
      "name": "Rock_Shale_Cobble",
      "rotation": 1
    },
    {
      "x": -23,
      "y": -11,
      "z": 9,
      "name": "Empty"
    },
    {
      "x": -23,
      "y": -10,
      "z": 9,
      "name": "Empty"
    },
    {
      "x": -23,
      "y": -9,
      "z": 9,
      "name": "Empty"
    },
    {
      "x": -23,
      "y": -8,
      "z": 9,
      "name": "Empty"
    },
    {
      "x": -23,
      "y": -7,
      "z": 9,
      "name": "Empty"
    },
    {
      "x": -23,
      "y": -6,
      "z": 9,
      "name": "Rock_Stone"
    },
    {
      "x": -23,
      "y": -1,
      "z": 9,
      "name": "Rock_Ice",
      "rotation": 1
    },
    {
      "x": -23,
      "y": 0,
      "z": 9,
      "name": "Soil_Snow_Half"
    },
    {
      "x": -23,
      "y": -12,
      "z": 10,
      "name": "Rock_Shale_Cobble",
      "rotation": 1
    },
    {
      "x": -23,
      "y": -11,
      "z": 10,
      "name": "Empty"
    },
    {
      "x": -23,
      "y": -10,
      "z": 10,
      "name": "Empty"
    },
    {
      "x": -23,
      "y": -9,
      "z": 10,
      "name": "Empty"
    },
    {
      "x": -23,
      "y": -8,
      "z": 10,
      "name": "Empty"
    },
    {
      "x": -23,
      "y": -7,
      "z": 10,
      "name": "Empty"
    },
    {
      "x": -23,
      "y": -6,
      "z": 10,
      "name": "Rock_Ice"
    },
    {
      "x": -23,
      "y": -1,
      "z": 10,
      "name": "Rock_Ice",
      "rotation": 1
    },
    {
      "x": -23,
      "y": 0,
      "z": 10,
      "name": "Soil_Snow_Half"
    },
    {
      "x": -23,
      "y": -12,
      "z": 11,
      "name": "Rock_Shale_Cobble",
      "rotation": 1
    },
    {
      "x": -23,
      "y": -11,
      "z": 11,
      "name": "Empty"
    },
    {
      "x": -23,
      "y": -10,
      "z": 11,
      "name": "Empty"
    },
    {
      "x": -23,
      "y": -9,
      "z": 11,
      "name": "Empty"
    },
    {
      "x": -23,
      "y": -8,
      "z": 11,
      "name": "Empty"
    },
    {
      "x": -23,
      "y": -7,
      "z": 11,
      "name": "Empty"
    },
    {
      "x": -23,
      "y": -6,
      "z": 11,
      "name": "Rock_Ice_Permafrost"
    },
    {
      "x": -23,
      "y": -1,
      "z": 11,
      "name": "Rock_Ice",
      "rotation": 1
    },
    {
      "x": -23,
      "y": 0,
      "z": 11,
      "name": "Soil_Snow_Half"
    },
    {
      "x": -23,
      "y": -12,
      "z": 12,
      "name": "Rock_Shale_Cobble",
      "rotation": 1
    },
    {
      "x": -23,
      "y": -11,
      "z": 12,
      "name": "Empty"
    },
    {
      "x": -23,
      "y": -10,
      "z": 12,
      "name": "Empty"
    },
    {
      "x": -23,
      "y": -9,
      "z": 12,
      "name": "Empty"
    },
    {
      "x": -23,
      "y": -8,
      "z": 12,
      "name": "Empty"
    },
    {
      "x": -23,
      "y": -7,
      "z": 12,
      "name": "Empty"
    },
    {
      "x": -23,
      "y": -6,
      "z": 12,
      "name": "Rock_Ice"
    },
    {
      "x": -23,
      "y": -1,
      "z": 12,
      "name": "Rock_Ice",
      "rotation": 1
    },
    {
      "x": -23,
      "y": 0,
      "z": 12,
      "name": "Soil_Snow_Half"
    },
    {
      "x": -23,
      "y": -12,
      "z": 13,
      "name": "Rock_Shale_Cobble",
      "rotation": 1
    },
    {
      "x": -23,
      "y": -11,
      "z": 13,
      "name": "Empty"
    },
    {
      "x": -23,
      "y": -10,
      "z": 13,
      "name": "Empty"
    },
    {
      "x": -23,
      "y": -9,
      "z": 13,
      "name": "Empty"
    },
    {
      "x": -23,
      "y": -8,
      "z": 13,
      "name": "Empty"
    },
    {
      "x": -23,
      "y": -7,
      "z": 13,
      "name": "Rock_Ice_Icicles",
      "rotation": 8
    },
    {
      "x": -23,
      "y": -6,
      "z": 13,
      "name": "Rock_Ice"
    },
    {
      "x": -23,
      "y": -1,
      "z": 13,
      "name": "Rock_Ice",
      "rotation": 1
    },
    {
      "x": -23,
      "y": 0,
      "z": 13,
      "name": "Soil_Snow_Half"
    },
    {
      "x": -23,
      "y": -12,
      "z": 14,
      "name": "Rock_Ice",
      "rotation": 1
    },
    {
      "x": -23,
      "y": -11,
      "z": 14,
      "name": "Empty"
    },
    {
      "x": -23,
      "y": -10,
      "z": 14,
      "name": "Empty"
    },
    {
      "x": -23,
      "y": -9,
      "z": 14,
      "name": "Empty"
    },
    {
      "x": -23,
      "y": -8,
      "z": 14,
      "name": "Empty"
    },
    {
      "x": -23,
      "y": -6,
      "z": 14,
      "name": "Rock_Stone"
    },
    {
      "x": -23,
      "y": -12,
      "z": 15,
      "name": "Rock_Stone",
      "rotation": 1
    },
    {
      "x": -23,
      "y": -11,
      "z": 15,
      "name": "Empty"
    },
    {
      "x": -23,
      "y": -10,
      "z": 15,
      "name": "Empty"
    },
    {
      "x": -23,
      "y": -9,
      "z": 15,
      "name": "Empty"
    },
    {
      "x": -23,
      "y": -8,
      "z": 15,
      "name": "Rock_Shale_Brick_Stairs",
      "rotation": 11
    },
    {
      "x": -23,
      "y": -7,
      "z": 15,
      "name": "Rock_Shale_Brick"
    },
    {
      "x": -23,
      "y": -12,
      "z": 16,
      "name": "Rock_Ice_Permafrost"
    },
    {
      "x": -23,
      "y": -11,
      "z": 16,
      "name": "Empty"
    },
    {
      "x": -23,
      "y": -10,
      "z": 16,
      "name": "Empty"
    },
    {
      "x": -23,
      "y": -9,
      "z": 16,
      "name": "Empty"
    },
    {
      "x": -23,
      "y": -8,
      "z": 16,
      "name": "Rock_Ice"
    },
    {
      "x": -23,
      "y": -11,
      "z": 17,
      "name": "Rock_Stone"
    },
    {
      "x": -23,
      "y": -10,
      "z": 17,
      "name": "Rock_Stone"
    },
    {
      "x": -23,
      "y": -9,
      "z": 17,
      "name": "Rock_Ice_Permafrost"
    },
    {
      "x": -22,
      "y": -1,
      "z": -11,
      "name": "Rock_Ice",
      "rotation": 1
    },
    {
      "x": -22,
      "y": 0,
      "z": -11,
      "name": "Soil_Snow_Half"
    },
    {
      "x": -22,
      "y": -1,
      "z": -10,
      "name": "Rock_Ice",
      "rotation": 1
    },
    {
      "x": -22,
      "y": 0,
      "z": -10,
      "name": "Soil_Snow_Half"
    },
    {
      "x": -22,
      "y": -1,
      "z": -9,
      "name": "Rock_Ice",
      "rotation": 1
    },
    {
      "x": -22,
      "y": 0,
      "z": -9,
      "name": "Soil_Snow_Half"
    },
    {
      "x": -22,
      "y": 0,
      "z": -8,
      "name": "Rock_Ice",
      "rotation": 1
    },
    {
      "x": -22,
      "y": 0,
      "z": -7,
      "name": "Rock_Stone",
      "rotation": 1
    },
    {
      "x": -22,
      "y": 1,
      "z": -7,
      "name": "Rock_Ice"
    },
    {
      "x": -22,
      "y": 5,
      "z": -7,
      "name": "Rock_Ice"
    },
    {
      "x": -22,
      "y": 6,
      "z": -7,
      "name": "Rock_Ice"
    },
    {
      "x": -22,
      "y": 7,
      "z": -7,
      "name": "Rock_Ice",
      "rotation": 1
    },
    {
      "x": -22,
      "y": 0,
      "z": -6,
      "name": "Rock_Stone",
      "rotation": 1
    },
    {
      "x": -22,
      "y": 1,
      "z": -6,
      "name": "Rock_Stone",
      "rotation": 1
    },
    {
      "x": -22,
      "y": 2,
      "z": -6,
      "name": "Rock_Calcite_Brick",
      "rotation": 1
    },
    {
      "x": -22,
      "y": 3,
      "z": -6,
      "name": "Rock_Calcite_Brick",
      "rotation": 1
    },
    {
      "x": -22,
      "y": 4,
      "z": -6,
      "name": "Rock_Calcite_Brick",
      "rotation": 1
    },
    {
      "x": -22,
      "y": 5,
      "z": -6,
      "name": "Rock_Runic_Brick",
      "rotation": 1
    },
    {
      "x": -22,
      "y": 6,
      "z": -6,
      "name": "Rock_Runic_Brick",
      "rotation": 1
    },
    {
      "x": -22,
      "y": 7,
      "z": -6,
      "name": "Rock_Runic_Brick",
      "rotation": 1
    },
    {
      "x": -22,
      "y": 0,
      "z": -5,
      "name": "Rock_Stone",
      "rotation": 1
    },
    {
      "x": -22,
      "y": 1,
      "z": -5,
      "name": "Rock_Stone",
      "rotation": 1
    },
    {
      "x": -22,
      "y": 2,
      "z": -5,
      "name": "Rock_Runic_Brick",
      "rotation": 1
    },
    {
      "x": -22,
      "y": 3,
      "z": -5,
      "name": "Rock_Runic_Brick",
      "rotation": 1
    },
    {
      "x": -22,
      "y": 4,
      "z": -5,
      "name": "Rock_Calcite_Brick",
      "rotation": 1
    },
    {
      "x": -22,
      "y": 5,
      "z": -5,
      "name": "Rock_Calcite_Brick"
    },
    {
      "x": -22,
      "y": 6,
      "z": -5,
      "name": "Rock_Runic_Brick",
      "rotation": 1
    },
    {
      "x": -22,
      "y": 7,
      "z": -5,
      "name": "Rock_Runic_Brick",
      "rotation": 1
    },
    {
      "x": -22,
      "y": 9,
      "z": -5,
      "name": "Rock_Shale_Cobble_Half"
    },
    {
      "x": -22,
      "y": -1,
      "z": -4,
      "name": "Rock_Stone",
      "rotation": 1
    },
    {
      "x": -22,
      "y": 0,
      "z": -4,
      "name": "Rock_Stone",
      "rotation": 1
    },
    {
      "x": -22,
      "y": 1,
      "z": -4,
      "name": "Rock_Stone",
      "rotation": 1
    },
    {
      "x": -22,
      "y": 2,
      "z": -4,
      "name": "Rock_Runic_Brick",
      "rotation": 1
    },
    {
      "x": -22,
      "y": 3,
      "z": -4,
      "name": "Rock_Runic_Brick",
      "rotation": 1
    },
    {
      "x": -22,
      "y": 4,
      "z": -4,
      "name": "Rock_Runic_Brick",
      "rotation": 1
    },
    {
      "x": -22,
      "y": 5,
      "z": -4,
      "name": "Rock_Runic_Brick",
      "rotation": 1
    },
    {
      "x": -22,
      "y": 6,
      "z": -4,
      "name": "Rock_Runic_Brick",
      "rotation": 1
    },
    {
      "x": -22,
      "y": 7,
      "z": -4,
      "name": "Rock_Runic_Brick",
      "rotation": 1
    },
    {
      "x": -22,
      "y": 8,
      "z": -4,
      "name": "Rock_Runic_Brick"
    },
    {
      "x": -22,
      "y": 9,
      "z": -4,
      "name": "Rock_Shale_Brick_Smooth",
      "rotation": 1
    },
    {
      "x": -22,
      "y": -11,
      "z": -3,
      "name": "Rock_Shale_Cobble",
      "rotation": 1
    },
    {
      "x": -22,
      "y": -10,
      "z": -3,
      "name": "Rock_Shale_Cobble",
      "rotation": 1
    },
    {
      "x": -22,
      "y": -9,
      "z": -3,
      "name": "Rock_Shale_Cobble",
      "rotation": 1
    },
    {
      "x": -22,
      "y": -8,
      "z": -3,
      "name": "Rock_Shale_Cobble",
      "rotation": 1
    },
    {
      "x": -22,
      "y": -7,
      "z": -3,
      "name": "Rock_Shale_Cobble",
      "rotation": 1
    },
    {
      "x": -22,
      "y": -3,
      "z": -3,
      "name": "Rock_Stone"
    },
    {
      "x": -22,
      "y": -2,
      "z": -3,
      "name": "Rock_Stone",
      "rotation": 1
    },
    {
      "x": -22,
      "y": -1,
      "z": -3,
      "name": "Rock_Stone",
      "rotation": 1
    },
    {
      "x": -22,
      "y": 0,
      "z": -3,
      "name": "Rock_Stone",
      "rotation": 1
    },
    {
      "x": -22,
      "y": 1,
      "z": -3,
      "name": "Rock_Stone",
      "rotation": 1
    },
    {
      "x": -22,
      "y": 2,
      "z": -3,
      "name": "Rock_Marble",
      "rotation": 1
    },
    {
      "x": -22,
      "y": 3,
      "z": -3,
      "name": "Rock_Runic_Brick",
      "rotation": 1
    },
    {
      "x": -22,
      "y": 4,
      "z": -3,
      "name": "Rock_Runic_Brick",
      "rotation": 1
    },
    {
      "x": -22,
      "y": 5,
      "z": -3,
      "name": "Rock_Runic_Brick",
      "rotation": 1
    },
    {
      "x": -22,
      "y": 6,
      "z": -3,
      "name": "Rock_Runic_Brick",
      "rotation": 1
    },
    {
      "x": -22,
      "y": 7,
      "z": -3,
      "name": "Rock_Shale_Brick_Smooth"
    },
    {
      "x": -22,
      "y": 8,
      "z": -3,
      "name": "Rock_Runic_Brick"
    },
    {
      "x": -22,
      "y": 9,
      "z": -3,
      "name": "Rock_Shale_Brick_Smooth",
      "rotation": 1
    },
    {
      "x": -22,
      "y": 10,
      "z": -3,
      "name": "Rock_Ice",
      "rotation": 1
    },
    {
      "x": -22,
      "y": -12,
      "z": -2,
      "name": "Rock_Shale_Cobble",
      "rotation": 1
    },
    {
      "x": -22,
      "y": -11,
      "z": -2,
      "name": "Rock_Shale_Cobble",
      "rotation": 1
    },
    {
      "x": -22,
      "y": -10,
      "z": -2,
      "name": "Rock_Shale_Cobble",
      "rotation": 1
    },
    {
      "x": -22,
      "y": -9,
      "z": -2,
      "name": "Rock_Shale_Brick_Smooth"
    },
    {
      "x": -22,
      "y": -8,
      "z": -2,
      "name": "Rock_Shale_Cobble",
      "rotation": 1
    },
    {
      "x": -22,
      "y": -7,
      "z": -2,
      "name": "Rock_Shale_Cobble",
      "rotation": 1
    },
    {
      "x": -22,
      "y": -3,
      "z": -2,
      "name": "Rock_Stone"
    },
    {
      "x": -22,
      "y": -2,
      "z": -2,
      "name": "Rock_Stone",
      "rotation": 1
    },
    {
      "x": -22,
      "y": -1,
      "z": -2,
      "name": "Rock_Stone",
      "rotation": 1
    },
    {
      "x": -22,
      "y": 0,
      "z": -2,
      "name": "Rock_Stone",
      "rotation": 1
    },
    {
      "x": -22,
      "y": 1,
      "z": -2,
      "name": "Rock_Stone",
      "rotation": 1
    },
    {
      "x": -22,
      "y": 2,
      "z": -2,
      "name": "Rock_Runic_Brick",
      "rotation": 1
    },
    {
      "x": -22,
      "y": 3,
      "z": -2,
      "name": "Rock_Runic_Brick",
      "rotation": 1
    },
    {
      "x": -22,
      "y": 7,
      "z": -2,
      "name": "Rock_Shale_Brick_Smooth"
    },
    {
      "x": -22,
      "y": 8,
      "z": -2,
      "name": "Rock_Runic_Brick"
    },
    {
      "x": -22,
      "y": 9,
      "z": -2,
      "name": "Rock_Shale_Brick_Smooth",
      "rotation": 1
    },
    {
      "x": -22,
      "y": 10,
      "z": -2,
      "name": "Rock_Ice",
      "rotation": 1
    },
    {
      "x": -22,
      "y": 11,
      "z": -2,
      "name": "Rock_Ice",
      "rotation": 1
    },
    {
      "x": -22,
      "y": -12,
      "z": -1,
      "name": "Rock_Shale_Cobble",
      "rotation": 1
    },
    {
      "x": -22,
      "y": -11,
      "z": -1,
      "name": "Rock_Shale_Brick_Smooth"
    },
    {
      "x": -22,
      "y": -10,
      "z": -1,
      "name": "Rock_Shale_Brick_Smooth"
    },
    {
      "x": -22,
      "y": -9,
      "z": -1,
      "name": "Rock_Shale_Brick_Smooth"
    },
    {
      "x": -22,
      "y": -8,
      "z": -1,
      "name": "Rock_Shale_Cobble",
      "rotation": 1
    },
    {
      "x": -22,
      "y": -7,
      "z": -1,
      "name": "Rock_Shale_Cobble",
      "rotation": 1
    },
    {
      "x": -22,
      "y": -6,
      "z": -1,
      "name": "Rock_Shale_Cobble"
    },
    {
      "x": -22,
      "y": -3,
      "z": -1,
      "name": "Rock_Stone",
      "rotation": 1
    },
    {
      "x": -22,
      "y": -2,
      "z": -1,
      "name": "Rock_Stone",
      "rotation": 1
    },
    {
      "x": -22,
      "y": -1,
      "z": -1,
      "name": "Rock_Stone",
      "rotation": 1
    },
    {
      "x": -22,
      "y": 0,
      "z": -1,
      "name": "Rock_Stone",
      "rotation": 1
    },
    {
      "x": -22,
      "y": 1,
      "z": -1,
      "name": "Rock_Runic_Brick"
    },
    {
      "x": -22,
      "y": 2,
      "z": -1,
      "name": "Rock_Runic_Brick",
      "rotation": 1
    },
    {
      "x": -22,
      "y": 3,
      "z": -1,
      "name": "Rock_Runic_Brick",
      "rotation": 1
    },
    {
      "x": -22,
      "y": 7,
      "z": -1,
      "name": "Rock_Shale_Brick_Smooth"
    },
    {
      "x": -22,
      "y": 8,
      "z": -1,
      "name": "Rock_Runic_Brick"
    },
    {
      "x": -22,
      "y": 9,
      "z": -1,
      "name": "Rock_Shale_Brick_Smooth",
      "rotation": 1
    },
    {
      "x": -22,
      "y": 10,
      "z": -1,
      "name": "Rock_Ice",
      "rotation": 1
    },
    {
      "x": -22,
      "y": 11,
      "z": -1,
      "name": "Rock_Ice",
      "rotation": 1
    },
    {
      "x": -22,
      "y": -12,
      "z": 0,
      "name": "Rock_Ice_Permafrost",
      "rotation": 1
    },
    {
      "x": -22,
      "y": -11,
      "z": 0,
      "name": "Empty"
    },
    {
      "x": -22,
      "y": -10,
      "z": 0,
      "name": "Empty"
    },
    {
      "x": -22,
      "y": -9,
      "z": 0,
      "name": "Empty"
    },
    {
      "x": -22,
      "y": -8,
      "z": 0,
      "name": "Empty"
    },
    {
      "x": -22,
      "y": -7,
      "z": 0,
      "name": "Rock_Shale_Brick"
    },
    {
      "x": -22,
      "y": -6,
      "z": 0,
      "name": "Rock_Shale_Cobble"
    },
    {
      "x": -22,
      "y": -3,
      "z": 0,
      "name": "Rock_Stone",
      "rotation": 1
    },
    {
      "x": -22,
      "y": -2,
      "z": 0,
      "name": "Rock_Stone",
      "rotation": 1
    },
    {
      "x": -22,
      "y": -1,
      "z": 0,
      "name": "Rock_Stone",
      "rotation": 1
    },
    {
      "x": -22,
      "y": 0,
      "z": 0,
      "name": "Rock_Stone",
      "rotation": 1
    },
    {
      "x": -22,
      "y": 1,
      "z": 0,
      "name": "Rock_Runic_Brick"
    },
    {
      "x": -22,
      "y": 2,
      "z": 0,
      "name": "Rock_Runic_Brick",
      "rotation": 1
    },
    {
      "x": -22,
      "y": 3,
      "z": 0,
      "name": "Rock_Runic_Brick",
      "rotation": 1
    },
    {
      "x": -22,
      "y": 7,
      "z": 0,
      "name": "Rock_Shale_Brick_Smooth"
    },
    {
      "x": -22,
      "y": 8,
      "z": 0,
      "name": "Rock_Runic_Brick"
    },
    {
      "x": -22,
      "y": 9,
      "z": 0,
      "name": "Rock_Shale_Brick_Smooth",
      "rotation": 1
    },
    {
      "x": -22,
      "y": 10,
      "z": 0,
      "name": "Rock_Ice",
      "rotation": 1
    },
    {
      "x": -22,
      "y": 11,
      "z": 0,
      "name": "Rock_Ice",
      "rotation": 1
    },
    {
      "x": -22,
      "y": -12,
      "z": 1,
      "name": "Rock_Ice_Permafrost",
      "rotation": 1
    },
    {
      "x": -22,
      "y": -11,
      "z": 1,
      "name": "Empty"
    },
    {
      "x": -22,
      "y": -10,
      "z": 1,
      "name": "Empty"
    },
    {
      "x": -22,
      "y": -9,
      "z": 1,
      "name": "Empty"
    },
    {
      "x": -22,
      "y": -8,
      "z": 1,
      "name": "Empty"
    },
    {
      "x": -22,
      "y": -6,
      "z": 1,
      "name": "Rock_Shale_Brick_Smooth"
    },
    {
      "x": -22,
      "y": -3,
      "z": 1,
      "name": "Rock_Stone"
    },
    {
      "x": -22,
      "y": -2,
      "z": 1,
      "name": "Rock_Stone"
    },
    {
      "x": -22,
      "y": -1,
      "z": 1,
      "name": "Rock_Stone",
      "rotation": 1
    },
    {
      "x": -22,
      "y": 0,
      "z": 1,
      "name": "Rock_Ice_Permafrost",
      "rotation": 1
    },
    {
      "x": -22,
      "y": 1,
      "z": 1,
      "name": "Rock_Runic_Brick"
    },
    {
      "x": -22,
      "y": 2,
      "z": 1,
      "name": "Rock_Runic_Brick",
      "rotation": 1
    },
    {
      "x": -22,
      "y": 3,
      "z": 1,
      "name": "Rock_Runic_Brick",
      "rotation": 1
    },
    {
      "x": -22,
      "y": 7,
      "z": 1,
      "name": "Rock_Shale_Brick_Smooth"
    },
    {
      "x": -22,
      "y": 8,
      "z": 1,
      "name": "Rock_Runic_Brick"
    },
    {
      "x": -22,
      "y": 9,
      "z": 1,
      "name": "Rock_Shale_Brick_Smooth",
      "rotation": 1
    },
    {
      "x": -22,
      "y": 10,
      "z": 1,
      "name": "Rock_Ice",
      "rotation": 1
    },
    {
      "x": -22,
      "y": 11,
      "z": 1,
      "name": "Rock_Ice",
      "rotation": 1
    },
    {
      "x": -22,
      "y": -12,
      "z": 2,
      "name": "Rock_Ice"
    },
    {
      "x": -22,
      "y": -11,
      "z": 2,
      "name": "Empty"
    },
    {
      "x": -22,
      "y": -10,
      "z": 2,
      "name": "Empty"
    },
    {
      "x": -22,
      "y": -9,
      "z": 2,
      "name": "Empty"
    },
    {
      "x": -22,
      "y": -8,
      "z": 2,
      "name": "Rock_Ice_Stalactite_Large",
      "filler": 31744,
      "rotation": 8
    },
    {
      "x": -22,
      "y": -7,
      "z": 2,
      "name": "Rock_Ice_Stalactite_Large",
      "rotation": 8
    },
    {
      "x": -22,
      "y": -6,
      "z": 2,
      "name": "Rock_Shale_Brick_Smooth"
    },
    {
      "x": -22,
      "y": -1,
      "z": 2,
      "name": "Rock_Stone",
      "rotation": 1
    },
    {
      "x": -22,
      "y": 0,
      "z": 2,
      "name": "Rock_Stone",
      "rotation": 1
    },
    {
      "x": -22,
      "y": 1,
      "z": 2,
      "name": "Rock_Stone",
      "rotation": 1
    },
    {
      "x": -22,
      "y": 2,
      "z": 2,
      "name": "Rock_Runic_Brick",
      "rotation": 1
    },
    {
      "x": -22,
      "y": 3,
      "z": 2,
      "name": "Rock_Runic_Brick",
      "rotation": 1
    },
    {
      "x": -22,
      "y": 7,
      "z": 2,
      "name": "Rock_Shale_Brick_Smooth"
    },
    {
      "x": -22,
      "y": 8,
      "z": 2,
      "name": "Rock_Runic_Brick"
    },
    {
      "x": -22,
      "y": 9,
      "z": 2,
      "name": "Rock_Shale_Brick_Smooth",
      "rotation": 1
    },
    {
      "x": -22,
      "y": 10,
      "z": 2,
      "name": "Rock_Ice",
      "rotation": 1
    },
    {
      "x": -22,
      "y": 11,
      "z": 2,
      "name": "Rock_Ice",
      "rotation": 1
    },
    {
      "x": -22,
      "y": -12,
      "z": 3,
      "name": "Rock_Ice"
    },
    {
      "x": -22,
      "y": -11,
      "z": 3,
      "name": "Empty"
    },
    {
      "x": -22,
      "y": -10,
      "z": 3,
      "name": "Empty"
    },
    {
      "x": -22,
      "y": -9,
      "z": 3,
      "name": "Empty"
    },
    {
      "x": -22,
      "y": -8,
      "z": 3,
      "name": "Empty"
    },
    {
      "x": -22,
      "y": -7,
      "z": 3,
      "name": "Empty"
    },
    {
      "x": -22,
      "y": -6,
      "z": 3,
      "name": "Rock_Ice_Permafrost"
    },
    {
      "x": -22,
      "y": 0,
      "z": 3,
      "name": "Rock_Stone",
      "rotation": 1
    },
    {
      "x": -22,
      "y": 1,
      "z": 3,
      "name": "Rock_Stone",
      "rotation": 1
    },
    {
      "x": -22,
      "y": 2,
      "z": 3,
      "name": "Rock_Marble",
      "rotation": 1
    },
    {
      "x": -22,
      "y": 3,
      "z": 3,
      "name": "Rock_Runic_Brick",
      "rotation": 1
    },
    {
      "x": -22,
      "y": 4,
      "z": 3,
      "name": "Rock_Runic_Brick",
      "rotation": 1
    },
    {
      "x": -22,
      "y": 5,
      "z": 3,
      "name": "Rock_Runic_Brick",
      "rotation": 1
    },
    {
      "x": -22,
      "y": 6,
      "z": 3,
      "name": "Rock_Runic_Brick",
      "rotation": 1
    },
    {
      "x": -22,
      "y": 7,
      "z": 3,
      "name": "Rock_Shale_Brick_Smooth"
    },
    {
      "x": -22,
      "y": 8,
      "z": 3,
      "name": "Rock_Runic_Brick"
    },
    {
      "x": -22,
      "y": 9,
      "z": 3,
      "name": "Rock_Shale_Brick_Smooth",
      "rotation": 1
    },
    {
      "x": -22,
      "y": 10,
      "z": 3,
      "name": "Rock_Ice",
      "rotation": 1
    },
    {
      "x": -22,
      "y": -12,
      "z": 4,
      "name": "Rock_Ice_Permafrost"
    },
    {
      "x": -22,
      "y": -11,
      "z": 4,
      "name": "Empty"
    },
    {
      "x": -22,
      "y": -10,
      "z": 4,
      "name": "Empty"
    },
    {
      "x": -22,
      "y": -9,
      "z": 4,
      "name": "Empty"
    },
    {
      "x": -22,
      "y": -8,
      "z": 4,
      "name": "Empty"
    },
    {
      "x": -22,
      "y": -7,
      "z": 4,
      "name": "Empty"
    },
    {
      "x": -22,
      "y": -6,
      "z": 4,
      "name": "Rock_Stone"
    },
    {
      "x": -22,
      "y": 0,
      "z": 4,
      "name": "Rock_Stone",
      "rotation": 1
    },
    {
      "x": -22,
      "y": 1,
      "z": 4,
      "name": "Rock_Stone",
      "rotation": 1
    },
    {
      "x": -22,
      "y": 2,
      "z": 4,
      "name": "Rock_Runic_Brick",
      "rotation": 1
    },
    {
      "x": -22,
      "y": 3,
      "z": 4,
      "name": "Rock_Runic_Brick",
      "rotation": 1
    },
    {
      "x": -22,
      "y": 4,
      "z": 4,
      "name": "Rock_Runic_Brick",
      "rotation": 1
    },
    {
      "x": -22,
      "y": 5,
      "z": 4,
      "name": "Rock_Runic_Brick",
      "rotation": 1
    },
    {
      "x": -22,
      "y": 6,
      "z": 4,
      "name": "Rock_Runic_Brick",
      "rotation": 1
    },
    {
      "x": -22,
      "y": 7,
      "z": 4,
      "name": "Rock_Runic_Brick",
      "rotation": 1
    },
    {
      "x": -22,
      "y": 8,
      "z": 4,
      "name": "Rock_Runic_Brick"
    },
    {
      "x": -22,
      "y": 9,
      "z": 4,
      "name": "Rock_Shale_Brick_Smooth",
      "rotation": 1
    },
    {
      "x": -22,
      "y": -12,
      "z": 5,
      "name": "Rock_Ice_Permafrost"
    },
    {
      "x": -22,
      "y": -11,
      "z": 5,
      "name": "Rock_Ice_Stalactite_Large"
    },
    {
      "x": -22,
      "y": -10,
      "z": 5,
      "name": "Rock_Ice_Stalactite_Large",
      "filler": 1024
    },
    {
      "x": -22,
      "y": -9,
      "z": 5,
      "name": "Empty"
    },
    {
      "x": -22,
      "y": -8,
      "z": 5,
      "name": "Empty"
    },
    {
      "x": -22,
      "y": -7,
      "z": 5,
      "name": "Rock_Stone",
      "rotation": 1
    },
    {
      "x": -22,
      "y": -6,
      "z": 5,
      "name": "Rock_Ice"
    },
    {
      "x": -22,
      "y": 0,
      "z": 5,
      "name": "Rock_Stone",
      "rotation": 1
    },
    {
      "x": -22,
      "y": 1,
      "z": 5,
      "name": "Rock_Stone",
      "rotation": 1
    },
    {
      "x": -22,
      "y": 2,
      "z": 5,
      "name": "Rock_Runic_Brick",
      "rotation": 1
    },
    {
      "x": -22,
      "y": 3,
      "z": 5,
      "name": "Rock_Runic_Brick",
      "rotation": 1
    },
    {
      "x": -22,
      "y": 4,
      "z": 5,
      "name": "Rock_Calcite_Brick",
      "rotation": 1
    },
    {
      "x": -22,
      "y": 5,
      "z": 5,
      "name": "Rock_Runic_Brick",
      "rotation": 1
    },
    {
      "x": -22,
      "y": 6,
      "z": 5,
      "name": "Rock_Runic_Brick",
      "rotation": 1
    },
    {
      "x": -22,
      "y": 7,
      "z": 5,
      "name": "Rock_Runic_Brick",
      "rotation": 1
    },
    {
      "x": -22,
      "y": 9,
      "z": 5,
      "name": "Rock_Shale_Cobble_Half"
    },
    {
      "x": -22,
      "y": -12,
      "z": 6,
      "name": "Rock_Ice_Permafrost"
    },
    {
      "x": -22,
      "y": -11,
      "z": 6,
      "name": "Empty"
    },
    {
      "x": -22,
      "y": -10,
      "z": 6,
      "name": "Empty"
    },
    {
      "x": -22,
      "y": -9,
      "z": 6,
      "name": "Empty"
    },
    {
      "x": -22,
      "y": -8,
      "z": 6,
      "name": "Empty"
    },
    {
      "x": -22,
      "y": -7,
      "z": 6,
      "name": "Rock_Ice_Permafrost",
      "rotation": 1
    },
    {
      "x": -22,
      "y": -6,
      "z": 6,
      "name": "Rock_Ice"
    },
    {
      "x": -22,
      "y": 0,
      "z": 6,
      "name": "Rock_Stone",
      "rotation": 1
    },
    {
      "x": -22,
      "y": 1,
      "z": 6,
      "name": "Rock_Stone",
      "rotation": 1
    },
    {
      "x": -22,
      "y": 2,
      "z": 6,
      "name": "Rock_Runic_Brick",
      "rotation": 1
    },
    {
      "x": -22,
      "y": 3,
      "z": 6,
      "name": "Rock_Runic_Brick",
      "rotation": 1
    },
    {
      "x": -22,
      "y": 4,
      "z": 6,
      "name": "Rock_Calcite_Brick",
      "rotation": 1
    },
    {
      "x": -22,
      "y": 5,
      "z": 6,
      "name": "Rock_Calcite_Brick",
      "rotation": 1
    },
    {
      "x": -22,
      "y": 6,
      "z": 6,
      "name": "Rock_Calcite_Brick",
      "rotation": 1
    },
    {
      "x": -22,
      "y": 7,
      "z": 6,
      "name": "Rock_Runic_Brick",
      "rotation": 1
    },
    {
      "x": -22,
      "y": 8,
      "z": 6,
      "name": "Soil_Snow_Half"
    },
    {
      "x": -22,
      "y": -12,
      "z": 7,
      "name": "Rock_Ice_Permafrost"
    },
    {
      "x": -22,
      "y": -11,
      "z": 7,
      "name": "Empty"
    },
    {
      "x": -22,
      "y": -10,
      "z": 7,
      "name": "Empty"
    },
    {
      "x": -22,
      "y": -9,
      "z": 7,
      "name": "Empty"
    },
    {
      "x": -22,
      "y": -8,
      "z": 7,
      "name": "Empty"
    },
    {
      "x": -22,
      "y": -7,
      "z": 7,
      "name": "Empty"
    },
    {
      "x": -22,
      "y": -6,
      "z": 7,
      "name": "Rock_Ice"
    },
    {
      "x": -22,
      "y": 0,
      "z": 7,
      "name": "Rock_Stone",
      "rotation": 1
    },
    {
      "x": -22,
      "y": 1,
      "z": 7,
      "name": "Rock_Ice_Permafrost"
    },
    {
      "x": -22,
      "y": 5,
      "z": 7,
      "name": "Rock_Ice"
    },
    {
      "x": -22,
      "y": 6,
      "z": 7,
      "name": "Rock_Ice"
    },
    {
      "x": -22,
      "y": 7,
      "z": 7,
      "name": "Rock_Ice",
      "rotation": 1
    },
    {
      "x": -22,
      "y": 8,
      "z": 7,
      "name": "Soil_Snow_Half"
    },
    {
      "x": -22,
      "y": -12,
      "z": 8,
      "name": "Rock_Shale_Cobble",
      "rotation": 1
    },
    {
      "x": -22,
      "y": -11,
      "z": 8,
      "name": "Empty"
    },
    {
      "x": -22,
      "y": -10,
      "z": 8,
      "name": "Empty"
    },
    {
      "x": -22,
      "y": -9,
      "z": 8,
      "name": "Empty"
    },
    {
      "x": -22,
      "y": -8,
      "z": 8,
      "name": "Empty"
    },
    {
      "x": -22,
      "y": -7,
      "z": 8,
      "name": "Empty"
    },
    {
      "x": -22,
      "y": -6,
      "z": 8,
      "name": "Rock_Ice"
    },
    {
      "x": -22,
      "y": 0,
      "z": 8,
      "name": "Rock_Ice_Permafrost",
      "rotation": 1
    },
    {
      "x": -22,
      "y": -12,
      "z": 9,
      "name": "Rock_Shale_Cobble",
      "rotation": 1
    },
    {
      "x": -22,
      "y": -11,
      "z": 9,
      "name": "Empty"
    },
    {
      "x": -22,
      "y": -10,
      "z": 9,
      "name": "Empty"
    },
    {
      "x": -22,
      "y": -9,
      "z": 9,
      "name": "Empty"
    },
    {
      "x": -22,
      "y": -8,
      "z": 9,
      "name": "Empty"
    },
    {
      "x": -22,
      "y": -7,
      "z": 9,
      "name": "Empty"
    },
    {
      "x": -22,
      "y": -6,
      "z": 9,
      "name": "Rock_Stone"
    },
    {
      "x": -22,
      "y": -1,
      "z": 9,
      "name": "Rock_Ice",
      "rotation": 1
    },
    {
      "x": -22,
      "y": 0,
      "z": 9,
      "name": "Soil_Snow_Half"
    },
    {
      "x": -22,
      "y": -12,
      "z": 10,
      "name": "Rock_Shale_Brick_Smooth"
    },
    {
      "x": -22,
      "y": -11,
      "z": 10,
      "name": "Empty"
    },
    {
      "x": -22,
      "y": -10,
      "z": 10,
      "name": "Empty"
    },
    {
      "x": -22,
      "y": -9,
      "z": 10,
      "name": "Empty"
    },
    {
      "x": -22,
      "y": -8,
      "z": 10,
      "name": "Empty"
    },
    {
      "x": -22,
      "y": -7,
      "z": 10,
      "name": "Empty"
    },
    {
      "x": -22,
      "y": -6,
      "z": 10,
      "name": "Rock_Ice"
    },
    {
      "x": -22,
      "y": -1,
      "z": 10,
      "name": "Rock_Ice",
      "rotation": 1
    },
    {
      "x": -22,
      "y": 0,
      "z": 10,
      "name": "Soil_Snow_Half"
    },
    {
      "x": -22,
      "y": -12,
      "z": 11,
      "name": "Rock_Shale_Brick_Smooth"
    },
    {
      "x": -22,
      "y": -11,
      "z": 11,
      "name": "Empty"
    },
    {
      "x": -22,
      "y": -10,
      "z": 11,
      "name": "Empty"
    },
    {
      "x": -22,
      "y": -9,
      "z": 11,
      "name": "Empty"
    },
    {
      "x": -22,
      "y": -8,
      "z": 11,
      "name": "Empty"
    },
    {
      "x": -22,
      "y": -7,
      "z": 11,
      "name": "Empty"
    },
    {
      "x": -22,
      "y": -6,
      "z": 11,
      "name": "Rock_Stone"
    },
    {
      "x": -22,
      "y": -1,
      "z": 11,
      "name": "Rock_Ice",
      "rotation": 1
    },
    {
      "x": -22,
      "y": 0,
      "z": 11,
      "name": "Soil_Snow_Half"
    },
    {
      "x": -22,
      "y": -12,
      "z": 12,
      "name": "Rock_Shale_Cobble",
      "rotation": 1
    },
    {
      "x": -22,
      "y": -11,
      "z": 12,
      "name": "Empty"
    },
    {
      "x": -22,
      "y": -10,
      "z": 12,
      "name": "Empty"
    },
    {
      "x": -22,
      "y": -9,
      "z": 12,
      "name": "Empty"
    },
    {
      "x": -22,
      "y": -8,
      "z": 12,
      "name": "Empty"
    },
    {
      "x": -22,
      "y": -7,
      "z": 12,
      "name": "Empty"
    },
    {
      "x": -22,
      "y": -6,
      "z": 12,
      "name": "Rock_Stone"
    },
    {
      "x": -22,
      "y": -1,
      "z": 12,
      "name": "Rock_Ice",
      "rotation": 1
    },
    {
      "x": -22,
      "y": 0,
      "z": 12,
      "name": "Soil_Snow_Half"
    },
    {
      "x": -22,
      "y": -12,
      "z": 13,
      "name": "Rock_Shale_Cobble",
      "rotation": 1
    },
    {
      "x": -22,
      "y": -11,
      "z": 13,
      "name": "Empty"
    },
    {
      "x": -22,
      "y": -10,
      "z": 13,
      "name": "Empty"
    },
    {
      "x": -22,
      "y": -9,
      "z": 13,
      "name": "Empty"
    },
    {
      "x": -22,
      "y": -8,
      "z": 13,
      "name": "Empty"
    },
    {
      "x": -22,
      "y": -7,
      "z": 13,
      "name": "Rock_Ice_Icicles",
      "rotation": 8
    },
    {
      "x": -22,
      "y": -6,
      "z": 13,
      "name": "Rock_Ice"
    },
    {
      "x": -22,
      "y": -1,
      "z": 13,
      "name": "Rock_Ice",
      "rotation": 1
    },
    {
      "x": -22,
      "y": 0,
      "z": 13,
      "name": "Soil_Snow_Half"
    },
    {
      "x": -22,
      "y": -12,
      "z": 14,
      "name": "Rock_Shale_Cobble",
      "rotation": 1
    },
    {
      "x": -22,
      "y": -11,
      "z": 14,
      "name": "Empty"
    },
    {
      "x": -22,
      "y": -10,
      "z": 14,
      "name": "Empty"
    },
    {
      "x": -22,
      "y": -9,
      "z": 14,
      "name": "Empty"
    },
    {
      "x": -22,
      "y": -8,
      "z": 14,
      "name": "Empty"
    },
    {
      "x": -22,
      "y": -7,
      "z": 14,
      "name": "Rock_Ice_Permafrost",
      "rotation": 1
    },
    {
      "x": -22,
      "y": -6,
      "z": 14,
      "name": "Rock_Stone"
    },
    {
      "x": -22,
      "y": -12,
      "z": 15,
      "name": "Rock_Shale_Cobble",
      "rotation": 1
    },
    {
      "x": -22,
      "y": -11,
      "z": 15,
      "name": "Empty"
    },
    {
      "x": -22,
      "y": -10,
      "z": 15,
      "name": "Empty"
    },
    {
      "x": -22,
      "y": -9,
      "z": 15,
      "name": "Empty"
    },
    {
      "x": -22,
      "y": -8,
      "z": 15,
      "name": "Rock_Shale_Brick_Stairs",
      "rotation": 9
    },
    {
      "x": -22,
      "y": -7,
      "z": 15,
      "name": "Rock_Shale_Brick"
    },
    {
      "x": -22,
      "y": -12,
      "z": 16,
      "name": "Rock_Stone"
    },
    {
      "x": -22,
      "y": -11,
      "z": 16,
      "name": "Rock_Ice"
    },
    {
      "x": -22,
      "y": -10,
      "z": 16,
      "name": "Empty"
    },
    {
      "x": -22,
      "y": -9,
      "z": 16,
      "name": "Empty"
    },
    {
      "x": -22,
      "y": -8,
      "z": 16,
      "name": "Rock_Stone"
    },
    {
      "x": -22,
      "y": -11,
      "z": 17,
      "name": "Rock_Stone"
    },
    {
