{
  "version": 8,
  "blockIdVersion": 11,
  "anchorX": 0,
  "anchorY": 0,
  "anchorZ": 0,
  "blocks": [
    {
      "x": -13,
      "y": -3,
      "z": -13,
      "name": "Soil_Sand_White"
    },
    {
      "x": -13,
      "y": -3,
      "z": -12,
      "name": "Soil_Sand_White"
    },
    {
      "x": -13,
      "y": -3,
      "z": -11,
      "name": "Soil_Sand_White"
    },
    {
      "x": -12,
      "y": -3,
      "z": -18,
      "name": "Soil_Sand_White"
    },
    {
      "x": -12,
      "y": -3,
      "z": -17,
      "name": "Soil_Sand_White"
    },
    {
      "x": -12,
      "y": -3,
      "z": -16,
      "name": "Soil_Sand_White"
    },
    {
      "x": -12,
      "y": -3,
      "z": -14,
      "name": "Soil_Sand_White"
    },
    {
      "x": -12,
      "y": -3,
      "z": -13,
      "name": "Rock_Sandstone"
    },
    {
      "x": -12,
      "y": -2,
      "z": -13,
      "name": "Soil_Sand_White"
    },
    {
      "x": -12,
      "y": -3,
      "z": -12,
      "name": "Rock_Sandstone"
    },
    {
      "x": -12,
      "y": -2,
      "z": -12,
      "name": "Soil_Sand_White"
    },
    {
      "x": -12,
      "y": -3,
      "z": -11,
      "name": "Rock_Sandstone"
    },
    {
      "x": -12,
      "y": -2,
      "z": -11,
      "name": "Soil_Sand_White"
    },
    {
      "x": -12,
      "y": -3,
      "z": -10,
      "name": "Soil_Sand_White"
    },
    {
      "x": -11,
      "y": -3,
      "z": -19,
      "name": "Soil_Sand_White"
    },
    {
      "x": -11,
      "y": -3,
      "z": -18,
      "name": "Rock_Sandstone"
    },
    {
      "x": -11,
      "y": -2,
      "z": -18,
      "name": "Soil_Sand_White"
    },
    {
      "x": -11,
      "y": -3,
      "z": -17,
      "name": "Rock_Sandstone"
    },
    {
      "x": -11,
      "y": -2,
      "z": -17,
      "name": "Soil_Sand_White"
    },
    {
      "x": -11,
      "y": -3,
      "z": -16,
      "name": "Rock_Sandstone"
    },
    {
      "x": -11,
      "y": -2,
      "z": -16,
      "name": "Soil_Sand_White"
    },
    {
      "x": -11,
      "y": -3,
      "z": -15,
      "name": "Soil_Sand_White"
    },
    {
      "x": -11,
      "y": -3,
      "z": -14,
      "name": "Rock_Sandstone"
    },
    {
      "x": -11,
      "y": -2,
      "z": -14,
      "name": "Soil_Sand_White"
    },
    {
      "x": -11,
      "y": -3,
      "z": -13,
      "name": "Rock_Sandstone"
    },
    {
      "x": -11,
      "y": -2,
      "z": -13,
      "name": "Rock_Sandstone"
    },
    {
      "x": -11,
      "y": -1,
      "z": -13,
      "name": "Soil_Sand_White"
    },
    {
      "x": -11,
      "y": -3,
      "z": -12,
      "name": "Rock_Sandstone"
    },
    {
      "x": -11,
      "y": -2,
      "z": -12,
      "name": "Rock_Sandstone"
    },
    {
      "x": -11,
      "y": -1,
      "z": -12,
      "name": "Soil_Sand_White"
    },
    {
      "x": -11,
      "y": -3,
      "z": -11,
      "name": "Rock_Sandstone"
    },
    {
      "x": -11,
      "y": -2,
      "z": -11,
      "name": "Rock_Sandstone"
    },
    {
      "x": -11,
      "y": -1,
      "z": -11,
      "name": "Soil_Sand_White"
    },
    {
      "x": -11,
      "y": -3,
      "z": -10,
      "name": "Rock_Sandstone"
    },
    {
      "x": -11,
      "y": -2,
      "z": -10,
      "name": "Soil_Sand_White"
    },
    {
      "x": -11,
      "y": -3,
      "z": -9,
      "name": "Soil_Sand_White"
    },
    {
      "x": -11,
      "y": -3,
      "z": -8,
      "name": "Soil_Sand_White"
    },
    {
      "x": -11,
      "y": -3,
      "z": -6,
      "name": "Soil_Sand_White"
    },
    {
      "x": -11,
      "y": -3,
      "z": -5,
      "name": "Soil_Sand_White"
    },
    {
      "x": -11,
      "y": -3,
      "z": -4,
      "name": "Soil_Sand_White"
    },
    {
      "x": -11,
      "y": -3,
      "z": -1,
      "name": "Soil_Sand_White"
    },
    {
      "x": -11,
      "y": -3,
      "z": 0,
      "name": "Soil_Sand_White"
    },
    {
      "x": -11,
      "y": -3,
      "z": 1,
      "name": "Soil_Sand_White"
    },
    {
      "x": -10,
      "y": -3,
      "z": -20,
      "name": "Soil_Sand_White"
    },
    {
      "x": -10,
      "y": -3,
      "z": -19,
      "name": "Rock_Sandstone"
    },
    {
      "x": -10,
      "y": -2,
      "z": -19,
      "name": "Soil_Sand_White"
    },
    {
      "x": -10,
      "y": -3,
      "z": -18,
      "name": "Rock_Sandstone"
    },
    {
      "x": -10,
      "y": -2,
      "z": -18,
      "name": "Rock_Sandstone"
    },
    {
      "x": -10,
      "y": -1,
      "z": -18,
      "name": "Soil_Sand_White"
    },
    {
      "x": -10,
      "y": -3,
      "z": -17,
      "name": "Rock_Sandstone"
    },
    {
      "x": -10,
      "y": -2,
      "z": -17,
      "name": "Rock_Sandstone"
    },
    {
      "x": -10,
      "y": -1,
      "z": -17,
      "name": "Soil_Sand_White"
    },
    {
      "x": -10,
      "y": -3,
      "z": -16,
      "name": "Rock_Sandstone"
    },
    {
      "x": -10,
      "y": -2,
      "z": -16,
      "name": "Rock_Sandstone"
    },
    {
      "x": -10,
      "y": -1,
      "z": -16,
      "name": "Soil_Sand_White"
    },
    {
      "x": -10,
      "y": -3,
      "z": -15,
      "name": "Rock_Sandstone"
    },
    {
      "x": -10,
      "y": -2,
      "z": -15,
      "name": "Soil_Sand_White"
    },
    {
      "x": -10,
      "y": -3,
      "z": -14,
      "name": "Rock_Sandstone"
    },
    {
      "x": -10,
      "y": -2,
      "z": -14,
      "name": "Rock_Sandstone"
    },
    {
      "x": -10,
      "y": -1,
      "z": -14,
      "name": "Soil_Sand_White"
    },
    {
      "x": -10,
      "y": -3,
      "z": -13,
      "name": "Rock_Sandstone"
    },
    {
      "x": -10,
      "y": -2,
      "z": -13,
      "name": "Rock_Sandstone"
    },
    {
      "x": -10,
      "y": -1,
      "z": -13,
      "name": "Soil_Sand_White"
    },
    {
      "x": -10,
      "y": -3,
      "z": -12,
      "name": "Rock_Sandstone"
    },
    {
      "x": -10,
      "y": -2,
      "z": -12,
      "name": "Rock_Sandstone"
    },
    {
      "x": -10,
      "y": -1,
      "z": -12,
      "name": "Soil_Sand_White"
    },
    {
      "x": -10,
      "y": -3,
      "z": -11,
      "name": "Rock_Sandstone"
    },
    {
      "x": -10,
      "y": -2,
      "z": -11,
      "name": "Rock_Sandstone"
    },
    {
      "x": -10,
      "y": -1,
      "z": -11,
      "name": "Soil_Sand_White"
    },
    {
      "x": -10,
      "y": -3,
      "z": -10,
      "name": "Rock_Sandstone"
    },
    {
      "x": -10,
      "y": -2,
      "z": -10,
      "name": "Rock_Sandstone"
    },
    {
      "x": -10,
      "y": -1,
      "z": -10,
      "name": "Soil_Sand_White"
    },
    {
      "x": -10,
      "y": -3,
      "z": -9,
      "name": "Rock_Sandstone"
    },
    {
      "x": -10,
      "y": -2,
      "z": -9,
      "name": "Soil_Sand_White"
    },
    {
      "x": -10,
      "y": -3,
      "z": -8,
      "name": "Rock_Sandstone"
    },
    {
      "x": -10,
      "y": -2,
      "z": -8,
      "name": "Soil_Sand_White"
    },
    {
      "x": -10,
      "y": -3,
      "z": -7,
      "name": "Soil_Sand_White"
    },
    {
      "x": -10,
      "y": -3,
      "z": -6,
      "name": "Rock_Sandstone"
    },
    {
      "x": -10,
      "y": -2,
      "z": -6,
      "name": "Soil_Sand_White"
    },
    {
      "x": -10,
      "y": -3,
      "z": -5,
      "name": "Rock_Sandstone"
    },
    {
      "x": -10,
      "y": -2,
      "z": -5,
      "name": "Soil_Sand_White"
    },
    {
      "x": -10,
      "y": -3,
      "z": -4,
      "name": "Rock_Sandstone"
    },
    {
      "x": -10,
      "y": -2,
      "z": -4,
      "name": "Soil_Sand_White"
    },
    {
      "x": -10,
      "y": -3,
      "z": -3,
      "name": "Soil_Sand_White"
    },
    {
      "x": -10,
      "y": -3,
      "z": -2,
      "name": "Soil_Sand_White"
    },
    {
      "x": -10,
      "y": -3,
      "z": -1,
      "name": "Rock_Sandstone"
    },
    {
      "x": -10,
      "y": -2,
      "z": -1,
      "name": "Soil_Sand_White"
    },
    {
      "x": -10,
      "y": -3,
      "z": 0,
      "name": "Rock_Sandstone"
    },
    {
      "x": -10,
      "y": -2,
      "z": 0,
      "name": "Soil_Sand_White"
    },
    {
      "x": -10,
      "y": -3,
      "z": 1,
      "name": "Rock_Sandstone"
    },
    {
      "x": -10,
      "y": -2,
      "z": 1,
      "name": "Soil_Sand_White"
    },
    {
      "x": -10,
      "y": -3,
      "z": 2,
      "name": "Soil_Sand_White"
    },
    {
      "x": -9,
      "y": -3,
      "z": -21,
      "name": "Soil_Sand_White"
    },
    {
      "x": -9,
      "y": -3,
      "z": -20,
      "name": "Rock_Sandstone"
    },
    {
      "x": -9,
      "y": -2,
      "z": -20,
      "name": "Soil_Sand_White"
    },
    {
      "x": -9,
      "y": -3,
      "z": -19,
      "name": "Rock_Sandstone"
    },
    {
      "x": -9,
      "y": -2,
      "z": -19,
      "name": "Rock_Sandstone"
    },
    {
      "x": -9,
      "y": -1,
      "z": -19,
      "name": "Soil_Sand_White"
    },
    {
      "x": -9,
      "y": -3,
      "z": -18,
      "name": "Rock_Sandstone"
    },
    {
      "x": -9,
      "y": -2,
      "z": -18,
      "name": "Rock_Sandstone"
    },
    {
      "x": -9,
      "y": -1,
      "z": -18,
      "name": "Soil_Sand_White"
    },
    {
      "x": -9,
      "y": -3,
      "z": -17,
      "name": "Rock_Sandstone"
    },
    {
      "x": -9,
      "y": -2,
      "z": -17,
      "name": "Rock_Sandstone"
    },
    {
      "x": -9,
      "y": -1,
      "z": -17,
      "name": "Soil_Sand_White"
    },
    {
      "x": -9,
      "y": -3,
      "z": -16,
      "name": "Rock_Sandstone"
    },
    {
      "x": -9,
      "y": -2,
      "z": -16,
      "name": "Rock_Sandstone"
    },
    {
      "x": -9,
      "y": -1,
      "z": -16,
      "name": "Soil_Sand_White"
    },
    {
      "x": -9,
      "y": -3,
      "z": -15,
      "name": "Rock_Sandstone"
    },
    {
      "x": -9,
      "y": -2,
      "z": -15,
      "name": "Rock_Sandstone"
    },
    {
      "x": -9,
      "y": -1,
      "z": -15,
      "name": "Soil_Sand_White"
    },
    {
      "x": -9,
      "y": -3,
      "z": -14,
      "name": "Rock_Sandstone"
    },
    {
      "x": -9,
      "y": -2,
      "z": -14,
      "name": "Rock_Sandstone"
    },
    {
      "x": -9,
      "y": -1,
      "z": -14,
      "name": "Soil_Sand_White"
    },
    {
      "x": -9,
      "y": -3,
      "z": -13,
      "name": "Rock_Sandstone"
    },
    {
      "x": -9,
      "y": -2,
      "z": -13,
      "name": "Rock_Sandstone"
    },
    {
      "x": -9,
      "y": -1,
      "z": -13,
      "name": "Soil_Sand_White"
    },
    {
      "x": -9,
      "y": -3,
      "z": -12,
      "name": "Rock_Sandstone"
    },
    {
      "x": -9,
      "y": -2,
      "z": -12,
      "name": "Rock_Sandstone"
    },
    {
      "x": -9,
      "y": -1,
      "z": -12,
      "name": "Soil_Sand_White"
    },
    {
      "x": -9,
      "y": 0,
      "z": -12,
      "name": "Soil_Sand_White"
    },
    {
      "x": -9,
      "y": -3,
      "z": -11,
      "name": "Rock_Sandstone"
    },
    {
      "x": -9,
      "y": -2,
      "z": -11,
      "name": "Rock_Sandstone"
    },
    {
      "x": -9,
      "y": -1,
      "z": -11,
      "name": "Soil_Sand_White"
    },
    {
      "x": -9,
      "y": 0,
      "z": -11,
      "name": "Soil_Sand_White"
    },
    {
      "x": -9,
      "y": -3,
      "z": -10,
      "name": "Rock_Sandstone"
    },
    {
      "x": -9,
      "y": -2,
      "z": -10,
      "name": "Rock_Sandstone"
    },
    {
      "x": -9,
      "y": -1,
      "z": -10,
      "name": "Soil_Sand_White"
    },
    {
      "x": -9,
      "y": -3,
      "z": -9,
      "name": "Rock_Sandstone"
    },
    {
      "x": -9,
      "y": -2,
      "z": -9,
      "name": "Rock_Sandstone"
    },
    {
      "x": -9,
      "y": -1,
      "z": -9,
      "name": "Soil_Sand_White"
    },
    {
      "x": -9,
      "y": -3,
      "z": -8,
      "name": "Rock_Sandstone"
    },
    {
      "x": -9,
      "y": -2,
      "z": -8,
      "name": "Rock_Sandstone"
    },
    {
      "x": -9,
      "y": -1,
      "z": -8,
      "name": "Soil_Sand_White"
    },
    {
      "x": -9,
      "y": -3,
      "z": -7,
      "name": "Rock_Sandstone"
    },
    {
      "x": -9,
      "y": -2,
      "z": -7,
      "name": "Soil_Sand_White"
    },
    {
      "x": -9,
      "y": -3,
      "z": -6,
      "name": "Rock_Sandstone"
    },
    {
      "x": -9,
      "y": -2,
      "z": -6,
      "name": "Rock_Sandstone"
    },
    {
      "x": -9,
      "y": -1,
      "z": -6,
      "name": "Soil_Sand_White"
    },
    {
      "x": -9,
      "y": -3,
      "z": -5,
      "name": "Rock_Sandstone"
    },
    {
      "x": -9,
      "y": -2,
      "z": -5,
      "name": "Rock_Sandstone"
    },
    {
      "x": -9,
      "y": -1,
      "z": -5,
      "name": "Soil_Sand_White"
    },
    {
      "x": -9,
      "y": -3,
      "z": -4,
      "name": "Rock_Sandstone"
    },
    {
      "x": -9,
      "y": -2,
      "z": -4,
      "name": "Soil_Sand_White"
    },
    {
      "x": -9,
      "y": -3,
      "z": -3,
      "name": "Rock_Sandstone"
    },
    {
      "x": -9,
      "y": -2,
      "z": -3,
      "name": "Soil_Sand_White"
    },
    {
      "x": -9,
      "y": -3,
      "z": -2,
      "name": "Rock_Sandstone"
    },
    {
      "x": -9,
      "y": -2,
      "z": -2,
      "name": "Soil_Sand_White"
    },
    {
      "x": -9,
      "y": -3,
      "z": -1,
      "name": "Rock_Sandstone"
    },
    {
      "x": -9,
      "y": -2,
      "z": -1,
      "name": "Rock_Sandstone"
    },
    {
      "x": -9,
      "y": -1,
      "z": -1,
      "name": "Soil_Sand_White"
    },
    {
      "x": -9,
      "y": -3,
      "z": 0,
      "name": "Rock_Sandstone"
    },
    {
      "x": -9,
      "y": -2,
      "z": 0,
      "name": "Rock_Sandstone"
    },
    {
      "x": -9,
      "y": -1,
      "z": 0,
      "name": "Soil_Sand_White"
    },
    {
      "x": -9,
      "y": -3,
      "z": 1,
      "name": "Rock_Sandstone"
    },
    {
      "x": -9,
      "y": -2,
      "z": 1,
      "name": "Soil_Sand_White"
    },
    {
      "x": -9,
      "y": -3,
      "z": 2,
      "name": "Rock_Sandstone"
    },
    {
      "x": -9,
      "y": -2,
      "z": 2,
      "name": "Soil_Sand_White"
    },
    {
      "x": -9,
      "y": -3,
      "z": 3,
      "name": "Soil_Sand_White"
    },
    {
      "x": -8,
      "y": -3,
      "z": -22,
      "name": "Soil_Sand_White"
    },
    {
      "x": -8,
      "y": -3,
      "z": -21,
      "name": "Rock_Sandstone"
    },
    {
      "x": -8,
      "y": -2,
      "z": -21,
      "name": "Soil_Sand_White"
    },
    {
      "x": -8,
      "y": -3,
      "z": -20,
      "name": "Rock_Sandstone"
    },
    {
      "x": -8,
      "y": -2,
      "z": -20,
      "name": "Soil_Sand_White"
    },
    {
      "x": -8,
      "y": -3,
      "z": -19,
      "name": "Rock_Sandstone"
    },
    {
      "x": -8,
      "y": -2,
      "z": -19,
      "name": "Rock_Sandstone"
    },
    {
      "x": -8,
      "y": -1,
      "z": -19,
      "name": "Soil_Sand_White"
    },
    {
      "x": -8,
      "y": -3,
      "z": -18,
      "name": "Rock_Sandstone"
    },
    {
      "x": -8,
      "y": -2,
      "z": -18,
      "name": "Rock_Sandstone"
    },
    {
      "x": -8,
      "y": -1,
      "z": -18,
      "name": "Soil_Sand_White"
    },
    {
      "x": -8,
      "y": -3,
      "z": -17,
      "name": "Rock_Sandstone"
    },
    {
      "x": -8,
      "y": -2,
      "z": -17,
      "name": "Rock_Sandstone"
    },
    {
      "x": -8,
      "y": -1,
      "z": -17,
      "name": "Soil_Sand_White"
    },
    {
      "x": -8,
      "y": -3,
      "z": -16,
      "name": "Rock_Sandstone"
    },
    {
      "x": -8,
      "y": -2,
      "z": -16,
      "name": "Rock_Sandstone"
    },
    {
      "x": -8,
      "y": -1,
      "z": -16,
      "name": "Soil_Sand_White"
    },
    {
      "x": -8,
      "y": -3,
      "z": -15,
      "name": "Rock_Sandstone"
    },
    {
      "x": -8,
      "y": -2,
      "z": -15,
      "name": "Rock_Sandstone"
    },
    {
      "x": -8,
      "y": -1,
      "z": -15,
      "name": "Soil_Sand_White"
    },
    {
      "x": -8,
      "y": -3,
      "z": -14,
      "name": "Rock_Sandstone"
    },
    {
      "x": -8,
      "y": -2,
      "z": -14,
      "name": "Rock_Sandstone"
    },
    {
      "x": -8,
      "y": -1,
      "z": -14,
      "name": "Soil_Sand_White"
    },
    {
      "x": -8,
      "y": 0,
      "z": -14,
      "name": "Soil_Sand_White"
    },
    {
      "x": -8,
      "y": -3,
      "z": -13,
      "name": "Rock_Sandstone"
    },
    {
      "x": -8,
      "y": -2,
      "z": -13,
      "name": "Rock_Sandstone"
    },
    {
      "x": -8,
      "y": -1,
      "z": -13,
      "name": "Soil_Sand_White"
    },
    {
      "x": -8,
      "y": 0,
      "z": -13,
      "name": "Soil_Sand_White"
    },
    {
      "x": -8,
      "y": -3,
      "z": -12,
      "name": "Rock_Sandstone"
    },
    {
      "x": -8,
      "y": -2,
      "z": -12,
      "name": "Rock_Sandstone"
    },
    {
      "x": -8,
      "y": -1,
      "z": -12,
      "name": "Soil_Sand_White"
    },
    {
      "x": -8,
      "y": 0,
      "z": -12,
      "name": "Soil_Sand_White"
    },
    {
      "x": -8,
      "y": -3,
      "z": -11,
      "name": "Rock_Sandstone"
    },
    {
      "x": -8,
      "y": -2,
      "z": -11,
      "name": "Rock_Sandstone"
    },
    {
      "x": -8,
      "y": -1,
      "z": -11,
      "name": "Soil_Sand_White"
    },
    {
      "x": -8,
      "y": 0,
      "z": -11,
      "name": "Soil_Sand_White"
    },
    {
      "x": -8,
      "y": -3,
      "z": -10,
      "name": "Rock_Sandstone"
    },
    {
      "x": -8,
      "y": -2,
      "z": -10,
      "name": "Rock_Sandstone"
    },
    {
      "x": -8,
      "y": -1,
      "z": -10,
      "name": "Soil_Sand_White"
    },
    {
      "x": -8,
      "y": 0,
      "z": -10,
      "name": "Soil_Sand_White"
    },
    {
      "x": -8,
      "y": -3,
      "z": -9,
      "name": "Rock_Sandstone"
    },
    {
      "x": -8,
      "y": -2,
      "z": -9,
      "name": "Rock_Sandstone"
    },
    {
      "x": -8,
      "y": -1,
      "z": -9,
      "name": "Soil_Sand_White"
    },
    {
      "x": -8,
      "y": -3,
      "z": -8,
      "name": "Rock_Sandstone"
    },
    {
      "x": -8,
      "y": -2,
      "z": -8,
      "name": "Rock_Sandstone"
    },
    {
      "x": -8,
      "y": -1,
      "z": -8,
      "name": "Soil_Sand_White"
    },
    {
      "x": -8,
      "y": -3,
      "z": -7,
      "name": "Rock_Sandstone"
    },
    {
      "x": -8,
      "y": -2,
      "z": -7,
      "name": "Rock_Sandstone"
    },
    {
      "x": -8,
      "y": -1,
      "z": -7,
      "name": "Soil_Sand_White"
    },
    {
      "x": -8,
      "y": -3,
      "z": -6,
      "name": "Rock_Sandstone"
    },
    {
      "x": -8,
      "y": -2,
      "z": -6,
      "name": "Rock_Sandstone"
    },
    {
      "x": -8,
      "y": -1,
      "z": -6,
      "name": "Soil_Sand_White"
    },
    {
      "x": -8,
      "y": -3,
      "z": -5,
      "name": "Rock_Sandstone"
    },
    {
      "x": -8,
      "y": -2,
      "z": -5,
      "name": "Rock_Sandstone"
    },
    {
      "x": -8,
      "y": -1,
      "z": -5,
      "name": "Soil_Sand_White"
    },
    {
      "x": -8,
      "y": -3,
      "z": -4,
      "name": "Rock_Sandstone"
    },
    {
      "x": -8,
      "y": -2,
      "z": -4,
      "name": "Rock_Sandstone"
    },
    {
      "x": -8,
      "y": -1,
      "z": -4,
      "name": "Soil_Sand_White"
    },
    {
      "x": -8,
      "y": -3,
      "z": -3,
      "name": "Rock_Sandstone"
    },
    {
      "x": -8,
      "y": -2,
      "z": -3,
      "name": "Rock_Sandstone"
    },
    {
      "x": -8,
      "y": -1,
      "z": -3,
      "name": "Soil_Sand_White"
    },
    {
      "x": -8,
      "y": -3,
      "z": -2,
      "name": "Rock_Sandstone"
    },
    {
      "x": -8,
      "y": -2,
      "z": -2,
      "name": "Rock_Sandstone"
    },
    {
      "x": -8,
      "y": -1,
      "z": -2,
      "name": "Soil_Sand_White"
    },
    {
      "x": -8,
      "y": -3,
      "z": -1,
      "name": "Rock_Sandstone"
    },
    {
      "x": -8,
      "y": -2,
      "z": -1,
      "name": "Rock_Sandstone"
    },
    {
      "x": -8,
      "y": -1,
      "z": -1,
      "name": "Soil_Sand_White"
    },
    {
      "x": -8,
      "y": -3,
      "z": 0,
      "name": "Rock_Sandstone"
    },
    {
      "x": -8,
      "y": -2,
      "z": 0,
      "name": "Rock_Sandstone"
    },
    {
      "x": -8,
      "y": -1,
      "z": 0,
      "name": "Soil_Sand_White"
    },
    {
      "x": -8,
      "y": -3,
      "z": 1,
      "name": "Rock_Sandstone"
    },
    {
      "x": -8,
      "y": -2,
      "z": 1,
      "name": "Rock_Sandstone"
    },
    {
      "x": -8,
      "y": -1,
      "z": 1,
      "name": "Soil_Sand_White"
    },
    {
      "x": -8,
      "y": -3,
      "z": 2,
      "name": "Rock_Sandstone"
    },
    {
      "x": -8,
      "y": -2,
      "z": 2,
      "name": "Soil_Sand_White"
    },
    {
      "x": -8,
      "y": -3,
      "z": 3,
      "name": "Rock_Sandstone"
    },
    {
      "x": -8,
      "y": -2,
      "z": 3,
      "name": "Soil_Sand_White"
    },
    {
      "x": -8,
      "y": -3,
      "z": 4,
      "name": "Soil_Sand_White"
    },
    {
      "x": -7,
      "y": -3,
      "z": -23,
      "name": "Soil_Sand_White"
    },
    {
      "x": -7,
      "y": -3,
      "z": -22,
      "name": "Rock_Sandstone"
    },
    {
      "x": -7,
      "y": -2,
      "z": -22,
      "name": "Soil_Sand_White"
    },
    {
      "x": -7,
      "y": -3,
      "z": -21,
      "name": "Rock_Sandstone"
    },
    {
      "x": -7,
      "y": -2,
      "z": -21,
      "name": "Rock_Sandstone"
    },
    {
      "x": -7,
      "y": -1,
      "z": -21,
      "name": "Soil_Sand_White"
    },
    {
      "x": -7,
      "y": -3,
      "z": -20,
      "name": "Rock_Sandstone"
    },
    {
      "x": -7,
      "y": -2,
      "z": -20,
      "name": "Rock_Sandstone"
    },
    {
      "x": -7,
      "y": -1,
      "z": -20,
      "name": "Soil_Sand_White"
    },
    {
      "x": -7,
      "y": -3,
      "z": -19,
      "name": "Rock_Sandstone"
    },
    {
      "x": -7,
      "y": -2,
      "z": -19,
      "name": "Rock_Sandstone"
    },
    {
      "x": -7,
      "y": -1,
      "z": -19,
      "name": "Soil_Sand_White"
    },
    {
      "x": -7,
      "y": -3,
      "z": -18,
      "name": "Rock_Sandstone"
    },
    {
      "x": -7,
      "y": -2,
      "z": -18,
      "name": "Rock_Sandstone"
    },
    {
      "x": -7,
      "y": -1,
      "z": -18,
      "name": "Soil_Sand_White"
    },
    {
      "x": -7,
      "y": -3,
      "z": -17,
      "name": "Rock_Sandstone"
    },
    {
      "x": -7,
      "y": -2,
      "z": -17,
      "name": "Rock_Sandstone"
    },
    {
      "x": -7,
      "y": -1,
      "z": -17,
      "name": "Rock_Sandstone"
    },
    {
      "x": -7,
      "y": 0,
      "z": -17,
      "name": "Soil_Sand_White"
    },
    {
      "x": -7,
      "y": -3,
      "z": -16,
      "name": "Rock_Sandstone"
    },
    {
      "x": -7,
      "y": -2,
      "z": -16,
      "name": "Rock_Sandstone"
    },
    {
      "x": -7,
      "y": -1,
      "z": -16,
      "name": "Rock_Sandstone"
    },
    {
      "x": -7,
      "y": 0,
      "z": -16,
      "name": "Soil_Sand_White"
    },
    {
      "x": -7,
      "y": -3,
      "z": -15,
      "name": "Rock_Sandstone"
    },
    {
      "x": -7,
      "y": -2,
      "z": -15,
      "name": "Rock_Sandstone"
    },
    {
      "x": -7,
      "y": -1,
      "z": -15,
      "name": "Rock_Sandstone"
    },
    {
      "x": -7,
      "y": 0,
      "z": -15,
      "name": "Soil_Sand_White"
    },
    {
      "x": -7,
      "y": -2,
      "z": -14,
      "name": "Rock_Sandstone"
    },
    {
      "x": -7,
      "y": -1,
      "z": -14,
      "name": "Soil_Sand_White"
    },
    {
      "x": -7,
      "y": 0,
      "z": -14,
      "name": "Soil_Sand_White"
    },
    {
      "x": -7,
      "y": -2,
      "z": -13,
      "name": "Rock_Sandstone"
    },
    {
      "x": -7,
      "y": -1,
      "z": -13,
      "name": "Rock_Sandstone"
    },
    {
      "x": -7,
      "y": 0,
      "z": -13,
      "name": "Soil_Sand_White"
    },
    {
      "x": -7,
      "y": -2,
      "z": -12,
      "name": "Rock_Sandstone"
    },
    {
      "x": -7,
      "y": -1,
      "z": -12,
      "name": "Soil_Sand_White"
    },
    {
      "x": -7,
      "y": 0,
      "z": -12,
      "name": "Soil_Sand_White"
    },
    {
      "x": -7,
      "y": 1,
      "z": -12,
      "name": "Soil_Sand_White"
    },
    {
      "x": -7,
      "y": -2,
      "z": -11,
      "name": "Rock_Sandstone"
    },
    {
      "x": -7,
      "y": -1,
      "z": -11,
      "name": "Soil_Sand_White"
    },
    {
      "x": -7,
      "y": 0,
      "z": -11,
      "name": "Soil_Sand_White"
    },
    {
      "x": -7,
      "y": 1,
      "z": -11,
      "name": "Soil_Sand_White"
    },
    {
      "x": -7,
      "y": -2,
      "z": -10,
      "name": "Rock_Sandstone"
    },
    {
      "x": -7,
      "y": -1,
      "z": -10,
      "name": "Soil_Sand_White"
    },
    {
      "x": -7,
      "y": 0,
      "z": -10,
      "name": "Soil_Sand_White"
    },
    {
      "x": -7,
      "y": -2,
      "z": -9,
      "name": "Rock_Sandstone"
    },
    {
      "x": -7,
      "y": -1,
      "z": -9,
      "name": "Soil_Sand_White"
    },
    {
      "x": -7,
      "y": 0,
      "z": -9,
      "name": "Soil_Sand_White"
    },
    {
      "x": -7,
      "y": -3,
      "z": -8,
      "name": "Rock_Sandstone"
    },
    {
      "x": -7,
      "y": -2,
      "z": -8,
      "name": "Rock_Sandstone"
    },
    {
      "x": -7,
      "y": -1,
      "z": -8,
      "name": "Rock_Sandstone"
    },
    {
      "x": -7,
      "y": 0,
      "z": -8,
      "name": "Soil_Sand_White"
    },
    {
      "x": -7,
      "y": -3,
      "z": -7,
      "name": "Rock_Sandstone"
    },
    {
      "x": -7,
      "y": -2,
      "z": -7,
      "name": "Rock_Sandstone"
    },
    {
      "x": -7,
      "y": -1,
      "z": -7,
      "name": "Rock_Sandstone"
    },
    {
      "x": -7,
      "y": 0,
      "z": -7,
      "name": "Soil_Sand_White"
    },
    {
      "x": -7,
      "y": -2,
      "z": -6,
      "name": "Rock_Sandstone"
    },
    {
      "x": -7,
      "y": -1,
      "z": -6,
      "name": "Soil_Sand_White"
    },
    {
      "x": -7,
      "y": -2,
      "z": -5,
      "name": "Rock_Sandstone"
    },
    {
      "x": -7,
      "y": -1,
      "z": -5,
      "name": "Soil_Sand_White"
    },
    {
      "x": -7,
      "y": -2,
      "z": -4,
      "name": "Rock_Sandstone"
    },
    {
      "x": -7,
      "y": -1,
      "z": -4,
      "name": "Soil_Sand_White"
    },
    {
      "x": -7,
      "y": -2,
      "z": -3,
      "name": "Rock_Sandstone"
    },
    {
      "x": -7,
      "y": -1,
      "z": -3,
      "name": "Soil_Sand_White"
    },
    {
      "x": -7,
      "y": -2,
      "z": -2,
      "name": "Rock_Sandstone"
    },
    {
      "x": -7,
      "y": -1,
      "z": -2,
      "name": "Soil_Sand_White"
    },
    {
      "x": -7,
      "y": -2,
      "z": -1,
      "name": "Rock_Sandstone"
    },
    {
      "x": -7,
      "y": -1,
      "z": -1,
      "name": "Soil_Sand_White"
    },
    {
      "x": -7,
      "y": -3,
      "z": 0,
      "name": "Rock_Sandstone"
    },
    {
      "x": -7,
      "y": -2,
      "z": 0,
      "name": "Rock_Sandstone"
    },
    {
      "x": -7,
      "y": -1,
      "z": 0,
      "name": "Soil_Sand_White"
    },
    {
      "x": -7,
      "y": -3,
      "z": 1,
      "name": "Rock_Sandstone"
    },
    {
      "x": -7,
      "y": -2,
      "z": 1,
      "name": "Rock_Sandstone"
    },
    {
      "x": -7,
      "y": -1,
      "z": 1,
      "name": "Soil_Sand_White"
    },
    {
      "x": -7,
      "y": -3,
      "z": 2,
      "name": "Rock_Sandstone"
    },
    {
      "x": -7,
      "y": -2,
      "z": 2,
      "name": "Rock_Sandstone"
    },
    {
      "x": -7,
      "y": -1,
      "z": 2,
      "name": "Soil_Sand_White"
    },
    {
      "x": -7,
      "y": -3,
      "z": 3,
      "name": "Rock_Sandstone"
    },
    {
      "x": -7,
      "y": -2,
      "z": 3,
      "name": "Soil_Sand_White"
    },
    {
      "x": -7,
      "y": -3,
      "z": 4,
      "name": "Rock_Sandstone"
    },
    {
      "x": -7,
      "y": -2,
      "z": 4,
      "name": "Soil_Sand_White"
    },
    {
      "x": -7,
      "y": -3,
      "z": 5,
      "name": "Soil_Sand_White"
    },
    {
      "x": -6,
      "y": -3,
      "z": -24,
      "name": "Soil_Sand_White"
    },
    {
      "x": -6,
      "y": -3,
      "z": -23,
      "name": "Rock_Sandstone"
    },
    {
      "x": -6,
      "y": -2,
      "z": -23,
      "name": "Soil_Sand_White"
    },
    {
      "x": -6,
      "y": -3,
      "z": -22,
      "name": "Rock_Sandstone"
    },
    {
      "x": -6,
      "y": -2,
      "z": -22,
      "name": "Soil_Sand_White"
    },
    {
      "x": -6,
      "y": -3,
      "z": -21,
      "name": "Rock_Sandstone"
    },
    {
      "x": -6,
      "y": -2,
      "z": -21,
      "name": "Rock_Sandstone"
    },
    {
      "x": -6,
      "y": -1,
      "z": -21,
      "name": "Soil_Sand_White"
    },
    {
      "x": -6,
      "y": -3,
      "z": -20,
      "name": "Rock_Sandstone"
    },
    {
      "x": -6,
      "y": -2,
      "z": -20,
      "name": "Rock_Sandstone"
    },
    {
      "x": -6,
      "y": -1,
      "z": -20,
      "name": "Soil_Sand_White"
    },
    {
      "x": -6,
      "y": -3,
      "z": -19,
      "name": "Rock_Sandstone"
    },
    {
      "x": -6,
      "y": -2,
      "z": -19,
      "name": "Rock_Sandstone"
    },
    {
      "x": -6,
      "y": -1,
      "z": -19,
      "name": "Soil_Sand_White"
    },
    {
      "x": -6,
      "y": -3,
      "z": -18,
      "name": "Rock_Sandstone"
    },
    {
      "x": -6,
      "y": -2,
      "z": -18,
      "name": "Rock_Sandstone"
    },
    {
      "x": -6,
      "y": -1,
      "z": -18,
      "name": "Rock_Sandstone"
    },
    {
      "x": -6,
      "y": 0,
      "z": -18,
      "name": "Soil_Sand_White"
    },
    {
      "x": -6,
      "y": -3,
      "z": -17,
      "name": "Rock_Sandstone"
    },
    {
      "x": -6,
      "y": -2,
      "z": -17,
      "name": "Rock_Sandstone"
    },
    {
      "x": -6,
      "y": -1,
      "z": -17,
      "name": "Rock_Sandstone"
    },
    {
      "x": -6,
      "y": 0,
      "z": -17,
      "name": "Soil_Sand_White"
    },
    {
      "x": -6,
      "y": 1,
      "z": -17,
      "name": "Soil_Sand_White"
    },
    {
      "x": -6,
      "y": -3,
      "z": -16,
      "name": "Rock_Sandstone"
    },
    {
      "x": -6,
      "y": -2,
      "z": -16,
      "name": "Rock_Sandstone"
    },
    {
      "x": -6,
      "y": -1,
      "z": -16,
      "name": "Rock_Sandstone"
    },
    {
      "x": -6,
      "y": 0,
      "z": -16,
      "name": "Soil_Sand_White"
    },
    {
      "x": -6,
      "y": 1,
      "z": -16,
      "name": "Soil_Sand_White"
    },
    {
      "x": -6,
      "y": -2,
      "z": -15,
      "name": "Rock_Sandstone"
    },
    {
      "x": -6,
      "y": -1,
      "z": -15,
      "name": "Rock_Sandstone"
    },
    {
      "x": -6,
      "y": 0,
      "z": -15,
      "name": "Soil_Sand_White"
    },
    {
      "x": -6,
      "y": 1,
      "z": -15,
      "name": "Soil_Sand_White"
    },
    {
      "x": -6,
      "y": -2,
      "z": -14,
      "name": "Rock_Sandstone"
    },
    {
      "x": -6,
      "y": -1,
      "z": -14,
      "name": "Rock_Sandstone"
    },
    {
      "x": -6,
      "y": 0,
      "z": -14,
      "name": "Soil_Sand_White"
    },
    {
      "x": -6,
      "y": 1,
      "z": -14,
      "name": "Soil_Sand_White"
    },
    {
      "x": -6,
      "y": -2,
      "z": -13,
      "name": "Rock_Sandstone"
    },
    {
      "x": -6,
      "y": -1,
      "z": -13,
      "name": "Rock_Sandstone"
    },
    {
      "x": -6,
      "y": 0,
      "z": -13,
      "name": "Soil_Sand_White"
    },
    {
      "x": -6,
      "y": 1,
      "z": -13,
      "name": "Soil_Sand_White"
    },
    {
      "x": -6,
      "y": -2,
      "z": -12,
      "name": "Rock_Sandstone"
    },
    {
      "x": -6,
      "y": -1,
      "z": -12,
      "name": "Rock_Sandstone"
    },
    {
      "x": -6,
      "y": 0,
      "z": -12,
      "name": "Soil_Sand_White"
    },
    {
      "x": -6,
      "y": 1,
      "z": -12,
      "name": "Soil_Sand_White"
    },
    {
      "x": -6,
      "y": -1,
      "z": -11,
      "name": "Rock_Sandstone"
    },
    {
      "x": -6,
      "y": 0,
      "z": -11,
      "name": "Soil_Sand_White"
    },
    {
      "x": -6,
      "y": 1,
      "z": -11,
      "name": "Soil_Sand_White"
    },
    {
      "x": -6,
      "y": -1,
      "z": -10,
      "name": "Rock_Sandstone"
    },
    {
      "x": -6,
      "y": 0,
      "z": -10,
      "name": "Soil_Sand_White"
    },
    {
      "x": -6,
      "y": 1,
      "z": -10,
      "name": "Soil_Sand_White"
    },
    {
      "x": -6,
      "y": -1,
      "z": -9,
      "name": "Rock_Sandstone"
    },
    {
      "x": -6,
      "y": 0,
      "z": -9,
      "name": "Soil_Sand_White"
    },
    {
      "x": -6,
      "y": 1,
      "z": -9,
      "name": "Soil_Sand_White"
    },
    {
      "x": -6,
      "y": -2,
      "z": -8,
      "name": "Rock_Sandstone"
    },
    {
      "x": -6,
      "y": -1,
      "z": -8,
      "name": "Rock_Sandstone"
    },
    {
      "x": -6,
      "y": 0,
      "z": -8,
      "name": "Soil_Sand_White"
    },
    {
      "x": -6,
      "y": 1,
      "z": -8,
      "name": "Soil_Sand_White"
    },
    {
      "x": -6,
      "y": -2,
      "z": -7,
      "name": "Rock_Sandstone"
    },
    {
      "x": -6,
      "y": -1,
      "z": -7,
      "name": "Rock_Sandstone"
    },
    {
      "x": -6,
      "y": 0,
      "z": -7,
      "name": "Soil_Sand_White"
    },
    {
      "x": -6,
      "y": 1,
      "z": -7,
      "name": "Soil_Sand_White"
    },
    {
      "x": -6,
      "y": -1,
      "z": -6,
      "name": "Rock_Sandstone"
    },
    {
      "x": -6,
      "y": 0,
      "z": -6,
      "name": "Soil_Sand_White"
    },
    {
      "x": -6,
      "y": -1,
      "z": -5,
      "name": "Rock_Sandstone"
    },
    {
      "x": -6,
      "y": 0,
      "z": -5,
      "name": "Soil_Sand_White"
    },
    {
      "x": -6,
      "y": -1,
      "z": -4,
      "name": "Rock_Sandstone"
    },
    {
      "x": -6,
      "y": 0,
      "z": -4,
      "name": "Soil_Sand_White"
    },
    {
      "x": -6,
      "y": -2,
      "z": -3,
      "name": "Rock_Sandstone"
    },
    {
      "x": -6,
      "y": -1,
      "z": -3,
      "name": "Rock_Sandstone"
    },
    {
      "x": -6,
      "y": 0,
      "z": -3,
      "name": "Soil_Sand_White"
    },
    {
      "x": -6,
      "y": -2,
      "z": -2,
      "name": "Rock_Sandstone"
    },
    {
      "x": -6,
      "y": -1,
      "z": -2,
      "name": "Rock_Sandstone"
    },
    {
      "x": -6,
      "y": 0,
      "z": -2,
      "name": "Soil_Sand_White"
    },
    {
      "x": -6,
      "y": -2,
      "z": -1,
      "name": "Rock_Sandstone"
    },
    {
      "x": -6,
      "y": -1,
      "z": -1,
      "name": "Soil_Sand_White"
    },
    {
      "x": -6,
      "y": -2,
      "z": 0,
      "name": "Rock_Sandstone"
    },
    {
      "x": -6,
      "y": -1,
      "z": 0,
      "name": "Soil_Sand_White"
    },
    {
      "x": -6,
      "y": -3,
      "z": 1,
      "name": "Rock_Sandstone"
    },
    {
      "x": -6,
      "y": -2,
      "z": 1,
      "name": "Rock_Sandstone"
    },
    {
      "x": -6,
      "y": -1,
      "z": 1,
      "name": "Soil_Sand_White"
    },
    {
      "x": -6,
      "y": -3,
      "z": 2,
      "name": "Rock_Sandstone"
    },
    {
      "x": -6,
      "y": -2,
      "z": 2,
      "name": "Soil_Sand_White"
    },
    {
      "x": -6,
      "y": -1,
      "z": 2,
      "name": "Soil_Sand_White"
    },
    {
      "x": -6,
      "y": -3,
      "z": 3,
      "name": "Rock_Sandstone"
    },
    {
      "x": -6,
      "y": -2,
      "z": 3,
      "name": "Soil_Sand_White"
    },
    {
      "x": -6,
      "y": -1,
      "z": 3,
      "name": "Soil_Sand_White"
    },
    {
      "x": -6,
      "y": -3,
      "z": 4,
      "name": "Rock_Sandstone"
    },
    {
      "x": -6,
      "y": -2,
      "z": 4,
      "name": "Soil_Sand_White"
    },
    {
      "x": -6,
      "y": -3,
      "z": 5,
      "name": "Rock_Sandstone"
    },
    {
      "x": -6,
      "y": -2,
      "z": 5,
      "name": "Soil_Sand_White"
    },
    {
      "x": -6,
      "y": -3,
      "z": 6,
      "name": "Soil_Sand_White"
    },
    {
      "x": -5,
      "y": -3,
      "z": -24,
      "name": "Soil_Sand_White"
    },
    {
      "x": -5,
      "y": -3,
      "z": -23,
      "name": "Rock_Sandstone"
    },
    {
      "x": -5,
      "y": -2,
      "z": -23,
      "name": "Soil_Sand_White"
    },
    {
      "x": -5,
      "y": -3,
      "z": -22,
      "name": "Rock_Sandstone"
    },
    {
      "x": -5,
      "y": -2,
      "z": -22,
      "name": "Soil_Sand_White"
    },
    {
      "x": -5,
      "y": -3,
      "z": -21,
      "name": "Rock_Sandstone"
    },
    {
      "x": -5,
      "y": -2,
      "z": -21,
      "name": "Rock_Sandstone"
    },
    {
      "x": -5,
      "y": -1,
      "z": -21,
      "name": "Soil_Sand_White"
    },
    {
      "x": -5,
      "y": -3,
      "z": -20,
      "name": "Rock_Sandstone"
    },
    {
      "x": -5,
      "y": -2,
      "z": -20,
      "name": "Rock_Sandstone"
    },
    {
      "x": -5,
      "y": -1,
      "z": -20,
      "name": "Soil_Sand_White"
    },
    {
      "x": -5,
      "y": -3,
      "z": -19,
      "name": "Rock_Sandstone"
    },
    {
      "x": -5,
      "y": -2,
      "z": -19,
      "name": "Rock_Sandstone"
    },
    {
      "x": -5,
      "y": -1,
      "z": -19,
      "name": "Soil_Sand_White"
    },
    {
      "x": -5,
      "y": 0,
      "z": -19,
      "name": "Soil_Sand_White"
    },
    {
      "x": -5,
      "y": -3,
      "z": -18,
      "name": "Rock_Sandstone"
    },
    {
      "x": -5,
      "y": -2,
      "z": -18,
      "name": "Rock_Sandstone"
    },
    {
      "x": -5,
      "y": -1,
      "z": -18,
      "name": "Rock_Sandstone"
    },
    {
      "x": -5,
      "y": 0,
      "z": -18,
      "name": "Soil_Sand_White"
    },
    {
      "x": -5,
      "y": 1,
      "z": -18,
      "name": "Soil_Sand_White"
    },
    {
      "x": -5,
      "y": -2,
      "z": -17,
      "name": "Rock_Sandstone"
    },
    {
      "x": -5,
      "y": -1,
      "z": -17,
      "name": "Rock_Sandstone"
    },
    {
      "x": -5,
      "y": 0,
      "z": -17,
      "name": "Soil_Sand_White"
    },
    {
      "x": -5,
      "y": 1,
      "z": -17,
      "name": "Soil_Sand_White"
    },
    {
      "x": -5,
      "y": -2,
      "z": -16,
      "name": "Rock_Sandstone"
    },
    {
      "x": -5,
      "y": -1,
      "z": -16,
      "name": "Rock_Sandstone"
    },
    {
      "x": -5,
      "y": 0,
      "z": -16,
      "name": "Soil_Sand_White"
    },
    {
      "x": -5,
      "y": 1,
      "z": -16,
      "name": "Soil_Sand_White"
    },
    {
      "x": -5,
      "y": -2,
      "z": -15,
      "name": "Rock_Sandstone"
    },
    {
      "x": -5,
      "y": -1,
      "z": -15,
      "name": "Rock_Sandstone"
    },
    {
      "x": -5,
      "y": 0,
      "z": -15,
      "name": "Soil_Sand_White"
    },
    {
      "x": -5,
      "y": 1,
      "z": -15,
      "name": "Soil_Sand_White"
    },
    {
      "x": -5,
      "y": -2,
      "z": -14,
      "name": "Rock_Sandstone"
    },
    {
      "x": -5,
      "y": -1,
      "z": -14,
      "name": "Rock_Sandstone"
    },
    {
      "x": -5,
      "y": 0,
      "z": -14,
      "name": "Soil_Sand_White"
    },
    {
      "x": -5,
      "y": 1,
      "z": -14,
      "name": "Soil_Sand_White"
    },
    {
      "x": -5,
      "y": 2,
      "z": -14,
      "name": "Soil_Sand_White"
    },
    {
      "x": -5,
      "y": -2,
      "z": -13,
      "name": "Rock_Sandstone"
    },
    {
      "x": -5,
      "y": -1,
      "z": -13,
      "name": "Rock_Sandstone"
    },
    {
      "x": -5,
      "y": 0,
      "z": -13,
      "name": "Soil_Sand_White"
    },
    {
      "x": -5,
      "y": 1,
      "z": -13,
      "name": "Soil_Sand_White"
    },
    {
      "x": -5,
      "y": 2,
      "z": -13,
      "name": "Soil_Sand_White"
    },
    {
      "x": -5,
      "y": -1,
      "z": -12,
      "name": "Rock_Sandstone"
    },
    {
      "x": -5,
      "y": 0,
      "z": -12,
      "name": "Soil_Sand_White"
    },
    {
      "x": -5,
      "y": 1,
      "z": -12,
      "name": "Soil_Sand_White"
    },
    {
      "x": -5,
      "y": 2,
      "z": -12,
      "name": "Soil_Sand_White"
    },
    {
      "x": -5,
      "y": -1,
      "z": -11,
      "name": "Rock_Sandstone"
    },
    {
      "x": -5,
      "y": 0,
      "z": -11,
      "name": "Soil_Sand_White"
    },
    {
      "x": -5,
      "y": 1,
      "z": -11,
      "name": "Soil_Sand_White"
    },
    {
      "x": -5,
      "y": -1,
      "z": -10,
      "name": "Rock_Sandstone"
    },
    {
      "x": -5,
      "y": 0,
      "z": -10,
      "name": "Soil_Sand_White"
    },
    {
      "x": -5,
      "y": 1,
      "z": -10,
      "name": "Soil_Sand_White"
    },
    {
      "x": -5,
      "y": -1,
      "z": -9,
      "name": "Rock_Sandstone"
    },
    {
      "x": -5,
      "y": 0,
      "z": -9,
      "name": "Soil_Sand_White"
    },
    {
      "x": -5,
      "y": 1,
      "z": -9,
      "name": "Soil_Sand_White"
    },
    {
      "x": -5,
      "y": -1,
      "z": -8,
      "name": "Rock_Sandstone"
    },
    {
      "x": -5,
      "y": 0,
      "z": -8,
      "name": "Soil_Sand_White"
    },
    {
      "x": -5,
      "y": 1,
      "z": -8,
      "name": "Soil_Sand_White"
    },
    {
      "x": -5,
      "y": -1,
      "z": -7,
      "name": "Rock_Sandstone"
    },
    {
      "x": -5,
      "y": 0,
      "z": -7,
      "name": "Soil_Sand_White"
    },
    {
      "x": -5,
      "y": 1,
      "z": -7,
      "name": "Soil_Sand_White"
    },
    {
      "x": -5,
      "y": -1,
      "z": -6,
      "name": "Rock_Sandstone"
    },
    {
      "x": -5,
      "y": 0,
      "z": -6,
      "name": "Soil_Sand_White"
    },
    {
      "x": -5,
      "y": -1,
      "z": -5,
      "name": "Rock_Sandstone"
    },
    {
      "x": -5,
      "y": 0,
      "z": -5,
      "name": "Soil_Sand_White"
    },
    {
      "x": -5,
      "y": -1,
      "z": -4,
      "name": "Rock_Sandstone"
    },
    {
      "x": -5,
      "y": 0,
      "z": -4,
      "name": "Soil_Sand_White"
    },
    {
      "x": -5,
      "y": -1,
      "z": -3,
      "name": "Rock_Sandstone"
    },
    {
      "x": -5,
      "y": 0,
      "z": -3,
      "name": "Soil_Sand_White"
    },
    {
      "x": -5,
      "y": -2,
      "z": -2,
      "name": "Rock_Sandstone"
    },
    {
      "x": -5,
      "y": -1,
      "z": -2,
      "name": "Rock_Sandstone"
    },
    {
      "x": -5,
      "y": 0,
      "z": -2,
      "name": "Soil_Sand_White"
    },
    {
      "x": -5,
      "y": -2,
      "z": -1,
      "name": "Rock_Sandstone"
    },
    {
      "x": -5,
      "y": -1,
      "z": -1,
      "name": "Rock_Sandstone"
    },
    {
      "x": -5,
      "y": 0,
      "z": -1,
      "name": "Soil_Sand_White"
    },
    {
      "x": -5,
      "y": -2,
      "z": 0,
      "name": "Rock_Sandstone"
    },
    {
      "x": -5,
      "y": -1,
      "z": 0,
      "name": "Rock_Sandstone"
    },
    {
      "x": -5,
      "y": 0,
      "z": 0,
      "name": "Soil_Sand_White"
    },
    {
      "x": -5,
      "y": -3,
      "z": 1,
      "name": "Rock_Sandstone"
    },
    {
      "x": -5,
      "y": -2,
      "z": 1,
      "name": "Rock_Sandstone"
    },
    {
      "x": -5,
      "y": -1,
      "z": 1,
      "name": "Rock_Sandstone"
    },
    {
      "x": -5,
      "y": 0,
      "z": 1,
      "name": "Soil_Sand_White"
    },
    {
      "x": -5,
      "y": -3,
      "z": 2,
      "name": "Rock_Sandstone"
    },
    {
      "x": -5,
      "y": -2,
      "z": 2,
      "name": "Rock_Sandstone"
    },
    {
      "x": -5,
      "y": -1,
      "z": 2,
      "name": "Soil_Sand_White"
    },
    {
      "x": -5,
      "y": -3,
      "z": 3,
      "name": "Rock_Sandstone"
    },
    {
      "x": -5,
      "y": -2,
      "z": 3,
      "name": "Rock_Sandstone"
    },
    {
      "x": -5,
      "y": -1,
      "z": 3,
      "name": "Soil_Sand_White"
    },
    {
      "x": -5,
      "y": -3,
      "z": 4,
      "name": "Rock_Sandstone"
    },
    {
      "x": -5,
      "y": -2,
      "z": 4,
      "name": "Soil_Sand_White"
    },
    {
      "x": -5,
      "y": -3,
      "z": 5,
      "name": "Rock_Sandstone"
    },
    {
      "x": -5,
      "y": -2,
      "z": 5,
      "name": "Soil_Sand_White"
    },
    {
      "x": -5,
      "y": -3,
      "z": 6,
      "name": "Soil_Sand_White"
    },
    {
      "x": -4,
      "y": -3,
      "z": -24,
      "name": "Soil_Sand_White"
    },
    {
      "x": -4,
      "y": -3,
      "z": -23,
      "name": "Rock_Sandstone"
    },
    {
      "x": -4,
      "y": -2,
      "z": -23,
      "name": "Soil_Sand_White"
    },
    {
      "x": -4,
      "y": -3,
      "z": -22,
      "name": "Rock_Sandstone"
    },
    {
      "x": -4,
      "y": -2,
      "z": -22,
      "name": "Rock_Sandstone"
    },
    {
      "x": -4,
      "y": -1,
      "z": -22,
      "name": "Soil_Sand_White"
    },
    {
      "x": -4,
      "y": -3,
      "z": -21,
      "name": "Rock_Sandstone"
    },
    {
      "x": -4,
      "y": -2,
      "z": -21,
      "name": "Rock_Sandstone"
    },
    {
      "x": -4,
      "y": -1,
      "z": -21,
      "name": "Soil_Sand_White"
    },
    {
      "x": -4,
      "y": -3,
      "z": -20,
      "name": "Rock_Sandstone"
    },
    {
      "x": -4,
      "y": -2,
      "z": -20,
      "name": "Rock_Sandstone"
    },
    {
      "x": -4,
      "y": -1,
      "z": -20,
      "name": "Soil_Sand_White"
    },
    {
      "x": -4,
      "y": 0,
      "z": -20,
      "name": "Soil_Sand_White"
    },
    {
      "x": -4,
      "y": -3,
      "z": -19,
      "name": "Rock_Sandstone"
    },
    {
      "x": -4,
      "y": -2,
      "z": -19,
      "name": "Rock_Sandstone"
    },
    {
      "x": -4,
      "y": -1,
      "z": -19,
      "name": "Rock_Sandstone"
    },
    {
      "x": -4,
      "y": 0,
      "z": -19,
      "name": "Soil_Gravel_Sand_White",
      "support": 15
    },
    {
      "x": -4,
      "y": -2,
      "z": -18,
      "name": "Rock_Sandstone"
    },
    {
      "x": -4,
      "y": -1,
      "z": -18,
      "name": "Rock_Sandstone"
    },
    {
      "x": -4,
      "y": 0,
      "z": -18,
      "name": "Soil_Gravel_Sand_White",
      "support": 15
    },
    {
      "x": -4,
      "y": 1,
      "z": -18,
      "name": "Soil_Sand_White"
    },
    {
      "x": -4,
      "y": -2,
      "z": -17,
      "name": "Rock_Sandstone"
    },
    {
      "x": -4,
      "y": -1,
      "z": -17,
      "name": "Rock_Sandstone"
    },
    {
      "x": -4,
      "y": 0,
      "z": -17,
      "name": "Soil_Sand_White"
    },
    {
      "x": -4,
      "y": 1,
      "z": -17,
      "name": "Soil_Sand_White"
    },
    {
      "x": -4,
      "y": -2,
      "z": -16,
      "name": "Rock_Sandstone"
    },
    {
      "x": -4,
      "y": -1,
      "z": -16,
      "name": "Rock_Sandstone"
    },
    {
      "x": -4,
      "y": 0,
      "z": -16,
      "name": "Soil_Sand_White"
    },
    {
      "x": -4,
      "y": 1,
      "z": -16,
      "name": "Soil_Sand_White"
    },
    {
      "x": -4,
      "y": 2,
      "z": -16,
      "name": "Soil_Sand_White"
    },
    {
      "x": -4,
      "y": -2,
      "z": -15,
      "name": "Rock_Sandstone"
    },
    {
      "x": -4,
      "y": -1,
      "z": -15,
      "name": "Rock_Sandstone"
    },
    {
      "x": -4,
      "y": 0,
      "z": -15,
      "name": "Soil_Sand_White"
    },
    {
      "x": -4,
      "y": 1,
      "z": -15,
      "name": "Soil_Sand_White"
    },
    {
      "x": -4,
      "y": 2,
      "z": -15,
      "name": "Soil_Sand_White"
    },
    {
      "x": -4,
      "y": -2,
      "z": -14,
      "name": "Rock_Sandstone"
    },
    {
      "x": -4,
      "y": -1,
      "z": -14,
      "name": "Rock_Sandstone"
    },
    {
      "x": -4,
      "y": 0,
      "z": -14,
      "name": "Soil_Sand_White"
    },
    {
      "x": -4,
      "y": 1,
      "z": -14,
      "name": "Soil_Sand_White"
    },
    {
      "x": -4,
      "y": 2,
      "z": -14,
      "name": "Soil_Gravel_Sand_White",
      "support": 15
    },
    {
      "x": -4,
      "y": -2,
      "z": -13,
      "name": "Rock_Sandstone"
    },
    {
      "x": -4,
      "y": -1,
      "z": -13,
      "name": "Rock_Sandstone"
    },
    {
      "x": -4,
      "y": 0,
      "z": -13,
      "name": "Soil_Sand_White"
    },
    {
      "x": -4,
      "y": 1,
      "z": -13,
      "name": "Soil_Sand_White"
    },
    {
      "x": -4,
      "y": 2,
      "z": -13,
      "name": "Soil_Sand_White"
    },
    {
      "x": -4,
      "y": -1,
      "z": -12,
      "name": "Rock_Sandstone"
    },
    {
      "x": -4,
      "y": 0,
      "z": -12,
      "name": "Soil_Sand_White"
    },
    {
      "x": -4,
      "y": 1,
      "z": -12,
      "name": "Soil_Sand_White"
    },
    {
      "x": -4,
      "y": -1,
      "z": -11,
      "name": "Rock_Sandstone"
    },
    {
      "x": -4,
      "y": 0,
      "z": -11,
      "name": "Soil_Sand_White"
    },
    {
      "x": -4,
      "y": 1,
      "z": -11,
      "name": "Soil_Sand_White"
    },
    {
      "x": -4,
      "y": -1,
      "z": -10,
      "name": "Rock_Sandstone"
    },
    {
      "x": -4,
      "y": 0,
      "z": -10,
      "name": "Soil_Sand_White"
    },
    {
      "x": -4,
      "y": 1,
      "z": -10,
      "name": "Soil_Sand_White"
    },
    {
      "x": -4,
      "y": 2,
      "z": -10,
      "name": "Metal_Iron_Roof_Flat",
      "rotation": 1
    },
    {
      "x": -4,
      "y": -1,
      "z": -9,
      "name": "Rock_Sandstone"
    },
    {
      "x": -4,
      "y": 0,
      "z": -9,
      "name": "Soil_Sand_White"
    },
    {
      "x": -4,
      "y": 1,
      "z": -9,
      "name": "Soil_Gravel_Sand_White",
      "support": 15
    },
    {
      "x": -4,
      "y": 2,
      "z": -9,
      "name": "Metal_Iron_Roof_Flat",
      "rotation": 1
    },
    {
      "x": -4,
      "y": -1,
      "z": -8,
      "name": "Rock_Sandstone"
    },
    {
      "x": -4,
      "y": 0,
      "z": -8,
      "name": "Soil_Sand_White"
    },
    {
      "x": -4,
      "y": 1,
      "z": -8,
      "name": "Soil_Sand_White"
    },
    {
      "x": -4,
      "y": -1,
      "z": -7,
      "name": "Rock_Sandstone"
    },
    {
      "x": -4,
      "y": 0,
      "z": -7,
      "name": "Soil_Sand_White"
    },
    {
      "x": -4,
      "y": 1,
      "z": -7,
      "name": "Soil_Sand_White"
    },
    {
      "x": -4,
      "y": -1,
      "z": -6,
      "name": "Rock_Sandstone"
    },
    {
      "x": -4,
      "y": 0,
      "z": -6,
      "name": "Soil_Sand_White"
    },
    {
      "x": -4,
      "y": 1,
      "z": -6,
      "name": "Soil_Sand_White"
    },
    {
      "x": -4,
      "y": -1,
      "z": -5,
      "name": "Rock_Sandstone"
    },
    {
      "x": -4,
      "y": 0,
      "z": -5,
      "name": "Soil_Sand_White"
    },
    {
      "x": -4,
      "y": 1,
      "z": -5,
      "name": "Soil_Sand_White"
    },
    {
      "x": -4,
      "y": -1,
      "z": -4,
      "name": "Rock_Sandstone"
    },
    {
      "x": -4,
      "y": 0,
      "z": -4,
      "name": "Soil_Sand_White"
    },
    {
      "x": -4,
      "y": 1,
      "z": -4,
      "name": "Soil_Sand_White"
    },
    {
      "x": -4,
      "y": -1,
      "z": -3,
      "name": "Rock_Sandstone"
    },
    {
      "x": -4,
      "y": 0,
      "z": -3,
      "name": "Soil_Sand_White"
    },
    {
      "x": -4,
      "y": -1,
      "z": -2,
      "name": "Rock_Sandstone"
    },
    {
      "x": -4,
      "y": 0,
      "z": -2,
      "name": "Soil_Sand_White"
    },
    {
      "x": -4,
      "y": -1,
      "z": -1,
      "name": "Rock_Sandstone"
    },
    {
      "x": -4,
      "y": 0,
      "z": -1,
      "name": "Soil_Sand_White"
    },
    {
      "x": -4,
      "y": -1,
      "z": 0,
      "name": "Rock_Sandstone"
    },
    {
      "x": -4,
      "y": 0,
      "z": 0,
      "name": "Soil_Sand_White"
    },
    {
      "x": -4,
      "y": -2,
      "z": 1,
      "name": "Rock_Sandstone"
    },
    {
      "x": -4,
      "y": -1,
      "z": 1,
      "name": "Rock_Sandstone"
    },
    {
      "x": -4,
      "y": 0,
      "z": 1,
      "name": "Soil_Sand_White"
    },
    {
      "x": -4,
      "y": -3,
      "z": 2,
      "name": "Rock_Sandstone"
    },
    {
      "x": -4,
      "y": -2,
      "z": 2,
      "name": "Rock_Sandstone"
    },
    {
      "x": -4,
      "y": -1,
      "z": 2,
      "name": "Rock_Sandstone"
    },
    {
      "x": -4,
      "y": 0,
      "z": 2,
      "name": "Soil_Sand_White"
    },
    {
      "x": -4,
      "y": -3,
      "z": 3,
      "name": "Rock_Sandstone"
    },
    {
      "x": -4,
      "y": -2,
      "z": 3,
      "name": "Rock_Sandstone"
    },
    {
      "x": -4,
      "y": -1,
      "z": 3,
      "name": "Soil_Sand_White"
    },
    {
      "x": -4,
      "y": -3,
      "z": 4,
      "name": "Rock_Sandstone"
    },
    {
      "x": -4,
      "y": -2,
      "z": 4,
      "name": "Soil_Sand_White"
    },
    {
      "x": -4,
      "y": -3,
      "z": 5,
      "name": "Rock_Sandstone"
    },
    {
      "x": -4,
      "y": -2,
      "z": 5,
      "name": "Soil_Sand_White"
    },
    {
      "x": -4,
      "y": -3,
      "z": 6,
      "name": "Soil_Sand_White"
    },
    {
      "x": -3,
      "y": -3,
      "z": -25,
      "name": "Soil_Sand_White"
    },
    {
      "x": -3,
      "y": -3,
      "z": -24,
      "name": "Rock_Sandstone"
    },
    {
      "x": -3,
      "y": -2,
      "z": -24,
      "name": "Soil_Sand_White"
    },
    {
      "x": -3,
      "y": -3,
      "z": -23,
      "name": "Rock_Sandstone"
    },
    {
      "x": -3,
      "y": -2,
      "z": -23,
      "name": "Rock_Sandstone"
    },
    {
      "x": -3,
      "y": -1,
      "z": -23,
      "name": "Soil_Sand_White"
    },
    {
      "x": -3,
      "y": -3,
      "z": -22,
      "name": "Rock_Sandstone"
    },
    {
      "x": -3,
      "y": -2,
      "z": -22,
      "name": "Rock_Sandstone"
    },
    {
      "x": -3,
      "y": -1,
      "z": -22,
      "name": "Soil_Sand_White"
    },
    {
      "x": -3,
      "y": -3,
      "z": -21,
      "name": "Rock_Sandstone"
    },
    {
      "x": -3,
      "y": -2,
      "z": -21,
      "name": "Rock_Sandstone"
    },
    {
      "x": -3,
      "y": -1,
      "z": -21,
      "name": "Soil_Sand_White"
    },
    {
      "x": -3,
      "y": 0,
      "z": -21,
      "name": "Soil_Sand_White"
    },
    {
      "x": -3,
      "y": -3,
      "z": -20,
      "name": "Rock_Sandstone"
    },
    {
      "x": -3,
      "y": -2,
      "z": -20,
      "name": "Rock_Sandstone"
    },
    {
      "x": -3,
      "y": -1,
      "z": -20,
      "name": "Soil_Sand_White"
    },
    {
      "x": -3,
      "y": 0,
      "z": -20,
      "name": "Soil_Sand_White"
    },
    {
      "x": -3,
      "y": -3,
      "z": -19,
      "name": "Rock_Sandstone"
    },
    {
      "x": -3,
      "y": -2,
      "z": -19,
      "name": "Rock_Sandstone"
    },
    {
      "x": -3,
      "y": -1,
      "z": -19,
      "name": "Rock_Sandstone"
    },
    {
      "x": -3,
      "y": 0,
      "z": -19,
      "name": "Soil_Sand_White"
    },
    {
      "x": -3,
      "y": 1,
      "z": -19,
      "name": "Soil_Sand_White"
    },
    {
      "x": -3,
      "y": -2,
      "z": -18,
      "name": "Rock_Sandstone"
    },
    {
      "x": -3,
      "y": -1,
      "z": -18,
      "name": "Rock_Sandstone"
    },
    {
      "x": -3,
      "y": 0,
      "z": -18,
      "name": "Soil_Sand_White"
    },
    {
      "x": -3,
      "y": 1,
      "z": -18,
      "name": "Soil_Gravel_Sand_White",
      "support": 15
    },
    {
      "x": -3,
      "y": 2,
      "z": -18,
      "name": "Soil_Sand_White"
    },
    {
      "x": -3,
      "y": -2,
      "z": -17,
      "name": "Rock_Sandstone"
    },
    {
      "x": -3,
      "y": -1,
      "z": -17,
      "name": "Rock_Sandstone"
    },
    {
      "x": -3,
      "y": 0,
      "z": -17,
      "name": "Soil_Sand_White"
    },
    {
      "x": -3,
      "y": 1,
      "z": -17,
      "name": "Soil_Sand_White"
    },
    {
      "x": -3,
      "y": 2,
      "z": -17,
      "name": "Soil_Sand_White"
    },
    {
      "x": -3,
      "y": -2,
      "z": -16,
      "name": "Rock_Sandstone"
    },
    {
      "x": -3,
      "y": -1,
      "z": -16,
      "name": "Rock_Sandstone"
    },
    {
      "x": -3,
      "y": 0,
      "z": -16,
      "name": "Soil_Sand_White"
    },
    {
      "x": -3,
      "y": 1,
      "z": -16,
      "name": "Soil_Sand_White"
    },
    {
      "x": -3,
      "y": 2,
      "z": -16,
      "name": "Soil_Gravel_Sand_White",
      "support": 15
    },
    {
      "x": -3,
      "y": -2,
      "z": -15,
      "name": "Rock_Sandstone"
    },
    {
      "x": -3,
      "y": -1,
      "z": -15,
      "name": "Rock_Sandstone"
    },
    {
      "x": -3,
      "y": 0,
      "z": -15,
      "name": "Soil_Sand_White"
    },
    {
      "x": -3,
      "y": 1,
      "z": -15,
      "name": "Soil_Sand_White"
    },
    {
      "x": -3,
      "y": 2,
      "z": -15,
      "name": "Soil_Sand_White"
    },
    {
      "x": -3,
      "y": -2,
      "z": -14,
      "name": "Rock_Sandstone"
    },
    {
      "x": -3,
      "y": -1,
      "z": -14,
      "name": "Rock_Sandstone"
    },
    {
      "x": -3,
      "y": 0,
      "z": -14,
      "name": "Soil_Sand_White"
    },
    {
      "x": -3,
      "y": 1,
      "z": -14,
      "name": "Soil_Sand_White"
    },
    {
      "x": -3,
      "y": 2,
      "z": -14,
      "name": "Soil_Sand_White"
    },
    {
      "x": -3,
      "y": 3,
      "z": -14,
      "name": "Soil_Sand_White"
    },
    {
      "x": -3,
      "y": -2,
      "z": -13,
      "name": "Rock_Sandstone"
    },
    {
      "x": -3,
      "y": -1,
      "z": -13,
      "name": "Rock_Sandstone"
    },
    {
      "x": -3,
      "y": 0,
      "z": -13,
      "name": "Soil_Sand_White"
    },
    {
      "x": -3,
      "y": 1,
      "z": -13,
      "name": "Soil_Sand_White"
    },
    {
      "x": -3,
      "y": 2,
      "z": -13,
      "name": "Soil_Gravel_Sand_White_Half",
      "support": 15
    },
    {
      "x": -3,
      "y": -1,
      "z": -12,
      "name": "Rock_Sandstone"
    },
    {
      "x": -3,
      "y": 0,
      "z": -12,
      "name": "Soil_Sand_White"
    },
    {
      "x": -3,
      "y": 1,
      "z": -12,
      "name": "Soil_Gravel_Sand_White",
      "support": 15
    },
    {
      "x": -3,
      "y": -1,
      "z": -11,
      "name": "Rock_Sandstone"
    },
    {
      "x": -3,
      "y": 0,
      "z": -11,
      "name": "Soil_Sand_White"
    },
    {
      "x": -3,
      "y": 1,
      "z": -11,
      "name": "Soil_Sand_White"
    },
    {
      "x": -3,
      "y": -1,
      "z": -10,
      "name": "Rock_Sandstone"
    },
    {
      "x": -3,
      "y": 0,
      "z": -10,
      "name": "Soil_Sand_White"
    },
    {
      "x": -3,
      "y": 1,
      "z": -10,
      "name": "Soil_Gravel_Sand_White",
      "support": 15
    },
    {
      "x": -3,
      "y": -1,
      "z": -9,
      "name": "Rock_Sandstone"
    },
    {
      "x": -3,
      "y": 0,
      "z": -9,
      "name": "Soil_Sand_White"
    },
    {
      "x": -3,
      "y": 1,
      "z": -9,
      "name": "Soil_Sand_White"
    },
    {
      "x": -3,
      "y": 2,
      "z": -9,
      "name": "Soil_Sand_White"
    },
    {
      "x": -3,
      "y": -1,
      "z": -8,
      "name": "Rock_Sandstone"
    },
    {
      "x": -3,
      "y": 0,
      "z": -8,
      "name": "Soil_Sand_White"
    },
    {
      "x": -3,
      "y": 1,
      "z": -8,
      "name": "Soil_Sand_White"
    },
    {
      "x": -3,
      "y": 2,
      "z": -8,
      "name": "Soil_Sand_White"
    },
    {
      "x": -3,
      "y": -1,
      "z": -7,
      "name": "Rock_Sandstone"
    },
    {
      "x": -3,
      "y": 0,
      "z": -7,
      "name": "Soil_Sand_White"
    },
    {
      "x": -3,
      "y": 1,
      "z": -7,
      "name": "Soil_Sand_White"
    },
    {
      "x": -3,
      "y": -1,
      "z": -6,
      "name": "Rock_Sandstone"
    },
    {
      "x": -3,
      "y": 0,
      "z": -6,
      "name": "Soil_Sand_White"
    },
    {
      "x": -3,
      "y": 1,
      "z": -6,
      "name": "Soil_Sand_White"
    },
    {
      "x": -3,
      "y": 2,
      "z": -6,
      "name": "Soil_Sand_White"
    },
    {
      "x": -3,
      "y": -1,
      "z": -5,
      "name": "Rock_Sandstone"
    },
    {
      "x": -3,
      "y": 0,
      "z": -5,
      "name": "Soil_Sand_White"
    },
    {
      "x": -3,
      "y": 1,
      "z": -5,
      "name": "Soil_Sand_White"
    },
    {
      "x": -3,
      "y": 2,
      "z": -5,
      "name": "OrbisGalactic_Scrap_Block"
    },
    {
      "x": -3,
      "y": -1,
      "z": -4,
      "name": "Rock_Sandstone"
    },
    {
      "x": -3,
      "y": 0,
      "z": -4,
      "name": "Soil_Sand_White"
    },
    {
      "x": -3,
      "y": 1,
      "z": -4,
      "name": "Soil_Sand_White"
    },
    {
      "x": -3,
      "y": -1,
      "z": -3,
      "name": "Rock_Sandstone"
    },
    {
      "x": -3,
      "y": 0,
      "z": -3,
      "name": "Soil_Sand_White"
    },
    {
      "x": -3,
      "y": 1,
      "z": -3,
      "name": "Soil_Sand_White"
    },
    {
      "x": -3,
      "y": -1,
      "z": -2,
      "name": "Rock_Sandstone"
    },
    {
      "x": -3,
      "y": 0,
      "z": -2,
      "name": "Soil_Sand_White"
    },
    {
      "x": -3,
      "y": -1,
      "z": -1,
      "name": "Rock_Sandstone"
    },
    {
      "x": -3,
      "y": 0,
      "z": -1,
      "name": "Soil_Sand_White"
    },
    {
      "x": -3,
      "y": -1,
      "z": 0,
      "name": "Rock_Sandstone"
    },
    {
      "x": -3,
      "y": 0,
      "z": 0,
      "name": "Soil_Sand_White"
    },
    {
      "x": -3,
      "y": -1,
      "z": 1,
      "name": "Rock_Sandstone"
    },
    {
      "x": -3,
      "y": 0,
      "z": 1,
      "name": "Soil_Sand_White"
    },
    {
      "x": -3,
      "y": -2,
      "z": 2,
      "name": "Rock_Sandstone"
    },
    {
      "x": -3,
      "y": -1,
      "z": 2,
      "name": "Rock_Sandstone"
    },
    {
      "x": -3,
      "y": 0,
      "z": 2,
      "name": "Soil_Sand_White"
    },
    {
      "x": -3,
      "y": -3,
      "z": 3,
      "name": "Rock_Sandstone"
    },
    {
      "x": -3,
      "y": -2,
      "z": 3,
      "name": "Rock_Sandstone"
    },
    {
      "x": -3,
      "y": -1,
      "z": 3,
      "name": "Rock_Sandstone"
    },
    {
      "x": -3,
      "y": 0,
      "z": 3,
      "name": "Soil_Sand_White"
    },
    {
      "x": -3,
      "y": -3,
      "z": 4,
      "name": "Rock_Sandstone"
    },
    {
      "x": -3,
      "y": -2,
      "z": 4,
      "name": "Rock_Sandstone"
    },
    {
      "x": -3,
      "y": -1,
      "z": 4,
      "name": "Soil_Sand_White"
    },
    {
      "x": -3,
      "y": -3,
      "z": 5,
      "name": "Rock_Sandstone"
    },
    {
      "x": -3,
      "y": -2,
      "z": 5,
      "name": "Soil_Sand_White"
    },
    {
      "x": -3,
      "y": -3,
      "z": 6,
      "name": "Soil_Sand_White"
    },
    {
      "x": -2,
      "y": -3,
      "z": -25,
      "name": "Soil_Sand_White"
    },
    {
      "x": -2,
      "y": -3,
      "z": -24,
      "name": "Rock_Sandstone"
    },
    {
      "x": -2,
      "y": -2,
      "z": -24,
      "name": "Soil_Sand_White"
    },
    {
      "x": -2,
      "y": -3,
      "z": -23,
      "name": "Rock_Sandstone"
    },
    {
      "x": -2,
      "y": -2,
      "z": -23,
      "name": "Rock_Sandstone"
    },
    {
      "x": -2,
      "y": -1,
      "z": -23,
      "name": "Soil_Sand_White"
    },
    {
      "x": -2,
      "y": -3,
      "z": -22,
      "name": "Rock_Sandstone"
    },
    {
      "x": -2,
      "y": -2,
      "z": -22,
      "name": "Rock_Sandstone"
    },
    {
      "x": -2,
      "y": -1,
      "z": -22,
      "name": "Soil_Sand_White"
    },
    {
      "x": -2,
      "y": 0,
      "z": -22,
      "name": "Soil_Sand_White"
    },
    {
      "x": -2,
      "y": -2,
      "z": -21,
      "name": "Rock_Sandstone"
    },
    {
      "x": -2,
      "y": -1,
      "z": -21,
      "name": "Soil_Sand_White"
    },
    {
      "x": -2,
      "y": 0,
      "z": -21,
      "name": "Soil_Sand_White"
    },
    {
      "x": -2,
      "y": -2,
      "z": -20,
      "name": "Rock_Sandstone"
    },
    {
      "x": -2,
      "y": -1,
      "z": -20,
      "name": "Rock_Sandstone"
    },
    {
      "x": -2,
      "y": 0,
      "z": -20,
      "name": "Soil_Sand_White"
    },
    {
      "x": -2,
      "y": 1,
      "z": -20,
      "name": "Soil_Sand_White"
    },
    {
      "x": -2,
      "y": -2,
      "z": -19,
      "name": "Rock_Sandstone"
    },
    {
      "x": -2,
      "y": -1,
      "z": -19,
      "name": "Rock_Sandstone"
    },
    {
      "x": -2,
      "y": 0,
      "z": -19,
      "name": "Soil_Sand_White"
    },
    {
      "x": -2,
      "y": 1,
      "z": -19,
      "name": "Soil_Sand_White"
    },
    {
      "x": -2,
      "y": -2,
      "z": -18,
      "name": "Rock_Sandstone"
    },
    {
      "x": -2,
      "y": -1,
      "z": -18,
      "name": "Rock_Sandstone"
    },
    {
      "x": -2,
      "y": 0,
      "z": -18,
      "name": "Soil_Sand_White"
    },
    {
      "x": -2,
      "y": 1,
      "z": -18,
      "name": "Soil_Sand_White"
    },
    {
      "x": -2,
      "y": 2,
      "z": -18,
      "name": "Soil_Sand_White"
    },
    {
      "x": -2,
      "y": -2,
      "z": -17,
      "name": "Rock_Sandstone"
    },
    {
      "x": -2,
      "y": -1,
      "z": -17,
      "name": "Rock_Sandstone"
    },
    {
      "x": -2,
      "y": 0,
      "z": -17,
      "name": "Soil_Sand_White"
    },
    {
      "x": -2,
      "y": 1,
      "z": -17,
      "name": "Soil_Sand_White"
    },
    {
      "x": -2,
      "y": 2,
      "z": -17,
      "name": "Soil_Sand_White"
    },
    {
      "x": -2,
      "y": -2,
      "z": -16,
      "name": "Rock_Sandstone"
    },
    {
      "x": -2,
      "y": -1,
      "z": -16,
      "name": "Rock_Sandstone"
    },
    {
      "x": -2,
      "y": 0,
      "z": -16,
      "name": "Soil_Sand_White"
    },
    {
      "x": -2,
      "y": 1,
      "z": -16,
      "name": "Soil_Sand_White"
    },
    {
      "x": -2,
      "y": 2,
      "z": -16,
      "name": "Soil_Sand_White"
    },
    {
      "x": -2,
      "y": -2,
      "z": -15,
      "name": "Rock_Sandstone"
    },
    {
      "x": -2,
      "y": -1,
      "z": -15,
      "name": "Rock_Sandstone"
    },
    {
      "x": -2,
      "y": 0,
      "z": -15,
      "name": "Soil_Sand_White"
    },
    {
      "x": -2,
      "y": 1,
      "z": -15,
      "name": "Soil_Sand_White"
    },
    {
      "x": -2,
      "y": 2,
      "z": -15,
      "name": "Soil_Sand_White"
    },
    {
      "x": -2,
      "y": 3,
      "z": -15,
      "name": "Soil_Gravel_Sand_White",
      "support": 15
    },
    {
      "x": -2,
      "y": -2,
      "z": -14,
      "name": "Rock_Sandstone"
    },
    {
      "x": -2,
      "y": -1,
      "z": -14,
      "name": "Rock_Sandstone"
    },
    {
      "x": -2,
      "y": 0,
      "z": -14,
      "name": "Soil_Sand_White"
    },
    {
      "x": -2,
      "y": 1,
      "z": -14,
      "name": "Metal_Iron_Half",
      "rotation": 7
    },
    {
      "x": -2,
      "y": 2,
      "z": -14,
      "name": "Metal_Iron_Smooth"
    },
    {
      "x": -2,
      "y": 3,
      "z": -14,
      "name": "Metal_Iron_Half",
      "rotation": 7
    },
    {
      "x": -2,
      "y": -2,
      "z": -13,
      "name": "Rock_Sandstone"
    },
    {
      "x": -2,
      "y": -1,
      "z": -13,
      "name": "Rock_Sandstone"
    },
    {
      "x": -2,
      "y": 0,
      "z": -13,
      "name": "Soil_Sand_White"
    },
    {
      "x": -2,
      "y": 1,
      "z": -13,
      "name": "Metal_Iron_Half",
      "rotation": 7
    },
    {
      "x": -2,
      "y": 2,
      "z": -13,
      "name": "Metal_Iron_Smooth"
    },
    {
      "x": -2,
      "y": 3,
      "z": -13,
      "name": "Metal_Iron_Half",
      "rotation": 7
    },
    {
      "x": -2,
      "y": -2,
      "z": -12,
      "name": "Rock_Sandstone"
    },
    {
      "x": -2,
      "y": -1,
      "z": -12,
      "name": "Rock_Sandstone"
    },
    {
      "x": -2,
      "y": 0,
      "z": -12,
      "name": "Soil_Sand_White"
    },
    {
      "x": -2,
      "y": 1,
      "z": -12,
      "name": "Metal_Iron_Half",
      "rotation": 7
    },
    {
      "x": -2,
      "y": 2,
      "z": -12,
      "name": "Metal_Iron_Half",
      "rotation": 4
    },
    {
      "x": -2,
      "y": 3,
      "z": -12,
      "name": "Metal_Iron_Half",
      "rotation": 4
    },
    {
      "x": -2,
      "y": -1,
      "z": -11,
      "name": "Rock_Sandstone"
    },
    {
      "x": -2,
      "y": 0,
      "z": -11,
      "name": "Soil_Sand_White"
    },
    {
      "x": -2,
      "y": 1,
      "z": -11,
      "name": "Metal_Iron_Half",
      "rotation": 7
    },
    {
      "x": -2,
      "y": 2,
      "z": -11,
      "name": "Metal_Iron_Half",
      "rotation": 6
    },
    {
      "x": -2,
      "y": 3,
      "z": -11,
      "name": "Metal_Iron_Half",
      "rotation": 6
    },
    {
      "x": -2,
      "y": -1,
      "z": -10,
      "name": "Rock_Sandstone"
    },
    {
      "x": -2,
      "y": 0,
      "z": -10,
      "name": "Soil_Sand_White"
    },
    {
      "x": -2,
      "y": 1,
      "z": -10,
      "name": "Metal_Iron_Half",
      "rotation": 7
    },
    {
      "x": -2,
      "y": 2,
      "z": -10,
      "name": "Metal_Iron_Smooth"
    },
    {
      "x": -2,
      "y": 3,
      "z": -10,
      "name": "Metal_Iron_Half",
      "rotation": 7
    },
    {
      "x": -2,
      "y": -1,
      "z": -9,
      "name": "Rock_Sandstone"
    },
    {
      "x": -2,
      "y": 0,
      "z": -9,
      "name": "Soil_Sand_White"
    },
    {
      "x": -2,
      "y": 1,
      "z": -9,
      "name": "Metal_Iron_Half",
      "rotation": 7
    },
    {
      "x": -2,
      "y": 2,
      "z": -9,
      "name": "Metal_Iron_Smooth"
    },
    {
      "x": -2,
      "y": 3,
      "z": -9,
      "name": "OrbisGalactic_Scrap_Block"
    },
    {
      "x": -2,
      "y": -1,
      "z": -8,
      "name": "Rock_Sandstone"
    },
    {
      "x": -2,
      "y": 0,
      "z": -8,
      "name": "Soil_Sand_White"
    },
    {
      "x": -2,
      "y": 1,
      "z": -8,
      "name": "Soil_Sand_White"
    },
    {
      "x": -2,
      "y": 2,
      "z": -8,
      "name": "Soil_Gravel_Sand_White",
      "support": 15
    },
    {
      "x": -2,
      "y": -2,
      "z": -7,
      "name": "Rock_Sandstone"
    },
    {
      "x": -2,
      "y": -1,
      "z": -7,
      "name": "Rock_Sandstone"
    },
    {
      "x": -2,
      "y": 0,
      "z": -7,
      "name": "Soil_Sand_White"
    },
    {
      "x": -2,
      "y": 1,
      "z": -7,
      "name": "Soil_Gravel_Sand_White",
      "support": 15
    },
    {
      "x": -2,
      "y": 2,
      "z": -7,
      "name": "Empty"
    },
    {
      "x": -2,
      "y": -1,
      "z": -6,
      "name": "Rock_Sandstone"
    },
    {
      "x": -2,
      "y": 0,
      "z": -6,
      "name": "Soil_Sand_White"
    },
    {
      "x": -2,
      "y": 1,
      "z": -6,
      "name": "Soil_Sand_White"
    },
    {
      "x": -2,
      "y": 2,
      "z": -6,
      "name": "Empty"
    },
    {
      "x": -2,
      "y": -1,
      "z": -5,
      "name": "Rock_Sandstone"
    },
    {
      "x": -2,
      "y": 0,
      "z": -5,
      "name": "Soil_Sand_White"
    },
    {
      "x": -2,
      "y": 1,
      "z": -5,
      "name": "Soil_Sand_White"
    },
    {
      "x": -2,
      "y": 2,
      "z": -5,
      "name": "Empty"
    },
    {
      "x": -2,
      "y": -1,
      "z": -4,
      "name": "Rock_Sandstone"
    },
    {
      "x": -2,
      "y": 0,
      "z": -4,
      "name": "Soil_Sand_White"
    },
    {
      "x": -2,
      "y": 1,
      "z": -4,
      "name": "Soil_Sand_White"
    },
    {
      "x": -2,
      "y": 2,
      "z": -4,
      "name": "Empty"
    },
    {
      "x": -2,
      "y": -1,
      "z": -3,
      "name": "Rock_Sandstone"
    },
    {
      "x": -2,
      "y": 0,
      "z": -3,
      "name": "Soil_Sand_White"
    },
    {
      "x": -2,
      "y": 1,
      "z": -3,
      "name": "Soil_Sand_White"
    },
    {
      "x": -2,
      "y": 2,
      "z": -3,
      "name": "Empty"
    },
    {
      "x": -2,
      "y": -1,
      "z": -2,
      "name": "Rock_Sandstone"
    },
    {
      "x": -2,
      "y": 0,
      "z": -2,
      "name": "Soil_Sand_White"
    },
    {
      "x": -2,
      "y": 1,
      "z": -2,
      "name": "Soil_Sand_White"
    },
    {
      "x": -2,
      "y": 2,
      "z": -2,
      "name": "Empty"
    },
    {
      "x": -2,
      "y": -1,
      "z": -1,
      "name": "Rock_Sandstone"
    },
    {
      "x": -2,
      "y": 0,
      "z": -1,
      "name": "Soil_Sand_White"
    },
    {
      "x": -2,
      "y": 1,
      "z": -1,
      "name": "Empty"
    },
    {
      "x": -2,
      "y": -1,
      "z": 0,
      "name": "Rock_Sandstone"
    },
    {
      "x": -2,
      "y": 0,
      "z": 0,
      "name": "Soil_Sand_White"
    },
    {
      "x": -2,
      "y": 1,
      "z": 0,
      "name": "Empty"
    },
    {
      "x": -2,
      "y": -1,
      "z": 1,
      "name": "Rock_Sandstone"
    },
    {
      "x": -2,
      "y": 0,
      "z": 1,
      "name": "Soil_Sand_White"
    },
    {
      "x": -2,
      "y": 1,
      "z": 1,
      "name": "Empty"
    },
    {
      "x": -2,
      "y": -2,
      "z": 2,
      "name": "Rock_Sandstone"
    },
    {
      "x": -2,
      "y": -1,
      "z": 2,
      "name": "Rock_Sandstone"
    },
    {
      "x": -2,
      "y": 0,
      "z": 2,
      "name": "Soil_Sand_White"
    },
    {
      "x": -2,
      "y": -3,
      "z": 3,
      "name": "Rock_Sandstone"
    },
    {
      "x": -2,
      "y": -2,
      "z": 3,
      "name": "Rock_Sandstone"
    },
    {
      "x": -2,
      "y": -1,
      "z": 3,
      "name": "Rock_Sandstone"
    },
    {
      "x": -2,
      "y": 0,
      "z": 3,
      "name": "Soil_Sand_White"
    },
    {
      "x": -2,
      "y": -3,
      "z": 4,
      "name": "Rock_Sandstone"
    },
    {
      "x": -2,
      "y": -2,
      "z": 4,
      "name": "Rock_Sandstone"
    },
    {
      "x": -2,
      "y": -1,
      "z": 4,
      "name": "Soil_Sand_White"
    },
    {
      "x": -2,
      "y": -3,
      "z": 5,
      "name": "Rock_Sandstone"
    },
    {
      "x": -2,
      "y": -2,
      "z": 5,
      "name": "Soil_Sand_White"
    },
    {
      "x": -2,
      "y": -3,
      "z": 6,
      "name": "Rock_Sandstone"
    },
    {
      "x": -2,
      "y": -2,
      "z": 6,
      "name": "Soil_Sand_White"
    },
    {
      "x": -2,
      "y": -3,
      "z": 7,
      "name": "Soil_Sand_White"
    },
    {
      "x": -1,
      "y": -3,
      "z": -25,
      "name": "Soil_Sand_White"
    },
    {
      "x": -1,
      "y": -3,
      "z": -24,
      "name": "Rock_Sandstone"
    },
    {
      "x": -1,
      "y": -2,
      "z": -24,
      "name": "Soil_Sand_White"
    },
    {
      "x": -1,
      "y": -3,
      "z": -23,
      "name": "Rock_Sandstone"
    },
    {
      "x": -1,
      "y": -2,
      "z": -23,
      "name": "Rock_Sandstone"
    },
    {
      "x": -1,
      "y": -1,
      "z": -23,
      "name": "Soil_Sand_White"
    },
    {
      "x": -1,
      "y": -2,
      "z": -22,
      "name": "Rock_Sandstone"
    },
    {
      "x": -1,
      "y": -1,
      "z": -22,
      "name": "Soil_Sand_White"
    },
    {
      "x": -1,
      "y": 0,
      "z": -22,
      "name": "Soil_Sand_White"
    },
    {
      "x": -1,
      "y": -2,
      "z": -21,
      "name": "Rock_Sandstone"
    },
    {
      "x": -1,
      "y": -1,
      "z": -21,
      "name": "Soil_Sand_White"
    },
    {
      "x": -1,
      "y": 0,
      "z": -21,
      "name": "Soil_Sand_White"
    },
    {
      "x": -1,
      "y": -2,
      "z": -20,
      "name": "Rock_Sandstone"
    },
    {
      "x": -1,
      "y": -1,
      "z": -20,
      "name": "Rock_Sandstone"
    },
    {
      "x": -1,
      "y": 0,
      "z": -20,
      "name": "Soil_Sand_White"
    },
    {
      "x": -1,
      "y": 1,
      "z": -20,
      "name": "Soil_Sand_White"
    },
    {
      "x": -1,
      "y": -2,
      "z": -19,
      "name": "Rock_Sandstone"
    },
    {
      "x": -1,
      "y": -1,
      "z": -19,
      "name": "Rock_Sandstone"
    },
    {
      "x": -1,
      "y": 0,
      "z": -19,
      "name": "Soil_Sand_White"
    },
    {
      "x": -1,
      "y": 1,
      "z": -19,
      "name": "Soil_Sand_White"
    },
    {
      "x": -1,
      "y": 2,
      "z": -19,
      "name": "Soil_Sand_White"
    },
    {
      "x": -1,
      "y": -2,
      "z": -18,
      "name": "Rock_Sandstone"
    },
    {
      "x": -1,
      "y": -1,
      "z": -18,
      "name": "Rock_Sandstone"
    },
    {
      "x": -1,
      "y": 0,
      "z": -18,
      "name": "Soil_Sand_White"
    },
    {
      "x": -1,
      "y": 1,
      "z": -18,
      "name": "Soil_Sand_White"
    },
    {
      "x": -1,
      "y": 2,
      "z": -18,
      "name": "Soil_Gravel_Sand_White",
      "support": 15
    },
    {
      "x": -1,
      "y": -2,
      "z": -17,
      "name": "Rock_Sandstone"
    },
    {
      "x": -1,
      "y": -1,
      "z": -17,
      "name": "Rock_Sandstone"
    },
    {
      "x": -1,
      "y": 0,
      "z": -17,
      "name": "Soil_Sand_White"
    },
    {
      "x": -1,
      "y": 1,
      "z": -17,
      "name": "Soil_Sand_White"
    },
    {
      "x": -1,
      "y": 2,
      "z": -17,
      "name": "Soil_Sand_White"
    },
    {
      "x": -1,
      "y": -2,
      "z": -16,
      "name": "Rock_Sandstone"
    },
    {
      "x": -1,
      "y": -1,
      "z": -16,
      "name": "Rock_Sandstone"
    },
    {
      "x": -1,
      "y": 0,
      "z": -16,
      "name": "Soil_Sand_White"
    },
    {
      "x": -1,
      "y": 1,
      "z": -16,
      "name": "Soil_Sand_White"
    },
    {
      "x": -1,
      "y": 2,
      "z": -16,
      "name": "Soil_Sand_White"
    },
    {
      "x": -1,
      "y": 3,
      "z": -16,
      "name": "Soil_Gravel_Sand_White",
      "support": 15
    },
    {
      "x": -1,
      "y": -2,
      "z": -15,
      "name": "Rock_Sandstone"
    },
    {
      "x": -1,
      "y": -1,
      "z": -15,
      "name": "Rock_Sandstone"
    },
    {
      "x": -1,
      "y": 0,
      "z": -15,
      "name": "Soil_Sand_White"
    },
    {
      "x": -1,
      "y": 1,
      "z": -15,
      "name": "Metal_Iron_Stairs",
      "rotation": 8
    },
    {
      "x": -1,
      "y": 2,
      "z": -15,
      "name": "OrbisGalactic_Block_Ship_Window"
    },
    {
      "x": -1,
      "y": 3,
      "z": -15,
      "name": "Metal_Iron_Stairs",
      "rotation": 3
    },
    {
      "x": -1,
      "y": -2,
      "z": -14,
      "name": "Rock_Sandstone"
    },
    {
      "x": -1,
      "y": -1,
      "z": -14,
      "name": "Rock_Sandstone"
    },
    {
      "x": -1,
      "y": 0,
      "z": -14,
      "name": "Metal_Iron_Half",
      "rotation": 8
    },
    {
      "x": -1,
      "y": 1,
      "z": -14,
      "name": "Metal_Iron_Stairs",
      "rotation": 1
    },
    {
      "x": -1,
      "y": 2,
      "z": -14,
      "name": "Empty"
    },
    {
      "x": -1,
      "y": 3,
      "z": -14,
      "name": "Metal_Iron_Stairs",
      "rotation": 11
    },
    {
      "x": -1,
      "y": 4,
      "z": -14,
      "name": "Soil_Gravel_Sand_White",
      "support": 15
    },
    {
      "x": -1,
      "y": -2,
      "z": -13,
      "name": "Rock_Sandstone"
    },
    {
      "x": -1,
      "y": -1,
      "z": -13,
      "name": "Rock_Sandstone"
    },
    {
      "x": -1,
      "y": 0,
      "z": -13,
      "name": "Metal_Iron_Half",
      "rotation": 8
    },
    {
      "x": -1,
      "y": 1,
      "z": -13,
      "name": "Metal_Iron_Stairs",
      "rotation": 1
    },
    {
      "x": -1,
      "y": 2,
      "z": -13,
      "name": "Empty"
    },
    {
      "x": -1,
      "y": 3,
      "z": -13,
      "name": "Metal_Iron_Half",
      "rotation": 5
    },
    {
      "x": -1,
      "y": 4,
      "z": -13,
      "name": "Metal_Iron_Half"
    },
    {
      "x": -1,
      "y": -1,
      "z": -12,
      "name": "Rock_Sandstone"
    },
    {
      "x": -1,
      "y": 0,
      "z": -12,
      "name": "Metal_Iron_Half",
      "rotation": 8
    },
    {
      "x": -1,
      "y": 1,
      "z": -12,
      "name": "Metal_Iron_Stairs",
      "rotation": 1
    },
    {
      "x": -1,
      "y": 2,
      "z": -12,
      "name": "Empty"
    },
    {
      "x": -1,
      "y": 3,
      "z": -12,
      "name": "Empty"
    },
    {
      "x": -1,
      "y": 4,
      "z": -12,
      "name": "Metal_Iron_Half"
    },
    {
      "x": -1,
      "y": -1,
      "z": -11,
      "name": "Rock_Sandstone"
    },
    {
      "x": -1,
      "y": 0,
      "z": -11,
      "name": "Metal_Iron_Half",
      "rotation": 8
    },
    {
      "x": -1,
      "y": 1,
      "z": -11,
      "name": "Metal_Iron_Stairs",
      "rotation": 1
    },
    {
      "x": -1,
      "y": 2,
      "z": -11,
      "name": "Empty"
    },
    {
      "x": -1,
      "y": 3,
      "z": -11,
      "name": "Empty"
    },
    {
      "x": -1,
      "y": 4,
      "z": -11,
      "name": "Metal_Iron_Half"
    },
    {
      "x": -1,
      "y": -1,
      "z": -10,
      "name": "Rock_Sandstone"
    },
    {
      "x": -1,
      "y": 0,
      "z": -10,
      "name": "Metal_Iron_Half",
      "rotation": 8
    },
    {
      "x": -1,
      "y": 1,
      "z": -10,
      "name": "Metal_Iron_Stairs",
      "rotation": 1
    },
    {
      "x": -1,
      "y": 2,
      "z": -10,
      "name": "Empty"
    },
    {
      "x": -1,
      "y": 3,
      "z": -10,
      "name": "Metal_Iron_Stairs",
      "rotation": 11
    },
    {
      "x": -1,
      "y": 4,
      "z": -10,
      "name": "Metal_Iron_Half"
    },
    {
      "x": -1,
      "y": -1,
      "z": -9,
      "name": "Rock_Sandstone"
    },
    {
      "x": -1,
      "y": 0,
      "z": -9,
      "name": "Metal_Iron_Half",
      "rotation": 8
    },
    {
      "x": -1,
      "y": 1,
      "z": -9,
      "name": "Metal_Iron_Smooth"
    },
    {
      "x": -1,
      "y": 2,
      "z": -9,
      "name": "Metal_Iron_Ornate"
    },
    {
      "x": -1,
      "y": 3,
      "z": -9,
      "name": "Metal_Iron_Half",
      "rotation": 4
    },
    {
      "x": -1,
      "y": 4,
      "z": -9,
      "name": "Metal_Iron_Half"
    },
    {
      "x": -1,
      "y": -1,
      "z": -8,
      "name": "Rock_Sandstone"
    },
    {
      "x": -1,
      "y": 0,
      "z": -8,
      "name": "Soil_Sand_White"
    },
    {
      "x": -1,
      "y": 1,
      "z": -8,
      "name": "Metal_Iron_Pipe_Short",
      "support": 15
    },
    {
      "x": -1,
      "y": 2,
      "z": -8,
      "name": "Empty"
    },
    {
      "x": -1,
      "y": 3,
      "z": -8,
      "name": "Empty"
    },
    {
      "x": -1,
      "y": -2,
      "z": -7,
      "name": "Rock_Sandstone"
    },
    {
      "x": -1,
      "y": -1,
      "z": -7,
      "name": "Rock_Sandstone"
    },
    {
      "x": -1,
      "y": 0,
      "z": -7,
      "name": "Soil_Sand_White"
    },
    {
      "x": -1,
      "y": 1,
      "z": -7,
      "name": "Empty"
    },
    {
      "x": -1,
      "y": 2,
      "z": -7,
      "name": "Empty"
    },
    {
      "x": -1,
      "y": 3,
      "z": -7,
      "name": "Empty"
    },
    {
      "x": -1,
      "y": -2,
      "z": -6,
      "name": "Rock_Sandstone"
    },
    {
      "x": -1,
      "y": -1,
      "z": -6,
      "name": "Rock_Sandstone"
    },
    {
      "x": -1,
      "y": 0,
      "z": -6,
      "name": "Soil_Sand_White"
    },
    {
      "x": -1,
      "y": 1,
      "z": -6,
      "name": "Soil_Gravel_Sand_White_Half",
      "support": 15
    },
    {
      "x": -1,
      "y": 2,
      "z": -6,
      "name": "Empty"
    },
    {
      "x": -1,
      "y": 3,
      "z": -6,
      "name": "Empty"
    },
    {
      "x": -1,
      "y": -2,
      "z": -5,
      "name": "Rock_Sandstone"
    },
    {
      "x": -1,
      "y": -1,
      "z": -5,
      "name": "Rock_Sandstone"
    },
    {
      "x": -1,
      "y": 0,
      "z": -5,
      "name": "Soil_Sand_White"
    },
    {
      "x": -1,
      "y": 1,
      "z": -5,
      "name": "Metal_Iron_Pipe_Large_Mouthpiece",
      "support": 15,
      "rotation": 5
    },
    {
      "x": -1,
      "y": 2,
      "z": -5,
      "name": "Empty"
    },
    {
      "x": -1,
      "y": 3,
      "z": -5,
      "name": "Empty"
    },
    {
      "x": -1,
      "y": -2,
      "z": -4,
      "name": "Rock_Sandstone"
    },
    {
      "x": -1,
      "y": -1,
      "z": -4,
      "name": "Rock_Sandstone"
    },
    {
      "x": -1,
      "y": 0,
      "z": -4,
      "name": "Soil_Gravel_Sand_White_Half",
      "support": 15
    },
    {
      "x": -1,
      "y": 1,
      "z": -4,
      "name": "Empty"
    },
    {
      "x": -1,
      "y": 2,
      "z": -4,
      "name": "Empty"
    },
    {
      "x": -1,
      "y": 3,
      "z": -4,
      "name": "Empty"
    },
    {
      "x": -1,
      "y": -1,
      "z": -3,
      "name": "Rock_Sandstone"
    },
    {
      "x": -1,
      "y": 0,
      "z": -3,
      "name": "Soil_Gravel_Sand_White_Half",
      "support": 15
    },
    {
      "x": -1,
      "y": 1,
      "z": -3,
      "name": "Empty"
    },
    {
      "x": -1,
      "y": 2,
      "z": -3,
      "name": "Empty"
    },
    {
      "x": -1,
      "y": 3,
      "z": -3,
      "name": "Empty"
    },
    {
      "x": -1,
      "y": -1,
      "z": -2,
      "name": "Rock_Sandstone"
    },
    {
      "x": -1,
      "y": 0,
      "z": -2,
      "name": "Soil_Sand_White"
    },
    {
      "x": -1,
      "y": 1,
      "z": -2,
      "name": "Empty"
    },
    {
      "x": -1,
      "y": 3,
      "z": -2,
      "name": "Empty"
    },
    {
      "x": -1,
      "y": -1,
      "z": -1,
      "name": "Rock_Sandstone"
    },
    {
      "x": -1,
      "y": 0,
      "z": -1,
      "name": "Soil_Gravel_Sand_White_Half",
      "support": 15
    },
    {
      "x": -1,
      "y": 1,
      "z": -1,
      "name": "Empty"
    },
    {
      "x": -1,
      "y": 2,
      "z": -1,
      "name": "Empty"
    },
    {
      "x": -1,
      "y": 3,
      "z": -1,
      "name": "Empty"
    },
    {
      "x": -1,
      "y": -1,
      "z": 0,
      "name": "Rock_Sandstone"
    },
    {
      "x": -1,
      "y": 0,
      "z": 0,
      "name": "Soil_Gravel_Sand_White_Half",
      "support": 15
    },
    {
      "x": -1,
      "y": 1,
      "z": 0,
      "name": "Empty"
    },
    {
      "x": -1,
      "y": 2,
      "z": 0,
      "name": "Empty"
    },
    {
      "x": -1,
      "y": -1,
      "z": 1,
      "name": "Rock_Sandstone"
    },
    {
      "x": -1,
      "y": 0,
      "z": 1,
      "name": "Soil_Sand_White"
    },
    {
      "x": -1,
      "y": 1,
      "z": 1,
      "name": "Soil_Gravel_Sand_White_Half",
      "support": 15
    },
    {
      "x": -1,
      "y": 2,
      "z": 1,
      "name": "Empty"
    },
    {
      "x": -1,
      "y": -2,
      "z": 2,
      "name": "Rock_Sandstone"
    },
    {
      "x": -1,
      "y": -1,
      "z": 2,
      "name": "Rock_Sandstone"
    },
    {
      "x": -1,
      "y": 0,
      "z": 2,
      "name": "Soil_Sand_White"
    },
    {
      "x": -1,
      "y": -3,
      "z": 3,
      "name": "Rock_Sandstone"
    },
    {
      "x": -1,
      "y": -2,
      "z": 3,
      "name": "Rock_Sandstone"
    },
    {
      "x": -1,
      "y": -1,
      "z": 3,
      "name": "Rock_Sandstone"
    },
    {
      "x": -1,
      "y": 0,
      "z": 3,
      "name": "Soil_Sand_White"
    },
    {
      "x": -1,
      "y": -3,
      "z": 4,
      "name": "Rock_Sandstone"
    },
    {
      "x": -1,
      "y": -2,
      "z": 4,
      "name": "Rock_Sandstone"
    },
    {
      "x": -1,
      "y": -1,
      "z": 4,
      "name": "Soil_Sand_White"
    },
    {
      "x": -1,
      "y": -3,
      "z": 5,
      "name": "Rock_Sandstone"
    },
    {
      "x": -1,
      "y": -2,
      "z": 5,
      "name": "Soil_Sand_White"
    },
    {
      "x": -1,
      "y": -3,
      "z": 6,
      "name": "Rock_Sandstone"
    },
    {
      "x": -1,
      "y": -2,
      "z": 6,
      "name": "Soil_Sand_White"
    },
    {
      "x": -1,
      "y": -3,
      "z": 7,
      "name": "Soil_Sand_White"
    },
    {
      "x": 0,
      "y": -3,
      "z": -26,
      "name": "Soil_Sand_White"
    },
    {
      "x": 0,
      "y": -3,
      "z": -25,
      "name": "Rock_Sandstone"
    },
    {
      "x": 0,
      "y": -2,
      "z": -25,
      "name": "Soil_Sand_White"
    },
    {
      "x": 0,
      "y": -3,
      "z": -24,
      "name": "Rock_Sandstone"
    },
    {
      "x": 0,
      "y": -2,
      "z": -24,
      "name": "Rock_Sandstone"
    },
    {
      "x": 0,
      "y": -1,
      "z": -24,
      "name": "Soil_Sand_White"
    },
    {
      "x": 0,
      "y": -3,
      "z": -23,
      "name": "Rock_Sandstone"
    },
    {
      "x": 0,
      "y": -2,
      "z": -23,
      "name": "Rock_Sandstone"
    },
    {
      "x": 0,
      "y": -1,
      "z": -23,
      "name": "Soil_Sand_White"
    },
    {
      "x": 0,
      "y": -2,
      "z": -22,
      "name": "Rock_Sandstone"
    },
    {
      "x": 0,
      "y": -1,
      "z": -22,
      "name": "Soil_Sand_White"
    },
    {
      "x": 0,
      "y": 0,
      "z": -22,
      "name": "Soil_Sand_White"
    },
    {
      "x": 0,
      "y": -2,
      "z": -21,
      "name": "Rock_Sandstone"
    },
    {
      "x": 0,
      "y": -1,
      "z": -21,
      "name": "Soil_Sand_White"
    },
    {
      "x": 0,
      "y": 0,
      "z": -21,
      "name": "Soil_Sand_White"
    },
    {
      "x": 0,
      "y": -2,
      "z": -20,
      "name": "Rock_Sandstone"
    },
    {
      "x": 0,
      "y": -1,
      "z": -20,
      "name": "Rock_Sandstone"
    },
    {
      "x": 0,
      "y": 0,
      "z": -20,
      "name": "Soil_Sand_White"
    },
    {
      "x": 0,
      "y": 1,
      "z": -20,
      "name": "Soil_Sand_White"
    },
    {
      "x": 0,
      "y": -2,
      "z": -19,
      "name": "Rock_Sandstone"
    },
    {
      "x": 0,
      "y": -1,
      "z": -19,
      "name": "Rock_Sandstone"
    },
    {
      "x": 0,
      "y": 0,
      "z": -19,
      "name": "Soil_Sand_White"
    },
    {
      "x": 0,
      "y": 1,
      "z": -19,
      "name": "Soil_Sand_White"
    },
    {
      "x": 0,
      "y": 2,
      "z": -19,
      "name": "Soil_Sand_White"
    },
    {
      "x": 0,
      "y": -2,
      "z": -18,
      "name": "Rock_Sandstone"
    },
    {
      "x": 0,
      "y": -1,
      "z": -18,
      "name": "Rock_Sandstone"
    },
    {
      "x": 0,
      "y": 0,
      "z": -18,
      "name": "Soil_Sand_White"
    },
    {
      "x": 0,
      "y": 1,
      "z": -18,
      "name": "Soil_Sand_White"
    },
    {
      "x": 0,
      "y": 2,
      "z": -18,
      "name": "Soil_Sand_White"
    },
    {
      "x": 0,
      "y": -3,
      "z": -17,
      "name": "Rock_Sandstone"
    },
    {
      "x": 0,
      "y": -2,
      "z": -17,
      "name": "Rock_Sandstone"
    },
    {
      "x": 0,
      "y": -1,
      "z": -17,
      "name": "Rock_Sandstone"
    },
    {
      "x": 0,
      "y": 0,
      "z": -17,
      "name": "Soil_Sand_White"
    },
    {
      "x": 0,
      "y": 1,
      "z": -17,
      "name": "Soil_Sand_White"
    },
    {
      "x": 0,
      "y": 2,
      "z": -17,
      "name": "Soil_Sand_White"
    },
    {
      "x": 0,
      "y": 3,
      "z": -17,
      "name": "Soil_Gravel_Sand_White_Half",
      "support": 15
    },
    {
      "x": 0,
      "y": -2,
      "z": -16,
      "name": "Rock_Sandstone"
    },
    {
      "x": 0,
      "y": -1,
      "z": -16,
      "name": "Rock_Sandstone"
    },
    {
      "x": 0,
      "y": 0,
      "z": -16,
      "name": "Soil_Sand_White"
    },
    {
      "x": 0,
      "y": 1,
      "z": -16,
      "name": "Metal_Iron_Stairs",
      "rotation": 8
    },
    {
      "x": 0,
      "y": 2,
      "z": -16,
      "name": "OrbisGalactic_Block_Ship_Window"
    },
    {
      "x": 0,
      "y": 3,
      "z": -16,
      "name": "Metal_Iron_Stairs",
      "rotation": 2
    },
    {
      "x": 0,
      "y": -2,
      "z": -15,
      "name": "Rock_Sandstone"
    },
    {
      "x": 0,
      "y": -1,
      "z": -15,
      "name": "Rock_Sandstone"
    },
    {
      "x": 0,
      "y": 0,
      "z": -15,
      "name": "Metal_Iron_Half",
      "rotation": 8
    },
    {
      "x": 0,
      "y": 1,
      "z": -15,
      "name": "Metal_Iron_Stairs"
    },
    {
      "x": 0,
      "y": 2,
      "z": -15,
      "name": "Empty"
    },
    {
      "x": 0,
      "y": 3,
      "z": -15,
      "name": "Metal_Iron_Stairs",
      "rotation": 10
    },
    {
      "x": 0,
      "y": 4,
      "z": -15,
      "name": "Metal_Iron_Half"
    },
    {
      "x": 0,
      "y": -2,
      "z": -14,
      "name": "Rock_Sandstone"
    },
    {
      "x": 0,
      "y": -1,
      "z": -14,
      "name": "Rock_Sandstone"
    },
    {
      "x": 0,
      "y": 0,
      "z": -14,
      "name": "Metal_Iron_Decorative",
      "rotation": 4
    },
    {
      "x": 0,
      "y": 1,
      "z": -14,
      "name": "Metal_Iron_Half"
    },
    {
      "x": 0,
      "y": 2,
      "z": -14,
      "name": "Empty"
    },
    {
      "x": 0,
      "y": 3,
      "z": -14,
      "name": "Empty"
    },
    {
      "x": 0,
      "y": 4,
      "z": -14,
      "name": "Metal_Iron_Half"
    },
    {
      "x": 0,
      "y": -2,
      "z": -13,
      "name": "Rock_Sandstone"
    },
    {
      "x": 0,
      "y": -1,
      "z": -13,
      "name": "Rock_Sandstone"
    },
    {
      "x": 0,
      "y": 0,
      "z": -13,
      "name": "Metal_Iron_Decorative",
      "rotation": 4
    },
    {
      "x": 0,
      "y": 1,
      "z": -13,
      "name": "Empty"
    },
    {
      "x": 0,
      "y": 2,
      "z": -13,
      "name": "Empty"
    },
    {
      "x": 0,
      "y": 3,
      "z": -13,
      "name": "Empty"
    },
    {
      "x": 0,
      "y": 4,
      "z": -13,
      "name": "Metal_Iron"
    },
    {
      "x": 0,
      "y": -1,
      "z": -12,
      "name": "Rock_Sandstone"
    },
    {
      "x": 0,
      "y": 0,
      "z": -12,
      "name": "Metal_Iron_Decorative",
      "rotation": 4
    },
    {
      "x": 0,
      "y": 1,
      "z": -12,
      "name": "Empty"
    },
    {
      "x": 0,
      "y": 2,
      "z": -12,
      "name": "Empty"
    },
    {
      "x": 0,
      "y": 3,
      "z": -12,
      "name": "Empty"
    },
    {
      "x": 0,
      "y": 4,
      "z": -12,
      "name": "Metal_Iron"
    },
    {
      "x": 0,
      "y": -1,
      "z": -11,
      "name": "Rock_Sandstone"
    },
    {
      "x": 0,
      "y": 0,
      "z": -11,
      "name": "Metal_Iron_Decorative",
      "rotation": 4
    },
    {
      "x": 0,
      "y": 1,
      "z": -11,
      "name": "Empty"
    },
    {
      "x": 0,
      "y": 2,
      "z": -11,
      "name": "Empty"
    },
    {
      "x": 0,
      "y": 3,
      "z": -11,
      "name": "Empty"
    },
    {
      "x": 0,
      "y": 4,
      "z": -11,
      "name": "Metal_Iron"
    },
    {
      "x": 0,
      "y": -1,
      "z": -10,
      "name": "Rock_Sandstone"
    },
    {
      "x": 0,
      "y": 0,
      "z": -10,
      "name": "Metal_Iron_Decorative",
      "rotation": 4
    },
    {
      "x": 0,
      "y": 1,
      "z": -10,
      "name": "Empty"
    },
    {
      "x": 0,
      "y": 2,
      "z": -10,
      "name": "Empty"
    },
    {
      "x": 0,
      "y": 3,
      "z": -10,
      "name": "Empty"
    },
    {
      "x": 0,
      "y": 4,
      "z": -10,
      "name": "Metal_Iron"
    },
    {
      "x": 0,
      "y": -1,
      "z": -9,
      "name": "Rock_Sandstone"
    },
    {
      "x": 0,
      "y": 0,
      "z": -9,
      "name": "Metal_Iron_Decorative",
      "rotation": 4
    },
    {
      "x": 0,
      "y": 1,
      "z": -9,
      "name": "Metal_Iron_Ornate"
    },
    {
      "x": 0,
      "y": 2,
      "z": -9,
      "name": "Metal_Iron_Smooth"
    },
    {
      "x": 0,
      "y": 3,
      "z": -9,
      "name": "Metal_Iron_Ornate"
    },
    {
      "x": 0,
      "y": 4,
      "z": -9,
      "name": "Metal_Iron"
    },
    {
      "x": 0,
      "y": -1,
      "z": -8,
      "name": "Rock_Sandstone"
    },
    {
      "x": 0,
      "y": 0,
      "z": -8,
      "name": "Soil_Sand_White"
    },
    {
      "x": 0,
      "y": 1,
      "z": -8,
      "name": "Empty"
    },
    {
      "x": 0,
      "y": 2,
      "z": -8,
      "name": "Metal_Iron_Pipe_Large_Mouthpiece",
      "support": 15,
      "rotation": 6
    },
    {
      "x": 0,
      "y": 3,
      "z": -8,
      "name": "Empty"
    },
    {
      "x": 0,
      "y": -2,
      "z": -7,
      "name": "Rock_Sandstone"
    },
    {
      "x": 0,
      "y": -1,
      "z": -7,
      "name": "Rock_Sandstone"
    },
    {
      "x": 0,
      "y": 0,
      "z": -7,
      "name": "Soil_Sand_White"
    },
    {
      "x": 0,
      "y": 1,
      "z": -7,
      "name": "Empty"
    },
    {
      "x": 0,
      "y": 2,
      "z": -7,
      "name": "Metal_Iron_Pipe_Short",
      "support": 15
    },
    {
      "x": 0,
      "y": 3,
      "z": -7,
      "name": "Empty"
    },
    {
      "x": 0,
      "y": -2,
      "z": -6,
      "name": "Rock_Sandstone"
    },
    {
      "x": 0,
      "y": -1,
      "z": -6,
      "name": "Rock_Sandstone"
    },
    {
      "x": 0,
      "y": 0,
      "z": -6,
      "name": "Soil_Gravel_Sand_White_Half",
      "support": 15
    },
    {
      "x": 0,
      "y": 1,
      "z": -6,
      "name": "Empty"
    },
    {
      "x": 0,
      "y": 2,
      "z": -6,
      "name": "Empty"
    },
    {
      "x": 0,
      "y": 3,
      "z": -6,
      "name": "Empty"
    },
    {
      "x": 0,
      "y": -2,
      "z": -5,
      "name": "Rock_Sandstone"
    },
    {
      "x": 0,
      "y": -1,
      "z": -5,
      "name": "Rock_Sandstone"
    },
    {
      "x": 0,
      "y": 0,
      "z": -5,
      "name": "Soil_Gravel_Sand_White_Half",
      "support": 15
    },
    {
      "x": 0,
      "y": 1,
      "z": -5,
      "name": "Metal_Iron_Pipe_Short",
      "support": 15,
      "rotation": 1
    },
    {
      "x": 0,
      "y": 2,
      "z": -5,
      "name": "Empty"
    },
    {
      "x": 0,
      "y": 3,
      "z": -5,
      "name": "Empty"
    },
    {
      "x": 0,
      "y": -2,
      "z": -4,
      "name": "Rock_Sandstone"
    },
    {
      "x": 0,
      "y": -1,
      "z": -4,
      "name": "Rock_Sandstone"
    },
    {
      "x": 0,
      "y": 0,
      "z": -4,
      "name": "Soil_Sand_White"
    },
    {
      "x": 0,
      "y": 1,
      "z": -4,
      "name": "Soil_Gravel_Sand_White_Half",
      "support": 15
    },
    {
      "x": 0,
      "y": 2,
      "z": -4,
      "name": "Empty"
    },
    {
      "x": 0,
      "y": 3,
      "z": -4,
      "name": "Empty"
    },
    {
      "x": 0,
      "y": -2,
      "z": -3,
      "name": "Rock_Sandstone"
    },
    {
      "x": 0,
      "y": -1,
      "z": -3,
      "name": "Rock_Sandstone"
    },
    {
      "x": 0,
      "y": 0,
      "z": -3,
      "name": "Soil_Sand_White"
    },
    {
      "x": 0,
