{
  "version": 8,
  "blockIdVersion": 11,
  "anchorX": 0,
  "anchorY": 0,
  "anchorZ": 0,
  "blocks": [
    {
      "x": -2,
      "y": 0,
      "z": 1,
      "name": "OrbisGalactic_Scrap_Block"
    },
    {
      "x": -2,
      "y": 0,
      "z": 2,
      "name": "OrbisGalactic_Scrap_Block"
    },
    {
      "x": -1,
      "y": 0,
      "z": 0,
      "name": "OrbisGalactic_Scrap_Block"
    },
    {
      "x": -1,
      "y": 1,
      "z": 0,
      "name": "OrbisGalactic_Scrap_Block"
    },
    {
      "x": -1,
      "y": 2,
      "z": 0,
      "name": "OrbisGalactic_Scrap_Block"
    },
    {
      "x": -1,
      "y": 0,
      "z": 1,
      "name": "OrbisGalactic_Scrap_Block"
    },
    {
      "x": -1,
      "y": 1,
      "z": 1,
      "name": "OrbisGalactic_Scrap_Block"
    },
    {
      "x": -1,
      "y": 2,
      "z": 1,
      "name": "OrbisGalactic_Scrap_Block"
    },
    {
      "x": -1,
      "y": 0,
      "z": 2,
      "name": "OrbisGalactic_Scrap_Block"
    },
    {
      "x": -1,
      "y": 0,
      "z": 3,
      "name": "OrbisGalactic_Scrap_Block"
    },
    {
      "x": 0,
      "y": 0,
      "z": -1,
      "name": "OrbisGalactic_Scrap_Block"
    },
    {
      "x": 0,
      "y": 2,
      "z": -1,
      "name": "OrbisGalactic_Scrap_Block"
    },
    {
      "x": 0,
      "y": 0,
      "z": 0,
      "name": "OrbisGalactic_Scrap_Block"
    },
    {
      "x": 0,
      "y": 1,
      "z": 0,
      "name": "OrbisGalactic_Scrap_Block"
    },
    {
      "x": 0,
      "y": 2,
      "z": 0,
      "name": "OrbisGalactic_Scrap_Block"
    },
    {
      "x": 0,
      "y": 3,
      "z": 0,
      "name": "OrbisGalactic_Scrap_Block"
    },
    {
      "x": 0,
      "y": 0,
      "z": 1,
      "name": "OrbisGalactic_Scrap_Block"
    },
    {
      "x": 0,
      "y": 1,
      "z": 1,
      "name": "OrbisGalactic_Scrap_Block"
    },
    {
      "x": 0,
      "y": 0,
      "z": 2,
      "name": "OrbisGalactic_Scrap_Block"
    },
    {
      "x": 0,
      "y": 1,
      "z": 2,
      "name": "OrbisGalactic_Scrap_Block"
    },
    {
      "x": 0,
      "y": 0,
      "z": 3,
      "name": "OrbisGalactic_Scrap_Block"
    },
    {
      "x": 1,
      "y": 0,
      "z": -1,
      "name": "OrbisGalactic_Scrap_Block"
    },
    {
      "x": 1,
      "y": 0,
      "z": 0,
      "name": "OrbisGalactic_Scrap_Block"
    },
    {
      "x": 1,
      "y": 1,
      "z": 0,
      "name": "OrbisGalactic_Scrap_Block"
    },
    {
      "x": 1,
      "y": 2,
      "z": 0,
      "name": "OrbisGalactic_Scrap_Block"
    },
    {
      "x": 1,
      "y": 0,
      "z": 1,
      "name": "OrbisGalactic_Scrap_Block"
    },
    {
      "x": 1,
      "y": 1,
      "z": 1,
      "name": "OrbisGalactic_Scrap_Block"
    },
    {
      "x": 1,
      "y": 0,
      "z": 2,
      "name": "OrbisGalactic_Scrap_Block"
    },
    {
      "x": 2,
      "y": 0,
      "z": 0,
      "name": "OrbisGalactic_Scrap_Block"
    },
    {
      "x": 2,
      "y": 0,
      "z": 1,
      "name": "OrbisGalactic_Scrap_Block"
    },
    {
      "x": 3,
      "y": 0,
      "z": 0,
      "name": "OrbisGalactic_Scrap_Block"
    }
  ],
  "fluids": [
    {
      "x": -2,
      "y": 0,
      "z": 1,
      "name": "Empty",
      "level": 0
    },
    {
      "x": -2,
      "y": 0,
      "z": 2,
      "name": "Empty",
      "level": 0
    },
    {
      "x": -1,
      "y": 0,
      "z": 0,
      "name": "Empty",
      "level": 0
    },
    {
      "x": -1,
      "y": 1,
      "z": 0,
      "name": "Empty",
      "level": 0
    },
    {
      "x": -1,
      "y": 2,
      "z": 0,
      "name": "Empty",
      "level": 0
    },
    {
      "x": -1,
      "y": 0,
      "z": 1,
      "name": "Empty",
      "level": 0
    },
    {
      "x": -1,
      "y": 1,
      "z": 1,
      "name": "Empty",
      "level": 0
    },
    {
      "x": -1,
      "y": 2,
      "z": 1,
      "name": "Empty",
      "level": 0
    },
    {
      "x": -1,
      "y": 0,
      "z": 2,
      "name": "Empty",
      "level": 0
    },
    {
      "x": -1,
      "y": 0,
      "z": 3,
      "name": "Empty",
      "level": 0
    },
    {
      "x": 0,
      "y": 0,
      "z": -1,
      "name": "Empty",
      "level": 0
    },
    {
      "x": 0,
      "y": 2,
      "z": -1,
      "name": "Empty",
      "level": 0
    },
    {
      "x": 0,
      "y": 0,
      "z": 0,
      "name": "Empty",
      "level": 0
    },
    {
      "x": 0,
      "y": 1,
      "z": 0,
      "name": "Empty",
      "level": 0
    },
    {
      "x": 0,
      "y": 2,
      "z": 0,
      "name": "Empty",
      "level": 0
    },
    {
      "x": 0,
      "y": 3,
      "z": 0,
      "name": "Empty",
      "level": 0
    },
    {
      "x": 0,
      "y": 0,
      "z": 1,
      "name": "Empty",
      "level": 0
    },
    {
      "x": 0,
      "y": 1,
      "z": 1,
      "name": "Empty",
      "level": 0
    },
    {
      "x": 0,
      "y": 0,
      "z": 2,
      "name": "Empty",
      "level": 0
    },
    {
      "x": 0,
      "y": 1,
      "z": 2,
      "name": "Empty",
      "level": 0
    },
    {
      "x": 0,
      "y": 0,
      "z": 3,
      "name": "Empty",
      "level": 0
    },
    {
      "x": 1,
      "y": 0,
      "z": -1,
      "name": "Empty",
      "level": 0
    },
    {
      "x": 1,
      "y": 0,
      "z": 0,
      "name": "Empty",
      "level": 0
    },
    {
      "x": 1,
      "y": 1,
      "z": 0,
      "name": "Empty",
      "level": 0
    },
    {
      "x": 1,
      "y": 2,
      "z": 0,
      "name": "Empty",
      "level": 0
    },
    {
      "x": 1,
      "y": 0,
      "z": 1,
      "name": "Empty",
      "level": 0
    },
    {
      "x": 1,
      "y": 1,
      "z": 1,
      "name": "Empty",
      "level": 0
    },
    {
      "x": 1,
      "y": 0,
      "z": 2,
      "name": "Empty",
      "level": 0
    },
    {
      "x": 2,
      "y": 0,
      "z": 0,
      "name": "Empty",
      "level": 0
    },
    {
      "x": 2,
      "y": 0,
      "z": 1,
      "name": "Empty",
      "level": 0
    },
    {
      "x": 3,
      "y": 0,
      "z": 0,
      "name": "Empty",
      "level": 0
    }
  ]
}