{
  "version": 8,
  "blockIdVersion": 11,
  "anchorX": 0,
  "anchorY": 0,
  "anchorZ": 0,
  "blocks": [
    {
      "x": -5,
      "y": 0,
      "z": -3,
      "name": "OrbisGalactic_Scrap_Block"
    },
    {
      "x": -5,
      "y": 1,
      "z": -3,
      "name": "OrbisGalactic_Scrap_Block"
    },
    {
      "x": -5,
      "y": 2,
      "z": -3,
      "name": "OrbisGalactic_Scrap_Block"
    },
    {
      "x": -5,
      "y": 3,
      "z": -3,
      "name": "OrbisGalactic_Scrap_Block"
    },
    {
      "x": -5,
      "y": 0,
      "z": -2,
      "name": "OrbisGalactic_Scrap_Block"
    },
    {
      "x": -5,
      "y": 1,
      "z": -2,
      "name": "OrbisGalactic_Scrap_Block"
    },
    {
      "x": -4,
      "y": 0,
      "z": -3,
      "name": "OrbisGalactic_Scrap_Block"
    },
    {
      "x": -4,
      "y": 1,
      "z": -3,
      "name": "OrbisGalactic_Scrap_Block"
    },
    {
      "x": -4,
      "y": 2,
      "z": -3,
      "name": "OrbisGalactic_Scrap_Block"
    },
    {
      "x": -4,
      "y": 1,
      "z": -2,
      "name": "OrbisGalactic_Scrap_Block"
    },
    {
      "x": -3,
      "y": 0,
      "z": -3,
      "name": "OrbisGalactic_Scrap_Block"
    },
    {
      "x": -3,
      "y": 1,
      "z": 0,
      "name": "OrbisGalactic_Block_Spaceship_Hull_Plating_Rusty"
    },
    {
      "x": -2,
      "y": 1,
      "z": 0,
      "name": "OrbisGalactic_Block_Spaceship_Hull_Plating_Rusty"
    },
    {
      "x": -2,
      "y": 1,
      "z": 1,
      "name": "OrbisGalactic_Block_Spaceship_Hull_Plating_Rusty"
    },
    {
      "x": -1,
      "y": 1,
      "z": 0,
      "name": "OrbisGalactic_Block_Spaceship_Hull_Plating_Rusty"
    },
    {
      "x": -1,
      "y": 0,
      "z": 1,
      "name": "OrbisGalactic_Block_Spaceship_Hull_Plating"
    },
    {
      "x": -1,
      "y": 1,
      "z": 1,
      "name": "OrbisGalactic_Block_Spaceship_Hull_Plating_Rusting"
    },
    {
      "x": 0,
      "y": 1,
      "z": 0,
      "name": "OrbisGalactic_Block_Spaceship_Hull_Plating_Rusting"
    },
    {
      "x": 0,
      "y": 0,
      "z": 1,
      "name": "OrbisGalactic_Block_Spaceship_Hull_Plating"
    },
    {
      "x": 0,
      "y": 1,
      "z": 1,
      "name": "OrbisGalactic_Block_Spaceship_Hull_Plating"
    },
    {
      "x": 1,
      "y": 1,
      "z": -1,
      "name": "OrbisGalactic_Block_Spaceship_Hull_Plating_Rusty"
    },
    {
      "x": 1,
      "y": 2,
      "z": -1,
      "name": "OrbisGalactic_Block_Spaceship_Hull_Plating_Rusty"
    },
    {
      "x": 1,
      "y": 0,
      "z": 0,
      "name": "OrbisGalactic_Block_Spaceship_Hull_Plating_Rusting"
    },
    {
      "x": 1,
      "y": 1,
      "z": 0,
      "name": "OrbisGalactic_Block_Spaceship_Hull_Plating"
    },
    {
      "x": 1,
      "y": 0,
      "z": 1,
      "name": "OrbisGalactic_Block_Spaceship_Hull_Plating"
    },
    {
      "x": 1,
      "y": 1,
      "z": 1,
      "name": "OrbisGalactic_Block_Spaceship_Hull_Plating"
    },
    {
      "x": 2,
      "y": 0,
      "z": -1,
      "name": "OrbisGalactic_Block_Spaceship_Hull_Plating"
    },
    {
      "x": 2,
      "y": 1,
      "z": -1,
      "name": "OrbisGalactic_Block_Spaceship_Hull_Plating"
    },
    {
      "x": 2,
      "y": 2,
      "z": -1,
      "name": "OrbisGalactic_Block_Spaceship_Hull_Plating_Rusting"
    },
    {
      "x": 2,
      "y": 3,
      "z": -1,
      "name": "OrbisGalactic_Block_Spaceship_Hull_Plating_Rusting"
    },
    {
      "x": 2,
      "y": 4,
      "z": -1,
      "name": "OrbisGalactic_Block_Spaceship_Hull_Plating_Rusty"
    },
    {
      "x": 2,
      "y": 0,
      "z": 0,
      "name": "OrbisGalactic_Block_Spaceship_Hull_Plating"
    },
    {
      "x": 2,
      "y": 1,
      "z": 0,
      "name": "OrbisGalactic_Block_Spaceship_Hull_Plating"
    },
    {
      "x": 2,
      "y": 0,
      "z": 1,
      "name": "OrbisGalactic_Block_Spaceship_Hull_Plating"
    },
    {
      "x": 2,
      "y": 1,
      "z": 1,
      "name": "OrbisGalactic_Block_Spaceship_Hull_Plating"
    },
    {
      "x": 2,
      "y": 1,
      "z": 3,
      "name": "OrbisGalactic_Scrap_Block"
    },
    {
      "x": 2,
      "y": 2,
      "z": 3,
      "name": "OrbisGalactic_Scrap_Block"
    },
    {
      "x": 2,
      "y": 3,
      "z": 3,
      "name": "OrbisGalactic_Scrap_Block"
    },
    {
      "x": 2,
      "y": 0,
      "z": 4,
      "name": "OrbisGalactic_Scrap_Block"
    },
    {
      "x": 2,
      "y": 1,
      "z": 4,
      "name": "OrbisGalactic_Scrap_Block"
    },
    {
      "x": 3,
      "y": 0,
      "z": -1,
      "name": "OrbisGalactic_Block_Spaceship_Hull_Plating"
    },
    {
      "x": 3,
      "y": 1,
      "z": -1,
      "name": "OrbisGalactic_Block_Spaceship_Hull_Plating"
    },
    {
      "x": 3,
      "y": 2,
      "z": -1,
      "name": "OrbisGalactic_Block_Spaceship_Hull_Plating"
    },
    {
      "x": 3,
      "y": 3,
      "z": -1,
      "name": "OrbisGalactic_Block_Spaceship_Hull_Plating_Rusting"
    },
    {
      "x": 3,
      "y": 4,
      "z": -1,
      "name": "OrbisGalactic_Block_Spaceship_Hull_Plating_Rusting"
    },
    {
      "x": 3,
      "y": 5,
      "z": -1,
      "name": "OrbisGalactic_Block_Spaceship_Hull_Plating_Rusty"
    },
    {
      "x": 3,
      "y": 6,
      "z": -1,
      "name": "OrbisGalactic_Block_Spaceship_Hull_Plating_Rusty"
    },
    {
      "x": 3,
      "y": 0,
      "z": 0,
      "name": "OrbisGalactic_Block_Spaceship_Hull_Plating"
    },
    {
      "x": 3,
      "y": 1,
      "z": 0,
      "name": "OrbisGalactic_Block_Spaceship_Hull_Plating"
    },
    {
      "x": 3,
      "y": 2,
      "z": 0,
      "name": "OrbisGalactic_Block_Spaceship_Hull_Plating_Rusting"
    },
    {
      "x": 3,
      "y": 1,
      "z": 3,
      "name": "OrbisGalactic_Scrap_Block"
    },
    {
      "x": 3,
      "y": 2,
      "z": 3,
      "name": "OrbisGalactic_Scrap_Block"
    },
    {
      "x": 3,
      "y": 1,
      "z": 4,
      "name": "OrbisGalactic_Scrap_Block"
    },
    {
      "x": 4,
      "y": 0,
      "z": -1,
      "name": "OrbisGalactic_Block_Spaceship_Hull_Plating"
    },
    {
      "x": 4,
      "y": 1,
      "z": -1,
      "name": "OrbisGalactic_Block_Spaceship_Hull_Plating"
    },
    {
      "x": 4,
      "y": 2,
      "z": -1,
      "name": "OrbisGalactic_Block_Spaceship_Hull_Plating"
    },
    {
      "x": 4,
      "y": 3,
      "z": -1,
      "name": "OrbisGalactic_Block_Spaceship_Hull_Plating_Rusting"
    },
    {
      "x": 4,
      "y": 4,
      "z": -1,
      "name": "OrbisGalactic_Block_Spaceship_Hull_Plating_Rusting"
    },
    {
      "x": 4,
      "y": 5,
      "z": -1,
      "name": "OrbisGalactic_Block_Spaceship_Hull_Plating_Rusting"
    },
    {
      "x": 4,
      "y": 6,
      "z": -1,
      "name": "OrbisGalactic_Block_Spaceship_Hull_Plating_Rusty"
    },
    {
      "x": 4,
      "y": 7,
      "z": -1,
      "name": "OrbisGalactic_Block_Spaceship_Hull_Plating_Rusty"
    },
    {
      "x": 4,
      "y": 8,
      "z": -1,
      "name": "OrbisGalactic_Block_Spaceship_Hull_Plating_Rusty"
    },
    {
      "x": 4,
      "y": 0,
      "z": 0,
      "name": "OrbisGalactic_Block_Spaceship_Hull_Plating"
    },
    {
      "x": 4,
      "y": 1,
      "z": 0,
      "name": "OrbisGalactic_Block_Spaceship_Hull_Plating"
    },
    {
      "x": 4,
      "y": 2,
      "z": 0,
      "name": "OrbisGalactic_Block_Spaceship_Hull_Plating_Rusting"
    }
  ],
  "fluids": [
    {
      "x": -5,
      "y": 0,
      "z": -3,
      "name": "Empty",
      "level": 0
    },
    {
      "x": -5,
      "y": 1,
      "z": -3,
      "name": "Empty",
      "level": 0
    },
    {
      "x": -5,
      "y": 2,
      "z": -3,
      "name": "Empty",
      "level": 0
    },
    {
      "x": -5,
      "y": 3,
      "z": -3,
      "name": "Empty",
      "level": 0
    },
    {
      "x": -5,
      "y": 0,
      "z": -2,
      "name": "Empty",
      "level": 0
    },
    {
      "x": -5,
      "y": 1,
      "z": -2,
      "name": "Empty",
      "level": 0
    },
    {
      "x": -4,
      "y": 0,
      "z": -3,
      "name": "Empty",
      "level": 0
    },
    {
      "x": -4,
      "y": 1,
      "z": -3,
      "name": "Empty",
      "level": 0
    },
    {
      "x": -4,
      "y": 2,
      "z": -3,
      "name": "Empty",
      "level": 0
    },
    {
      "x": -4,
      "y": 1,
      "z": -2,
      "name": "Empty",
      "level": 0
    },
    {
      "x": -3,
      "y": 0,
      "z": -3,
      "name": "Empty",
      "level": 0
    },
    {
      "x": -3,
      "y": 1,
      "z": 0,
      "name": "Empty",
      "level": 0
    },
    {
      "x": -2,
      "y": 1,
      "z": 0,
      "name": "Empty",
      "level": 0
    },
    {
      "x": -2,
      "y": 1,
      "z": 1,
      "name": "Empty",
      "level": 0
    },
    {
      "x": -1,
      "y": 1,
      "z": 0,
      "name": "Empty",
      "level": 0
    },
    {
      "x": -1,
      "y": 0,
      "z": 1,
      "name": "Empty",
      "level": 0
    },
    {
      "x": -1,
      "y": 1,
      "z": 1,
      "name": "Empty",
      "level": 0
    },
    {
      "x": 0,
      "y": 1,
      "z": 0,
      "name": "Empty",
      "level": 0
    },
    {
      "x": 0,
      "y": 0,
      "z": 1,
      "name": "Empty",
      "level": 0
    },
    {
      "x": 0,
      "y": 1,
      "z": 1,
      "name": "Empty",
      "level": 0
    },
    {
      "x": 1,
      "y": 1,
      "z": -1,
      "name": "Empty",
      "level": 0
    },
    {
      "x": 1,
      "y": 2,
      "z": -1,
      "name": "Empty",
      "level": 0
    },
    {
      "x": 1,
      "y": 0,
      "z": 0,
      "name": "Empty",
      "level": 0
    },
    {
      "x": 1,
      "y": 1,
      "z": 0,
      "name": "Empty",
      "level": 0
    },
    {
      "x": 1,
      "y": 0,
      "z": 1,
      "name": "Empty",
      "level": 0
    },
    {
      "x": 1,
      "y": 1,
      "z": 1,
      "name": "Empty",
      "level": 0
    },
    {
      "x": 2,
      "y": 0,
      "z": -1,
      "name": "Empty",
      "level": 0
    },
    {
      "x": 2,
      "y": 1,
      "z": -1,
      "name": "Empty",
      "level": 0
    },
    {
      "x": 2,
      "y": 2,
      "z": -1,
      "name": "Empty",
      "level": 0
    },
    {
      "x": 2,
      "y": 3,
      "z": -1,
      "name": "Empty",
      "level": 0
    },
    {
      "x": 2,
      "y": 4,
      "z": -1,
      "name": "Empty",
      "level": 0
    },
    {
      "x": 2,
      "y": 0,
      "z": 0,
      "name": "Empty",
      "level": 0
    },
    {
      "x": 2,
      "y": 1,
      "z": 0,
      "name": "Empty",
      "level": 0
    },
    {
      "x": 2,
      "y": 0,
      "z": 1,
      "name": "Empty",
      "level": 0
    },
    {
      "x": 2,
      "y": 1,
      "z": 1,
      "name": "Empty",
      "level": 0
    },
    {
      "x": 2,
      "y": 1,
      "z": 3,
      "name": "Empty",
      "level": 0
    },
    {
      "x": 2,
      "y": 2,
      "z": 3,
      "name": "Empty",
      "level": 0
    },
    {
      "x": 2,
      "y": 3,
      "z": 3,
      "name": "Empty",
      "level": 0
    },
    {
      "x": 2,
      "y": 0,
      "z": 4,
      "name": "Empty",
      "level": 0
    },
    {
      "x": 2,
      "y": 1,
      "z": 4,
      "name": "Empty",
      "level": 0
    },
    {
      "x": 3,
      "y": 0,
      "z": -1,
      "name": "Empty",
      "level": 0
    },
    {
      "x": 3,
      "y": 1,
      "z": -1,
      "name": "Empty",
      "level": 0
    },
    {
      "x": 3,
      "y": 2,
      "z": -1,
      "name": "Empty",
      "level": 0
    },
    {
      "x": 3,
      "y": 3,
      "z": -1,
      "name": "Empty",
      "level": 0
    },
    {
      "x": 3,
      "y": 4,
      "z": -1,
      "name": "Empty",
      "level": 0
    },
    {
      "x": 3,
      "y": 5,
      "z": -1,
      "name": "Empty",
      "level": 0
    },
    {
      "x": 3,
      "y": 6,
      "z": -1,
      "name": "Empty",
      "level": 0
    },
    {
      "x": 3,
      "y": 0,
      "z": 0,
      "name": "Empty",
      "level": 0
    },
    {
      "x": 3,
      "y": 1,
      "z": 0,
      "name": "Empty",
      "level": 0
    },
    {
      "x": 3,
      "y": 2,
      "z": 0,
      "name": "Empty",
      "level": 0
    },
    {
      "x": 3,
      "y": 1,
      "z": 3,
      "name": "Empty",
      "level": 0
    },
    {
      "x": 3,
      "y": 2,
      "z": 3,
      "name": "Empty",
      "level": 0
    },
    {
      "x": 3,
      "y": 1,
      "z": 4,
      "name": "Empty",
      "level": 0
    },
    {
      "x": 4,
      "y": 0,
      "z": -1,
      "name": "Empty",
      "level": 0
    },
    {
      "x": 4,
      "y": 1,
      "z": -1,
      "name": "Empty",
      "level": 0
    },
    {
      "x": 4,
      "y": 2,
      "z": -1,
      "name": "Empty",
      "level": 0
    },
    {
      "x": 4,
      "y": 3,
      "z": -1,
      "name": "Empty",
      "level": 0
    },
    {
      "x": 4,
      "y": 4,
      "z": -1,
      "name": "Empty",
      "level": 0
    },
    {
      "x": 4,
      "y": 5,
      "z": -1,
      "name": "Empty",
      "level": 0
    },
    {
      "x": 4,
      "y": 6,
      "z": -1,
      "name": "Empty",
      "level": 0
    },
    {
      "x": 4,
      "y": 7,
      "z": -1,
      "name": "Empty",
      "level": 0
    },
    {
      "x": 4,
      "y": 8,
      "z": -1,
      "name": "Empty",
      "level": 0
    },
    {
      "x": 4,
      "y": 0,
      "z": 0,
      "name": "Empty",
      "level": 0
    },
    {
      "x": 4,
      "y": 1,
      "z": 0,
      "name": "Empty",
      "level": 0
    },
    {
      "x": 4,
      "y": 2,
      "z": 0,
      "name": "Empty",
      "level": 0
    }
  ]
}