{
  "version": 8,
  "blockIdVersion": 11,
  "anchorX": 0,
  "anchorY": 0,
  "anchorZ": 0,
  "blocks": [
    {
      "x": -2,
      "y": 0,
      "z": -2,
      "name": "OrbisGalactic_Scrap_Block"
    },
    {
      "x": -2,
      "y": 0,
      "z": -1,
      "name": "OrbisGalactic_Block_Spaceship_Hull_Plating"
    },
    {
      "x": -2,
      "y": 3,
      "z": -1,
      "name": "OrbisGalactic_Block_Spaceship_Hull_Plating_Rusting"
    },
    {
      "x": -2,
      "y": 0,
      "z": 0,
      "name": "OrbisGalactic_Block_Spaceship_Hull_Plating"
    },
    {
      "x": -2,
      "y": 1,
      "z": 0,
      "name": "OrbisGalactic_Block_Spaceship_Hull_Plating"
    },
    {
      "x": -2,
      "y": 2,
      "z": 0,
      "name": "OrbisGalactic_Block_Spaceship_Hull_Plating_Rusting"
    },
    {
      "x": -2,
      "y": 3,
      "z": 0,
      "name": "OrbisGalactic_Block_Spaceship_Hull_Plating_Rusting"
    },
    {
      "x": -2,
      "y": 0,
      "z": 1,
      "name": "OrbisGalactic_Block_Spaceship_Hull_Plating"
    },
    {
      "x": -2,
      "y": 1,
      "z": 1,
      "name": "OrbisGalactic_Scrap_Block"
    },
    {
      "x": -2,
      "y": 2,
      "z": 1,
      "name": "OrbisGalactic_Scrap_Block"
    },
    {
      "x": -2,
      "y": 3,
      "z": 1,
      "name": "OrbisGalactic_Block_Spaceship_Hull_Plating_Rusty"
    },
    {
      "x": -2,
      "y": 0,
      "z": 2,
      "name": "OrbisGalactic_Block_Spaceship_Hull_Plating"
    },
    {
      "x": -2,
      "y": 1,
      "z": 2,
      "name": "OrbisGalactic_Block_Spaceship_Hull_Plating_Rusting"
    },
    {
      "x": -2,
      "y": 2,
      "z": 2,
      "name": "OrbisGalactic_Block_Spaceship_Hull_Plating_Rusting"
    },
    {
      "x": -2,
      "y": 3,
      "z": 2,
      "name": "OrbisGalactic_Block_Spaceship_Hull_Plating_Rusty"
    },
    {
      "x": -2,
      "y": 0,
      "z": 3,
      "name": "OrbisGalactic_Block_Spaceship_Hull_Plating"
    },
    {
      "x": -2,
      "y": 1,
      "z": 3,
      "name": "OrbisGalactic_Block_Spaceship_Hull_Plating_Rusting"
    },
    {
      "x": -2,
      "y": 0,
      "z": 4,
      "name": "OrbisGalactic_Block_Spaceship_Hull_Plating_Rusting"
    },
    {
      "x": -1,
      "y": 0,
      "z": -4,
      "name": "OrbisGalactic_Block_Spaceship_Hull_Plating"
    },
    {
      "x": -1,
      "y": 0,
      "z": -3,
      "name": "OrbisGalactic_Block_Spaceship_Hull_Plating"
    },
    {
      "x": -1,
      "y": 0,
      "z": -2,
      "name": "OrbisGalactic_Scrap_Block"
    },
    {
      "x": -1,
      "y": 3,
      "z": -2,
      "name": "OrbisGalactic_Block_Spaceship_Hull_Plating_Rusting"
    },
    {
      "x": -1,
      "y": 0,
      "z": -1,
      "name": "OrbisGalactic_Scrap_Block"
    },
    {
      "x": -1,
      "y": 3,
      "z": -1,
      "name": "OrbisGalactic_Block_Spaceship_Hull_Plating_Rusting"
    },
    {
      "x": -1,
      "y": 0,
      "z": 0,
      "name": "OrbisGalactic_Block_Spaceship_Hull_Plating"
    },
    {
      "x": -1,
      "y": 3,
      "z": 0,
      "name": "OrbisGalactic_Block_Spaceship_Hull_Plating_Rusty"
    },
    {
      "x": -1,
      "y": 0,
      "z": 1,
      "name": "OrbisGalactic_Block_Spaceship_Hull_Plating_Rusting"
    },
    {
      "x": -1,
      "y": 3,
      "z": 1,
      "name": "OrbisGalactic_Block_Spaceship_Hull_Plating_Rusting"
    },
    {
      "x": -1,
      "y": 0,
      "z": 2,
      "name": "OrbisGalactic_Block_Spaceship_Hull_Plating_Rusting"
    },
    {
      "x": -1,
      "y": 3,
      "z": 2,
      "name": "OrbisGalactic_Block_Spaceship_Hull_Plating_Rusting"
    },
    {
      "x": -1,
      "y": 0,
      "z": 3,
      "name": "OrbisGalactic_Block_Spaceship_Hull_Plating_Rusting"
    },
    {
      "x": -1,
      "y": 3,
      "z": 3,
      "name": "OrbisGalactic_Block_Spaceship_Hull_Plating_Rusty"
    },
    {
      "x": -1,
      "y": 0,
      "z": 4,
      "name": "OrbisGalactic_Block_Spaceship_Hull_Plating"
    },
    {
      "x": -1,
      "y": 0,
      "z": 5,
      "name": "OrbisGalactic_Block_Spaceship_Hull_Plating"
    },
    {
      "x": 0,
      "y": 0,
      "z": -3,
      "name": "OrbisGalactic_Block_Spaceship_Hull_Plating"
    },
    {
      "x": 0,
      "y": 0,
      "z": -2,
      "name": "OrbisGalactic_Block_Spaceship_Hull_Plating"
    },
    {
      "x": 0,
      "y": 0,
      "z": -1,
      "name": "OrbisGalactic_Block_Spaceship_Hull_Plating"
    },
    {
      "x": 0,
      "y": 3,
      "z": -1,
      "name": "OrbisGalactic_Block_Spaceship_Hull_Plating_Rusty"
    },
    {
      "x": 0,
      "y": 0,
      "z": 0,
      "name": "OrbisGalactic_Block_Spaceship_Hull_Plating"
    },
    {
      "x": 0,
      "y": 3,
      "z": 0,
      "name": "OrbisGalactic_Block_Spaceship_Hull_Plating_Rusty"
    },
    {
      "x": 0,
      "y": 0,
      "z": 1,
      "name": "OrbisGalactic_Block_Spaceship_Hull_Plating_Rusting"
    },
    {
      "x": 0,
      "y": 3,
      "z": 1,
      "name": "OrbisGalactic_Block_Spaceship_Hull_Plating_Rusting"
    },
    {
      "x": 0,
      "y": 0,
      "z": 2,
      "name": "OrbisGalactic_Block_Spaceship_Hull_Plating_Rusting"
    },
    {
      "x": 0,
      "y": 3,
      "z": 2,
      "name": "OrbisGalactic_Block_Spaceship_Hull_Plating_Rusty"
    },
    {
      "x": 0,
      "y": 0,
      "z": 3,
      "name": "OrbisGalactic_Block_Spaceship_Hull_Plating"
    },
    {
      "x": 0,
      "y": 3,
      "z": 3,
      "name": "OrbisGalactic_Block_Spaceship_Hull_Plating_Rusting"
    },
    {
      "x": 0,
      "y": 0,
      "z": 4,
      "name": "OrbisGalactic_Block_Spaceship_Hull_Plating"
    },
    {
      "x": 0,
      "y": 0,
      "z": 5,
      "name": "OrbisGalactic_Block_Spaceship_Hull_Plating"
    },
    {
      "x": 1,
      "y": 0,
      "z": -2,
      "name": "OrbisGalactic_Block_Spaceship_Hull_Plating"
    },
    {
      "x": 1,
      "y": 0,
      "z": -1,
      "name": "OrbisGalactic_Scrap_Block"
    },
    {
      "x": 1,
      "y": 0,
      "z": 0,
      "name": "OrbisGalactic_Block_Spaceship_Hull_Plating_Rusting"
    },
    {
      "x": 1,
      "y": 0,
      "z": 1,
      "name": "OrbisGalactic_Block_Spaceship_Hull_Plating_Rusting"
    },
    {
      "x": 1,
      "y": 3,
      "z": 1,
      "name": "OrbisGalactic_Block_Spaceship_Hull_Plating_Rusting"
    },
    {
      "x": 1,
      "y": 0,
      "z": 2,
      "name": "OrbisGalactic_Block_Spaceship_Hull_Plating_Rusting"
    },
    {
      "x": 1,
      "y": 3,
      "z": 2,
      "name": "OrbisGalactic_Block_Spaceship_Hull_Plating_Rusty"
    },
    {
      "x": 1,
      "y": 0,
      "z": 3,
      "name": "OrbisGalactic_Block_Spaceship_Hull_Plating"
    },
    {
      "x": 1,
      "y": 3,
      "z": 3,
      "name": "OrbisGalactic_Block_Spaceship_Hull_Plating_Rusty"
    },
    {
      "x": 1,
      "y": 0,
      "z": 4,
      "name": "OrbisGalactic_Block_Spaceship_Hull_Plating"
    },
    {
      "x": 1,
      "y": 0,
      "z": 5,
      "name": "OrbisGalactic_Block_Spaceship_Hull_Plating"
    },
    {
      "x": 2,
      "y": 0,
      "z": -1,
      "name": "OrbisGalactic_Block_Spaceship_Hull_Plating"
    },
    {
      "x": 2,
      "y": 0,
      "z": 0,
      "name": "OrbisGalactic_Block_Spaceship_Hull_Plating"
    },
    {
      "x": 2,
      "y": 1,
      "z": 0,
      "name": "OrbisGalactic_Block_Spaceship_Hull_Plating"
    },
    {
      "x": 2,
      "y": 2,
      "z": 0,
      "name": "OrbisGalactic_Block_Spaceship_Hull_Plating_Rusting"
    },
    {
      "x": 2,
      "y": 0,
      "z": 1,
      "name": "OrbisGalactic_Block_Spaceship_Hull_Plating"
    },
    {
      "x": 2,
      "y": 1,
      "z": 1,
      "name": "OrbisGalactic_Block_Spaceship_Hull_Plating_Rusting"
    },
    {
      "x": 2,
      "y": 2,
      "z": 1,
      "name": "OrbisGalactic_Scrap_Block"
    },
    {
      "x": 2,
      "y": 3,
      "z": 1,
      "name": "OrbisGalactic_Block_Spaceship_Hull_Plating_Rusty"
    },
    {
      "x": 2,
      "y": 0,
      "z": 2,
      "name": "OrbisGalactic_Block_Spaceship_Hull_Plating"
    },
    {
      "x": 2,
      "y": 1,
      "z": 2,
      "name": "OrbisGalactic_Block_Spaceship_Hull_Plating_Rusting"
    },
    {
      "x": 2,
      "y": 2,
      "z": 2,
      "name": "OrbisGalactic_Block_Spaceship_Hull_Plating_Rusting"
    },
    {
      "x": 2,
      "y": 3,
      "z": 2,
      "name": "OrbisGalactic_Block_Spaceship_Hull_Plating_Rusting"
    },
    {
      "x": 2,
      "y": 0,
      "z": 3,
      "name": "OrbisGalactic_Block_Spaceship_Hull_Plating"
    },
    {
      "x": 2,
      "y": 1,
      "z": 3,
      "name": "OrbisGalactic_Block_Spaceship_Hull_Plating_Rusting"
    },
    {
      "x": 2,
      "y": 2,
      "z": 3,
      "name": "OrbisGalactic_Block_Spaceship_Hull_Plating"
    },
    {
      "x": 2,
      "y": 0,
      "z": 4,
      "name": "OrbisGalactic_Block_Spaceship_Hull_Plating"
    }
  ]
}