{
  "version": 8,
  "blockIdVersion": 11,
  "anchorX": 0,
  "anchorY": 0,
  "anchorZ": 0,
  "blocks": [
    {
      "x": -5,
      "y": 0,
      "z": -2,
      "name": "Soil_Snow"
    },
    {
      "x": -5,
      "y": 0,
      "z": 8,
      "name": "Soil_Snow"
    },
    {
      "x": -4,
      "y": 0,
      "z": -2,
      "name": "Soil_Snow"
    },
    {
      "x": -4,
      "y": 0,
      "z": -1,
      "name": "Soil_Snow"
    },
    {
      "x": -4,
      "y": 0,
      "z": 0,
      "name": "Soil_Snow"
    },
    {
      "x": -4,
      "y": 0,
      "z": 4,
      "name": "Soil_Snow"
    },
    {
      "x": -4,
      "y": 0,
      "z": 5,
      "name": "Soil_Snow"
    },
    {
      "x": -4,
      "y": 0,
      "z": 6,
      "name": "Soil_Snow"
    },
    {
      "x": -4,
      "y": 0,
      "z": 7,
      "name": "Soil_Snow"
    },
    {
      "x": -4,
      "y": 0,
      "z": 8,
      "name": "Soil_Snow"
    },
    {
      "x": -4,
      "y": 0,
      "z": 9,
      "name": "Soil_Snow"
    },
    {
      "x": -3,
      "y": 0,
      "z": -3,
      "name": "Soil_Snow"
    },
    {
      "x": -3,
      "y": 0,
      "z": -2,
      "name": "Soil_Snow"
    },
    {
      "x": -3,
      "y": 0,
      "z": -1,
      "name": "Soil_Snow"
    },
    {
      "x": -3,
      "y": 0,
      "z": 0,
      "name": "Soil_Snow"
    },
    {
      "x": -3,
      "y": 0,
      "z": 1,
      "name": "Soil_Snow"
    },
    {
      "x": -3,
      "y": 0,
      "z": 2,
      "name": "Soil_Snow"
    },
    {
      "x": -3,
      "y": 0,
      "z": 3,
      "name": "Soil_Snow"
    },
    {
      "x": -3,
      "y": 0,
      "z": 4,
      "name": "Soil_Snow"
    },
    {
      "x": -3,
      "y": 0,
      "z": 5,
      "name": "Soil_Snow"
    },
    {
      "x": -3,
      "y": 1,
      "z": 5,
      "name": "Soil_Snow"
    },
    {
      "x": -3,
      "y": 0,
      "z": 6,
      "name": "Soil_Snow"
    },
    {
      "x": -3,
      "y": 1,
      "z": 6,
      "name": "Soil_Snow"
    },
    {
      "x": -3,
      "y": 0,
      "z": 7,
      "name": "Soil_Snow"
    },
    {
      "x": -3,
      "y": 0,
      "z": 8,
      "name": "Soil_Snow"
    },
    {
      "x": -3,
      "y": 1,
      "z": 8,
      "name": "Soil_Snow"
    },
    {
      "x": -3,
      "y": 0,
      "z": 9,
      "name": "Soil_Snow"
    },
    {
      "x": -3,
      "y": 0,
      "z": 10,
      "name": "Soil_Snow"
    },
    {
      "x": -2,
      "y": 0,
      "z": -7,
      "name": "Soil_Snow"
    },
    {
      "x": -2,
      "y": 0,
      "z": -6,
      "name": "Soil_Snow"
    },
    {
      "x": -2,
      "y": 0,
      "z": -5,
      "name": "Soil_Snow"
    },
    {
      "x": -2,
      "y": 0,
      "z": -4,
      "name": "Soil_Snow"
    },
    {
      "x": -2,
      "y": 1,
      "z": -4,
      "name": "Soil_Snow"
    },
    {
      "x": -2,
      "y": 0,
      "z": -3,
      "name": "Soil_Snow"
    },
    {
      "x": -2,
      "y": 1,
      "z": -3,
      "name": "Soil_Snow"
    },
    {
      "x": -2,
      "y": 0,
      "z": -2,
      "name": "Soil_Snow"
    },
    {
      "x": -2,
      "y": 0,
      "z": -1,
      "name": "Soil_Snow"
    },
    {
      "x": -2,
      "y": 0,
      "z": 0,
      "name": "Soil_Snow"
    },
    {
      "x": -2,
      "y": 0,
      "z": 1,
      "name": "Soil_Snow"
    },
    {
      "x": -2,
      "y": 0,
      "z": 2,
      "name": "Soil_Snow"
    },
    {
      "x": -2,
      "y": 0,
      "z": 3,
      "name": "Soil_Snow"
    },
    {
      "x": -2,
      "y": 1,
      "z": 3,
      "name": "Soil_Snow"
    },
    {
      "x": -2,
      "y": 0,
      "z": 4,
      "name": "Soil_Snow"
    },
    {
      "x": -2,
      "y": 1,
      "z": 4,
      "name": "Soil_Snow"
    },
    {
      "x": -2,
      "y": 0,
      "z": 5,
      "name": "Soil_Snow"
    },
    {
      "x": -2,
      "y": 1,
      "z": 5,
      "name": "Soil_Snow"
    },
    {
      "x": -2,
      "y": 0,
      "z": 6,
      "name": "Soil_Snow"
    },
    {
      "x": -2,
      "y": 1,
      "z": 6,
      "name": "Soil_Snow"
    },
    {
      "x": -2,
      "y": 0,
      "z": 7,
      "name": "Soil_Snow"
    },
    {
      "x": -2,
      "y": 1,
      "z": 7,
      "name": "Soil_Snow"
    },
    {
      "x": -2,
      "y": 0,
      "z": 8,
      "name": "Soil_Snow"
    },
    {
      "x": -2,
      "y": 1,
      "z": 8,
      "name": "Soil_Snow"
    },
    {
      "x": -2,
      "y": 0,
      "z": 9,
      "name": "Soil_Snow"
    },
    {
      "x": -2,
      "y": 1,
      "z": 9,
      "name": "Soil_Snow"
    },
    {
      "x": -2,
      "y": 0,
      "z": 10,
      "name": "Soil_Snow"
    },
    {
      "x": -2,
      "y": 1,
      "z": 10,
      "name": "Soil_Snow"
    },
    {
      "x": -2,
      "y": 0,
      "z": 11,
      "name": "Soil_Snow"
    },
    {
      "x": -2,
      "y": 0,
      "z": 12,
      "name": "Soil_Snow"
    },
    {
      "x": -1,
      "y": 0,
      "z": -9,
      "name": "Soil_Snow"
    },
    {
      "x": -1,
      "y": 0,
      "z": -8,
      "name": "Soil_Snow"
    },
    {
      "x": -1,
      "y": 0,
      "z": -7,
      "name": "Soil_Snow"
    },
    {
      "x": -1,
      "y": 0,
      "z": -6,
      "name": "Soil_Snow"
    },
    {
      "x": -1,
      "y": 1,
      "z": -6,
      "name": "Soil_Snow"
    },
    {
      "x": -1,
      "y": 0,
      "z": -5,
      "name": "Soil_Snow"
    },
    {
      "x": -1,
      "y": 1,
      "z": -5,
      "name": "Soil_Snow"
    },
    {
      "x": -1,
      "y": 0,
      "z": -4,
      "name": "Soil_Snow"
    },
    {
      "x": -1,
      "y": 1,
      "z": -4,
      "name": "Soil_Snow"
    },
    {
      "x": -1,
      "y": 0,
      "z": -3,
      "name": "Soil_Snow"
    },
    {
      "x": -1,
      "y": 1,
      "z": -3,
      "name": "Soil_Snow"
    },
    {
      "x": -1,
      "y": 2,
      "z": -3,
      "name": "Soil_Snow"
    },
    {
      "x": -1,
      "y": 0,
      "z": -2,
      "name": "Soil_Snow"
    },
    {
      "x": -1,
      "y": 0,
      "z": -1,
      "name": "Soil_Snow"
    },
    {
      "x": -1,
      "y": 0,
      "z": 0,
      "name": "Soil_Snow"
    },
    {
      "x": -1,
      "y": 0,
      "z": 1,
      "name": "Soil_Snow"
    },
    {
      "x": -1,
      "y": 0,
      "z": 2,
      "name": "Soil_Snow"
    },
    {
      "x": -1,
      "y": 1,
      "z": 2,
      "name": "Soil_Snow"
    },
    {
      "x": -1,
      "y": 0,
      "z": 3,
      "name": "Soil_Snow"
    },
    {
      "x": -1,
      "y": 1,
      "z": 3,
      "name": "Soil_Snow"
    },
    {
      "x": -1,
      "y": 2,
      "z": 3,
      "name": "Soil_Snow"
    },
    {
      "x": -1,
      "y": 0,
      "z": 4,
      "name": "Soil_Snow"
    },
    {
      "x": -1,
      "y": 1,
      "z": 4,
      "name": "Soil_Snow"
    },
    {
      "x": -1,
      "y": 2,
      "z": 4,
      "name": "Soil_Snow"
    },
    {
      "x": -1,
      "y": 3,
      "z": 4,
      "name": "Soil_Snow"
    },
    {
      "x": -1,
      "y": 0,
      "z": 5,
      "name": "Soil_Snow"
    },
    {
      "x": -1,
      "y": 1,
      "z": 5,
      "name": "Soil_Snow"
    },
    {
      "x": -1,
      "y": 2,
      "z": 5,
      "name": "Soil_Snow"
    },
    {
      "x": -1,
      "y": 0,
      "z": 6,
      "name": "Soil_Snow"
    },
    {
      "x": -1,
      "y": 1,
      "z": 6,
      "name": "Soil_Snow"
    },
    {
      "x": -1,
      "y": 2,
      "z": 6,
      "name": "Soil_Snow"
    },
    {
      "x": -1,
      "y": 0,
      "z": 7,
      "name": "Soil_Snow"
    },
    {
      "x": -1,
      "y": 1,
      "z": 7,
      "name": "Soil_Snow"
    },
    {
      "x": -1,
      "y": 2,
      "z": 7,
      "name": "Soil_Snow"
    },
    {
      "x": -1,
      "y": 0,
      "z": 8,
      "name": "Soil_Snow"
    },
    {
      "x": -1,
      "y": 1,
      "z": 8,
      "name": "Soil_Snow"
    },
    {
      "x": -1,
      "y": 2,
      "z": 8,
      "name": "Soil_Snow"
    },
    {
      "x": -1,
      "y": 0,
      "z": 9,
      "name": "Soil_Snow"
    },
    {
      "x": -1,
      "y": 1,
      "z": 9,
      "name": "Soil_Snow"
    },
    {
      "x": -1,
      "y": 2,
      "z": 9,
      "name": "Soil_Snow"
    },
    {
      "x": -1,
      "y": 0,
      "z": 10,
      "name": "Soil_Snow"
    },
    {
      "x": -1,
      "y": 1,
      "z": 10,
      "name": "Soil_Snow"
    },
    {
      "x": -1,
      "y": 2,
      "z": 10,
      "name": "Soil_Snow"
    },
    {
      "x": -1,
      "y": 0,
      "z": 11,
      "name": "Soil_Snow"
    },
    {
      "x": -1,
      "y": 1,
      "z": 11,
      "name": "Soil_Snow"
    },
    {
      "x": -1,
      "y": 2,
      "z": 11,
      "name": "Soil_Snow"
    },
    {
      "x": -1,
      "y": 0,
      "z": 12,
      "name": "Soil_Snow"
    },
    {
      "x": -1,
      "y": 1,
      "z": 12,
      "name": "Soil_Snow"
    },
    {
      "x": -1,
      "y": 0,
      "z": 13,
      "name": "Soil_Snow"
    },
    {
      "x": 0,
      "y": 0,
      "z": -11,
      "name": "Soil_Snow"
    },
    {
      "x": 0,
      "y": 0,
      "z": -10,
      "name": "Soil_Snow"
    },
    {
      "x": 0,
      "y": 0,
      "z": -9,
      "name": "Soil_Snow"
    },
    {
      "x": 0,
      "y": 1,
      "z": -9,
      "name": "Soil_Snow"
    },
    {
      "x": 0,
      "y": 0,
      "z": -8,
      "name": "Soil_Snow"
    },
    {
      "x": 0,
      "y": 1,
      "z": -8,
      "name": "Soil_Snow"
    },
    {
      "x": 0,
      "y": 0,
      "z": -7,
      "name": "Soil_Snow"
    },
    {
      "x": 0,
      "y": 1,
      "z": -7,
      "name": "Soil_Snow"
    },
    {
      "x": 0,
      "y": 0,
      "z": -6,
      "name": "Soil_Snow"
    },
    {
      "x": 0,
      "y": 1,
      "z": -6,
      "name": "Soil_Snow"
    },
    {
      "x": 0,
      "y": 0,
      "z": -5,
      "name": "Soil_Snow"
    },
    {
      "x": 0,
      "y": 1,
      "z": -5,
      "name": "Soil_Snow"
    },
    {
      "x": 0,
      "y": 2,
      "z": -5,
      "name": "Soil_Snow"
    },
    {
      "x": 0,
      "y": 0,
      "z": -4,
      "name": "Soil_Snow"
    },
    {
      "x": 0,
      "y": 1,
      "z": -4,
      "name": "Soil_Snow"
    },
    {
      "x": 0,
      "y": 2,
      "z": -4,
      "name": "Soil_Snow"
    },
    {
      "x": 0,
      "y": 0,
      "z": -3,
      "name": "Soil_Snow"
    },
    {
      "x": 0,
      "y": 1,
      "z": -3,
      "name": "Soil_Snow"
    },
    {
      "x": 0,
      "y": 2,
      "z": -3,
      "name": "Soil_Snow"
    },
    {
      "x": 0,
      "y": 3,
      "z": -3,
      "name": "Soil_Snow"
    },
    {
      "x": 0,
      "y": 0,
      "z": -2,
      "name": "Soil_Snow"
    },
    {
      "x": 0,
      "y": 1,
      "z": -2,
      "name": "Soil_Snow"
    },
    {
      "x": 0,
      "y": 2,
      "z": -2,
      "name": "Soil_Snow"
    },
    {
      "x": 0,
      "y": 3,
      "z": -2,
      "name": "Soil_Snow"
    },
    {
      "x": 0,
      "y": 0,
      "z": -1,
      "name": "Soil_Snow"
    },
    {
      "x": 0,
      "y": 0,
      "z": 0,
      "name": "Soil_Snow"
    },
    {
      "x": 0,
      "y": 0,
      "z": 1,
      "name": "Soil_Snow"
    },
    {
      "x": 0,
      "y": 0,
      "z": 2,
      "name": "Soil_Snow"
    },
    {
      "x": 0,
      "y": 1,
      "z": 2,
      "name": "Soil_Snow"
    },
    {
      "x": 0,
      "y": 2,
      "z": 2,
      "name": "Soil_Snow"
    },
    {
      "x": 0,
      "y": 3,
      "z": 2,
      "name": "Soil_Snow"
    },
    {
      "x": 0,
      "y": 0,
      "z": 3,
      "name": "Soil_Snow"
    },
    {
      "x": 0,
      "y": 1,
      "z": 3,
      "name": "Soil_Snow"
    },
    {
      "x": 0,
      "y": 2,
      "z": 3,
      "name": "Soil_Snow"
    },
    {
      "x": 0,
      "y": 3,
      "z": 3,
      "name": "Soil_Snow"
    },
    {
      "x": 0,
      "y": 4,
      "z": 3,
      "name": "Soil_Snow"
    },
    {
      "x": 0,
      "y": 0,
      "z": 4,
      "name": "Soil_Snow"
    },
    {
      "x": 0,
      "y": 1,
      "z": 4,
      "name": "Soil_Snow"
    },
    {
      "x": 0,
      "y": 2,
      "z": 4,
      "name": "Soil_Snow"
    },
    {
      "x": 0,
      "y": 3,
      "z": 4,
      "name": "Empty"
    },
    {
      "x": 0,
      "y": 4,
      "z": 4,
      "name": "Soil_Snow"
    },
    {
      "x": 0,
      "y": 0,
      "z": 5,
      "name": "Soil_Snow"
    },
    {
      "x": 0,
      "y": 1,
      "z": 5,
      "name": "Soil_Snow"
    },
    {
      "x": 0,
      "y": 2,
      "z": 5,
      "name": "Soil_Snow"
    },
    {
      "x": 0,
      "y": 3,
      "z": 5,
      "name": "Soil_Snow"
    },
    {
      "x": 0,
      "y": 0,
      "z": 6,
      "name": "Soil_Snow"
    },
    {
      "x": 0,
      "y": 1,
      "z": 6,
      "name": "Soil_Snow"
    },
    {
      "x": 0,
      "y": 2,
      "z": 6,
      "name": "Soil_Snow"
    },
    {
      "x": 0,
      "y": 3,
      "z": 6,
      "name": "Soil_Snow"
    },
    {
      "x": 0,
      "y": 0,
      "z": 7,
      "name": "Soil_Snow"
    },
    {
      "x": 0,
      "y": 1,
      "z": 7,
      "name": "Soil_Snow"
    },
    {
      "x": 0,
      "y": 2,
      "z": 7,
      "name": "Soil_Snow"
    },
    {
      "x": 0,
      "y": 3,
      "z": 7,
      "name": "Soil_Snow"
    },
    {
      "x": 0,
      "y": 0,
      "z": 8,
      "name": "Soil_Snow"
    },
    {
      "x": 0,
      "y": 1,
      "z": 8,
      "name": "Soil_Snow"
    },
    {
      "x": 0,
      "y": 2,
      "z": 8,
      "name": "Soil_Snow"
    },
    {
      "x": 0,
      "y": 3,
      "z": 8,
      "name": "Soil_Snow"
    },
    {
      "x": 0,
      "y": 0,
      "z": 9,
      "name": "Soil_Snow"
    },
    {
      "x": 0,
      "y": 1,
      "z": 9,
      "name": "Soil_Snow"
    },
    {
      "x": 0,
      "y": 2,
      "z": 9,
      "name": "Soil_Snow"
    },
    {
      "x": 0,
      "y": 3,
      "z": 9,
      "name": "Soil_Snow"
    },
    {
      "x": 0,
      "y": 0,
      "z": 10,
      "name": "Soil_Snow"
    },
    {
      "x": 0,
      "y": 1,
      "z": 10,
      "name": "Soil_Snow"
    },
    {
      "x": 0,
      "y": 2,
      "z": 10,
      "name": "Soil_Snow"
    },
    {
      "x": 0,
      "y": 0,
      "z": 11,
      "name": "Soil_Snow"
    },
    {
      "x": 0,
      "y": 1,
      "z": 11,
      "name": "Soil_Snow"
    },
    {
      "x": 0,
      "y": 2,
      "z": 11,
      "name": "Soil_Snow"
    },
    {
      "x": 0,
      "y": 0,
      "z": 12,
      "name": "Soil_Snow"
    },
    {
      "x": 0,
      "y": 1,
      "z": 12,
      "name": "Soil_Snow"
    },
    {
      "x": 0,
      "y": 2,
      "z": 12,
      "name": "Soil_Snow"
    },
    {
      "x": 0,
      "y": 0,
      "z": 13,
      "name": "Soil_Snow"
    },
    {
      "x": 0,
      "y": 0,
      "z": 14,
      "name": "Soil_Snow"
    },
    {
      "x": 1,
      "y": 0,
      "z": -12,
      "name": "Soil_Snow"
    },
    {
      "x": 1,
      "y": 1,
      "z": -12,
      "name": "Soil_Snow"
    },
    {
      "x": 1,
      "y": 0,
      "z": -11,
      "name": "Soil_Snow"
    },
    {
      "x": 1,
      "y": 1,
      "z": -11,
      "name": "Soil_Snow"
    },
    {
      "x": 1,
      "y": 0,
      "z": -10,
      "name": "Soil_Snow"
    },
    {
      "x": 1,
      "y": 1,
      "z": -10,
      "name": "Soil_Snow"
    },
    {
      "x": 1,
      "y": 0,
      "z": -9,
      "name": "Soil_Snow"
    },
    {
      "x": 1,
      "y": 1,
      "z": -9,
      "name": "Soil_Snow"
    },
    {
      "x": 1,
      "y": 0,
      "z": -8,
      "name": "Soil_Snow"
    },
    {
      "x": 1,
      "y": 1,
      "z": -8,
      "name": "Soil_Snow"
    },
    {
      "x": 1,
      "y": 2,
      "z": -8,
      "name": "Soil_Snow"
    },
    {
      "x": 1,
      "y": 0,
      "z": -7,
      "name": "Soil_Snow"
    },
    {
      "x": 1,
      "y": 1,
      "z": -7,
      "name": "Soil_Snow"
    },
    {
      "x": 1,
      "y": 2,
      "z": -7,
      "name": "Soil_Snow"
    },
    {
      "x": 1,
      "y": 0,
      "z": -6,
      "name": "Soil_Snow"
    },
    {
      "x": 1,
      "y": 1,
      "z": -6,
      "name": "Soil_Snow"
    },
    {
      "x": 1,
      "y": 2,
      "z": -6,
      "name": "Soil_Snow"
    },
    {
      "x": 1,
      "y": 0,
      "z": -5,
      "name": "Soil_Snow"
    },
    {
      "x": 1,
      "y": 1,
      "z": -5,
      "name": "Soil_Snow"
    },
    {
      "x": 1,
      "y": 2,
      "z": -5,
      "name": "Soil_Snow"
    },
    {
      "x": 1,
      "y": 3,
      "z": -5,
      "name": "Soil_Snow"
    },
    {
      "x": 1,
      "y": 0,
      "z": -4,
      "name": "Soil_Snow"
    },
    {
      "x": 1,
      "y": 1,
      "z": -4,
      "name": "Soil_Snow"
    },
    {
      "x": 1,
      "y": 2,
      "z": -4,
      "name": "Soil_Snow"
    },
    {
      "x": 1,
      "y": 3,
      "z": -4,
      "name": "Soil_Snow"
    },
    {
      "x": 1,
      "y": 0,
      "z": -3,
      "name": "Soil_Snow"
    },
    {
      "x": 1,
      "y": 1,
      "z": -3,
      "name": "Soil_Snow"
    },
    {
      "x": 1,
      "y": 2,
      "z": -3,
      "name": "Soil_Snow"
    },
    {
      "x": 1,
      "y": 3,
      "z": -3,
      "name": "Soil_Snow"
    },
    {
      "x": 1,
      "y": 4,
      "z": -3,
      "name": "Soil_Snow"
    },
    {
      "x": 1,
      "y": 0,
      "z": -2,
      "name": "Soil_Snow"
    },
    {
      "x": 1,
      "y": 1,
      "z": -2,
      "name": "Soil_Snow"
    },
    {
      "x": 1,
      "y": 2,
      "z": -2,
      "name": "Soil_Snow"
    },
    {
      "x": 1,
      "y": 3,
      "z": -2,
      "name": "Soil_Snow"
    },
    {
      "x": 1,
      "y": 4,
      "z": -2,
      "name": "Soil_Snow"
    },
    {
      "x": 1,
      "y": 5,
      "z": -2,
      "name": "Soil_Snow"
    },
    {
      "x": 1,
      "y": 0,
      "z": -1,
      "name": "Soil_Snow"
    },
    {
      "x": 1,
      "y": 1,
      "z": -1,
      "name": "Empty"
    },
    {
      "x": 1,
      "y": 2,
      "z": -1,
      "name": "Empty"
    },
    {
      "x": 1,
      "y": 3,
      "z": -1,
      "name": "Empty"
    },
    {
      "x": 1,
      "y": 4,
      "z": -1,
      "name": "Empty"
    },
    {
      "x": 1,
      "y": 5,
      "z": -1,
      "name": "Soil_Snow"
    },
    {
      "x": 1,
      "y": 0,
      "z": 0,
      "name": "Soil_Snow_Half"
    },
    {
      "x": 1,
      "y": 1,
      "z": 0,
      "name": "Empty"
    },
    {
      "x": 1,
      "y": 2,
      "z": 0,
      "name": "Empty"
    },
    {
      "x": 1,
      "y": 3,
      "z": 0,
      "name": "Empty"
    },
    {
      "x": 1,
      "y": 4,
      "z": 0,
      "name": "Empty"
    },
    {
      "x": 1,
      "y": 5,
      "z": 0,
      "name": "Soil_Snow"
    },
    {
      "x": 1,
      "y": 0,
      "z": 1,
      "name": "Soil_Snow_Half"
    },
    {
      "x": 1,
      "y": 1,
      "z": 1,
      "name": "Empty"
    },
    {
      "x": 1,
      "y": 2,
      "z": 1,
      "name": "Empty"
    },
    {
      "x": 1,
      "y": 3,
      "z": 1,
      "name": "Empty"
    },
    {
      "x": 1,
      "y": 4,
      "z": 1,
      "name": "Empty"
    },
    {
      "x": 1,
      "y": 5,
      "z": 1,
      "name": "Soil_Snow"
    },
    {
      "x": 1,
      "y": 0,
      "z": 2,
      "name": "Soil_Snow"
    },
    {
      "x": 1,
      "y": 1,
      "z": 2,
      "name": "Empty"
    },
    {
      "x": 1,
      "y": 2,
      "z": 2,
      "name": "Empty"
    },
    {
      "x": 1,
      "y": 3,
      "z": 2,
      "name": "Empty"
    },
    {
      "x": 1,
      "y": 4,
      "z": 2,
      "name": "Soil_Snow"
    },
    {
      "x": 1,
      "y": 5,
      "z": 2,
      "name": "Soil_Snow"
    },
    {
      "x": 1,
      "y": 0,
      "z": 3,
      "name": "Soil_Snow"
    },
    {
      "x": 1,
      "y": 1,
      "z": 3,
      "name": "Soil_Snow"
    },
    {
      "x": 1,
      "y": 2,
      "z": 3,
      "name": "Empty"
    },
    {
      "x": 1,
      "y": 3,
      "z": 3,
      "name": "Empty"
    },
    {
      "x": 1,
      "y": 4,
      "z": 3,
      "name": "Soil_Snow"
    },
    {
      "x": 1,
      "y": 5,
      "z": 3,
      "name": "Soil_Snow"
    },
    {
      "x": 1,
      "y": 0,
      "z": 4,
      "name": "Soil_Snow"
    },
    {
      "x": 1,
      "y": 1,
      "z": 4,
      "name": "Soil_Snow"
    },
    {
      "x": 1,
      "y": 2,
      "z": 4,
      "name": "Soil_Snow"
    },
    {
      "x": 1,
      "y": 3,
      "z": 4,
      "name": "Soil_Snow"
    },
    {
      "x": 1,
      "y": 4,
      "z": 4,
      "name": "Soil_Snow"
    },
    {
      "x": 1,
      "y": 0,
      "z": 5,
      "name": "Soil_Snow"
    },
    {
      "x": 1,
      "y": 1,
      "z": 5,
      "name": "Soil_Snow"
    },
    {
      "x": 1,
      "y": 2,
      "z": 5,
      "name": "Soil_Snow"
    },
    {
      "x": 1,
      "y": 3,
      "z": 5,
      "name": "Soil_Snow"
    },
    {
      "x": 1,
      "y": 4,
      "z": 5,
      "name": "Soil_Snow"
    },
    {
      "x": 1,
      "y": 0,
      "z": 6,
      "name": "Soil_Snow"
    },
    {
      "x": 1,
      "y": 1,
      "z": 6,
      "name": "Soil_Snow"
    },
    {
      "x": 1,
      "y": 2,
      "z": 6,
      "name": "Soil_Snow"
    },
    {
      "x": 1,
      "y": 3,
      "z": 6,
      "name": "Soil_Snow"
    },
    {
      "x": 1,
      "y": 4,
      "z": 6,
      "name": "Soil_Snow"
    },
    {
      "x": 1,
      "y": 0,
      "z": 7,
      "name": "Soil_Snow"
    },
    {
      "x": 1,
      "y": 1,
      "z": 7,
      "name": "Soil_Snow"
    },
    {
      "x": 1,
      "y": 2,
      "z": 7,
      "name": "Soil_Snow"
    },
    {
      "x": 1,
      "y": 3,
      "z": 7,
      "name": "Soil_Snow"
    },
    {
      "x": 1,
      "y": 4,
      "z": 7,
      "name": "Soil_Snow"
    },
    {
      "x": 1,
      "y": 0,
      "z": 8,
      "name": "Soil_Snow"
    },
    {
      "x": 1,
      "y": 1,
      "z": 8,
      "name": "Soil_Snow"
    },
    {
      "x": 1,
      "y": 2,
      "z": 8,
      "name": "Soil_Snow"
    },
    {
      "x": 1,
      "y": 3,
      "z": 8,
      "name": "Soil_Snow"
    },
    {
      "x": 1,
      "y": 0,
      "z": 9,
      "name": "Soil_Snow"
    },
    {
      "x": 1,
      "y": 1,
      "z": 9,
      "name": "Soil_Snow"
    },
    {
      "x": 1,
      "y": 2,
      "z": 9,
      "name": "Soil_Snow"
    },
    {
      "x": 1,
      "y": 3,
      "z": 9,
      "name": "Soil_Snow"
    },
    {
      "x": 1,
      "y": 0,
      "z": 10,
      "name": "Soil_Snow"
    },
    {
      "x": 1,
      "y": 1,
      "z": 10,
      "name": "Soil_Snow"
    },
    {
      "x": 1,
      "y": 2,
      "z": 10,
      "name": "Soil_Snow"
    },
    {
      "x": 1,
      "y": 3,
      "z": 10,
      "name": "Soil_Snow"
    },
    {
      "x": 1,
      "y": 0,
      "z": 11,
      "name": "Soil_Snow"
    },
    {
      "x": 1,
      "y": 1,
      "z": 11,
      "name": "Soil_Snow"
    },
    {
      "x": 1,
      "y": 2,
      "z": 11,
      "name": "Soil_Snow"
    },
    {
      "x": 1,
      "y": 0,
      "z": 12,
      "name": "Soil_Snow"
    },
    {
      "x": 1,
      "y": 1,
      "z": 12,
      "name": "Soil_Snow"
    },
    {
      "x": 1,
      "y": 2,
      "z": 12,
      "name": "Soil_Snow"
    },
    {
      "x": 1,
      "y": 0,
      "z": 13,
      "name": "Soil_Snow"
    },
    {
      "x": 1,
      "y": 1,
      "z": 13,
      "name": "Soil_Snow"
    },
    {
      "x": 1,
      "y": 0,
      "z": 14,
      "name": "Soil_Snow"
    },
    {
      "x": 2,
      "y": 0,
      "z": -13,
      "name": "Soil_Snow"
    },
    {
      "x": 2,
      "y": 1,
      "z": -13,
      "name": "Soil_Snow"
    },
    {
      "x": 2,
      "y": 0,
      "z": -12,
      "name": "Soil_Snow"
    },
    {
      "x": 2,
      "y": 1,
      "z": -12,
      "name": "Soil_Snow"
    },
    {
      "x": 2,
      "y": 0,
      "z": -11,
      "name": "Soil_Snow"
    },
    {
      "x": 2,
      "y": 1,
      "z": -11,
      "name": "Soil_Snow"
    },
    {
      "x": 2,
      "y": 0,
      "z": -10,
      "name": "Soil_Snow"
    },
    {
      "x": 2,
      "y": 1,
      "z": -10,
      "name": "Soil_Snow"
    },
    {
      "x": 2,
      "y": 2,
      "z": -10,
      "name": "Soil_Snow"
    },
    {
      "x": 2,
      "y": 0,
      "z": -9,
      "name": "Soil_Snow"
    },
    {
      "x": 2,
      "y": 1,
      "z": -9,
      "name": "Soil_Snow"
    },
    {
      "x": 2,
      "y": 2,
      "z": -9,
      "name": "Soil_Snow"
    },
    {
      "x": 2,
      "y": 0,
      "z": -8,
      "name": "Soil_Snow"
    },
    {
      "x": 2,
      "y": 1,
      "z": -8,
      "name": "Soil_Snow"
    },
    {
      "x": 2,
      "y": 2,
      "z": -8,
      "name": "Soil_Snow"
    },
    {
      "x": 2,
      "y": 0,
      "z": -7,
      "name": "Soil_Snow"
    },
    {
      "x": 2,
      "y": 1,
      "z": -7,
      "name": "Soil_Snow"
    },
    {
      "x": 2,
      "y": 2,
      "z": -7,
      "name": "Soil_Snow"
    },
    {
      "x": 2,
      "y": 3,
      "z": -7,
      "name": "Soil_Snow"
    },
    {
      "x": 2,
      "y": 0,
      "z": -6,
      "name": "Soil_Snow"
    },
    {
      "x": 2,
      "y": 1,
      "z": -6,
      "name": "Soil_Snow"
    },
    {
      "x": 2,
      "y": 2,
      "z": -6,
      "name": "Soil_Snow"
    },
    {
      "x": 2,
      "y": 3,
      "z": -6,
      "name": "Soil_Snow"
    },
    {
      "x": 2,
      "y": 0,
      "z": -5,
      "name": "Soil_Snow"
    },
    {
      "x": 2,
      "y": 1,
      "z": -5,
      "name": "Soil_Snow"
    },
    {
      "x": 2,
      "y": 2,
      "z": -5,
      "name": "Soil_Snow"
    },
    {
      "x": 2,
      "y": 3,
      "z": -5,
      "name": "Soil_Snow"
    },
    {
      "x": 2,
      "y": 0,
      "z": -4,
      "name": "Soil_Snow"
    },
    {
      "x": 2,
      "y": 1,
      "z": -4,
      "name": "Soil_Snow"
    },
    {
      "x": 2,
      "y": 2,
      "z": -4,
      "name": "Soil_Snow"
    },
    {
      "x": 2,
      "y": 3,
      "z": -4,
      "name": "Soil_Snow"
    },
    {
      "x": 2,
      "y": 4,
      "z": -4,
      "name": "Soil_Snow"
    },
    {
      "x": 2,
      "y": 0,
      "z": -3,
      "name": "Soil_Snow"
    },
    {
      "x": 2,
      "y": 1,
      "z": -3,
      "name": "Soil_Snow"
    },
    {
      "x": 2,
      "y": 2,
      "z": -3,
      "name": "Soil_Snow"
    },
    {
      "x": 2,
      "y": 3,
      "z": -3,
      "name": "Soil_Snow"
    },
    {
      "x": 2,
      "y": 4,
      "z": -3,
      "name": "Soil_Snow"
    },
    {
      "x": 2,
      "y": 5,
      "z": -3,
      "name": "Soil_Snow"
    },
    {
      "x": 2,
      "y": 0,
      "z": -2,
      "name": "Soil_Snow"
    },
    {
      "x": 2,
      "y": 1,
      "z": -2,
      "name": "Soil_Snow_Half"
    },
    {
      "x": 2,
      "y": 2,
      "z": -2,
      "name": "Soil_Snow"
    },
    {
      "x": 2,
      "y": 3,
      "z": -2,
      "name": "Soil_Snow"
    },
    {
      "x": 2,
      "y": 4,
      "z": -2,
      "name": "Soil_Snow"
    },
    {
      "x": 2,
      "y": 5,
      "z": -2,
      "name": "Soil_Snow"
    },
    {
      "x": 2,
      "y": 0,
      "z": -1,
      "name": "Soil_Snow_Half"
    },
    {
      "x": 2,
      "y": 1,
      "z": -1,
      "name": "Empty"
    },
    {
      "x": 2,
      "y": 2,
      "z": -1,
      "name": "Empty"
    },
    {
      "x": 2,
      "y": 3,
      "z": -1,
      "name": "Empty"
    },
    {
      "x": 2,
      "y": 4,
      "z": -1,
      "name": "Empty"
    },
    {
      "x": 2,
      "y": 5,
      "z": -1,
      "name": "Soil_Snow"
    },
    {
      "x": 2,
      "y": -1,
      "z": 0,
      "name": "Soil_Snow"
    },
    {
      "x": 2,
      "y": 0,
      "z": 0,
      "name": "Empty"
    },
    {
      "x": 2,
      "y": 1,
      "z": 0,
      "name": "Empty"
    },
    {
      "x": 2,
      "y": 2,
      "z": 0,
      "name": "Empty"
    },
    {
      "x": 2,
      "y": 3,
      "z": 0,
      "name": "Empty"
    },
    {
      "x": 2,
      "y": 4,
      "z": 0,
      "name": "Empty"
    },
    {
      "x": 2,
      "y": 5,
      "z": 0,
      "name": "Soil_Snow"
    },
    {
      "x": 2,
      "y": -1,
      "z": 1,
      "name": "Soil_Snow"
    },
    {
      "x": 2,
      "y": 0,
      "z": 1,
      "name": "Empty"
    },
    {
      "x": 2,
      "y": 1,
      "z": 1,
      "name": "Empty"
    },
    {
      "x": 2,
      "y": 2,
      "z": 1,
      "name": "Empty"
    },
    {
      "x": 2,
      "y": 3,
      "z": 1,
      "name": "Empty"
    },
    {
      "x": 2,
      "y": 4,
      "z": 1,
      "name": "Empty"
    },
    {
      "x": 2,
      "y": 5,
      "z": 1,
      "name": "Soil_Snow"
    },
    {
      "x": 2,
      "y": -1,
      "z": 2,
      "name": "Soil_Snow"
    },
    {
      "x": 2,
      "y": 0,
      "z": 2,
      "name": "Empty"
    },
    {
      "x": 2,
      "y": 1,
      "z": 2,
      "name": "Empty"
    },
    {
      "x": 2,
      "y": 2,
      "z": 2,
      "name": "Empty"
    },
    {
      "x": 2,
      "y": 3,
      "z": 2,
      "name": "Empty"
    },
    {
      "x": 2,
      "y": 4,
      "z": 2,
      "name": "Empty"
    },
    {
      "x": 2,
      "y": 5,
      "z": 2,
      "name": "Soil_Snow"
    },
    {
      "x": 2,
      "y": 0,
      "z": 3,
      "name": "Soil_Snow"
    },
    {
      "x": 2,
      "y": 1,
      "z": 3,
      "name": "Rock_Ice_Icicles"
    },
    {
      "x": 2,
      "y": 2,
      "z": 3,
      "name": "Empty"
    },
    {
      "x": 2,
      "y": 3,
      "z": 3,
      "name": "Empty"
    },
    {
      "x": 2,
      "y": 4,
      "z": 3,
      "name": "Soil_Snow"
    },
    {
      "x": 2,
      "y": 5,
      "z": 3,
      "name": "Soil_Snow"
    },
    {
      "x": 2,
      "y": 0,
      "z": 4,
      "name": "Soil_Snow"
    },
    {
      "x": 2,
      "y": 1,
      "z": 4,
      "name": "Soil_Snow"
    },
    {
      "x": 2,
      "y": 2,
      "z": 4,
      "name": "Soil_Snow"
    },
    {
      "x": 2,
      "y": 3,
      "z": 4,
      "name": "Soil_Snow"
    },
    {
      "x": 2,
      "y": 4,
      "z": 4,
      "name": "Soil_Snow"
    },
    {
      "x": 2,
      "y": 5,
      "z": 4,
      "name": "Soil_Snow"
    },
    {
      "x": 2,
      "y": 0,
      "z": 5,
      "name": "Soil_Snow"
    },
    {
      "x": 2,
      "y": 1,
      "z": 5,
      "name": "Soil_Snow"
    },
    {
      "x": 2,
      "y": 2,
      "z": 5,
      "name": "Soil_Snow"
    },
    {
      "x": 2,
      "y": 3,
      "z": 5,
      "name": "Soil_Snow"
    },
    {
      "x": 2,
      "y": 4,
      "z": 5,
      "name": "Soil_Snow"
    },
    {
      "x": 2,
      "y": 5,
      "z": 5,
      "name": "Soil_Snow"
    },
    {
      "x": 2,
      "y": 0,
      "z": 6,
      "name": "Soil_Snow"
    },
    {
      "x": 2,
      "y": 1,
      "z": 6,
      "name": "Soil_Snow"
    },
    {
      "x": 2,
      "y": 2,
      "z": 6,
      "name": "Soil_Snow"
    },
    {
      "x": 2,
      "y": 3,
      "z": 6,
      "name": "Soil_Snow"
    },
    {
      "x": 2,
      "y": 4,
      "z": 6,
      "name": "Soil_Snow"
    },
    {
      "x": 2,
      "y": 5,
      "z": 6,
      "name": "Soil_Snow"
    },
    {
      "x": 2,
      "y": 0,
      "z": 7,
      "name": "Soil_Snow"
    },
    {
      "x": 2,
      "y": 1,
      "z": 7,
      "name": "Soil_Snow"
    },
    {
      "x": 2,
      "y": 2,
      "z": 7,
      "name": "Soil_Snow"
    },
    {
      "x": 2,
      "y": 3,
      "z": 7,
      "name": "Soil_Snow"
    },
    {
      "x": 2,
      "y": 4,
      "z": 7,
      "name": "Soil_Snow"
    },
    {
      "x": 2,
      "y": 0,
      "z": 8,
      "name": "Soil_Snow"
    },
    {
      "x": 2,
      "y": 1,
      "z": 8,
      "name": "Soil_Snow"
    },
    {
      "x": 2,
      "y": 2,
      "z": 8,
      "name": "Soil_Snow"
    },
    {
      "x": 2,
      "y": 3,
      "z": 8,
      "name": "Soil_Snow"
    },
    {
      "x": 2,
      "y": 4,
      "z": 8,
      "name": "Soil_Snow"
    },
    {
      "x": 2,
      "y": 0,
      "z": 9,
      "name": "Soil_Snow"
    },
    {
      "x": 2,
      "y": 1,
      "z": 9,
      "name": "Soil_Snow"
    },
    {
      "x": 2,
      "y": 2,
      "z": 9,
      "name": "Soil_Snow"
    },
    {
      "x": 2,
      "y": 3,
      "z": 9,
      "name": "Soil_Snow"
    },
    {
      "x": 2,
      "y": 4,
      "z": 9,
      "name": "Soil_Snow"
    },
    {
      "x": 2,
      "y": 0,
      "z": 10,
      "name": "Soil_Snow"
    },
    {
      "x": 2,
      "y": 1,
      "z": 10,
      "name": "Soil_Snow"
    },
    {
      "x": 2,
      "y": 2,
      "z": 10,
      "name": "Soil_Snow"
    },
    {
      "x": 2,
      "y": 3,
      "z": 10,
      "name": "Soil_Snow"
    },
    {
      "x": 2,
      "y": 0,
      "z": 11,
      "name": "Soil_Snow"
    },
    {
      "x": 2,
      "y": 1,
      "z": 11,
      "name": "Soil_Snow"
    },
    {
      "x": 2,
      "y": 2,
      "z": 11,
      "name": "Soil_Snow"
    },
    {
      "x": 2,
      "y": 3,
      "z": 11,
      "name": "Soil_Snow"
    },
    {
      "x": 2,
      "y": 0,
      "z": 12,
      "name": "Soil_Snow"
    },
    {
      "x": 2,
      "y": 1,
      "z": 12,
      "name": "Soil_Snow"
    },
    {
      "x": 2,
      "y": 2,
      "z": 12,
      "name": "Soil_Snow"
    },
    {
      "x": 2,
      "y": 0,
      "z": 13,
      "name": "Soil_Snow"
    },
    {
      "x": 2,
      "y": 1,
      "z": 13,
      "name": "Soil_Snow"
    },
    {
      "x": 2,
      "y": 2,
      "z": 13,
      "name": "Soil_Snow"
    },
    {
      "x": 2,
      "y": 0,
      "z": 14,
      "name": "Soil_Snow"
    },
    {
      "x": 2,
      "y": 0,
      "z": 15,
      "name": "Soil_Snow"
    },
    {
      "x": 3,
      "y": 0,
      "z": -15,
      "name": "Soil_Snow"
    },
    {
      "x": 3,
      "y": 0,
      "z": -14,
      "name": "Soil_Snow"
    },
    {
      "x": 3,
      "y": 1,
      "z": -14,
      "name": "Soil_Snow"
    },
    {
      "x": 3,
      "y": 0,
      "z": -13,
      "name": "Soil_Snow"
    },
    {
      "x": 3,
      "y": 1,
      "z": -13,
      "name": "Soil_Snow"
    },
    {
      "x": 3,
      "y": 0,
      "z": -12,
      "name": "Soil_Snow"
    },
    {
      "x": 3,
      "y": 1,
      "z": -12,
      "name": "Soil_Snow"
    },
    {
      "x": 3,
      "y": 0,
      "z": -11,
      "name": "Soil_Snow"
    },
    {
      "x": 3,
      "y": 1,
      "z": -11,
      "name": "Soil_Snow"
    },
    {
      "x": 3,
      "y": 2,
      "z": -11,
      "name": "Soil_Snow"
    },
    {
      "x": 3,
      "y": 0,
      "z": -10,
      "name": "Soil_Snow"
    },
    {
      "x": 3,
      "y": 1,
      "z": -10,
      "name": "Soil_Snow"
    },
    {
      "x": 3,
      "y": 2,
      "z": -10,
      "name": "Soil_Snow"
    },
    {
      "x": 3,
      "y": 0,
      "z": -9,
      "name": "Soil_Snow"
    },
    {
      "x": 3,
      "y": 1,
      "z": -9,
      "name": "Soil_Snow"
    },
    {
      "x": 3,
      "y": 2,
      "z": -9,
      "name": "Soil_Snow"
    },
    {
      "x": 3,
      "y": 3,
      "z": -9,
      "name": "Soil_Snow"
    },
    {
      "x": 3,
      "y": 0,
      "z": -8,
      "name": "Soil_Snow"
    },
    {
      "x": 3,
      "y": 1,
      "z": -8,
      "name": "Soil_Snow"
    },
    {
      "x": 3,
      "y": 2,
      "z": -8,
      "name": "Soil_Snow"
    },
    {
      "x": 3,
      "y": 3,
      "z": -8,
      "name": "Soil_Snow"
    },
    {
      "x": 3,
      "y": 0,
      "z": -7,
      "name": "Soil_Snow"
    },
    {
      "x": 3,
      "y": 1,
      "z": -7,
      "name": "Soil_Snow"
    },
    {
      "x": 3,
      "y": 2,
      "z": -7,
      "name": "Soil_Snow"
    },
    {
      "x": 3,
      "y": 3,
      "z": -7,
      "name": "Soil_Snow"
    },
    {
      "x": 3,
      "y": 4,
      "z": -7,
      "name": "Soil_Snow"
    },
    {
      "x": 3,
      "y": 0,
      "z": -6,
      "name": "Soil_Snow"
    },
    {
      "x": 3,
      "y": 1,
      "z": -6,
      "name": "Soil_Snow"
    },
    {
      "x": 3,
      "y": 2,
      "z": -6,
      "name": "Soil_Snow"
    },
    {
      "x": 3,
      "y": 3,
      "z": -6,
      "name": "Soil_Snow"
    },
    {
      "x": 3,
      "y": 4,
      "z": -6,
      "name": "Soil_Snow"
    },
    {
      "x": 3,
      "y": 0,
      "z": -5,
      "name": "Soil_Snow"
    },
    {
      "x": 3,
      "y": 1,
      "z": -5,
      "name": "Soil_Snow"
    },
    {
      "x": 3,
      "y": 2,
      "z": -5,
      "name": "Soil_Snow"
    },
    {
      "x": 3,
      "y": 3,
      "z": -5,
      "name": "Soil_Snow"
    },
    {
      "x": 3,
      "y": 4,
      "z": -5,
      "name": "Soil_Snow"
    },
    {
      "x": 3,
      "y": 5,
      "z": -5,
      "name": "Soil_Snow"
    },
    {
      "x": 3,
      "y": 0,
      "z": -4,
      "name": "Soil_Snow"
    },
    {
      "x": 3,
      "y": 1,
      "z": -4,
      "name": "Soil_Snow"
    },
    {
      "x": 3,
      "y": 2,
      "z": -4,
      "name": "Soil_Snow"
    },
    {
      "x": 3,
      "y": 3,
      "z": -4,
      "name": "Soil_Snow"
    },
    {
      "x": 3,
      "y": 4,
      "z": -4,
      "name": "Soil_Snow"
    },
    {
      "x": 3,
      "y": 5,
      "z": -4,
      "name": "Soil_Snow"
    },
    {
      "x": 3,
      "y": 0,
      "z": -3,
      "name": "Soil_Snow"
    },
    {
      "x": 3,
      "y": 1,
      "z": -3,
      "name": "Soil_Snow"
    },
    {
      "x": 3,
      "y": 2,
      "z": -3,
      "name": "Soil_Snow"
    },
    {
      "x": 3,
      "y": 3,
      "z": -3,
      "name": "Soil_Snow"
    },
    {
      "x": 3,
      "y": 4,
      "z": -3,
      "name": "Soil_Snow"
    },
    {
      "x": 3,
      "y": 5,
      "z": -3,
      "name": "Soil_Snow"
    },
    {
      "x": 3,
      "y": -1,
      "z": -2,
      "name": "Soil_Snow"
    },
    {
      "x": 3,
      "y": 0,
      "z": -2,
      "name": "Empty"
    },
    {
      "x": 3,
      "y": 1,
      "z": -2,
      "name": "Soil_Snow"
    },
    {
      "x": 3,
      "y": 2,
      "z": -2,
      "name": "Rock_Ice_Permafrost"
    },
    {
      "x": 3,
      "y": 3,
      "z": -2,
      "name": "Soil_Snow"
    },
    {
      "x": 3,
      "y": 4,
      "z": -2,
      "name": "Soil_Snow"
    },
    {
      "x": 3,
      "y": 5,
      "z": -2,
      "name": "Soil_Snow"
    },
    {
      "x": 3,
      "y": 6,
      "z": -2,
      "name": "Soil_Snow"
    },
    {
      "x": 3,
      "y": -1,
      "z": -1,
      "name": "Soil_Snow"
    },
    {
      "x": 3,
      "y": 0,
      "z": -1,
      "name": "Empty"
    },
    {
      "x": 3,
      "y": 1,
      "z": -1,
      "name": "Empty"
    },
    {
      "x": 3,
      "y": 2,
      "z": -1,
      "name": "Empty"
    },
    {
      "x": 3,
      "y": 3,
      "z": -1,
      "name": "Empty"
    },
    {
      "x": 3,
      "y": 4,
      "z": -1,
      "name": "Soil_Snow"
    },
    {
      "x": 3,
      "y": 5,
      "z": -1,
      "name": "Soil_Snow"
    },
    {
      "x": 3,
      "y": 6,
      "z": -1,
      "name": "Soil_Snow"
    },
    {
      "x": 3,
      "y": -2,
      "z": 0,
      "name": "Soil_Snow"
    },
    {
      "x": 3,
      "y": -1,
      "z": 0,
      "name": "Soil_Snow"
    },
    {
      "x": 3,
      "y": 0,
      "z": 0,
      "name": "Empty"
    },
    {
      "x": 3,
      "y": 1,
      "z": 0,
      "name": "Empty"
    },
    {
      "x": 3,
      "y": 2,
      "z": 0,
      "name": "Empty"
    },
    {
      "x": 3,
      "y": 3,
      "z": 0,
      "name": "Empty"
    },
    {
      "x": 3,
      "y": 4,
      "z": 0,
      "name": "Soil_Snow"
    },
    {
      "x": 3,
      "y": 5,
      "z": 0,
      "name": "Soil_Snow"
    },
    {
      "x": 3,
      "y": 6,
      "z": 0,
      "name": "Soil_Snow"
    },
    {
      "x": 3,
      "y": -2,
      "z": 1,
      "name": "Soil_Snow"
    },
    {
      "x": 3,
      "y": -1,
      "z": 1,
      "name": "Soil_Snow_Half"
    },
    {
      "x": 3,
      "y": 0,
      "z": 1,
      "name": "Empty"
    },
    {
      "x": 3,
      "y": 1,
      "z": 1,
      "name": "Empty"
    },
    {
      "x": 3,
      "y": 2,
      "z": 1,
      "name": "Empty"
    },
    {
      "x": 3,
      "y": 3,
      "z": 1,
      "name": "Empty"
    },
    {
      "x": 3,
      "y": 4,
      "z": 1,
      "name": "Empty"
    },
    {
      "x": 3,
      "y": 5,
      "z": 1,
      "name": "Soil_Snow"
    },
    {
      "x": 3,
      "y": 6,
      "z": 1,
      "name": "Soil_Snow"
    },
    {
      "x": 3,
      "y": -2,
      "z": 2,
      "name": "Soil_Snow"
    },
    {
      "x": 3,
      "y": -1,
      "z": 2,
      "name": "Soil_Snow_Half"
    },
    {
      "x": 3,
      "y": 0,
      "z": 2,
      "name": "Empty"
    },
    {
      "x": 3,
      "y": 1,
      "z": 2,
      "name": "Empty"
    },
    {
      "x": 3,
      "y": 2,
      "z": 2,
      "name": "Empty"
    },
    {
      "x": 3,
      "y": 3,
      "z": 2,
      "name": "Empty"
    },
    {
      "x": 3,
      "y": 4,
      "z": 2,
      "name": "Soil_Snow"
    },
    {
      "x": 3,
      "y": 5,
      "z": 2,
      "name": "Soil_Snow"
    },
    {
      "x": 3,
      "y": 6,
      "z": 2,
      "name": "Soil_Snow"
    },
    {
      "x": 3,
      "y": -1,
      "z": 3,
      "name": "Soil_Snow"
    },
    {
      "x": 3,
      "y": 0,
      "z": 3,
      "name": "Empty"
    },
    {
      "x": 3,
      "y": 1,
      "z": 3,
      "name": "Empty"
    },
    {
      "x": 3,
      "y": 2,
      "z": 3,
      "name": "Empty"
    },
    {
      "x": 3,
      "y": 3,
      "z": 3,
      "name": "Soil_Snow"
    },
    {
      "x": 3,
      "y": 4,
      "z": 3,
      "name": "Soil_Snow"
    },
    {
      "x": 3,
      "y": 5,
      "z": 3,
      "name": "Soil_Snow"
    },
    {
      "x": 3,
      "y": 6,
      "z": 3,
      "name": "Soil_Snow"
    },
    {
      "x": 3,
      "y": 0,
      "z": 4,
      "name": "Soil_Snow"
    },
    {
      "x": 3,
      "y": 1,
      "z": 4,
      "name": "Soil_Snow"
    },
    {
      "x": 3,
      "y": 2,
      "z": 4,
      "name": "Empty"
    },
    {
      "x": 3,
      "y": 3,
      "z": 4,
      "name": "Soil_Snow"
    },
    {
      "x": 3,
      "y": 4,
      "z": 4,
      "name": "Soil_Snow"
    },
    {
      "x": 3,
      "y": 5,
      "z": 4,
      "name": "Soil_Snow"
    },
    {
      "x": 3,
      "y": 6,
      "z": 4,
      "name": "Soil_Snow"
    },
    {
      "x": 3,
      "y": 0,
      "z": 5,
      "name": "Soil_Snow"
    },
    {
      "x": 3,
      "y": 1,
      "z": 5,
      "name": "Soil_Snow"
    },
    {
      "x": 3,
      "y": 2,
      "z": 5,
      "name": "Soil_Snow"
    },
    {
      "x": 3,
      "y": 3,
      "z": 5,
      "name": "Soil_Snow"
    },
    {
      "x": 3,
      "y": 4,
      "z": 5,
      "name": "Soil_Snow"
    },
    {
      "x": 3,
      "y": 5,
      "z": 5,
      "name": "Soil_Snow"
    },
    {
      "x": 3,
      "y": 6,
      "z": 5,
      "name": "Soil_Snow"
    },
    {
      "x": 3,
      "y": 0,
      "z": 6,
      "name": "Soil_Snow"
    },
    {
      "x": 3,
      "y": 1,
      "z": 6,
      "name": "Soil_Snow"
    },
    {
      "x": 3,
      "y": 2,
      "z": 6,
      "name": "Soil_Snow"
    },
    {
      "x": 3,
      "y": 3,
      "z": 6,
      "name": "Soil_Snow"
    },
    {
      "x": 3,
      "y": 4,
      "z": 6,
      "name": "Soil_Snow"
    },
    {
      "x": 3,
      "y": 5,
      "z": 6,
      "name": "Soil_Snow"
    },
    {
      "x": 3,
      "y": 0,
      "z": 7,
      "name": "Soil_Snow"
    },
    {
      "x": 3,
      "y": 1,
      "z": 7,
      "name": "Soil_Snow"
    },
    {
      "x": 3,
      "y": 2,
      "z": 7,
      "name": "Soil_Snow"
    },
    {
      "x": 3,
      "y": 3,
      "z": 7,
      "name": "Soil_Snow"
    },
    {
      "x": 3,
      "y": 4,
      "z": 7,
      "name": "Soil_Snow"
    },
    {
      "x": 3,
      "y": 5,
      "z": 7,
      "name": "Soil_Snow"
    },
    {
      "x": 3,
      "y": 0,
      "z": 8,
      "name": "Soil_Snow"
    },
    {
      "x": 3,
      "y": 1,
      "z": 8,
      "name": "Soil_Snow"
    },
    {
      "x": 3,
      "y": 2,
      "z": 8,
      "name": "Soil_Snow"
    },
    {
      "x": 3,
      "y": 3,
      "z": 8,
      "name": "Soil_Snow"
    },
    {
      "x": 3,
      "y": 4,
      "z": 8,
      "name": "Soil_Snow"
    },
    {
      "x": 3,
      "y": 5,
      "z": 8,
      "name": "Soil_Snow"
    },
    {
      "x": 3,
      "y": 0,
      "z": 9,
      "name": "Soil_Snow"
    },
    {
      "x": 3,
      "y": 1,
      "z": 9,
      "name": "Soil_Snow"
    },
    {
      "x": 3,
      "y": 2,
      "z": 9,
      "name": "Soil_Snow"
    },
    {
      "x": 3,
      "y": 3,
      "z": 9,
      "name": "Soil_Snow"
    },
    {
      "x": 3,
      "y": 4,
      "z": 9,
      "name": "Soil_Snow"
    },
    {
      "x": 3,
      "y": 0,
      "z": 10,
      "name": "Soil_Snow"
    },
    {
      "x": 3,
      "y": 1,
      "z": 10,
      "name": "Soil_Snow"
    },
    {
      "x": 3,
      "y": 2,
      "z": 10,
      "name": "Soil_Snow"
    },
    {
      "x": 3,
      "y": 3,
      "z": 10,
      "name": "Soil_Snow"
    },
    {
      "x": 3,
      "y": 4,
      "z": 10,
      "name": "Soil_Snow"
    },
    {
      "x": 3,
      "y": 0,
      "z": 11,
      "name": "Soil_Snow"
    },
    {
      "x": 3,
      "y": 1,
      "z": 11,
      "name": "Soil_Snow"
    },
    {
      "x": 3,
      "y": 2,
      "z": 11,
      "name": "Soil_Snow"
    },
    {
      "x": 3,
      "y": 3,
      "z": 11,
      "name": "Soil_Snow"
    },
    {
      "x": 3,
      "y": 0,
      "z": 12,
      "name": "Soil_Snow"
    },
    {
      "x": 3,
      "y": 1,
      "z": 12,
      "name": "Soil_Snow"
    },
    {
      "x": 3,
      "y": 2,
      "z": 12,
      "name": "Soil_Snow"
    },
    {
      "x": 3,
      "y": 0,
      "z": 13,
      "name": "Soil_Snow"
    },
    {
      "x": 3,
      "y": 1,
      "z": 13,
      "name": "Soil_Snow"
    },
    {
      "x": 3,
      "y": 2,
      "z": 13,
      "name": "Soil_Snow"
    },
    {
      "x": 3,
      "y": 0,
      "z": 14,
      "name": "Soil_Snow"
    },
    {
      "x": 3,
      "y": 0,
      "z": 15,
      "name": "Soil_Snow"
    },
    {
      "x": 4,
      "y": 0,
      "z": -16,
      "name": "Soil_Snow"
    },
    {
      "x": 4,
      "y": 0,
      "z": -15,
      "name": "Soil_Snow"
    },
    {
      "x": 4,
      "y": 1,
      "z": -15,
      "name": "Soil_Snow"
    },
    {
      "x": 4,
      "y": 0,
      "z": -14,
      "name": "Soil_Snow"
    },
    {
      "x": 4,
      "y": 1,
      "z": -14,
      "name": "Soil_Snow"
    },
    {
      "x": 4,
      "y": 0,
      "z": -13,
      "name": "Soil_Snow"
    },
    {
      "x": 4,
      "y": 1,
      "z": -13,
      "name": "Soil_Snow"
    },
    {
      "x": 4,
      "y": 0,
      "z": -12,
      "name": "Soil_Snow"
    },
    {
      "x": 4,
      "y": 1,
      "z": -12,
      "name": "Soil_Snow"
    },
    {
      "x": 4,
      "y": 2,
      "z": -12,
      "name": "Soil_Snow"
    },
    {
      "x": 4,
      "y": 0,
      "z": -11,
      "name": "Soil_Snow"
    },
    {
      "x": 4,
      "y": 1,
      "z": -11,
      "name": "Soil_Snow"
    },
    {
      "x": 4,
      "y": 2,
      "z": -11,
      "name": "Soil_Snow"
    },
    {
      "x": 4,
      "y": 0,
      "z": -10,
      "name": "Soil_Snow"
    },
    {
      "x": 4,
      "y": 1,
      "z": -10,
      "name": "Soil_Snow"
    },
    {
      "x": 4,
      "y": 2,
      "z": -10,
      "name": "Soil_Snow"
    },
    {
      "x": 4,
      "y": 3,
      "z": -10,
      "name": "Soil_Snow"
    },
    {
      "x": 4,
      "y": 0,
      "z": -9,
      "name": "Soil_Snow"
    },
    {
      "x": 4,
      "y": 1,
      "z": -9,
      "name": "Soil_Snow"
    },
    {
      "x": 4,
      "y": 2,
      "z": -9,
      "name": "Soil_Snow"
    },
    {
      "x": 4,
      "y": 3,
      "z": -9,
      "name": "Soil_Snow"
    },
    {
      "x": 4,
      "y": 0,
      "z": -8,
      "name": "Soil_Snow"
    },
    {
      "x": 4,
      "y": 1,
      "z": -8,
      "name": "Soil_Snow"
    },
    {
      "x": 4,
      "y": 2,
      "z": -8,
      "name": "Soil_Snow"
    },
    {
      "x": 4,
      "y": 3,
      "z": -8,
      "name": "Soil_Snow"
    },
    {
      "x": 4,
      "y": 4,
      "z": -8,
      "name": "Soil_Snow"
    },
    {
      "x": 4,
      "y": 0,
      "z": -7,
      "name": "Soil_Snow"
    },
    {
      "x": 4,
      "y": 1,
      "z": -7,
      "name": "Soil_Snow"
    },
    {
      "x": 4,
      "y": 2,
      "z": -7,
      "name": "Soil_Snow"
    },
    {
      "x": 4,
      "y": 3,
      "z": -7,
      "name": "Soil_Snow"
    },
    {
      "x": 4,
      "y": 4,
      "z": -7,
      "name": "Soil_Snow"
    },
    {
      "x": 4,
      "y": 0,
      "z": -6,
      "name": "Soil_Snow"
    },
    {
      "x": 4,
      "y": 1,
      "z": -6,
      "name": "Soil_Snow"
    },
    {
      "x": 4,
      "y": 2,
      "z": -6,
      "name": "Soil_Snow"
    },
    {
      "x": 4,
      "y": 3,
      "z": -6,
      "name": "Soil_Snow"
    },
    {
      "x": 4,
      "y": 4,
      "z": -6,
      "name": "Soil_Snow"
    },
    {
      "x": 4,
      "y": 5,
      "z": -6,
      "name": "Soil_Snow"
    },
    {
      "x": 4,
      "y": 0,
      "z": -5,
      "name": "Soil_Snow"
    },
    {
      "x": 4,
      "y": 1,
      "z": -5,
      "name": "Soil_Snow"
    },
    {
      "x": 4,
      "y": 2,
      "z": -5,
      "name": "Soil_Snow"
    },
    {
      "x": 4,
      "y": 3,
      "z": -5,
      "name": "Soil_Snow"
    },
    {
      "x": 4,
      "y": 4,
      "z": -5,
      "name": "Soil_Snow"
    },
    {
      "x": 4,
      "y": 5,
      "z": -5,
      "name": "Soil_Snow"
    },
    {
      "x": 4,
      "y": 0,
      "z": -4,
      "name": "Soil_Snow"
    },
    {
      "x": 4,
      "y": 1,
      "z": -4,
      "name": "Soil_Snow"
    },
    {
      "x": 4,
      "y": 2,
      "z": -4,
      "name": "Soil_Snow"
    },
    {
      "x": 4,
      "y": 3,
      "z": -4,
      "name": "Soil_Snow"
    },
    {
      "x": 4,
      "y": 4,
      "z": -4,
      "name": "Soil_Snow"
    },
    {
      "x": 4,
      "y": 5,
      "z": -4,
      "name": "Soil_Snow"
    },
    {
      "x": 4,
      "y": 6,
      "z": -4,
      "name": "Soil_Snow"
    },
    {
      "x": 4,
      "y": -1,
      "z": -3,
      "name": "Soil_Snow"
    },
    {
      "x": 4,
      "y": 0,
      "z": -3,
      "name": "Soil_Snow"
    },
    {
      "x": 4,
      "y": 1,
      "z": -3,
      "name": "Soil_Snow"
    },
    {
      "x": 4,
      "y": 2,
      "z": -3,
      "name": "Rock_Ice"
    },
    {
      "x": 4,
      "y": 3,
      "z": -3,
      "name": "Soil_Snow"
    },
    {
      "x": 4,
      "y": 4,
      "z": -3,
      "name": "Soil_Snow"
    },
    {
      "x": 4,
      "y": 5,
      "z": -3,
      "name": "Soil_Snow"
    },
    {
      "x": 4,
      "y": 6,
      "z": -3,
      "name": "Soil_Snow"
    },
    {
      "x": 4,
      "y": -1,
      "z": -2,
      "name": "Soil_Snow"
    },
    {
      "x": 4,
      "y": 0,
      "z": -2,
      "name": "Soil_Snow"
    },
    {
      "x": 4,
      "y": 1,
      "z": -2,
      "name": "Rock_Ice"
    },
    {
      "x": 4,
      "y": 2,
      "z": -2,
      "name": "Rock_Ice"
    },
    {
      "x": 4,
      "y": 3,
      "z": -2,
      "name": "Rock_Ice_Permafrost"
    },
    {
      "x": 4,
      "y": 4,
      "z": -2,
      "name": "Soil_Snow"
    },
    {
      "x": 4,
      "y": 5,
      "z": -2,
      "name": "Soil_Snow"
    },
    {
      "x": 4,
      "y": 6,
      "z": -2,
      "name": "Soil_Snow"
    },
    {
      "x": 4,
      "y": -2,
      "z": -1,
      "name": "Soil_Snow"
    },
    {
      "x": 4,
      "y": -1,
      "z": -1,
      "name": "Soil_Snow"
    },
    {
      "x": 4,
      "y": 0,
      "z": -1,
      "name": "Empty"
    },
    {
      "x": 4,
      "y": 1,
      "z": -1,
      "name": "Empty"
    },
    {
      "x": 4,
      "y": 2,
      "z": -1,
      "name": "Empty"
    },
    {
      "x": 4,
      "y": 3,
      "z": -1,
      "name": "Empty"
    },
    {
      "x": 4,
      "y": 4,
      "z": -1,
      "name": "Soil_Snow"
    },
    {
      "x": 4,
      "y": 5,
      "z": -1,
      "name": "Soil_Snow"
    },
    {
      "x": 4,
      "y": 6,
      "z": -1,
      "name": "Soil_Snow"
    },
    {
      "x": 4,
      "y": -2,
      "z": 0,
      "name": "Soil_Snow"
    },
    {
      "x": 4,
      "y": -1,
      "z": 0,
      "name": "Soil_Snow_Half"
    },
    {
      "x": 4,
      "y": 0,
      "z": 0,
      "name": "Empty"
    },
    {
      "x": 4,
      "y": 1,
      "z": 0,
      "name": "Empty"
    },
    {
      "x": 4,
      "y": 2,
      "z": 0,
      "name": "Empty"
    },
    {
      "x": 4,
      "y": 3,
      "z": 0,
      "name": "Empty"
    },
    {
      "x": 4,
      "y": 4,
      "z": 0,
      "name": "Soil_Snow"
    },
    {
      "x": 4,
      "y": 5,
      "z": 0,
      "name": "Soil_Snow"
    },
    {
      "x": 4,
      "y": 6,
      "z": 0,
      "name": "Soil_Snow"
    },
    {
      "x": 4,
      "y": 7,
      "z": 0,
      "name": "Soil_Snow"
    },
    {
      "x": 4,
      "y": -2,
      "z": 1,
      "name": "Soil_Snow"
    },
    {
      "x": 4,
      "y": -1,
      "z": 1,
      "name": "Empty"
    },
    {
      "x": 4,
      "y": 0,
      "z": 1,
      "name": "Empty"
    },
    {
      "x": 4,
      "y": 1,
      "z": 1,
      "name": "Empty"
    },
    {
      "x": 4,
      "y": 2,
      "z": 1,
      "name": "Empty"
    },
    {
      "x": 4,
      "y": 3,
      "z": 1,
      "name": "Empty"
    },
    {
      "x": 4,
      "y": 4,
      "z": 1,
      "name": "Soil_Snow"
    },
    {
      "x": 4,
      "y": 5,
      "z": 1,
      "name": "Soil_Snow"
    },
    {
      "x": 4,
      "y": 6,
      "z": 1,
      "name": "Soil_Snow"
    },
    {
      "x": 4,
      "y": 7,
      "z": 1,
      "name": "Soil_Snow"
    },
    {
      "x": 4,
      "y": -2,
      "z": 2,
      "name": "Soil_Snow"
    },
    {
      "x": 4,
      "y": -1,
      "z": 2,
      "name": "Empty"
    },
    {
      "x": 4,
      "y": 0,
      "z": 2,
      "name": "Empty"
    },
    {
      "x": 4,
      "y": 1,
      "z": 2,
      "name": "Empty"
    },
    {
      "x": 4,
      "y": 2,
      "z": 2,
      "name": "Empty"
    },
    {
      "x": 4,
      "y": 3,
      "z": 2,
      "name": "Empty"
    },
    {
      "x": 4,
      "y": 4,
      "z": 2,
      "name": "Soil_Snow"
    },
    {
      "x": 4,
      "y": 5,
      "z": 2,
      "name": "Soil_Snow"
    },
    {
      "x": 4,
      "y": 6,
      "z": 2,
      "name": "Soil_Snow"
    },
    {
      "x": 4,
      "y": 7,
      "z": 2,
      "name": "Soil_Snow"
    },
    {
      "x": 4,
      "y": -1,
      "z": 3,
      "name": "Soil_Snow"
    },
    {
      "x": 4,
      "y": 0,
      "z": 3,
      "name": "Empty"
    },
    {
      "x": 4,
      "y": 1,
      "z": 3,
      "name": "Empty"
    },
    {
      "x": 4,
      "y": 2,
      "z": 3,
      "name": "Empty"
    },
    {
      "x": 4,
      "y": 3,
      "z": 3,
      "name": "Soil_Snow"
    },
    {
      "x": 4,
      "y": 4,
      "z": 3,
      "name": "Soil_Snow"
    },
    {
      "x": 4,
      "y": 5,
      "z": 3,
      "name": "Soil_Snow"
    },
    {
      "x": 4,
      "y": 6,
      "z": 3,
      "name": "Soil_Snow"
    },
    {
      "x": 4,
      "y": 7,
      "z": 3,
      "name": "Soil_Snow"
    },
    {
      "x": 4,
      "y": 0,
      "z": 4,
      "name": "Soil_Snow"
    },
    {
      "x": 4,
      "y": 1,
      "z": 4,
      "name": "Soil_Snow"
    },
    {
      "x": 4,
      "y": 2,
      "z": 4,
      "name": "Empty"
    },
    {
      "x": 4,
      "y": 3,
      "z": 4,
      "name": "Soil_Snow"
    },
    {
      "x": 4,
      "y": 4,
      "z": 4,
      "name": "Soil_Snow"
    },
    {
      "x": 4,
      "y": 5,
      "z": 4,
      "name": "Soil_Snow"
    },
    {
      "x": 4,
      "y": 6,
      "z": 4,
      "name": "Soil_Snow"
    },
    {
      "x": 4,
      "y": 0,
      "z": 5,
      "name": "Soil_Snow"
    },
    {
      "x": 4,
      "y": 1,
      "z": 5,
      "name": "Soil_Snow"
    },
    {
      "x": 4,
      "y": 2,
      "z": 5,
      "name": "Soil_Snow"
    },
    {
      "x": 4,
      "y": 3,
      "z": 5,
      "name": "Soil_Snow"
    },
    {
      "x": 4,
      "y": 4,
      "z": 5,
      "name": "Soil_Snow"
    },
    {
      "x": 4,
      "y": 5,
      "z": 5,
      "name": "Soil_Snow"
    },
    {
      "x": 4,
      "y": 6,
      "z": 5,
      "name": "Soil_Snow"
    },
    {
      "x": 4,
      "y": 0,
      "z": 6,
      "name": "Soil_Snow"
    },
    {
      "x": 4,
      "y": 1,
      "z": 6,
      "name": "Soil_Snow"
    },
    {
      "x": 4,
      "y": 2,
      "z": 6,
      "name": "Soil_Snow"
    },
    {
      "x": 4,
      "y": 3,
      "z": 6,
      "name": "Soil_Snow"
    },
    {
      "x": 4,
      "y": 4,
      "z": 6,
      "name": "Soil_Snow"
    },
    {
      "x": 4,
      "y": 5,
      "z": 6,
      "name": "Soil_Snow"
    },
    {
      "x": 4,
      "y": 6,
      "z": 6,
      "name": "Soil_Snow"
    },
    {
      "x": 4,
      "y": 0,
      "z": 7,
      "name": "Soil_Snow"
    },
    {
      "x": 4,
      "y": 1,
      "z": 7,
      "name": "Soil_Snow"
    },
    {
      "x": 4,
      "y": 2,
      "z": 7,
      "name": "Soil_Snow"
    },
    {
      "x": 4,
      "y": 3,
      "z": 7,
      "name": "Soil_Snow"
    },
    {
      "x": 4,
      "y": 4,
      "z": 7,
      "name": "Soil_Snow"
    },
    {
      "x": 4,
      "y": 5,
      "z": 7,
      "name": "Soil_Snow"
    },
    {
      "x": 4,
      "y": 0,
      "z": 8,
      "name": "Soil_Snow"
    },
    {
      "x": 4,
      "y": 1,
      "z": 8,
      "name": "Soil_Snow"
    },
    {
      "x": 4,
      "y": 2,
      "z": 8,
      "name": "Soil_Snow"
    },
    {
      "x": 4,
      "y": 3,
      "z": 8,
      "name": "Soil_Snow"
    },
    {
      "x": 4,
      "y": 4,
      "z": 8,
      "name": "Soil_Snow"
    },
    {
      "x": 4,
      "y": 5,
      "z": 8,
      "name": "Soil_Snow"
    },
    {
      "x": 4,
      "y": 0,
      "z": 9,
      "name": "Soil_Snow"
    },
    {
      "x": 4,
      "y": 1,
      "z": 9,
      "name": "Soil_Snow"
    },
    {
      "x": 4,
      "y": 2,
      "z": 9,
      "name": "Soil_Snow"
    },
    {
      "x": 4,
      "y": 3,
      "z": 9,
      "name": "Soil_Snow"
    },
    {
      "x": 4,
      "y": 4,
      "z": 9,
      "name": "Soil_Snow"
    },
    {
      "x": 4,
      "y": 0,
      "z": 10,
      "name": "Soil_Snow"
    },
    {
      "x": 4,
      "y": 1,
      "z": 10,
      "name": "Soil_Snow"
    },
    {
      "x": 4,
      "y": 2,
      "z": 10,
      "name": "Soil_Snow"
    },
    {
      "x": 4,
      "y": 3,
      "z": 10,
      "name": "Soil_Snow"
    },
    {
      "x": 4,
      "y": 4,
      "z": 10,
      "name": "Soil_Snow"
    },
    {
      "x": 4,
      "y": 0,
      "z": 11,
      "name": "Soil_Snow"
    },
    {
      "x": 4,
      "y": 1,
      "z": 11,
      "name": "Soil_Snow"
    },
    {
      "x": 4,
      "y": 2,
      "z": 11,
      "name": "Soil_Snow"
    },
    {
      "x": 4,
      "y": 3,
      "z": 11,
      "name": "Soil_Snow"
    },
    {
      "x": 4,
      "y": 0,
      "z": 12,
      "name": "Soil_Snow"
    },
    {
      "x": 4,
      "y": 1,
      "z": 12,
      "name": "Soil_Snow"
    },
    {
      "x": 4,
      "y": 2,
      "z": 12,
      "name": "Soil_Snow"
    },
    {
      "x": 4,
      "y": 3,
      "z": 12,
      "name": "Soil_Snow"
    },
    {
      "x": 4,
      "y": 0,
      "z": 13,
      "name": "Soil_Snow"
    },
    {
      "x": 4,
      "y": 1,
      "z": 13,
      "name": "Soil_Snow"
    },
    {
      "x": 4,
      "y": 2,
      "z": 13,
      "name": "Soil_Snow"
    },
    {
      "x": 4,
      "y": 0,
      "z": 14,
      "name": "Soil_Snow"
    },
    {
      "x": 4,
      "y": 1,
      "z": 14,
      "name": "Soil_Snow"
    },
    {
      "x": 4,
      "y": 0,
      "z": 15,
      "name": "Soil_Snow"
    },
    {
      "x": 5,
      "y": 0,
      "z": -17,
      "name": "Soil_Snow"
    },
    {
      "x": 5,
      "y": 0,
      "z": -16,
      "name": "Soil_Snow"
    },
    {
      "x": 5,
      "y": 1,
      "z": -16,
      "name": "Soil_Snow"
    },
    {
      "x": 5,
      "y": 0,
      "z": -15,
      "name": "Soil_Snow"
    },
    {
      "x": 5,
      "y": 1,
      "z": -15,
      "name": "Soil_Snow"
    },
    {
      "x": 5,
      "y": 0,
      "z": -14,
      "name": "Soil_Snow"
    },
    {
      "x": 5,
      "y": 1,
      "z": -14,
      "name": "Soil_Snow"
    },
    {
      "x": 5,
      "y": 0,
      "z": -13,
      "name": "Soil_Snow"
    },
    {
      "x": 5,
      "y": 1,
      "z": -13,
      "name": "Soil_Snow"
    },
    {
      "x": 5,
      "y": 2,
      "z": -13,
      "name": "Soil_Snow"
    },
    {
      "x": 5,
      "y": 0,
      "z": -12,
      "name": "Soil_Snow"
    },
    {
      "x": 5,
      "y": 1,
      "z": -12,
      "name": "Soil_Snow"
    },
    {
      "x": 5,
      "y": 2,
      "z": -12,
      "name": "Soil_Snow"
    },
    {
      "x": 5,
      "y": 0,
      "z": -11,
      "name": "Soil_Snow"
    },
    {
      "x": 5,
      "y": 1,
      "z": -11,
      "name": "Soil_Snow"
    },
    {
      "x": 5,
      "y": 2,
      "z": -11,
      "name": "Soil_Snow"
    },
    {
      "x": 5,
      "y": 3,
      "z": -11,
      "name": "Soil_Snow"
    },
    {
      "x": 5,
      "y": 0,
      "z": -10,
      "name": "Soil_Snow"
    },
    {
      "x": 5,
      "y": 1,
      "z": -10,
      "name": "Soil_Snow"
    },
    {
      "x": 5,
      "y": 2,
      "z": -10,
      "name": "Soil_Snow"
    },
    {
      "x": 5,
      "y": 3,
      "z": -10,
      "name": "Soil_Snow"
    },
    {
      "x": 5,
      "y": 0,
      "z": -9,
      "name": "Soil_Snow"
    },
    {
      "x": 5,
      "y": 1,
      "z": -9,
      "name": "Soil_Snow"
    },
    {
      "x": 5,
      "y": 2,
      "z": -9,
      "name": "Soil_Snow"
    },
    {
      "x": 5,
      "y": 3,
      "z": -9,
      "name": "Soil_Snow"
    },
    {
      "x": 5,
      "y": 4,
      "z": -9,
      "name": "Soil_Snow"
    },
    {
      "x": 5,
      "y": 0,
      "z": -8,
      "name": "Soil_Snow"
    },
    {
      "x": 5,
      "y": 1,
      "z": -8,
      "name": "Soil_Snow"
    },
    {
      "x": 5,
      "y": 2,
      "z": -8,
      "name": "Soil_Snow"
    },
    {
      "x": 5,
      "y": 3,
      "z": -8,
      "name": "Soil_Snow"
    },
    {
      "x": 5,
      "y": 4,
      "z": -8,
      "name": "Soil_Snow"
    },
    {
      "x": 5,
      "y": 0,
      "z": -7,
      "name": "Soil_Snow"
    },
    {
      "x": 5,
      "y": 1,
      "z": -7,
      "name": "Soil_Snow"
    },
    {
      "x": 5,
      "y": 2,
      "z": -7,
      "name": "Soil_Snow"
    },
    {
      "x": 5,
      "y": 3,
      "z": -7,
      "name": "Soil_Snow"
    },
    {
      "x": 5,
      "y": 4,
      "z": -7,
      "name": "Soil_Snow"
    },
    {
      "x": 5,
      "y": 5,
      "z": -7,
      "name": "Soil_Snow"
    },
    {
      "x": 5,
      "y": 0,
      "z": -6,
      "name": "Soil_Snow"
    },
    {
      "x": 5,
      "y": 1,
      "z": -6,
      "name": "Soil_Snow"
    },
    {
      "x": 5,
      "y": 2,
      "z": -6,
      "name": "Soil_Snow"
    },
    {
      "x": 5,
      "y": 3,
      "z": -6,
      "name": "Soil_Snow"
    },
    {
      "x": 5,
      "y": 4,
      "z": -6,
      "name": "Soil_Snow"
    },
    {
      "x": 5,
      "y": 5,
      "z": -6,
      "name": "Soil_Snow"
    },
    {
      "x": 5,
      "y": 6,
      "z": -6,
      "name": "Soil_Snow"
    },
    {
      "x": 5,
      "y": 0,
      "z": -5,
      "name": "Soil_Snow"
    },
    {
      "x": 5,
      "y": 1,
      "z": -5,
      "name": "Soil_Snow"
    },
    {
      "x": 5,
      "y": 2,
      "z": -5,
      "name": "Soil_Snow"
    },
    {
      "x": 5,
      "y": 3,
      "z": -5,
      "name": "Soil_Snow"
    },
    {
      "x": 5,
      "y": 4,
      "z": -5,
      "name": "Soil_Snow"
    },
    {
      "x": 5,
      "y": 5,
      "z": -5,
      "name": "Soil_Snow"
    },
    {
      "x": 5,
      "y": 6,
      "z": -5,
      "name": "Soil_Snow"
    },
    {
      "x": 5,
      "y": 0,
      "z": -4,
      "name": "Soil_Snow"
    },
    {
      "x": 5,
      "y": 1,
      "z": -4,
      "name": "Soil_Snow"
    },
    {
      "x": 5,
      "y": 2,
      "z": -4,
      "name": "Soil_Snow"
    },
    {
      "x": 5,
      "y": 3,
      "z": -4,
      "name": "Soil_Snow"
    },
    {
      "x": 5,
      "y": 4,
      "z": -4,
      "name": "Soil_Snow"
    },
    {
      "x": 5,
      "y": 5,
      "z": -4,
      "name": "Soil_Snow"
    },
    {
      "x": 5,
      "y": 6,
      "z": -4,
      "name": "Soil_Snow"
    },
    {
      "x": 5,
      "y": -1,
      "z": -3,
      "name": "Soil_Snow"
    },
    {
      "x": 5,
      "y": 0,
      "z": -3,
      "name": "Soil_Snow"
    },
    {
      "x": 5,
      "y": 1,
      "z": -3,
      "name": "Soil_Snow"
    },
    {
      "x": 5,
      "y": 2,
      "z": -3,
      "name": "Soil_Snow"
    },
    {
      "x": 5,
      "y": 3,
      "z": -3,
      "name": "Soil_Snow"
    },
    {
      "x": 5,
      "y": 4,
      "z": -3,
      "name": "Soil_Snow"
    },
    {
      "x": 5,
      "y": 5,
      "z": -3,
      "name": "Soil_Snow"
    },
    {
      "x": 5,
      "y": 6,
      "z": -3,
      "name": "Soil_Snow"
    },
    {
      "x": 5,
      "y": 7,
      "z": -3,
      "name": "Soil_Snow"
    },
    {
      "x": 5,
      "y": -2,
      "z": -2,
      "name": "Soil_Snow"
    },
    {
      "x": 5,
      "y": -1,
      "z": -2,
      "name": "Soil_Snow"
    },
    {
      "x": 5,
      "y": 0,
      "z": -2,
      "name": "Soil_Snow"
    },
    {
      "x": 5,
      "y": 1,
      "z": -2,
      "name": "Soil_Snow"
    },
    {
      "x": 5,
      "y": 2,
      "z": -2,
      "name": "Rock_Ice_Permafrost"
    },
    {
      "x": 5,
      "y": 3,
      "z": -2,
      "name": "Soil_Snow"
    },
    {
      "x": 5,
      "y": 4,
      "z": -2,
      "name": "Soil_Snow"
    },
    {
      "x": 5,
      "y": 5,
      "z": -2,
      "name": "Soil_Snow"
    },
    {
      "x": 5,
      "y": 6,
      "z": -2,
      "name": "Soil_Snow"
    },
    {
      "x": 5,
      "y": 7,
      "z": -2,
      "name": "Soil_Snow"
    },
    {
      "x": 5,
      "y": -2,
      "z": -1,
      "name": "Soil_Snow"
    },
    {
      "x": 5,
      "y": -1,
      "z": -1,
      "name": "Soil_Snow"
    },
    {
      "x": 5,
      "y": 0,
      "z": -1,
      "name": "Empty"
    },
    {
      "x": 5,
      "y": 1,
      "z": -1,
      "name": "Empty"
    },
    {
      "x": 5,
      "y": 2,
      "z": -1,
      "name": "Empty"
    },
    {
      "x": 5,
      "y": 3,
      "z": -1,
      "name": "Soil_Snow"
    },
    {
      "x": 5,
      "y": 4,
      "z": -1,
      "name": "Soil_Snow"
    },
    {
      "x": 5,
      "y": 5,
      "z": -1,
      "name": "Soil_Snow"
    },
    {
      "x": 5,
      "y": 6,
      "z": -1,
      "name": "Soil_Snow"
    },
    {
      "x": 5,
      "y": 7,
      "z": -1,
      "name": "Soil_Snow"
    },
    {
      "x": 5,
      "y": -2,
      "z": 0,
      "name": "Rock_Ice"
    },
    {
      "x": 5,
      "y": -1,
      "z": 0,
      "name": "Empty"
    },
    {
      "x": 5,
      "y": 0,
      "z": 0,
      "name": "Empty"
    },
    {
      "x": 5,
      "y": 1,
      "z": 0,
      "name": "Empty"
    },
    {
      "x": 5,
      "y": 2,
      "z": 0,
      "name": "Empty"
    },
    {
      "x": 5,
      "y": 3,
      "z": 0,
      "name": "Empty"
    },
    {
      "x": 5,
      "y": 4,
      "z": 0,
      "name": "Soil_Snow"
    },
    {
      "x": 5,
      "y": 5,
      "z": 0,
      "name": "Soil_Snow"
    },
    {
      "x": 5,
      "y": 6,
      "z": 0,
      "name": "Soil_Snow"
    },
    {
      "x": 5,
      "y": 7,
      "z": 0,
      "name": "Soil_Snow"
    },
    {
      "x": 5,
      "y": -2,
      "z": 1,
      "name": "Soil_Snow"
    },
    {
      "x": 5,
      "y": -1,
      "z": 1,
      "name": "Empty"
    },
    {
      "x": 5,
      "y": 0,
      "z": 1,
      "name": "Empty"
    },
    {
      "x": 5,
      "y": 1,
      "z": 1,
      "name": "Empty"
    },
    {
      "x": 5,
      "y": 2,
      "z": 1,
      "name": "Empty"
    },
    {
      "x": 5,
      "y": 3,
      "z": 1,
      "name": "Empty"
    },
    {
      "x": 5,
      "y": 4,
      "z": 1,
      "name": "Soil_Snow"
    },
    {
      "x": 5,
      "y": 5,
      "z": 1,
      "name": "Soil_Snow"
    },
    {
      "x": 5,
      "y": 6,
      "z": 1,
      "name": "Soil_Snow"
    },
    {
      "x": 5,
      "y": 7,
      "z": 1,
      "name": "Soil_Snow"
    },
    {
      "x": 5,
      "y": -2,
      "z": 2,
      "name": "Soil_Snow"
    },
    {
      "x": 5,
      "y": -1,
      "z": 2,
      "name": "Empty"
    },
    {
      "x": 5,
      "y": 0,
      "z": 2,
      "name": "Empty"
    },
    {
      "x": 5,
      "y": 1,
      "z": 2,
      "name": "Empty"
    },
    {
      "x": 5,
      "y": 2,
      "z": 2,
      "name": "Empty"
    },
    {
      "x": 5,
      "y": 3,
      "z": 2,
      "name": "Soil_Snow"
    },
    {
      "x": 5,
      "y": 4,
      "z": 2,
      "name": "Soil_Snow"
    },
    {
      "x": 5,
      "y": 5,
      "z": 2,
      "name": "Soil_Snow"
    },
    {
      "x": 5,
      "y": 6,
      "z": 2,
      "name": "Soil_Snow"
    },
    {
      "x": 5,
      "y": 7,
      "z": 2,
      "name": "Soil_Snow"
    },
    {
      "x": 5,
      "y": -2,
      "z": 3,
      "name": "Soil_Snow"
    },
    {
      "x": 5,
      "y": -1,
      "z": 3,
      "name": "Soil_Snow"
    },
    {
      "x": 5,
      "y": 0,
      "z": 3,
      "name": "Empty"
    },
    {
      "x": 5,
      "y": 1,
      "z": 3,
      "name": "Empty"
    },
    {
      "x": 5,
      "y": 2,
      "z": 3,
      "name": "Empty"
    },
    {
      "x": 5,
      "y": 3,
      "z": 3,
      "name": "Soil_Snow"
    },
    {
      "x": 5,
      "y": 4,
      "z": 3,
      "name": "Soil_Snow"
    },
    {
      "x": 5,
      "y": 5,
      "z": 3,
      "name": "Soil_Snow"
    },
    {
      "x": 5,
      "y": 6,
      "z": 3,
      "name": "Soil_Snow"
    },
    {
      "x": 5,
      "y": 7,
      "z": 3,
      "name": "Soil_Snow"
    },
    {
      "x": 5,
      "y": -1,
      "z": 4,
      "name": "Soil_Snow"
    },
    {
      "x": 5,
      "y": 0,
      "z": 4,
      "name": "Soil_Snow"
    },
    {
      "x": 5,
      "y": 1,
      "z": 4,
      "name": "Soil_Snow"
    },
    {
      "x": 5,
      "y": 2,
      "z": 4,
      "name": "Empty"
    },
    {
      "x": 5,
      "y": 3,
      "z": 4,
      "name": "Soil_Snow"
    },
    {
      "x": 5,
      "y": 4,
      "z": 4,
      "name": "Soil_Snow"
    },
    {
      "x": 5,
      "y": 5,
      "z": 4,
      "name": "Soil_Snow"
    },
    {
      "x": 5,
      "y": 6,
      "z": 4,
      "name": "Soil_Snow"
    },
    {
      "x": 5,
      "y": 7,
      "z": 4,
      "name": "Soil_Snow"
    },
    {
      "x": 5,
      "y": 0,
      "z": 5,
      "name": "Soil_Snow"
    },
    {
      "x": 5,
      "y": 1,
      "z": 5,
      "name": "Soil_Snow"
    },
    {
      "x": 5,
      "y": 2,
      "z": 5,
      "name": "Soil_Snow"
    },
    {
      "x": 5,
      "y": 3,
      "z": 5,
      "name": "Soil_Snow"
    },
    {
      "x": 5,
      "y": 4,
      "z": 5,
      "name": "Soil_Snow"
    },
    {
      "x": 5,
      "y": 5,
      "z": 5,
      "name": "Soil_Snow"
    },
    {
      "x": 5,
      "y": 6,
      "z": 5,
      "name": "Soil_Snow"
    },
    {
      "x": 5,
      "y": 7,
      "z": 5,
      "name": "Soil_Snow"
    },
    {
      "x": 5,
      "y": 0,
      "z": 6,
      "name": "Soil_Snow"
    },
    {
      "x": 5,
      "y": 1,
      "z": 6,
      "name": "Soil_Snow"
    },
    {
      "x": 5,
      "y": 2,
      "z": 6,
      "name": "Soil_Snow"
    },
    {
      "x": 5,
      "y": 3,
      "z": 6,
      "name": "Soil_Snow"
    },
    {
      "x": 5,
      "y": 4,
      "z": 6,
      "name": "Soil_Snow"
    },
    {
      "x": 5,
      "y": 5,
      "z": 6,
      "name": "Soil_Snow"
    },
    {
      "x": 5,
      "y": 6,
      "z": 6,
      "name": "Soil_Snow"
    },
    {
      "x": 5,
      "y": 0,
      "z": 7,
      "name": "Soil_Snow"
    },
    {
      "x": 5,
      "y": 1,
      "z": 7,
      "name": "Soil_Snow"
    },
    {
      "x": 5,
      "y": 2,
      "z": 7,
      "name": "Soil_Snow"
    },
    {
      "x": 5,
      "y": 3,
      "z": 7,
      "name": "Soil_Snow"
    },
    {
      "x": 5,
      "y": 4,
      "z": 7,
      "name": "Soil_Snow"
    },
    {
      "x": 5,
      "y": 5,
      "z": 7,
      "name": "Soil_Snow"
    },
    {
      "x": 5,
      "y": 6,
      "z": 7,
      "name": "Soil_Snow"
    },
    {
      "x": 5,
      "y": 0,
      "z": 8,
      "name": "Soil_Snow"
    },
    {
      "x": 5,
      "y": 1,
      "z": 8,
      "name": "Soil_Snow"
    },
    {
      "x": 5,
      "y": 2,
      "z": 8,
      "name": "Soil_Snow"
    },
    {
      "x": 5,
      "y": 3,
      "z": 8,
      "name": "Soil_Snow"
    },
    {
      "x": 5,
      "y": 4,
      "z": 8,
      "name": "Soil_Snow"
    },
    {
      "x": 5,
      "y": 5,
      "z": 8,
      "name": "Soil_Snow"
    },
    {
      "x": 5,
      "y": 0,
      "z": 9,
      "name": "Soil_Snow"
    },
    {
      "x": 5,
      "y": 1,
      "z": 9,
      "name": "Soil_Snow"
    },
    {
      "x": 5,
      "y": 2,
      "z": 9,
      "name": "Soil_Snow"
    },
    {
      "x": 5,
      "y": 3,
      "z": 9,
      "name": "Soil_Snow"
    },
    {
      "x": 5,
      "y": 4,
      "z": 9,
      "name": "Soil_Snow"
    },
    {
      "x": 5,
      "y": 5,
      "z": 9,
      "name": "Soil_Snow"
    },
    {
      "x": 5,
      "y": 0,
      "z": 10,
      "name": "Soil_Snow"
    },
    {
      "x": 5,
      "y": 1,
      "z": 10,
      "name": "Soil_Snow"
    },
    {
      "x": 5,
      "y": 2,
      "z": 10,
      "name": "Soil_Snow"
    },
    {
      "x": 5,
      "y": 3,
      "z": 10,
      "name": "Soil_Snow"
    },
    {
      "x": 5,
      "y": 4,
      "z": 10,
      "name": "Soil_Snow"
    },
    {
      "x": 5,
      "y": 0,
      "z": 11,
      "name": "Soil_Snow"
    },
    {
      "x": 5,
      "y": 1,
      "z": 11,
      "name": "Soil_Snow"
    },
    {
      "x": 5,
      "y": 2,
      "z": 11,
      "name": "Soil_Snow"
    },
    {
      "x": 5,
      "y": 3,
      "z": 11,
      "name": "Soil_Snow"
    },
    {
      "x": 5,
      "y": 4,
      "z": 11,
      "name": "Soil_Snow"
    },
    {
      "x": 5,
      "y": 0,
      "z": 12,
      "name": "Soil_Snow"
    },
    {
      "x": 5,
      "y": 1,
      "z": 12,
      "name": "Soil_Snow"
    },
    {
      "x": 5,
      "y": 2,
      "z": 12,
      "name": "Soil_Snow"
    },
    {
      "x": 5,
      "y": 3,
      "z": 12,
      "name": "Soil_Snow"
    },
    {
      "x": 5,
      "y": 0,
      "z": 13,
      "name": "Soil_Snow"
    },
    {
      "x": 5,
      "y": 1,
      "z": 13,
      "name": "Soil_Snow"
    },
    {
      "x": 5,
      "y": 2,
      "z": 13,
      "name": "Soil_Snow"
    },
    {
      "x": 5,
      "y": 0,
      "z": 14,
      "name": "Soil_Snow"
    },
    {
      "x": 5,
      "y": 1,
      "z": 14,
      "name": "Soil_Snow"
    },
    {
      "x": 5,
      "y": 0,
      "z": 15,
      "name": "Soil_Snow"
    },
    {
      "x": 6,
      "y": 0,
      "z": -17,
      "name": "Soil_Snow"
    },
    {
      "x": 6,
      "y": 0,
      "z": -16,
      "name": "Soil_Snow"
    },
    {
      "x": 6,
      "y": 1,
      "z": -16,
      "name": "Soil_Snow"
    },
    {
      "x": 6,
      "y": 0,
      "z": -15,
      "name": "Soil_Snow"
    },
    {
      "x": 6,
      "y": 1,
      "z": -15,
      "name": "Soil_Snow"
    },
    {
      "x": 6,
      "y": 0,
      "z": -14,
      "name": "Soil_Snow"
    },
    {
      "x": 6,
      "y": 1,
      "z": -14,
      "name": "Soil_Snow"
    },
    {
      "x": 6,
      "y": 2,
      "z": -14,
      "name": "Soil_Snow"
    },
    {
      "x": 6,
      "y": 0,
      "z": -13,
      "name": "Soil_Snow"
    },
    {
      "x": 6,
      "y": 1,
      "z": -13,
      "name": "Soil_Snow"
    },
    {
      "x": 6,
      "y": 2,
      "z": -13,
      "name": "Soil_Snow"
    },
    {
      "x": 6,
      "y": 0,
      "z": -12,
      "name": "Soil_Snow"
    },
    {
      "x": 6,
      "y": 1,
      "z": -12,
      "name": "Soil_Snow"
    },
    {
      "x": 6,
      "y": 2,
      "z": -12,
      "name": "Soil_Snow"
    },
    {
      "x": 6,
      "y": 3,
      "z": -12,
      "name": "Soil_Snow"
    },
    {
      "x": 6,
      "y": 0,
      "z": -11,
      "name": "Soil_Snow"
    },
    {
      "x": 6,
      "y": 1,
      "z": -11,
      "name": "Soil_Snow"
    },
    {
      "x": 6,
      "y": 2,
      "z": -11,
      "name": "Soil_Snow"
    },
    {
      "x": 6,
      "y": 3,
      "z": -11,
      "name": "Soil_Snow"
    },
    {
      "x": 6,
      "y": 0,
      "z": -10,
      "name": "Soil_Snow"
    },
    {
      "x": 6,
      "y": 1,
      "z": -10,
      "name": "Soil_Snow"
    },
    {
      "x": 6,
      "y": 2,
      "z": -10,
      "name": "Soil_Snow"
    },
    {
      "x": 6,
      "y": 3,
      "z": -10,
      "name": "Soil_Snow"
    },
    {
      "x": 6,
      "y": 4,
      "z": -10,
      "name": "Soil_Snow"
    },
    {
      "x": 6,
      "y": 0,
      "z": -9,
      "name": "Soil_Snow"
    },
    {
      "x": 6,
      "y": 1,
      "z": -9,
      "name": "Soil_Snow"
    },
    {
      "x": 6,
      "y": 2,
      "z": -9,
      "name": "Soil_Snow"
    },
    {
      "x": 6,
      "y": 3,
      "z": -9,
      "name": "Soil_Snow"
    },
    {
      "x": 6,
      "y": 4,
      "z": -9,
      "name": "Soil_Snow"
    },
    {
      "x": 6,
      "y": 0,
      "z": -8,
      "name": "Soil_Snow"
    },
    {
      "x": 6,
      "y": 1,
      "z": -8,
      "name": "Soil_Snow"
    },
    {
      "x": 6,
      "y": 2,
      "z": -8,
      "name": "Soil_Snow"
    },
    {
      "x": 6,
      "y": 3,
      "z": -8,
      "name": "Soil_Snow"
    },
    {
      "x": 6,
      "y": 4,
      "z": -8,
      "name": "Soil_Snow"
    },
    {
      "x": 6,
      "y": 5,
      "z": -8,
      "name": "Soil_Snow"
    },
    {
      "x": 6,
      "y": 0,
      "z": -7,
      "name": "Soil_Snow"
    },
    {
      "x": 6,
      "y": 1,
      "z": -7,
      "name": "Soil_Snow"
    },
    {
      "x": 6,
      "y": 2,
      "z": -7,
      "name": "Soil_Snow"
    },
    {
      "x": 6,
      "y": 3,
      "z": -7,
      "name": "Soil_Snow"
    },
    {
      "x": 6,
      "y": 4,
      "z": -7,
      "name": "Soil_Snow"
    },
    {
      "x": 6,
      "y": 5,
      "z": -7,
      "name": "Soil_Snow"
    },
    {
      "x": 6,
      "y": 0,
      "z": -6,
      "name": "Soil_Snow"
    },
    {
      "x": 6,
      "y": 1,
      "z": -6,
      "name": "Soil_Snow"
    },
    {
      "x": 6,
      "y": 2,
      "z": -6,
      "name": "Soil_Snow"
    },
    {
      "x": 6,
      "y": 3,
      "z": -6,
      "name": "Soil_Snow"
    },
    {
      "x": 6,
      "y": 4,
      "z": -6,
      "name": "Soil_Snow"
    },
    {
      "x": 6,
      "y": 5,
      "z": -6,
      "name": "Soil_Snow"
    },
    {
      "x": 6,
      "y": 6,
      "z": -6,
      "name": "Soil_Snow"
    },
    {
      "x": 6,
      "y": 0,
      "z": -5,
      "name": "Soil_Snow"
    },
    {
      "x": 6,
      "y": 1,
      "z": -5,
      "name": "Soil_Snow"
    },
    {
      "x": 6,
      "y": 2,
      "z": -5,
      "name": "Soil_Snow"
    },
    {
      "x": 6,
      "y": 3,
      "z": -5,
      "name": "Soil_Snow"
    },
    {
      "x": 6,
      "y": 4,
      "z": -5,
      "name": "Soil_Snow"
    },
    {
      "x": 6,
      "y": 5,
      "z": -5,
      "name": "Soil_Snow"
    },
    {
      "x": 6,
      "y": 6,
      "z": -5,
      "name": "Soil_Snow"
    },
    {
      "x": 6,
      "y": 0,
      "z": -4,
      "name": "Soil_Snow"
    },
    {
      "x": 6,
      "y": 1,
      "z": -4,
      "name": "Soil_Snow"
    },
    {
      "x": 6,
      "y": 2,
      "z": -4,
      "name": "Soil_Snow"
    },
    {
      "x": 6,
      "y": 3,
      "z": -4,
      "name": "Soil_Snow"
    },
    {
      "x": 6,
      "y": 4,
      "z": -4,
      "name": "Soil_Snow"
    },
    {
      "x": 6,
      "y": 5,
      "z": -4,
      "name": "Soil_Snow"
    },
    {
      "x": 6,
      "y": 6,
      "z": -4,
      "name": "Soil_Snow"
    },
    {
      "x": 6,
      "y": 7,
      "z": -4,
      "name": "Soil_Snow"
    },
    {
      "x": 6,
      "y": -1,
      "z": -3,
      "name": "Soil_Snow"
    },
    {
      "x": 6,
      "y": 0,
      "z": -3,
      "name": "Soil_Snow"
    },
    {
      "x": 6,
      "y": 1,
      "z": -3,
      "name": "Soil_Snow"
    },
    {
      "x": 6,
      "y": 2,
      "z": -3,
      "name": "Soil_Snow"
    },
    {
      "x": 6,
      "y": 3,
      "z": -3,
      "name": "Soil_Snow"
    },
    {
      "x": 6,
      "y": 4,
      "z": -3,
      "name": "Soil_Snow"
    },
    {
      "x": 6,
      "y": 5,
      "z": -3,
      "name": "Soil_Snow"
    },
    {
      "x": 6,
      "y": 6,
      "z": -3,
      "name": "Soil_Snow"
    },
    {
      "x": 6,
      "y": 7,
      "z": -3,
      "name": "Soil_Snow"
    },
    {
      "x": 6,
      "y": -2,
      "z": -2,
      "name": "Soil_Snow"
    },
    {
      "x": 6,
      "y": -1,
      "z": -2,
      "name": "Soil_Snow"
    },
    {
      "x": 6,
      "y": 0,
      "z": -2,
      "name": "Empty"
    },
    {
      "x": 6,
      "y": 1,
      "z": -2,
      "name": "Soil_Snow"
    },
    {
      "x": 6,
      "y": 2,
      "z": -2,
      "name": "Soil_Snow"
    },
    {
      "x": 6,
      "y": 3,
      "z": -2,
      "name": "Soil_Snow"
    },
    {
      "x": 6,
      "y": 4,
      "z": -2,
      "name": "Soil_Snow"
    },
    {
      "x": 6,
      "y": 5,
      "z": -2,
      "name": "Soil_Snow"
    },
    {
      "x": 6,
      "y": 6,
      "z": -2,
      "name": "Soil_Snow"
    },
    {
      "x": 6,
      "y": 7,
      "z": -2,
      "name": "Soil_Snow"
    },
    {
      "x": 6,
      "y": -3,
      "z": -1,
      "name": "Soil_Snow"
    },
    {
      "x": 6,
      "y": -2,
      "z": -1,
      "name": "Rock_Ice_Permafrost"
    },
    {
      "x": 6,
      "y": -1,
      "z": -1,
      "name": "Rock_Ice_Stalactite_Large"
    },
    {
      "x": 6,
      "y": 0,
      "z": -1,
      "name": "Rock_Ice_Stalactite_Large",
      "filler": 1024
    },
    {
      "x": 6,
      "y": 1,
      "z": -1,
      "name": "Empty"
    },
    {
      "x": 6,
      "y": 2,
      "z": -1,
      "name": "Soil_Snow"
    },
    {
      "x": 6,
      "y": 3,
      "z": -1,
      "name": "Soil_Snow"
    },
    {
      "x": 6,
      "y": 4,
      "z": -1,
      "name": "Soil_Snow"
    },
    {
      "x": 6,
      "y": 5,
      "z": -1,
      "name": "Soil_Snow"
    },
    {
      "x": 6,
      "y": 6,
      "z": -1,
      "name": "Soil_Snow"
    },
    {
      "x": 6,
      "y": 7,
      "z": -1,
      "name": "Soil_Snow"
    },
    {
      "x": 6,
      "y": -3,
      "z": 0,
      "name": "Rock_Ice_Permafrost"
    },
    {
      "x": 6,
      "y": -2,
      "z": 0,
      "name": "Rock_Ice_Permafrost"
    },
    {
      "x": 6,
      "y": -1,
      "z": 0,
      "name": "Empty"
    },
    {
      "x": 6,
      "y": 0,
      "z": 0,
      "name": "Empty"
    },
    {
      "x": 6,
      "y": 1,
      "z": 0,
      "name": "Empty"
    },
    {
      "x": 6,
      "y": 2,
      "z": 0,
      "name": "Empty"
    },
    {
      "x": 6,
      "y": 3,
      "z": 0,
      "name": "Empty"
    },
    {
      "x": 6,
      "y": 4,
      "z": 0,
      "name": "Soil_Snow"
    },
    {
      "x": 6,
      "y": 5,
      "z": 0,
      "name": "Soil_Snow"
    },
    {
      "x": 6,
      "y": 6,
      "z": 0,
      "name": "Soil_Snow"
    },
    {
      "x": 6,
      "y": 7,
      "z": 0,
      "name": "Soil_Snow"
    },
    {
      "x": 6,
      "y": -3,
      "z": 1,
      "name": "Soil_Snow"
    },
    {
      "x": 6,
      "y": -2,
      "z": 1,
      "name": "Rock_Ice"
    },
    {
      "x": 6,
      "y": -1,
      "z": 1,
      "name": "Empty"
    },
    {
      "x": 6,
      "y": 0,
      "z": 1,
      "name": "Empty"
    },
    {
      "x": 6,
      "y": 1,
      "z": 1,
      "name": "Empty"
    },
    {
      "x": 6,
      "y": 2,
      "z": 1,
      "name": "Empty"
    },
    {
      "x": 6,
      "y": 3,
      "z": 1,
      "name": "Soil_Snow"
    },
    {
      "x": 6,
      "y": 4,
      "z": 1,
      "name": "Soil_Snow"
    },
    {
      "x": 6,
      "y": 5,
      "z": 1,
      "name": "Soil_Snow"
    },
    {
      "x": 6,
      "y": 6,
      "z": 1,
      "name": "Soil_Snow"
    },
    {
      "x": 6,
      "y": 7,
      "z": 1,
      "name": "Soil_Snow"
    },
    {
      "x": 6,
      "y": -2,
      "z": 2,
      "name": "Soil_Snow"
    },
    {
      "x": 6,
      "y": -1,
      "z": 2,
      "name": "Empty"
    },
    {
      "x": 6,
      "y": 0,
      "z": 2,
      "name": "Empty"
    },
    {
      "x": 6,
      "y": 1,
      "z": 2,
      "name": "Empty"
    },
    {
      "x": 6,
      "y": 2,
      "z": 2,
      "name": "Empty"
    },
    {
      "x": 6,
      "y": 3,
      "z": 2,
      "name": "Soil_Snow"
    },
    {
      "x": 6,
      "y": 4,
      "z": 2,
      "name": "Soil_Snow"
    },
    {
      "x": 6,
      "y": 5,
      "z": 2,
      "name": "Soil_Snow"
    },
    {
      "x": 6,
      "y": 6,
      "z": 2,
      "name": "Soil_Snow"
    },
    {
      "x": 6,
      "y": 7,
      "z": 2,
      "name": "Soil_Snow"
    },
    {
      "x": 6,
      "y": -2,
      "z": 3,
      "name": "Soil_Snow"
    },
    {
      "x": 6,
      "y": -1,
      "z": 3,
      "name": "Empty"
    },
    {
      "x": 6,
      "y": 0,
      "z": 3,
      "name": "Empty"
    },
    {
      "x": 6,
      "y": 1,
      "z": 3,
      "name": "Empty"
    },
    {
      "x": 6,
      "y": 2,
      "z": 3,
      "name": "Empty"
    },
    {
      "x": 6,
      "y": 3,
      "z": 3,
      "name": "Soil_Snow"
    },
    {
      "x": 6,
      "y": 4,
      "z": 3,
      "name": "Soil_Snow"
    },
    {
      "x": 6,
      "y": 5,
      "z": 3,
      "name": "Soil_Snow"
    },
    {
      "x": 6,
      "y": 6,
      "z": 3,
      "name": "Soil_Snow"
    },
    {
      "x": 6,
      "y": 7,
      "z": 3,
      "name": "Soil_Snow"
    },
    {
      "x": 6,
      "y": -1,
      "z": 4,
      "name": "Soil_Snow"
    },
    {
      "x": 6,
      "y": 0,
      "z": 4,
      "name": "Rock_Ice"
    },
    {
      "x": 6,
      "y": 1,
      "z": 4,
      "name": "Empty"
    },
    {
      "x": 6,
      "y": 2,
      "z": 4,
      "name": "Soil_Snow"
    },
    {
      "x": 6,
      "y": 3,
      "z": 4,
      "name": "Soil_Snow"
    },
    {
      "x": 6,
      "y": 4,
      "z": 4,
      "name": "Soil_Snow"
    },
    {
      "x": 6,
      "y": 5,
      "z": 4,
      "name": "Soil_Snow"
    },
    {
      "x": 6,
      "y": 6,
      "z": 4,
      "name": "Soil_Snow"
    },
    {
      "x": 6,
      "y": 7,
      "z": 4,
      "name": "Soil_Snow"
    },
    {
      "x": 6,
      "y": 0,
      "z": 5,
      "name": "Soil_Snow"
    },
    {
      "x": 6,
      "y": 1,
      "z": 5,
      "name": "Soil_Snow"
    },
    {
      "x": 6,
      "y": 2,
      "z": 5,
      "name": "Soil_Snow"
    },
    {
      "x": 6,
      "y": 3,
      "z": 5,
      "name": "Soil_Snow"
    },
    {
      "x": 6,
      "y": 4,
      "z": 5,
      "name": "Soil_Snow"
    },
    {
      "x": 6,
      "y": 5,
      "z": 5,
      "name": "Soil_Snow"
    },
    {
      "x": 6,
      "y": 6,
      "z": 5,
      "name": "Soil_Snow"
    },
    {
      "x": 6,
      "y": 7,
      "z": 5,
      "name": "Soil_Snow"
    },
    {
      "x": 6,
      "y": 0,
      "z": 6,
      "name": "Soil_Snow"
    },
    {
      "x": 6,
      "y": 1,
      "z": 6,
      "name": "Soil_Snow"
    },
    {
      "x": 6,
      "y": 2,
      "z": 6,
      "name": "Soil_Snow"
    },
    {
      "x": 6,
      "y": 3,
      "z": 6,
      "name": "Soil_Snow"
    },
    {
      "x": 6,
      "y": 4,
      "z": 6,
      "name": "Soil_Snow"
    },
    {
      "x": 6,
      "y": 5,
      "z": 6,
      "name": "Soil_Snow"
    },
    {
      "x": 6,
      "y": 6,
      "z": 6,
      "name": "Soil_Snow"
    },
    {
      "x": 6,
      "y": 0,
      "z": 7,
      "name": "Soil_Snow"
    },
    {
      "x": 6,
      "y": 1,
      "z": 7,
      "name": "Soil_Snow"
    },
    {
      "x": 6,
      "y": 2,
      "z": 7,
      "name": "Soil_Snow"
    },
    {
      "x": 6,
      "y": 3,
      "z": 7,
      "name": "Soil_Snow"
    },
    {
      "x": 6,
      "y": 4,
      "z": 7,
      "name": "Soil_Snow"
    },
    {
      "x": 6,
      "y": 5,
      "z": 7,
      "name": "Soil_Snow"
    },
    {
      "x": 6,
      "y": 6,
      "z": 7,
      "name": "Soil_Snow"
    },
    {
      "x": 6,
      "y": 0,
      "z": 8,
      "name": "Soil_Snow"
    },
    {
      "x": 6,
      "y": 1,
      "z": 8,
      "name": "Soil_Snow"
    },
    {
      "x": 6,
      "y": 2,
      "z": 8,
      "name": "Soil_Snow"
    },
    {
      "x": 6,
      "y": 3,
      "z": 8,
      "name": "Soil_Snow"
    },
    {
      "x": 6,
      "y": 4,
      "z": 8,
      "name": "Soil_Snow"
    },
    {
      "x": 6,
      "y": 5,
      "z": 8,
      "name": "Soil_Snow"
    },
    {
      "x": 6,
      "y": 0,
      "z": 9,
      "name": "Soil_Snow"
    },
    {
      "x": 6,
      "y": 1,
      "z": 9,
      "name": "Soil_Snow"
    },
    {
      "x": 6,
      "y": 2,
      "z": 9,
      "name": "Soil_Snow"
    },
    {
      "x": 6,
      "y": 3,
      "z": 9,
      "name": "Soil_Snow"
    },
    {
      "x": 6,
      "y": 4,
      "z": 9,
      "name": "Soil_Snow"
    },
    {
      "x": 6,
      "y": 5,
      "z": 9,
      "name": "Soil_Snow"
    },
    {
      "x": 6,
      "y": 0,
      "z": 10,
      "name": "Soil_Snow"
    },
    {
      "x": 6,
      "y": 1,
      "z": 10,
      "name": "Soil_Snow"
    },
    {
      "x": 6,
      "y": 2,
      "z": 10,
      "name": "Soil_Snow"
    },
    {
      "x": 6,
      "y": 3,
      "z": 10,
      "name": "Soil_Snow"
    },
    {
      "x": 6,
      "y": 4,
      "z": 10,
      "name": "Soil_Snow"
    },
    {
      "x": 6,
      "y": 0,
      "z": 11,
      "name": "Soil_Snow"
    },
    {
      "x": 6,
      "y": 1,
      "z": 11,
      "name": "Soil_Snow"
    },
    {
      "x": 6,
      "y": 2,
      "z": 11,
      "name": "Soil_Snow"
    },
    {
      "x": 6,
      "y": 3,
      "z": 11,
      "name": "Soil_Snow"
    },
    {
      "x": 6,
      "y": 4,
      "z": 11,
      "name": "Soil_Snow"
    },
    {
      "x": 6,
      "y": 0,
      "z": 12,
      "name": "Soil_Snow"
    },
    {
      "x": 6,
      "y": 1,
      "z": 12,
      "name": "Soil_Snow"
    },
    {
      "x": 6,
      "y": 2,
      "z": 12,
      "name": "Soil_Snow"
    },
    {
      "x": 6,
      "y": 3,
      "z": 12,
      "name": "Soil_Snow"
    },
    {
      "x": 6,
      "y": 0,
      "z": 13,
      "name": "Soil_Snow"
    },
    {
      "x": 6,
      "y": 1,
      "z": 13,
      "name": "Soil_Snow"
    },
    {
      "x": 6,
      "y": 2,
      "z": 13,
      "name": "Soil_Snow"
    },
    {
      "x": 6,
      "y": 0,
      "z": 14,
      "name": "Soil_Snow"
    },
    {
      "x": 6,
      "y": 1,
      "z": 14,
      "name": "Soil_Snow"
    },
    {
      "x": 6,
      "y": 0,
      "z": 15,
      "name": "Soil_Snow"
    },
    {
      "x": 7,
      "y": 0,
      "z": -18,
      "name": "Soil_Snow"
    },
    {
      "x": 7,
      "y": 0,
      "z": -17,
      "name": "Soil_Snow"
    },
    {
      "x": 7,
      "y": 0,
      "z": -16,
      "name": "Soil_Snow"
    },
    {
      "x": 7,
      "y": 1,
      "z": -16,
      "name": "Soil_Snow"
    },
    {
      "x": 7,
      "y": 0,
      "z": -15,
      "name": "Soil_Snow"
    },
    {
      "x": 7,
      "y": 1,
      "z": -15,
      "name": "Soil_Snow"
    },
    {
      "x": 7,
      "y": 2,
      "z": -15,
      "name": "Soil_Snow"
    },
    {
      "x": 7,
      "y": 0,
      "z": -14,
      "name": "Soil_Snow"
    },
    {
      "x": 7,
      "y": 1,
      "z": -14,
      "name": "Soil_Snow"
    },
    {
      "x": 7,
      "y": 2,
      "z": -14,
      "name": "Soil_Snow"
    },
    {
      "x": 7,
      "y": 0,
      "z": -13,
      "name": "Soil_Snow"
    },
    {
      "x": 7,
      "y": 1,
      "z": -13,
      "name": "Soil_Snow"
    },
    {
      "x": 7,
      "y": 2,
      "z": -13,
      "name": "Soil_Snow"
    },
    {
      "x": 7,
      "y": 3,
      "z": -13,
      "name": "Soil_Snow"
    },
    {
      "x": 7,
      "y": 0,
      "z": -12,
      "name": "Soil_Snow"
    },
    {
      "x": 7,
      "y": 1,
      "z": -12,
      "name": "Soil_Snow"
    },
    {
      "x": 7,
      "y": 2,
      "z": -12,
      "name": "Soil_Snow"
    },
    {
      "x": 7,
      "y": 3,
      "z": -12,
      "name": "Soil_Snow"
    },
    {
      "x": 7,
      "y": 0,
      "z": -11,
      "name": "Soil_Snow"
    },
    {
      "x": 7,
      "y": 1,
      "z": -11,
      "name": "Soil_Snow"
    },
    {
      "x": 7,
      "y": 2,
      "z": -11,
      "name": "Soil_Snow"
    },
    {
      "x": 7,
      "y": 3,
      "z": -11,
      "name": "Soil_Snow"
    },
    {
      "x": 7,
      "y": 4,
      "z": -11,
      "name": "Soil_Snow"
    },
    {
      "x": 7,
      "y": 0,
      "z": -10,
      "name": "Soil_Snow"
    },
    {
      "x": 7,
      "y": 1,
      "z": -10,
      "name": "Soil_Snow"
    },
    {
      "x": 7,
      "y": 2,
      "z": -10,
      "name": "Soil_Snow"
    },
    {
      "x": 7,
      "y": 3,
      "z": -10,
      "name": "Soil_Snow"
    },
    {
      "x": 7,
      "y": 4,
      "z": -10,
      "name": "Soil_Snow"
    },
    {
      "x": 7,
      "y": 0,
      "z": -9,
      "name": "Soil_Snow"
    },
    {
      "x": 7,
      "y": 1,
      "z": -9,
      "name": "Soil_Snow"
    },
    {
      "x": 7,
      "y": 2,
      "z": -9,
      "name": "Soil_Snow"
    },
    {
      "x": 7,
      "y": 3,
      "z": -9,
      "name": "Soil_Snow"
    },
    {
      "x": 7,
      "y": 4,
      "z": -9,
      "name": "Soil_Snow"
    },
    {
      "x": 7,
      "y": 5,
      "z": -9,
      "name": "Soil_Snow"
    },
    {
      "x": 7,
      "y": 0,
      "z": -8,
      "name": "Soil_Snow"
    },
    {
      "x": 7,
      "y": 1,
      "z": -8,
      "name": "Soil_Snow"
    },
    {
      "x": 7,
      "y": 2,
      "z": -8,
      "name": "Soil_Snow"
    },
    {
      "x": 7,
      "y": 3,
      "z": -8,
      "name": "Soil_Snow"
    },
    {
      "x": 7,
      "y": 4,
      "z": -8,
      "name": "Soil_Snow"
    },
    {
      "x": 7,
      "y": 5,
      "z": -8,
      "name": "Soil_Snow"
    },
    {
      "x": 7,
      "y": 0,
      "z": -7,
      "name": "Soil_Snow"
    },
    {
      "x": 7,
      "y": 1,
      "z": -7,
      "name": "Soil_Snow"
    },
    {
      "x": 7,
      "y": 2,
      "z": -7,
      "name": "Soil_Snow"
    },
    {
      "x": 7,
      "y": 3,
      "z": -7,
      "name": "Soil_Snow"
    },
    {
      "x": 7,
      "y": 4,
      "z": -7,
      "name": "Soil_Snow"
    },
    {
      "x": 7,
      "y": 5,
      "z": -7,
      "name": "Soil_Snow"
    },
    {
      "x": 7,
      "y": 6,
      "z": -7,
      "name": "Soil_Snow"
    },
    {
      "x": 7,
      "y": 0,
      "z": -6,
      "name": "Soil_Snow"
    },
    {
      "x": 7,
      "y": 1,
      "z": -6,
      "name": "Soil_Snow"
    },
    {
      "x": 7,
      "y": 2,
      "z": -6,
      "name": "Soil_Snow"
    },
    {
      "x": 7,
      "y": 3,
      "z": -6,
      "name": "Soil_Snow"
    },
    {
      "x": 7,
      "y": 4,
      "z": -6,
      "name": "Soil_Snow"
    },
    {
      "x": 7,
      "y": 5,
      "z": -6,
      "name": "Soil_Snow"
    },
    {
      "x": 7,
      "y": 6,
      "z": -6,
      "name": "Soil_Snow"
    },
    {
      "x": 7,
      "y": 0,
      "z": -5,
      "name": "Soil_Snow"
    },
    {
      "x": 7,
      "y": 1,
      "z": -5,
      "name": "Soil_Snow"
    },
    {
      "x": 7,
      "y": 2,
      "z": -5,
      "name": "Soil_Snow"
    },
    {
      "x": 7,
      "y": 3,
      "z": -5,
      "name": "Soil_Snow"
    },
    {
      "x": 7,
      "y": 4,
      "z": -5,
      "name": "Soil_Snow"
    },
    {
      "x": 7,
      "y": 5,
      "z": -5,
      "name": "Soil_Snow"
    },
    {
      "x": 7,
      "y": 6,
      "z": -5,
      "name": "Soil_Snow"
    },
    {
      "x": 7,
      "y": 7,
      "z": -5,
      "name": "Soil_Snow"
    },
    {
      "x": 7,
      "y": 0,
      "z": -4,
      "name": "Soil_Snow"
    },
    {
      "x": 7,
      "y": 1,
      "z": -4,
      "name": "Soil_Snow"
    },
    {
      "x": 7,
      "y": 2,
      "z": -4,
      "name": "Soil_Snow"
    },
    {
      "x": 7,
      "y": 3,
      "z": -4,
      "name": "Soil_Snow"
    },
    {
      "x": 7,
      "y": 4,
      "z": -4,
      "name": "Soil_Snow"
    },
    {
      "x": 7,
      "y": 5,
      "z": -4,
      "name": "Soil_Snow"
    },
    {
      "x": 7,
      "y": 6,
      "z": -4,
      "name": "Soil_Snow"
    },
    {
      "x": 7,
      "y": 7,
      "z": -4,
      "name": "Soil_Snow"
    },
    {
      "x": 7,
      "y": -1,
      "z": -3,
      "name": "Soil_Snow"
    },
    {
      "x": 7,
      "y": 0,
      "z": -3,
      "name": "Soil_Snow"
    },
    {
      "x": 7,
      "y": 1,
      "z": -3,
      "name": "Soil_Snow"
    },
    {
      "x": 7,
      "y": 2,
      "z": -3,
      "name": "Soil_Snow"
    },
    {
      "x": 7,
      "y": 3,
      "z": -3,
      "name": "Soil_Snow"
    },
    {
      "x": 7,
      "y": 4,
      "z": -3,
      "name": "Soil_Snow"
    },
    {
      "x": 7,
      "y": 5,
      "z": -3,
      "name": "Soil_Snow"
    },
    {
      "x": 7,
      "y": 6,
      "z": -3,
      "name": "Soil_Snow"
    },
    {
      "x": 7,
      "y": 7,
      "z": -3,
      "name": "Soil_Snow"
    },
    {
      "x": 7,
      "y": -2,
      "z": -2,
      "name": "Soil_Snow"
    },
    {
      "x": 7,
      "y": -1,
      "z": -2,
      "name": "Rock_Ice"
    },
    {
      "x": 7,
      "y": 0,
      "z": -2,
      "name": "Empty"
    },
    {
      "x": 7,
      "y": 1,
      "z": -2,
      "name": "Soil_Snow"
    },
    {
      "x": 7,
      "y": 2,
      "z": -2,
      "name": "Soil_Snow"
    },
    {
      "x": 7,
      "y": 3,
      "z": -2,
      "name": "Soil_Snow"
    },
    {
      "x": 7,
      "y": 4,
      "z": -2,
      "name": "Soil_Snow"
    },
    {
      "x": 7,
      "y": 5,
      "z": -2,
      "name": "Soil_Snow"
    },
    {
      "x": 7,
      "y": 6,
      "z": -2,
      "name": "Soil_Snow"
    },
    {
      "x": 7,
      "y": 7,
      "z": -2,
      "name": "Soil_Snow"
    },
    {
      "x": 7,
      "y": 8,
      "z": -2,
      "name": "Soil_Snow"
    },
    {
      "x": 7,
      "y": -3,
      "z": -1,
      "name": "Soil_Snow"
    },
    {
      "x": 7,
      "y": -2,
      "z": -1,
      "name": "Soil_Snow"
    },
    {
      "x": 7,
      "y": -1,
      "z": -1,
      "name": "Empty"
    },
    {
      "x": 7,
      "y": 0,
      "z": -1,
      "name": "Empty"
    },
    {
      "x": 7,
      "y": 1,
      "z": -1,
      "name": "Empty"
    },
    {
      "x": 7,
      "y": 2,
      "z": -1,
      "name": "Empty"
    },
    {
      "x": 7,
      "y": 3,
      "z": -1,
      "name": "Soil_Snow"
    },
    {
      "x": 7,
      "y": 4,
      "z": -1,
      "name": "Soil_Snow"
    },
    {
      "x": 7,
      "y": 5,
      "z": -1,
      "name": "Soil_Snow"
    },
    {
      "x": 7,
      "y": 6,
      "z": -1,
      "name": "Soil_Snow"
    },
    {
      "x": 7,
      "y": 7,
      "z": -1,
