{
  "version": 8,
  "blockIdVersion": 10,
  "anchorX": 0,
  "anchorY": 0,
  "anchorZ": 0,
  "blocks": [
    {
      "x": -10,
      "y": 3,
      "z": -5,
      "name": "Rock_Ice_Permafrost"
    },
    {
      "x": -10,
      "y": 4,
      "z": -5,
      "name": "Rubble_Ice",
      "support": 15
    },
    {
      "x": -10,
      "y": 3,
      "z": -4,
      "name": "Rock_Ice_Permafrost"
    },
    {
      "x": -10,
      "y": 4,
      "z": -4,
      "name": "Rock_Crystal_Cyan_Medium"
    },
    {
      "x": -10,
      "y": 3,
      "z": -3,
      "name": "Rock_Ice_Permafrost"
    },
    {
      "x": -10,
      "y": 3,
      "z": -2,
      "name": "Rock_Ice_Permafrost"
    },
    {
      "x": -10,
      "y": 4,
      "z": -2,
      "name": "Rubble_Ice_Medium",
      "support": 15
    },
    {
      "x": -10,
      "y": 3,
      "z": 4,
      "name": "Rock_Ice_Permafrost"
    },
    {
      "x": -9,
      "y": 3,
      "z": -6,
      "name": "Rock_Ice_Permafrost"
    },
    {
      "x": -9,
      "y": 4,
      "z": -6,
      "name": "Rock_Ice_Icicles"
    },
    {
      "x": -9,
      "y": 3,
      "z": -5,
      "name": "Rock_Ice_Permafrost"
    },
    {
      "x": -9,
      "y": 4,
      "z": -5,
      "name": "Rock_Ice_Permafrost"
    },
    {
      "x": -9,
      "y": 5,
      "z": -5,
      "name": "Rock_Ice_Permafrost"
    },
    {
      "x": -9,
      "y": 6,
      "z": -5,
      "name": "Rock_Ice_Stalactite_Large"
    },
    {
      "x": -9,
      "y": 7,
      "z": -5,
      "name": "Rock_Ice_Stalactite_Large",
      "filler": 1024
    },
    {
      "x": -9,
      "y": 3,
      "z": -4,
      "name": "Rock_Ice_Permafrost"
    },
    {
      "x": -9,
      "y": 4,
      "z": -4,
      "name": "Rock_Ice_Permafrost"
    },
    {
      "x": -9,
      "y": 5,
      "z": -4,
      "name": "Rock_Ice_Permafrost"
    },
    {
      "x": -9,
      "y": 3,
      "z": -3,
      "name": "Rock_Ice_Permafrost"
    },
    {
      "x": -9,
      "y": 4,
      "z": -3,
      "name": "Rock_Ice_Permafrost"
    },
    {
      "x": -9,
      "y": 5,
      "z": -3,
      "name": "Rock_Ice_Permafrost"
    },
    {
      "x": -9,
      "y": 3,
      "z": -2,
      "name": "Rock_Ice_Permafrost"
    },
    {
      "x": -9,
      "y": 4,
      "z": -2,
      "name": "Rock_Ice_Permafrost"
    },
    {
      "x": -9,
      "y": 5,
      "z": -2,
      "name": "Rock_Ice_Icicles"
    },
    {
      "x": -9,
      "y": 3,
      "z": -1,
      "name": "Rock_Ice_Permafrost"
    },
    {
      "x": -9,
      "y": 0,
      "z": 2,
      "name": "Rock_Ice_Permafrost",
      "rotation": 2
    },
    {
      "x": -9,
      "y": 1,
      "z": 2,
      "name": "Rock_Ice_Permafrost",
      "rotation": 2
    },
    {
      "x": -9,
      "y": 2,
      "z": 2,
      "name": "Rock_Ice_Permafrost",
      "rotation": 2
    },
    {
      "x": -9,
      "y": 3,
      "z": 2,
      "name": "Rock_Ice_Permafrost",
      "rotation": 2
    },
    {
      "x": -9,
      "y": 4,
      "z": 2,
      "name": "Rock_Ice_Stalactite_Large",
      "rotation": 2
    },
    {
      "x": -9,
      "y": 5,
      "z": 2,
      "name": "Rock_Ice_Stalactite_Large",
      "filler": 1024,
      "rotation": 2
    },
    {
      "x": -9,
      "y": 0,
      "z": 3,
      "name": "Rock_Ice_Permafrost",
      "rotation": 2
    },
    {
      "x": -9,
      "y": 1,
      "z": 3,
      "name": "Rock_Ice_Permafrost",
      "rotation": 2
    },
    {
      "x": -9,
      "y": 2,
      "z": 3,
      "name": "Rock_Ice_Permafrost",
      "rotation": 2
    },
    {
      "x": -9,
      "y": 3,
      "z": 3,
      "name": "Rock_Ice_Permafrost",
      "rotation": 2
    },
    {
      "x": -9,
      "y": 4,
      "z": 3,
      "name": "Rock_Ice_Permafrost",
      "rotation": 2
    },
    {
      "x": -9,
      "y": 5,
      "z": 3,
      "name": "Rock_Ice_Permafrost",
      "rotation": 2
    },
    {
      "x": -9,
      "y": 0,
      "z": 4,
      "name": "Rock_Ice_Permafrost",
      "rotation": 2
    },
    {
      "x": -9,
      "y": 1,
      "z": 4,
      "name": "Rock_Ice_Permafrost",
      "rotation": 2
    },
    {
      "x": -9,
      "y": 2,
      "z": 4,
      "name": "Rock_Ice_Permafrost",
      "rotation": 2
    },
    {
      "x": -9,
      "y": 3,
      "z": 4,
      "name": "Rock_Ice_Permafrost",
      "rotation": 2
    },
    {
      "x": -9,
      "y": 4,
      "z": 4,
      "name": "Rock_Ice_Permafrost",
      "rotation": 2
    },
    {
      "x": -9,
      "y": 5,
      "z": 4,
      "name": "Rock_Ice_Permafrost",
      "rotation": 2
    },
    {
      "x": -9,
      "y": 6,
      "z": 4,
      "name": "Rubble_Ice",
      "support": 15,
      "rotation": 2
    },
    {
      "x": -9,
      "y": 0,
      "z": 5,
      "name": "Rock_Ice_Permafrost",
      "rotation": 2
    },
    {
      "x": -9,
      "y": 1,
      "z": 5,
      "name": "Rock_Ice_Permafrost",
      "rotation": 2
    },
    {
      "x": -9,
      "y": 2,
      "z": 5,
      "name": "Rock_Ice_Permafrost",
      "rotation": 2
    },
    {
      "x": -9,
      "y": 3,
      "z": 5,
      "name": "Rock_Ice_Permafrost",
      "rotation": 2
    },
    {
      "x": -9,
      "y": 4,
      "z": 5,
      "name": "Rock_Ice_Permafrost",
      "rotation": 2
    },
    {
      "x": -9,
      "y": 5,
      "z": 5,
      "name": "Rock_Ice_Permafrost",
      "rotation": 2
    },
    {
      "x": -9,
      "y": 6,
      "z": 5,
      "name": "Rock_Ice_Permafrost",
      "rotation": 2
    },
    {
      "x": -9,
      "y": 0,
      "z": 6,
      "name": "Rock_Ice_Permafrost",
      "rotation": 2
    },
    {
      "x": -9,
      "y": 1,
      "z": 6,
      "name": "Rock_Ice_Permafrost",
      "rotation": 2
    },
    {
      "x": -9,
      "y": 2,
      "z": 6,
      "name": "Rock_Ice_Permafrost",
      "rotation": 2
    },
    {
      "x": -9,
      "y": 3,
      "z": 6,
      "name": "Rock_Ice_Permafrost",
      "rotation": 2
    },
    {
      "x": -9,
      "y": 4,
      "z": 6,
      "name": "Rock_Ice_Permafrost",
      "rotation": 2
    },
    {
      "x": -9,
      "y": 5,
      "z": 6,
      "name": "Rock_Ice_Permafrost",
      "rotation": 2
    },
    {
      "x": -9,
      "y": 6,
      "z": 6,
      "name": "Rock_Ice_Stalactite_Large",
      "rotation": 2
    },
    {
      "x": -9,
      "y": 7,
      "z": 6,
      "name": "Rock_Ice_Stalactite_Large",
      "filler": 1024,
      "rotation": 2
    },
    {
      "x": -8,
      "y": 3,
      "z": -7,
      "name": "Rock_Ice_Permafrost"
    },
    {
      "x": -8,
      "y": 3,
      "z": -6,
      "name": "Rock_Ice_Permafrost"
    },
    {
      "x": -8,
      "y": 4,
      "z": -6,
      "name": "Rock_Ice_Permafrost"
    },
    {
      "x": -8,
      "y": 5,
      "z": -6,
      "name": "Rock_Ice_Permafrost"
    },
    {
      "x": -8,
      "y": 3,
      "z": -5,
      "name": "Rock_Ice_Permafrost"
    },
    {
      "x": -8,
      "y": 4,
      "z": -5,
      "name": "Rock_Ice_Permafrost"
    },
    {
      "x": -8,
      "y": 5,
      "z": -5,
      "name": "Rock_Ice_Permafrost"
    },
    {
      "x": -8,
      "y": 6,
      "z": -5,
      "name": "Rock_Ice_Permafrost"
    },
    {
      "x": -8,
      "y": 3,
      "z": -4,
      "name": "Rock_Ice_Permafrost"
    },
    {
      "x": -8,
      "y": 4,
      "z": -4,
      "name": "Rock_Ice_Permafrost"
    },
    {
      "x": -8,
      "y": 5,
      "z": -4,
      "name": "Rock_Ice_Permafrost"
    },
    {
      "x": -8,
      "y": 6,
      "z": -4,
      "name": "Rock_Ice_Permafrost"
    },
    {
      "x": -8,
      "y": 7,
      "z": -4,
      "name": "Rock_Ice_Permafrost"
    },
    {
      "x": -8,
      "y": 8,
      "z": -4,
      "name": "Rock_Ice_Icicles"
    },
    {
      "x": -8,
      "y": 3,
      "z": -3,
      "name": "Rock_Ice_Permafrost"
    },
    {
      "x": -8,
      "y": 4,
      "z": -3,
      "name": "Rock_Ice_Permafrost"
    },
    {
      "x": -8,
      "y": 5,
      "z": -3,
      "name": "Rock_Ice_Permafrost"
    },
    {
      "x": -8,
      "y": 6,
      "z": -3,
      "name": "Rubble_Ice_Medium",
      "support": 15
    },
    {
      "x": -8,
      "y": 3,
      "z": -2,
      "name": "Rock_Ice_Permafrost"
    },
    {
      "x": -8,
      "y": 4,
      "z": -2,
      "name": "Rock_Ice_Permafrost"
    },
    {
      "x": -8,
      "y": 5,
      "z": -2,
      "name": "Rock_Ice_Permafrost"
    },
    {
      "x": -8,
      "y": 6,
      "z": -2,
      "name": "Rock_Ice_Stalactite_Large"
    },
    {
      "x": -8,
      "y": 7,
      "z": -2,
      "name": "Rock_Ice_Stalactite_Large",
      "filler": 1024
    },
    {
      "x": -8,
      "y": 3,
      "z": -1,
      "name": "Rock_Ice_Permafrost"
    },
    {
      "x": -8,
      "y": 4,
      "z": -1,
      "name": "Rock_Ice_Permafrost"
    },
    {
      "x": -8,
      "y": 3,
      "z": 0,
      "name": "Rock_Ice_Permafrost"
    },
    {
      "x": -8,
      "y": 0,
      "z": 1,
      "name": "Rock_Ice_Permafrost",
      "rotation": 2
    },
    {
      "x": -8,
      "y": 1,
      "z": 1,
      "name": "Rock_Ice_Permafrost",
      "rotation": 2
    },
    {
      "x": -8,
      "y": 2,
      "z": 1,
      "name": "Rock_Ice_Permafrost",
      "rotation": 2
    },
    {
      "x": -8,
      "y": 3,
      "z": 1,
      "name": "Rock_Ice_Permafrost",
      "rotation": 2
    },
    {
      "x": -8,
      "y": 4,
      "z": 1,
      "name": "Rock_Ice_Permafrost",
      "rotation": 2
    },
    {
      "x": -8,
      "y": 5,
      "z": 1,
      "name": "Rubble_Ice_Medium",
      "support": 15,
      "rotation": 2
    },
    {
      "x": -8,
      "y": 0,
      "z": 2,
      "name": "Rock_Ice_Permafrost",
      "rotation": 2
    },
    {
      "x": -8,
      "y": 1,
      "z": 2,
      "name": "Rock_Ice_Permafrost",
      "rotation": 2
    },
    {
      "x": -8,
      "y": 2,
      "z": 2,
      "name": "Rock_Ice_Permafrost",
      "rotation": 2
    },
    {
      "x": -8,
      "y": 3,
      "z": 2,
      "name": "Rock_Ice_Permafrost",
      "rotation": 2
    },
    {
      "x": -8,
      "y": 4,
      "z": 2,
      "name": "Rock_Ice_Permafrost",
      "rotation": 2
    },
    {
      "x": -8,
      "y": 5,
      "z": 2,
      "name": "Rock_Ice_Permafrost",
      "rotation": 2
    },
    {
      "x": -8,
      "y": 0,
      "z": 3,
      "name": "Rock_Ice_Permafrost",
      "rotation": 2
    },
    {
      "x": -8,
      "y": 1,
      "z": 3,
      "name": "Rock_Ice_Permafrost",
      "rotation": 2
    },
    {
      "x": -8,
      "y": 2,
      "z": 3,
      "name": "Rock_Ice_Permafrost",
      "rotation": 2
    },
    {
      "x": -8,
      "y": 3,
      "z": 3,
      "name": "Rock_Ice_Permafrost",
      "rotation": 2
    },
    {
      "x": -8,
      "y": 4,
      "z": 3,
      "name": "Rock_Ice_Permafrost",
      "rotation": 2
    },
    {
      "x": -8,
      "y": 5,
      "z": 3,
      "name": "Rock_Ice_Permafrost",
      "rotation": 2
    },
    {
      "x": -8,
      "y": 6,
      "z": 3,
      "name": "Rock_Ice_Permafrost",
      "rotation": 2
    },
    {
      "x": -8,
      "y": 7,
      "z": 3,
      "name": "Rock_Ice_Permafrost",
      "rotation": 2
    },
    {
      "x": -8,
      "y": 0,
      "z": 4,
      "name": "Rock_Ice_Permafrost",
      "rotation": 2
    },
    {
      "x": -8,
      "y": 1,
      "z": 4,
      "name": "Rock_Ice_Permafrost",
      "rotation": 2
    },
    {
      "x": -8,
      "y": 2,
      "z": 4,
      "name": "Rock_Ice_Permafrost",
      "rotation": 2
    },
    {
      "x": -8,
      "y": 3,
      "z": 4,
      "name": "Rock_Ice_Permafrost",
      "rotation": 2
    },
    {
      "x": -8,
      "y": 4,
      "z": 4,
      "name": "Rock_Ice_Permafrost",
      "rotation": 2
    },
    {
      "x": -8,
      "y": 5,
      "z": 4,
      "name": "Rock_Ice_Permafrost",
      "rotation": 2
    },
    {
      "x": -8,
      "y": 6,
      "z": 4,
      "name": "Rock_Ice_Permafrost",
      "rotation": 2
    },
    {
      "x": -8,
      "y": 7,
      "z": 4,
      "name": "Rock_Ice_Permafrost",
      "rotation": 2
    },
    {
      "x": -8,
      "y": 8,
      "z": 4,
      "name": "Rock_Ice_Permafrost",
      "rotation": 2
    },
    {
      "x": -8,
      "y": 9,
      "z": 4,
      "name": "Rock_Ice_Stalactite_Large",
      "rotation": 2
    },
    {
      "x": -8,
      "y": 10,
      "z": 4,
      "name": "Rock_Ice_Stalactite_Large",
      "filler": 1024,
      "rotation": 2
    },
    {
      "x": -8,
      "y": 0,
      "z": 5,
      "name": "Rock_Ice_Permafrost",
      "rotation": 2
    },
    {
      "x": -8,
      "y": 1,
      "z": 5,
      "name": "Rock_Ice_Permafrost",
      "rotation": 2
    },
    {
      "x": -8,
      "y": 2,
      "z": 5,
      "name": "Rock_Ice_Permafrost",
      "rotation": 2
    },
    {
      "x": -8,
      "y": 3,
      "z": 5,
      "name": "Rock_Ice_Permafrost",
      "rotation": 2
    },
    {
      "x": -8,
      "y": 4,
      "z": 5,
      "name": "Rock_Ice_Permafrost",
      "rotation": 2
    },
    {
      "x": -8,
      "y": 5,
      "z": 5,
      "name": "Rock_Ice_Permafrost",
      "rotation": 2
    },
    {
      "x": -8,
      "y": 6,
      "z": 5,
      "name": "Rock_Ice_Permafrost",
      "rotation": 2
    },
    {
      "x": -8,
      "y": 7,
      "z": 5,
      "name": "Rock_Ice_Permafrost",
      "rotation": 2
    },
    {
      "x": -8,
      "y": 8,
      "z": 5,
      "name": "Rock_Ice_Permafrost",
      "rotation": 2
    },
    {
      "x": -8,
      "y": 9,
      "z": 5,
      "name": "Rock_Ice_Permafrost",
      "rotation": 2
    },
    {
      "x": -8,
      "y": 10,
      "z": 5,
      "name": "Rubble_Ice",
      "support": 15,
      "rotation": 2
    },
    {
      "x": -8,
      "y": 0,
      "z": 6,
      "name": "Rock_Ice_Permafrost",
      "rotation": 2
    },
    {
      "x": -8,
      "y": 1,
      "z": 6,
      "name": "Rock_Ice_Permafrost",
      "rotation": 2
    },
    {
      "x": -8,
      "y": 2,
      "z": 6,
      "name": "Rock_Ice_Permafrost",
      "rotation": 2
    },
    {
      "x": -8,
      "y": 3,
      "z": 6,
      "name": "Rock_Ice_Permafrost",
      "rotation": 2
    },
    {
      "x": -8,
      "y": 4,
      "z": 6,
      "name": "Rock_Ice_Permafrost",
      "rotation": 2
    },
    {
      "x": -8,
      "y": 5,
      "z": 6,
      "name": "Rock_Ice_Permafrost",
      "rotation": 2
    },
    {
      "x": -8,
      "y": 6,
      "z": 6,
      "name": "Rock_Ice_Permafrost",
      "rotation": 2
    },
    {
      "x": -8,
      "y": 7,
      "z": 6,
      "name": "Rock_Ice_Permafrost",
      "rotation": 2
    },
    {
      "x": -8,
      "y": 8,
      "z": 6,
      "name": "Rock_Ice_Permafrost",
      "rotation": 2
    },
    {
      "x": -8,
      "y": 9,
      "z": 6,
      "name": "Rock_Ice_Permafrost",
      "rotation": 2
    },
    {
      "x": -8,
      "y": 10,
      "z": 6,
      "name": "Rock_Ice_Stalactite_Large",
      "rotation": 2
    },
    {
      "x": -8,
      "y": 11,
      "z": 6,
      "name": "Rock_Ice_Stalactite_Large",
      "filler": 1024,
      "rotation": 2
    },
    {
      "x": -8,
      "y": 0,
      "z": 7,
      "name": "Rock_Ice_Permafrost",
      "rotation": 2
    },
    {
      "x": -8,
      "y": 1,
      "z": 7,
      "name": "Rock_Ice_Permafrost",
      "rotation": 2
    },
    {
      "x": -8,
      "y": 2,
      "z": 7,
      "name": "Rock_Ice_Permafrost",
      "rotation": 2
    },
    {
      "x": -8,
      "y": 3,
      "z": 7,
      "name": "Rock_Ice_Permafrost",
      "rotation": 2
    },
    {
      "x": -8,
      "y": 4,
      "z": 7,
      "name": "Rock_Ice_Permafrost",
      "rotation": 2
    },
    {
      "x": -8,
      "y": 5,
      "z": 7,
      "name": "Rock_Ice_Permafrost",
      "rotation": 2
    },
    {
      "x": -8,
      "y": 6,
      "z": 7,
      "name": "Rock_Ice_Permafrost",
      "rotation": 2
    },
    {
      "x": -8,
      "y": 7,
      "z": 7,
      "name": "Rock_Ice_Permafrost",
      "rotation": 2
    },
    {
      "x": -8,
      "y": 0,
      "z": 8,
      "name": "Rock_Ice_Permafrost",
      "rotation": 2
    },
    {
      "x": -8,
      "y": 1,
      "z": 8,
      "name": "Rock_Ice_Permafrost",
      "rotation": 2
    },
    {
      "x": -8,
      "y": 2,
      "z": 8,
      "name": "Rock_Ice_Permafrost",
      "rotation": 2
    },
    {
      "x": -8,
      "y": 3,
      "z": 8,
      "name": "Rock_Ice_Permafrost",
      "rotation": 2
    },
    {
      "x": -8,
      "y": 4,
      "z": 8,
      "name": "Rock_Ice_Permafrost",
      "rotation": 2
    },
    {
      "x": -8,
      "y": 5,
      "z": 8,
      "name": "Rock_Ice_Icicles",
      "rotation": 2
    },
    {
      "x": -7,
      "y": 3,
      "z": -8,
      "name": "Rock_Ice_Permafrost"
    },
    {
      "x": -7,
      "y": 3,
      "z": -7,
      "name": "Rock_Ice_Permafrost"
    },
    {
      "x": -7,
      "y": 4,
      "z": -7,
      "name": "Rock_Ice_Permafrost"
    },
    {
      "x": -7,
      "y": 5,
      "z": -7,
      "name": "Rock_Ice_Stalactite_Large"
    },
    {
      "x": -7,
      "y": 6,
      "z": -7,
      "name": "Rock_Ice_Stalactite_Large",
      "filler": 1024
    },
    {
      "x": -7,
      "y": 3,
      "z": -6,
      "name": "Rock_Ice_Permafrost"
    },
    {
      "x": -7,
      "y": 4,
      "z": -6,
      "name": "Rock_Ice_Permafrost"
    },
    {
      "x": -7,
      "y": 5,
      "z": -6,
      "name": "Rock_Ice_Permafrost"
    },
    {
      "x": -7,
      "y": 6,
      "z": -6,
      "name": "Rock_Ice_Permafrost"
    },
    {
      "x": -7,
      "y": 3,
      "z": -5,
      "name": "Rock_Ice_Permafrost"
    },
    {
      "x": -7,
      "y": 4,
      "z": -5,
      "name": "Rock_Ice_Permafrost"
    },
    {
      "x": -7,
      "y": 5,
      "z": -5,
      "name": "Rock_Ice_Permafrost"
    },
    {
      "x": -7,
      "y": 6,
      "z": -5,
      "name": "Rock_Ice_Permafrost"
    },
    {
      "x": -7,
      "y": 7,
      "z": -5,
      "name": "Rock_Ice_Permafrost"
    },
    {
      "x": -7,
      "y": 8,
      "z": -5,
      "name": "Rock_Ice_Permafrost"
    },
    {
      "x": -7,
      "y": 9,
      "z": -5,
      "name": "Rock_Ice_Permafrost"
    },
    {
      "x": -7,
      "y": 3,
      "z": -4,
      "name": "Rock_Ice_Permafrost"
    },
    {
      "x": -7,
      "y": 4,
      "z": -4,
      "name": "Rock_Ice_Permafrost"
    },
    {
      "x": -7,
      "y": 5,
      "z": -4,
      "name": "Rock_Ice_Permafrost"
    },
    {
      "x": -7,
      "y": 6,
      "z": -4,
      "name": "Rock_Ice_Permafrost"
    },
    {
      "x": -7,
      "y": 7,
      "z": -4,
      "name": "Rock_Ice_Permafrost"
    },
    {
      "x": -7,
      "y": 8,
      "z": -4,
      "name": "Rock_Ice_Permafrost"
    },
    {
      "x": -7,
      "y": 9,
      "z": -4,
      "name": "Rock_Ice_Permafrost"
    },
    {
      "x": -7,
      "y": 10,
      "z": -4,
      "name": "Rock_Ice_Permafrost"
    },
    {
      "x": -7,
      "y": 11,
      "z": -4,
      "name": "Rock_Ice_Permafrost"
    },
    {
      "x": -7,
      "y": 12,
      "z": -4,
      "name": "Rock_Ice_Permafrost"
    },
    {
      "x": -7,
      "y": 13,
      "z": -4,
      "name": "Rock_Ice_Icicles"
    },
    {
      "x": -7,
      "y": 3,
      "z": -3,
      "name": "Rock_Ice_Permafrost"
    },
    {
      "x": -7,
      "y": 4,
      "z": -3,
      "name": "Rock_Ice_Permafrost"
    },
    {
      "x": -7,
      "y": 5,
      "z": -3,
      "name": "Rock_Ice_Permafrost"
    },
    {
      "x": -7,
      "y": 6,
      "z": -3,
      "name": "Rock_Ice_Permafrost"
    },
    {
      "x": -7,
      "y": 7,
      "z": -3,
      "name": "Rock_Ice_Permafrost"
    },
    {
      "x": -7,
      "y": 8,
      "z": -3,
      "name": "Rock_Ice_Permafrost"
    },
    {
      "x": -7,
      "y": 9,
      "z": -3,
      "name": "Rock_Ice_Permafrost"
    },
    {
      "x": -7,
      "y": 10,
      "z": -3,
      "name": "Rock_Ice_Permafrost"
    },
    {
      "x": -7,
      "y": 11,
      "z": -3,
      "name": "Rock_Ice_Permafrost"
    },
    {
      "x": -7,
      "y": 3,
      "z": -2,
      "name": "Rock_Ice_Permafrost"
    },
    {
      "x": -7,
      "y": 4,
      "z": -2,
      "name": "Rock_Ice_Permafrost"
    },
    {
      "x": -7,
      "y": 5,
      "z": -2,
      "name": "Rock_Ice_Permafrost"
    },
    {
      "x": -7,
      "y": 6,
      "z": -2,
      "name": "Rock_Ice_Permafrost"
    },
    {
      "x": -7,
      "y": 7,
      "z": -2,
      "name": "Rock_Ice_Permafrost"
    },
    {
      "x": -7,
      "y": 3,
      "z": -1,
      "name": "Rock_Ice_Permafrost"
    },
    {
      "x": -7,
      "y": 4,
      "z": -1,
      "name": "Rock_Ice_Permafrost"
    },
    {
      "x": -7,
      "y": 0,
      "z": 0,
      "name": "Rock_Ice_Permafrost",
      "rotation": 2
    },
    {
      "x": -7,
      "y": 1,
      "z": 0,
      "name": "Rock_Ice_Permafrost",
      "rotation": 2
    },
    {
      "x": -7,
      "y": 2,
      "z": 0,
      "name": "Rock_Ice_Permafrost",
      "rotation": 2
    },
    {
      "x": -7,
      "y": 3,
      "z": 0,
      "name": "Rock_Ice_Permafrost",
      "rotation": 2
    },
    {
      "x": -7,
      "y": 4,
      "z": 0,
      "name": "Rock_Ice_Permafrost",
      "rotation": 2
    },
    {
      "x": -7,
      "y": 0,
      "z": 1,
      "name": "Rock_Ice_Permafrost",
      "rotation": 2
    },
    {
      "x": -7,
      "y": 1,
      "z": 1,
      "name": "Rock_Ice_Permafrost",
      "rotation": 2
    },
    {
      "x": -7,
      "y": 2,
      "z": 1,
      "name": "Rock_Ice_Permafrost",
      "rotation": 2
    },
    {
      "x": -7,
      "y": 3,
      "z": 1,
      "name": "Rock_Ice_Permafrost",
      "rotation": 2
    },
    {
      "x": -7,
      "y": 4,
      "z": 1,
      "name": "Rock_Ice_Permafrost",
      "rotation": 2
    },
    {
      "x": -7,
      "y": 5,
      "z": 1,
      "name": "Rock_Ice_Permafrost",
      "rotation": 2
    },
    {
      "x": -7,
      "y": 6,
      "z": 1,
      "name": "Rock_Ice_Stalactite_Large",
      "rotation": 2
    },
    {
      "x": -7,
      "y": 7,
      "z": 1,
      "name": "Rock_Ice_Stalactite_Large",
      "filler": 1024,
      "rotation": 2
    },
    {
      "x": -7,
      "y": 0,
      "z": 2,
      "name": "Rock_Ice_Permafrost",
      "rotation": 2
    },
    {
      "x": -7,
      "y": 1,
      "z": 2,
      "name": "Rock_Ice_Permafrost",
      "rotation": 2
    },
    {
      "x": -7,
      "y": 2,
      "z": 2,
      "name": "Rock_Ice_Permafrost",
      "rotation": 2
    },
    {
      "x": -7,
      "y": 3,
      "z": 2,
      "name": "Rock_Ice_Permafrost",
      "rotation": 2
    },
    {
      "x": -7,
      "y": 4,
      "z": 2,
      "name": "Rock_Ice_Permafrost",
      "rotation": 2
    },
    {
      "x": -7,
      "y": 5,
      "z": 2,
      "name": "Rock_Ice_Permafrost",
      "rotation": 2
    },
    {
      "x": -7,
      "y": 6,
      "z": 2,
      "name": "Rock_Ice_Permafrost",
      "rotation": 2
    },
    {
      "x": -7,
      "y": 7,
      "z": 2,
      "name": "Rock_Ice_Permafrost",
      "rotation": 2
    },
    {
      "x": -7,
      "y": 8,
      "z": 2,
      "name": "Rubble_Ice_Medium",
      "support": 15,
      "rotation": 2
    },
    {
      "x": -7,
      "y": 0,
      "z": 3,
      "name": "Rock_Ice_Permafrost",
      "rotation": 2
    },
    {
      "x": -7,
      "y": 1,
      "z": 3,
      "name": "Rock_Ice_Permafrost",
      "rotation": 2
    },
    {
      "x": -7,
      "y": 2,
      "z": 3,
      "name": "Rock_Ice_Permafrost",
      "rotation": 2
    },
    {
      "x": -7,
      "y": 3,
      "z": 3,
      "name": "Rock_Ice_Permafrost",
      "rotation": 2
    },
    {
      "x": -7,
      "y": 4,
      "z": 3,
      "name": "Rock_Ice_Permafrost",
      "rotation": 2
    },
    {
      "x": -7,
      "y": 5,
      "z": 3,
      "name": "Rock_Ice_Permafrost",
      "rotation": 2
    },
    {
      "x": -7,
      "y": 6,
      "z": 3,
      "name": "Rock_Ice_Permafrost",
      "rotation": 2
    },
    {
      "x": -7,
      "y": 7,
      "z": 3,
      "name": "Rock_Ice_Permafrost",
      "rotation": 2
    },
    {
      "x": -7,
      "y": 8,
      "z": 3,
      "name": "Rock_Ice_Permafrost",
      "rotation": 2
    },
    {
      "x": -7,
      "y": 0,
      "z": 4,
      "name": "Rock_Ice_Permafrost",
      "rotation": 2
    },
    {
      "x": -7,
      "y": 1,
      "z": 4,
      "name": "Rock_Ice_Permafrost",
      "rotation": 2
    },
    {
      "x": -7,
      "y": 2,
      "z": 4,
      "name": "Rock_Ice_Permafrost",
      "rotation": 2
    },
    {
      "x": -7,
      "y": 3,
      "z": 4,
      "name": "Rock_Ice_Permafrost",
      "rotation": 2
    },
    {
      "x": -7,
      "y": 4,
      "z": 4,
      "name": "Rock_Ice_Permafrost",
      "rotation": 2
    },
    {
      "x": -7,
      "y": 5,
      "z": 4,
      "name": "Rock_Ice_Permafrost",
      "rotation": 2
    },
    {
      "x": -7,
      "y": 6,
      "z": 4,
      "name": "Rock_Ice_Permafrost",
      "rotation": 2
    },
    {
      "x": -7,
      "y": 7,
      "z": 4,
      "name": "Rock_Ice_Permafrost",
      "rotation": 2
    },
    {
      "x": -7,
      "y": 8,
      "z": 4,
      "name": "Rock_Ice_Permafrost",
      "rotation": 2
    },
    {
      "x": -7,
      "y": 9,
      "z": 4,
      "name": "Rock_Ice_Permafrost",
      "rotation": 2
    },
    {
      "x": -7,
      "y": 0,
      "z": 5,
      "name": "Rock_Ice_Permafrost",
      "rotation": 2
    },
    {
      "x": -7,
      "y": 1,
      "z": 5,
      "name": "Rock_Ice_Permafrost",
      "rotation": 2
    },
    {
      "x": -7,
      "y": 2,
      "z": 5,
      "name": "Rock_Ice_Permafrost",
      "rotation": 2
    },
    {
      "x": -7,
      "y": 3,
      "z": 5,
      "name": "Rock_Ice_Permafrost",
      "rotation": 2
    },
    {
      "x": -7,
      "y": 4,
      "z": 5,
      "name": "Rock_Ice_Permafrost",
      "rotation": 2
    },
    {
      "x": -7,
      "y": 5,
      "z": 5,
      "name": "Rock_Ice_Permafrost",
      "rotation": 2
    },
    {
      "x": -7,
      "y": 6,
      "z": 5,
      "name": "Rock_Ice_Permafrost",
      "rotation": 2
    },
    {
      "x": -7,
      "y": 7,
      "z": 5,
      "name": "Rock_Ice_Permafrost",
      "rotation": 2
    },
    {
      "x": -7,
      "y": 8,
      "z": 5,
      "name": "Rock_Ice_Permafrost",
      "rotation": 2
    },
    {
      "x": -7,
      "y": 9,
      "z": 5,
      "name": "Rock_Ice_Permafrost",
      "rotation": 2
    },
    {
      "x": -7,
      "y": 10,
      "z": 5,
      "name": "Rock_Ice_Permafrost",
      "rotation": 2
    },
    {
      "x": -7,
      "y": 11,
      "z": 5,
      "name": "Rock_Ice_Permafrost",
      "rotation": 2
    },
    {
      "x": -7,
      "y": 12,
      "z": 5,
      "name": "Rock_Ice_Icicles",
      "rotation": 2
    },
    {
      "x": -7,
      "y": 0,
      "z": 6,
      "name": "Rock_Ice_Permafrost",
      "rotation": 2
    },
    {
      "x": -7,
      "y": 1,
      "z": 6,
      "name": "Rock_Ice_Permafrost",
      "rotation": 2
    },
    {
      "x": -7,
      "y": 2,
      "z": 6,
      "name": "Rock_Ice_Permafrost",
      "rotation": 2
    },
    {
      "x": -7,
      "y": 3,
      "z": 6,
      "name": "Rock_Ice_Permafrost",
      "rotation": 2
    },
    {
      "x": -7,
      "y": 4,
      "z": 6,
      "name": "Rock_Ice_Permafrost",
      "rotation": 2
    },
    {
      "x": -7,
      "y": 5,
      "z": 6,
      "name": "Rock_Ice_Permafrost",
      "rotation": 2
    },
    {
      "x": -7,
      "y": 6,
      "z": 6,
      "name": "Rock_Ice_Permafrost",
      "rotation": 2
    },
    {
      "x": -7,
      "y": 7,
      "z": 6,
      "name": "Rock_Ice_Permafrost",
      "rotation": 2
    },
    {
      "x": -7,
      "y": 8,
      "z": 6,
      "name": "Rock_Ice_Permafrost",
      "rotation": 2
    },
    {
      "x": -7,
      "y": 9,
      "z": 6,
      "name": "Rock_Ice_Permafrost",
      "rotation": 2
    },
    {
      "x": -7,
      "y": 10,
      "z": 6,
      "name": "Rock_Ice_Permafrost",
      "rotation": 2
    },
    {
      "x": -7,
      "y": 11,
      "z": 6,
      "name": "Rock_Ice_Permafrost",
      "rotation": 2
    },
    {
      "x": -7,
      "y": 12,
      "z": 6,
      "name": "Rock_Ice_Permafrost",
      "rotation": 2
    },
    {
      "x": -7,
      "y": 0,
      "z": 7,
      "name": "Rock_Ice_Permafrost",
      "rotation": 2
    },
    {
      "x": -7,
      "y": 1,
      "z": 7,
      "name": "Rock_Ice_Permafrost",
      "rotation": 2
    },
    {
      "x": -7,
      "y": 2,
      "z": 7,
      "name": "Rock_Ice_Permafrost",
      "rotation": 2
    },
    {
      "x": -7,
      "y": 3,
      "z": 7,
      "name": "Rock_Ice_Permafrost",
      "rotation": 2
    },
    {
      "x": -7,
      "y": 4,
      "z": 7,
      "name": "Rock_Ice_Permafrost",
      "rotation": 2
    },
    {
      "x": -7,
      "y": 5,
      "z": 7,
      "name": "Rock_Ice_Permafrost",
      "rotation": 2
    },
    {
      "x": -7,
      "y": 6,
      "z": 7,
      "name": "Rock_Ice_Permafrost",
      "rotation": 2
    },
    {
      "x": -7,
      "y": 7,
      "z": 7,
      "name": "Rock_Ice_Permafrost",
      "rotation": 2
    },
    {
      "x": -7,
      "y": 8,
      "z": 7,
      "name": "Rock_Ice_Permafrost",
      "rotation": 2
    },
    {
      "x": -7,
      "y": 9,
      "z": 7,
      "name": "Rock_Ice_Permafrost",
      "rotation": 2
    },
    {
      "x": -7,
      "y": 10,
      "z": 7,
      "name": "Rock_Ice_Permafrost",
      "rotation": 2
    },
    {
      "x": -7,
      "y": 11,
      "z": 7,
      "name": "Rock_Ice_Permafrost",
      "rotation": 2
    },
    {
      "x": -7,
      "y": 12,
      "z": 7,
      "name": "Rock_Ice_Permafrost",
      "rotation": 2
    },
    {
      "x": -7,
      "y": 13,
      "z": 7,
      "name": "Rock_Ice_Icicles",
      "rotation": 2
    },
    {
      "x": -7,
      "y": 0,
      "z": 8,
      "name": "Rock_Ice_Permafrost",
      "rotation": 2
    },
    {
      "x": -7,
      "y": 1,
      "z": 8,
      "name": "Rock_Ice_Permafrost",
      "rotation": 2
    },
    {
      "x": -7,
      "y": 2,
      "z": 8,
      "name": "Rock_Ice_Permafrost",
      "rotation": 2
    },
    {
      "x": -7,
      "y": 3,
      "z": 8,
      "name": "Rock_Ice_Permafrost",
      "rotation": 2
    },
    {
      "x": -7,
      "y": 4,
      "z": 8,
      "name": "Rock_Ice_Permafrost",
      "rotation": 2
    },
    {
      "x": -7,
      "y": 5,
      "z": 8,
      "name": "Rock_Ice_Permafrost",
      "rotation": 2
    },
    {
      "x": -7,
      "y": 6,
      "z": 8,
      "name": "Rock_Ice_Permafrost",
      "rotation": 2
    },
    {
      "x": -7,
      "y": 7,
      "z": 8,
      "name": "Rock_Ice_Permafrost",
      "rotation": 2
    },
    {
      "x": -7,
      "y": 8,
      "z": 8,
      "name": "Rock_Ice_Icicles",
      "rotation": 2
    },
    {
      "x": -7,
      "y": 0,
      "z": 9,
      "name": "Rock_Ice_Permafrost",
      "rotation": 2
    },
    {
      "x": -7,
      "y": 1,
      "z": 9,
      "name": "Rock_Ice_Permafrost",
      "rotation": 2
    },
    {
      "x": -7,
      "y": 2,
      "z": 9,
      "name": "Rock_Ice_Permafrost",
      "rotation": 2
    },
    {
      "x": -7,
      "y": 3,
      "z": 9,
      "name": "Rock_Ice_Permafrost",
      "rotation": 2
    },
    {
      "x": -7,
      "y": 4,
      "z": 9,
      "name": "Rock_Ice_Permafrost",
      "rotation": 2
    },
    {
      "x": -7,
      "y": 5,
      "z": 9,
      "name": "Rock_Ice_Stalactite_Large",
      "rotation": 2
    },
    {
      "x": -7,
      "y": 6,
      "z": 9,
      "name": "Rock_Ice_Stalactite_Large",
      "filler": 1024,
      "rotation": 2
    },
    {
      "x": -6,
      "y": 3,
      "z": -8,
      "name": "Rock_Ice_Permafrost"
    },
    {
      "x": -6,
      "y": 3,
      "z": -7,
      "name": "Rock_Ice_Permafrost"
    },
    {
      "x": -6,
      "y": 4,
      "z": -7,
      "name": "Rock_Ice_Permafrost"
    },
    {
      "x": -6,
      "y": 5,
      "z": -7,
      "name": "Rock_Ice_Permafrost"
    },
    {
      "x": -6,
      "y": 6,
      "z": -7,
      "name": "Rock_Ice_Permafrost"
    },
    {
      "x": -6,
      "y": 3,
      "z": -6,
      "name": "Rock_Ice_Permafrost"
    },
    {
      "x": -6,
      "y": 4,
      "z": -6,
      "name": "Rock_Ice_Permafrost"
    },
    {
      "x": -6,
      "y": 5,
      "z": -6,
      "name": "Rock_Ice_Permafrost"
    },
    {
      "x": -6,
      "y": 6,
      "z": -6,
      "name": "Rock_Ice_Permafrost"
    },
    {
      "x": -6,
      "y": 7,
      "z": -6,
      "name": "Rock_Ice_Permafrost"
    },
    {
      "x": -6,
      "y": 8,
      "z": -6,
      "name": "Rock_Ice_Permafrost"
    },
    {
      "x": -6,
      "y": 9,
      "z": -6,
      "name": "Rock_Ice_Permafrost"
    },
    {
      "x": -6,
      "y": 10,
      "z": -6,
      "name": "Rock_Ice_Permafrost"
    },
    {
      "x": -6,
      "y": 11,
      "z": -6,
      "name": "Rock_Ice_Permafrost"
    },
    {
      "x": -6,
      "y": 12,
      "z": -6,
      "name": "Rock_Ice_Permafrost"
    },
    {
      "x": -6,
      "y": 13,
      "z": -6,
      "name": "Rock_Ice_Permafrost"
    },
    {
      "x": -6,
      "y": 14,
      "z": -6,
      "name": "Rock_Ice_Stalactite_Large"
    },
    {
      "x": -6,
      "y": 15,
      "z": -6,
      "name": "Rock_Ice_Stalactite_Large",
      "filler": 1024
    },
    {
      "x": -6,
      "y": 3,
      "z": -5,
      "name": "Rock_Ice_Permafrost"
    },
    {
      "x": -6,
      "y": 4,
      "z": -5,
      "name": "Rock_Ice_Permafrost"
    },
    {
      "x": -6,
      "y": 5,
      "z": -5,
      "name": "Rock_Ice_Permafrost"
    },
    {
      "x": -6,
      "y": 6,
      "z": -5,
      "name": "Rock_Ice_Permafrost"
    },
    {
      "x": -6,
      "y": 7,
      "z": -5,
      "name": "Rock_Ice_Permafrost"
    },
    {
      "x": -6,
      "y": 8,
      "z": -5,
      "name": "Rock_Ice_Permafrost"
    },
    {
      "x": -6,
      "y": 9,
      "z": -5,
      "name": "Rock_Ice_Permafrost"
    },
    {
      "x": -6,
      "y": 10,
      "z": -5,
      "name": "Rock_Ice_Permafrost"
    },
    {
      "x": -6,
      "y": 11,
      "z": -5,
      "name": "Rock_Ice_Permafrost"
    },
    {
      "x": -6,
      "y": 12,
      "z": -5,
      "name": "Rock_Ice_Permafrost"
    },
    {
      "x": -6,
      "y": 13,
      "z": -5,
      "name": "Rock_Ice_Permafrost"
    },
    {
      "x": -6,
      "y": 14,
      "z": -5,
      "name": "Rock_Ice_Permafrost"
    },
    {
      "x": -6,
      "y": 3,
      "z": -4,
      "name": "Rock_Ice_Permafrost"
    },
    {
      "x": -6,
      "y": 4,
      "z": -4,
      "name": "Rock_Ice_Permafrost"
    },
    {
      "x": -6,
      "y": 5,
      "z": -4,
      "name": "Rock_Ice_Permafrost"
    },
    {
      "x": -6,
      "y": 6,
      "z": -4,
      "name": "Rock_Ice_Permafrost"
    },
    {
      "x": -6,
      "y": 7,
      "z": -4,
      "name": "Rock_Ice_Permafrost"
    },
    {
      "x": -6,
      "y": 8,
      "z": -4,
      "name": "Rock_Ice_Permafrost"
    },
    {
      "x": -6,
      "y": 9,
      "z": -4,
      "name": "Rock_Ice_Permafrost"
    },
    {
      "x": -6,
      "y": 10,
      "z": -4,
      "name": "Rock_Ice_Permafrost"
    },
    {
      "x": -6,
      "y": 11,
      "z": -4,
      "name": "Rock_Ice_Permafrost"
    },
    {
      "x": -6,
      "y": 12,
      "z": -4,
      "name": "Rock_Ice_Permafrost"
    },
    {
      "x": -6,
      "y": 13,
      "z": -4,
      "name": "Rock_Ice_Permafrost"
    },
    {
      "x": -6,
      "y": 14,
      "z": -4,
      "name": "Rock_Ice_Permafrost"
    },
    {
      "x": -6,
      "y": 3,
      "z": -3,
      "name": "Rock_Ice_Permafrost"
    },
    {
      "x": -6,
      "y": 4,
      "z": -3,
      "name": "Rock_Ice_Permafrost"
    },
    {
      "x": -6,
      "y": 5,
      "z": -3,
      "name": "Rock_Ice_Permafrost"
    },
    {
      "x": -6,
      "y": 6,
      "z": -3,
      "name": "Rock_Ice_Permafrost"
    },
    {
      "x": -6,
      "y": 7,
      "z": -3,
      "name": "Rock_Ice_Permafrost"
    },
    {
      "x": -6,
      "y": 8,
      "z": -3,
      "name": "Rock_Ice_Permafrost"
    },
    {
      "x": -6,
      "y": 9,
      "z": -3,
      "name": "Rock_Ice_Permafrost"
    },
    {
      "x": -6,
      "y": 10,
      "z": -3,
      "name": "Rock_Ice_Permafrost"
    },
    {
      "x": -6,
      "y": 11,
      "z": -3,
      "name": "Rock_Ice_Permafrost"
    },
    {
      "x": -6,
      "y": 12,
      "z": -3,
      "name": "Rock_Ice_Permafrost"
    },
    {
      "x": -6,
      "y": 13,
      "z": -3,
      "name": "Rock_Ice_Permafrost"
    },
    {
      "x": -6,
      "y": 14,
      "z": -3,
      "name": "Rubble_Ice",
      "support": 15
    },
    {
      "x": -6,
      "y": 3,
      "z": -2,
      "name": "Rock_Ice_Permafrost"
    },
    {
      "x": -6,
      "y": 4,
      "z": -2,
      "name": "Rock_Ice_Permafrost"
    },
    {
      "x": -6,
      "y": 5,
      "z": -2,
      "name": "Rock_Ice_Permafrost"
    },
    {
      "x": -6,
      "y": 6,
      "z": -2,
      "name": "Rock_Ice_Permafrost"
    },
    {
      "x": -6,
      "y": 7,
      "z": -2,
      "name": "Rock_Ice_Permafrost"
    },
    {
      "x": -6,
      "y": 8,
      "z": -2,
      "name": "Rock_Ice_Permafrost"
    },
    {
      "x": -6,
      "y": 9,
      "z": -2,
      "name": "Rock_Ice_Permafrost"
    },
    {
      "x": -6,
      "y": 10,
      "z": -2,
      "name": "Rock_Ice_Permafrost"
    },
    {
      "x": -6,
      "y": 11,
      "z": -2,
      "name": "Rock_Ice_Permafrost"
    },
    {
      "x": -6,
      "y": 12,
      "z": -2,
      "name": "Rock_Ice_Permafrost"
    },
    {
      "x": -6,
      "y": 13,
      "z": -2,
      "name": "Rock_Ice_Icicles"
    },
    {
      "x": -6,
      "y": 0,
      "z": -1,
      "name": "Rock_Ice_Permafrost",
      "rotation": 2
    },
    {
      "x": -6,
      "y": 1,
      "z": -1,
      "name": "Rock_Ice_Permafrost",
      "rotation": 2
    },
    {
      "x": -6,
      "y": 2,
      "z": -1,
      "name": "Rock_Ice_Permafrost",
      "rotation": 2
    },
    {
      "x": -6,
      "y": 3,
      "z": -1,
      "name": "Rubble_Ice_Medium",
      "support": 15,
      "rotation": 2
    },
    {
      "x": -6,
      "y": 4,
      "z": -1,
      "name": "Rock_Ice_Permafrost"
    },
    {
      "x": -6,
      "y": 5,
      "z": -1,
      "name": "Rock_Crystal_Cyan_Large",
      "rotation": 7
    },
    {
      "x": -6,
      "y": 0,
      "z": 0,
      "name": "Rock_Ice_Permafrost",
      "rotation": 2
    },
    {
      "x": -6,
      "y": 1,
      "z": 0,
      "name": "Rock_Ice_Permafrost",
      "rotation": 2
    },
    {
      "x": -6,
      "y": 2,
      "z": 0,
      "name": "Rock_Ice_Permafrost",
      "rotation": 2
    },
    {
      "x": -6,
      "y": 3,
      "z": 0,
      "name": "Rock_Ice_Permafrost",
      "rotation": 2
    },
    {
      "x": -6,
      "y": 4,
      "z": 0,
      "name": "Rock_Ice_Permafrost",
      "rotation": 2
    },
    {
      "x": -6,
      "y": 5,
      "z": 0,
      "name": "Rock_Ice_Permafrost",
      "rotation": 2
    },
    {
      "x": -6,
      "y": 0,
      "z": 1,
      "name": "Rock_Ice_Permafrost",
      "rotation": 2
    },
    {
      "x": -6,
      "y": 1,
      "z": 1,
      "name": "Rock_Ice_Permafrost",
      "rotation": 2
    },
    {
      "x": -6,
      "y": 2,
      "z": 1,
      "name": "Rock_Ice_Permafrost",
      "rotation": 2
    },
    {
      "x": -6,
      "y": 3,
      "z": 1,
      "name": "Rock_Ice_Permafrost",
      "rotation": 2
    },
    {
      "x": -6,
      "y": 4,
      "z": 1,
      "name": "Rock_Ice_Permafrost",
      "rotation": 2
    },
    {
      "x": -6,
      "y": 5,
      "z": 1,
      "name": "Rock_Ice_Permafrost",
      "rotation": 2
    },
    {
      "x": -6,
      "y": 6,
      "z": 1,
      "name": "Rock_Ice_Permafrost",
      "rotation": 2
    },
    {
      "x": -6,
      "y": 7,
      "z": 1,
      "name": "Rock_Crystal_Cyan_Large",
      "rotation": 2
    },
    {
      "x": -6,
      "y": 0,
      "z": 2,
      "name": "Rock_Ice_Permafrost",
      "rotation": 2
    },
    {
      "x": -6,
      "y": 1,
      "z": 2,
      "name": "Rock_Ice_Permafrost",
      "rotation": 2
    },
    {
      "x": -6,
      "y": 2,
      "z": 2,
      "name": "Rock_Ice_Permafrost",
      "rotation": 2
    },
    {
      "x": -6,
      "y": 3,
      "z": 2,
      "name": "Rock_Ice_Permafrost",
      "rotation": 2
    },
    {
      "x": -6,
      "y": 4,
      "z": 2,
      "name": "Rock_Ice_Permafrost",
      "rotation": 2
    },
    {
      "x": -6,
      "y": 5,
      "z": 2,
      "name": "Rock_Ice_Permafrost",
      "rotation": 2
    },
    {
      "x": -6,
      "y": 6,
      "z": 2,
      "name": "Rock_Ice_Permafrost",
      "rotation": 2
    },
    {
      "x": -6,
      "y": 7,
      "z": 2,
      "name": "Rock_Ice_Permafrost",
      "rotation": 2
    },
    {
      "x": -6,
      "y": 8,
      "z": 2,
      "name": "Rock_Ice_Permafrost",
      "rotation": 2
    },
    {
      "x": -6,
      "y": 0,
      "z": 3,
      "name": "Rock_Ice_Permafrost",
      "rotation": 2
    },
    {
      "x": -6,
      "y": 1,
      "z": 3,
      "name": "Rock_Ice_Permafrost",
      "rotation": 2
    },
    {
      "x": -6,
      "y": 2,
      "z": 3,
      "name": "Rock_Ice_Permafrost",
      "rotation": 2
    },
    {
      "x": -6,
      "y": 3,
      "z": 3,
      "name": "Rock_Ice_Permafrost",
      "rotation": 2
    },
    {
      "x": -6,
      "y": 4,
      "z": 3,
      "name": "Rock_Ice_Permafrost",
      "rotation": 2
    },
    {
      "x": -6,
      "y": 5,
      "z": 3,
      "name": "Rock_Ice_Permafrost",
      "rotation": 2
    },
    {
      "x": -6,
      "y": 6,
      "z": 3,
      "name": "Rock_Ice_Permafrost",
      "rotation": 2
    },
    {
      "x": -6,
      "y": 7,
      "z": 3,
      "name": "Rock_Ice_Permafrost",
      "rotation": 2
    },
    {
      "x": -6,
      "y": 8,
      "z": 3,
      "name": "Rock_Ice_Permafrost",
      "rotation": 2
    },
    {
      "x": -6,
      "y": 9,
      "z": 3,
      "name": "Rock_Ice_Permafrost",
      "rotation": 2
    },
    {
      "x": -6,
      "y": 10,
      "z": 3,
      "name": "Rock_Ice_Icicles",
      "rotation": 2
    },
    {
      "x": -6,
      "y": 0,
      "z": 4,
      "name": "Rock_Ice_Permafrost",
      "rotation": 2
    },
    {
      "x": -6,
      "y": 1,
      "z": 4,
      "name": "Rock_Ice_Permafrost",
      "rotation": 2
    },
    {
      "x": -6,
      "y": 2,
      "z": 4,
      "name": "Rock_Ice_Permafrost",
      "rotation": 2
    },
    {
      "x": -6,
      "y": 3,
      "z": 4,
      "name": "Rock_Ice_Permafrost",
      "rotation": 2
    },
    {
      "x": -6,
      "y": 4,
      "z": 4,
      "name": "Rock_Ice_Permafrost",
      "rotation": 2
    },
    {
      "x": -6,
      "y": 5,
      "z": 4,
      "name": "Rock_Ice_Permafrost",
      "rotation": 2
    },
    {
      "x": -6,
      "y": 6,
      "z": 4,
      "name": "Rock_Ice_Permafrost",
      "rotation": 2
    },
    {
      "x": -6,
      "y": 7,
      "z": 4,
      "name": "Rock_Ice_Permafrost",
      "rotation": 2
    },
    {
      "x": -6,
      "y": 8,
      "z": 4,
      "name": "Rock_Ice_Permafrost",
      "rotation": 2
    },
    {
      "x": -6,
      "y": 9,
      "z": 4,
      "name": "Rock_Ice_Permafrost",
      "rotation": 2
    },
    {
      "x": -6,
      "y": 10,
      "z": 4,
      "name": "Rock_Ice_Permafrost",
      "rotation": 2
    },
    {
      "x": -6,
      "y": 11,
      "z": 4,
      "name": "Rock_Ice_Permafrost",
      "rotation": 2
    },
    {
      "x": -6,
      "y": 0,
      "z": 5,
      "name": "Rock_Ice_Permafrost",
      "rotation": 2
    },
    {
      "x": -6,
      "y": 1,
      "z": 5,
      "name": "Rock_Ice_Permafrost",
      "rotation": 2
    },
    {
      "x": -6,
      "y": 2,
      "z": 5,
      "name": "Rock_Ice_Permafrost",
      "rotation": 2
    },
    {
      "x": -6,
      "y": 3,
      "z": 5,
      "name": "Rock_Ice_Permafrost",
      "rotation": 2
    },
    {
      "x": -6,
      "y": 4,
      "z": 5,
      "name": "Rock_Ice_Permafrost",
      "rotation": 2
    },
    {
      "x": -6,
      "y": 5,
      "z": 5,
      "name": "Rock_Ice_Permafrost",
      "rotation": 2
    },
    {
      "x": -6,
      "y": 6,
      "z": 5,
      "name": "Rock_Ice_Permafrost",
      "rotation": 2
    },
    {
      "x": -6,
      "y": 7,
      "z": 5,
      "name": "Rock_Ice_Permafrost",
      "rotation": 2
    },
    {
      "x": -6,
      "y": 8,
      "z": 5,
      "name": "Rock_Ice_Permafrost",
      "rotation": 2
    },
    {
      "x": -6,
      "y": 9,
      "z": 5,
      "name": "Rock_Ice_Permafrost",
      "rotation": 2
    },
    {
      "x": -6,
      "y": 10,
      "z": 5,
      "name": "Rock_Ice_Permafrost",
      "rotation": 2
    },
    {
      "x": -6,
      "y": 11,
      "z": 5,
      "name": "Rock_Ice_Permafrost",
      "rotation": 2
    },
    {
      "x": -6,
      "y": 12,
      "z": 5,
      "name": "Rock_Ice_Permafrost",
      "rotation": 2
    },
    {
      "x": -6,
      "y": 13,
      "z": 5,
      "name": "Rock_Ice_Icicles",
      "rotation": 2
    },
    {
      "x": -6,
      "y": 0,
      "z": 6,
      "name": "Rock_Ice_Permafrost",
      "rotation": 2
    },
    {
      "x": -6,
      "y": 1,
      "z": 6,
      "name": "Rock_Ice_Permafrost",
      "rotation": 2
    },
    {
      "x": -6,
      "y": 2,
      "z": 6,
      "name": "Rock_Ice_Permafrost",
      "rotation": 2
    },
    {
      "x": -6,
      "y": 3,
      "z": 6,
      "name": "Rock_Ice_Permafrost",
      "rotation": 2
    },
    {
      "x": -6,
      "y": 4,
      "z": 6,
      "name": "Rock_Ice_Permafrost",
      "rotation": 2
    },
    {
      "x": -6,
      "y": 5,
      "z": 6,
      "name": "Rock_Ice_Permafrost",
      "rotation": 2
    },
    {
      "x": -6,
      "y": 6,
      "z": 6,
      "name": "Rock_Ice_Permafrost",
      "rotation": 2
    },
    {
      "x": -6,
      "y": 7,
      "z": 6,
      "name": "Rock_Ice_Permafrost",
      "rotation": 2
    },
    {
      "x": -6,
      "y": 8,
      "z": 6,
      "name": "Rock_Ice_Permafrost",
      "rotation": 2
    },
    {
      "x": -6,
      "y": 9,
      "z": 6,
      "name": "Rock_Ice_Permafrost",
      "rotation": 2
    },
    {
      "x": -6,
      "y": 10,
      "z": 6,
      "name": "Rock_Ice_Permafrost",
      "rotation": 2
    },
    {
      "x": -6,
      "y": 11,
      "z": 6,
      "name": "Rock_Ice_Permafrost",
      "rotation": 2
    },
    {
      "x": -6,
      "y": 12,
      "z": 6,
      "name": "Rock_Ice_Permafrost",
      "rotation": 2
    },
    {
      "x": -6,
      "y": 13,
      "z": 6,
      "name": "Rock_Ice_Permafrost",
      "rotation": 2
    },
    {
      "x": -6,
      "y": 0,
      "z": 7,
      "name": "Rock_Ice_Permafrost",
      "rotation": 2
    },
    {
      "x": -6,
      "y": 1,
      "z": 7,
      "name": "Rock_Ice_Permafrost",
      "rotation": 2
    },
    {
      "x": -6,
      "y": 2,
      "z": 7,
      "name": "Rock_Ice_Permafrost",
      "rotation": 2
    },
    {
      "x": -6,
      "y": 3,
      "z": 7,
      "name": "Rock_Ice_Permafrost",
      "rotation": 2
    },
    {
      "x": -6,
      "y": 4,
      "z": 7,
      "name": "Rock_Ice_Permafrost",
      "rotation": 2
    },
    {
      "x": -6,
      "y": 5,
      "z": 7,
      "name": "Rock_Ice_Permafrost",
      "rotation": 2
    },
    {
      "x": -6,
      "y": 6,
      "z": 7,
      "name": "Rock_Ice_Permafrost",
      "rotation": 2
    },
    {
      "x": -6,
      "y": 7,
      "z": 7,
      "name": "Rock_Ice_Permafrost",
      "rotation": 2
    },
    {
      "x": -6,
      "y": 8,
      "z": 7,
      "name": "Rock_Ice_Permafrost",
      "rotation": 2
    },
    {
      "x": -6,
      "y": 9,
      "z": 7,
      "name": "Rock_Ice_Permafrost",
      "rotation": 2
    },
    {
      "x": -6,
      "y": 10,
      "z": 7,
      "name": "Rock_Ice_Permafrost",
      "rotation": 2
    },
    {
      "x": -6,
      "y": 11,
      "z": 7,
      "name": "Rock_Ice_Permafrost",
      "rotation": 2
    },
    {
      "x": -6,
      "y": 12,
      "z": 7,
      "name": "Rock_Ice_Permafrost",
      "rotation": 2
    },
    {
      "x": -6,
      "y": 13,
      "z": 7,
      "name": "Rock_Ice_Permafrost",
      "rotation": 2
    },
    {
      "x": -6,
      "y": 14,
      "z": 7,
      "name": "Rock_Ice_Permafrost",
      "rotation": 2
    },
    {
      "x": -6,
      "y": 15,
      "z": 7,
      "name": "Rock_Ice_Permafrost",
      "rotation": 2
    },
    {
      "x": -6,
      "y": 16,
      "z": 7,
      "name": "Rock_Crystal_Cyan_Medium",
      "rotation": 2
    },
    {
      "x": -6,
      "y": 0,
      "z": 8,
      "name": "Rock_Ice_Permafrost",
      "rotation": 2
    },
    {
      "x": -6,
      "y": 1,
      "z": 8,
      "name": "Rock_Ice_Permafrost",
      "rotation": 2
    },
    {
      "x": -6,
      "y": 2,
      "z": 8,
      "name": "Rock_Ice_Permafrost",
      "rotation": 2
    },
    {
      "x": -6,
      "y": 3,
      "z": 8,
      "name": "Rock_Ice_Permafrost",
      "rotation": 2
    },
    {
      "x": -6,
      "y": 4,
      "z": 8,
      "name": "Rock_Ice_Permafrost",
      "rotation": 2
    },
    {
      "x": -6,
      "y": 5,
      "z": 8,
      "name": "Rock_Ice_Permafrost",
      "rotation": 2
    },
    {
      "x": -6,
      "y": 6,
      "z": 8,
      "name": "Rock_Ice_Permafrost",
      "rotation": 2
    },
    {
      "x": -6,
      "y": 7,
      "z": 8,
      "name": "Rock_Ice_Permafrost",
      "rotation": 2
    },
    {
      "x": -6,
      "y": 8,
      "z": 8,
      "name": "Rock_Ice_Permafrost",
      "rotation": 2
    },
    {
      "x": -6,
      "y": 9,
      "z": 8,
      "name": "Rock_Ice_Permafrost",
      "rotation": 2
    },
    {
      "x": -6,
      "y": 10,
      "z": 8,
      "name": "Rock_Ice_Permafrost",
      "rotation": 2
    },
    {
      "x": -6,
      "y": 11,
      "z": 8,
      "name": "Rock_Ice_Permafrost",
      "rotation": 2
    },
    {
      "x": -6,
      "y": 12,
      "z": 8,
      "name": "Rock_Ice_Permafrost",
      "rotation": 2
    },
    {
      "x": -6,
      "y": 13,
      "z": 8,
      "name": "Rock_Ice_Permafrost",
      "rotation": 2
    },
    {
      "x": -6,
      "y": 14,
      "z": 8,
      "name": "Rock_Ice_Permafrost",
      "rotation": 2
    },
    {
      "x": -6,
      "y": 15,
      "z": 8,
      "name": "Rock_Ice_Permafrost",
      "rotation": 2
    },
    {
      "x": -6,
      "y": 16,
      "z": 8,
      "name": "Rock_Ice_Icicles",
      "rotation": 2
    },
    {
      "x": -6,
      "y": 0,
      "z": 9,
      "name": "Rock_Ice_Permafrost",
      "rotation": 2
    },
    {
      "x": -6,
      "y": 1,
      "z": 9,
      "name": "Rock_Ice_Permafrost",
      "rotation": 2
    },
    {
      "x": -6,
      "y": 2,
      "z": 9,
      "name": "Rock_Ice_Permafrost",
      "rotation": 2
    },
    {
      "x": -6,
      "y": 3,
      "z": 9,
      "name": "Rock_Ice_Permafrost",
      "rotation": 2
    },
    {
      "x": -6,
      "y": 4,
      "z": 9,
      "name": "Rock_Ice_Permafrost",
      "rotation": 2
    },
    {
      "x": -6,
      "y": 5,
      "z": 9,
      "name": "Rock_Ice_Permafrost",
      "rotation": 2
    },
    {
      "x": -6,
      "y": 6,
      "z": 9,
      "name": "Rock_Ice_Icicles",
      "rotation": 2
    },
    {
      "x": -6,
      "y": 15,
      "z": 9,
      "name": "Rock_Ice_Permafrost",
      "rotation": 2
    },
    {
      "x": -6,
      "y": 16,
      "z": 9,
      "name": "Rock_Ice_Permafrost",
      "rotation": 2
    },
    {
      "x": -6,
      "y": 17,
      "z": 9,
      "name": "Rock_Ice_Icicles",
      "rotation": 2
    },
    {
      "x": -5,
      "y": 3,
      "z": -9,
      "name": "Rock_Ice_Permafrost"
    },
    {
      "x": -5,
      "y": 3,
      "z": -8,
      "name": "Rock_Ice_Permafrost"
    },
    {
      "x": -5,
      "y": 4,
      "z": -8,
      "name": "Rock_Ice_Permafrost"
    },
    {
      "x": -5,
      "y": 5,
      "z": -8,
      "name": "Rock_Ice_Permafrost"
    },
    {
      "x": -5,
      "y": 3,
      "z": -7,
      "name": "Rock_Ice_Permafrost"
    },
    {
      "x": -5,
      "y": 4,
      "z": -7,
      "name": "Rock_Ice_Permafrost"
    },
    {
      "x": -5,
      "y": 5,
      "z": -7,
      "name": "Rock_Ice_Permafrost"
    },
    {
      "x": -5,
      "y": 6,
      "z": -7,
      "name": "Rock_Ice_Permafrost"
    },
    {
      "x": -5,
      "y": 7,
      "z": -7,
      "name": "Rock_Ice_Permafrost"
    },
    {
      "x": -5,
      "y": 8,
      "z": -7,
      "name": "Rock_Ice_Permafrost"
    },
    {
      "x": -5,
      "y": 9,
      "z": -7,
      "name": "Rock_Ice_Permafrost"
    },
    {
      "x": -5,
      "y": 10,
      "z": -7,
      "name": "Rock_Ice_Permafrost"
    },
    {
      "x": -5,
      "y": 11,
      "z": -7,
      "name": "Rock_Ice_Permafrost"
    },
    {
      "x": -5,
      "y": 12,
      "z": -7,
      "name": "Rock_Ice_Permafrost"
    },
    {
      "x": -5,
      "y": 13,
      "z": -7,
      "name": "Rock_Ice_Permafrost"
    },
    {
      "x": -5,
      "y": 14,
      "z": -7,
      "name": "Rock_Crystal_Cyan_Medium",
      "rotation": 6
    },
    {
      "x": -5,
      "y": 16,
      "z": -7,
      "name": "Rock_Ice_Permafrost"
    },
    {
      "x": -5,
      "y": 17,
      "z": -7,
      "name": "Rock_Ice_Permafrost"
    },
    {
      "x": -5,
      "y": 18,
      "z": -7,
      "name": "Rock_Ice_Permafrost"
    },
    {
      "x": -5,
      "y": 19,
      "z": -7,
      "name": "Rock_Ice_Permafrost"
    },
    {
      "x": -5,
      "y": 20,
      "z": -7,
      "name": "Rock_Ice_Permafrost"
    },
    {
      "x": -5,
      "y": 21,
      "z": -7,
      "name": "Rock_Ice_Icicles"
    },
    {
      "x": -5,
      "y": 3,
      "z": -6,
      "name": "Rock_Ice_Permafrost"
    },
    {
      "x": -5,
      "y": 4,
      "z": -6,
      "name": "Rock_Ice_Permafrost"
    },
    {
      "x": -5,
      "y": 5,
      "z": -6,
      "name": "Rock_Ice_Permafrost"
    },
    {
      "x": -5,
      "y": 6,
      "z": -6,
      "name": "Rock_Ice_Permafrost"
    },
    {
      "x": -5,
      "y": 7,
      "z": -6,
      "name": "Rock_Ice_Permafrost"
    },
    {
      "x": -5,
      "y": 8,
      "z": -6,
      "name": "Rock_Ice_Permafrost"
    },
    {
      "x": -5,
      "y": 9,
      "z": -6,
      "name": "Rock_Ice_Permafrost"
    },
    {
      "x": -5,
      "y": 10,
      "z": -6,
      "name": "Rock_Ice_Permafrost"
    },
    {
      "x": -5,
      "y": 11,
      "z": -6,
      "name": "Rock_Ice_Permafrost"
    },
    {
      "x": -5,
      "y": 12,
      "z": -6,
      "name": "Rock_Ice_Permafrost"
    },
    {
      "x": -5,
      "y": 13,
      "z": -6,
      "name": "Rock_Ice_Permafrost"
    },
    {
      "x": -5,
      "y": 14,
      "z": -6,
      "name": "Rock_Ice_Permafrost"
    },
    {
      "x": -5,
      "y": 15,
      "z": -6,
      "name": "Rock_Ice_Permafrost"
    },
    {
      "x": -5,
      "y": 16,
      "z": -6,
      "name": "Rock_Ice_Permafrost"
    },
    {
      "x": -5,
      "y": 17,
      "z": -6,
      "name": "Rock_Ice_Permafrost"
    },
    {
      "x": -5,
      "y": 18,
      "z": -6,
      "name": "Rock_Ice_Permafrost"
    },
    {
      "x": -5,
      "y": 19,
      "z": -6,
      "name": "Rock_Ice_Permafrost"
    },
    {
      "x": -5,
      "y": 20,
      "z": -6,
      "name": "Rock_Ice_Permafrost"
    },
    {
      "x": -5,
      "y": 21,
      "z": -6,
      "name": "Rock_Ice_Permafrost"
    },
    {
      "x": -5,
      "y": 3,
      "z": -5,
      "name": "Rock_Ice_Permafrost"
    },
    {
      "x": -5,
      "y": 4,
      "z": -5,
      "name": "Rock_Ice_Permafrost"
    },
    {
      "x": -5,
      "y": 5,
      "z": -5,
      "name": "Rock_Ice_Permafrost"
    },
    {
      "x": -5,
      "y": 6,
      "z": -5,
      "name": "Rock_Ice_Permafrost"
    },
    {
      "x": -5,
      "y": 7,
      "z": -5,
      "name": "Rock_Ice_Permafrost"
    },
    {
      "x": -5,
      "y": 8,
      "z": -5,
      "name": "Rock_Ice_Permafrost"
    },
    {
      "x": -5,
      "y": 9,
      "z": -5,
      "name": "Rock_Ice_Permafrost"
    },
    {
      "x": -5,
      "y": 10,
      "z": -5,
      "name": "Rock_Ice_Permafrost"
    },
    {
      "x": -5,
      "y": 11,
      "z": -5,
      "name": "Rock_Ice_Permafrost"
    },
    {
      "x": -5,
      "y": 12,
      "z": -5,
      "name": "Rock_Ice_Permafrost"
    },
    {
      "x": -5,
      "y": 13,
      "z": -5,
      "name": "Rock_Ice_Permafrost"
    },
    {
      "x": -5,
      "y": 14,
      "z": -5,
      "name": "Rock_Ice_Permafrost"
    },
    {
      "x": -5,
      "y": 15,
      "z": -5,
      "name": "Rock_Ice_Permafrost"
    },
    {
      "x": -5,
      "y": 16,
      "z": -5,
      "name": "Rock_Ice_Permafrost"
    },
    {
      "x": -5,
      "y": 17,
      "z": -5,
      "name": "Rock_Ice_Permafrost"
    },
    {
      "x": -5,
      "y": 18,
      "z": -5,
      "name": "Rock_Ice_Permafrost"
    },
    {
      "x": -5,
      "y": 19,
      "z": -5,
      "name": "Rock_Ice_Permafrost"
    },
    {
      "x": -5,
      "y": 0,
      "z": -4,
      "name": "Rock_Ice_Permafrost"
    },
    {
      "x": -5,
      "y": 1,
      "z": -4,
      "name": "Rubble_Ice",
      "support": 15
    },
    {
      "x": -5,
      "y": 3,
      "z": -4,
      "name": "Rock_Ice_Permafrost"
    },
    {
      "x": -5,
      "y": 4,
      "z": -4,
      "name": "Rock_Ice_Permafrost"
    },
    {
      "x": -5,
      "y": 5,
      "z": -4,
      "name": "Rock_Ice_Permafrost"
    },
    {
      "x": -5,
      "y": 6,
      "z": -4,
      "name": "Rock_Ice_Permafrost"
    },
    {
      "x": -5,
      "y": 7,
      "z": -4,
      "name": "Rock_Ice_Permafrost"
    },
    {
      "x": -5,
      "y": 8,
      "z": -4,
      "name": "Rock_Ice_Permafrost"
    },
    {
      "x": -5,
      "y": 9,
      "z": -4,
      "name": "Rock_Ice_Permafrost"
    },
    {
      "x": -5,
      "y": 10,
      "z": -4,
      "name": "Rock_Ice_Permafrost"
    },
    {
      "x": -5,
      "y": 11,
      "z": -4,
      "name": "Rock_Ice_Permafrost"
    },
    {
      "x": -5,
      "y": 12,
      "z": -4,
      "name": "Rock_Ice_Permafrost"
    },
    {
      "x": -5,
      "y": 13,
      "z": -4,
      "name": "Rock_Ice_Permafrost"
    },
    {
      "x": -5,
      "y": 14,
      "z": -4,
      "name": "Rock_Ice_Permafrost"
    },
    {
      "x": -5,
      "y": 15,
      "z": -4,
      "name": "Rock_Ice_Permafrost"
    },
    {
      "x": -5,
      "y": 16,
      "z": -4,
      "name": "Rock_Ice_Permafrost"
    },
    {
      "x": -5,
      "y": 0,
      "z": -3,
      "name": "Rock_Ice_Permafrost"
    },
    {
      "x": -5,
      "y": 1,
      "z": -3,
      "name": "Rock_Crystal_Cyan_Medium"
    },
    {
      "x": -5,
      "y": 3,
      "z": -3,
      "name": "Rock_Ice_Permafrost"
    },
    {
      "x": -5,
      "y": 4,
      "z": -3,
      "name": "Rock_Ice_Permafrost"
    },
    {
      "x": -5,
      "y": 5,
      "z": -3,
      "name": "Rock_Ice_Permafrost"
    },
    {
      "x": -5,
      "y": 6,
      "z": -3,
      "name": "Rock_Ice_Permafrost"
    },
    {
      "x": -5,
      "y": 7,
      "z": -3,
      "name": "Rock_Ice_Permafrost"
    },
    {
      "x": -5,
      "y": 8,
      "z": -3,
      "name": "Rock_Ice_Permafrost"
    },
    {
      "x": -5,
      "y": 9,
      "z": -3,
      "name": "Rock_Ice_Permafrost"
    },
    {
      "x": -5,
      "y": 10,
      "z": -3,
      "name": "Rock_Ice_Permafrost"
    },
    {
      "x": -5,
      "y": 11,
      "z": -3,
      "name": "Rock_Ice_Permafrost"
    },
    {
      "x": -5,
      "y": 12,
      "z": -3,
      "name": "Rock_Ice_Permafrost"
    },
    {
      "x": -5,
      "y": 13,
      "z": -3,
      "name": "Rock_Ice_Permafrost"
    },
    {
      "x": -5,
      "y": 14,
      "z": -3,
      "name": "Rock_Ice_Permafrost"
    },
    {
      "x": -5,
      "y": 15,
      "z": -3,
      "name": "Rock_Ice_Permafrost"
    },
    {
      "x": -5,
      "y": 16,
      "z": -3,
      "name": "Rock_Ice_Icicles"
    },
    {
      "x": -5,
      "y": 0,
      "z": -2,
      "name": "Rock_Ice_Permafrost"
    },
    {
      "x": -5,
      "y": 3,
      "z": -2,
      "name": "Rock_Ice_Permafrost"
    },
    {
      "x": -5,
      "y": 4,
      "z": -2,
      "name": "Rock_Ice_Permafrost"
    },
    {
      "x": -5,
      "y": 5,
      "z": -2,
      "name": "Rock_Ice_Permafrost"
    },
    {
      "x": -5,
      "y": 6,
      "z": -2,
      "name": "Rock_Ice_Permafrost"
    },
    {
      "x": -5,
      "y": 7,
      "z": -2,
      "name": "Rock_Ice_Permafrost"
    },
    {
      "x": -5,
      "y": 8,
      "z": -2,
      "name": "Rock_Ice_Permafrost"
    },
    {
      "x": -5,
      "y": 9,
      "z": -2,
      "name": "Rock_Ice_Permafrost"
    },
    {
      "x": -5,
      "y": 10,
      "z": -2,
      "name": "Rock_Ice_Permafrost"
    },
    {
      "x": -5,
      "y": 11,
      "z": -2,
      "name": "Rock_Ice_Permafrost"
    },
    {
      "x": -5,
      "y": 12,
      "z": -2,
      "name": "Rock_Ice_Permafrost"
    },
    {
      "x": -5,
      "y": 13,
      "z": -2,
      "name": "Rock_Ice_Permafrost"
    },
    {
      "x": -5,
      "y": 0,
      "z": -1,
      "name": "Rock_Ice_Permafrost",
      "rotation": 2
    },
    {
      "x": -5,
      "y": 1,
      "z": -1,
      "name": "Rock_Ice_Permafrost",
      "rotation": 2
    },
    {
      "x": -5,
      "y": 2,
      "z": -1,
      "name": "Rock_Ice_Permafrost",
      "rotation": 2
    },
    {
      "x": -5,
      "y": 3,
      "z": -1,
      "name": "Rock_Ice_Permafrost",
      "rotation": 2
    },
    {
      "x": -5,
      "y": 4,
      "z": -1,
      "name": "Rock_Ice_Permafrost",
      "rotation": 2
    },
    {
      "x": -5,
      "y": 5,
      "z": -1,
      "name": "Rock_Ice_Permafrost"
    },
    {
      "x": -5,
      "y": 6,
      "z": -1,
      "name": "Rock_Ice_Permafrost"
    },
    {
      "x": -5,
      "y": 7,
      "z": -1,
      "name": "Rock_Ice_Permafrost"
    },
    {
      "x": -5,
      "y": 8,
      "z": -1,
      "name": "Rock_Ice_Permafrost"
    },
    {
      "x": -5,
      "y": 9,
      "z": -1,
      "name": "Rock_Ice_Permafrost"
    },
    {
      "x": -5,
      "y": 10,
      "z": -1,
      "name": "Rock_Ice_Permafrost"
    },
    {
      "x": -5,
      "y": 11,
      "z": -1,
      "name": "Rock_Ice_Permafrost"
    },
    {
      "x": -5,
      "y": 12,
      "z": -1,
      "name": "Rock_Ice_Permafrost"
    },
    {
      "x": -5,
      "y": 13,
      "z": -1,
      "name": "Rubble_Ice_Medium",
      "support": 15
    },
    {
      "x": -5,
      "y": 0,
      "z": 0,
      "name": "Rock_Ice_Permafrost",
      "rotation": 2
    },
    {
      "x": -5,
      "y": 1,
      "z": 0,
      "name": "Rock_Ice_Permafrost",
      "rotation": 2
    },
    {
      "x": -5,
      "y": 2,
      "z": 0,
      "name": "Rock_Ice_Permafrost",
      "rotation": 2
    },
    {
      "x": -5,
      "y": 3,
      "z": 0,
      "name": "Rock_Ice_Permafrost",
      "rotation": 2
    },
    {
      "x": -5,
      "y": 4,
      "z": 0,
      "name": "Rock_Ice_Permafrost",
      "rotation": 2
    },
    {
      "x": -5,
      "y": 5,
      "z": 0,
      "name": "Rock_Ice_Permafrost",
      "rotation": 2
    },
    {
      "x": -5,
      "y": 6,
      "z": 0,
      "name": "Rock_Ice_Permafrost",
      "rotation": 2
    },
    {
      "x": -5,
      "y": 7,
      "z": 0,
      "name": "Rock_Ice_Permafrost"
    },
    {
      "x": -5,
      "y": 8,
      "z": 0,
      "name": "Rock_Ice_Permafrost"
    },
    {
      "x": -5,
      "y": 9,
      "z": 0,
      "name": "Rock_Ice_Stalactite_Large"
    },
    {
      "x": -5,
      "y": 10,
      "z": 0,
      "name": "Rock_Ice_Stalactite_Large",
      "filler": 1024
    },
    {
      "x": -5,
      "y": 0,
      "z": 1,
      "name": "Rock_Ice_Permafrost",
      "rotation": 2
    },
    {
      "x": -5,
      "y": 1,
      "z": 1,
      "name": "Rock_Ice_Permafrost",
      "rotation": 2
    },
    {
      "x": -5,
      "y": 2,
      "z": 1,
      "name": "Rock_Ice_Permafrost",
      "rotation": 2
    },
    {
      "x": -5,
      "y": 3,
      "z": 1,
      "name": "Rock_Ice_Permafrost",
      "rotation": 2
    },
    {
      "x": -5,
      "y": 4,
      "z": 1,
      "name": "Rock_Ice_Permafrost",
      "rotation": 2
    },
    {
      "x": -5,
      "y": 5,
      "z": 1,
      "name": "Rock_Ice_Permafrost",
      "rotation": 2
    },
    {
      "x": -5,
      "y": 6,
      "z": 1,
      "name": "Rock_Ice_Permafrost",
      "rotation": 2
    },
    {
      "x": -5,
      "y": 7,
      "z": 1,
      "name": "Rock_Ice_Permafrost",
      "rotation": 2
    },
    {
      "x": -5,
      "y": 0,
      "z": 2,
      "name": "Rock_Ice_Permafrost",
      "rotation": 2
    },
    {
      "x": -5,
      "y": 1,
      "z": 2,
      "name": "Rock_Ice_Permafrost",
      "rotation": 2
    },
    {
      "x": -5,
      "y": 2,
      "z": 2,
      "name": "Rock_Ice_Permafrost",
      "rotation": 2
    },
    {
      "x": -5,
      "y": 3,
      "z": 2,
      "name": "Rock_Ice_Permafrost",
      "rotation": 2
    },
    {
      "x": -5,
      "y": 4,
      "z": 2,
      "name": "Rock_Ice_Permafrost",
      "rotation": 2
    },
    {
      "x": -5,
      "y": 5,
      "z": 2,
      "name": "Rock_Ice_Permafrost",
      "rotation": 2
    },
    {
      "x": -5,
      "y": 6,
      "z": 2,
      "name": "Rock_Ice_Permafrost",
      "rotation": 2
    },
    {
      "x": -5,
      "y": 7,
      "z": 2,
      "name": "Rock_Ice_Permafrost",
      "rotation": 2
    },
    {
      "x": -5,
      "y": 8,
      "z": 2,
      "name": "Rock_Ice_Permafrost",
      "rotation": 2
    },
    {
      "x": -5,
      "y": 9,
      "z": 2,
      "name": "Rubble_Ice",
      "support": 15,
      "rotation": 2
    },
    {
      "x": -5,
      "y": 0,
      "z": 3,
      "name": "Rock_Ice_Permafrost",
      "rotation": 2
    },
    {
      "x": -5,
      "y": 1,
      "z": 3,
      "name": "Rock_Ice_Permafrost",
      "rotation": 2
    },
    {
      "x": -5,
      "y": 2,
      "z": 3,
      "name": "Rock_Ice_Permafrost",
      "rotation": 2
    },
    {
      "x": -5,
      "y": 3,
      "z": 3,
      "name": "Rock_Ice_Permafrost",
      "rotation": 2
    },
    {
      "x": -5,
      "y": 4,
      "z": 3,
      "name": "Rock_Ice_Permafrost",
      "rotation": 2
    },
    {
      "x": -5,
      "y": 5,
      "z": 3,
      "name": "Rock_Ice_Permafrost",
      "rotation": 2
    },
    {
      "x": -5,
      "y": 6,
      "z": 3,
      "name": "Rock_Ice_Permafrost",
      "rotation": 2
    },
    {
      "x": -5,
      "y": 7,
      "z": 3,
      "name": "Rock_Ice_Permafrost",
      "rotation": 2
    },
    {
      "x": -5,
      "y": 8,
      "z": 3,
      "name": "Rock_Ice_Permafrost",
      "rotation": 2
    },
    {
      "x": -5,
      "y": 9,
      "z": 3,
      "name": "Rock_Ice_Permafrost",
      "rotation": 2
    },
    {
      "x": -5,
      "y": 0,
      "z": 4,
      "name": "Rock_Ice_Permafrost",
      "rotation": 2
    },
    {
      "x": -5,
      "y": 1,
      "z": 4,
      "name": "Rock_Ice_Permafrost",
      "rotation": 2
    },
    {
      "x": -5,
      "y": 2,
      "z": 4,
      "name": "Rock_Ice_Permafrost",
      "rotation": 2
    },
    {
      "x": -5,
      "y": 3,
      "z": 4,
      "name": "Rock_Ice_Permafrost",
      "rotation": 2
    },
    {
      "x": -5,
      "y": 4,
      "z": 4,
      "name": "Rock_Ice_Permafrost",
      "rotation": 2
    },
    {
      "x": -5,
      "y": 5,
      "z": 4,
      "name": "Rock_Ice_Permafrost",
      "rotation": 2
    },
    {
      "x": -5,
      "y": 6,
      "z": 4,
      "name": "Rock_Ice_Permafrost",
      "rotation": 2
    },
    {
      "x": -5,
      "y": 7,
      "z": 4,
      "name": "Rock_Ice_Permafrost",
      "rotation": 2
    },
    {
      "x": -5,
      "y": 8,
      "z": 4,
      "name": "Rock_Ice_Permafrost",
      "rotation": 2
    },
    {
      "x": -5,
      "y": 9,
      "z": 4,
      "name": "Rock_Ice_Permafrost",
      "rotation": 2
    },
    {
      "x": -5,
      "y": 10,
      "z": 4,
      "name": "Rock_Ice_Permafrost",
      "rotation": 2
    },
    {
      "x": -5,
      "y": 11,
      "z": 4,
      "name": "Rock_Ice_Permafrost",
      "rotation": 2
    },
    {
      "x": -5,
      "y": 0,
      "z": 5,
      "name": "Rock_Ice_Permafrost",
      "rotation": 2
    },
    {
      "x": -5,
      "y": 1,
      "z": 5,
      "name": "Rock_Ice_Permafrost",
      "rotation": 2
    },
    {
      "x": -5,
      "y": 2,
      "z": 5,
      "name": "Rock_Ice_Permafrost",
      "rotation": 2
    },
    {
      "x": -5,
      "y": 3,
      "z": 5,
      "name": "Rock_Ice_Permafrost",
      "rotation": 2
    },
    {
      "x": -5,
      "y": 4,
      "z": 5,
      "name": "Rock_Ice_Permafrost",
      "rotation": 2
    },
    {
      "x": -5,
      "y": 5,
      "z": 5,
      "name": "Rock_Ice_Permafrost",
      "rotation": 2
    },
    {
      "x": -5,
      "y": 6,
      "z": 5,
      "name": "Rock_Ice_Permafrost",
      "rotation": 2
    },
    {
      "x": -5,
      "y": 7,
      "z": 5,
      "name": "Rock_Ice_Permafrost",
      "rotation": 2
    },
    {
      "x": -5,
      "y": 8,
      "z": 5,
      "name": "Rock_Ice_Permafrost",
      "rotation": 2
    },
    {
      "x": -5,
      "y": 9,
      "z": 5,
      "name": "Rock_Ice_Permafrost",
      "rotation": 2
    },
    {
      "x": -5,
      "y": 10,
      "z": 5,
      "name": "Rock_Ice_Permafrost",
      "rotation": 2
    },
    {
      "x": -5,
      "y": 11,
      "z": 5,
      "name": "Rock_Ice_Permafrost",
      "rotation": 2
    },
    {
      "x": -5,
      "y": 12,
      "z": 5,
      "name": "Rock_Ice_Permafrost",
      "rotation": 2
    },
    {
      "x": -5,
      "y": 13,
      "z": 5,
      "name": "Rubble_Ice",
      "support": 15,
      "rotation": 2
    },
    {
      "x": -5,
      "y": 0,
      "z": 6,
      "name": "Rock_Ice_Permafrost",
      "rotation": 2
    },
    {
      "x": -5,
      "y": 1,
      "z": 6,
      "name": "Rock_Ice_Permafrost",
      "rotation": 2
    },
    {
      "x": -5,
      "y": 2,
      "z": 6,
      "name": "Rock_Ice_Permafrost",
      "rotation": 2
    },
    {
      "x": -5,
      "y": 3,
      "z": 6,
      "name": "Rock_Ice_Permafrost",
      "rotation": 2
    },
    {
      "x": -5,
      "y": 4,
      "z": 6,
      "name": "Rock_Ice_Permafrost",
      "rotation": 2
    },
    {
      "x": -5,
      "y": 5,
      "z": 6,
      "name": "Rock_Ice_Permafrost",
      "rotation": 2
    },
    {
      "x": -5,
      "y": 6,
      "z": 6,
      "name": "Rock_Ice_Permafrost",
      "rotation": 2
    },
    {
      "x": -5,
      "y": 7,
      "z": 6,
      "name": "Rock_Ice_Permafrost",
      "rotation": 2
    },
    {
      "x": -5,
      "y": 8,
      "z": 6,
      "name": "Rock_Ice_Permafrost",
      "rotation": 2
    },
    {
      "x": -5,
      "y": 9,
      "z": 6,
      "name": "Rock_Ice_Permafrost",
      "rotation": 2
    },
    {
      "x": -5,
      "y": 10,
      "z": 6,
      "name": "Rock_Ice_Permafrost",
      "rotation": 2
    },
    {
      "x": -5,
      "y": 11,
      "z": 6,
      "name": "Rock_Ice_Permafrost",
      "rotation": 2
    },
    {
      "x": -5,
      "y": 12,
      "z": 6,
      "name": "Rock_Ice_Permafrost",
      "rotation": 2
    },
    {
      "x": -5,
      "y": 13,
      "z": 6,
      "name": "Rock_Ice_Permafrost",
      "rotation": 2
    },
    {
      "x": -5,
      "y": 14,
      "z": 6,
      "name": "Rock_Ice_Permafrost",
      "rotation": 2
    },
    {
      "x": -5,
      "y": 15,
      "z": 6,
      "name": "Rock_Ice_Icicles",
      "rotation": 2
    },
    {
      "x": -5,
      "y": 0,
      "z": 7,
      "name": "Rock_Ice_Permafrost",
      "rotation": 2
    },
    {
      "x": -5,
      "y": 1,
      "z": 7,
      "name": "Rock_Ice_Permafrost",
      "rotation": 2
    },
    {
      "x": -5,
      "y": 2,
      "z": 7,
      "name": "Rock_Ice_Permafrost",
      "rotation": 2
    },
    {
      "x": -5,
      "y": 3,
      "z": 7,
      "name": "Rock_Ice_Permafrost",
      "rotation": 2
    },
    {
      "x": -5,
      "y": 4,
      "z": 7,
      "name": "Rock_Ice_Permafrost",
      "rotation": 2
    },
    {
      "x": -5,
      "y": 5,
      "z": 7,
      "name": "Rock_Ice_Permafrost",
      "rotation": 2
    },
    {
      "x": -5,
      "y": 6,
      "z": 7,
      "name": "Rock_Ice_Permafrost",
      "rotation": 2
    },
    {
      "x": -5,
      "y": 7,
      "z": 7,
      "name": "Rock_Ice_Permafrost",
      "rotation": 2
    },
    {
      "x": -5,
      "y": 8,
      "z": 7,
      "name": "Rock_Ice_Permafrost",
      "rotation": 2
    },
    {
      "x": -5,
      "y": 9,
      "z": 7,
      "name": "Rock_Ice_Permafrost",
      "rotation": 2
    },
    {
      "x": -5,
      "y": 10,
      "z": 7,
      "name": "Rock_Ice_Permafrost",
      "rotation": 2
    },
    {
      "x": -5,
      "y": 11,
      "z": 7,
      "name": "Rock_Ice_Permafrost",
      "rotation": 2
    },
    {
      "x": -5,
      "y": 12,
      "z": 7,
      "name": "Rock_Ice_Permafrost",
      "rotation": 2
    },
    {
      "x": -5,
      "y": 13,
      "z": 7,
      "name": "Rock_Ice_Permafrost",
      "rotation": 2
    },
    {
      "x": -5,
      "y": 14,
      "z": 7,
      "name": "Rock_Ice_Permafrost",
      "rotation": 2
    },
    {
      "x": -5,
      "y": 15,
      "z": 7,
      "name": "Rock_Ice_Permafrost",
      "rotation": 2
    },
    {
      "x": -5,
      "y": 16,
      "z": 7,
      "name": "Rock_Ice_Permafrost",
      "rotation": 2
    },
    {
      "x": -5,
      "y": 17,
      "z": 7,
      "name": "Rubble_Ice_Medium",
      "support": 15,
      "rotation": 2
    },
    {
      "x": -5,
      "y": 0,
      "z": 8,
      "name": "Rock_Ice_Permafrost",
      "rotation": 2
    },
    {
      "x": -5,
      "y": 1,
      "z": 8,
      "name": "Rock_Ice_Permafrost",
      "rotation": 2
    },
    {
      "x": -5,
      "y": 2,
      "z": 8,
      "name": "Rock_Ice_Permafrost",
      "rotation": 2
    },
    {
      "x": -5,
      "y": 3,
      "z": 8,
      "name": "Rock_Ice_Permafrost",
      "rotation": 2
    },
    {
      "x": -5,
      "y": 4,
      "z": 8,
      "name": "Rock_Ice_Permafrost",
      "rotation": 2
    },
    {
      "x": -5,
      "y": 5,
      "z": 8,
      "name": "Rock_Ice_Permafrost",
      "rotation": 2
    },
    {
      "x": -5,
      "y": 6,
      "z": 8,
      "name": "Rock_Ice_Permafrost",
      "rotation": 2
    },
    {
      "x": -5,
      "y": 7,
      "z": 8,
      "name": "Rock_Ice_Permafrost",
      "rotation": 2
    },
    {
      "x": -5,
      "y": 8,
      "z": 8,
      "name": "Rock_Ice_Permafrost",
      "rotation": 2
    },
    {
      "x": -5,
      "y": 9,
      "z": 8,
      "name": "Rock_Ice_Permafrost",
      "rotation": 2
    },
    {
      "x": -5,
      "y": 10,
      "z": 8,
      "name": "Rock_Ice_Permafrost",
      "rotation": 2
    },
    {
      "x": -5,
      "y": 11,
      "z": 8,
      "name": "Rock_Ice_Permafrost",
      "rotation": 2
    },
    {
      "x": -5,
      "y": 12,
      "z": 8,
      "name": "Rock_Ice_Permafrost",
      "rotation": 2
    },
    {
      "x": -5,
      "y": 13,
      "z": 8,
      "name": "Rock_Ice_Permafrost",
      "rotation": 2
    },
    {
      "x": -5,
      "y": 14,
      "z": 8,
      "name": "Rock_Ice_Permafrost",
      "rotation": 2
    },
    {
      "x": -5,
      "y": 15,
      "z": 8,
      "name": "Rock_Ice_Permafrost",
      "rotation": 2
    },
    {
      "x": -5,
      "y": 16,
      "z": 8,
      "name": "Rock_Ice_Permafrost",
      "rotation": 2
    },
    {
      "x": -5,
      "y": 17,
      "z": 8,
      "name": "Rock_Ice_Permafrost",
      "rotation": 2
    },
    {
      "x": -5,
      "y": 0,
      "z": 9,
      "name": "Rock_Ice_Permafrost",
      "rotation": 2
    },
    {
      "x": -5,
      "y": 1,
      "z": 9,
      "name": "Rock_Ice_Permafrost",
      "rotation": 2
    },
    {
      "x": -5,
      "y": 2,
      "z": 9,
      "name": "Rock_Ice_Permafrost",
      "rotation": 2
    },
    {
      "x": -5,
      "y": 3,
      "z": 9,
      "name": "Rock_Ice_Permafrost",
      "rotation": 2
    },
    {
      "x": -5,
      "y": 4,
      "z": 9,
      "name": "Rock_Ice_Permafrost",
      "rotation": 2
    },
    {
      "x": -5,
      "y": 5,
      "z": 9,
      "name": "Rock_Ice_Permafrost",
      "rotation": 2
    },
    {
      "x": -5,
      "y": 6,
      "z": 9,
      "name": "Rock_Crystal_Cyan_Large",
      "rotation": 2
    },
    {
      "x": -5,
      "y": 13,
      "z": 9,
      "name": "Rock_Ice_Icicles",
      "rotation": 10
    },
    {
      "x": -5,
      "y": 14,
      "z": 9,
      "name": "Rock_Ice_Permafrost",
      "rotation": 2
    },
    {
      "x": -5,
      "y": 15,
      "z": 9,
      "name": "Rock_Ice_Permafrost",
      "rotation": 2
    },
    {
      "x": -5,
      "y": 16,
      "z": 9,
      "name": "Rock_Ice_Permafrost",
      "rotation": 2
    },
    {
      "x": -5,
      "y": 17,
      "z": 9,
      "name": "Rock_Ice_Permafrost",
      "rotation": 2
    },
    {
      "x": -5,
      "y": 18,
      "z": 9,
      "name": "Rock_Ice_Permafrost",
      "rotation": 2
    },
    {
      "x": -5,
      "y": 15,
      "z": 10,
      "name": "Rock_Ice_Icicles",
      "rotation": 10
    },
    {
      "x": -5,
      "y": 16,
      "z": 10,
      "name": "Rock_Ice_Permafrost",
      "rotation": 2
    },
    {
      "x": -5,
      "y": 17,
      "z": 10,
      "name": "Rock_Ice_Permafrost",
      "rotation": 2
    },
    {
      "x": -5,
      "y": 18,
      "z": 10,
      "name": "Rock_Ice_Permafrost",
      "rotation": 2
    },
    {
      "x": -5,
      "y": 19,
      "z": 10,
      "name": "Rock_Ice_Permafrost",
      "rotation": 2
    },
    {
      "x": -5,
      "y": 20,
      "z": 10,
      "name": "Rock_Ice_Stalactite_Large",
      "rotation": 2
    },
    {
      "x": -5,
      "y": 21,
      "z": 10,
      "name": "Rock_Ice_Stalactite_Large",
      "filler": 1024,
      "rotation": 2
    },
    {
      "x": -4,
      "y": 3,
      "z": -10,
      "name": "Rock_Ice_Permafrost"
    },
    {
      "x": -4,
      "y": 3,
      "z": -9,
      "name": "Rock_Ice_Permafrost"
    },
    {
      "x": -4,
      "y": 4,
      "z": -9,
      "name": "Rock_Ice_Permafrost"
    },
    {
      "x": -4,
      "y": 5,
      "z": -9,
      "name": "Rock_Ice_Permafrost"
    },
    {
      "x": -4,
      "y": 3,
      "z": -8,
      "name": "Rock_Ice_Permafrost"
    },
    {
      "x": -4,
      "y": 4,
      "z": -8,
      "name": "Rock_Ice_Permafrost"
    },
    {
      "x": -4,
      "y": 5,
      "z": -8,
      "name": "Rock_Ice_Permafrost"
    },
    {
      "x": -4,
      "y": 6,
      "z": -8,
      "name": "Rock_Ice_Permafrost"
    },
    {
      "x": -4,
      "y": 7,
      "z": -8,
      "name": "Rock_Ice_Permafrost"
    },
    {
      "x": -4,
      "y": 8,
      "z": -8,
      "name": "Rock_Ice_Stalactite_Large"
    },
    {
      "x": -4,
      "y": 9,
      "z": -8,
      "name": "Rock_Ice_Stalactite_Large",
      "filler": 1024
    },
    {
      "x": -4,
      "y": 11,
      "z": -8,
      "name": "Rock_Ice_Permafrost"
    },
    {
      "x": -4,
      "y": 12,
      "z": -8,
      "name": "Rock_Ice_Permafrost"
    },
    {
      "x": -4,
      "y": 13,
      "z": -8,
      "name": "Rock_Ice_Permafrost"
    },
    {
      "x": -4,
      "y": 14,
      "z": -8,
      "name": "Rock_Ice_Permafrost"
    },
    {
      "x": -4,
      "y": 15,
      "z": -8,
      "name": "Rock_Ice_Permafrost"
    },
    {
      "x": -4,
      "y": 16,
      "z": -8,
      "name": "Rock_Ice_Permafrost"
    },
    {
      "x": -4,
      "y": 17,
      "z": -8,
      "name": "Rock_Ice_Permafrost"
    },
    {
      "x": -4,
      "y": 18,
      "z": -8,
      "name": "Rock_Ice_Permafrost"
    },
    {
      "x": -4,
      "y": 19,
      "z": -8,
      "name": "Rock_Ice_Permafrost"
    },
    {
      "x": -4,
      "y": 20,
      "z": -8,
      "name": "Rock_Ice_Permafrost"
    },
    {
      "x": -4,
      "y": 21,
      "z": -8,
      "name": "Rock_Ice_Permafrost"
    },
    {
      "x": -4,
      "y": 22,
      "z": -8,
      "name": "Rock_Ice_Stalactite_Large"
    },
    {
      "x": -4,
      "y": 23,
      "z": -8,
      "name": "Rock_Ice_Stalactite_Large",
      "filler": 1024
    },
    {
      "x": -4,
      "y": 3,
      "z": -7,
      "name": "Rock_Ice_Permafrost"
    },
    {
      "x": -4,
      "y": 4,
      "z": -7,
      "name": "Rock_Ice_Permafrost"
    },
    {
      "x": -4,
      "y": 5,
      "z": -7,
      "name": "Rock_Ice_Permafrost"
    },
    {
      "x": -4,
      "y": 6,
      "z": -7,
      "name": "Rock_Ice_Permafrost"
    },
    {
      "x": -4,
      "y": 7,
      "z": -7,
      "name": "Rock_Ice_Permafrost"
    },
    {
      "x": -4,
      "y": 8,
      "z": -7,
      "name": "Rock_Ice_Permafrost"
    },
    {
      "x": -4,
      "y": 9,
      "z": -7,
      "name": "Rock_Ice_Permafrost"
    },
    {
      "x": -4,
      "y": 10,
      "z": -7,
      "name": "Rock_Ice_Permafrost"
    },
    {
      "x": -4,
      "y": 11,
      "z": -7,
      "name": "Rock_Ice_Permafrost"
    },
    {
      "x": -4,
      "y": 12,
      "z": -7,
      "name": "Rock_Ice_Permafrost"
    },
    {
      "x": -4,
      "y": 13,
      "z": -7,
      "name": "Rock_Ice_Permafrost"
    },
    {
      "x": -4,
      "y": 14,
      "z": -7,
      "name": "Rock_Ice_Permafrost"
    },
    {
      "x": -4,
      "y": 15,
      "z": -7,
      "name": "Rock_Ice_Permafrost"
    },
    {
      "x": -4,
      "y": 16,
      "z": -7,
      "name": "Rock_Ice_Permafrost"
    },
    {
      "x": -4,
      "y": 17,
      "z": -7,
      "name": "Rock_Ice_Permafrost"
    },
    {
      "x": -4,
      "y": 18,
      "z": -7,
      "name": "Rock_Ice_Permafrost"
    },
    {
      "x": -4,
      "y": 19,
      "z": -7,
      "name": "Rock_Ice_Permafrost"
    },
    {
      "x": -4,
      "y": 20,
      "z": -7,
      "name": "Rock_Ice_Permafrost"
    },
    {
      "x": -4,
      "y": 21,
      "z": -7,
      "name": "Rock_Ice_Permafrost"
    },
    {
      "x": -4,
      "y": 22,
      "z": -7,
      "name": "Rock_Ice_Permafrost"
    },
    {
      "x": -4,
      "y": 23,
      "z": -7,
      "name": "Rock_Ice_Permafrost"
    },
    {
      "x": -4,
      "y": 24,
      "z": -7,
      "name": "Rock_Ice_Stalactite_Large"
    },
    {
      "x": -4,
      "y": 25,
      "z": -7,
      "name": "Rock_Ice_Stalactite_Large",
      "filler": 1024
    },
    {
      "x": -4,
      "y": 3,
      "z": -6,
      "name": "Rock_Ice_Permafrost"
    },
    {
      "x": -4,
      "y": 4,
      "z": -6,
      "name": "Rock_Ice_Permafrost"
    },
    {
      "x": -4,
      "y": 5,
      "z": -6,
      "name": "Rock_Ice_Permafrost"
    },
    {
      "x": -4,
      "y": 6,
      "z": -6,
      "name": "Rock_Ice_Permafrost"
    },
    {
      "x": -4,
      "y": 7,
      "z": -6,
      "name": "Rock_Ice_Permafrost"
    },
    {
      "x": -4,
      "y": 8,
      "z": -6,
      "name": "Rock_Ice_Permafrost"
    },
    {
      "x": -4,
      "y": 9,
      "z": -6,
      "name": "Rock_Ice_Permafrost"
    },
    {
      "x": -4,
      "y": 10,
      "z": -6,
      "name": "Rock_Ice_Permafrost"
    },
    {
      "x": -4,
      "y": 11,
      "z": -6,
      "name": "Rock_Ice_Permafrost"
    },
    {
      "x": -4,
      "y": 12,
      "z": -6,
      "name": "Rock_Ice_Permafrost"
    },
    {
      "x": -4,
      "y": 13,
      "z": -6,
      "name": "Rock_Ice_Permafrost"
    },
    {
      "x": -4,
      "y": 14,
      "z": -6,
      "name": "Rock_Ice_Permafrost"
    },
    {
      "x": -4,
      "y": 15,
      "z": -6,
      "name": "Rock_Ice_Permafrost"
    },
    {
      "x": -4,
      "y": 16,
      "z": -6,
      "name": "Rock_Ice_Permafrost"
    },
    {
      "x": -4,
      "y": 17,
      "z": -6,
      "name": "Rock_Ice_Permafrost"
    },
    {
      "x": -4,
      "y": 18,
      "z": -6,
      "name": "Rock_Ice_Permafrost"
    },
    {
      "x": -4,
      "y": 19,
      "z": -6,
      "name": "Rock_Ice_Permafrost"
    },
    {
      "x": -4,
      "y": 20,
      "z": -6,
      "name": "Rock_Ice_Permafrost"
    },
    {
      "x": -4,
      "y": 21,
      "z": -6,
      "name": "Rock_Ice_Permafrost"
    },
    {
      "x": -4,
      "y": 22,
      "z": -6,
      "name": "Rock_Ice_Permafrost"
    },
    {
      "x": -4,
      "y": 0,
      "z": -5,
      "name": "Rock_Ice_Permafrost"
    },
    {
      "x": -4,
      "y": 1,
      "z": -5,
      "name": "Rock_Ice_Icicles"
    },
    {
      "x": -4,
      "y": 3,
      "z": -5,
      "name": "Rock_Ice_Permafrost"
    },
    {
      "x": -4,
      "y": 4,
      "z": -5,
      "name": "Rock_Ice_Permafrost"
    },
    {
      "x": -4,
      "y": 5,
      "z": -5,
      "name": "Rock_Ice_Permafrost"
    },
    {
      "x": -4,
      "y": 6,
      "z": -5,
      "name": "Rock_Ice_Permafrost"
    },
    {
      "x": -4,
      "y": 7,
      "z": -5,
      "name": "Rock_Ice_Permafrost"
    },
    {
      "x": -4,
      "y": 8,
      "z": -5,
      "name": "Rock_Ice_Permafrost"
    },
    {
      "x": -4,
      "y": 9,
      "z": -5,
      "name": "Rock_Ice_Permafrost"
    },
    {
      "x": -4,
      "y": 10,
      "z": -5,
      "name": "Rock_Ice_Permafrost"
    },
    {
      "x": -4,
      "y": 11,
      "z": -5,
      "name": "Rock_Ice_Permafrost"
    },
    {
      "x": -4,
      "y": 12,
      "z": -5,
      "name": "Rock_Ice_Permafrost"
    },
    {
      "x": -4,
      "y": 13,
      "z": -5,
      "name": "Rock_Ice_Permafrost"
    },
    {
      "x": -4,
      "y": 14,
      "z": -5,
      "name": "Rock_Ice_Permafrost"
    },
    {
      "x": -4,
      "y": 15,
      "z": -5,
      "name": "Rock_Ice_Permafrost"
    },
    {
      "x": -4,
      "y": 16,
      "z": -5,
      "name": "Rock_Ice_Permafrost"
    },
    {
      "x": -4,
      "y": 17,
      "z": -5,
      "name": "Rock_Ice_Permafrost"
    },
    {
      "x": -4,
      "y": 18,
      "z": -5,
      "name": "Rock_Ice_Permafrost"
    },
    {
      "x": -4,
      "y": 19,
      "z": -5,
      "name": "Rock_Ice_Permafrost"
    },
    {
      "x": -4,
      "y": 20,
      "z": -5,
      "name": "Rock_Ice_Permafrost"
    },
    {
      "x": -4,
      "y": 21,
      "z": -5,
      "name": "Rock_Ice_Permafrost"
    },
    {
      "x": -4,
      "y": 22,
      "z": -5,
      "name": "Rock_Crystal_Cyan_Medium",
      "rotation": 7
    },
    {
      "x": -4,
      "y": 0,
      "z": -4,
      "name": "Rock_Ice_Permafrost"
    },
    {
      "x": -4,
      "y": 1,
      "z": -4,
      "name": "Rock_Ice_Permafrost"
    },
    {
      "x": -4,
      "y": 2,
      "z": -4,
      "name": "Rock_Ice_Permafrost"
    },
    {
      "x": -4,
      "y": 3,
      "z": -4,
      "name": "Rock_Ice_Permafrost"
    },
    {
      "x": -4,
      "y": 4,
      "z": -4,
      "name": "Rock_Ice_Permafrost"
    },
    {
      "x": -4,
      "y": 5,
      "z": -4,
      "name": "Rock_Ice_Permafrost"
    },
    {
      "x": -4,
      "y": 6,
      "z": -4,
      "name": "Rock_Ice_Permafrost"
    },
    {
      "x": -4,
      "y": 7,
      "z": -4,
      "name": "Rock_Ice_Permafrost"
    },
    {
      "x": -4,
      "y": 8,
      "z": -4,
      "name": "Rock_Ice_Permafrost"
    },
    {
      "x": -4,
      "y": 9,
      "z": -4,
      "name": "Rock_Ice_Permafrost"
    },
    {
      "x": -4,
      "y": 10,
      "z": -4,
      "name": "Rock_Ice_Permafrost"
    },
    {
      "x": -4,
      "y": 11,
      "z": -4,
      "name": "Rock_Ice_Permafrost"
    },
    {
      "x": -4,
      "y": 12,
      "z": -4,
      "name": "Rock_Ice_Permafrost"
    },
    {
      "x": -4,
      "y": 13,
      "z": -4,
      "name": "Rock_Ice_Permafrost"
    },
    {
      "x": -4,
      "y": 14,
      "z": -4,
      "name": "Rock_Ice_Permafrost"
    },
    {
      "x": -4,
      "y": 15,
      "z": -4,
      "name": "Rock_Ice_Permafrost"
    },
    {
      "x": -4,
      "y": 16,
      "z": -4,
      "name": "Rock_Ice_Permafrost"
    },
    {
      "x": -4,
      "y": 17,
      "z": -4,
      "name": "Rock_Ice_Permafrost"
    },
    {
      "x": -4,
      "y": 18,
      "z": -4,
      "name": "Rock_Ice_Permafrost"
    },
    {
      "x": -4,
      "y": 19,
      "z": -4,
      "name": "Rock_Ice_Permafrost"
    },
    {
      "x": -4,
      "y": 20,
      "z": -4,
      "name": "Rock_Ice_Stalactite_Large"
    },
    {
      "x": -4,
      "y": 21,
      "z": -4,
      "name": "Rock_Ice_Stalactite_Large",
      "filler": 1024
    },
    {
      "x": -4,
      "y": 0,
      "z": -3,
      "name": "Rock_Ice_Permafrost"
    },
    {
      "x": -4,
      "y": 1,
      "z": -3,
      "name": "Rock_Ice_Permafrost"
    },
    {
      "x": -4,
      "y": 2,
      "z": -3,
      "name": "Rock_Ice_Permafrost"
    },
    {
      "x": -4,
      "y": 3,
      "z": -3,
      "name": "Rock_Ice_Permafrost"
    },
    {
      "x": -4,
      "y": 4,
      "z": -3,
      "name": "Rock_Ice_Permafrost"
    },
    {
      "x": -4,
      "y": 5,
      "z": -3,
      "name": "Rock_Ice_Permafrost"
    },
    {
      "x": -4,
      "y": 6,
      "z": -3,
      "name": "Rock_Ice_Permafrost"
    },
    {
      "x": -4,
      "y": 7,
      "z": -3,
      "name": "Rock_Ice_Permafrost"
    },
    {
      "x": -4,
      "y": 8,
      "z": -3,
      "name": "Rock_Ice_Permafrost"
    },
    {
      "x": -4,
      "y": 9,
      "z": -3,
      "name": "Rock_Ice_Permafrost"
    },
    {
      "x": -4,
      "y": 10,
      "z": -3,
      "name": "Rock_Ice_Permafrost"
    },
    {
      "x": -4,
      "y": 11,
      "z": -3,
      "name": "Rock_Ice_Permafrost"
    },
    {
      "x": -4,
      "y": 12,
      "z": -3,
      "name": "Rock_Ice_Permafrost"
    },
    {
      "x": -4,
      "y": 13,
      "z": -3,
      "name": "Rock_Ice_Permafrost"
    },
    {
      "x": -4,
      "y": 14,
      "z": -3,
      "name": "Rock_Ice_Permafrost"
    },
    {
      "x": -4,
      "y": 15,
      "z": -3,
      "name": "Rock_Ice_Permafrost"
    },
    {
      "x": -4,
      "y": 16,
      "z": -3,
      "name": "Rock_Ice_Permafrost"
    },
    {
      "x": -4,
      "y": 17,
      "z": -3,
      "name": "Rock_Ice_Permafrost"
    },
    {
      "x": -4,
      "y": 0,
      "z": -2,
      "name": "Rock_Ice_Permafrost"
    },
    {
      "x": -4,
      "y": 1,
      "z": -2,
      "name": "Rock_Ice_Permafrost"
    },
    {
      "x": -4,
      "y": 2,
      "z": -2,
      "name": "Rock_Ice_Permafrost"
    },
    {
      "x": -4,
      "y": 3,
      "z": -2,
      "name": "Rock_Ice_Permafrost"
    },
    {
      "x": -4,
      "y": 4,
      "z": -2,
      "name": "Rock_Ice_Permafrost"
    },
    {
      "x": -4,
      "y": 5,
      "z": -2,
      "name": "Rock_Ice_Permafrost"
    },
    {
      "x": -4,
      "y": 6,
      "z": -2,
      "name": "Rock_Ice_Permafrost"
    },
    {
      "x": -4,
      "y": 7,
      "z": -2,
      "name": "Rock_Ice_Permafrost"
    },
    {
      "x": -4,
      "y": 8,
      "z": -2,
      "name": "Rock_Ice_Permafrost"
    },
    {
      "x": -4,
      "y": 9,
      "z": -2,
      "name": "Rock_Ice_Permafrost"
    },
    {
      "x": -4,
      "y": 10,
      "z": -2,
      "name": "Rock_Ice_Permafrost"
    },
    {
      "x": -4,
      "y": 11,
      "z": -2,
      "name": "Rock_Ice_Permafrost"
    },
    {
      "x": -4,
      "y": 12,
      "z": -2,
      "name": "Rock_Ice_Permafrost"
    },
    {
      "x": -4,
      "y": 13,
      "z": -2,
      "name": "Rock_Ice_Permafrost"
    },
    {
      "x": -4,
      "y": 14,
      "z": -2,
      "name": "Rock_Ice_Permafrost"
    },
    {
      "x": -4,
      "y": 15,
      "z": -2,
      "name": "Rock_Ice_Permafrost"
    },
    {
      "x": -4,
      "y": 0,
      "z": -1,
      "name": "Rock_Ice_Permafrost",
      "rotation": 2
    },
    {
      "x": -4,
      "y": 1,
      "z": -1,
      "name": "Rock_Ice_Permafrost",
      "rotation": 2
    },
    {
      "x": -4,
      "y": 2,
      "z": -1,
      "name": "Rock_Ice_Permafrost",
      "rotation": 2
    },
    {
      "x": -4,
      "y": 3,
      "z": -1,
      "name": "Rock_Ice_Permafrost",
      "rotation": 2
    },
    {
      "x": -4,
      "y": 4,
      "z": -1,
      "name": "Rock_Ice_Permafrost",
      "rotation": 2
    },
    {
      "x": -4,
      "y": 5,
      "z": -1,
      "name": "Rock_Ice_Stalactite_Large",
      "rotation": 2
    },
    {
      "x": -4,
      "y": 6,
      "z": -1,
      "name": "Rock_Ice_Stalactite_Large",
      "filler": 1024,
      "rotation": 2
    },
    {
      "x": -4,
      "y": 7,
      "z": -1,
      "name": "Rock_Ice_Permafrost"
    },
    {
      "x": -4,
      "y": 8,
      "z": -1,
      "name": "Rock_Ice_Permafrost"
    },
    {
      "x": -4,
      "y": 9,
      "z": -1,
      "name": "Rock_Ice_Permafrost"
    },
    {
      "x": -4,
      "y": 10,
      "z": -1,
      "name": "Rock_Ice_Permafrost"
    },
    {
      "x": -4,
      "y": 11,
      "z": -1,
      "name": "Rock_Ice_Permafrost"
    },
    {
      "x": -4,
      "y": 12,
      "z": -1,
      "name": "Rock_Ice_Permafrost"
    },
    {
      "x": -4,
      "y": 13,
      "z": -1,
      "name": "Rock_Ice_Permafrost"
    },
    {
      "x": -4,
      "y": 14,
      "z": -1,
      "name": "Rock_Crystal_Cyan_Medium"
    },
    {
      "x": -4,
      "y": 0,
      "z": 0,
      "name": "Rock_Ice_Permafrost",
      "rotation": 2
    },
    {
      "x": -4,
      "y": 1,
      "z": 0,
      "name": "Rock_Ice_Permafrost",
      "rotation": 2
    },
    {
      "x": -4,
      "y": 2,
      "z": 0,
      "name": "Rock_Ice_Permafrost",
      "rotation": 2
    },
    {
      "x": -4,
      "y": 3,
      "z": 0,
      "name": "Rock_Ice_Permafrost",
      "rotation": 2
    },
    {
      "x": -4,
      "y": 4,
      "z": 0,
      "name": "Rock_Ice_Permafrost",
      "rotation": 2
    },
    {
      "x": -4,
      "y": 5,
      "z": 0,
      "name": "Rock_Ice_Permafrost",
      "rotation": 2
    },
    {
      "x": -4,
      "y": 6,
      "z": 0,
      "name": "Rock_Ice_Permafrost",
      "rotation": 2
    },
    {
      "x": -4,
      "y": 7,
      "z": 0,
      "name": "Rock_Ice_Permafrost",
      "rotation": 2
    },
    {
      "x": -4,
      "y": 8,
      "z": 0,
      "name": "Rock_Ice_Permafrost"
    },
    {
      "x": -4,
      "y": 9,
      "z": 0,
      "name": "Rock_Ice_Permafrost"
    },
    {
      "x": -4,
      "y": 0,
      "z": 1,
      "name": "Rock_Ice_Permafrost",
      "rotation": 2
    },
    {
      "x": -4,
      "y": 1,
      "z": 1,
      "name": "Rock_Ice_Permafrost",
      "rotation": 2
    },
    {
      "x": -4,
      "y": 2,
      "z": 1,
      "name": "Rock_Ice_Permafrost",
      "rotation": 2
    },
    {
      "x": -4,
      "y": 3,
      "z": 1,
      "name": "Rock_Ice_Permafrost",
      "rotation": 2
    },
    {
      "x": -4,
      "y": 4,
      "z": 1,
      "name": "Rock_Ice_Permafrost",
      "rotation": 2
    },
    {
      "x": -4,
      "y": 5,
      "z": 1,
      "name": "Rock_Ice_Permafrost",
      "rotation": 2
    },
    {
      "x": -4,
      "y": 6,
      "z": 1,
      "name": "Rock_Ice_Permafrost",
      "rotation": 2
    },
    {
      "x": -4,
      "y": 7,
      "z": 1,
      "name": "Rock_Ice_Permafrost",
      "rotation": 2
    },
    {
      "x": -4,
      "y": 8,
      "z": 1,
      "name": "Rock_Ice_Permafrost",
      "rotation": 2
    },
    {
      "x": -4,
      "y": 9,
      "z": 1,
      "name": "Rock_Ice_Icicles",
      "rotation": 2
    },
    {
      "x": -4,
      "y": 0,
      "z": 2,
      "name": "Rock_Ice_Permafrost",
      "rotation": 2
    },
    {
      "x": -4,
      "y": 1,
      "z": 2,
      "name": "Rock_Ice_Permafrost",
      "rotation": 2
    },
    {
      "x": -4,
      "y": 2,
      "z": 2,
      "name": "Rock_Ice_Permafrost",
      "rotation": 2
    },
    {
      "x": -4,
      "y": 3,
      "z": 2,
      "name": "Rock_Ice_Permafrost",
      "rotation": 2
    },
    {
      "x": -4,
      "y": 4,
      "z": 2,
      "name": "Rock_Ice_Permafrost",
      "rotation": 2
    },
    {
      "x": -4,
      "y": 5,
      "z": 2,
      "name": "Rock_Ice_Permafrost",
      "rotation": 2
    },
    {
      "x": -4,
      "y": 6,
      "z": 2,
      "name": "Rock_Ice_Permafrost",
      "rotation": 2
    },
    {
      "x": -4,
      "y": 7,
      "z": 2,
      "name": "Rock_Ice_Permafrost",
      "rotation": 2
    },
    {
      "x": -4,
      "y": 8,
      "z": 2,
      "name": "Rock_Ice_Permafrost",
      "rotation": 2
    },
    {
      "x": -4,
      "y": 9,
      "z": 2,
      "name": "Rock_Ice_Permafrost",
      "rotation": 2
    },
    {
      "x": -4,
      "y": 10,
      "z": 2,
      "name": "Rubble_Ice",
      "support": 15,
      "rotation": 2
    },
    {
      "x": -4,
      "y": 0,
      "z": 3,
      "name": "Rock_Ice_Permafrost",
      "rotation": 2
    },
    {
      "x": -4,
      "y": 1,
      "z": 3,
      "name": "Rock_Ice_Permafrost",
      "rotation": 2
    },
    {
      "x": -4,
      "y": 2,
      "z": 3,
      "name": "Rock_Ice_Permafrost",
      "rotation": 2
    },
    {
      "x": -4,
      "y": 3,
      "z": 3,
      "name": "Rock_Ice_Permafrost",
      "rotation": 2
    },
    {
      "x": -4,
      "y": 4,
      "z": 3,
      "name": "Rock_Ice_Permafrost",
      "rotation": 2
    },
    {
      "x": -4,
      "y": 5,
      "z": 3,
      "name": "Rock_Ice_Permafrost",
      "rotation": 2
    },
    {
      "x": -4,
      "y": 6,
      "z": 3,
      "name": "Rock_Ice_Permafrost",
      "rotation": 2
    },
    {
      "x": -4,
      "y": 7,
      "z": 3,
      "name": "Rock_Ice_Permafrost",
      "rotation": 2
    },
    {
      "x": -4,
      "y": 8,
      "z": 3,
      "name": "Rock_Ice_Permafrost",
      "rotation": 2
    },
    {
      "x": -4,
      "y": 9,
      "z": 3,
      "name": "Rock_Ice_Permafrost",
      "rotation": 2
    },
    {
      "x": -4,
      "y": 10,
      "z": 3,
      "name": "Rock_Crystal_Cyan_Medium",
      "rotation": 2
    },
    {
      "x": -4,
      "y": 0,
      "z": 4,
      "name": "Rock_Ice_Permafrost",
      "rotation": 2
    },
    {
      "x": -4,
      "y": 1,
      "z": 4,
      "name": "Rock_Ice_Permafrost",
      "rotation": 2
    },
    {
      "x": -4,
      "y": 2,
      "z": 4,
      "name": "Rock_Ice_Permafrost",
      "rotation": 2
    },
    {
      "x": -4,
      "y": 3,
      "z": 4,
      "name": "Rock_Ice_Permafrost",
      "rotation": 2
    },
    {
      "x": -4,
      "y": 4,
      "z": 4,
      "name": "Rock_Ice_Permafrost",
      "rotation": 2
    },
    {
      "x": -4,
      "y": 5,
      "z": 4,
      "name": "Rock_Ice_Permafrost",
      "rotation": 2
    },
    {
      "x": -4,
      "y": 6,
      "z": 4,
      "name": "Rock_Ice_Permafrost",
      "rotation": 2
    },
    {
      "x": -4,
      "y": 7,
      "z": 4,
      "name": "Rock_Ice_Permafrost",
      "rotation": 2
    },
    {
      "x": -4,
      "y": 8,
      "z": 4,
      "name": "Rock_Ice_Permafrost",
      "rotation": 2
    },
    {
      "x": -4,
      "y": 9,
      "z": 4,
      "name": "Rock_Ice_Permafrost",
      "rotation": 2
    },
    {
      "x": -4,
      "y": 10,
      "z": 4,
      "name": "Rock_Ice_Permafrost",
      "rotation": 2
    },
    {
      "x": -4,
      "y": 0,
      "z": 5,
      "name": "Rock_Ice_Permafrost",
      "rotation": 2
    },
    {
      "x": -4,
      "y": 1,
      "z": 5,
      "name": "Rock_Ice_Permafrost",
      "rotation": 2
    },
    {
      "x": -4,
