{
  "version": 8,
  "blockIdVersion": 10,
  "anchorX": 0,
  "anchorY": 0,
  "anchorZ": 0,
  "blocks": [
    {
      "x": -13,
      "y": 0,
      "z": 1,
      "name": "Rock_Volcanic"
    },
    {
      "x": -12,
      "y": 0,
      "z": -5,
      "name": "Rock_Volcanic"
    },
    {
      "x": -12,
      "y": 0,
      "z": 1,
      "name": "Rock_Volcanic"
    },
    {
      "x": -12,
      "y": 0,
      "z": 2,
      "name": "Rock_Volcanic"
    },
    {
      "x": -11,
      "y": 0,
      "z": -5,
      "name": "Rock_Volcanic"
    },
    {
      "x": -11,
      "y": 0,
      "z": -4,
      "name": "Rock_Volcanic"
    },
    {
      "x": -11,
      "y": 0,
      "z": 1,
      "name": "Rock_Volcanic"
    },
    {
      "x": -11,
      "y": 0,
      "z": 2,
      "name": "Rock_Volcanic"
    },
    {
      "x": -11,
      "y": 0,
      "z": 12,
      "name": "Rock_Volcanic"
    },
    {
      "x": -10,
      "y": 0,
      "z": -5,
      "name": "Rock_Volcanic"
    },
    {
      "x": -10,
      "y": 0,
      "z": -4,
      "name": "Rock_Volcanic"
    },
    {
      "x": -10,
      "y": 0,
      "z": 1,
      "name": "Rock_Volcanic"
    },
    {
      "x": -10,
      "y": 0,
      "z": 2,
      "name": "Rock_Volcanic"
    },
    {
      "x": -10,
      "y": 0,
      "z": 3,
      "name": "Rock_Volcanic"
    },
    {
      "x": -10,
      "y": 0,
      "z": 11,
      "name": "Rock_Volcanic"
    },
    {
      "x": -10,
      "y": 0,
      "z": 12,
      "name": "Rock_Volcanic"
    },
    {
      "x": -10,
      "y": 0,
      "z": 13,
      "name": "Rock_Volcanic"
    },
    {
      "x": -9,
      "y": 0,
      "z": -6,
      "name": "Rock_Volcanic"
    },
    {
      "x": -9,
      "y": 0,
      "z": -5,
      "name": "Rock_Volcanic"
    },
    {
      "x": -9,
      "y": 0,
      "z": -4,
      "name": "Rock_Volcanic"
    },
    {
      "x": -9,
      "y": 0,
      "z": -1,
      "name": "Rock_Volcanic"
    },
    {
      "x": -9,
      "y": 0,
      "z": 0,
      "name": "Rock_Volcanic"
    },
    {
      "x": -9,
      "y": 0,
      "z": 1,
      "name": "Rock_Volcanic"
    },
    {
      "x": -9,
      "y": 0,
      "z": 2,
      "name": "Rock_Volcanic"
    },
    {
      "x": -9,
      "y": 0,
      "z": 3,
      "name": "Rock_Volcanic"
    },
    {
      "x": -9,
      "y": 0,
      "z": 4,
      "name": "Rock_Volcanic"
    },
    {
      "x": -9,
      "y": 0,
      "z": 9,
      "name": "Rock_Volcanic"
    },
    {
      "x": -9,
      "y": 0,
      "z": 10,
      "name": "Rock_Volcanic"
    },
    {
      "x": -9,
      "y": 0,
      "z": 11,
      "name": "Rock_Volcanic"
    },
    {
      "x": -9,
      "y": 0,
      "z": 12,
      "name": "Rock_Volcanic"
    },
    {
      "x": -8,
      "y": 0,
      "z": -6,
      "name": "Rock_Volcanic"
    },
    {
      "x": -8,
      "y": 0,
      "z": -5,
      "name": "Rock_Volcanic"
    },
    {
      "x": -8,
      "y": 0,
      "z": -4,
      "name": "Rock_Volcanic"
    },
    {
      "x": -8,
      "y": 0,
      "z": -3,
      "name": "Rock_Volcanic"
    },
    {
      "x": -8,
      "y": 0,
      "z": -2,
      "name": "Rock_Volcanic"
    },
    {
      "x": -8,
      "y": 0,
      "z": -1,
      "name": "Rock_Volcanic"
    },
    {
      "x": -8,
      "y": 1,
      "z": -1,
      "name": "Rock_Volcanic"
    },
    {
      "x": -8,
      "y": 0,
      "z": 0,
      "name": "Rock_Volcanic"
    },
    {
      "x": -8,
      "y": 1,
      "z": 0,
      "name": "Rock_Volcanic"
    },
    {
      "x": -8,
      "y": 1,
      "z": 1,
      "name": "Rock_Ice_Permafrost"
    },
    {
      "x": -8,
      "y": 2,
      "z": 1,
      "name": "Rock_Ice_Stalactite_Large"
    },
    {
      "x": -8,
      "y": 3,
      "z": 1,
      "name": "Rock_Ice_Stalactite_Large",
      "filler": 1024
    },
    {
      "x": -8,
      "y": 1,
      "z": 2,
      "name": "Rock_Ice_Permafrost"
    },
    {
      "x": -8,
      "y": 0,
      "z": 3,
      "name": "Rock_Volcanic"
    },
    {
      "x": -8,
      "y": 1,
      "z": 3,
      "name": "Rock_Volcanic"
    },
    {
      "x": -8,
      "y": 1,
      "z": 4,
      "name": "Rock_Volcanic"
    },
    {
      "x": -8,
      "y": 0,
      "z": 5,
      "name": "Rock_Volcanic"
    },
    {
      "x": -8,
      "y": 0,
      "z": 6,
      "name": "Rock_Volcanic"
    },
    {
      "x": -8,
      "y": 0,
      "z": 7,
      "name": "Rock_Volcanic"
    },
    {
      "x": -8,
      "y": 0,
      "z": 8,
      "name": "Rock_Volcanic"
    },
    {
      "x": -8,
      "y": 0,
      "z": 9,
      "name": "Rock_Volcanic"
    },
    {
      "x": -8,
      "y": 0,
      "z": 10,
      "name": "Rock_Volcanic"
    },
    {
      "x": -8,
      "y": 0,
      "z": 11,
      "name": "Rock_Volcanic"
    },
    {
      "x": -7,
      "y": 0,
      "z": -12,
      "name": "Rock_Volcanic"
    },
    {
      "x": -7,
      "y": 0,
      "z": -11,
      "name": "Rock_Volcanic"
    },
    {
      "x": -7,
      "y": 0,
      "z": -10,
      "name": "Rock_Volcanic"
    },
    {
      "x": -7,
      "y": 0,
      "z": -6,
      "name": "Rock_Volcanic"
    },
    {
      "x": -7,
      "y": 1,
      "z": -5,
      "name": "Rock_Volcanic"
    },
    {
      "x": -7,
      "y": 0,
      "z": -4,
      "name": "Rock_Volcanic"
    },
    {
      "x": -7,
      "y": 1,
      "z": -4,
      "name": "Rock_Volcanic"
    },
    {
      "x": -7,
      "y": 0,
      "z": -3,
      "name": "Rock_Volcanic"
    },
    {
      "x": -7,
      "y": 1,
      "z": -3,
      "name": "Rock_Volcanic"
    },
    {
      "x": -7,
      "y": 0,
      "z": -2,
      "name": "Rock_Volcanic"
    },
    {
      "x": -7,
      "y": 1,
      "z": -2,
      "name": "Rock_Volcanic"
    },
    {
      "x": -7,
      "y": 0,
      "z": -1,
      "name": "Rock_Volcanic"
    },
    {
      "x": -7,
      "y": 1,
      "z": -1,
      "name": "Rock_Volcanic"
    },
    {
      "x": -7,
      "y": 0,
      "z": 0,
      "name": "Rock_Volcanic"
    },
    {
      "x": -7,
      "y": 1,
      "z": 0,
      "name": "Rock_Ice_Permafrost"
    },
    {
      "x": -7,
      "y": 2,
      "z": 0,
      "name": "Rock_Ice_Icicles"
    },
    {
      "x": -7,
      "y": 0,
      "z": 1,
      "name": "Rock_Volcanic"
    },
    {
      "x": -7,
      "y": 1,
      "z": 1,
      "name": "Rock_Volcanic"
    },
    {
      "x": -7,
      "y": 2,
      "z": 1,
      "name": "Rock_Ice_Permafrost"
    },
    {
      "x": -7,
      "y": 0,
      "z": 2,
      "name": "Rock_Volcanic"
    },
    {
      "x": -7,
      "y": 1,
      "z": 2,
      "name": "Rock_Volcanic"
    },
    {
      "x": -7,
      "y": 2,
      "z": 2,
      "name": "Rock_Ice_Permafrost"
    },
    {
      "x": -7,
      "y": 0,
      "z": 3,
      "name": "Rock_Volcanic"
    },
    {
      "x": -7,
      "y": 1,
      "z": 3,
      "name": "Rock_Volcanic"
    },
    {
      "x": -7,
      "y": 2,
      "z": 3,
      "name": "Rock_Ice_Permafrost"
    },
    {
      "x": -7,
      "y": 3,
      "z": 3,
      "name": "Rock_Ice_Stalactite_Large"
    },
    {
      "x": -7,
      "y": 4,
      "z": 3,
      "name": "Rock_Ice_Stalactite_Large",
      "filler": 1024
    },
    {
      "x": -7,
      "y": 0,
      "z": 4,
      "name": "Rock_Volcanic"
    },
    {
      "x": -7,
      "y": 1,
      "z": 4,
      "name": "Rock_Volcanic"
    },
    {
      "x": -7,
      "y": 2,
      "z": 4,
      "name": "Rock_Volcanic"
    },
    {
      "x": -7,
      "y": 1,
      "z": 5,
      "name": "Rock_Volcanic"
    },
    {
      "x": -7,
      "y": 1,
      "z": 6,
      "name": "Rock_Volcanic"
    },
    {
      "x": -7,
      "y": 0,
      "z": 7,
      "name": "Rock_Volcanic"
    },
    {
      "x": -7,
      "y": 1,
      "z": 7,
      "name": "Rock_Volcanic"
    },
    {
      "x": -7,
      "y": 1,
      "z": 8,
      "name": "Rock_Volcanic"
    },
    {
      "x": -7,
      "y": 2,
      "z": 8,
      "name": "Rubble_Ice",
      "support": 15
    },
    {
      "x": -7,
      "y": 0,
      "z": 9,
      "name": "Rock_Volcanic"
    },
    {
      "x": -7,
      "y": 0,
      "z": 10,
      "name": "Rock_Volcanic"
    },
    {
      "x": -7,
      "y": 0,
      "z": 11,
      "name": "Rock_Volcanic"
    },
    {
      "x": -6,
      "y": 0,
      "z": -11,
      "name": "Rock_Volcanic"
    },
    {
      "x": -6,
      "y": 0,
      "z": -10,
      "name": "Rock_Volcanic"
    },
    {
      "x": -6,
      "y": 0,
      "z": -9,
      "name": "Rock_Volcanic"
    },
    {
      "x": -6,
      "y": 0,
      "z": -7,
      "name": "Rock_Volcanic"
    },
    {
      "x": -6,
      "y": 1,
      "z": -6,
      "name": "Rock_Volcanic"
    },
    {
      "x": -6,
      "y": 0,
      "z": -5,
      "name": "Rock_Volcanic"
    },
    {
      "x": -6,
      "y": 1,
      "z": -5,
      "name": "Rock_Volcanic"
    },
    {
      "x": -6,
      "y": 2,
      "z": -5,
      "name": "Rubble_Ice",
      "support": 15
    },
    {
      "x": -6,
      "y": 0,
      "z": -4,
      "name": "Rock_Volcanic"
    },
    {
      "x": -6,
      "y": 1,
      "z": -4,
      "name": "Rock_Volcanic"
    },
    {
      "x": -6,
      "y": 2,
      "z": -4,
      "name": "Rubble_Ice_Medium",
      "support": 15
    },
    {
      "x": -6,
      "y": 0,
      "z": -3,
      "name": "Rock_Volcanic"
    },
    {
      "x": -6,
      "y": 1,
      "z": -3,
      "name": "Rock_Volcanic"
    },
    {
      "x": -6,
      "y": 2,
      "z": -3,
      "name": "Rock_Volcanic"
    },
    {
      "x": -6,
      "y": 0,
      "z": -2,
      "name": "Rock_Volcanic"
    },
    {
      "x": -6,
      "y": 1,
      "z": -2,
      "name": "Rock_Volcanic"
    },
    {
      "x": -6,
      "y": 2,
      "z": -2,
      "name": "Rock_Volcanic"
    },
    {
      "x": -6,
      "y": 3,
      "z": -2,
      "name": "Rubble_Ice",
      "support": 15
    },
    {
      "x": -6,
      "y": 0,
      "z": -1,
      "name": "Rock_Volcanic"
    },
    {
      "x": -6,
      "y": 1,
      "z": -1,
      "name": "Rock_Volcanic"
    },
    {
      "x": -6,
      "y": 2,
      "z": -1,
      "name": "Rock_Volcanic"
    },
    {
      "x": -6,
      "y": 0,
      "z": 0,
      "name": "Rock_Volcanic"
    },
    {
      "x": -6,
      "y": 1,
      "z": 0,
      "name": "Rock_Volcanic"
    },
    {
      "x": -6,
      "y": 2,
      "z": 0,
      "name": "Rock_Volcanic"
    },
    {
      "x": -6,
      "y": 3,
      "z": 0,
      "name": "Rubble_Ice",
      "support": 15
    },
    {
      "x": -6,
      "y": 0,
      "z": 1,
      "name": "Rock_Volcanic"
    },
    {
      "x": -6,
      "y": 1,
      "z": 1,
      "name": "Rock_Volcanic"
    },
    {
      "x": -6,
      "y": 2,
      "z": 1,
      "name": "Rock_Ice_Permafrost"
    },
    {
      "x": -6,
      "y": 3,
      "z": 1,
      "name": "Rock_Ice_Icicles"
    },
    {
      "x": -6,
      "y": 0,
      "z": 2,
      "name": "Rock_Volcanic"
    },
    {
      "x": -6,
      "y": 1,
      "z": 2,
      "name": "Rock_Volcanic"
    },
    {
      "x": -6,
      "y": 2,
      "z": 2,
      "name": "Rock_Volcanic"
    },
    {
      "x": -6,
      "y": 0,
      "z": 3,
      "name": "Rock_Volcanic"
    },
    {
      "x": -6,
      "y": 1,
      "z": 3,
      "name": "Rock_Volcanic"
    },
    {
      "x": -6,
      "y": 2,
      "z": 3,
      "name": "Rock_Volcanic"
    },
    {
      "x": -6,
      "y": 0,
      "z": 4,
      "name": "Rock_Volcanic"
    },
    {
      "x": -6,
      "y": 1,
      "z": 4,
      "name": "Rock_Volcanic"
    },
    {
      "x": -6,
      "y": 2,
      "z": 4,
      "name": "Rock_Volcanic"
    },
    {
      "x": -6,
      "y": 0,
      "z": 5,
      "name": "Rock_Volcanic"
    },
    {
      "x": -6,
      "y": 1,
      "z": 5,
      "name": "Rock_Volcanic"
    },
    {
      "x": -6,
      "y": 2,
      "z": 5,
      "name": "Rock_Volcanic"
    },
    {
      "x": -6,
      "y": 3,
      "z": 5,
      "name": "Rubble_Ice",
      "support": 15
    },
    {
      "x": -6,
      "y": 0,
      "z": 6,
      "name": "Rock_Volcanic"
    },
    {
      "x": -6,
      "y": 1,
      "z": 6,
      "name": "Rock_Volcanic"
    },
    {
      "x": -6,
      "y": 2,
      "z": 6,
      "name": "Rock_Volcanic"
    },
    {
      "x": -6,
      "y": 0,
      "z": 7,
      "name": "Rock_Volcanic"
    },
    {
      "x": -6,
      "y": 1,
      "z": 7,
      "name": "Rock_Volcanic"
    },
    {
      "x": -6,
      "y": 2,
      "z": 7,
      "name": "Rock_Volcanic"
    },
    {
      "x": -6,
      "y": 0,
      "z": 8,
      "name": "Rock_Volcanic"
    },
    {
      "x": -6,
      "y": 1,
      "z": 8,
      "name": "Rock_Ice_Permafrost"
    },
    {
      "x": -6,
      "y": 2,
      "z": 8,
      "name": "Rock_Ice_Icicles"
    },
    {
      "x": -6,
      "y": 1,
      "z": 9,
      "name": "Rock_Volcanic"
    },
    {
      "x": -6,
      "y": 0,
      "z": 10,
      "name": "Rock_Volcanic"
    },
    {
      "x": -5,
      "y": 0,
      "z": -10,
      "name": "Rock_Volcanic"
    },
    {
      "x": -5,
      "y": 0,
      "z": -9,
      "name": "Rock_Volcanic"
    },
    {
      "x": -5,
      "y": 0,
      "z": -8,
      "name": "Rock_Volcanic"
    },
    {
      "x": -5,
      "y": 0,
      "z": -7,
      "name": "Rock_Volcanic"
    },
    {
      "x": -5,
      "y": 1,
      "z": -7,
      "name": "Rock_Volcanic"
    },
    {
      "x": -5,
      "y": 0,
      "z": -6,
      "name": "Rock_Volcanic"
    },
    {
      "x": -5,
      "y": 1,
      "z": -6,
      "name": "Rock_Ice_Permafrost"
    },
    {
      "x": -5,
      "y": 0,
      "z": -5,
      "name": "Rock_Volcanic"
    },
    {
      "x": -5,
      "y": 1,
      "z": -5,
      "name": "Rock_Volcanic"
    },
    {
      "x": -5,
      "y": 2,
      "z": -5,
      "name": "Rock_Ice_Permafrost"
    },
    {
      "x": -5,
      "y": 0,
      "z": -4,
      "name": "Rock_Volcanic"
    },
    {
      "x": -5,
      "y": 1,
      "z": -4,
      "name": "Rock_Volcanic"
    },
    {
      "x": -5,
      "y": 2,
      "z": -4,
      "name": "Rock_Volcanic"
    },
    {
      "x": -5,
      "y": 0,
      "z": -3,
      "name": "Rock_Volcanic"
    },
    {
      "x": -5,
      "y": 1,
      "z": -3,
      "name": "Rock_Volcanic"
    },
    {
      "x": -5,
      "y": 2,
      "z": -3,
      "name": "Rock_Volcanic"
    },
    {
      "x": -5,
      "y": 0,
      "z": -2,
      "name": "Rock_Volcanic"
    },
    {
      "x": -5,
      "y": 1,
      "z": -2,
      "name": "Rock_Volcanic"
    },
    {
      "x": -5,
      "y": 2,
      "z": -2,
      "name": "Rock_Ice_Permafrost"
    },
    {
      "x": -5,
      "y": 3,
      "z": -2,
      "name": "Rock_Ice_Icicles"
    },
    {
      "x": -5,
      "y": 0,
      "z": -1,
      "name": "Rock_Volcanic"
    },
    {
      "x": -5,
      "y": 1,
      "z": -1,
      "name": "Rock_Volcanic"
    },
    {
      "x": -5,
      "y": 2,
      "z": -1,
      "name": "Rock_Volcanic"
    },
    {
      "x": -5,
      "y": 0,
      "z": 0,
      "name": "Rock_Volcanic"
    },
    {
      "x": -5,
      "y": 1,
      "z": 0,
      "name": "Rock_Volcanic"
    },
    {
      "x": -5,
      "y": 2,
      "z": 0,
      "name": "Rock_Volcanic"
    },
    {
      "x": -5,
      "y": 0,
      "z": 1,
      "name": "Rock_Volcanic"
    },
    {
      "x": -5,
      "y": 1,
      "z": 1,
      "name": "Rock_Volcanic"
    },
    {
      "x": -5,
      "y": 2,
      "z": 1,
      "name": "Rock_Volcanic"
    },
    {
      "x": -5,
      "y": 3,
      "z": 1,
      "name": "Rock_Volcanic"
    },
    {
      "x": -5,
      "y": 0,
      "z": 2,
      "name": "Rock_Volcanic"
    },
    {
      "x": -5,
      "y": 1,
      "z": 2,
      "name": "Rock_Volcanic"
    },
    {
      "x": -5,
      "y": 2,
      "z": 2,
      "name": "Rock_Volcanic"
    },
    {
      "x": -5,
      "y": 3,
      "z": 2,
      "name": "Rock_Ice_Permafrost"
    },
    {
      "x": -5,
      "y": 4,
      "z": 2,
      "name": "Rock_Ice_Icicles"
    },
    {
      "x": -5,
      "y": 0,
      "z": 3,
      "name": "Rock_Volcanic"
    },
    {
      "x": -5,
      "y": 1,
      "z": 3,
      "name": "Rock_Volcanic"
    },
    {
      "x": -5,
      "y": 2,
      "z": 3,
      "name": "Rock_Volcanic"
    },
    {
      "x": -5,
      "y": 3,
      "z": 3,
      "name": "Rock_Ice_Permafrost"
    },
    {
      "x": -5,
      "y": 0,
      "z": 4,
      "name": "Rock_Volcanic"
    },
    {
      "x": -5,
      "y": 1,
      "z": 4,
      "name": "Rock_Volcanic"
    },
    {
      "x": -5,
      "y": 2,
      "z": 4,
      "name": "Rock_Volcanic"
    },
    {
      "x": -5,
      "y": 3,
      "z": 4,
      "name": "Rock_Volcanic"
    },
    {
      "x": -5,
      "y": 0,
      "z": 5,
      "name": "Rock_Volcanic"
    },
    {
      "x": -5,
      "y": 1,
      "z": 5,
      "name": "Rock_Volcanic"
    },
    {
      "x": -5,
      "y": 2,
      "z": 5,
      "name": "Rock_Volcanic"
    },
    {
      "x": -5,
      "y": 3,
      "z": 5,
      "name": "Rock_Volcanic"
    },
    {
      "x": -5,
      "y": 0,
      "z": 6,
      "name": "Rock_Volcanic"
    },
    {
      "x": -5,
      "y": 1,
      "z": 6,
      "name": "Rock_Volcanic"
    },
    {
      "x": -5,
      "y": 2,
      "z": 6,
      "name": "Rock_Volcanic"
    },
    {
      "x": -5,
      "y": 0,
      "z": 7,
      "name": "Rock_Volcanic"
    },
    {
      "x": -5,
      "y": 1,
      "z": 7,
      "name": "Rock_Volcanic"
    },
    {
      "x": -5,
      "y": 2,
      "z": 7,
      "name": "Rock_Ice_Permafrost"
    },
    {
      "x": -5,
      "y": 3,
      "z": 7,
      "name": "Rock_Ice_Stalactite_Large"
    },
    {
      "x": -5,
      "y": 4,
      "z": 7,
      "name": "Rock_Ice_Stalactite_Large",
      "filler": 1024
    },
    {
      "x": -5,
      "y": 0,
      "z": 8,
      "name": "Rock_Volcanic"
    },
    {
      "x": -5,
      "y": 1,
      "z": 8,
      "name": "Rock_Volcanic"
    },
    {
      "x": -5,
      "y": 2,
      "z": 8,
      "name": "Rock_Ice_Permafrost"
    },
    {
      "x": -5,
      "y": 0,
      "z": 9,
      "name": "Rock_Volcanic"
    },
    {
      "x": -5,
      "y": 1,
      "z": 9,
      "name": "Rock_Ice_Permafrost"
    },
    {
      "x": -5,
      "y": 2,
      "z": 9,
      "name": "Rock_Ice_Stalactite_Large"
    },
    {
      "x": -5,
      "y": 3,
      "z": 9,
      "name": "Rock_Ice_Stalactite_Large",
      "filler": 1024
    },
    {
      "x": -5,
      "y": 0,
      "z": 10,
      "name": "Rock_Volcanic"
    },
    {
      "x": -5,
      "y": 0,
      "z": 11,
      "name": "Rock_Volcanic"
    },
    {
      "x": -4,
      "y": 0,
      "z": -10,
      "name": "Rock_Volcanic"
    },
    {
      "x": -4,
      "y": 0,
      "z": -9,
      "name": "Rock_Volcanic"
    },
    {
      "x": -4,
      "y": 0,
      "z": -8,
      "name": "Rock_Volcanic"
    },
    {
      "x": -4,
      "y": 1,
      "z": -8,
      "name": "Rock_Volcanic"
    },
    {
      "x": -4,
      "y": 0,
      "z": -7,
      "name": "Rock_Volcanic"
    },
    {
      "x": -4,
      "y": 1,
      "z": -7,
      "name": "Rock_Ice_Permafrost"
    },
    {
      "x": -4,
      "y": 2,
      "z": -7,
      "name": "Rock_Ice_Stalactite_Large"
    },
    {
      "x": -4,
      "y": 3,
      "z": -7,
      "name": "Rock_Ice_Stalactite_Large",
      "filler": 1024
    },
    {
      "x": -4,
      "y": 0,
      "z": -6,
      "name": "Rock_Volcanic"
    },
    {
      "x": -4,
      "y": 1,
      "z": -6,
      "name": "Rock_Volcanic"
    },
    {
      "x": -4,
      "y": 2,
      "z": -6,
      "name": "Rock_Ice_Permafrost"
    },
    {
      "x": -4,
      "y": 0,
      "z": -5,
      "name": "Rock_Volcanic"
    },
    {
      "x": -4,
      "y": 1,
      "z": -5,
      "name": "Rock_Volcanic"
    },
    {
      "x": -4,
      "y": 2,
      "z": -5,
      "name": "Rock_Ice_Permafrost"
    },
    {
      "x": -4,
      "y": 3,
      "z": -5,
      "name": "Rock_Ice_Icicles"
    },
    {
      "x": -4,
      "y": 0,
      "z": -4,
      "name": "Rock_Volcanic"
    },
    {
      "x": -4,
      "y": 1,
      "z": -4,
      "name": "Rock_Volcanic"
    },
    {
      "x": -4,
      "y": 2,
      "z": -4,
      "name": "Rock_Volcanic"
    },
    {
      "x": -4,
      "y": 0,
      "z": -3,
      "name": "Rock_Volcanic"
    },
    {
      "x": -4,
      "y": 1,
      "z": -3,
      "name": "Rock_Volcanic"
    },
    {
      "x": -4,
      "y": 2,
      "z": -3,
      "name": "Rock_Ice_Permafrost"
    },
    {
      "x": -4,
      "y": 3,
      "z": -3,
      "name": "Rock_Ice_Stalactite_Large"
    },
    {
      "x": -4,
      "y": 4,
      "z": -3,
      "name": "Rock_Ice_Stalactite_Large",
      "filler": 1024
    },
    {
      "x": -4,
      "y": 0,
      "z": -2,
      "name": "Rock_Volcanic"
    },
    {
      "x": -4,
      "y": 1,
      "z": -2,
      "name": "Rock_Volcanic"
    },
    {
      "x": -4,
      "y": 2,
      "z": -2,
      "name": "Rock_Ice_Permafrost"
    },
    {
      "x": -4,
      "y": 3,
      "z": -2,
      "name": "Rock_Ice_Permafrost"
    },
    {
      "x": -4,
      "y": 0,
      "z": -1,
      "name": "Rock_Volcanic"
    },
    {
      "x": -4,
      "y": 1,
      "z": -1,
      "name": "Rock_Volcanic"
    },
    {
      "x": -4,
      "y": 2,
      "z": -1,
      "name": "Rock_Volcanic"
    },
    {
      "x": -4,
      "y": 3,
      "z": -1,
      "name": "Rock_Volcanic"
    },
    {
      "x": -4,
      "y": 0,
      "z": 0,
      "name": "Rock_Volcanic"
    },
    {
      "x": -4,
      "y": 1,
      "z": 0,
      "name": "Rock_Volcanic"
    },
    {
      "x": -4,
      "y": 2,
      "z": 0,
      "name": "Rock_Volcanic"
    },
    {
      "x": -4,
      "y": 3,
      "z": 0,
      "name": "Rock_Volcanic"
    },
    {
      "x": -4,
      "y": 0,
      "z": 1,
      "name": "Rock_Volcanic"
    },
    {
      "x": -4,
      "y": 1,
      "z": 1,
      "name": "Rock_Volcanic"
    },
    {
      "x": -4,
      "y": 2,
      "z": 1,
      "name": "Rock_Volcanic"
    },
    {
      "x": -4,
      "y": 3,
      "z": 1,
      "name": "Rock_Volcanic"
    },
    {
      "x": -4,
      "y": 0,
      "z": 2,
      "name": "Rock_Volcanic"
    },
    {
      "x": -4,
      "y": 1,
      "z": 2,
      "name": "Rock_Volcanic"
    },
    {
      "x": -4,
      "y": 2,
      "z": 2,
      "name": "Rock_Volcanic"
    },
    {
      "x": -4,
      "y": 3,
      "z": 2,
      "name": "Rock_Ice_Permafrost"
    },
    {
      "x": -4,
      "y": 0,
      "z": 3,
      "name": "Rock_Volcanic"
    },
    {
      "x": -4,
      "y": 1,
      "z": 3,
      "name": "Rock_Volcanic"
    },
    {
      "x": -4,
      "y": 2,
      "z": 3,
      "name": "Rock_Volcanic"
    },
    {
      "x": -4,
      "y": 3,
      "z": 3,
      "name": "Rock_Ice_Permafrost"
    },
    {
      "x": -4,
      "y": 4,
      "z": 3,
      "name": "Rock_Ice_Stalactite_Large"
    },
    {
      "x": -4,
      "y": 5,
      "z": 3,
      "name": "Rock_Ice_Stalactite_Large",
      "filler": 1024
    },
    {
      "x": -4,
      "y": 0,
      "z": 4,
      "name": "Rock_Volcanic"
    },
    {
      "x": -4,
      "y": 1,
      "z": 4,
      "name": "Rock_Volcanic"
    },
    {
      "x": -4,
      "y": 2,
      "z": 4,
      "name": "Rock_Volcanic"
    },
    {
      "x": -4,
      "y": 3,
      "z": 4,
      "name": "Rock_Volcanic"
    },
    {
      "x": -4,
      "y": 0,
      "z": 5,
      "name": "Rock_Volcanic"
    },
    {
      "x": -4,
      "y": 1,
      "z": 5,
      "name": "Rock_Volcanic"
    },
    {
      "x": -4,
      "y": 2,
      "z": 5,
      "name": "Rock_Volcanic"
    },
    {
      "x": -4,
      "y": 3,
      "z": 5,
      "name": "Rock_Volcanic"
    },
    {
      "x": -4,
      "y": 0,
      "z": 6,
      "name": "Rock_Volcanic"
    },
    {
      "x": -4,
      "y": 1,
      "z": 6,
      "name": "Rock_Volcanic"
    },
    {
      "x": -4,
      "y": 2,
      "z": 6,
      "name": "Rock_Volcanic"
    },
    {
      "x": -4,
      "y": 3,
      "z": 6,
      "name": "Rock_Volcanic"
    },
    {
      "x": -4,
      "y": 0,
      "z": 7,
      "name": "Rock_Volcanic"
    },
    {
      "x": -4,
      "y": 1,
      "z": 7,
      "name": "Rock_Volcanic"
    },
    {
      "x": -4,
      "y": 2,
      "z": 7,
      "name": "Rock_Volcanic"
    },
    {
      "x": -4,
      "y": 0,
      "z": 8,
      "name": "Rock_Volcanic"
    },
    {
      "x": -4,
      "y": 1,
      "z": 8,
      "name": "Rock_Volcanic"
    },
    {
      "x": -4,
      "y": 2,
      "z": 8,
      "name": "Rock_Ice_Permafrost"
    },
    {
      "x": -4,
      "y": 3,
      "z": 8,
      "name": "Rock_Ice_Icicles"
    },
    {
      "x": -4,
      "y": 1,
      "z": 9,
      "name": "Rock_Ice_Permafrost"
    },
    {
      "x": -4,
      "y": 0,
      "z": 10,
      "name": "Rock_Volcanic"
    },
    {
      "x": -4,
      "y": 1,
      "z": 10,
      "name": "Rubble_Ice",
      "support": 15
    },
    {
      "x": -4,
      "y": 0,
      "z": 11,
      "name": "Rock_Volcanic"
    },
    {
      "x": -4,
      "y": 1,
      "z": 11,
      "name": "Rubble_Ice",
      "support": 15
    },
    {
      "x": -3,
      "y": 0,
      "z": -9,
      "name": "Rock_Volcanic"
    },
    {
      "x": -3,
      "y": 0,
      "z": -8,
      "name": "Rock_Volcanic"
    },
    {
      "x": -3,
      "y": 1,
      "z": -8,
      "name": "Rock_Volcanic"
    },
    {
      "x": -3,
      "y": 0,
      "z": -7,
      "name": "Rock_Volcanic"
    },
    {
      "x": -3,
      "y": 1,
      "z": -7,
      "name": "Rock_Ice_Permafrost"
    },
    {
      "x": -3,
      "y": 0,
      "z": -6,
      "name": "Rock_Volcanic"
    },
    {
      "x": -3,
      "y": 1,
      "z": -6,
      "name": "Rock_Volcanic"
    },
    {
      "x": -3,
      "y": 2,
      "z": -6,
      "name": "Rock_Volcanic"
    },
    {
      "x": -3,
      "y": 0,
      "z": -5,
      "name": "Rock_Volcanic"
    },
    {
      "x": -3,
      "y": 1,
      "z": -5,
      "name": "Rock_Volcanic"
    },
    {
      "x": -3,
      "y": 2,
      "z": -5,
      "name": "Rock_Volcanic"
    },
    {
      "x": -3,
      "y": 0,
      "z": -4,
      "name": "Rock_Volcanic"
    },
    {
      "x": -3,
      "y": 1,
      "z": -4,
      "name": "Rock_Volcanic"
    },
    {
      "x": -3,
      "y": 2,
      "z": -4,
      "name": "Rock_Volcanic"
    },
    {
      "x": -3,
      "y": 3,
      "z": -4,
      "name": "Rock_Volcanic"
    },
    {
      "x": -3,
      "y": 0,
      "z": -3,
      "name": "Rock_Volcanic"
    },
    {
      "x": -3,
      "y": 1,
      "z": -3,
      "name": "Rock_Volcanic"
    },
    {
      "x": -3,
      "y": 2,
      "z": -3,
      "name": "Rock_Volcanic"
    },
    {
      "x": -3,
      "y": 3,
      "z": -3,
      "name": "Rock_Volcanic"
    },
    {
      "x": -3,
      "y": 0,
      "z": -2,
      "name": "Rock_Volcanic"
    },
    {
      "x": -3,
      "y": 1,
      "z": -2,
      "name": "Rock_Volcanic"
    },
    {
      "x": -3,
      "y": 2,
      "z": -2,
      "name": "Rock_Volcanic"
    },
    {
      "x": -3,
      "y": 3,
      "z": -2,
      "name": "Rock_Volcanic"
    },
    {
      "x": -3,
      "y": 4,
      "z": -2,
      "name": "Rock_Volcanic"
    },
    {
      "x": -3,
      "y": 0,
      "z": -1,
      "name": "Rock_Volcanic"
    },
    {
      "x": -3,
      "y": 1,
      "z": -1,
      "name": "Rock_Volcanic"
    },
    {
      "x": -3,
      "y": 2,
      "z": -1,
      "name": "Rock_Volcanic"
    },
    {
      "x": -3,
      "y": 3,
      "z": -1,
      "name": "Rock_Volcanic"
    },
    {
      "x": -3,
      "y": 4,
      "z": -1,
      "name": "Rubble_Ice_Medium",
      "support": 15
    },
    {
      "x": -3,
      "y": 0,
      "z": 0,
      "name": "Rock_Volcanic"
    },
    {
      "x": -3,
      "y": 1,
      "z": 0,
      "name": "Rock_Volcanic"
    },
    {
      "x": -3,
      "y": 2,
      "z": 0,
      "name": "Rock_Volcanic"
    },
    {
      "x": -3,
      "y": 3,
      "z": 0,
      "name": "Rock_Volcanic"
    },
    {
      "x": -3,
      "y": 4,
      "z": 0,
      "name": "Rubble_Ice",
      "support": 15
    },
    {
      "x": -3,
      "y": 0,
      "z": 1,
      "name": "Rock_Volcanic"
    },
    {
      "x": -3,
      "y": 1,
      "z": 1,
      "name": "Rock_Volcanic"
    },
    {
      "x": -3,
      "y": 2,
      "z": 1,
      "name": "Rock_Volcanic"
    },
    {
      "x": -3,
      "y": 3,
      "z": 1,
      "name": "Rock_Ice_Permafrost"
    },
    {
      "x": -3,
      "y": 4,
      "z": 1,
      "name": "Rock_Ice_Stalactite_Large"
    },
    {
      "x": -3,
      "y": 5,
      "z": 1,
      "name": "Rock_Ice_Stalactite_Large",
      "filler": 1024
    },
    {
      "x": -3,
      "y": 0,
      "z": 2,
      "name": "Rock_Volcanic"
    },
    {
      "x": -3,
      "y": 1,
      "z": 2,
      "name": "Rock_Volcanic"
    },
    {
      "x": -3,
      "y": 2,
      "z": 2,
      "name": "Rock_Volcanic"
    },
    {
      "x": -3,
      "y": 3,
      "z": 2,
      "name": "Rock_Ice_Permafrost"
    },
    {
      "x": -3,
      "y": 0,
      "z": 3,
      "name": "Rock_Volcanic"
    },
    {
      "x": -3,
      "y": 1,
      "z": 3,
      "name": "Rock_Volcanic"
    },
    {
      "x": -3,
      "y": 2,
      "z": 3,
      "name": "Rock_Volcanic"
    },
    {
      "x": -3,
      "y": 3,
      "z": 3,
      "name": "Rock_Volcanic"
    },
    {
      "x": -3,
      "y": 0,
      "z": 4,
      "name": "Rock_Volcanic"
    },
    {
      "x": -3,
      "y": 1,
      "z": 4,
      "name": "Rock_Volcanic"
    },
    {
      "x": -3,
      "y": 2,
      "z": 4,
      "name": "Rock_Volcanic"
    },
    {
      "x": -3,
      "y": 3,
      "z": 4,
      "name": "Rock_Volcanic"
    },
    {
      "x": -3,
      "y": 0,
      "z": 5,
      "name": "Rock_Volcanic"
    },
    {
      "x": -3,
      "y": 1,
      "z": 5,
      "name": "Rock_Volcanic"
    },
    {
      "x": -3,
      "y": 2,
      "z": 5,
      "name": "Rock_Volcanic"
    },
    {
      "x": -3,
      "y": 3,
      "z": 5,
      "name": "Rock_Volcanic"
    },
    {
      "x": -3,
      "y": 0,
      "z": 6,
      "name": "Rock_Volcanic"
    },
    {
      "x": -3,
      "y": 1,
      "z": 6,
      "name": "Rock_Volcanic"
    },
    {
      "x": -3,
      "y": 2,
      "z": 6,
      "name": "Rock_Volcanic"
    },
    {
      "x": -3,
      "y": 3,
      "z": 6,
      "name": "Rock_Volcanic"
    },
    {
      "x": -3,
      "y": 4,
      "z": 6,
      "name": "Rock_Volcanic"
    },
    {
      "x": -3,
      "y": 5,
      "z": 6,
      "name": "Rubble_Ice_Medium",
      "support": 15
    },
    {
      "x": -3,
      "y": 0,
      "z": 7,
      "name": "Rock_Volcanic"
    },
    {
      "x": -3,
      "y": 1,
      "z": 7,
      "name": "Rock_Volcanic"
    },
    {
      "x": -3,
      "y": 2,
      "z": 7,
      "name": "Rock_Volcanic"
    },
    {
      "x": -3,
      "y": 0,
      "z": 8,
      "name": "Rock_Volcanic"
    },
    {
      "x": -3,
      "y": 1,
      "z": 8,
      "name": "Rock_Volcanic"
    },
    {
      "x": -3,
      "y": 2,
      "z": 8,
      "name": "Rock_Volcanic"
    },
    {
      "x": -3,
      "y": 0,
      "z": 9,
      "name": "Rock_Volcanic"
    },
    {
      "x": -3,
      "y": 1,
      "z": 9,
      "name": "Rock_Volcanic"
    },
    {
      "x": -3,
      "y": 0,
      "z": 10,
      "name": "Rock_Volcanic"
    },
    {
      "x": -3,
      "y": 0,
      "z": 11,
      "name": "Rock_Volcanic"
    },
    {
      "x": -3,
      "y": 0,
      "z": 12,
      "name": "Rock_Volcanic"
    },
    {
      "x": -2,
      "y": 0,
      "z": -9,
      "name": "Rock_Volcanic"
    },
    {
      "x": -2,
      "y": 0,
      "z": -8,
      "name": "Rock_Volcanic"
    },
    {
      "x": -2,
      "y": 1,
      "z": -8,
      "name": "Rock_Volcanic"
    },
    {
      "x": -2,
      "y": 0,
      "z": -7,
      "name": "Rock_Volcanic"
    },
    {
      "x": -2,
      "y": 1,
      "z": -7,
      "name": "Rock_Volcanic"
    },
    {
      "x": -2,
      "y": 2,
      "z": -7,
      "name": "Rubble_Ice",
      "support": 15
    },
    {
      "x": -2,
      "y": 0,
      "z": -6,
      "name": "Rock_Volcanic"
    },
    {
      "x": -2,
      "y": 1,
      "z": -6,
      "name": "Rock_Volcanic"
    },
    {
      "x": -2,
      "y": 2,
      "z": -6,
      "name": "Rock_Volcanic"
    },
    {
      "x": -2,
      "y": 0,
      "z": -5,
      "name": "Rock_Volcanic"
    },
    {
      "x": -2,
      "y": 1,
      "z": -5,
      "name": "Rock_Volcanic"
    },
    {
      "x": -2,
      "y": 2,
      "z": -5,
      "name": "Rock_Volcanic"
    },
    {
      "x": -2,
      "y": 0,
      "z": -4,
      "name": "Rock_Volcanic"
    },
    {
      "x": -2,
      "y": 1,
      "z": -4,
      "name": "Rock_Volcanic"
    },
    {
      "x": -2,
      "y": 2,
      "z": -4,
      "name": "Rock_Volcanic"
    },
    {
      "x": -2,
      "y": 3,
      "z": -4,
      "name": "Rock_Volcanic"
    },
    {
      "x": -2,
      "y": 0,
      "z": -3,
      "name": "Rock_Volcanic"
    },
    {
      "x": -2,
      "y": 1,
      "z": -3,
      "name": "Rock_Volcanic"
    },
    {
      "x": -2,
      "y": 2,
      "z": -3,
      "name": "Rock_Volcanic"
    },
    {
      "x": -2,
      "y": 3,
      "z": -3,
      "name": "Rock_Volcanic"
    },
    {
      "x": -2,
      "y": 4,
      "z": -3,
      "name": "Rubble_Ice",
      "support": 15
    },
    {
      "x": -2,
      "y": 0,
      "z": -2,
      "name": "Rock_Volcanic"
    },
    {
      "x": -2,
      "y": 1,
      "z": -2,
      "name": "Rock_Volcanic"
    },
    {
      "x": -2,
      "y": 2,
      "z": -2,
      "name": "Rock_Volcanic"
    },
    {
      "x": -2,
      "y": 3,
      "z": -2,
      "name": "Rock_Volcanic"
    },
    {
      "x": -2,
      "y": 4,
      "z": -2,
      "name": "Rock_Volcanic"
    },
    {
      "x": -2,
      "y": 0,
      "z": -1,
      "name": "Rock_Volcanic"
    },
    {
      "x": -2,
      "y": 1,
      "z": -1,
      "name": "Rock_Volcanic"
    },
    {
      "x": -2,
      "y": 2,
      "z": -1,
      "name": "Rock_Volcanic"
    },
    {
      "x": -2,
      "y": 3,
      "z": -1,
      "name": "Rock_Volcanic"
    },
    {
      "x": -2,
      "y": 0,
      "z": 0,
      "name": "Rock_Volcanic"
    },
    {
      "x": -2,
      "y": 1,
      "z": 0,
      "name": "Rock_Volcanic"
    },
    {
      "x": -2,
      "y": 2,
      "z": 0,
      "name": "Rock_Volcanic"
    },
    {
      "x": -2,
      "y": 3,
      "z": 0,
      "name": "Rock_Volcanic"
    },
    {
      "x": -2,
      "y": 0,
      "z": 1,
      "name": "Rock_Volcanic"
    },
    {
      "x": -2,
      "y": 1,
      "z": 1,
      "name": "Rock_Volcanic"
    },
    {
      "x": -2,
      "y": 2,
      "z": 1,
      "name": "Rock_Volcanic"
    },
    {
      "x": -2,
      "y": 3,
      "z": 1,
      "name": "Rock_Ice_Permafrost"
    },
    {
      "x": -2,
      "y": 0,
      "z": 2,
      "name": "Rock_Volcanic"
    },
    {
      "x": -2,
      "y": 1,
      "z": 2,
      "name": "Rock_Volcanic"
    },
    {
      "x": -2,
      "y": 2,
      "z": 2,
      "name": "Rock_Volcanic"
    },
    {
      "x": -2,
      "y": 3,
      "z": 2,
      "name": "Rock_Volcanic_Cracked_Lava"
    },
    {
      "x": -2,
      "y": 0,
      "z": 3,
      "name": "Rock_Volcanic"
    },
    {
      "x": -2,
      "y": 1,
      "z": 3,
      "name": "Rock_Volcanic"
    },
    {
      "x": -2,
      "y": 2,
      "z": 3,
      "name": "Rock_Volcanic"
    },
    {
      "x": -2,
      "y": 3,
      "z": 3,
      "name": "Rock_Volcanic"
    },
    {
      "x": -2,
      "y": 4,
      "z": 3,
      "name": "Plant_Bramble_Dead_Lavathorn"
    },
    {
      "x": -2,
      "y": 0,
      "z": 4,
      "name": "Rock_Volcanic"
    },
    {
      "x": -2,
      "y": 1,
      "z": 4,
      "name": "Rock_Volcanic"
    },
    {
      "x": -2,
      "y": 2,
      "z": 4,
      "name": "Rock_Volcanic"
    },
    {
      "x": -2,
      "y": 3,
      "z": 4,
      "name": "Rock_Volcanic"
    },
    {
      "x": -2,
      "y": 0,
      "z": 5,
      "name": "Rock_Volcanic"
    },
    {
      "x": -2,
      "y": 1,
      "z": 5,
      "name": "Rock_Volcanic"
    },
    {
      "x": -2,
      "y": 2,
      "z": 5,
      "name": "Rock_Volcanic"
    },
    {
      "x": -2,
      "y": 3,
      "z": 5,
      "name": "Rock_Volcanic"
    },
    {
      "x": -2,
      "y": 0,
      "z": 6,
      "name": "Rock_Volcanic"
    },
    {
      "x": -2,
      "y": 1,
      "z": 6,
      "name": "Rock_Volcanic"
    },
    {
      "x": -2,
      "y": 2,
      "z": 6,
      "name": "Rock_Volcanic"
    },
    {
      "x": -2,
      "y": 3,
      "z": 6,
      "name": "Rock_Volcanic"
    },
    {
      "x": -2,
      "y": 4,
      "z": 6,
      "name": "Rock_Volcanic"
    },
    {
      "x": -2,
      "y": 0,
      "z": 7,
      "name": "Rock_Volcanic"
    },
    {
      "x": -2,
      "y": 1,
      "z": 7,
      "name": "Rock_Volcanic"
    },
    {
      "x": -2,
      "y": 2,
      "z": 7,
      "name": "Rock_Volcanic"
    },
    {
      "x": -2,
      "y": 3,
      "z": 7,
      "name": "Rock_Volcanic"
    },
    {
      "x": -2,
      "y": 4,
      "z": 7,
      "name": "Rock_Volcanic"
    },
    {
      "x": -2,
      "y": 0,
      "z": 8,
      "name": "Rock_Volcanic"
    },
    {
      "x": -2,
      "y": 1,
      "z": 8,
      "name": "Rock_Volcanic"
    },
    {
      "x": -2,
      "y": 2,
      "z": 8,
      "name": "Rock_Ice_Permafrost"
    },
    {
      "x": -2,
      "y": 3,
      "z": 8,
      "name": "Rock_Ice_Stalactite_Large"
    },
    {
      "x": -2,
      "y": 4,
      "z": 8,
      "name": "Rock_Ice_Stalactite_Large",
      "filler": 1024
    },
    {
      "x": -2,
      "y": 0,
      "z": 9,
      "name": "Rock_Volcanic"
    },
    {
      "x": -2,
      "y": 1,
      "z": 9,
      "name": "Rock_Volcanic"
    },
    {
      "x": -2,
      "y": 2,
      "z": 9,
      "name": "Rubble_Ice_Medium",
      "support": 15
    },
    {
      "x": -2,
      "y": 0,
      "z": 10,
      "name": "Rock_Volcanic"
    },
    {
      "x": -2,
      "y": 1,
      "z": 10,
      "name": "Rock_Volcanic"
    },
    {
      "x": -2,
      "y": 0,
      "z": 11,
      "name": "Rock_Volcanic"
    },
    {
      "x": -2,
      "y": 0,
      "z": 12,
      "name": "Rock_Volcanic"
    },
    {
      "x": -2,
      "y": 0,
      "z": 13,
      "name": "Rock_Volcanic"
    },
    {
      "x": -2,
      "y": 0,
      "z": 14,
      "name": "Rock_Volcanic"
    },
    {
      "x": -1,
      "y": 0,
      "z": -9,
      "name": "Rock_Volcanic"
    },
    {
      "x": -1,
      "y": 0,
      "z": -8,
      "name": "Rock_Volcanic"
    },
    {
      "x": -1,
      "y": 0,
      "z": -7,
      "name": "Rock_Volcanic"
    },
    {
      "x": -1,
      "y": 1,
      "z": -7,
      "name": "Rock_Volcanic"
    },
    {
      "x": -1,
      "y": 2,
      "z": -7,
      "name": "Rubble_Ice_Medium",
      "support": 15
    },
    {
      "x": -1,
      "y": 0,
      "z": -6,
      "name": "Rock_Volcanic"
    },
    {
      "x": -1,
      "y": 1,
      "z": -6,
      "name": "Rock_Volcanic"
    },
    {
      "x": -1,
      "y": 2,
      "z": -6,
      "name": "Rock_Ice_Permafrost"
    },
    {
      "x": -1,
      "y": 0,
      "z": -5,
      "name": "Rock_Volcanic"
    },
    {
      "x": -1,
      "y": 1,
      "z": -5,
      "name": "Rock_Volcanic"
    },
    {
      "x": -1,
      "y": 2,
      "z": -5,
      "name": "Rock_Ice_Permafrost"
    },
    {
      "x": -1,
      "y": 3,
      "z": -5,
      "name": "Rock_Ice_Icicles"
    },
    {
      "x": -1,
      "y": 0,
      "z": -4,
      "name": "Rock_Volcanic"
    },
    {
      "x": -1,
      "y": 1,
      "z": -4,
      "name": "Rock_Volcanic"
    },
    {
      "x": -1,
      "y": 2,
      "z": -4,
      "name": "Rock_Volcanic"
    },
    {
      "x": -1,
      "y": 3,
      "z": -4,
      "name": "Rock_Ice_Permafrost"
    },
    {
      "x": -1,
      "y": 4,
      "z": -4,
      "name": "Rock_Ice_Icicles"
    },
    {
      "x": -1,
      "y": 0,
      "z": -3,
      "name": "Rock_Volcanic"
    },
    {
      "x": -1,
      "y": 1,
      "z": -3,
      "name": "Rock_Volcanic"
    },
    {
      "x": -1,
      "y": 2,
      "z": -3,
      "name": "Rock_Volcanic"
    },
    {
      "x": -1,
      "y": 3,
      "z": -3,
      "name": "Rock_Volcanic"
    },
    {
      "x": -1,
      "y": 4,
      "z": -3,
      "name": "Rock_Volcanic"
    },
    {
      "x": -1,
      "y": 0,
      "z": -2,
      "name": "Rock_Volcanic"
    },
    {
      "x": -1,
      "y": 1,
      "z": -2,
      "name": "Rock_Volcanic"
    },
    {
      "x": -1,
      "y": 2,
      "z": -2,
      "name": "Rock_Volcanic"
    },
    {
      "x": -1,
      "y": 3,
      "z": -2,
      "name": "Rock_Volcanic"
    },
    {
      "x": -1,
      "y": 4,
      "z": -2,
      "name": "Rock_Volcanic"
    },
    {
      "x": -1,
      "y": 0,
      "z": -1,
      "name": "Rock_Volcanic"
    },
    {
      "x": -1,
      "y": 1,
      "z": -1,
      "name": "Rock_Volcanic"
    },
    {
      "x": -1,
      "y": 2,
      "z": -1,
      "name": "Rock_Volcanic"
    },
    {
      "x": -1,
      "y": 3,
      "z": -1,
      "name": "Rock_Volcanic"
    },
    {
      "x": -1,
      "y": 0,
      "z": 0,
      "name": "Rock_Volcanic"
    },
    {
      "x": -1,
      "y": 1,
      "z": 0,
      "name": "Rock_Volcanic"
    },
    {
      "x": -1,
      "y": 2,
      "z": 0,
      "name": "Rock_Volcanic"
    },
    {
      "x": -1,
      "y": 3,
      "z": 0,
      "name": "Rock_Volcanic"
    },
    {
      "x": -1,
      "y": 0,
      "z": 1,
      "name": "Rock_Volcanic"
    },
    {
      "x": -1,
      "y": 1,
      "z": 1,
      "name": "Rock_Volcanic"
    },
    {
      "x": -1,
      "y": 2,
      "z": 1,
      "name": "Rock_Volcanic"
    },
    {
      "x": -1,
      "y": 3,
      "z": 1,
      "name": "Rock_Volcanic"
    },
    {
      "x": -1,
      "y": 0,
      "z": 2,
      "name": "Rock_Volcanic"
    },
    {
      "x": -1,
      "y": 1,
      "z": 2,
      "name": "Rock_Volcanic"
    },
    {
      "x": -1,
      "y": 2,
      "z": 2,
      "name": "Rock_Volcanic"
    },
    {
      "x": -1,
      "y": 3,
      "z": 2,
      "name": "Rock_Volcanic"
    },
    {
      "x": -1,
      "y": 0,
      "z": 3,
      "name": "Rock_Volcanic"
    },
    {
      "x": -1,
      "y": 1,
      "z": 3,
      "name": "Rock_Volcanic"
    },
    {
      "x": -1,
      "y": 2,
      "z": 3,
      "name": "Rock_Volcanic"
    },
    {
      "x": -1,
      "y": 3,
      "z": 3,
      "name": "Rock_Volcanic_Cracked_Lava_Incandescent"
    },
    {
      "x": -1,
      "y": 0,
      "z": 4,
      "name": "Rock_Volcanic"
    },
    {
      "x": -1,
      "y": 1,
      "z": 4,
      "name": "Rock_Volcanic"
    },
    {
      "x": -1,
      "y": 2,
      "z": 4,
      "name": "Rock_Volcanic"
    },
    {
      "x": -1,
      "y": 3,
      "z": 4,
      "name": "Rock_Volcanic"
    },
    {
      "x": -1,
      "y": 0,
      "z": 5,
      "name": "Rock_Volcanic"
    },
    {
      "x": -1,
      "y": 1,
      "z": 5,
      "name": "Rock_Volcanic"
    },
    {
      "x": -1,
      "y": 2,
      "z": 5,
      "name": "Rock_Volcanic"
    },
    {
      "x": -1,
      "y": 3,
      "z": 5,
      "name": "Rock_Volcanic"
    },
    {
      "x": -1,
      "y": 4,
      "z": 5,
      "name": "Plant_Crop_Mushroom_Glowing_Blue"
    },
    {
      "x": -1,
      "y": 0,
      "z": 6,
      "name": "Rock_Volcanic"
    },
    {
      "x": -1,
      "y": 1,
      "z": 6,
      "name": "Rock_Volcanic"
    },
    {
      "x": -1,
      "y": 2,
      "z": 6,
      "name": "Rock_Volcanic"
    },
    {
      "x": -1,
      "y": 3,
      "z": 6,
      "name": "Rock_Volcanic"
    },
    {
      "x": -1,
      "y": 4,
      "z": 6,
      "name": "Rock_Volcanic"
    },
    {
      "x": -1,
      "y": 5,
      "z": 6,
      "name": "Rock_Volcanic"
    },
    {
      "x": -1,
      "y": 0,
      "z": 7,
      "name": "Rock_Volcanic"
    },
    {
      "x": -1,
      "y": 1,
      "z": 7,
      "name": "Rock_Volcanic"
    },
    {
      "x": -1,
      "y": 2,
      "z": 7,
      "name": "Rock_Volcanic"
    },
    {
      "x": -1,
      "y": 3,
      "z": 7,
      "name": "Rock_Volcanic"
    },
    {
      "x": -1,
      "y": 4,
      "z": 7,
      "name": "Rock_Volcanic"
    },
    {
      "x": -1,
      "y": 5,
      "z": 7,
      "name": "Rock_Volcanic"
    },
    {
      "x": -1,
      "y": 6,
      "z": 7,
      "name": "Rock_Volcanic"
    },
    {
      "x": -1,
      "y": 7,
      "z": 7,
      "name": "Rock_Volcanic"
    },
    {
      "x": -1,
      "y": 8,
      "z": 7,
      "name": "Rock_Volcanic"
    },
    {
      "x": -1,
      "y": 0,
      "z": 8,
      "name": "Rock_Volcanic"
    },
    {
      "x": -1,
      "y": 1,
      "z": 8,
      "name": "Rock_Volcanic"
    },
    {
      "x": -1,
      "y": 2,
      "z": 8,
      "name": "Rock_Volcanic"
    },
    {
      "x": -1,
      "y": 3,
      "z": 8,
      "name": "Rock_Volcanic"
    },
    {
      "x": -1,
      "y": 4,
      "z": 8,
      "name": "Rock_Volcanic"
    },
    {
      "x": -1,
      "y": 5,
      "z": 8,
      "name": "Rock_Volcanic"
    },
    {
      "x": -1,
      "y": 6,
      "z": 8,
      "name": "Rock_Volcanic"
    },
    {
      "x": -1,
      "y": 0,
      "z": 9,
      "name": "Rock_Volcanic"
    },
    {
      "x": -1,
      "y": 1,
      "z": 9,
      "name": "Rock_Volcanic"
    },
    {
      "x": -1,
      "y": 0,
      "z": 10,
      "name": "Rock_Volcanic"
    },
    {
      "x": -1,
      "y": 1,
      "z": 10,
      "name": "Rock_Volcanic"
    },
    {
      "x": -1,
      "y": 0,
      "z": 11,
      "name": "Rock_Volcanic"
    },
    {
      "x": -1,
      "y": 1,
      "z": 11,
      "name": "Rock_Volcanic"
    },
    {
      "x": -1,
      "y": 0,
      "z": 12,
      "name": "Rock_Volcanic"
    },
    {
      "x": -1,
      "y": 0,
      "z": 13,
      "name": "Rock_Volcanic"
    },
    {
      "x": 0,
      "y": 0,
      "z": -9,
      "name": "Rock_Volcanic"
    },
    {
      "x": 0,
      "y": 1,
      "z": -8,
      "name": "Rock_Volcanic"
    },
    {
      "x": 0,
      "y": 0,
      "z": -7,
      "name": "Rock_Volcanic"
    },
    {
      "x": 0,
      "y": 1,
      "z": -7,
      "name": "Rock_Volcanic"
    },
    {
      "x": 0,
      "y": 0,
      "z": -6,
      "name": "Rock_Volcanic"
    },
    {
      "x": 0,
      "y": 1,
      "z": -6,
      "name": "Rock_Volcanic"
    },
    {
      "x": 0,
      "y": 2,
      "z": -6,
      "name": "Rock_Volcanic"
    },
    {
      "x": 0,
      "y": 0,
      "z": -5,
      "name": "Rock_Volcanic"
    },
    {
      "x": 0,
      "y": 1,
      "z": -5,
      "name": "Rock_Volcanic"
    },
    {
      "x": 0,
      "y": 2,
      "z": -5,
      "name": "Rock_Volcanic"
    },
    {
      "x": 0,
      "y": 0,
      "z": -4,
      "name": "Rock_Volcanic"
    },
    {
      "x": 0,
      "y": 1,
      "z": -4,
      "name": "Rock_Volcanic"
    },
    {
      "x": 0,
      "y": 2,
      "z": -4,
      "name": "Rock_Volcanic"
    },
    {
      "x": 0,
      "y": 3,
      "z": -4,
      "name": "Rock_Volcanic"
    },
    {
      "x": 0,
      "y": 4,
      "z": -4,
      "name": "Rock_Volcanic"
    },
    {
      "x": 0,
      "y": 0,
      "z": -3,
      "name": "Rock_Volcanic"
    },
    {
      "x": 0,
      "y": 1,
      "z": -3,
      "name": "Rock_Volcanic"
    },
    {
      "x": 0,
      "y": 2,
      "z": -3,
      "name": "Rock_Volcanic"
    },
    {
      "x": 0,
      "y": 3,
      "z": -3,
      "name": "Rock_Volcanic"
    },
    {
      "x": 0,
      "y": 4,
      "z": -3,
      "name": "Rock_Volcanic"
    },
    {
      "x": 0,
      "y": 5,
      "z": -3,
      "name": "Rock_Volcanic"
    },
    {
      "x": 0,
      "y": 0,
      "z": -2,
      "name": "Rock_Volcanic"
    },
    {
      "x": 0,
      "y": 1,
      "z": -2,
      "name": "Rock_Volcanic"
    },
    {
      "x": 0,
      "y": 2,
      "z": -2,
      "name": "Rock_Volcanic"
    },
    {
      "x": 0,
      "y": 3,
      "z": -2,
      "name": "Rock_Volcanic"
    },
    {
      "x": 0,
      "y": 4,
      "z": -2,
      "name": "Rock_Volcanic"
    },
    {
      "x": 0,
      "y": 5,
      "z": -2,
      "name": "Rock_Volcanic"
    },
    {
      "x": 0,
      "y": 6,
      "z": -2,
      "name": "Rock_Volcanic"
    },
    {
      "x": 0,
      "y": 0,
      "z": -1,
      "name": "Rock_Volcanic"
    },
    {
      "x": 0,
      "y": 1,
      "z": -1,
      "name": "Rock_Volcanic"
    },
    {
      "x": 0,
      "y": 2,
      "z": -1,
      "name": "Rock_Volcanic"
    },
    {
      "x": 0,
      "y": 3,
      "z": -1,
      "name": "Rock_Volcanic"
    },
    {
      "x": 0,
      "y": 4,
      "z": -1,
      "name": "Plant_Crop_Mushroom_Glowing_Blue"
    },
    {
      "x": 0,
      "y": 0,
      "z": 0,
      "name": "Rock_Volcanic"
    },
    {
      "x": 0,
      "y": 1,
      "z": 0,
      "name": "Rock_Volcanic"
    },
    {
      "x": 0,
      "y": 2,
      "z": 0,
      "name": "Rock_Volcanic"
    },
    {
      "x": 0,
      "y": 3,
      "z": 0,
      "name": "Rock_Volcanic"
    },
    {
      "x": 0,
      "y": 0,
      "z": 1,
      "name": "Rock_Volcanic"
    },
    {
      "x": 0,
      "y": 1,
      "z": 1,
      "name": "Rock_Volcanic"
    },
    {
      "x": 0,
      "y": 2,
      "z": 1,
      "name": "Rock_Volcanic"
    },
    {
      "x": 0,
      "y": 3,
      "z": 1,
      "name": "Rock_Volcanic_Cracked_Lava"
    },
    {
      "x": 0,
      "y": 0,
      "z": 2,
      "name": "Rock_Volcanic"
    },
    {
      "x": 0,
      "y": 1,
      "z": 2,
      "name": "Rock_Volcanic"
    },
    {
      "x": 0,
      "y": 2,
      "z": 2,
      "name": "Rock_Volcanic"
    },
    {
      "x": 0,
      "y": 3,
      "z": 2,
      "name": "Empty"
    },
    {
      "x": 0,
      "y": 0,
      "z": 3,
      "name": "Rock_Volcanic"
    },
    {
      "x": 0,
      "y": 1,
      "z": 3,
      "name": "Rock_Volcanic"
    },
    {
      "x": 0,
      "y": 2,
      "z": 3,
      "name": "Rock_Volcanic"
    },
    {
      "x": 0,
      "y": 3,
      "z": 3,
      "name": "Rock_Volcanic"
    },
    {
      "x": 0,
      "y": 0,
      "z": 4,
      "name": "Rock_Volcanic"
    },
    {
      "x": 0,
      "y": 1,
      "z": 4,
      "name": "Rock_Volcanic"
    },
    {
      "x": 0,
      "y": 2,
      "z": 4,
      "name": "Rock_Volcanic"
    },
    {
      "x": 0,
      "y": 3,
      "z": 4,
      "name": "Rock_Volcanic_Cracked_Lava_Incandescent"
    },
    {
      "x": 0,
      "y": 0,
      "z": 5,
      "name": "Rock_Volcanic"
    },
    {
      "x": 0,
      "y": 1,
      "z": 5,
      "name": "Rock_Volcanic"
    },
    {
      "x": 0,
      "y": 2,
      "z": 5,
      "name": "Rock_Volcanic"
    },
    {
      "x": 0,
      "y": 3,
      "z": 5,
      "name": "Rock_Volcanic"
    },
    {
      "x": 0,
      "y": 0,
      "z": 6,
      "name": "Rock_Volcanic"
    },
    {
      "x": 0,
      "y": 1,
      "z": 6,
      "name": "Rock_Volcanic"
    },
    {
      "x": 0,
      "y": 2,
      "z": 6,
      "name": "Rock_Volcanic"
    },
    {
      "x": 0,
      "y": 3,
      "z": 6,
      "name": "Rock_Volcanic"
    },
    {
      "x": 0,
      "y": 4,
      "z": 6,
      "name": "Rock_Volcanic"
    },
    {
      "x": 0,
      "y": 0,
      "z": 7,
      "name": "Rock_Volcanic"
    },
    {
      "x": 0,
      "y": 1,
      "z": 7,
      "name": "Rock_Volcanic"
    },
    {
      "x": 0,
      "y": 2,
      "z": 7,
      "name": "Rock_Volcanic"
    },
    {
      "x": 0,
      "y": 3,
      "z": 7,
      "name": "Rock_Volcanic"
    },
    {
      "x": 0,
      "y": 4,
      "z": 7,
      "name": "Rock_Volcanic"
    },
    {
      "x": 0,
      "y": 5,
      "z": 7,
      "name": "Rock_Volcanic"
    },
    {
      "x": 0,
      "y": 6,
      "z": 7,
      "name": "Rock_Volcanic"
    },
    {
      "x": 0,
      "y": 7,
      "z": 7,
      "name": "Rock_Volcanic"
    },
    {
      "x": 0,
      "y": 8,
      "z": 7,
      "name": "OrbisGalactic_Kyber_Ore_Volcanic"
    },
    {
      "x": 0,
      "y": 9,
      "z": 7,
      "name": "Rock_Volcanic"
    },
    {
      "x": 0,
      "y": 0,
      "z": 8,
      "name": "Rock_Volcanic"
    },
    {
      "x": 0,
      "y": 1,
      "z": 8,
      "name": "Rock_Volcanic"
    },
    {
      "x": 0,
      "y": 2,
      "z": 8,
      "name": "Rock_Volcanic"
    },
    {
      "x": 0,
      "y": 3,
      "z": 8,
      "name": "Rock_Volcanic"
    },
    {
      "x": 0,
      "y": 0,
      "z": 9,
      "name": "Rock_Volcanic"
    },
    {
      "x": 0,
      "y": 1,
      "z": 9,
      "name": "Rock_Volcanic"
    },
    {
      "x": 0,
      "y": 2,
      "z": 9,
      "name": "Rubble_Ice",
      "support": 15
    },
    {
      "x": 0,
      "y": 0,
      "z": 10,
      "name": "Rock_Volcanic"
    },
    {
      "x": 0,
      "y": 1,
      "z": 10,
      "name": "Rock_Volcanic"
    },
    {
      "x": 0,
      "y": 0,
      "z": 11,
      "name": "Rock_Volcanic"
    },
    {
      "x": 0,
      "y": 0,
      "z": 12,
      "name": "Rock_Volcanic"
    },
    {
      "x": 1,
      "y": 0,
      "z": -9,
      "name": "Rock_Volcanic"
    },
    {
      "x": 1,
      "y": 0,
      "z": -8,
      "name": "Rock_Volcanic"
    },
    {
      "x": 1,
      "y": 1,
      "z": -8,
      "name": "Rock_Volcanic"
    },
    {
      "x": 1,
      "y": 0,
      "z": -7,
      "name": "Rock_Volcanic"
    },
    {
      "x": 1,
      "y": 1,
      "z": -7,
      "name": "Rock_Volcanic"
    },
    {
      "x": 1,
      "y": 0,
      "z": -6,
      "name": "Rock_Volcanic"
    },
    {
      "x": 1,
      "y": 1,
      "z": -6,
      "name": "Rock_Volcanic"
    },
    {
      "x": 1,
      "y": 2,
      "z": -6,
      "name": "Rock_Volcanic"
    },
    {
      "x": 1,
      "y": 3,
      "z": -6,
      "name": "Rubble_Ice",
      "support": 15
    },
    {
      "x": 1,
      "y": 0,
      "z": -5,
      "name": "Rock_Volcanic"
    },
    {
      "x": 1,
      "y": 1,
      "z": -5,
      "name": "Rock_Volcanic"
    },
    {
      "x": 1,
      "y": 2,
      "z": -5,
      "name": "Rock_Volcanic"
    },
    {
      "x": 1,
      "y": 0,
      "z": -4,
      "name": "Rock_Volcanic"
    },
    {
      "x": 1,
      "y": 1,
      "z": -4,
      "name": "Rock_Volcanic"
    },
    {
      "x": 1,
      "y": 2,
      "z": -4,
      "name": "Rock_Volcanic"
    },
    {
      "x": 1,
      "y": 3,
      "z": -4,
      "name": "Rock_Volcanic"
    },
    {
      "x": 1,
      "y": 4,
      "z": -4,
      "name": "Rock_Volcanic"
    },
    {
      "x": 1,
      "y": 0,
      "z": -3,
      "name": "Rock_Volcanic"
    },
    {
      "x": 1,
      "y": 1,
      "z": -3,
      "name": "Rock_Volcanic"
    },
    {
      "x": 1,
      "y": 2,
      "z": -3,
      "name": "Rock_Volcanic"
    },
    {
      "x": 1,
      "y": 3,
      "z": -3,
      "name": "Rock_Volcanic"
    },
    {
      "x": 1,
      "y": 4,
      "z": -3,
      "name": "Rock_Volcanic"
    },
    {
      "x": 1,
      "y": 5,
      "z": -3,
      "name": "Rock_Volcanic"
    },
    {
      "x": 1,
      "y": 0,
      "z": -2,
      "name": "Rock_Volcanic"
    },
    {
      "x": 1,
      "y": 1,
      "z": -2,
      "name": "Rock_Volcanic"
    },
    {
      "x": 1,
      "y": 2,
      "z": -2,
      "name": "Rock_Volcanic"
    },
    {
      "x": 1,
      "y": 3,
      "z": -2,
      "name": "Rock_Volcanic"
    },
    {
      "x": 1,
      "y": 4,
      "z": -2,
      "name": "Rock_Volcanic"
    },
    {
      "x": 1,
      "y": 5,
      "z": -2,
      "name": "OrbisGalactic_Kyber_Ore_Volcanic"
    },
    {
      "x": 1,
      "y": 6,
      "z": -2,
      "name": "Rock_Volcanic"
    },
    {
      "x": 1,
      "y": 7,
      "z": -2,
      "name": "Rock_Volcanic"
    },
    {
      "x": 1,
      "y": 8,
      "z": -2,
      "name": "Rock_Volcanic"
    },
    {
      "x": 1,
      "y": 0,
      "z": -1,
      "name": "Rock_Volcanic"
    },
    {
      "x": 1,
      "y": 1,
      "z": -1,
      "name": "Rock_Volcanic"
    },
    {
      "x": 1,
      "y": 2,
      "z": -1,
      "name": "Rock_Volcanic"
    },
    {
      "x": 1,
      "y": 3,
      "z": -1,
      "name": "Rock_Volcanic"
    },
    {
      "x": 1,
      "y": 0,
      "z": 0,
      "name": "Rock_Volcanic"
    },
    {
      "x": 1,
      "y": 1,
      "z": 0,
      "name": "Rock_Volcanic"
    },
    {
      "x": 1,
      "y": 2,
      "z": 0,
      "name": "Rock_Volcanic"
    },
    {
      "x": 1,
      "y": 3,
      "z": 0,
      "name": "Rock_Volcanic_Cracked_Lava_Incandescent"
    },
    {
      "x": 1,
      "y": 0,
      "z": 1,
      "name": "Rock_Volcanic"
    },
    {
      "x": 1,
      "y": 1,
      "z": 1,
      "name": "Rock_Volcanic"
    },
    {
      "x": 1,
      "y": 2,
      "z": 1,
      "name": "Rock_Volcanic"
    },
    {
      "x": 1,
      "y": 3,
      "z": 1,
      "name": "Empty"
    },
    {
      "x": 1,
      "y": 0,
      "z": 2,
      "name": "Rock_Volcanic"
    },
    {
      "x": 1,
      "y": 1,
      "z": 2,
      "name": "Rock_Volcanic"
    },
    {
      "x": 1,
      "y": 2,
      "z": 2,
      "name": "Rock_Volcanic"
    },
    {
      "x": 1,
      "y": 3,
      "z": 2,
      "name": "Empty"
    },
    {
      "x": 1,
      "y": 0,
      "z": 3,
      "name": "Rock_Volcanic"
    },
    {
      "x": 1,
      "y": 1,
      "z": 3,
      "name": "Rock_Volcanic"
    },
    {
      "x": 1,
      "y": 2,
      "z": 3,
      "name": "Rock_Volcanic"
    },
    {
      "x": 1,
      "y": 3,
      "z": 3,
      "name": "Empty"
    },
    {
      "x": 1,
      "y": 0,
      "z": 4,
      "name": "Rock_Volcanic"
    },
    {
      "x": 1,
      "y": 1,
      "z": 4,
      "name": "Rock_Volcanic"
    },
    {
      "x": 1,
      "y": 2,
      "z": 4,
      "name": "Rock_Volcanic"
    },
    {
      "x": 1,
      "y": 3,
      "z": 4,
      "name": "Rock_Volcanic"
    },
    {
      "x": 1,
      "y": 0,
      "z": 5,
      "name": "Rock_Volcanic"
    },
    {
      "x": 1,
      "y": 1,
      "z": 5,
      "name": "Rock_Volcanic"
    },
    {
      "x": 1,
      "y": 2,
      "z": 5,
      "name": "Rock_Volcanic"
    },
    {
      "x": 1,
      "y": 3,
      "z": 5,
      "name": "Rock_Volcanic"
    },
    {
      "x": 1,
      "y": 0,
      "z": 6,
      "name": "Rock_Volcanic"
    },
    {
      "x": 1,
      "y": 1,
      "z": 6,
      "name": "Rock_Volcanic"
    },
    {
      "x": 1,
      "y": 2,
      "z": 6,
      "name": "Rock_Volcanic"
    },
    {
      "x": 1,
      "y": 3,
      "z": 6,
      "name": "Rock_Ice_Permafrost"
    },
    {
      "x": 1,
      "y": 0,
      "z": 7,
      "name": "Rock_Volcanic"
    },
    {
      "x": 1,
      "y": 1,
      "z": 7,
      "name": "Rock_Volcanic"
    },
    {
      "x": 1,
      "y": 2,
      "z": 7,
      "name": "Rock_Volcanic"
    },
    {
      "x": 1,
      "y": 3,
      "z": 7,
      "name": "Rock_Ice_Permafrost"
    },
    {
      "x": 1,
      "y": 0,
      "z": 8,
      "name": "Rock_Volcanic"
    },
    {
      "x": 1,
      "y": 1,
      "z": 8,
      "name": "Rock_Volcanic"
    },
    {
      "x": 1,
      "y": 2,
      "z": 8,
      "name": "Rock_Volcanic"
    },
    {
      "x": 1,
      "y": 0,
      "z": 9,
      "name": "Rock_Volcanic"
    },
    {
      "x": 1,
      "y": 1,
      "z": 9,
      "name": "Rock_Volcanic"
    },
    {
      "x": 1,
      "y": 2,
      "z": 9,
      "name": "Rock_Volcanic"
    },
    {
      "x": 1,
      "y": 0,
      "z": 10,
      "name": "Rock_Volcanic"
    },
    {
      "x": 1,
      "y": 1,
      "z": 10,
      "name": "Rock_Volcanic"
    },
    {
      "x": 1,
      "y": 0,
      "z": 11,
      "name": "Rock_Volcanic"
    },
    {
      "x": 1,
      "y": 1,
      "z": 11,
      "name": "Rock_Volcanic"
    },
    {
      "x": 1,
      "y": 0,
      "z": 12,
      "name": "Rock_Volcanic"
    },
    {
      "x": 2,
      "y": 0,
      "z": -9,
      "name": "Rock_Volcanic"
    },
    {
      "x": 2,
      "y": 1,
      "z": -8,
      "name": "Rock_Ice_Permafrost"
    },
    {
      "x": 2,
      "y": 2,
      "z": -8,
      "name": "Rock_Ice_Icicles"
    },
    {
      "x": 2,
      "y": 0,
      "z": -7,
      "name": "Rock_Volcanic"
    },
    {
      "x": 2,
      "y": 1,
      "z": -7,
      "name": "Rock_Ice_Permafrost"
    },
    {
      "x": 2,
      "y": 0,
      "z": -6,
      "name": "Rock_Volcanic"
    },
    {
      "x": 2,
      "y": 1,
      "z": -6,
      "name": "Rock_Volcanic"
    },
    {
      "x": 2,
      "y": 2,
      "z": -6,
      "name": "Rock_Volcanic"
    },
    {
      "x": 2,
      "y": 0,
      "z": -5,
      "name": "Rock_Volcanic"
    },
    {
      "x": 2,
      "y": 1,
      "z": -5,
      "name": "Rock_Volcanic"
    },
    {
      "x": 2,
      "y": 2,
      "z": -5,
      "name": "Rock_Volcanic"
    },
    {
      "x": 2,
      "y": 0,
      "z": -4,
      "name": "Rock_Volcanic"
    },
    {
      "x": 2,
      "y": 1,
      "z": -4,
      "name": "Rock_Volcanic"
    },
    {
      "x": 2,
      "y": 2,
      "z": -4,
      "name": "Rock_Volcanic"
    },
    {
      "x": 2,
      "y": 3,
      "z": -4,
      "name": "Rubble_Ice_Medium",
      "support": 15
    },
    {
      "x": 2,
      "y": 0,
      "z": -3,
      "name": "Rock_Volcanic"
    },
    {
      "x": 2,
      "y": 1,
      "z": -3,
      "name": "Rock_Volcanic"
    },
    {
      "x": 2,
      "y": 2,
      "z": -3,
      "name": "Rock_Volcanic"
    },
    {
      "x": 2,
      "y": 3,
      "z": -3,
      "name": "Rock_Ice_Permafrost"
    },
    {
      "x": 2,
      "y": 0,
      "z": -2,
      "name": "Rock_Volcanic"
    },
    {
      "x": 2,
      "y": 1,
      "z": -2,
      "name": "Rock_Volcanic"
    },
    {
      "x": 2,
      "y": 2,
      "z": -2,
      "name": "Rock_Volcanic"
    },
    {
      "x": 2,
      "y": 3,
      "z": -2,
      "name": "Rock_Ice_Permafrost"
    },
    {
      "x": 2,
      "y": 4,
      "z": -2,
      "name": "Rock_Ice_Icicles"
    },
    {
      "x": 2,
      "y": 0,
      "z": -1,
      "name": "Rock_Volcanic"
    },
    {
      "x": 2,
      "y": 1,
      "z": -1,
      "name": "Rock_Volcanic"
    },
    {
      "x": 2,
      "y": 2,
      "z": -1,
      "name": "Rock_Volcanic"
    },
    {
      "x": 2,
      "y": 3,
      "z": -1,
      "name": "Rock_Volcanic"
    },
    {
      "x": 2,
      "y": 0,
      "z": 0,
      "name": "Rock_Volcanic"
    },
    {
      "x": 2,
      "y": 1,
      "z": 0,
      "name": "Rock_Volcanic"
    },
    {
      "x": 2,
      "y": 2,
      "z": 0,
      "name": "Rock_Volcanic"
    },
    {
      "x": 2,
      "y": 3,
      "z": 0,
      "name": "Rock_Volcanic"
    },
    {
      "x": 2,
      "y": 0,
      "z": 1,
      "name": "Rock_Volcanic"
    },
    {
      "x": 2,
      "y": 1,
      "z": 1,
      "name": "Rock_Volcanic"
    },
    {
      "x": 2,
      "y": 2,
      "z": 1,
      "name": "Rock_Volcanic"
    },
    {
      "x": 2,
      "y": 3,
      "z": 1,
      "name": "Empty"
    },
    {
      "x": 2,
      "y": 0,
      "z": 2,
      "name": "Rock_Volcanic"
    },
    {
      "x": 2,
      "y": 1,
      "z": 2,
      "name": "Rock_Volcanic"
    },
    {
      "x": 2,
      "y": 2,
      "z": 2,
      "name": "Rock_Volcanic"
    },
    {
      "x": 2,
      "y": 3,
      "z": 2,
      "name": "Rock_Volcanic_Cracked_Lava"
    },
    {
      "x": 2,
      "y": 0,
      "z": 3,
      "name": "Rock_Volcanic"
    },
    {
      "x": 2,
      "y": 1,
      "z": 3,
      "name": "Rock_Volcanic"
    },
    {
      "x": 2,
      "y": 2,
      "z": 3,
      "name": "Rock_Volcanic"
    },
    {
      "x": 2,
      "y": 3,
      "z": 3,
      "name": "Rock_Volcanic_Cracked_Lava_Incandescent"
    },
    {
      "x": 2,
      "y": 0,
      "z": 4,
      "name": "Rock_Volcanic"
    },
    {
      "x": 2,
      "y": 1,
      "z": 4,
      "name": "Rock_Volcanic"
    },
    {
      "x": 2,
      "y": 2,
      "z": 4,
      "name": "Rock_Volcanic"
    },
    {
      "x": 2,
      "y": 3,
      "z": 4,
      "name": "Rock_Volcanic"
    },
    {
      "x": 2,
      "y": 0,
      "z": 5,
      "name": "Rock_Volcanic"
    },
    {
      "x": 2,
      "y": 1,
      "z": 5,
      "name": "Rock_Volcanic"
    },
    {
      "x": 2,
      "y": 2,
      "z": 5,
      "name": "Rock_Volcanic"
    },
    {
      "x": 2,
      "y": 3,
      "z": 5,
      "name": "Rock_Volcanic"
    },
    {
      "x": 2,
      "y": 4,
      "z": 5,
      "name": "Plant_Bramble_Dead_Lavathorn"
    },
    {
      "x": 2,
      "y": 0,
      "z": 6,
      "name": "Rock_Volcanic"
    },
    {
      "x": 2,
      "y": 1,
      "z": 6,
      "name": "Rock_Volcanic"
    },
    {
      "x": 2,
      "y": 2,
      "z": 6,
      "name": "Rock_Volcanic"
    },
    {
      "x": 2,
      "y": 3,
      "z": 6,
      "name": "Rock_Volcanic"
    },
    {
      "x": 2,
      "y": 0,
      "z": 7,
      "name": "Rock_Volcanic"
    },
    {
      "x": 2,
      "y": 1,
      "z": 7,
      "name": "Rock_Volcanic"
    },
    {
      "x": 2,
      "y": 2,
      "z": 7,
      "name": "Rock_Volcanic"
    },
    {
      "x": 2,
      "y": 3,
      "z": 7,
      "name": "Rock_Ice_Permafrost"
    },
    {
      "x": 2,
      "y": 4,
      "z": 7,
      "name": "Rock_Ice_Icicles"
    },
    {
      "x": 2,
      "y": 0,
      "z": 8,
      "name": "Rock_Volcanic"
    },
    {
      "x": 2,
      "y": 1,
      "z": 8,
      "name": "Rock_Volcanic"
    },
    {
      "x": 2,
      "y": 2,
      "z": 8,
      "name": "Rock_Volcanic"
    },
    {
      "x": 2,
      "y": 3,
      "z": 8,
      "name": "Rubble_Ice_Medium",
      "support": 15
    },
    {
      "x": 2,
      "y": 0,
      "z": 9,
      "name": "Rock_Volcanic"
    },
    {
      "x": 2,
      "y": 1,
      "z": 9,
      "name": "Rock_Volcanic"
    },
    {
      "x": 2,
      "y": 2,
      "z": 9,
      "name": "Rock_Volcanic"
    },
    {
      "x": 2,
      "y": 0,
      "z": 10,
      "name": "Rock_Volcanic"
    },
    {
      "x": 2,
      "y": 1,
      "z": 10,
      "name": "Rock_Volcanic"
    },
    {
      "x": 2,
      "y": 2,
      "z": 10,
      "name": "Rock_Volcanic"
    },
    {
      "x": 2,
      "y": 0,
      "z": 11,
      "name": "Rock_Volcanic"
    },
    {
      "x": 2,
      "y": 1,
      "z": 11,
      "name": "Rock_Volcanic"
    },
    {
      "x": 2,
      "y": 0,
      "z": 12,
      "name": "Rock_Volcanic"
    },
    {
      "x": 3,
      "y": 0,
      "z": -13,
      "name": "Rock_Volcanic"
    },
    {
      "x": 3,
      "y": 0,
      "z": -12,
      "name": "Rock_Volcanic"
    },
    {
      "x": 3,
      "y": 0,
      "z": -11,
      "name": "Rock_Volcanic"
    },
    {
      "x": 3,
      "y": 0,
      "z": -10,
      "name": "Rock_Volcanic"
    },
    {
      "x": 3,
      "y": 0,
      "z": -9,
      "name": "Rock_Volcanic"
    },
    {
      "x": 3,
      "y": 0,
      "z": -8,
      "name": "Rock_Ice_Permafrost"
    },
    {
      "x": 3,
      "y": 1,
      "z": -8,
      "name": "Rock_Ice_Icicles"
    },
    {
      "x": 3,
      "y": 1,
      "z": -7,
      "name": "Rock_Ice_Permafrost"
    },
    {
      "x": 3,
      "y": 0,
      "z": -6,
      "name": "Rock_Volcanic"
    },
    {
      "x": 3,
      "y": 1,
      "z": -6,
      "name": "Rock_Ice_Permafrost"
    },
    {
      "x": 3,
      "y": 2,
      "z": -6,
      "name": "Rock_Ice_Icicles"
    },
    {
      "x": 3,
      "y": 0,
      "z": -5,
      "name": "Rock_Volcanic"
    },
    {
      "x": 3,
      "y": 1,
      "z": -5,
      "name": "Rock_Volcanic"
    },
    {
      "x": 3,
      "y": 2,
      "z": -5,
      "name": "Rock_Volcanic"
    },
    {
      "x": 3,
      "y": 0,
      "z": -4,
      "name": "Rock_Volcanic"
    },
    {
      "x": 3,
      "y": 1,
      "z": -4,
      "name": "Rock_Volcanic"
    },
    {
      "x": 3,
      "y": 2,
      "z": -4,
      "name": "Rock_Volcanic"
    },
    {
      "x": 3,
      "y": 0,
      "z": -3,
      "name": "Rock_Volcanic"
    },
    {
      "x": 3,
      "y": 1,
      "z": -3,
      "name": "Rock_Volcanic"
    },
    {
      "x": 3,
      "y": 2,
      "z": -3,
      "name": "Rock_Volcanic"
    },
    {
      "x": 3,
      "y": 3,
      "z": -3,
      "name": "Rubble_Ice",
      "support": 15
    },
    {
      "x": 3,
      "y": 0,
      "z": -2,
      "name": "Rock_Volcanic"
    },
    {
      "x": 3,
      "y": 1,
      "z": -2,
      "name": "Rock_Volcanic"
    },
    {
      "x": 3,
      "y": 2,
      "z": -2,
      "name": "Rock_Volcanic"
    },
    {
      "x": 3,
      "y": 3,
      "z": -2,
      "name": "Rock_Ice_Permafrost"
    },
    {
      "x": 3,
      "y": 0,
      "z": -1,
      "name": "Rock_Volcanic"
    },
    {
      "x": 3,
      "y": 1,
      "z": -1,
      "name": "Rock_Volcanic"
    },
    {
      "x": 3,
      "y": 2,
      "z": -1,
      "name": "Rock_Volcanic"
    },
    {
      "x": 3,
      "y": 3,
      "z": -1,
      "name": "Rock_Volcanic"
    },
    {
      "x": 3,
      "y": 0,
      "z": 0,
      "name": "Rock_Volcanic"
    },
    {
      "x": 3,
      "y": 1,
      "z": 0,
      "name": "Rock_Volcanic"
    },
    {
      "x": 3,
      "y": 2,
      "z": 0,
      "name": "Rock_Volcanic"
    },
    {
      "x": 3,
      "y": 3,
      "z": 0,
      "name": "Rock_Volcanic_Cracked_Lava"
    },
    {
      "x": 3,
      "y": 0,
      "z": 1,
      "name": "Rock_Volcanic"
    },
    {
      "x": 3,
      "y": 1,
      "z": 1,
      "name": "Rock_Volcanic"
    },
    {
      "x": 3,
      "y": 2,
      "z": 1,
      "name": "Rock_Volcanic"
    },
    {
      "x": 3,
      "y": 3,
      "z": 1,
      "name": "Rock_Volcanic"
    },
    {
      "x": 3,
      "y": 4,
      "z": 1,
      "name": "Plant_Bramble_Dead_Lavathorn"
    },
    {
      "x": 3,
      "y": 0,
      "z": 2,
      "name": "Rock_Volcanic"
    },
    {
      "x": 3,
      "y": 1,
      "z": 2,
      "name": "Rock_Volcanic"
    },
    {
      "x": 3,
      "y": 2,
      "z": 2,
      "name": "Rock_Volcanic"
    },
    {
      "x": 3,
      "y": 3,
      "z": 2,
      "name": "Rock_Volcanic"
    },
    {
      "x": 3,
      "y": 0,
      "z": 3,
      "name": "Rock_Volcanic"
    },
    {
      "x": 3,
      "y": 1,
      "z": 3,
      "name": "Rock_Volcanic"
    },
    {
      "x": 3,
      "y": 2,
      "z": 3,
      "name": "Rock_Volcanic"
    },
    {
      "x": 3,
      "y": 3,
      "z": 3,
      "name": "Rock_Volcanic"
    },
    {
      "x": 3,
      "y": 4,
      "z": 3,
      "name": "Plant_Crop_Mushroom_Glowing_Blue"
    },
    {
      "x": 3,
      "y": 0,
      "z": 4,
      "name": "Rock_Volcanic"
    },
    {
      "x": 3,
      "y": 1,
      "z": 4,
      "name": "Rock_Volcanic"
    },
    {
      "x": 3,
      "y": 2,
      "z": 4,
      "name": "Rock_Volcanic"
    },
    {
      "x": 3,
      "y": 3,
      "z": 4,
      "name": "Rock_Volcanic"
    },
    {
      "x": 3,
      "y": 0,
      "z": 5,
      "name": "Rock_Volcanic"
    },
    {
      "x": 3,
      "y": 1,
      "z": 5,
      "name": "Rock_Volcanic"
    },
    {
      "x": 3,
      "y": 2,
      "z": 5,
      "name": "Rock_Volcanic"
    },
    {
      "x": 3,
      "y": 3,
      "z": 5,
      "name": "Rock_Volcanic"
    },
    {
      "x": 3,
      "y": 0,
      "z": 6,
      "name": "Rock_Volcanic"
    },
    {
      "x": 3,
      "y": 1,
      "z": 6,
      "name": "Rock_Volcanic"
    },
    {
      "x": 3,
      "y": 2,
      "z": 6,
      "name": "Rock_Volcanic"
    },
    {
      "x": 3,
      "y": 3,
      "z": 6,
      "name": "Rock_Volcanic"
    },
    {
      "x": 3,
      "y": 0,
      "z": 7,
      "name": "Rock_Volcanic"
    },
    {
      "x": 3,
      "y": 1,
      "z": 7,
      "name": "Rock_Volcanic"
    },
    {
      "x": 3,
      "y": 2,
      "z": 7,
      "name": "Rock_Volcanic"
    },
    {
      "x": 3,
      "y": 3,
      "z": 7,
      "name": "Rock_Volcanic"
    },
    {
      "x": 3,
      "y": 0,
      "z": 8,
      "name": "Rock_Volcanic"
    },
    {
      "x": 3,
      "y": 1,
      "z": 8,
      "name": "Rock_Volcanic"
    },
    {
      "x": 3,
      "y": 2,
      "z": 8,
      "name": "Rock_Volcanic"
    },
    {
      "x": 3,
      "y": 0,
      "z": 9,
      "name": "Rock_Volcanic"
    },
    {
      "x": 3,
      "y": 1,
      "z": 9,
      "name": "Rock_Volcanic"
    },
    {
      "x": 3,
      "y": 2,
      "z": 9,
      "name": "Rock_Ice_Permafrost"
    },
    {
      "x": 3,
      "y": 3,
      "z": 9,
      "name": "Rock_Ice_Icicles"
    },
    {
      "x": 3,
      "y": 0,
      "z": 10,
      "name": "Rock_Volcanic"
    },
    {
      "x": 3,
      "y": 1,
      "z": 10,
      "name": "Rock_Volcanic"
    },
    {
      "x": 3,
      "y": 2,
      "z": 10,
      "name": "Rock_Volcanic"
    },
    {
      "x": 3,
      "y": 0,
      "z": 11,
      "name": "Rock_Volcanic"
    },
    {
      "x": 3,
      "y": 1,
      "z": 11,
      "name": "Rock_Volcanic"
    },
    {
      "x": 3,
      "y": 2,
      "z": 11,
      "name": "Rubble_Ice_Medium",
      "support": 15
    },
    {
      "x": 3,
      "y": 0,
      "z": 12,
      "name": "Rock_Volcanic"
    },
    {
      "x": 4,
      "y": 0,
      "z": -12,
      "name": "Rock_Volcanic"
    },
    {
      "x": 4,
      "y": 0,
      "z": -11,
      "name": "Rock_Volcanic"
    },
    {
      "x": 4,
      "y": 0,
      "z": -10,
      "name": "Rock_Volcanic"
    },
    {
      "x": 4,
      "y": 0,
      "z": -9,
      "name": "Rock_Volcanic"
    },
    {
      "x": 4,
      "y": 0,
      "z": -8,
      "name": "Rock_Ice_Permafrost"
    },
    {
      "x": 4,
      "y": 0,
      "z": -7,
      "name": "Rock_Volcanic"
    },
    {
      "x": 4,
      "y": 1,
      "z": -7,
      "name": "Rock_Ice_Permafrost"
    },
    {
      "x": 4,
      "y": 0,
      "z": -6,
      "name": "Rock_Volcanic"
    },
    {
      "x": 4,
      "y": 1,
      "z": -6,
      "name": "Rock_Ice_Permafrost"
    },
    {
      "x": 4,
      "y": 2,
      "z": -6,
      "name": "Rock_Ice_Stalactite_Large"
    },
    {
      "x": 4,
      "y": 3,
      "z": -6,
      "name": "Rock_Ice_Stalactite_Large",
      "filler": 1024
    },
    {
      "x": 4,
      "y": 0,
      "z": -5,
      "name": "Rock_Volcanic"
    },
    {
      "x": 4,
      "y": 1,
      "z": -5,
      "name": "Rock_Volcanic"
    },
    {
      "x": 4,
      "y": 0,
      "z": -4,
      "name": "Rock_Volcanic"
    },
    {
      "x": 4,
      "y": 1,
      "z": -4,
      "name": "Rock_Volcanic"
    },
    {
      "x": 4,
      "y": 2,
      "z": -4,
      "name": "Rock_Volcanic"
    },
    {
      "x": 4,
      "y": 0,
      "z": -3,
      "name": "Rock_Volcanic"
    },
    {
      "x": 4,
      "y": 1,
      "z": -3,
      "name": "Rock_Volcanic"
    },
    {
      "x": 4,
      "y": 2,
      "z": -3,
      "name": "Rock_Volcanic"
    },
    {
      "x": 4,
      "y": 0,
      "z": -2,
      "name": "Rock_Volcanic"
    },
    {
      "x": 4,
      "y": 1,
      "z": -2,
      "name": "Rock_Volcanic"
    },
    {
      "x": 4,
      "y": 2,
      "z": -2,
      "name": "Rock_Ice_Permafrost"
    },
    {
      "x": 4,
      "y": 3,
      "z": -2,
      "name": "Rock_Ice_Stalactite_Large"
    },
    {
      "x": 4,
      "y": 4,
      "z": -2,
      "name": "Rock_Ice_Stalactite_Large",
      "filler": 1024
    },
    {
      "x": 4,
      "y": 0,
      "z": -1,
      "name": "Rock_Volcanic"
    },
    {
      "x": 4,
      "y": 1,
      "z": -1,
      "name": "Rock_Volcanic"
    },
    {
      "x": 4,
      "y": 2,
      "z": -1,
      "name": "Rock_Volcanic"
    },
    {
      "x": 4,
      "y": 3,
      "z": -1,
      "name": "Rock_Volcanic"
    },
    {
      "x": 4,
      "y": 0,
      "z": 0,
      "name": "Rock_Volcanic"
    },
    {
      "x": 4,
      "y": 1,
      "z": 0,
      "name": "Rock_Volcanic"
    },
    {
      "x": 4,
      "y": 2,
      "z": 0,
      "name": "Rock_Volcanic"
    },
    {
      "x": 4,
      "y": 3,
      "z": 0,
      "name": "Rock_Volcanic"
    },
    {
      "x": 4,
      "y": 0,
      "z": 1,
      "name": "Rock_Volcanic"
    },
    {
      "x": 4,
      "y": 1,
      "z": 1,
      "name": "Rock_Volcanic"
    },
    {
      "x": 4,
      "y": 2,
      "z": 1,
      "name": "Rock_Volcanic"
    },
    {
      "x": 4,
      "y": 3,
      "z": 1,
      "name": "Rock_Volcanic"
    },
    {
      "x": 4,
      "y": 4,
      "z": 1,
      "name": "Rock_Volcanic"
    },
    {
      "x": 4,
      "y": 0,
      "z": 2,
      "name": "Rock_Volcanic"
    },
    {
      "x": 4,
      "y": 1,
      "z": 2,
      "name": "Rock_Volcanic"
    },
    {
      "x": 4,
      "y": 2,
      "z": 2,
      "name": "Rock_Volcanic"
    },
    {
      "x": 4,
      "y": 3,
      "z": 2,
      "name": "Rock_Volcanic"
    },
    {
      "x": 4,
      "y": 4,
      "z": 2,
      "name": "Rock_Volcanic"
    },
    {
      "x": 4,
      "y": 5,
      "z": 2,
      "name": "Rock_Volcanic"
    },
    {
      "x": 4,
      "y": 6,
      "z": 2,
      "name": "Rock_Volcanic"
    },
    {
      "x": 4,
      "y": 7,
      "z": 2,
      "name": "Rock_Volcanic"
    },
    {
      "x": 4,
      "y": 8,
      "z": 2,
      "name": "Rock_Volcanic"
    },
    {
      "x": 4,
      "y": 9,
      "z": 2,
      "name": "Rock_Volcanic"
    },
    {
      "x": 4,
      "y": 0,
      "z": 3,
      "name": "Rock_Volcanic"
    },
    {
      "x": 4,
      "y": 1,
      "z": 3,
      "name": "Rock_Volcanic"
    },
    {
      "x": 4,
      "y": 2,
      "z": 3,
      "name": "Rock_Volcanic"
    },
    {
      "x": 4,
      "y": 3,
      "z": 3,
      "name": "Rock_Volcanic"
    },
    {
      "x": 4,
      "y": 0,
      "z": 4,
      "name": "Rock_Volcanic"
    },
    {
      "x": 4,
      "y": 1,
      "z": 4,
      "name": "Rock_Volcanic"
    },
    {
      "x": 4,
      "y": 2,
      "z": 4,
      "name": "Rock_Volcanic"
    },
    {
      "x": 4,
      "y": 3,
      "z": 4,
      "name": "Rock_Volcanic"
    },
    {
      "x": 4,
      "y": 0,
      "z": 5,
      "name": "Rock_Volcanic"
    },
    {
      "x": 4,
      "y": 1,
      "z": 5,
      "name": "Rock_Volcanic"
    },
    {
      "x": 4,
      "y": 2,
      "z": 5,
      "name": "Rock_Volcanic"
    },
    {
      "x": 4,
      "y": 3,
      "z": 5,
      "name": "Rock_Volcanic"
    },
    {
      "x": 4,
      "y": 0,
      "z": 6,
      "name": "Rock_Volcanic"
    },
    {
      "x": 4,
      "y": 1,
      "z": 6,
      "name": "Rock_Volcanic"
    },
    {
      "x": 4,
      "y": 2,
      "z": 6,
      "name": "Rock_Volcanic"
    },
    {
      "x": 4,
      "y": 3,
      "z": 6,
      "name": "Rock_Ice_Permafrost"
    },
    {
      "x": 4,
      "y": 4,
      "z": 6,
      "name": "Rock_Ice_Icicles"
    },
    {
      "x": 4,
      "y": 0,
      "z": 7,
      "name": "Rock_Volcanic"
    },
    {
      "x": 4,
      "y": 1,
      "z": 7,
      "name": "Rock_Volcanic"
    },
    {
      "x": 4,
      "y": 2,
      "z": 7,
      "name": "Rock_Volcanic"
    },
    {
      "x": 4,
      "y": 0,
      "z": 8,
      "name": "Rock_Volcanic"
    },
    {
      "x": 4,
      "y": 1,
      "z": 8,
      "name": "Rock_Volcanic"
    },
    {
      "x": 4,
      "y": 2,
      "z": 8,
      "name": "Rock_Volcanic"
    },
    {
      "x": 4,
      "y": 0,
      "z": 9,
      "name": "Rock_Volcanic"
    },
    {
      "x": 4,
      "y": 1,
      "z": 9,
      "name": "Rock_Volcanic"
    },
    {
      "x": 4,
      "y": 2,
      "z": 9,
      "name": "Rock_Ice_Permafrost"
    },
    {
      "x": 4,
      "y": 0,
      "z": 10,
      "name": "Rock_Volcanic"
    },
    {
      "x": 4,
      "y": 1,
      "z": 10,
      "name": "Rock_Ice_Permafrost"
    },
    {
      "x": 4,
      "y": 2,
      "z": 10,
      "name": "Rock_Ice_Icicles"
    },
    {
      "x": 4,
      "y": 1,
      "z": 11,
      "name": "Rock_Volcanic"
    },
    {
      "x": 4,
      "y": 0,
      "z": 12,
      "name": "Rock_Volcanic"
    },
    {
      "x": 5,
      "y": 0,
      "z": -8,
      "name": "Rock_Volcanic"
    },
    {
      "x": 5,
      "y": 0,
      "z": -7,
      "name": "Rock_Volcanic"
    },
    {
      "x": 5,
      "y": 0,
      "z": -6,
      "name": "Rock_Volcanic"
    },
    {
      "x": 5,
      "y": 1,
      "z": -6,
      "name": "Rock_Ice_Permafrost"
    },
    {
      "x": 5,
      "y": 0,
      "z": -5,
      "name": "Rock_Volcanic"
    },
    {
      "x": 5,
      "y": 1,
      "z": -5,
      "name": "Rock_Volcanic"
    },
    {
      "x": 5,
      "y": 0,
      "z": -4,
      "name": "Rock_Volcanic"
    },
    {
      "x": 5,
      "y": 1,
      "z": -4,
      "name": "Rock_Volcanic"
    },
    {
      "x": 5,
      "y": 2,
      "z": -4,
      "name": "Rock_Volcanic"
    },
    {
      "x": 5,
      "y": 0,
      "z": -3,
      "name": "Rock_Volcanic"
    },
    {
      "x": 5,
      "y": 1,
      "z": -3,
      "name": "Rock_Volcanic"
    },
    {
      "x": 5,
      "y": 2,
      "z": -3,
      "name": "Rock_Volcanic"
    },
    {
      "x": 5,
      "y": 0,
      "z": -2,
      "name": "Rock_Volcanic"
    },
    {
      "x": 5,
      "y": 1,
      "z": -2,
      "name": "Rock_Volcanic"
    },
    {
      "x": 5,
      "y": 2,
      "z": -2,
      "name": "Rock_Volcanic"
    },
    {
      "x": 5,
      "y": 0,
      "z": -1,
      "name": "Rock_Volcanic"
    },
    {
      "x": 5,
      "y": 1,
      "z": -1,
      "name": "Rock_Volcanic"
    },
    {
      "x": 5,
      "y": 2,
      "z": -1,
      "name": "Rock_Volcanic"
    },
    {
      "x": 5,
      "y": 0,
      "z": 0,
      "name": "Rock_Volcanic"
    },
    {
      "x": 5,
      "y": 1,
      "z": 0,
      "name": "Rock_Volcanic"
    },
    {
      "x": 5,
      "y": 2,
      "z": 0,
      "name": "Rock_Volcanic"
    },
    {
      "x": 5,
      "y": 3,
      "z": 0,
      "name": "Rock_Volcanic"
    },
    {
      "x": 5,
      "y": 0,
      "z": 1,
      "name": "Rock_Volcanic"
    },
    {
      "x": 5,
      "y": 1,
      "z": 1,
      "name": "Rock_Volcanic"
    },
    {
      "x": 5,
      "y": 2,
      "z": 1,
      "name": "Rock_Volcanic"
    },
    {
      "x": 5,
      "y": 3,
      "z": 1,
      "name": "Rock_Volcanic"
    },
    {
      "x": 5,
      "y": 4,
      "z": 1,
      "name": "Rubble_Ice",
      "support": 15
    },
    {
      "x": 5,
      "y": 0,
      "z": 2,
      "name": "Rock_Volcanic"
    },
    {
      "x": 5,
      "y": 1,
      "z": 2,
      "name": "Rock_Volcanic"
    },
    {
      "x": 5,
      "y": 2,
      "z": 2,
      "name": "Rock_Volcanic"
    },
    {
      "x": 5,
      "y": 3,
      "z": 2,
      "name": "Rock_Volcanic"
    },
    {
      "x": 5,
      "y": 4,
      "z": 2,
      "name": "Rock_Volcanic"
    },
    {
      "x": 5,
      "y": 5,
      "z": 2,
      "name": "OrbisGalactic_Kyber_Ore_Volcanic"
    },
    {
      "x": 5,
      "y": 6,
      "z": 2,
      "name": "Rock_Volcanic"
    },
    {
      "x": 5,
      "y": 7,
      "z": 2,
      "name": "Rock_Volcanic"
    },
    {
      "x": 5,
      "y": 0,
      "z": 3,
      "name": "Rock_Volcanic"
    },
    {
      "x": 5,
      "y": 1,
      "z": 3,
      "name": "Rock_Volcanic"
    },
    {
      "x": 5,
      "y": 2,
      "z": 3,
      "name": "Rock_Volcanic"
    },
    {
      "x": 5,
      "y": 3,
      "z": 3,
      "name": "Rock_Volcanic"
    },
    {
      "x": 5,
      "y": 4,
      "z": 3,
      "name": "Rock_Volcanic"
    },
    {
      "x": 5,
      "y": 0,
      "z": 4,
      "name": "Rock_Volcanic"
    },
    {
      "x": 5,
      "y": 1,
      "z": 4,
      "name": "Rock_Volcanic"
    },
    {
      "x": 5,
      "y": 2,
      "z": 4,
      "name": "Rock_Volcanic"
    },
    {
      "x": 5,
      "y": 3,
      "z": 4,
      "name": "Rock_Volcanic"
    },
    {
      "x": 5,
      "y": 0,
      "z": 5,
      "name": "Rock_Volcanic"
    },
    {
      "x": 5,
      "y": 1,
      "z": 5,
      "name": "Rock_Volcanic"
    },
    {
      "x": 5,
      "y": 2,
      "z": 5,
      "name": "Rock_Volcanic"
    },
    {
      "x": 5,
      "y": 3,
      "z": 5,
      "name": "Rock_Ice_Permafrost"
    },
    {
      "x": 5,
      "y": 0,
      "z": 6,
      "name": "Rock_Volcanic"
    },
    {
      "x": 5,
      "y": 1,
      "z": 6,
      "name": "Rock_Volcanic"
    },
    {
      "x": 5,
      "y": 2,
      "z": 6,
      "name": "Rock_Ice_Permafrost"
    },
    {
      "x": 5,
      "y": 3,
      "z": 6,
      "name": "Rock_Ice_Stalactite_Large"
    },
    {
      "x": 5,
      "y": 4,
      "z": 6,
      "name": "Rock_Ice_Stalactite_Large",
      "filler": 1024
    },
    {
      "x": 5,
      "y": 0,
      "z": 7,
      "name": "Rock_Volcanic"
    },
    {
      "x": 5,
      "y": 1,
      "z": 7,
      "name": "Rock_Volcanic"
    },
    {
      "x": 5,
      "y": 2,
      "z": 7,
      "name": "Rock_Volcanic"
    },
    {
      "x": 5,
      "y": 0,
      "z": 8,
      "name": "Rock_Volcanic"
    },
    {
      "x": 5,
      "y": 1,
      "z": 8,
      "name": "Rock_Volcanic"
    },
    {
      "x": 5,
      "y": 2,
      "z": 8,
      "name": "Rock_Volcanic"
    },
    {
      "x": 5,
      "y": 3,
      "z": 8,
      "name": "Rubble_Ice",
      "support": 15
    },
    {
      "x": 5,
      "y": 0,
      "z": 9,
      "name": "Rock_Volcanic"
    },
    {
      "x": 5,
      "y": 1,
      "z": 9,
      "name": "Rock_Volcanic"
    },
    {
      "x": 5,
      "y": 2,
      "z": 9,
      "name": "Rock_Volcanic"
    },
    {
      "x": 5,
      "y": 0,
      "z": 10,
      "name": "Rock_Volcanic"
    },
    {
      "x": 5,
      "y": 1,
      "z": 10,
      "name": "Rock_Volcanic"
    },
    {
      "x": 5,
      "y": 0,
      "z": 11,
      "name": "Rock_Volcanic"
    },
    {
      "x": 6,
      "y": 0,
      "z": -8,
      "name": "Rock_Volcanic"
    },
    {
      "x": 6,
      "y": 0,
      "z": -7,
      "name": "Rock_Volcanic"
    },
    {
      "x": 6,
      "y": 0,
      "z": -6,
      "name": "Rock_Volcanic"
    },
    {
      "x": 6,
      "y": 1,
      "z": -6,
      "name": "Rock_Volcanic"
    },
    {
      "x": 6,
      "y": 0,
      "z": -5,
      "name": "Rock_Volcanic"
    },
    {
      "x": 6,
      "y": 1,
      "z": -5,
      "name": "Rock_Volcanic"
    },
    {
      "x": 6,
      "y": 0,
      "z": -4,
      "name": "Rock_Volcanic"
    },
    {
      "x": 6,
      "y": 1,
      "z": -4,
      "name": "Rock_Volcanic"
    },
    {
      "x": 6,
      "y": 0,
      "z": -3,
      "name": "Rock_Volcanic"
    },
    {
      "x": 6,
      "y": 1,
      "z": -3,
      "name": "Rock_Volcanic"
    },
    {
      "x": 6,
      "y": 0,
      "z": -2,
      "name": "Rock_Volcanic"
    },
    {
      "x": 6,
      "y": 1,
      "z": -2,
      "name": "Rock_Volcanic"
    },
    {
      "x": 6,
      "y": 2,
      "z": -2,
      "name": "Rock_Volcanic"
    },
    {
      "x": 6,
      "y": 0,
      "z": -1,
      "name": "Rock_Volcanic"
    },
    {
      "x": 6,
      "y": 1,
      "z": -1,
      "name": "Rock_Volcanic"
    },
    {
      "x": 6,
      "y": 2,
      "z": -1,
      "name": "Rock_Volcanic"
    },
    {
      "x": 6,
      "y": 0,
      "z": 0,
      "name": "Rock_Volcanic"
    },
    {
      "x": 6,
      "y": 1,
      "z": 0,
      "name": "Rock_Volcanic"
    },
    {
      "x": 6,
      "y": 2,
      "z": 0,
      "name": "Rock_Volcanic"
    },
    {
      "x": 6,
      "y": 0,
      "z": 1,
      "name": "Rock_Volcanic"
    },
    {
      "x": 6,
      "y": 1,
      "z": 1,
      "name": "Rock_Volcanic"
    },
    {
      "x": 6,
      "y": 2,
      "z": 1,
      "name": "Rock_Volcanic"
    },
    {
      "x": 6,
      "y": 3,
      "z": 1,
      "name": "Rock_Volcanic"
    },
    {
      "x": 6,
      "y": 4,
      "z": 1,
      "name": "Rock_Volcanic"
    },
    {
      "x": 6,
      "y": 0,
      "z": 2,
      "name": "Rock_Volcanic"
    },
    {
      "x": 6,
      "y": 1,
      "z": 2,
      "name": "Rock_Volcanic"
    },
    {
      "x": 6,
      "y": 2,
      "z": 2,
      "name": "Rock_Volcanic"
    },
    {
      "x": 6,
      "y": 3,
      "z": 2,
      "name": "Rock_Volcanic"
    },
    {
      "x": 6,
      "y": 4,
      "z": 2,
      "name": "Rock_Volcanic"
    },
    {
      "x": 6,
      "y": 5,
      "z": 2,
      "name": "Rock_Volcanic"
    },
    {
      "x": 6,
      "y": 0,
      "z": 3,
      "name": "Rock_Volcanic"
    },
    {
      "x": 6,
      "y": 1,
      "z": 3,
      "name": "Rock_Volcanic"
    },
    {
      "x": 6,
      "y": 2,
      "z": 3,
      "name": "Rock_Volcanic"
    },
    {
      "x": 6,
      "y": 3,
      "z": 3,
      "name": "Rock_Volcanic"
    },
    {
      "x": 6,
      "y": 4,
      "z": 3,
      "name": "Rock_Volcanic"
    },
    {
      "x": 6,
      "y": 5,
      "z": 3,
      "name": "Rock_Volcanic"
    },
    {
      "x": 6,
      "y": 0,
      "z": 4,
      "name": "Rock_Volcanic"
    },
    {
      "x": 6,
      "y": 1,
      "z": 4,
      "name": "Rock_Volcanic"
    },
    {
      "x": 6,
      "y": 2,
      "z": 4,
      "name": "Rock_Volcanic"
    },
    {
      "x": 6,
      "y": 3,
      "z": 4,
      "name": "Rock_Volcanic"
    },
    {
      "x": 6,
      "y": 0,
      "z": 5,
      "name": "Rock_Volcanic"
    },
    {
      "x": 6,
      "y": 1,
      "z": 5,
      "name": "Rock_Volcanic"
    },
    {
      "x": 6,
      "y": 2,
      "z": 5,
      "name": "Rock_Ice_Permafrost"
    },
    {
      "x": 6,
      "y": 3,
      "z": 5,
      "name": "Rock_Ice_Icicles"
    },
    {
      "x": 6,
      "y": 0,
      "z": 6,
      "name": "Rock_Volcanic"
    },
    {
      "x": 6,
      "y": 1,
      "z": 6,
      "name": "Rock_Volcanic"
    },
    {
      "x": 6,
      "y": 2,
      "z": 6,
      "name": "Rock_Volcanic"
    },
    {
      "x": 6,
      "y": 0,
      "z": 7,
      "name": "Rock_Volcanic"
    },
    {
      "x": 6,
      "y": 1,
      "z": 7,
      "name": "Rock_Volcanic"
    },
    {
      "x": 6,
      "y": 2,
      "z": 7,
      "name": "Rock_Volcanic"
    },
    {
      "x": 6,
      "y": 0,
      "z": 8,
      "name": "Rock_Volcanic"
    },
    {
      "x": 6,
      "y": 1,
      "z": 8,
      "name": "Rock_Volcanic"
    },
    {
      "x": 6,
      "y": 0,
      "z": 9,
      "name": "Rock_Volcanic"
    },
    {
      "x": 6,
      "y": 1,
      "z": 9,
      "name": "Rock_Volcanic"
    },
    {
      "x": 6,
      "y": 0,
      "z": 10,
      "name": "Rock_Volcanic"
    },
    {
      "x": 6,
      "y": 0,
      "z": 11,
      "name": "Rock_Volcanic"
    },
    {
      "x": 6,
      "y": 0,
      "z": 12,
      "name": "Rock_Volcanic"
    },
    {
      "x": 7,
      "y": 0,
      "z": -7,
      "name": "Rock_Volcanic"
    },
    {
      "x": 7,
      "y": 0,
      "z": -6,
      "name": "Rock_Volcanic"
    },
    {
      "x": 7,
      "y": 0,
      "z": -5,
      "name": "Rock_Volcanic"
    },
    {
      "x": 7,
      "y": 1,
      "z": -5,
      "name": "Rock_Volcanic"
    },
    {
      "x": 7,
      "y": 0,
      "z": -4,
      "name": "Rock_Volcanic"
    },
    {
      "x": 7,
      "y": 1,
      "z": -4,
      "name": "Rock_Volcanic"
    },
    {
      "x": 7,
      "y": 0,
      "z": -3,
      "name": "Rock_Volcanic"
    },
    {
      "x": 7,
      "y": 1,
      "z": -3,
      "name": "Rock_Volcanic"
    },
    {
      "x": 7,
      "y": 0,
      "z": -2,
      "name": "Rock_Volcanic"
    },
    {
      "x": 7,
      "y": 1,
      "z": -2,
      "name": "Rock_Volcanic"
    },
    {
      "x": 7,
      "y": 2,
      "z": -2,
      "name": "Rubble_Ice_Medium",
      "support": 15
    },
    {
      "x": 7,
      "y": 0,
      "z": -1,
      "name": "Rock_Volcanic"
    },
    {
      "x": 7,
      "y": 1,
      "z": -1,
      "name": "Rock_Volcanic"
    },
    {
      "x": 7,
      "y": 2,
      "z": -1,
      "name": "Rock_Volcanic"
    },
    {
      "x": 7,
      "y": 0,
      "z": 0,
      "name": "Rock_Volcanic"
    },
    {
      "x": 7,
      "y": 1,
      "z": 0,
      "name": "Rock_Volcanic"
    },
    {
      "x": 7,
      "y": 2,
      "z": 0,
      "name": "Rock_Ice_Permafrost"
    },
    {
      "x": 7,
      "y": 3,
      "z": 0,
      "name": "Rock_Ice_Stalactite_Large"
    },
    {
      "x": 7,
      "y": 4,
      "z": 0,
      "name": "Rock_Ice_Stalactite_Large",
      "filler": 1024
    },
    {
      "x": 7,
      "y": 0,
      "z": 1,
      "name": "Rock_Volcanic"
    },
    {
      "x": 7,
      "y": 1,
      "z": 1,
      "name": "Rock_Volcanic"
    },
    {
      "x": 7,
      "y": 2,
      "z": 1,
      "name": "Rock_Ice_Permafrost"
    },
    {
      "x": 7,
      "y": 0,
      "z": 2,
      "name": "Rock_Volcanic"
    },
    {
      "x": 7,
      "y": 1,
      "z": 2,
      "name": "Rock_Volcanic"
    },
    {
      "x": 7,
      "y": 2,
      "z": 2,
      "name": "Rock_Volcanic"
    },
    {
      "x": 7,
      "y": 0,
      "z": 3,
      "name": "Rock_Volcanic"
    },
    {
      "x": 7,
      "y": 1,
      "z": 3,
      "name": "Rock_Volcanic"
    },
    {
      "x": 7,
      "y": 2,
      "z": 3,
      "name": "Rock_Volcanic"
    },
    {
      "x": 7,
      "y": 3,
      "z": 3,
      "name": "Rubble_Ice_Medium",
      "support": 15
    },
    {
      "x": 7,
      "y": 0,
      "z": 4,
      "name": "Rock_Volcanic"
    },
    {
      "x": 7,
      "y": 1,
      "z": 4,
      "name": "Rock_Volcanic"
    },
    {
      "x": 7,
      "y": 2,
      "z": 4,
      "name": "Rock_Volcanic"
    },
    {
      "x": 7,
      "y": 0,
      "z": 5,
      "name": "Rock_Volcanic"
    },
    {
      "x": 7,
      "y": 1,
      "z": 5,
      "name": "Rock_Volcanic"
    },
    {
      "x": 7,
      "y": 2,
      "z": 5,
      "name": "Rock_Ice_Permafrost"
    },
    {
      "x": 7,
      "y": 3,
      "z": 5,
      "name": "Rock_Ice_Stalactite_Large"
    },
    {
      "x": 7,
      "y": 4,
      "z": 5,
      "name": "Rock_Ice_Stalactite_Large",
      "filler": 1024
    },
    {
      "x": 7,
      "y": 0,
      "z": 6,
      "name": "Rock_Volcanic"
    },
    {
      "x": 7,
      "y": 1,
      "z": 6,
      "name": "Rock_Volcanic"
    },
    {
      "x": 7,
      "y": 2,
      "z": 6,
      "name": "Rock_Volcanic"
    },
    {
      "x": 7,
      "y": 0,
      "z": 7,
      "name": "Rock_Volcanic"
    },
    {
      "x": 7,
      "y": 1,
      "z": 7,
      "name": "Rock_Volcanic"
    },
    {
      "x": 7,
      "y": 0,
      "z": 8,
      "name": "Rock_Volcanic"
    },
    {
      "x": 7,
      "y": 1,
      "z": 8,
      "name": "Rock_Ice_Permafrost"
    },
    {
      "x": 7,
      "y": 2,
      "z": 8,
      "name": "Rock_Ice_Stalactite_Large"
    },
    {
      "x": 7,
      "y": 3,
      "z": 8,
      "name": "Rock_Ice_Stalactite_Large",
      "filler": 1024
    },
    {
      "x": 7,
      "y": 0,
      "z": 9,
      "name": "Rock_Ice_Permafrost"
    },
    {
      "x": 7,
      "y": 0,
      "z": 10,
      "name": "Rock_Volcanic"
    },
    {
      "x": 7,
      "y": 1,
      "z": 10,
      "name": "Rubble_Ice_Medium",
      "support": 15
    },
    {
      "x": 7,
      "y": 0,
      "z": 11,
      "name": "Rock_Volcanic"
    },
    {
      "x": 7,
      "y": 0,
      "z": 12,
      "name": "Rock_Volcanic"
    },
    {
      "x": 7,
      "y": 0,
      "z": 13,
      "name": "Rock_Volcanic"
    },
    {
      "x": 8,
      "y": 0,
      "z": -7,
      "name": "Rock_Volcanic"
    },
    {
      "x": 8,
      "y": 0,
      "z": -6,
      "name": "Rock_Volcanic"
    },
    {
      "x": 8,
      "y": 0,
      "z": -5,
      "name": "Rock_Volcanic"
    },
    {
      "x": 8,
      "y": 0,
      "z": -4,
      "name": "Rock_Volcanic"
    },
    {
      "x": 8,
      "y": 0,
      "z": -3,
      "name": "Rock_Volcanic"
    },
    {
      "x": 8,
      "y": 1,
      "z": -3,
      "name": "Rock_Volcanic"
    },
    {
      "x": 8,
      "y": 0,
      "z": -2,
      "name": "Rock_Volcanic"
    },
    {
      "x": 8,
      "y": 0,
      "z": -1,
      "name": "Rock_Volcanic"
    },
    {
      "x": 8,
      "y": 1,
      "z": -1,
      "name": "Rock_Volcanic"
    },
    {
      "x": 8,
      "y": 0,
      "z": 0,
      "name": "Rock_Volcanic"
    },
    {
      "x": 8,
      "y": 1,
      "z": 0,
      "name": "Rock_Ice_Permafrost"
    },
    {
      "x": 8,
      "y": 0,
      "z": 1,
      "name": "Rock_Volcanic"
    },
    {
      "x": 8,
      "y": 1,
      "z": 1,
      "name": "Rock_Volcanic"
    },
    {
      "x": 8,
      "y": 2,
      "z": 1,
      "name": "Rock_Ice_Permafrost"
    },
    {
      "x": 8,
      "y": 3,
      "z": 1,
      "name": "Rock_Ice_Icicles"
    },
    {
      "x": 8,
      "y": 0,
      "z": 2,
      "name": "Rock_Volcanic"
    },
    {
      "x": 8,
      "y": 1,
      "z": 2,
      "name": "Rock_Volcanic"
    },
    {
      "x": 8,
      "y": 2,
      "z": 2,
      "name": "Rock_Ice_Permafrost"
    },
    {
      "x": 8,
      "y": 0,
      "z": 3,
      "name": "Rock_Volcanic"
    },
    {
      "x": 8,
      "y": 1,
      "z": 3,
      "name": "Rock_Volcanic"
    },
    {
      "x": 8,
      "y": 2,
      "z": 3,
      "name": "Rock_Volcanic"
    },
    {
      "x": 8,
      "y": 0,
      "z": 4,
      "name": "Rock_Volcanic"
    },
    {
      "x": 8,
      "y": 1,
      "z": 4,
      "name": "Rock_Volcanic"
    },
    {
      "x": 8,
      "y": 2,
      "z": 4,
      "name": "Rock_Volcanic"
    },
    {
      "x": 8,
      "y": 0,
      "z": 5,
      "name": "Rock_Volcanic"
    },
    {
      "x": 8,
      "y": 1,
      "z": 5,
      "name": "Rock_Volcanic"
    },
    {
      "x": 8,
      "y": 2,
      "z": 5,
      "name": "Rock_Volcanic"
    },
    {
      "x": 8,
      "y": 0,
      "z": 6,
      "name": "Rock_Volcanic"
    },
    {
      "x": 8,
      "y": 1,
      "z": 6,
      "name": "Rock_Volcanic"
    },
    {
      "x": 8,
      "y": 0,
      "z": 7,
      "name": "Rock_Volcanic"
    },
    {
      "x": 8,
      "y": 1,
      "z": 7,
      "name": "Rock_Volcanic"
    },
    {
      "x": 8,
      "y": 0,
      "z": 8,
      "name": "Rock_Volcanic"
    },
    {
      "x": 8,
      "y": 0,
      "z": 9,
      "name": "Rock_Volcanic"
    },
    {
      "x": 8,
      "y": 0,
      "z": 10,
      "name": "Rock_Volcanic"
    },
    {
      "x": 8,
      "y": 0,
      "z": 12,
      "name": "Rock_Volcanic"
    },
    {
      "x": 9,
      "y": 0,
      "z": -8,
      "name": "Rock_Volcanic"
    },
    {
      "x": 9,
      "y": 0,
      "z": -7,
      "name": "Rock_Volcanic"
    },
    {
      "x": 9,
      "y": 0,
      "z": -6,
      "name": "Rock_Volcanic"
    },
    {
      "x": 9,
      "y": 0,
      "z": -4,
      "name": "Rock_Volcanic"
    },
    {
      "x": 9,
      "y": 0,
      "z": -3,
      "name": "Rock_Volcanic"
    },
    {
      "x": 9,
      "y": 0,
      "z": -2,
      "name": "Rock_Volcanic"
    },
    {
      "x": 9,
      "y": 0,
      "z": -1,
      "name": "Rock_Volcanic"
    },
    {
      "x": 9,
      "y": 0,
      "z": 0,
      "name": "Rock_Volcanic"
    },
    {
      "x": 9,
      "y": 1,
      "z": 0,
      "name": "Rock_Volcanic"
    },
    {
      "x": 9,
      "y": 0,
      "z": 1,
      "name": "Rock_Volcanic"
    },
    {
      "x": 9,
      "y": 1,
      "z": 1,
      "name": "Rock_Ice_Permafrost"
    },
    {
      "x": 9,
      "y": 0,
      "z": 2,
      "name": "Rock_Volcanic"
    },
    {
      "x": 9,
      "y": 1,
      "z": 2,
      "name": "Rock_Ice_Permafrost"
    },
    {
      "x": 9,
      "y": 2,
      "z": 2,
      "name": "Rock_Ice_Stalactite_Large"
    },
    {
      "x": 9,
      "y": 3,
      "z": 2,
      "name": "Rock_Ice_Stalactite_Large",
      "filler": 1024
    },
    {
      "x": 9,
      "y": 0,
      "z": 3,
      "name": "Rock_Volcanic"
    },
    {
      "x": 9,
      "y": 1,
      "z": 3,
      "name": "Rock_Volcanic"
    },
    {
      "x": 9,
