{
  "version": 8,
  "blockIdVersion": 10,
  "anchorX": 0,
  "anchorY": 0,
  "anchorZ": 0,
  "blocks": [
    {
      "x": -22,
      "y": 0,
      "z": -9,
      "name": "Rock_Ice_Permafrost"
    },
    {
      "x": -22,
      "y": 0,
      "z": -8,
      "name": "Rock_Ice_Permafrost"
    },
    {
      "x": -22,
      "y": 1,
      "z": -8,
      "name": "Rock_Ice_Stalactite_Large"
    },
    {
      "x": -22,
      "y": 0,
      "z": -7,
      "name": "Rock_Ice_Permafrost"
    },
    {
      "x": -22,
      "y": 1,
      "z": -7,
      "name": "Rock_Ice_Stalactite_Large"
    },
    {
      "x": -22,
      "y": 0,
      "z": -6,
      "name": "Rock_Ice_Permafrost"
    },
    {
      "x": -22,
      "y": 1,
      "z": -6,
      "name": "Rock_Ice_Stalactite_Large"
    },
    {
      "x": -22,
      "y": 0,
      "z": -5,
      "name": "Rock_Ice_Permafrost"
    },
    {
      "x": -22,
      "y": 0,
      "z": -4,
      "name": "Rock_Ice_Permafrost"
    },
    {
      "x": -22,
      "y": 1,
      "z": -4,
      "name": "Rock_Ice_Permafrost"
    },
    {
      "x": -22,
      "y": 0,
      "z": -3,
      "name": "Rock_Ice_Permafrost"
    },
    {
      "x": -22,
      "y": 1,
      "z": -3,
      "name": "Rock_Ice_Permafrost"
    },
    {
      "x": -22,
      "y": 2,
      "z": -3,
      "name": "Rock_Ice_Icicles"
    },
    {
      "x": -22,
      "y": 0,
      "z": -2,
      "name": "Rock_Ice_Permafrost"
    },
    {
      "x": -22,
      "y": 1,
      "z": -2,
      "name": "Rock_Ice_Permafrost"
    },
    {
      "x": -22,
      "y": 0,
      "z": -1,
      "name": "Rock_Ice_Permafrost"
    },
    {
      "x": -22,
      "y": 1,
      "z": -1,
      "name": "Rock_Ice_Permafrost"
    },
    {
      "x": -22,
      "y": 0,
      "z": 0,
      "name": "Rock_Ice_Permafrost"
    },
    {
      "x": -22,
      "y": 1,
      "z": 0,
      "name": "Rock_Ice_Permafrost"
    },
    {
      "x": -22,
      "y": 0,
      "z": 1,
      "name": "Rock_Ice_Permafrost"
    },
    {
      "x": -22,
      "y": 0,
      "z": 2,
      "name": "Rock_Ice_Permafrost"
    },
    {
      "x": -22,
      "y": 1,
      "z": 2,
      "name": "Rock_Ice_Stalactite_Large"
    },
    {
      "x": -21,
      "y": 0,
      "z": -10,
      "name": "Rock_Ice_Permafrost"
    },
    {
      "x": -21,
      "y": 0,
      "z": -9,
      "name": "Rock_Ice_Permafrost"
    },
    {
      "x": -21,
      "y": 0,
      "z": -8,
      "name": "Rock_Ice_Permafrost"
    },
    {
      "x": -21,
      "y": 1,
      "z": -8,
      "name": "Rock_Ice_Permafrost"
    },
    {
      "x": -21,
      "y": 0,
      "z": -7,
      "name": "Rock_Ice_Permafrost"
    },
    {
      "x": -21,
      "y": 1,
      "z": -7,
      "name": "Rock_Ice_Permafrost"
    },
    {
      "x": -21,
      "y": 2,
      "z": -7,
      "name": "Rock_Ice_Stalactite_Large"
    },
    {
      "x": -21,
      "y": 0,
      "z": -6,
      "name": "Rock_Ice_Permafrost"
    },
    {
      "x": -21,
      "y": 1,
      "z": -6,
      "name": "Rock_Ice_Permafrost"
    },
    {
      "x": -21,
      "y": 0,
      "z": -5,
      "name": "Rock_Ice_Permafrost"
    },
    {
      "x": -21,
      "y": 1,
      "z": -5,
      "name": "Rock_Ice_Permafrost"
    },
    {
      "x": -21,
      "y": 2,
      "z": -5,
      "name": "Rock_Ice_Permafrost"
    },
    {
      "x": -21,
      "y": 0,
      "z": -4,
      "name": "Rock_Ice_Permafrost"
    },
    {
      "x": -21,
      "y": 1,
      "z": -4,
      "name": "Rock_Ice_Permafrost"
    },
    {
      "x": -21,
      "y": 2,
      "z": -4,
      "name": "Rock_Ice_Permafrost"
    },
    {
      "x": -21,
      "y": 0,
      "z": -3,
      "name": "Rock_Ice_Permafrost"
    },
    {
      "x": -21,
      "y": 1,
      "z": -3,
      "name": "Rock_Ice_Permafrost"
    },
    {
      "x": -21,
      "y": 2,
      "z": -3,
      "name": "Rock_Ice_Permafrost"
    },
    {
      "x": -21,
      "y": 0,
      "z": -2,
      "name": "Rock_Ice_Permafrost"
    },
    {
      "x": -21,
      "y": 1,
      "z": -2,
      "name": "Rock_Ice_Permafrost"
    },
    {
      "x": -21,
      "y": 2,
      "z": -2,
      "name": "Rock_Ice_Permafrost"
    },
    {
      "x": -21,
      "y": 3,
      "z": -2,
      "name": "Rock_Ice_Permafrost"
    },
    {
      "x": -21,
      "y": 0,
      "z": -1,
      "name": "Rock_Ice_Permafrost"
    },
    {
      "x": -21,
      "y": 1,
      "z": -1,
      "name": "Rock_Ice_Permafrost"
    },
    {
      "x": -21,
      "y": 2,
      "z": -1,
      "name": "Rock_Ice_Permafrost"
    },
    {
      "x": -21,
      "y": 3,
      "z": -1,
      "name": "Rock_Ice_Permafrost"
    },
    {
      "x": -21,
      "y": 4,
      "z": -1,
      "name": "Rock_Ice_Icicles"
    },
    {
      "x": -21,
      "y": 0,
      "z": 0,
      "name": "Rock_Ice_Permafrost"
    },
    {
      "x": -21,
      "y": 1,
      "z": 0,
      "name": "Rock_Ice_Permafrost"
    },
    {
      "x": -21,
      "y": 2,
      "z": 0,
      "name": "Rock_Ice_Permafrost"
    },
    {
      "x": -21,
      "y": 3,
      "z": 0,
      "name": "Rock_Ice_Permafrost"
    },
    {
      "x": -21,
      "y": 0,
      "z": 1,
      "name": "Rock_Ice_Permafrost"
    },
    {
      "x": -21,
      "y": 1,
      "z": 1,
      "name": "Rock_Ice_Permafrost"
    },
    {
      "x": -21,
      "y": 2,
      "z": 1,
      "name": "Rock_Ice_Permafrost"
    },
    {
      "x": -21,
      "y": 3,
      "z": 1,
      "name": "Rock_Ice_Permafrost"
    },
    {
      "x": -21,
      "y": 0,
      "z": 2,
      "name": "Rock_Ice_Permafrost"
    },
    {
      "x": -21,
      "y": 1,
      "z": 2,
      "name": "Rock_Ice_Permafrost"
    },
    {
      "x": -21,
      "y": 2,
      "z": 2,
      "name": "Rock_Ice_Permafrost"
    },
    {
      "x": -21,
      "y": 3,
      "z": 2,
      "name": "Rock_Ice_Stalactite_Large"
    },
    {
      "x": -21,
      "y": 0,
      "z": 3,
      "name": "Rock_Ice_Permafrost"
    },
    {
      "x": -21,
      "y": 1,
      "z": 3,
      "name": "Rock_Ice_Permafrost"
    },
    {
      "x": -21,
      "y": 2,
      "z": 3,
      "name": "Rock_Ice_Permafrost"
    },
    {
      "x": -21,
      "y": 3,
      "z": 3,
      "name": "Rock_Ice_Stalactite_Large"
    },
    {
      "x": -21,
      "y": 0,
      "z": 4,
      "name": "Rock_Ice_Permafrost"
    },
    {
      "x": -21,
      "y": 1,
      "z": 4,
      "name": "Rock_Ice_Permafrost"
    },
    {
      "x": -21,
      "y": 2,
      "z": 4,
      "name": "Rock_Ice_Permafrost"
    },
    {
      "x": -21,
      "y": 0,
      "z": 5,
      "name": "Rock_Ice_Permafrost"
    },
    {
      "x": -21,
      "y": 1,
      "z": 5,
      "name": "Rock_Ice_Permafrost"
    },
    {
      "x": -21,
      "y": 0,
      "z": 6,
      "name": "Rock_Ice_Permafrost"
    },
    {
      "x": -21,
      "y": 1,
      "z": 6,
      "name": "Rock_Ice_Permafrost"
    },
    {
      "x": -21,
      "y": 0,
      "z": 7,
      "name": "Rock_Ice_Permafrost"
    },
    {
      "x": -21,
      "y": 0,
      "z": 8,
      "name": "Rock_Ice_Permafrost"
    },
    {
      "x": -20,
      "y": 0,
      "z": -12,
      "name": "Rock_Ice_Permafrost"
    },
    {
      "x": -20,
      "y": 0,
      "z": -11,
      "name": "Rock_Ice_Permafrost"
    },
    {
      "x": -20,
      "y": 0,
      "z": -10,
      "name": "Rock_Ice_Permafrost"
    },
    {
      "x": -20,
      "y": 1,
      "z": -10,
      "name": "Rock_Ice_Permafrost"
    },
    {
      "x": -20,
      "y": 0,
      "z": -9,
      "name": "Rock_Ice_Permafrost"
    },
    {
      "x": -20,
      "y": 1,
      "z": -9,
      "name": "Rock_Ice_Permafrost"
    },
    {
      "x": -20,
      "y": 0,
      "z": -8,
      "name": "Rock_Ice_Permafrost"
    },
    {
      "x": -20,
      "y": 1,
      "z": -8,
      "name": "Rock_Ice_Permafrost"
    },
    {
      "x": -20,
      "y": 2,
      "z": -8,
      "name": "Rock_Ice_Permafrost"
    },
    {
      "x": -20,
      "y": 0,
      "z": -7,
      "name": "Rock_Ice_Permafrost"
    },
    {
      "x": -20,
      "y": 1,
      "z": -7,
      "name": "Rock_Ice_Permafrost"
    },
    {
      "x": -20,
      "y": 2,
      "z": -7,
      "name": "Rock_Ice_Permafrost"
    },
    {
      "x": -20,
      "y": 0,
      "z": -6,
      "name": "Rock_Ice_Permafrost"
    },
    {
      "x": -20,
      "y": 1,
      "z": -6,
      "name": "Rock_Ice_Permafrost"
    },
    {
      "x": -20,
      "y": 2,
      "z": -6,
      "name": "Rock_Ice_Permafrost"
    },
    {
      "x": -20,
      "y": 3,
      "z": -6,
      "name": "Rock_Ice_Permafrost"
    },
    {
      "x": -20,
      "y": 0,
      "z": -5,
      "name": "Rock_Ice_Permafrost"
    },
    {
      "x": -20,
      "y": 1,
      "z": -5,
      "name": "Rock_Ice_Permafrost"
    },
    {
      "x": -20,
      "y": 2,
      "z": -5,
      "name": "Rock_Ice_Permafrost"
    },
    {
      "x": -20,
      "y": 3,
      "z": -5,
      "name": "Rock_Ice_Permafrost"
    },
    {
      "x": -20,
      "y": 0,
      "z": -4,
      "name": "Rock_Ice_Permafrost"
    },
    {
      "x": -20,
      "y": 1,
      "z": -4,
      "name": "Rock_Ice_Permafrost"
    },
    {
      "x": -20,
      "y": 2,
      "z": -4,
      "name": "Rock_Ice_Permafrost"
    },
    {
      "x": -20,
      "y": 3,
      "z": -4,
      "name": "Rock_Ice_Permafrost"
    },
    {
      "x": -20,
      "y": 4,
      "z": -4,
      "name": "Rock_Ice_Permafrost"
    },
    {
      "x": -20,
      "y": 0,
      "z": -3,
      "name": "Rock_Ice_Permafrost"
    },
    {
      "x": -20,
      "y": 1,
      "z": -3,
      "name": "Rock_Ice_Permafrost"
    },
    {
      "x": -20,
      "y": 2,
      "z": -3,
      "name": "Rock_Ice_Permafrost"
    },
    {
      "x": -20,
      "y": 3,
      "z": -3,
      "name": "Rock_Ice_Permafrost"
    },
    {
      "x": -20,
      "y": 4,
      "z": -3,
      "name": "Rock_Ice_Permafrost"
    },
    {
      "x": -20,
      "y": 0,
      "z": -2,
      "name": "Rock_Ice_Permafrost"
    },
    {
      "x": -20,
      "y": 1,
      "z": -2,
      "name": "Rock_Ice_Permafrost"
    },
    {
      "x": -20,
      "y": 2,
      "z": -2,
      "name": "Rock_Ice_Permafrost"
    },
    {
      "x": -20,
      "y": 3,
      "z": -2,
      "name": "Rock_Ice_Permafrost"
    },
    {
      "x": -20,
      "y": 4,
      "z": -2,
      "name": "Rock_Ice_Permafrost"
    },
    {
      "x": -20,
      "y": 0,
      "z": -1,
      "name": "Rock_Ice_Permafrost"
    },
    {
      "x": -20,
      "y": 1,
      "z": -1,
      "name": "Rock_Ice_Permafrost"
    },
    {
      "x": -20,
      "y": 2,
      "z": -1,
      "name": "Rock_Ice_Permafrost"
    },
    {
      "x": -20,
      "y": 3,
      "z": -1,
      "name": "Rock_Ice_Permafrost"
    },
    {
      "x": -20,
      "y": 4,
      "z": -1,
      "name": "Rock_Ice_Permafrost"
    },
    {
      "x": -20,
      "y": 5,
      "z": -1,
      "name": "Rock_Ice_Permafrost"
    },
    {
      "x": -20,
      "y": 0,
      "z": 0,
      "name": "Rock_Ice_Permafrost"
    },
    {
      "x": -20,
      "y": 1,
      "z": 0,
      "name": "Rock_Ice_Permafrost"
    },
    {
      "x": -20,
      "y": 2,
      "z": 0,
      "name": "Rock_Ice_Permafrost"
    },
    {
      "x": -20,
      "y": 3,
      "z": 0,
      "name": "Rock_Ice_Permafrost"
    },
    {
      "x": -20,
      "y": 4,
      "z": 0,
      "name": "Rock_Ice_Permafrost"
    },
    {
      "x": -20,
      "y": 5,
      "z": 0,
      "name": "Rock_Ice_Permafrost"
    },
    {
      "x": -20,
      "y": 0,
      "z": 1,
      "name": "Rock_Ice_Permafrost"
    },
    {
      "x": -20,
      "y": 1,
      "z": 1,
      "name": "Rock_Ice_Permafrost"
    },
    {
      "x": -20,
      "y": 2,
      "z": 1,
      "name": "Rock_Ice_Permafrost"
    },
    {
      "x": -20,
      "y": 3,
      "z": 1,
      "name": "Rock_Ice_Permafrost"
    },
    {
      "x": -20,
      "y": 4,
      "z": 1,
      "name": "Rock_Ice_Permafrost"
    },
    {
      "x": -20,
      "y": 0,
      "z": 2,
      "name": "Rock_Ice_Permafrost"
    },
    {
      "x": -20,
      "y": 1,
      "z": 2,
      "name": "Rock_Ice_Permafrost"
    },
    {
      "x": -20,
      "y": 2,
      "z": 2,
      "name": "Rock_Ice_Permafrost"
    },
    {
      "x": -20,
      "y": 3,
      "z": 2,
      "name": "Rock_Ice_Permafrost"
    },
    {
      "x": -20,
      "y": 4,
      "z": 2,
      "name": "Rock_Ice_Permafrost"
    },
    {
      "x": -20,
      "y": 0,
      "z": 3,
      "name": "Rock_Ice_Permafrost"
    },
    {
      "x": -20,
      "y": 1,
      "z": 3,
      "name": "Rock_Ice_Permafrost"
    },
    {
      "x": -20,
      "y": 2,
      "z": 3,
      "name": "Rock_Ice_Permafrost"
    },
    {
      "x": -20,
      "y": 3,
      "z": 3,
      "name": "Rock_Ice_Permafrost"
    },
    {
      "x": -20,
      "y": 4,
      "z": 3,
      "name": "Rock_Ice_Permafrost"
    },
    {
      "x": -20,
      "y": 0,
      "z": 4,
      "name": "Rock_Ice_Permafrost"
    },
    {
      "x": -20,
      "y": 1,
      "z": 4,
      "name": "Rock_Ice_Permafrost"
    },
    {
      "x": -20,
      "y": 2,
      "z": 4,
      "name": "Rock_Ice_Permafrost"
    },
    {
      "x": -20,
      "y": 3,
      "z": 4,
      "name": "Rock_Ice_Permafrost"
    },
    {
      "x": -20,
      "y": 4,
      "z": 4,
      "name": "Rock_Ice_Icicles"
    },
    {
      "x": -20,
      "y": 0,
      "z": 5,
      "name": "Rock_Ice_Permafrost"
    },
    {
      "x": -20,
      "y": 1,
      "z": 5,
      "name": "Rock_Ice_Permafrost"
    },
    {
      "x": -20,
      "y": 2,
      "z": 5,
      "name": "Rock_Ice_Permafrost"
    },
    {
      "x": -20,
      "y": 3,
      "z": 5,
      "name": "Rock_Ice_Permafrost"
    },
    {
      "x": -20,
      "y": 0,
      "z": 6,
      "name": "Rock_Ice_Permafrost"
    },
    {
      "x": -20,
      "y": 1,
      "z": 6,
      "name": "Rock_Ice_Permafrost"
    },
    {
      "x": -20,
      "y": 2,
      "z": 6,
      "name": "Rock_Ice_Permafrost"
    },
    {
      "x": -20,
      "y": 0,
      "z": 7,
      "name": "Rock_Ice_Permafrost"
    },
    {
      "x": -20,
      "y": 1,
      "z": 7,
      "name": "Rock_Ice_Permafrost"
    },
    {
      "x": -20,
      "y": 2,
      "z": 7,
      "name": "Rock_Ice_Permafrost"
    },
    {
      "x": -20,
      "y": 0,
      "z": 8,
      "name": "Rock_Ice_Permafrost"
    },
    {
      "x": -20,
      "y": 1,
      "z": 8,
      "name": "Rock_Ice_Permafrost"
    },
    {
      "x": -20,
      "y": 0,
      "z": 9,
      "name": "Rock_Ice_Permafrost"
    },
    {
      "x": -20,
      "y": 0,
      "z": 10,
      "name": "Rock_Ice_Permafrost"
    },
    {
      "x": -19,
      "y": 0,
      "z": -13,
      "name": "Rock_Ice_Permafrost"
    },
    {
      "x": -19,
      "y": 0,
      "z": -12,
      "name": "Rock_Ice_Permafrost"
    },
    {
      "x": -19,
      "y": 1,
      "z": -12,
      "name": "Rock_Ice_Stalactite_Large"
    },
    {
      "x": -19,
      "y": 0,
      "z": -11,
      "name": "Rock_Ice_Permafrost"
    },
    {
      "x": -19,
      "y": 1,
      "z": -11,
      "name": "Rock_Ice_Permafrost"
    },
    {
      "x": -19,
      "y": 0,
      "z": -10,
      "name": "Rock_Ice_Permafrost"
    },
    {
      "x": -19,
      "y": 1,
      "z": -10,
      "name": "Rock_Ice_Permafrost"
    },
    {
      "x": -19,
      "y": 2,
      "z": -10,
      "name": "Rock_Ice_Permafrost"
    },
    {
      "x": -19,
      "y": 0,
      "z": -9,
      "name": "Rock_Ice_Permafrost"
    },
    {
      "x": -19,
      "y": 1,
      "z": -9,
      "name": "Rock_Ice_Permafrost"
    },
    {
      "x": -19,
      "y": 2,
      "z": -9,
      "name": "Rock_Ice_Permafrost"
    },
    {
      "x": -19,
      "y": 0,
      "z": -8,
      "name": "Rock_Ice_Permafrost"
    },
    {
      "x": -19,
      "y": 1,
      "z": -8,
      "name": "Rock_Ice_Permafrost"
    },
    {
      "x": -19,
      "y": 2,
      "z": -8,
      "name": "Rock_Ice_Permafrost"
    },
    {
      "x": -19,
      "y": 3,
      "z": -8,
      "name": "Rock_Ice_Permafrost"
    },
    {
      "x": -19,
      "y": 0,
      "z": -7,
      "name": "Rock_Ice_Permafrost"
    },
    {
      "x": -19,
      "y": 1,
      "z": -7,
      "name": "Rock_Ice_Permafrost"
    },
    {
      "x": -19,
      "y": 2,
      "z": -7,
      "name": "Rock_Ice_Permafrost"
    },
    {
      "x": -19,
      "y": 3,
      "z": -7,
      "name": "Rock_Ice_Permafrost"
    },
    {
      "x": -19,
      "y": 0,
      "z": -6,
      "name": "Rock_Ice_Permafrost"
    },
    {
      "x": -19,
      "y": 1,
      "z": -6,
      "name": "Rock_Ice_Permafrost"
    },
    {
      "x": -19,
      "y": 2,
      "z": -6,
      "name": "Rock_Ice_Permafrost"
    },
    {
      "x": -19,
      "y": 3,
      "z": -6,
      "name": "Rock_Ice_Permafrost"
    },
    {
      "x": -19,
      "y": 4,
      "z": -6,
      "name": "Rock_Ice_Permafrost"
    },
    {
      "x": -19,
      "y": 5,
      "z": -6,
      "name": "Rock_Ice_Stalactite_Large"
    },
    {
      "x": -19,
      "y": 0,
      "z": -5,
      "name": "Rock_Ice_Permafrost"
    },
    {
      "x": -19,
      "y": 1,
      "z": -5,
      "name": "Rock_Ice_Permafrost"
    },
    {
      "x": -19,
      "y": 2,
      "z": -5,
      "name": "Rock_Ice_Permafrost"
    },
    {
      "x": -19,
      "y": 3,
      "z": -5,
      "name": "Rock_Ice_Permafrost"
    },
    {
      "x": -19,
      "y": 4,
      "z": -5,
      "name": "Rock_Ice_Permafrost"
    },
    {
      "x": -19,
      "y": 0,
      "z": -4,
      "name": "Rock_Ice_Permafrost"
    },
    {
      "x": -19,
      "y": 1,
      "z": -4,
      "name": "Rock_Ice_Permafrost"
    },
    {
      "x": -19,
      "y": 2,
      "z": -4,
      "name": "Rock_Ice_Permafrost"
    },
    {
      "x": -19,
      "y": 3,
      "z": -4,
      "name": "Rock_Ice_Permafrost"
    },
    {
      "x": -19,
      "y": 4,
      "z": -4,
      "name": "Rock_Ice_Permafrost"
    },
    {
      "x": -19,
      "y": 5,
      "z": -4,
      "name": "Rock_Ice_Permafrost"
    },
    {
      "x": -19,
      "y": 0,
      "z": -3,
      "name": "Rock_Ice_Permafrost"
    },
    {
      "x": -19,
      "y": 1,
      "z": -3,
      "name": "Rock_Ice_Permafrost"
    },
    {
      "x": -19,
      "y": 2,
      "z": -3,
      "name": "Rock_Ice_Permafrost"
    },
    {
      "x": -19,
      "y": 3,
      "z": -3,
      "name": "Rock_Ice_Permafrost"
    },
    {
      "x": -19,
      "y": 4,
      "z": -3,
      "name": "Rock_Ice_Permafrost"
    },
    {
      "x": -19,
      "y": 5,
      "z": -3,
      "name": "Rock_Ice_Permafrost"
    },
    {
      "x": -19,
      "y": 0,
      "z": -2,
      "name": "Rock_Ice_Permafrost"
    },
    {
      "x": -19,
      "y": 1,
      "z": -2,
      "name": "Rock_Ice_Permafrost"
    },
    {
      "x": -19,
      "y": 2,
      "z": -2,
      "name": "Rock_Ice_Permafrost"
    },
    {
      "x": -19,
      "y": 3,
      "z": -2,
      "name": "Rock_Ice_Permafrost"
    },
    {
      "x": -19,
      "y": 4,
      "z": -2,
      "name": "Rock_Ice_Permafrost"
    },
    {
      "x": -19,
      "y": 5,
      "z": -2,
      "name": "Rock_Ice_Permafrost"
    },
    {
      "x": -19,
      "y": 6,
      "z": -2,
      "name": "Rock_Ice_Permafrost"
    },
    {
      "x": -19,
      "y": 7,
      "z": -2,
      "name": "Rock_Ice_Icicles"
    },
    {
      "x": -19,
      "y": 0,
      "z": -1,
      "name": "Rock_Ice_Permafrost"
    },
    {
      "x": -19,
      "y": 1,
      "z": -1,
      "name": "Rock_Ice_Permafrost"
    },
    {
      "x": -19,
      "y": 2,
      "z": -1,
      "name": "Rock_Ice_Permafrost"
    },
    {
      "x": -19,
      "y": 3,
      "z": -1,
      "name": "Rock_Ice_Permafrost"
    },
    {
      "x": -19,
      "y": 4,
      "z": -1,
      "name": "Rock_Ice_Permafrost"
    },
    {
      "x": -19,
      "y": 5,
      "z": -1,
      "name": "Rock_Ice_Permafrost"
    },
    {
      "x": -19,
      "y": 6,
      "z": -1,
      "name": "Rock_Ice_Permafrost"
    },
    {
      "x": -19,
      "y": 0,
      "z": 0,
      "name": "Rock_Ice_Permafrost"
    },
    {
      "x": -19,
      "y": 1,
      "z": 0,
      "name": "Rock_Ice_Permafrost"
    },
    {
      "x": -19,
      "y": 2,
      "z": 0,
      "name": "Rock_Ice_Permafrost"
    },
    {
      "x": -19,
      "y": 3,
      "z": 0,
      "name": "Rock_Ice_Permafrost"
    },
    {
      "x": -19,
      "y": 4,
      "z": 0,
      "name": "Rock_Ice_Permafrost"
    },
    {
      "x": -19,
      "y": 5,
      "z": 0,
      "name": "Rock_Ice_Permafrost"
    },
    {
      "x": -19,
      "y": 6,
      "z": 0,
      "name": "Rock_Ice_Permafrost"
    },
    {
      "x": -19,
      "y": 0,
      "z": 1,
      "name": "Rock_Ice_Permafrost"
    },
    {
      "x": -19,
      "y": 1,
      "z": 1,
      "name": "Rock_Ice_Permafrost"
    },
    {
      "x": -19,
      "y": 2,
      "z": 1,
      "name": "Rock_Ice_Permafrost"
    },
    {
      "x": -19,
      "y": 3,
      "z": 1,
      "name": "Rock_Ice_Permafrost"
    },
    {
      "x": -19,
      "y": 4,
      "z": 1,
      "name": "Rock_Ice_Permafrost"
    },
    {
      "x": -19,
      "y": 5,
      "z": 1,
      "name": "Rock_Ice_Permafrost"
    },
    {
      "x": -19,
      "y": 6,
      "z": 1,
      "name": "Rock_Ice_Permafrost"
    },
    {
      "x": -19,
      "y": 0,
      "z": 2,
      "name": "Rock_Ice_Permafrost"
    },
    {
      "x": -19,
      "y": 1,
      "z": 2,
      "name": "Rock_Ice_Permafrost"
    },
    {
      "x": -19,
      "y": 2,
      "z": 2,
      "name": "Rock_Ice_Permafrost"
    },
    {
      "x": -19,
      "y": 3,
      "z": 2,
      "name": "Rock_Ice_Permafrost"
    },
    {
      "x": -19,
      "y": 4,
      "z": 2,
      "name": "Rock_Ice_Permafrost"
    },
    {
      "x": -19,
      "y": 5,
      "z": 2,
      "name": "Rock_Ice_Permafrost"
    },
    {
      "x": -19,
      "y": 6,
      "z": 2,
      "name": "Rock_Ice_Permafrost"
    },
    {
      "x": -19,
      "y": 7,
      "z": 2,
      "name": "Rock_Ice_Stalactite_Large"
    },
    {
      "x": -19,
      "y": 0,
      "z": 3,
      "name": "Rock_Ice_Permafrost"
    },
    {
      "x": -19,
      "y": 1,
      "z": 3,
      "name": "Rock_Ice_Permafrost"
    },
    {
      "x": -19,
      "y": 2,
      "z": 3,
      "name": "Rock_Ice_Permafrost"
    },
    {
      "x": -19,
      "y": 3,
      "z": 3,
      "name": "Rock_Ice_Permafrost"
    },
    {
      "x": -19,
      "y": 4,
      "z": 3,
      "name": "Rock_Ice_Permafrost"
    },
    {
      "x": -19,
      "y": 5,
      "z": 3,
      "name": "Rock_Ice_Permafrost"
    },
    {
      "x": -19,
      "y": 0,
      "z": 4,
      "name": "Rock_Ice_Permafrost"
    },
    {
      "x": -19,
      "y": 1,
      "z": 4,
      "name": "Rock_Ice_Permafrost"
    },
    {
      "x": -19,
      "y": 2,
      "z": 4,
      "name": "Rock_Ice_Permafrost"
    },
    {
      "x": -19,
      "y": 3,
      "z": 4,
      "name": "Rock_Ice_Permafrost"
    },
    {
      "x": -19,
      "y": 4,
      "z": 4,
      "name": "Rock_Ice_Permafrost"
    },
    {
      "x": -19,
      "y": 5,
      "z": 4,
      "name": "Rock_Ice_Permafrost"
    },
    {
      "x": -19,
      "y": 0,
      "z": 5,
      "name": "Rock_Ice_Permafrost"
    },
    {
      "x": -19,
      "y": 1,
      "z": 5,
      "name": "Rock_Ice_Permafrost"
    },
    {
      "x": -19,
      "y": 2,
      "z": 5,
      "name": "Rock_Ice_Permafrost"
    },
    {
      "x": -19,
      "y": 3,
      "z": 5,
      "name": "Rock_Ice_Permafrost"
    },
    {
      "x": -19,
      "y": 4,
      "z": 5,
      "name": "Rock_Ice_Permafrost"
    },
    {
      "x": -19,
      "y": 5,
      "z": 5,
      "name": "Rock_Ice_Icicles"
    },
    {
      "x": -19,
      "y": 0,
      "z": 6,
      "name": "Rock_Ice_Permafrost"
    },
    {
      "x": -19,
      "y": 1,
      "z": 6,
      "name": "Rock_Ice_Permafrost"
    },
    {
      "x": -19,
      "y": 2,
      "z": 6,
      "name": "Rock_Ice_Permafrost"
    },
    {
      "x": -19,
      "y": 3,
      "z": 6,
      "name": "Rock_Ice_Permafrost"
    },
    {
      "x": -19,
      "y": 4,
      "z": 6,
      "name": "Rock_Ice_Permafrost"
    },
    {
      "x": -19,
      "y": 0,
      "z": 7,
      "name": "Rock_Ice_Permafrost"
    },
    {
      "x": -19,
      "y": 1,
      "z": 7,
      "name": "Rock_Ice_Permafrost"
    },
    {
      "x": -19,
      "y": 2,
      "z": 7,
      "name": "Rock_Ice_Permafrost"
    },
    {
      "x": -19,
      "y": 3,
      "z": 7,
      "name": "Rock_Ice_Permafrost"
    },
    {
      "x": -19,
      "y": 0,
      "z": 8,
      "name": "Rock_Ice_Permafrost"
    },
    {
      "x": -19,
      "y": 1,
      "z": 8,
      "name": "Rock_Ice_Permafrost"
    },
    {
      "x": -19,
      "y": 2,
      "z": 8,
      "name": "Rock_Ice_Permafrost"
    },
    {
      "x": -19,
      "y": 0,
      "z": 9,
      "name": "Rock_Ice_Permafrost"
    },
    {
      "x": -19,
      "y": 1,
      "z": 9,
      "name": "Rock_Ice_Permafrost"
    },
    {
      "x": -19,
      "y": 2,
      "z": 9,
      "name": "Rock_Ice_Permafrost"
    },
    {
      "x": -19,
      "y": 0,
      "z": 10,
      "name": "Rock_Ice_Permafrost"
    },
    {
      "x": -19,
      "y": 1,
      "z": 10,
      "name": "Rock_Ice_Permafrost"
    },
    {
      "x": -19,
      "y": 0,
      "z": 11,
      "name": "Rock_Ice_Permafrost"
    },
    {
      "x": -19,
      "y": 0,
      "z": 12,
      "name": "Rock_Ice_Permafrost"
    },
    {
      "x": -18,
      "y": 0,
      "z": -13,
      "name": "Rock_Ice_Permafrost"
    },
    {
      "x": -18,
      "y": 0,
      "z": -12,
      "name": "Rock_Ice_Permafrost"
    },
    {
      "x": -18,
      "y": 1,
      "z": -12,
      "name": "Rock_Ice_Permafrost"
    },
    {
      "x": -18,
      "y": 0,
      "z": -11,
      "name": "Rock_Ice_Permafrost"
    },
    {
      "x": -18,
      "y": 1,
      "z": -11,
      "name": "Rock_Ice_Permafrost"
    },
    {
      "x": -18,
      "y": 2,
      "z": -11,
      "name": "Rock_Ice_Permafrost"
    },
    {
      "x": -18,
      "y": 0,
      "z": -10,
      "name": "Rock_Ice_Permafrost"
    },
    {
      "x": -18,
      "y": 1,
      "z": -10,
      "name": "Rock_Ice_Permafrost"
    },
    {
      "x": -18,
      "y": 2,
      "z": -10,
      "name": "Rock_Ice_Permafrost"
    },
    {
      "x": -18,
      "y": 0,
      "z": -9,
      "name": "Rock_Ice_Permafrost"
    },
    {
      "x": -18,
      "y": 1,
      "z": -9,
      "name": "Rock_Ice_Permafrost"
    },
    {
      "x": -18,
      "y": 2,
      "z": -9,
      "name": "Rock_Ice_Permafrost"
    },
    {
      "x": -18,
      "y": 3,
      "z": -9,
      "name": "Rock_Ice_Permafrost"
    },
    {
      "x": -18,
      "y": 0,
      "z": -8,
      "name": "Rock_Ice_Permafrost"
    },
    {
      "x": -18,
      "y": 1,
      "z": -8,
      "name": "Rock_Ice_Permafrost"
    },
    {
      "x": -18,
      "y": 2,
      "z": -8,
      "name": "Rock_Ice_Permafrost"
    },
    {
      "x": -18,
      "y": 3,
      "z": -8,
      "name": "Rock_Ice_Permafrost"
    },
    {
      "x": -18,
      "y": 4,
      "z": -8,
      "name": "Rock_Ice_Permafrost"
    },
    {
      "x": -18,
      "y": 0,
      "z": -7,
      "name": "Rock_Ice_Permafrost"
    },
    {
      "x": -18,
      "y": 1,
      "z": -7,
      "name": "Rock_Ice_Permafrost"
    },
    {
      "x": -18,
      "y": 2,
      "z": -7,
      "name": "Rock_Ice_Permafrost"
    },
    {
      "x": -18,
      "y": 3,
      "z": -7,
      "name": "Rock_Ice_Permafrost"
    },
    {
      "x": -18,
      "y": 4,
      "z": -7,
      "name": "Rock_Ice_Permafrost"
    },
    {
      "x": -18,
      "y": 0,
      "z": -6,
      "name": "Rock_Ice_Permafrost"
    },
    {
      "x": -18,
      "y": 1,
      "z": -6,
      "name": "Rock_Ice_Permafrost"
    },
    {
      "x": -18,
      "y": 2,
      "z": -6,
      "name": "Rock_Ice_Permafrost"
    },
    {
      "x": -18,
      "y": 3,
      "z": -6,
      "name": "Rock_Ice_Permafrost"
    },
    {
      "x": -18,
      "y": 4,
      "z": -6,
      "name": "Rock_Ice_Permafrost"
    },
    {
      "x": -18,
      "y": 5,
      "z": -6,
      "name": "Rock_Ice_Permafrost"
    },
    {
      "x": -18,
      "y": 0,
      "z": -5,
      "name": "Rock_Ice_Permafrost"
    },
    {
      "x": -18,
      "y": 1,
      "z": -5,
      "name": "Rock_Ice_Permafrost"
    },
    {
      "x": -18,
      "y": 2,
      "z": -5,
      "name": "Rock_Ice_Permafrost"
    },
    {
      "x": -18,
      "y": 3,
      "z": -5,
      "name": "Rock_Ice_Permafrost"
    },
    {
      "x": -18,
      "y": 4,
      "z": -5,
      "name": "Rock_Ice_Permafrost"
    },
    {
      "x": -18,
      "y": 5,
      "z": -5,
      "name": "Rock_Ice_Permafrost"
    },
    {
      "x": -18,
      "y": 6,
      "z": -5,
      "name": "Rock_Ice_Permafrost"
    },
    {
      "x": -18,
      "y": 0,
      "z": -4,
      "name": "Rock_Ice_Permafrost"
    },
    {
      "x": -18,
      "y": 1,
      "z": -4,
      "name": "Rock_Ice_Permafrost"
    },
    {
      "x": -18,
      "y": 2,
      "z": -4,
      "name": "Rock_Ice_Permafrost"
    },
    {
      "x": -18,
      "y": 3,
      "z": -4,
      "name": "Rock_Ice_Permafrost"
    },
    {
      "x": -18,
      "y": 4,
      "z": -4,
      "name": "Rock_Ice_Permafrost"
    },
    {
      "x": -18,
      "y": 5,
      "z": -4,
      "name": "Rock_Ice_Permafrost"
    },
    {
      "x": -18,
      "y": 6,
      "z": -4,
      "name": "Rock_Ice_Permafrost"
    },
    {
      "x": -18,
      "y": 0,
      "z": -3,
      "name": "Rock_Ice_Permafrost"
    },
    {
      "x": -18,
      "y": 1,
      "z": -3,
      "name": "Rock_Ice_Permafrost"
    },
    {
      "x": -18,
      "y": 2,
      "z": -3,
      "name": "Rock_Ice_Permafrost"
    },
    {
      "x": -18,
      "y": 3,
      "z": -3,
      "name": "Rock_Ice_Permafrost"
    },
    {
      "x": -18,
      "y": 4,
      "z": -3,
      "name": "Rock_Ice_Permafrost"
    },
    {
      "x": -18,
      "y": 5,
      "z": -3,
      "name": "Rock_Ice_Permafrost"
    },
    {
      "x": -18,
      "y": 6,
      "z": -3,
      "name": "Rock_Ice_Permafrost"
    },
    {
      "x": -18,
      "y": 7,
      "z": -3,
      "name": "Rock_Ice_Permafrost"
    },
    {
      "x": -18,
      "y": 0,
      "z": -2,
      "name": "Rock_Ice_Permafrost"
    },
    {
      "x": -18,
      "y": 1,
      "z": -2,
      "name": "Rock_Ice_Permafrost"
    },
    {
      "x": -18,
      "y": 2,
      "z": -2,
      "name": "Rock_Ice_Permafrost"
    },
    {
      "x": -18,
      "y": 3,
      "z": -2,
      "name": "Rock_Ice_Permafrost"
    },
    {
      "x": -18,
      "y": 4,
      "z": -2,
      "name": "Rock_Ice_Permafrost"
    },
    {
      "x": -18,
      "y": 5,
      "z": -2,
      "name": "Rock_Ice_Permafrost"
    },
    {
      "x": -18,
      "y": 6,
      "z": -2,
      "name": "Rock_Ice_Permafrost"
    },
    {
      "x": -18,
      "y": 7,
      "z": -2,
      "name": "Rock_Ice_Permafrost"
    },
    {
      "x": -18,
      "y": 8,
      "z": -2,
      "name": "Rock_Ice_Stalactite_Large"
    },
    {
      "x": -18,
      "y": 9,
      "z": -2,
      "name": "Rock_Ice_Stalactite_Large",
      "filler": 1024
    },
    {
      "x": -18,
      "y": 0,
      "z": -1,
      "name": "Rock_Ice_Permafrost"
    },
    {
      "x": -18,
      "y": 1,
      "z": -1,
      "name": "Rock_Ice_Permafrost"
    },
    {
      "x": -18,
      "y": 2,
      "z": -1,
      "name": "Rock_Ice_Permafrost"
    },
    {
      "x": -18,
      "y": 3,
      "z": -1,
      "name": "Rock_Ice_Permafrost"
    },
    {
      "x": -18,
      "y": 4,
      "z": -1,
      "name": "Rock_Ice_Permafrost"
    },
    {
      "x": -18,
      "y": 5,
      "z": -1,
      "name": "Rock_Ice_Permafrost"
    },
    {
      "x": -18,
      "y": 6,
      "z": -1,
      "name": "Rock_Ice_Permafrost"
    },
    {
      "x": -18,
      "y": 7,
      "z": -1,
      "name": "Rock_Ice_Permafrost"
    },
    {
      "x": -18,
      "y": 8,
      "z": -1,
      "name": "Rock_Ice_Stalactite_Large"
    },
    {
      "x": -18,
      "y": 9,
      "z": -1,
      "name": "Rock_Ice_Stalactite_Large",
      "filler": 1024
    },
    {
      "x": -18,
      "y": 0,
      "z": 0,
      "name": "Rock_Ice_Permafrost"
    },
    {
      "x": -18,
      "y": 1,
      "z": 0,
      "name": "Rock_Ice_Permafrost"
    },
    {
      "x": -18,
      "y": 2,
      "z": 0,
      "name": "Rock_Ice_Permafrost"
    },
    {
      "x": -18,
      "y": 3,
      "z": 0,
      "name": "Rock_Ice_Permafrost"
    },
    {
      "x": -18,
      "y": 4,
      "z": 0,
      "name": "Rock_Ice_Permafrost"
    },
    {
      "x": -18,
      "y": 5,
      "z": 0,
      "name": "Rock_Ice_Permafrost"
    },
    {
      "x": -18,
      "y": 6,
      "z": 0,
      "name": "Rock_Ice_Permafrost"
    },
    {
      "x": -18,
      "y": 7,
      "z": 0,
      "name": "Rock_Ice_Permafrost"
    },
    {
      "x": -18,
      "y": 8,
      "z": 0,
      "name": "Rock_Ice_Permafrost"
    },
    {
      "x": -18,
      "y": 0,
      "z": 1,
      "name": "Rock_Ice_Permafrost"
    },
    {
      "x": -18,
      "y": 1,
      "z": 1,
      "name": "Rock_Ice_Permafrost"
    },
    {
      "x": -18,
      "y": 2,
      "z": 1,
      "name": "Rock_Ice_Permafrost"
    },
    {
      "x": -18,
      "y": 3,
      "z": 1,
      "name": "Rock_Ice_Permafrost"
    },
    {
      "x": -18,
      "y": 4,
      "z": 1,
      "name": "Rock_Ice_Permafrost"
    },
    {
      "x": -18,
      "y": 5,
      "z": 1,
      "name": "Rock_Ice_Permafrost"
    },
    {
      "x": -18,
      "y": 6,
      "z": 1,
      "name": "Rock_Ice_Permafrost"
    },
    {
      "x": -18,
      "y": 7,
      "z": 1,
      "name": "Rock_Ice_Permafrost"
    },
    {
      "x": -18,
      "y": 0,
      "z": 2,
      "name": "Rock_Ice_Permafrost"
    },
    {
      "x": -18,
      "y": 1,
      "z": 2,
      "name": "Rock_Ice_Permafrost"
    },
    {
      "x": -18,
      "y": 2,
      "z": 2,
      "name": "Rock_Ice_Permafrost"
    },
    {
      "x": -18,
      "y": 3,
      "z": 2,
      "name": "Rock_Ice_Permafrost"
    },
    {
      "x": -18,
      "y": 4,
      "z": 2,
      "name": "Rock_Ice_Permafrost"
    },
    {
      "x": -18,
      "y": 5,
      "z": 2,
      "name": "Rock_Ice_Permafrost"
    },
    {
      "x": -18,
      "y": 6,
      "z": 2,
      "name": "Rock_Ice_Permafrost"
    },
    {
      "x": -18,
      "y": 7,
      "z": 2,
      "name": "Rock_Ice_Permafrost"
    },
    {
      "x": -18,
      "y": 8,
      "z": 2,
      "name": "Rock_Ice_Stalactite_Large"
    },
    {
      "x": -18,
      "y": 0,
      "z": 3,
      "name": "Rock_Ice_Permafrost"
    },
    {
      "x": -18,
      "y": 1,
      "z": 3,
      "name": "Rock_Ice_Permafrost"
    },
    {
      "x": -18,
      "y": 2,
      "z": 3,
      "name": "Rock_Ice_Permafrost"
    },
    {
      "x": -18,
      "y": 3,
      "z": 3,
      "name": "Rock_Ice_Permafrost"
    },
    {
      "x": -18,
      "y": 4,
      "z": 3,
      "name": "Rock_Ice_Permafrost"
    },
    {
      "x": -18,
      "y": 5,
      "z": 3,
      "name": "Rock_Ice_Permafrost"
    },
    {
      "x": -18,
      "y": 6,
      "z": 3,
      "name": "Rock_Ice_Permafrost"
    },
    {
      "x": -18,
      "y": 7,
      "z": 3,
      "name": "Rock_Ice_Permafrost"
    },
    {
      "x": -18,
      "y": 8,
      "z": 3,
      "name": "Rock_Ice_Stalactite_Large"
    },
    {
      "x": -18,
      "y": 9,
      "z": 3,
      "name": "Rock_Ice_Stalactite_Large",
      "filler": 1024
    },
    {
      "x": -18,
      "y": 0,
      "z": 4,
      "name": "Rock_Ice_Permafrost"
    },
    {
      "x": -18,
      "y": 1,
      "z": 4,
      "name": "Rock_Ice_Permafrost"
    },
    {
      "x": -18,
      "y": 2,
      "z": 4,
      "name": "Rock_Ice_Permafrost"
    },
    {
      "x": -18,
      "y": 3,
      "z": 4,
      "name": "Rock_Ice_Permafrost"
    },
    {
      "x": -18,
      "y": 4,
      "z": 4,
      "name": "Rock_Ice_Permafrost"
    },
    {
      "x": -18,
      "y": 5,
      "z": 4,
      "name": "Rock_Ice_Permafrost"
    },
    {
      "x": -18,
      "y": 6,
      "z": 4,
      "name": "Rock_Ice_Permafrost"
    },
    {
      "x": -18,
      "y": 7,
      "z": 4,
      "name": "Rock_Ice_Stalactite_Large"
    },
    {
      "x": -18,
      "y": 0,
      "z": 5,
      "name": "Rock_Ice_Permafrost"
    },
    {
      "x": -18,
      "y": 1,
      "z": 5,
      "name": "Rock_Ice_Permafrost"
    },
    {
      "x": -18,
      "y": 2,
      "z": 5,
      "name": "Rock_Ice_Permafrost"
    },
    {
      "x": -18,
      "y": 3,
      "z": 5,
      "name": "Rock_Ice_Permafrost"
    },
    {
      "x": -18,
      "y": 4,
      "z": 5,
      "name": "Rock_Ice_Permafrost"
    },
    {
      "x": -18,
      "y": 5,
      "z": 5,
      "name": "Rock_Ice_Permafrost"
    },
    {
      "x": -18,
      "y": 6,
      "z": 5,
      "name": "Rock_Ice_Permafrost"
    },
    {
      "x": -18,
      "y": 0,
      "z": 6,
      "name": "Rock_Ice_Permafrost"
    },
    {
      "x": -18,
      "y": 1,
      "z": 6,
      "name": "Rock_Ice_Permafrost"
    },
    {
      "x": -18,
      "y": 2,
      "z": 6,
      "name": "Rock_Ice_Permafrost"
    },
    {
      "x": -18,
      "y": 3,
      "z": 6,
      "name": "Rock_Ice_Permafrost"
    },
    {
      "x": -18,
      "y": 4,
      "z": 6,
      "name": "Rock_Ice_Permafrost"
    },
    {
      "x": -18,
      "y": 5,
      "z": 6,
      "name": "Rock_Ice_Permafrost"
    },
    {
      "x": -18,
      "y": 0,
      "z": 7,
      "name": "Rock_Ice_Permafrost"
    },
    {
      "x": -18,
      "y": 1,
      "z": 7,
      "name": "Rock_Ice_Permafrost"
    },
    {
      "x": -18,
      "y": 2,
      "z": 7,
      "name": "Rock_Ice_Permafrost"
    },
    {
      "x": -18,
      "y": 3,
      "z": 7,
      "name": "Rock_Ice_Permafrost"
    },
    {
      "x": -18,
      "y": 4,
      "z": 7,
      "name": "Rock_Ice_Permafrost"
    },
    {
      "x": -18,
      "y": 5,
      "z": 7,
      "name": "Rubble_Ice"
    },
    {
      "x": -18,
      "y": 0,
      "z": 8,
      "name": "Rock_Ice_Permafrost"
    },
    {
      "x": -18,
      "y": 1,
      "z": 8,
      "name": "Rock_Ice_Permafrost"
    },
    {
      "x": -18,
      "y": 2,
      "z": 8,
      "name": "Rock_Ice_Permafrost"
    },
    {
      "x": -18,
      "y": 3,
      "z": 8,
      "name": "Rock_Ice_Permafrost"
    },
    {
      "x": -18,
      "y": 4,
      "z": 8,
      "name": "Rock_Ice_Permafrost"
    },
    {
      "x": -18,
      "y": 0,
      "z": 9,
      "name": "Rock_Ice_Permafrost"
    },
    {
      "x": -18,
      "y": 1,
      "z": 9,
      "name": "Rock_Ice_Permafrost"
    },
    {
      "x": -18,
      "y": 2,
      "z": 9,
      "name": "Rock_Ice_Permafrost"
    },
    {
      "x": -18,
      "y": 3,
      "z": 9,
      "name": "Rock_Ice_Permafrost"
    },
    {
      "x": -18,
      "y": 4,
      "z": 9,
      "name": "Rubble_Ice"
    },
    {
      "x": -18,
      "y": 0,
      "z": 10,
      "name": "Rock_Ice_Permafrost"
    },
    {
      "x": -18,
      "y": 1,
      "z": 10,
      "name": "Rock_Ice_Permafrost"
    },
    {
      "x": -18,
      "y": 2,
      "z": 10,
      "name": "Rock_Ice_Permafrost"
    },
    {
      "x": -18,
      "y": 0,
      "z": 11,
      "name": "Rock_Ice_Permafrost"
    },
    {
      "x": -18,
      "y": 1,
      "z": 11,
      "name": "Rock_Ice_Permafrost"
    },
    {
      "x": -18,
      "y": 0,
      "z": 12,
      "name": "Rock_Ice_Permafrost"
    },
    {
      "x": -18,
      "y": 1,
      "z": 12,
      "name": "Rock_Ice_Icicles"
    },
    {
      "x": -18,
      "y": 0,
      "z": 13,
      "name": "Rock_Ice_Permafrost"
    },
    {
      "x": -17,
      "y": 0,
      "z": -14,
      "name": "Rock_Ice_Permafrost"
    },
    {
      "x": -17,
      "y": 0,
      "z": -13,
      "name": "Rock_Ice_Permafrost"
    },
    {
      "x": -17,
      "y": 1,
      "z": -13,
      "name": "Rock_Ice_Permafrost"
    },
    {
      "x": -17,
      "y": 2,
      "z": -13,
      "name": "Rock_Ice_Icicles"
    },
    {
      "x": -17,
      "y": 0,
      "z": -12,
      "name": "Rock_Ice_Permafrost"
    },
    {
      "x": -17,
      "y": 1,
      "z": -12,
      "name": "Rock_Ice_Permafrost"
    },
    {
      "x": -17,
      "y": 0,
      "z": -11,
      "name": "Rock_Ice_Permafrost"
    },
    {
      "x": -17,
      "y": 1,
      "z": -11,
      "name": "Rock_Ice_Permafrost"
    },
    {
      "x": -17,
      "y": 2,
      "z": -11,
      "name": "Rock_Ice_Permafrost"
    },
    {
      "x": -17,
      "y": 0,
      "z": -10,
      "name": "Rock_Ice_Permafrost"
    },
    {
      "x": -17,
      "y": 1,
      "z": -10,
      "name": "Rock_Ice_Permafrost"
    },
    {
      "x": -17,
      "y": 2,
      "z": -10,
      "name": "Rock_Ice_Permafrost"
    },
    {
      "x": -17,
      "y": 3,
      "z": -10,
      "name": "Rock_Ice_Permafrost"
    },
    {
      "x": -17,
      "y": 4,
      "z": -10,
      "name": "Rock_Ice_Icicles"
    },
    {
      "x": -17,
      "y": 0,
      "z": -9,
      "name": "Rock_Ice_Permafrost"
    },
    {
      "x": -17,
      "y": 1,
      "z": -9,
      "name": "Rock_Ice_Permafrost"
    },
    {
      "x": -17,
      "y": 2,
      "z": -9,
      "name": "Rock_Ice_Permafrost"
    },
    {
      "x": -17,
      "y": 3,
      "z": -9,
      "name": "Rock_Ice_Permafrost"
    },
    {
      "x": -17,
      "y": 4,
      "z": -9,
      "name": "Rock_Ice_Permafrost"
    },
    {
      "x": -17,
      "y": 0,
      "z": -8,
      "name": "Rock_Ice_Permafrost"
    },
    {
      "x": -17,
      "y": 1,
      "z": -8,
      "name": "Rock_Ice_Permafrost"
    },
    {
      "x": -17,
      "y": 2,
      "z": -8,
      "name": "Rock_Ice_Permafrost"
    },
    {
      "x": -17,
      "y": 3,
      "z": -8,
      "name": "Rock_Ice_Permafrost"
    },
    {
      "x": -17,
      "y": 4,
      "z": -8,
      "name": "Rock_Ice_Permafrost"
    },
    {
      "x": -17,
      "y": 0,
      "z": -7,
      "name": "Rock_Ice_Permafrost"
    },
    {
      "x": -17,
      "y": 1,
      "z": -7,
      "name": "Rock_Ice_Permafrost"
    },
    {
      "x": -17,
      "y": 2,
      "z": -7,
      "name": "Rock_Ice_Permafrost"
    },
    {
      "x": -17,
      "y": 3,
      "z": -7,
      "name": "Rock_Ice_Permafrost"
    },
    {
      "x": -17,
      "y": 4,
      "z": -7,
      "name": "Rock_Ice_Permafrost"
    },
    {
      "x": -17,
      "y": 5,
      "z": -7,
      "name": "Rock_Ice_Permafrost"
    },
    {
      "x": -17,
      "y": 0,
      "z": -6,
      "name": "Rock_Ice_Permafrost"
    },
    {
      "x": -17,
      "y": 1,
      "z": -6,
      "name": "Rock_Ice_Permafrost"
    },
    {
      "x": -17,
      "y": 2,
      "z": -6,
      "name": "Rock_Ice_Permafrost"
    },
    {
      "x": -17,
      "y": 3,
      "z": -6,
      "name": "Rock_Ice_Permafrost"
    },
    {
      "x": -17,
      "y": 4,
      "z": -6,
      "name": "Rock_Ice_Permafrost"
    },
    {
      "x": -17,
      "y": 5,
      "z": -6,
      "name": "Rock_Ice_Permafrost"
    },
    {
      "x": -17,
      "y": 6,
      "z": -6,
      "name": "Rock_Ice_Permafrost"
    },
    {
      "x": -17,
      "y": 0,
      "z": -5,
      "name": "Rock_Ice_Permafrost"
    },
    {
      "x": -17,
      "y": 1,
      "z": -5,
      "name": "Rock_Ice_Permafrost"
    },
    {
      "x": -17,
      "y": 2,
      "z": -5,
      "name": "Rock_Ice_Permafrost"
    },
    {
      "x": -17,
      "y": 3,
      "z": -5,
      "name": "Rock_Ice_Permafrost"
    },
    {
      "x": -17,
      "y": 4,
      "z": -5,
      "name": "Rock_Ice_Permafrost"
    },
    {
      "x": -17,
      "y": 5,
      "z": -5,
      "name": "Rock_Ice_Permafrost"
    },
    {
      "x": -17,
      "y": 6,
      "z": -5,
      "name": "Rock_Ice_Permafrost"
    },
    {
      "x": -17,
      "y": 7,
      "z": -5,
      "name": "Rock_Ice_Permafrost"
    },
    {
      "x": -17,
      "y": 0,
      "z": -4,
      "name": "Rock_Ice_Permafrost"
    },
    {
      "x": -17,
      "y": 1,
      "z": -4,
      "name": "Rock_Ice_Permafrost"
    },
    {
      "x": -17,
      "y": 2,
      "z": -4,
      "name": "Rock_Ice_Permafrost"
    },
    {
      "x": -17,
      "y": 3,
      "z": -4,
      "name": "Rock_Ice_Permafrost"
    },
    {
      "x": -17,
      "y": 4,
      "z": -4,
      "name": "Rock_Ice_Permafrost"
    },
    {
      "x": -17,
      "y": 5,
      "z": -4,
      "name": "Rock_Ice_Permafrost"
    },
    {
      "x": -17,
      "y": 6,
      "z": -4,
      "name": "Rock_Ice_Permafrost"
    },
    {
      "x": -17,
      "y": 7,
      "z": -4,
      "name": "Rock_Ice_Permafrost"
    },
    {
      "x": -17,
      "y": 8,
      "z": -4,
      "name": "Rock_Ice_Icicles"
    },
    {
      "x": -17,
      "y": 0,
      "z": -3,
      "name": "Rock_Ice_Permafrost"
    },
    {
      "x": -17,
      "y": 1,
      "z": -3,
      "name": "Rock_Ice_Permafrost"
    },
    {
      "x": -17,
      "y": 2,
      "z": -3,
      "name": "Rock_Ice_Permafrost"
    },
    {
      "x": -17,
      "y": 3,
      "z": -3,
      "name": "Rock_Ice_Permafrost"
    },
    {
      "x": -17,
      "y": 4,
      "z": -3,
      "name": "Rock_Ice_Permafrost"
    },
    {
      "x": -17,
      "y": 5,
      "z": -3,
      "name": "Rock_Ice_Permafrost"
    },
    {
      "x": -17,
      "y": 6,
      "z": -3,
      "name": "Rock_Ice_Permafrost"
    },
    {
      "x": -17,
      "y": 7,
      "z": -3,
      "name": "Rock_Ice_Permafrost"
    },
    {
      "x": -17,
      "y": 8,
      "z": -3,
      "name": "Rock_Ice_Permafrost"
    },
    {
      "x": -17,
      "y": 0,
      "z": -2,
      "name": "Rock_Ice_Permafrost"
    },
    {
      "x": -17,
      "y": 1,
      "z": -2,
      "name": "Rock_Ice_Permafrost"
    },
    {
      "x": -17,
      "y": 2,
      "z": -2,
      "name": "Rock_Ice_Permafrost"
    },
    {
      "x": -17,
      "y": 3,
      "z": -2,
      "name": "Rock_Ice_Permafrost"
    },
    {
      "x": -17,
      "y": 4,
      "z": -2,
      "name": "Rock_Ice_Permafrost"
    },
    {
      "x": -17,
      "y": 5,
      "z": -2,
      "name": "Rock_Ice_Permafrost"
    },
    {
      "x": -17,
      "y": 6,
      "z": -2,
      "name": "Rock_Ice_Permafrost"
    },
    {
      "x": -17,
      "y": 7,
      "z": -2,
      "name": "Rock_Ice_Permafrost"
    },
    {
      "x": -17,
      "y": 8,
      "z": -2,
      "name": "Rock_Ice_Permafrost"
    },
    {
      "x": -17,
      "y": 9,
      "z": -2,
      "name": "Rock_Ice_Stalactite_Large"
    },
    {
      "x": -17,
      "y": 0,
      "z": -1,
      "name": "Rock_Ice_Permafrost"
    },
    {
      "x": -17,
      "y": 1,
      "z": -1,
      "name": "Rock_Ice_Permafrost"
    },
    {
      "x": -17,
      "y": 2,
      "z": -1,
      "name": "Rock_Ice_Permafrost"
    },
    {
      "x": -17,
      "y": 3,
      "z": -1,
      "name": "Rock_Ice_Permafrost"
    },
    {
      "x": -17,
      "y": 4,
      "z": -1,
      "name": "Rock_Ice_Permafrost"
    },
    {
      "x": -17,
      "y": 5,
      "z": -1,
      "name": "Rock_Ice_Permafrost"
    },
    {
      "x": -17,
      "y": 6,
      "z": -1,
      "name": "Rock_Ice_Permafrost"
    },
    {
      "x": -17,
      "y": 7,
      "z": -1,
      "name": "Rock_Ice_Permafrost"
    },
    {
      "x": -17,
      "y": 8,
      "z": -1,
      "name": "Rock_Ice_Permafrost"
    },
    {
      "x": -17,
      "y": 9,
      "z": -1,
      "name": "Rock_Ice_Permafrost"
    },
    {
      "x": -17,
      "y": 0,
      "z": 0,
      "name": "Rock_Ice_Permafrost"
    },
    {
      "x": -17,
      "y": 1,
      "z": 0,
      "name": "Rock_Ice_Permafrost"
    },
    {
      "x": -17,
      "y": 2,
      "z": 0,
      "name": "Rock_Ice_Permafrost"
    },
    {
      "x": -17,
      "y": 3,
      "z": 0,
      "name": "Rock_Ice_Permafrost"
    },
    {
      "x": -17,
      "y": 4,
      "z": 0,
      "name": "Rock_Ice_Permafrost"
    },
    {
      "x": -17,
      "y": 5,
      "z": 0,
      "name": "Rock_Ice_Permafrost"
    },
    {
      "x": -17,
      "y": 6,
      "z": 0,
      "name": "Rock_Ice_Permafrost"
    },
    {
      "x": -17,
      "y": 7,
      "z": 0,
      "name": "Rock_Ice_Permafrost"
    },
    {
      "x": -17,
      "y": 8,
      "z": 0,
      "name": "Rock_Ice_Permafrost"
    },
    {
      "x": -17,
      "y": 9,
      "z": 0,
      "name": "Rock_Ice_Permafrost"
    },
    {
      "x": -17,
      "y": 0,
      "z": 1,
      "name": "Rock_Ice_Permafrost"
    },
    {
      "x": -17,
      "y": 1,
      "z": 1,
      "name": "Rock_Ice_Permafrost"
    },
    {
      "x": -17,
      "y": 2,
      "z": 1,
      "name": "Rock_Ice_Permafrost"
    },
    {
      "x": -17,
      "y": 3,
      "z": 1,
      "name": "Rock_Ice_Permafrost"
    },
    {
      "x": -17,
      "y": 4,
      "z": 1,
      "name": "Rock_Ice_Permafrost"
    },
    {
      "x": -17,
      "y": 5,
      "z": 1,
      "name": "Rock_Ice_Permafrost"
    },
    {
      "x": -17,
      "y": 6,
      "z": 1,
      "name": "Rock_Ice_Permafrost"
    },
    {
      "x": -17,
      "y": 7,
      "z": 1,
      "name": "Rock_Ice_Permafrost"
    },
    {
      "x": -17,
      "y": 8,
      "z": 1,
      "name": "Rock_Ice_Permafrost"
    },
    {
      "x": -17,
      "y": 9,
      "z": 1,
      "name": "Rock_Ice_Permafrost"
    },
    {
      "x": -17,
      "y": 10,
      "z": 1,
      "name": "Rock_Ice_Stalactite_Large"
    },
    {
      "x": -17,
      "y": 0,
      "z": 2,
      "name": "Rock_Ice_Permafrost"
    },
    {
      "x": -17,
      "y": 1,
      "z": 2,
      "name": "Rock_Ice_Permafrost"
    },
    {
      "x": -17,
      "y": 2,
      "z": 2,
      "name": "Rock_Ice_Permafrost"
    },
    {
      "x": -17,
      "y": 3,
      "z": 2,
      "name": "Rock_Ice_Permafrost"
    },
    {
      "x": -17,
      "y": 4,
      "z": 2,
      "name": "Rock_Ice_Permafrost"
    },
    {
      "x": -17,
      "y": 5,
      "z": 2,
      "name": "Rock_Ice_Permafrost"
    },
    {
      "x": -17,
      "y": 6,
      "z": 2,
      "name": "Rock_Ice_Permafrost"
    },
    {
      "x": -17,
      "y": 7,
      "z": 2,
      "name": "Rock_Ice_Permafrost"
    },
    {
      "x": -17,
      "y": 8,
      "z": 2,
      "name": "Rock_Ice_Permafrost"
    },
    {
      "x": -17,
      "y": 0,
      "z": 3,
      "name": "Rock_Ice_Permafrost"
    },
    {
      "x": -17,
      "y": 1,
      "z": 3,
      "name": "Rock_Ice_Permafrost"
    },
    {
      "x": -17,
      "y": 2,
      "z": 3,
      "name": "Rock_Ice_Permafrost"
    },
    {
      "x": -17,
      "y": 3,
      "z": 3,
      "name": "Rock_Ice_Permafrost"
    },
    {
      "x": -17,
      "y": 4,
      "z": 3,
      "name": "Rock_Ice_Permafrost"
    },
    {
      "x": -17,
      "y": 5,
      "z": 3,
      "name": "Rock_Ice_Permafrost"
    },
    {
      "x": -17,
      "y": 6,
      "z": 3,
      "name": "Rock_Ice_Permafrost"
    },
    {
      "x": -17,
      "y": 7,
      "z": 3,
      "name": "Rock_Ice_Permafrost"
    },
    {
      "x": -17,
      "y": 8,
      "z": 3,
      "name": "Rock_Ice_Permafrost"
    },
    {
      "x": -17,
      "y": 9,
      "z": 3,
      "name": "Rock_Ice_Icicles"
    },
    {
      "x": -17,
      "y": 0,
      "z": 4,
      "name": "Rock_Ice_Permafrost"
    },
    {
      "x": -17,
      "y": 1,
      "z": 4,
      "name": "Rock_Ice_Permafrost"
    },
    {
      "x": -17,
      "y": 2,
      "z": 4,
      "name": "Rock_Ice_Permafrost"
    },
    {
      "x": -17,
      "y": 3,
      "z": 4,
      "name": "Rock_Ice_Permafrost"
    },
    {
      "x": -17,
      "y": 4,
      "z": 4,
      "name": "Rock_Ice_Permafrost"
    },
    {
      "x": -17,
      "y": 5,
      "z": 4,
      "name": "Rock_Ice_Permafrost"
    },
    {
      "x": -17,
      "y": 6,
      "z": 4,
      "name": "Rock_Ice_Permafrost"
    },
    {
      "x": -17,
      "y": 7,
      "z": 4,
      "name": "Rock_Ice_Permafrost"
    },
    {
      "x": -17,
      "y": 0,
      "z": 5,
      "name": "Rock_Ice_Permafrost"
    },
    {
      "x": -17,
      "y": 1,
      "z": 5,
      "name": "Rock_Ice_Permafrost"
    },
    {
      "x": -17,
      "y": 2,
      "z": 5,
      "name": "Rock_Ice_Permafrost"
    },
    {
      "x": -17,
      "y": 3,
      "z": 5,
      "name": "Rock_Ice_Permafrost"
    },
    {
      "x": -17,
      "y": 4,
      "z": 5,
      "name": "Rock_Ice_Permafrost"
    },
    {
      "x": -17,
      "y": 5,
      "z": 5,
      "name": "Rock_Ice_Permafrost"
    },
    {
      "x": -17,
      "y": 6,
      "z": 5,
      "name": "Rock_Ice_Permafrost"
    },
    {
      "x": -17,
      "y": 7,
      "z": 5,
      "name": "Rock_Ice_Permafrost"
    },
    {
      "x": -17,
      "y": 0,
      "z": 6,
      "name": "Rock_Ice_Permafrost"
    },
    {
      "x": -17,
      "y": 1,
      "z": 6,
      "name": "Rock_Ice_Permafrost"
    },
    {
      "x": -17,
      "y": 2,
      "z": 6,
      "name": "Rock_Ice_Permafrost"
    },
    {
      "x": -17,
      "y": 3,
      "z": 6,
      "name": "Rock_Ice_Permafrost"
    },
    {
      "x": -17,
      "y": 4,
      "z": 6,
      "name": "Rock_Ice_Permafrost"
    },
    {
      "x": -17,
      "y": 5,
      "z": 6,
      "name": "Rock_Ice_Permafrost"
    },
    {
      "x": -17,
      "y": 6,
      "z": 6,
      "name": "Rock_Ice_Permafrost"
    },
    {
      "x": -17,
      "y": 0,
      "z": 7,
      "name": "Rock_Ice_Permafrost"
    },
    {
      "x": -17,
      "y": 1,
      "z": 7,
      "name": "Rock_Ice_Permafrost"
    },
    {
      "x": -17,
      "y": 2,
      "z": 7,
      "name": "Rock_Ice_Permafrost"
    },
    {
      "x": -17,
      "y": 3,
      "z": 7,
      "name": "Rock_Ice_Permafrost"
    },
    {
      "x": -17,
      "y": 4,
      "z": 7,
      "name": "Rock_Ice_Permafrost"
    },
    {
      "x": -17,
      "y": 5,
      "z": 7,
      "name": "Rock_Ice_Permafrost"
    },
    {
      "x": -17,
      "y": 0,
      "z": 8,
      "name": "Rock_Ice_Permafrost"
    },
    {
      "x": -17,
      "y": 1,
      "z": 8,
      "name": "Rock_Ice_Permafrost"
    },
    {
      "x": -17,
      "y": 2,
      "z": 8,
      "name": "Rock_Ice_Permafrost"
    },
    {
      "x": -17,
      "y": 3,
      "z": 8,
      "name": "Rock_Ice_Permafrost"
    },
    {
      "x": -17,
      "y": 4,
      "z": 8,
      "name": "Rock_Ice_Permafrost"
    },
    {
      "x": -17,
      "y": 5,
      "z": 8,
      "name": "Rock_Ice_Permafrost"
    },
    {
      "x": -17,
      "y": 0,
      "z": 9,
      "name": "Rock_Ice_Permafrost"
    },
    {
      "x": -17,
      "y": 1,
      "z": 9,
      "name": "Rock_Ice_Permafrost"
    },
    {
      "x": -17,
      "y": 2,
      "z": 9,
      "name": "Rock_Ice_Permafrost"
    },
    {
      "x": -17,
      "y": 3,
      "z": 9,
      "name": "Rock_Ice_Permafrost"
    },
    {
      "x": -17,
      "y": 4,
      "z": 9,
      "name": "Rock_Ice_Permafrost"
    },
    {
      "x": -17,
      "y": 0,
      "z": 10,
      "name": "Rock_Ice_Permafrost"
    },
    {
      "x": -17,
      "y": 1,
      "z": 10,
      "name": "Rock_Ice_Permafrost"
    },
    {
      "x": -17,
      "y": 2,
      "z": 10,
      "name": "Rock_Ice_Permafrost"
    },
    {
      "x": -17,
      "y": 3,
      "z": 10,
      "name": "Rock_Ice_Permafrost"
    },
    {
      "x": -17,
      "y": 0,
      "z": 11,
      "name": "Rock_Ice_Permafrost"
    },
    {
      "x": -17,
      "y": 1,
      "z": 11,
      "name": "Rock_Ice_Permafrost"
    },
    {
      "x": -17,
      "y": 2,
      "z": 11,
      "name": "Rock_Ice_Permafrost"
    },
    {
      "x": -17,
      "y": 0,
      "z": 12,
      "name": "Rock_Ice_Permafrost"
    },
    {
      "x": -17,
      "y": 1,
      "z": 12,
      "name": "Rock_Ice_Permafrost"
    },
    {
      "x": -17,
      "y": 0,
      "z": 13,
      "name": "Rock_Ice_Permafrost"
    },
    {
      "x": -17,
      "y": 0,
      "z": 14,
      "name": "Rock_Ice_Permafrost"
    },
    {
      "x": -17,
      "y": 1,
      "z": 14,
      "name": "Rock_Ice_Icicles"
    },
    {
      "x": -16,
      "y": 0,
      "z": -14,
      "name": "Rock_Ice_Permafrost"
    },
    {
      "x": -16,
      "y": 1,
      "z": -14,
      "name": "Rock_Ice_Stalactite_Large"
    },
    {
      "x": -16,
      "y": 0,
      "z": -13,
      "name": "Rock_Ice_Permafrost"
    },
    {
      "x": -16,
      "y": 1,
      "z": -13,
      "name": "Rock_Ice_Permafrost"
    },
    {
      "x": -16,
      "y": 2,
      "z": -13,
      "name": "Rock_Ice_Icicles"
    },
    {
      "x": -16,
      "y": 0,
      "z": -12,
      "name": "Rock_Ice_Permafrost"
    },
    {
      "x": -16,
      "y": 1,
      "z": -12,
      "name": "Rock_Ice_Permafrost"
    },
    {
      "x": -16,
      "y": 2,
      "z": -12,
      "name": "Rock_Ice_Permafrost"
    },
    {
      "x": -16,
      "y": 0,
      "z": -11,
      "name": "Rock_Ice_Permafrost"
    },
    {
      "x": -16,
      "y": 1,
      "z": -11,
      "name": "Rock_Ice_Permafrost"
    },
    {
      "x": -16,
      "y": 2,
      "z": -11,
      "name": "Rock_Ice_Permafrost"
    },
    {
      "x": -16,
      "y": 3,
      "z": -11,
      "name": "Rock_Ice_Permafrost"
    },
    {
      "x": -16,
      "y": 0,
      "z": -10,
      "name": "Rock_Ice_Permafrost"
    },
    {
      "x": -16,
      "y": 1,
      "z": -10,
      "name": "Rock_Ice_Permafrost"
    },
    {
      "x": -16,
      "y": 2,
      "z": -10,
      "name": "Rock_Ice_Permafrost"
    },
    {
      "x": -16,
      "y": 3,
      "z": -10,
      "name": "Rock_Ice_Permafrost"
    },
    {
      "x": -16,
      "y": 4,
      "z": -10,
      "name": "Rock_Ice_Permafrost"
    },
    {
      "x": -16,
      "y": 0,
      "z": -9,
      "name": "Rock_Ice_Permafrost"
    },
    {
      "x": -16,
      "y": 1,
      "z": -9,
      "name": "Rock_Ice_Permafrost"
    },
    {
      "x": -16,
      "y": 2,
      "z": -9,
      "name": "Rock_Ice_Permafrost"
    },
    {
      "x": -16,
      "y": 3,
      "z": -9,
      "name": "Rock_Ice_Permafrost"
    },
    {
      "x": -16,
      "y": 4,
      "z": -9,
      "name": "Rock_Ice_Permafrost"
    },
    {
      "x": -16,
      "y": 0,
      "z": -8,
      "name": "Rock_Ice_Permafrost"
    },
    {
      "x": -16,
      "y": 1,
      "z": -8,
      "name": "Rock_Ice_Permafrost"
    },
    {
      "x": -16,
      "y": 2,
      "z": -8,
      "name": "Rock_Ice_Permafrost"
    },
    {
      "x": -16,
      "y": 3,
      "z": -8,
      "name": "Rock_Ice_Permafrost"
    },
    {
      "x": -16,
      "y": 4,
      "z": -8,
      "name": "Rock_Ice_Permafrost"
    },
    {
      "x": -16,
      "y": 5,
      "z": -8,
      "name": "Rock_Ice_Permafrost"
    },
    {
      "x": -16,
      "y": 0,
      "z": -7,
      "name": "Rock_Ice_Permafrost"
    },
    {
      "x": -16,
      "y": 1,
      "z": -7,
      "name": "Rock_Ice_Permafrost"
    },
    {
      "x": -16,
      "y": 2,
      "z": -7,
      "name": "Rock_Ice_Permafrost"
    },
    {
      "x": -16,
      "y": 3,
      "z": -7,
      "name": "Rock_Ice_Permafrost"
    },
    {
      "x": -16,
      "y": 4,
      "z": -7,
      "name": "Rock_Ice_Permafrost"
    },
    {
      "x": -16,
      "y": 5,
      "z": -7,
      "name": "Rock_Ice_Permafrost"
    },
    {
      "x": -16,
      "y": 6,
      "z": -7,
      "name": "Rock_Ice_Permafrost"
    },
    {
      "x": -16,
      "y": 0,
      "z": -6,
      "name": "Rock_Ice_Permafrost"
    },
    {
      "x": -16,
      "y": 1,
      "z": -6,
      "name": "Rock_Ice_Permafrost"
    },
    {
      "x": -16,
      "y": 2,
      "z": -6,
      "name": "Rock_Ice_Permafrost"
    },
    {
      "x": -16,
      "y": 3,
      "z": -6,
      "name": "Rock_Ice_Permafrost"
    },
    {
      "x": -16,
      "y": 4,
      "z": -6,
      "name": "Rock_Ice_Permafrost"
    },
    {
      "x": -16,
      "y": 5,
      "z": -6,
      "name": "Rock_Ice_Permafrost"
    },
    {
      "x": -16,
      "y": 6,
      "z": -6,
      "name": "Rock_Ice_Permafrost"
    },
    {
      "x": -16,
      "y": 7,
      "z": -6,
      "name": "Rock_Ice_Permafrost"
    },
    {
      "x": -16,
      "y": 8,
      "z": -6,
      "name": "Rock_Ice_Icicles"
    },
    {
      "x": -16,
      "y": 0,
      "z": -5,
      "name": "Rock_Ice_Permafrost"
    },
    {
      "x": -16,
      "y": 1,
      "z": -5,
      "name": "Rock_Ice_Permafrost"
    },
    {
      "x": -16,
      "y": 2,
      "z": -5,
      "name": "Rock_Ice_Permafrost"
    },
    {
      "x": -16,
      "y": 3,
      "z": -5,
      "name": "Rock_Ice_Permafrost"
    },
    {
      "x": -16,
      "y": 4,
      "z": -5,
      "name": "Rock_Ice_Permafrost"
    },
    {
      "x": -16,
      "y": 5,
      "z": -5,
      "name": "Rock_Ice_Permafrost"
    },
    {
      "x": -16,
      "y": 6,
      "z": -5,
      "name": "Rock_Ice_Permafrost"
    },
    {
      "x": -16,
      "y": 7,
      "z": -5,
      "name": "Rock_Ice_Permafrost"
    },
    {
      "x": -16,
      "y": 8,
      "z": -5,
      "name": "Rock_Ice_Permafrost"
    },
    {
      "x": -16,
      "y": 0,
      "z": -4,
      "name": "Rock_Ice_Permafrost"
    },
    {
      "x": -16,
      "y": 1,
      "z": -4,
      "name": "Rock_Ice_Permafrost"
    },
    {
      "x": -16,
      "y": 2,
      "z": -4,
      "name": "Rock_Ice_Permafrost"
    },
    {
      "x": -16,
      "y": 3,
      "z": -4,
      "name": "Rock_Ice_Permafrost"
    },
    {
      "x": -16,
      "y": 4,
      "z": -4,
      "name": "Rock_Ice_Permafrost"
    },
    {
      "x": -16,
      "y": 5,
      "z": -4,
      "name": "Rock_Ice_Permafrost"
    },
    {
      "x": -16,
      "y": 6,
      "z": -4,
      "name": "Rock_Ice_Permafrost"
    },
    {
      "x": -16,
      "y": 7,
      "z": -4,
      "name": "Rock_Ice_Permafrost"
    },
    {
      "x": -16,
      "y": 8,
      "z": -4,
      "name": "Rock_Ice_Permafrost"
    },
    {
      "x": -16,
      "y": 0,
      "z": -3,
      "name": "Rock_Ice_Permafrost"
    },
    {
      "x": -16,
      "y": 1,
      "z": -3,
      "name": "Rock_Ice_Permafrost"
    },
    {
      "x": -16,
      "y": 2,
      "z": -3,
      "name": "Rock_Ice_Permafrost"
    },
    {
      "x": -16,
      "y": 3,
      "z": -3,
      "name": "Rock_Ice_Permafrost"
    },
    {
      "x": -16,
      "y": 4,
      "z": -3,
      "name": "Rock_Ice_Permafrost"
    },
    {
      "x": -16,
      "y": 5,
      "z": -3,
      "name": "Rock_Ice_Permafrost"
    },
    {
      "x": -16,
      "y": 6,
      "z": -3,
      "name": "Rock_Ice_Permafrost"
    },
    {
      "x": -16,
      "y": 7,
      "z": -3,
      "name": "Rock_Ice_Permafrost"
    },
    {
      "x": -16,
      "y": 8,
      "z": -3,
      "name": "Rock_Ice_Permafrost"
    },
    {
      "x": -16,
      "y": 9,
      "z": -3,
      "name": "Rock_Ice_Permafrost"
    },
    {
      "x": -16,
      "y": 10,
      "z": -3,
      "name": "Rock_Ice_Icicles"
    },
    {
      "x": -16,
      "y": 0,
      "z": -2,
      "name": "Rock_Ice_Permafrost"
    },
    {
      "x": -16,
      "y": 1,
      "z": -2,
      "name": "Rock_Ice_Permafrost"
    },
    {
      "x": -16,
      "y": 2,
      "z": -2,
      "name": "Rock_Ice_Permafrost"
    },
    {
      "x": -16,
      "y": 3,
      "z": -2,
      "name": "Rock_Ice_Permafrost"
    },
    {
      "x": -16,
      "y": 4,
      "z": -2,
      "name": "Rock_Ice_Permafrost"
    },
    {
      "x": -16,
      "y": 5,
      "z": -2,
      "name": "Rock_Ice_Permafrost"
    },
    {
      "x": -16,
      "y": 6,
      "z": -2,
      "name": "Rock_Ice_Permafrost"
    },
    {
      "x": -16,
      "y": 7,
      "z": -2,
      "name": "Rock_Ice_Permafrost"
    },
    {
      "x": -16,
      "y": 8,
      "z": -2,
      "name": "Rock_Ice_Permafrost"
    },
    {
      "x": -16,
      "y": 9,
      "z": -2,
      "name": "Rock_Ice_Permafrost"
    },
    {
      "x": -16,
      "y": 10,
      "z": -2,
      "name": "Rock_Ice_Icicles"
    },
    {
      "x": -16,
      "y": 0,
      "z": -1,
      "name": "Rock_Ice_Permafrost"
    },
    {
      "x": -16,
      "y": 1,
      "z": -1,
      "name": "Rock_Ice_Permafrost"
    },
    {
      "x": -16,
      "y": 2,
      "z": -1,
      "name": "Rock_Ice_Permafrost"
    },
    {
      "x": -16,
      "y": 3,
      "z": -1,
      "name": "Rock_Ice_Permafrost"
    },
    {
      "x": -16,
      "y": 4,
      "z": -1,
      "name": "Rock_Ice_Permafrost"
    },
    {
      "x": -16,
      "y": 5,
      "z": -1,
      "name": "Rock_Ice_Permafrost"
    },
    {
      "x": -16,
      "y": 6,
      "z": -1,
      "name": "Rock_Ice_Permafrost"
    },
    {
      "x": -16,
      "y": 7,
      "z": -1,
      "name": "Rock_Ice_Permafrost"
    },
    {
      "x": -16,
      "y": 8,
      "z": -1,
      "name": "Rock_Ice_Permafrost"
    },
    {
      "x": -16,
      "y": 9,
      "z": -1,
      "name": "Rock_Ice_Permafrost"
    },
    {
      "x": -16,
      "y": 10,
      "z": -1,
      "name": "Rock_Ice_Permafrost"
    },
    {
      "x": -16,
      "y": 0,
      "z": 0,
      "name": "Rock_Ice_Permafrost"
    },
    {
      "x": -16,
      "y": 1,
      "z": 0,
      "name": "Rock_Ice_Permafrost"
    },
    {
      "x": -16,
      "y": 2,
      "z": 0,
      "name": "Rock_Ice_Permafrost"
    },
    {
      "x": -16,
      "y": 3,
      "z": 0,
      "name": "Rock_Ice_Permafrost"
    },
    {
      "x": -16,
      "y": 4,
      "z": 0,
      "name": "Rock_Ice_Permafrost"
    },
    {
      "x": -16,
      "y": 5,
      "z": 0,
      "name": "Rock_Ice_Permafrost"
    },
    {
      "x": -16,
      "y": 6,
      "z": 0,
      "name": "Rock_Ice_Permafrost"
    },
    {
      "x": -16,
      "y": 7,
      "z": 0,
      "name": "Rock_Ice_Permafrost"
    },
    {
      "x": -16,
      "y": 8,
      "z": 0,
      "name": "Rock_Ice_Permafrost"
    },
    {
      "x": -16,
      "y": 9,
      "z": 0,
      "name": "Rock_Ice_Permafrost"
    },
    {
      "x": -16,
      "y": 10,
      "z": 0,
      "name": "Rock_Ice_Permafrost"
    },
    {
      "x": -16,
      "y": 0,
      "z": 1,
      "name": "Rock_Ice_Permafrost"
    },
    {
      "x": -16,
      "y": 1,
      "z": 1,
      "name": "Rock_Ice_Permafrost"
    },
    {
      "x": -16,
      "y": 2,
      "z": 1,
      "name": "Rock_Ice_Permafrost"
    },
    {
      "x": -16,
      "y": 3,
      "z": 1,
      "name": "Rock_Ice_Permafrost"
    },
    {
      "x": -16,
      "y": 4,
      "z": 1,
      "name": "Rock_Ice_Permafrost"
    },
    {
      "x": -16,
      "y": 5,
      "z": 1,
      "name": "Rock_Ice_Permafrost"
    },
    {
      "x": -16,
      "y": 6,
      "z": 1,
      "name": "Rock_Ice_Permafrost"
    },
    {
      "x": -16,
      "y": 7,
      "z": 1,
      "name": "Rock_Ice_Permafrost"
    },
    {
      "x": -16,
      "y": 8,
      "z": 1,
      "name": "Rock_Ice_Permafrost"
    },
    {
      "x": -16,
      "y": 9,
      "z": 1,
      "name": "Rock_Ice_Permafrost"
    },
    {
      "x": -16,
      "y": 10,
      "z": 1,
      "name": "Rock_Ice_Permafrost"
    },
    {
      "x": -16,
      "y": 11,
      "z": 1,
      "name": "Rock_Crystal_Cyan_Medium"
    },
    {
      "x": -16,
      "y": 0,
      "z": 2,
      "name": "Rock_Ice_Permafrost"
    },
    {
      "x": -16,
      "y": 1,
      "z": 2,
      "name": "Rock_Ice_Permafrost"
    },
    {
      "x": -16,
      "y": 2,
      "z": 2,
      "name": "Rock_Ice_Permafrost"
    },
    {
      "x": -16,
      "y": 3,
      "z": 2,
      "name": "Rock_Ice_Permafrost"
    },
    {
      "x": -16,
      "y": 4,
      "z": 2,
      "name": "Rock_Ice_Permafrost"
    },
    {
      "x": -16,
      "y": 5,
      "z": 2,
      "name": "Rock_Ice_Permafrost"
    },
    {
      "x": -16,
      "y": 6,
      "z": 2,
      "name": "Rock_Ice_Permafrost"
    },
    {
      "x": -16,
      "y": 7,
      "z": 2,
      "name": "Rock_Ice_Permafrost"
    },
    {
      "x": -16,
      "y": 8,
      "z": 2,
      "name": "Rock_Ice_Permafrost"
    },
    {
      "x": -16,
      "y": 9,
      "z": 2,
      "name": "Rock_Ice_Permafrost"
    },
    {
      "x": -16,
      "y": 10,
      "z": 2,
      "name": "Rock_Ice_Permafrost"
    },
    {
      "x": -16,
      "y": 0,
      "z": 3,
      "name": "Rock_Ice_Permafrost"
    },
    {
      "x": -16,
      "y": 1,
      "z": 3,
      "name": "Rock_Ice_Permafrost"
    },
    {
      "x": -16,
      "y": 2,
      "z": 3,
      "name": "Rock_Ice_Permafrost"
    },
    {
      "x": -16,
      "y": 3,
      "z": 3,
      "name": "Rock_Ice_Permafrost"
    },
    {
      "x": -16,
      "y": 4,
      "z": 3,
      "name": "Rock_Ice_Permafrost"
    },
    {
      "x": -16,
      "y": 5,
      "z": 3,
      "name": "Rock_Ice_Permafrost"
    },
    {
      "x": -16,
      "y": 6,
      "z": 3,
      "name": "Rock_Ice_Permafrost"
    },
    {
      "x": -16,
      "y": 7,
      "z": 3,
      "name": "Rock_Ice_Permafrost"
    },
    {
      "x": -16,
      "y": 8,
      "z": 3,
      "name": "Rock_Ice_Permafrost"
    },
    {
      "x": -16,
      "y": 9,
      "z": 3,
      "name": "Rock_Ice_Permafrost"
    },
    {
      "x": -16,
      "y": 10,
      "z": 3,
      "name": "Rock_Ice_Stalactite_Large"
    },
    {
      "x": -16,
      "y": 0,
      "z": 4,
      "name": "Rock_Ice_Permafrost"
    },
    {
      "x": -16,
      "y": 1,
      "z": 4,
      "name": "Rock_Ice_Permafrost"
    },
    {
      "x": -16,
      "y": 2,
      "z": 4,
      "name": "Rock_Ice_Permafrost"
    },
    {
      "x": -16,
      "y": 3,
      "z": 4,
      "name": "Rock_Ice_Permafrost"
    },
    {
      "x": -16,
      "y": 4,
      "z": 4,
      "name": "Rock_Ice_Permafrost"
    },
    {
      "x": -16,
      "y": 5,
      "z": 4,
      "name": "Rock_Ice_Permafrost"
    },
    {
      "x": -16,
      "y": 6,
      "z": 4,
      "name": "Rock_Ice_Permafrost"
    },
    {
      "x": -16,
      "y": 7,
      "z": 4,
      "name": "Rock_Ice_Permafrost"
    },
    {
      "x": -16,
      "y": 8,
      "z": 4,
      "name": "Rock_Ice_Permafrost"
    },
    {
      "x": -16,
      "y": 9,
      "z": 4,
      "name": "Rock_Ice_Permafrost"
    },
    {
      "x": -16,
      "y": 0,
      "z": 5,
      "name": "Rock_Ice_Permafrost"
    },
    {
      "x": -16,
      "y": 1,
      "z": 5,
      "name": "Rock_Ice_Permafrost"
    },
    {
      "x": -16,
      "y": 2,
      "z": 5,
      "name": "Rock_Ice_Permafrost"
    },
    {
      "x": -16,
      "y": 3,
      "z": 5,
      "name": "Rock_Ice_Permafrost"
    },
    {
      "x": -16,
      "y": 4,
      "z": 5,
      "name": "Rock_Ice_Permafrost"
    },
    {
      "x": -16,
      "y": 5,
      "z": 5,
      "name": "Rock_Ice_Permafrost"
    },
    {
      "x": -16,
      "y": 6,
      "z": 5,
      "name": "Rock_Ice_Permafrost"
    },
    {
      "x": -16,
      "y": 7,
      "z": 5,
      "name": "Rock_Ice_Permafrost"
    },
    {
      "x": -16,
      "y": 8,
      "z": 5,
      "name": "Rock_Ice_Permafrost"
    },
    {
      "x": -16,
      "y": 0,
      "z": 6,
      "name": "Rock_Ice_Permafrost"
    },
    {
      "x": -16,
      "y": 1,
      "z": 6,
      "name": "Rock_Ice_Permafrost"
    },
    {
      "x": -16,
      "y": 2,
      "z": 6,
      "name": "Rock_Ice_Permafrost"
    },
    {
      "x": -16,
      "y": 3,
      "z": 6,
      "name": "Rock_Ice_Permafrost"
    },
    {
      "x": -16,
      "y": 4,
      "z": 6,
      "name": "Rock_Ice_Permafrost"
    },
    {
      "x": -16,
      "y": 5,
      "z": 6,
      "name": "Rock_Ice_Permafrost"
    },
    {
      "x": -16,
      "y": 6,
      "z": 6,
      "name": "Rock_Ice_Permafrost"
    },
    {
      "x": -16,
      "y": 7,
      "z": 6,
      "name": "Rock_Ice_Permafrost"
    },
    {
      "x": -16,
      "y": 0,
      "z": 7,
      "name": "Rock_Ice_Permafrost"
    },
    {
      "x": -16,
      "y": 1,
      "z": 7,
      "name": "Rock_Ice_Permafrost"
    },
    {
      "x": -16,
      "y": 2,
      "z": 7,
      "name": "Rock_Ice_Permafrost"
    },
    {
      "x": -16,
      "y": 3,
      "z": 7,
      "name": "Rock_Ice_Permafrost"
    },
    {
      "x": -16,
      "y": 4,
      "z": 7,
      "name": "Rock_Ice_Permafrost"
    },
    {
      "x": -16,
      "y": 5,
      "z": 7,
      "name": "Rock_Ice_Permafrost"
    },
    {
      "x": -16,
      "y": 6,
      "z": 7,
      "name": "Rock_Ice_Permafrost"
    },
    {
      "x": -16,
      "y": 0,
      "z": 8,
      "name": "Rock_Ice_Permafrost"
    },
    {
      "x": -16,
      "y": 1,
      "z": 8,
      "name": "Rock_Ice_Permafrost"
    },
    {
      "x": -16,
      "y": 2,
      "z": 8,
      "name": "Rock_Ice_Permafrost"
    },
    {
      "x": -16,
      "y": 3,
      "z": 8,
      "name": "Rock_Ice_Permafrost"
    },
    {
      "x": -16,
      "y": 4,
      "z": 8,
      "name": "Rock_Ice_Permafrost"
    },
    {
      "x": -16,
      "y": 5,
      "z": 8,
      "name": "Rock_Ice_Permafrost"
    },
    {
      "x": -16,
      "y": 6,
      "z": 8,
      "name": "Rock_Ice_Permafrost"
    },
    {
      "x": -16,
      "y": 0,
      "z": 9,
      "name": "Rock_Ice_Permafrost"
    },
    {
      "x": -16,
      "y": 1,
      "z": 9,
      "name": "Rock_Ice_Permafrost"
    },
    {
      "x": -16,
      "y": 2,
      "z": 9,
      "name": "Rock_Ice_Permafrost"
    },
    {
      "x": -16,
      "y": 3,
      "z": 9,
      "name": "Rock_Ice_Permafrost"
    },
    {
      "x": -16,
      "y": 4,
      "z": 9,
      "name": "Rock_Ice_Permafrost"
    },
    {
      "x": -16,
      "y": 5,
      "z": 9,
      "name": "Rock_Ice_Permafrost"
    },
    {
      "x": -16,
      "y": 0,
      "z": 10,
      "name": "Rock_Ice_Permafrost"
    },
    {
      "x": -16,
      "y": 1,
      "z": 10,
      "name": "Rock_Ice_Permafrost"
    },
    {
      "x": -16,
      "y": 2,
      "z": 10,
      "name": "Rock_Ice_Permafrost"
    },
    {
      "x": -16,
      "y": 3,
      "z": 10,
      "name": "Rock_Ice_Permafrost"
    },
    {
      "x": -16,
      "y": 4,
      "z": 10,
      "name": "Rock_Ice_Permafrost"
    },
    {
      "x": -16,
      "y": 0,
      "z": 11,
      "name": "Rock_Ice_Permafrost"
    },
    {
      "x": -16,
      "y": 1,
      "z": 11,
      "name": "Rock_Ice_Permafrost"
    },
    {
      "x": -16,
      "y": 2,
      "z": 11,
      "name": "Rock_Ice_Permafrost"
    },
    {
      "x": -16,
      "y": 3,
      "z": 11,
      "name": "Rock_Ice_Permafrost"
    },
    {
      "x": -16,
      "y": 4,
      "z": 11,
      "name": "Rock_Ice_Icicles"
    },
    {
      "x": -16,
      "y": 0,
      "z": 12,
      "name": "Rock_Ice_Permafrost"
    },
    {
      "x": -16,
      "y": 1,
      "z": 12,
      "name": "Rock_Ice_Permafrost"
    },
    {
      "x": -16,
      "y": 2,
      "z": 12,
      "name": "Rock_Ice_Permafrost"
    },
    {
      "x": -16,
      "y": 0,
      "z": 13,
      "name": "Rock_Ice_Permafrost"
    },
    {
      "x": -16,
      "y": 1,
      "z": 13,
      "name": "Rock_Ice_Permafrost"
    },
    {
      "x": -16,
      "y": 0,
      "z": 14,
      "name": "Rock_Ice_Permafrost"
    },
    {
      "x": -15,
      "y": 0,
      "z": -15,
      "name": "Rock_Ice_Permafrost"
    },
    {
      "x": -15,
      "y": 0,
      "z": -14,
      "name": "Rock_Ice_Permafrost"
    },
    {
      "x": -15,
      "y": 1,
      "z": -14,
      "name": "Rock_Ice_Permafrost"
    },
    {
      "x": -15,
      "y": 0,
      "z": -13,
      "name": "Rock_Ice_Permafrost"
    },
    {
      "x": -15,
      "y": 1,
      "z": -13,
      "name": "Rock_Ice_Permafrost"
    },
    {
      "x": -15,
      "y": 2,
      "z": -13,
      "name": "Rock_Ice_Permafrost"
    },
    {
      "x": -15,
      "y": 0,
      "z": -12,
      "name": "Rock_Ice_Permafrost"
    },
    {
      "x": -15,
      "y": 1,
      "z": -12,
      "name": "Rock_Ice_Permafrost"
    },
    {
      "x": -15,
      "y": 2,
      "z": -12,
      "name": "Rock_Ice_Permafrost"
    },
    {
      "x": -15,
      "y": 0,
      "z": -11,
      "name": "Rock_Ice_Permafrost"
    },
    {
      "x": -15,
      "y": 1,
      "z": -11,
      "name": "Rock_Ice_Permafrost"
    },
    {
      "x": -15,
      "y": 2,
      "z": -11,
      "name": "Rock_Ice_Permafrost"
    },
    {
      "x": -15,
      "y": 3,
      "z": -11,
      "name": "Rock_Ice_Permafrost"
    },
    {
      "x": -15,
      "y": 0,
      "z": -10,
      "name": "Rock_Ice_Permafrost"
    },
    {
      "x": -15,
      "y": 1,
      "z": -10,
      "name": "Rock_Ice_Permafrost"
    },
    {
      "x": -15,
      "y": 2,
      "z": -10,
      "name": "Rock_Ice_Permafrost"
    },
    {
      "x": -15,
      "y": 3,
      "z": -10,
      "name": "Rock_Ice_Permafrost"
    },
    {
      "x": -15,
      "y": 4,
      "z": -10,
      "name": "Rock_Ice_Permafrost"
    },
    {
      "x": -15,
      "y": 0,
      "z": -9,
      "name": "Rock_Ice_Permafrost"
    },
    {
      "x": -15,
      "y": 1,
      "z": -9,
      "name": "Rock_Ice_Permafrost"
    },
    {
      "x": -15,
      "y": 2,
      "z": -9,
      "name": "Rock_Ice_Permafrost"
    },
    {
      "x": -15,
      "y": 3,
      "z": -9,
      "name": "Rock_Ice_Permafrost"
    },
    {
      "x": -15,
      "y": 4,
      "z": -9,
      "name": "Rock_Ice_Permafrost"
    },
    {
      "x": -15,
      "y": 5,
      "z": -9,
      "name": "Rock_Ice_Permafrost"
    },
    {
      "x": -15,
      "y": 6,
      "z": -9,
      "name": "Rock_Ice_Stalactite_Large"
    },
    {
      "x": -15,
      "y": 0,
      "z": -8,
      "name": "Rock_Ice_Permafrost"
    },
    {
      "x": -15,
      "y": 1,
      "z": -8,
      "name": "Rock_Ice_Permafrost"
    },
    {
      "x": -15,
      "y": 2,
      "z": -8,
      "name": "Rock_Ice_Permafrost"
    },
    {
      "x": -15,
      "y": 3,
      "z": -8,
      "name": "Rock_Ice_Permafrost"
    },
    {
      "x": -15,
      "y": 4,
      "z": -8,
      "name": "Rock_Ice_Permafrost"
    },
    {
      "x": -15,
      "y": 5,
      "z": -8,
      "name": "Rock_Ice_Permafrost"
    },
    {
      "x": -15,
      "y": 6,
      "z": -8,
      "name": "Rock_Ice_Permafrost"
    },
    {
      "x": -15,
      "y": 0,
      "z": -7,
      "name": "Rock_Ice_Permafrost"
    },
    {
      "x": -15,
      "y": 1,
      "z": -7,
      "name": "Rock_Ice_Permafrost"
    },
    {
      "x": -15,
      "y": 2,
      "z": -7,
      "name": "Rock_Ice_Permafrost"
    },
    {
      "x": -15,
      "y": 3,
      "z": -7,
      "name": "Rock_Ice_Permafrost"
    },
    {
      "x": -15,
      "y": 4,
      "z": -7,
      "name": "Rock_Ice_Permafrost"
    },
    {
      "x": -15,
      "y": 5,
      "z": -7,
      "name": "Rock_Ice_Permafrost"
    },
    {
      "x": -15,
      "y": 6,
      "z": -7,
      "name": "Rock_Ice_Permafrost"
    },
    {
      "x": -15,
      "y": 7,
      "z": -7,
      "name": "Rock_Ice_Permafrost"
    },
    {
      "x": -15,
      "y": 0,
      "z": -6,
      "name": "Rock_Ice_Permafrost"
    },
    {
      "x": -15,
      "y": 1,
      "z": -6,
      "name": "Rock_Ice_Permafrost"
    },
    {
      "x": -15,
      "y": 2,
      "z": -6,
      "name": "Rock_Ice_Permafrost"
    },
    {
      "x": -15,
      "y": 3,
      "z": -6,
      "name": "Rock_Ice_Permafrost"
    },
    {
      "x": -15,
      "y": 4,
      "z": -6,
      "name": "Rock_Ice_Permafrost"
    },
    {
      "x": -15,
      "y": 5,
      "z": -6,
      "name": "Rock_Ice_Permafrost"
    },
    {
      "x": -15,
      "y": 6,
      "z": -6,
      "name": "Rock_Ice_Permafrost"
    },
    {
      "x": -15,
      "y": 7,
      "z": -6,
      "name": "Rock_Ice_Permafrost"
    },
    {
      "x": -15,
      "y": 8,
      "z": -6,
      "name": "Rock_Ice_Permafrost"
    },
    {
      "x": -15,
      "y": 0,
      "z": -5,
      "name": "Rock_Ice_Permafrost"
    },
    {
      "x": -15,
      "y": 1,
      "z": -5,
      "name": "Rock_Ice_Permafrost"
    },
    {
      "x": -15,
      "y": 2,
      "z": -5,
      "name": "Rock_Ice_Permafrost"
    },
    {
      "x": -15,
      "y": 3,
      "z": -5,
      "name": "Rock_Ice_Permafrost"
    },
    {
      "x": -15,
      "y": 4,
      "z": -5,
      "name": "Rock_Ice_Permafrost"
    },
    {
      "x": -15,
      "y": 5,
      "z": -5,
      "name": "Rock_Ice_Permafrost"
    },
    {
      "x": -15,
      "y": 6,
      "z": -5,
      "name": "Rock_Ice_Permafrost"
    },
    {
      "x": -15,
      "y": 7,
      "z": -5,
      "name": "Rock_Ice_Permafrost"
    },
    {
      "x": -15,
      "y": 8,
      "z": -5,
      "name": "Rock_Ice_Permafrost"
    },
    {
      "x": -15,
      "y": 9,
      "z": -5,
      "name": "Rock_Ice_Permafrost"
    },
    {
      "x": -15,
      "y": 10,
      "z": -5,
      "name": "Rock_Ice_Stalactite_Large"
    },
    {
      "x": -15,
      "y": 11,
      "z": -5,
      "name": "Rock_Ice_Stalactite_Large",
      "filler": 1024
    },
    {
      "x": -15,
      "y": 0,
      "z": -4,
      "name": "Rock_Ice_Permafrost"
    },
    {
      "x": -15,
      "y": 1,
      "z": -4,
      "name": "Rock_Ice_Permafrost"
    },
    {
      "x": -15,
      "y": 2,
      "z": -4,
      "name": "Rock_Ice_Permafrost"
    },
    {
      "x": -15,
      "y": 3,
      "z": -4,
      "name": "Rock_Ice_Permafrost"
    },
    {
      "x": -15,
      "y": 4,
      "z": -4,
      "name": "Rock_Ice_Permafrost"
    },
    {
      "x": -15,
      "y": 5,
      "z": -4,
      "name": "Rock_Ice_Permafrost"
    },
    {
      "x": -15,
      "y": 6,
      "z": -4,
      "name": "Rock_Ice_Permafrost"
    },
    {
      "x": -15,
      "y": 7,
      "z": -4,
      "name": "Rock_Ice_Permafrost"
    },
    {
      "x": -15,
      "y": 8,
      "z": -4,
      "name": "Rock_Ice_Permafrost"
    },
    {
      "x": -15,
      "y": 9,
      "z": -4,
      "name": "Rock_Ice_Permafrost"
    },
    {
      "x": -15,
      "y": 0,
      "z": -3,
      "name": "Rock_Ice_Permafrost"
    },
    {
      "x": -15,
      "y": 1,
      "z": -3,
      "name": "Rock_Ice_Permafrost"
    },
    {
      "x": -15,
      "y": 2,
      "z": -3,
      "name": "Rock_Ice_Permafrost"
    },
    {
      "x": -15,
      "y": 3,
      "z": -3,
      "name": "Rock_Ice_Permafrost"
    },
    {
      "x": -15,
      "y": 4,
      "z": -3,
      "name": "Rock_Ice_Permafrost"
    },
    {
      "x": -15,
      "y": 5,
      "z": -3,
      "name": "Rock_Ice_Permafrost"
    },
    {
      "x": -15,
      "y": 6,
      "z": -3,
      "name": "Rock_Ice_Permafrost"
    },
    {
      "x": -15,
      "y": 7,
      "z": -3,
      "name": "Rock_Ice_Permafrost"
    },
    {
      "x": -15,
      "y": 8,
      "z": -3,
      "name": "Rock_Ice_Permafrost"
    },
    {
      "x": -15,
      "y": 9,
      "z": -3,
      "name": "Rock_Ice_Permafrost"
    },
    {
      "x": -15,
      "y": 10,
      "z": -3,
      "name": "Rock_Ice_Permafrost"
    },
    {
      "x": -15,
      "y": 0,
      "z": -2,
      "name": "Rock_Ice_Permafrost"
    },
    {
      "x": -15,
      "y": 1,
      "z": -2,
      "name": "Rock_Ice_Permafrost"
    },
    {
      "x": -15,
      "y": 2,
      "z": -2,
      "name": "Rock_Ice_Permafrost"
    },
    {
      "x": -15,
      "y": 3,
      "z": -2,
      "name": "Rock_Ice_Permafrost"
    },
    {
      "x": -15,
      "y": 4,
      "z": -2,
      "name": "Rock_Ice_Permafrost"
    },
    {
      "x": -15,
      "y": 5,
      "z": -2,
      "name": "Rock_Ice_Permafrost"
    },
    {
      "x": -15,
      "y": 6,
      "z": -2,
      "name": "Rock_Ice_Permafrost"
    },
    {
      "x": -15,
      "y": 7,
      "z": -2,
      "name": "Rock_Ice_Permafrost"
    },
    {
      "x": -15,
      "y": 8,
      "z": -2,
      "name": "Rock_Ice_Permafrost"
    },
    {
      "x": -15,
      "y": 9,
      "z": -2,
      "name": "Rock_Ice_Permafrost"
    },
    {
      "x": -15,
      "y": 10,
      "z": -2,
      "name": "Rock_Ice_Permafrost"
    },
    {
      "x": -15,
      "y": 11,
      "z": -2,
      "name": "Rock_Ice_Stalactite_Large"
    },
    {
      "x": -15,
      "y": 0,
      "z": -1,
      "name": "Rock_Ice_Permafrost"
    },
    {
      "x": -15,
      "y": 1,
      "z": -1,
      "name": "Rock_Ice_Permafrost"
    },
    {
      "x": -15,
      "y": 2,
      "z": -1,
      "name": "Rock_Ice_Permafrost"
    },
    {
      "x": -15,
      "y": 3,
      "z": -1,
      "name": "Rock_Ice_Permafrost"
    },
    {
      "x": -15,
      "y": 4,
      "z": -1,
      "name": "Rock_Ice_Permafrost"
    },
    {
      "x": -15,
      "y": 5,
      "z": -1,
      "name": "Rock_Ice_Permafrost"
    },
    {
      "x": -15,
      "y": 6,
      "z": -1,
      "name": "Rock_Ice_Permafrost"
    },
    {
      "x": -15,
      "y": 7,
      "z": -1,
      "name": "Rock_Ice_Permafrost"
    },
    {
      "x": -15,
      "y": 8,
      "z": -1,
      "name": "Rock_Ice_Permafrost"
    },
    {
      "x": -15,
      "y": 9,
      "z": -1,
      "name": "Rock_Ice_Permafrost"
    },
    {
      "x": -15,
      "y": 10,
      "z": -1,
      "name": "Rock_Ice_Permafrost"
    },
    {
      "x": -15,
      "y": 11,
      "z": -1,
      "name": "Rock_Ice_Permafrost"
    },
    {
      "x": -15,
      "y": 12,
      "z": -1,
      "name": "Rock_Ice_Icicles"
    },
    {
      "x": -15,
      "y": 0,
      "z": 0,
      "name": "Rock_Ice_Permafrost"
    },
    {
      "x": -15,
      "y": 1,
      "z": 0,
      "name": "Rock_Ice_Permafrost"
    },
    {
      "x": -15,
      "y": 2,
      "z": 0,
      "name": "Rock_Ice_Permafrost"
    },
    {
      "x": -15,
      "y": 3,
      "z": 0,
      "name": "Rock_Ice_Permafrost"
    },
    {
      "x": -15,
      "y": 4,
      "z": 0,
      "name": "Rock_Ice_Permafrost"
    },
    {
      "x": -15,
      "y": 5,
      "z": 0,
      "name": "Rock_Ice_Permafrost"
    },
    {
      "x": -15,
      "y": 6,
      "z": 0,
      "name": "Rock_Ice_Permafrost"
    },
    {
      "x": -15,
      "y": 7,
      "z": 0,
      "name": "Rock_Ice_Permafrost"
    },
    {
      "x": -15,
      "y": 8,
      "z": 0,
      "name": "Rock_Ice_Permafrost"
    },
    {
      "x": -15,
      "y": 9,
      "z": 0,
      "name": "Rock_Ice_Permafrost"
    },
    {
      "x": -15,
      "y": 10,
      "z": 0,
      "name": "Rock_Ice_Permafrost"
    },
    {
      "x": -15,
      "y": 11,
      "z": 0,
      "name": "Rock_Ice_Permafrost"
    },
    {
      "x": -15,
      "y": 0,
      "z": 1,
      "name": "Rock_Ice_Permafrost"
    },
    {
      "x": -15,
      "y": 1,
      "z": 1,
      "name": "Rock_Ice_Permafrost"
    },
    {
      "x": -15,
      "y": 2,
      "z": 1,
      "name": "Rock_Ice_Permafrost"
    },
    {
      "x": -15,
      "y": 3,
      "z": 1,
      "name": "Rock_Ice_Permafrost"
    },
    {
      "x": -15,
      "y": 4,
      "z": 1,
      "name": "Rock_Ice_Permafrost"
    },
    {
      "x": -15,
      "y": 5,
      "z": 1,
      "name": "Rock_Ice_Permafrost"
    },
    {
      "x": -15,
      "y": 6,
      "z": 1,
      "name": "Rock_Ice_Permafrost"
    },
    {
      "x": -15,
      "y": 7,
      "z": 1,
      "name": "Rock_Ice_Permafrost"
    },
    {
      "x": -15,
      "y": 8,
      "z": 1,
      "name": "Rock_Ice_Permafrost"
    },
    {
      "x": -15,
      "y": 9,
      "z": 1,
      "name": "Rock_Ice_Permafrost"
    },
    {
      "x": -15,
      "y": 10,
      "z": 1,
      "name": "Rock_Ice_Permafrost"
    },
    {
      "x": -15,
      "y": 11,
      "z": 1,
      "name": "Rock_Ice_Permafrost"
    },
    {
      "x": -15,
      "y": 12,
      "z": 1,
      "name": "Rock_Ice_Icicles"
    },
    {
      "x": -15,
      "y": 0,
      "z": 2,
      "name": "Rock_Ice_Permafrost"
    },
    {
      "x": -15,
      "y": 1,
      "z": 2,
      "name": "Rock_Ice_Permafrost"
    },
    {
      "x": -15,
      "y": 2,
      "z": 2,
      "name": "Rock_Ice_Permafrost"
    },
    {
      "x": -15,
      "y": 3,
      "z": 2,
      "name": "Rock_Ice_Permafrost"
    },
    {
      "x": -15,
      "y": 4,
      "z": 2,
      "name": "Rock_Ice_Permafrost"
    },
    {
      "x": -15,
      "y": 5,
      "z": 2,
      "name": "Rock_Ice_Permafrost"
    },
    {
      "x": -15,
      "y": 6,
      "z": 2,
      "name": "Rock_Ice_Permafrost"
    },
    {
      "x": -15,
      "y": 7,
      "z": 2,
      "name": "Rock_Ice_Permafrost"
    },
    {
      "x": -15,
      "y": 8,
      "z": 2,
      "name": "Rock_Ice_Permafrost"
    },
    {
      "x": -15,
      "y": 9,
      "z": 2,
      "name": "Rock_Ice_Permafrost"
    },
    {
      "x": -15,
      "y": 10,
      "z": 2,
      "name": "Rock_Ice_Permafrost"
    },
    {
      "x": -15,
      "y": 11,
      "z": 2,
      "name": "Rock_Ice_Permafrost"
    },
    {
      "x": -15,
      "y": 0,
      "z": 3,
      "name": "Rock_Ice_Permafrost"
    },
    {
      "x": -15,
      "y": 1,
      "z": 3,
      "name": "Rock_Ice_Permafrost"
    },
    {
      "x": -15,
      "y": 2,
      "z": 3,
      "name": "Rock_Ice_Permafrost"
    },
    {
      "x": -15,
      "y": 3,
      "z": 3,
      "name": "Rock_Ice_Permafrost"
    },
    {
      "x": -15,
      "y": 4,
      "z": 3,
      "name": "Rock_Ice_Permafrost"
    },
    {
      "x": -15,
      "y": 5,
      "z": 3,
      "name": "Rock_Ice_Permafrost"
    },
    {
      "x": -15,
      "y": 6,
      "z": 3,
      "name": "Rock_Ice_Permafrost"
    },
    {
      "x": -15,
      "y": 7,
      "z": 3,
      "name": "Rock_Ice_Permafrost"
    },
    {
      "x": -15,
      "y": 8,
      "z": 3,
      "name": "Rock_Ice_Permafrost"
    },
    {
      "x": -15,
      "y": 9,
      "z": 3,
      "name": "Rock_Ice_Permafrost"
    },
    {
      "x": -15,
      "y": 10,
      "z": 3,
      "name": "Rock_Ice_Permafrost"
    },
    {
      "x": -15,
      "y": 0,
      "z": 4,
      "name": "Rock_Ice_Permafrost"
    },
    {
      "x": -15,
      "y": 1,
      "z": 4,
      "name": "Rock_Ice_Permafrost"
    },
    {
      "x": -15,
      "y": 2,
      "z": 4,
      "name": "Rock_Ice_Permafrost"
    },
    {
      "x": -15,
      "y": 3,
      "z": 4,
      "name": "Rock_Ice_Permafrost"
    },
    {
      "x": -15,
      "y": 4,
      "z": 4,
      "name": "Rock_Ice_Permafrost"
    },
    {
      "x": -15,
      "y": 5,
      "z": 4,
      "name": "Rock_Ice_Permafrost"
    },
    {
      "x": -15,
      "y": 6,
      "z": 4,
      "name": "Rock_Ice_Permafrost"
    },
    {
      "x": -15,
      "y": 7,
      "z": 4,
      "name": "Rock_Ice_Permafrost"
    },
    {
      "x": -15,
      "y": 8,
      "z": 4,
      "name": "Rock_Ice_Permafrost"
    },
    {
      "x": -15,
      "y": 9,
      "z": 4,
      "name": "Rock_Ice_Permafrost"
    },
    {
      "x": -15,
      "y": 10,
      "z": 4,
      "name": "Rock_Ice_Permafrost"
    },
    {
      "x": -15,
      "y": 0,
      "z": 5,
      "name": "Rock_Ice_Permafrost"
    },
    {
      "x": -15,
      "y": 1,
      "z": 5,
      "name": "Rock_Ice_Permafrost"
    },
    {
      "x": -15,
      "y": 2,
      "z": 5,
      "name": "Rock_Ice_Permafrost"
    },
    {
      "x": -15,
      "y": 3,
      "z": 5,
      "name": "Rock_Ice_Permafrost"
    },
    {
      "x": -15,
      "y": 4,
      "z": 5,
      "name": "Rock_Ice_Permafrost"
    },
    {
      "x": -15,
      "y": 5,
      "z": 5,
      "name": "Rock_Ice_Permafrost"
    },
    {
      "x": -15,
      "y": 6,
      "z": 5,
      "name": "Rock_Ice_Permafrost"
    },
    {
      "x": -15,
      "y": 7,
      "z": 5,
      "name": "Rock_Ice_Permafrost"
    },
    {
      "x": -15,
      "y": 8,
      "z": 5,
      "name": "Rock_Ice_Permafrost"
    },
    {
      "x": -15,
      "y": 9,
      "z": 5,
      "name": "Rock_Ice_Permafrost"
    },
    {
      "x": -15,
      "y": 0,
      "z": 6,
      "name": "Rock_Ice_Permafrost"
    },
    {
      "x": -15,
      "y": 1,
      "z": 6,
      "name": "Rock_Ice_Permafrost"
    },
    {
      "x": -15,
      "y": 2,
      "z": 6,
      "name": "Rock_Ice_Permafrost"
    },
    {
      "x": -15,
      "y": 3,
      "z": 6,
      "name": "Rock_Ice_Permafrost"
    },
    {
      "x": -15,
      "y": 4,
      "z": 6,
      "name": "Rock_Ice_Permafrost"
    },
    {
      "x": -15,
      "y": 5,
      "z": 6,
      "name": "Rock_Ice_Permafrost"
    },
    {
      "x": -15,
      "y": 6,
      "z": 6,
      "name": "Rock_Ice_Permafrost"
    },
    {
      "x": -15,
      "y": 7,
      "z": 6,
      "name": "Rock_Ice_Permafrost"
    },
    {
      "x": -15,
      "y": 8,
      "z": 6,
      "name": "Rock_Ice_Permafrost"
    },
    {
      "x": -15,
      "y": 9,
      "z": 6,
      "name": "Rock_Ice_Stalactite_Large"
    },
    {
      "x": -15,
      "y": 10,
      "z": 6,
      "name": "Rock_Ice_Stalactite_Large",
      "filler": 1024
    },
    {
      "x": -15,
      "y": 0,
      "z": 7,
      "name": "Rock_Ice_Permafrost"
    },
    {
      "x": -15,
      "y": 1,
      "z": 7,
      "name": "Rock_Ice_Permafrost"
    },
    {
      "x": -15,
      "y": 2,
      "z": 7,
      "name": "Rock_Ice_Permafrost"
    },
    {
      "x": -15,
      "y": 3,
      "z": 7,
      "name": "Rock_Ice_Permafrost"
    },
    {
      "x": -15,
      "y": 4,
      "z": 7,
      "name": "Rock_Ice_Permafrost"
    },
    {
      "x": -15,
      "y": 5,
      "z": 7,
      "name": "Rock_Ice_Permafrost"
    },
    {
      "x": -15,
      "y": 6,
      "z": 7,
      "name": "Rock_Ice_Permafrost"
    },
    {
      "x": -15,
      "y": 7,
      "z": 7,
      "name": "Rock_Ice_Permafrost"
    },
    {
      "x": -15,
      "y": 0,
      "z": 8,
      "name": "Rock_Ice_Permafrost"
    },
    {
      "x": -15,
      "y": 1,
      "z": 8,
      "name": "Rock_Ice_Permafrost"
    },
    {
      "x": -15,
      "y": 2,
      "z": 8,
      "name": "Rock_Ice_Permafrost"
    },
    {
      "x": -15,
      "y": 3,
      "z": 8,
      "name": "Rock_Ice_Permafrost"
    },
    {
      "x": -15,
      "y": 4,
      "z": 8,
      "name": "Rock_Ice_Permafrost"
    },
    {
      "x": -15,
      "y": 5,
      "z": 8,
      "name": "Rock_Ice_Permafrost"
    },
    {
      "x": -15,
      "y": 6,
      "z": 8,
      "name": "Rock_Ice_Permafrost"
    },
    {
      "x": -15,
      "y": 7,
      "z": 8,
      "name": "Rock_Ice_Permafrost"
    },
    {
      "x": -15,
      "y": 0,
      "z": 9,
      "name": "Rock_Ice_Permafrost"
    },
    {
      "x": -15,
      "y": 1,
      "z": 9,
      "name": "Rock_Ice_Permafrost"
    },
    {
      "x": -15,
      "y": 2,
      "z": 9,
      "name": "Rock_Ice_Permafrost"
    },
    {
      "x": -15,
      "y": 3,
      "z": 9,
      "name": "Rock_Ice_Permafrost"
    },
    {
      "x": -15,
      "y": 4,
      "z": 9,
      "name": "Rock_Ice_Permafrost"
    },
    {
      "x": -15,
      "y": 5,
      "z": 9,
      "name": "Rock_Ice_Permafrost"
    },
    {
      "x": -15,
      "y": 6,
      "z": 9,
      "name": "Rock_Ice_Permafrost"
    },
    {
      "x": -15,
      "y": 7,
      "z": 9,
      "name": "Rock_Ice_Icicles"
    },
    {
      "x": -15,
      "y": 0,
      "z": 10,
      "name": "Rock_Ice_Permafrost"
    },
    {
      "x": -15,
      "y": 1,
      "z": 10,
      "name": "Rock_Ice_Permafrost"
    },
    {
      "x": -15,
      "y": 2,
      "z": 10,
      "name": "Rock_Ice_Permafrost"
    },
    {
      "x": -15,
      "y": 3,
      "z": 10,
      "name": "Rock_Ice_Permafrost"
    },
    {
      "x": -15,
      "y": 4,
      "z": 10,
      "name": "Rock_Ice_Permafrost"
    },
    {
      "x": -15,
      "y": 5,
      "z": 10,
      "name": "Rock_Ice_Permafrost"
    },
    {
      "x": -15,
      "y": 0,
      "z": 11,
      "name": "Rock_Ice_Permafrost"
    },
    {
      "x": -15,
      "y": 1,
      "z": 11,
      "name": "Rock_Ice_Permafrost"
    },
    {
      "x": -15,
      "y": 2,
      "z": 11,
      "name": "Rock_Ice_Permafrost"
    },
    {
      "x": -15,
      "y": 3,
      "z": 11,
      "name": "Rock_Ice_Permafrost"
    },
    {
      "x": -15,
      "y": 4,
      "z": 11,
      "name": "Rock_Ice_Permafrost"
    },
    {
      "x": -15,
      "y": 0,
      "z": 12,
      "name": "Rock_Ice_Permafrost"
    },
    {
      "x": -15,
      "y": 1,
      "z": 12,
      "name": "Rock_Ice_Permafrost"
    },
    {
      "x": -15,
      "y": 2,
      "z": 12,
      "name": "Rock_Ice_Permafrost"
    },
    {
      "x": -15,
      "y": 3,
      "z": 12,
      "name": "Rock_Ice_Permafrost"
    },
    {
      "x": -15,
      "y": 0,
      "z": 13,
      "name": "Rock_Ice_Permafrost"
    },
    {
      "x": -15,
      "y": 1,
      "z": 13,
      "name": "Rock_Ice_Permafrost"
    },
    {
      "x": -15,
      "y": 2,
      "z": 13,
      "name": "Rock_Ice_Permafrost"
    },
    {
      "x": -15,
      "y": 0,
      "z": 14,
      "name": "Rock_Ice_Permafrost"
    },
    {
      "x": -15,
      "y": 1,
      "z": 14,
      "name": "Rock_Ice_Permafrost"
    },
    {
      "x": -15,
      "y": 0,
      "z": 15,
      "name": "Rock_Ice_Permafrost"
    },
    {
      "x": -14,
      "y": 0,
      "z": -15,
      "name": "Rock_Ice_Permafrost"
    },
    {
      "x": -14,
      "y": 0,
      "z": -14,
      "name": "Rock_Ice_Permafrost"
    },
    {
      "x": -14,
      "y": 1,
      "z": -14,
      "name": "Rock_Ice_Permafrost"
    },
    {
      "x": -14,
      "y": 0,
      "z": -13,
      "name": "Rock_Ice_Permafrost"
    },
    {
      "x": -14,
      "y": 1,
      "z": -13,
      "name": "Rock_Ice_Permafrost"
    },
    {
      "x": -14,
      "y": 2,
      "z": -13,
      "name": "Rock_Ice_Permafrost"
    },
    {
      "x": -14,
      "y": 3,
      "z": -13,
      "name": "Rock_Ice_Icicles"
    },
    {
      "x": -14,
      "y": 0,
      "z": -12,
      "name": "Rock_Ice_Permafrost"
    },
    {
      "x": -14,
      "y": 1,
      "z": -12,
      "name": "Rock_Ice_Permafrost"
    },
    {
      "x": -14,
      "y": 2,
      "z": -12,
      "name": "Rock_Ice_Permafrost"
    },
    {
      "x": -14,
      "y": 3,
      "z": -12,
      "name": "Rock_Ice_Permafrost"
    },
    {
      "x": -14,
      "y": 0,
      "z": -11,
      "name": "Rock_Ice_Permafrost"
    },
    {
      "x": -14,
      "y": 1,
      "z": -11,
      "name": "Rock_Ice_Permafrost"
    },
    {
      "x": -14,
      "y": 2,
      "z": -11,
      "name": "Rock_Ice_Permafrost"
    },
    {
      "x": -14,
      "y": 3,
      "z": -11,
      "name": "Rock_Ice_Permafrost"
    },
    {
      "x": -14,
      "y": 4,
      "z": -11,
      "name": "Rock_Ice_Permafrost"
    },
    {
      "x": -14,
      "y": 5,
      "z": -11,
      "name": "Rock_Ice_Icicles"
    },
    {
      "x": -14,
      "y": 0,
      "z": -10,
      "name": "Rock_Ice_Permafrost"
    },
    {
      "x": -14,
      "y": 1,
      "z": -10,
      "name": "Rock_Ice_Permafrost"
    },
    {
      "x": -14,
      "y": 2,
      "z": -10,
      "name": "Rock_Ice_Permafrost"
    },
    {
      "x": -14,
      "y": 3,
      "z": -10,
      "name": "Rock_Ice_Permafrost"
    },
    {
      "x": -14,
      "y": 4,
      "z": -10,
      "name": "Rock_Ice_Permafrost"
    },
    {
      "x": -14,
      "y": 5,
      "z": -10,
      "name": "Rock_Ice_Permafrost"
    },
    {
      "x": -14,
      "y": 6,
      "z": -10,
      "name": "Rock_Ice_Icicles"
    },
    {
      "x": -14,
      "y": 0,
      "z": -9,
      "name": "Rock_Ice_Permafrost"
    },
    {
      "x": -14,
      "y": 1,
      "z": -9,
      "name": "Rock_Ice_Permafrost"
    },
    {
      "x": -14,
      "y": 2,
      "z": -9,
      "name": "Rock_Ice_Permafrost"
    },
    {
      "x": -14,
      "y": 3,
      "z": -9,
      "name": "Rock_Ice_Permafrost"
    },
    {
      "x": -14,
      "y": 4,
      "z": -9,
      "name": "Rock_Ice_Permafrost"
    },
    {
      "x": -14,
      "y": 5,
      "z": -9,
      "name": "Rock_Ice_Permafrost"
    },
    {
      "x": -14,
      "y": 6,
      "z": -9,
      "name": "Rock_Ice_Permafrost"
    },
    {
      "x": -14,
