{
  "version": 8,
  "blockIdVersion": 10,
  "anchorX": 0,
  "anchorY": 0,
  "anchorZ": 0,
  "blocks": [
    {
      "x": -8,
      "y": 0,
      "z": 2,
      "name": "Rock_Ice_Permafrost",
      "rotation": 3
    },
    {
      "x": -8,
      "y": 0,
      "z": 3,
      "name": "Rock_Ice_Permafrost",
      "rotation": 3
    },
    {
      "x": -8,
      "y": 1,
      "z": 3,
      "name": "Rock_Ice_Stalactite_Large",
      "rotation": 3
    },
    {
      "x": -8,
      "y": 2,
      "z": 3,
      "name": "Rock_Ice_Stalactite_Large",
      "filler": 1024,
      "rotation": 3
    },
    {
      "x": -7,
      "y": 0,
      "z": 0,
      "name": "Rock_Ice_Permafrost",
      "rotation": 3
    },
    {
      "x": -7,
      "y": 1,
      "z": 0,
      "name": "Rock_Ice_Permafrost",
      "rotation": 3
    },
    {
      "x": -7,
      "y": 0,
      "z": 1,
      "name": "Rock_Ice_Permafrost",
      "rotation": 3
    },
    {
      "x": -7,
      "y": 1,
      "z": 1,
      "name": "Rock_Ice_Permafrost",
      "rotation": 3
    },
    {
      "x": -7,
      "y": 2,
      "z": 1,
      "name": "Rock_Ice_Icicles",
      "rotation": 3
    },
    {
      "x": -7,
      "y": 0,
      "z": 2,
      "name": "Rock_Ice_Permafrost"
    },
    {
      "x": -7,
      "y": 1,
      "z": 2,
      "name": "Rock_Ice_Permafrost",
      "rotation": 3
    },
    {
      "x": -7,
      "y": 0,
      "z": 3,
      "name": "Rock_Ice_Permafrost",
      "rotation": 3
    },
    {
      "x": -7,
      "y": 0,
      "z": 4,
      "name": "Rock_Ice_Permafrost",
      "rotation": 3
    },
    {
      "x": -6,
      "y": 0,
      "z": -1,
      "name": "Rock_Ice_Permafrost",
      "rotation": 3
    },
    {
      "x": -6,
      "y": 1,
      "z": -1,
      "name": "Rock_Ice_Permafrost",
      "rotation": 3
    },
    {
      "x": -6,
      "y": 2,
      "z": -1,
      "name": "Rock_Crystal_Cyan_Medium",
      "rotation": 3
    },
    {
      "x": -6,
      "y": 0,
      "z": 0,
      "name": "Rock_Ice_Permafrost",
      "rotation": 3
    },
    {
      "x": -6,
      "y": 1,
      "z": 0,
      "name": "Rock_Ice_Permafrost",
      "rotation": 3
    },
    {
      "x": -6,
      "y": 2,
      "z": 0,
      "name": "Rock_Ice_Permafrost",
      "rotation": 3
    },
    {
      "x": -6,
      "y": 3,
      "z": 0,
      "name": "Rock_Ice_Permafrost",
      "rotation": 3
    },
    {
      "x": -6,
      "y": 0,
      "z": 1,
      "name": "Rock_Ice_Permafrost",
      "rotation": 3
    },
    {
      "x": -6,
      "y": 1,
      "z": 1,
      "name": "Rock_Ice_Permafrost",
      "rotation": 3
    },
    {
      "x": -6,
      "y": 2,
      "z": 1,
      "name": "Rock_Ice_Permafrost",
      "rotation": 3
    },
    {
      "x": -6,
      "y": 0,
      "z": 2,
      "name": "Rock_Ice_Permafrost",
      "rotation": 3
    },
    {
      "x": -6,
      "y": 1,
      "z": 2,
      "name": "Rock_Ice_Permafrost",
      "rotation": 3
    },
    {
      "x": -6,
      "y": 2,
      "z": 2,
      "name": "Rock_Ice_Permafrost",
      "rotation": 3
    },
    {
      "x": -6,
      "y": 0,
      "z": 3,
      "name": "Rock_Ice_Permafrost",
      "rotation": 3
    },
    {
      "x": -6,
      "y": 1,
      "z": 3,
      "name": "Rock_Ice_Permafrost",
      "rotation": 3
    },
    {
      "x": -6,
      "y": 2,
      "z": 3,
      "name": "Rock_Ice_Icicles",
      "rotation": 3
    },
    {
      "x": -6,
      "y": 0,
      "z": 4,
      "name": "Rock_Ice_Permafrost",
      "rotation": 3
    },
    {
      "x": -6,
      "y": 0,
      "z": 5,
      "name": "Rock_Ice_Permafrost",
      "rotation": 3
    },
    {
      "x": -5,
      "y": 0,
      "z": -2,
      "name": "Rock_Ice_Permafrost",
      "rotation": 3
    },
    {
      "x": -5,
      "y": 0,
      "z": -1,
      "name": "Rock_Ice_Permafrost"
    },
    {
      "x": -5,
      "y": 1,
      "z": -1,
      "name": "Rock_Ice_Permafrost",
      "rotation": 3
    },
    {
      "x": -5,
      "y": 2,
      "z": -1,
      "name": "Rock_Ice_Permafrost",
      "rotation": 3
    },
    {
      "x": -5,
      "y": 3,
      "z": -1,
      "name": "Rock_Ice_Permafrost",
      "rotation": 3
    },
    {
      "x": -5,
      "y": 4,
      "z": -1,
      "name": "Rock_Ice_Icicles",
      "rotation": 3
    },
    {
      "x": -5,
      "y": 0,
      "z": 0,
      "name": "Rock_Ice_Permafrost"
    },
    {
      "x": -5,
      "y": 1,
      "z": 0,
      "name": "Rock_Ice_Permafrost",
      "rotation": 3
    },
    {
      "x": -5,
      "y": 2,
      "z": 0,
      "name": "Rock_Ice_Permafrost",
      "rotation": 3
    },
    {
      "x": -5,
      "y": 3,
      "z": 0,
      "name": "Rock_Ice_Permafrost",
      "rotation": 3
    },
    {
      "x": -5,
      "y": 0,
      "z": 1,
      "name": "Rock_Ice_Permafrost",
      "rotation": 3
    },
    {
      "x": -5,
      "y": 1,
      "z": 1,
      "name": "Rock_Ice_Permafrost",
      "rotation": 3
    },
    {
      "x": -5,
      "y": 2,
      "z": 1,
      "name": "Rock_Ice_Permafrost",
      "rotation": 3
    },
    {
      "x": -5,
      "y": 3,
      "z": 1,
      "name": "Rock_Ice_Permafrost",
      "rotation": 3
    },
    {
      "x": -5,
      "y": 0,
      "z": 2,
      "name": "Rock_Ice_Permafrost",
      "rotation": 3
    },
    {
      "x": -5,
      "y": 1,
      "z": 2,
      "name": "Rock_Ice_Permafrost",
      "rotation": 3
    },
    {
      "x": -5,
      "y": 2,
      "z": 2,
      "name": "Rock_Ice_Permafrost",
      "rotation": 3
    },
    {
      "x": -5,
      "y": 3,
      "z": 2,
      "name": "Rubble_Ice_Medium",
      "support": 15,
      "rotation": 3
    },
    {
      "x": -5,
      "y": 0,
      "z": 3,
      "name": "Rock_Ice_Permafrost",
      "rotation": 3
    },
    {
      "x": -5,
      "y": 1,
      "z": 3,
      "name": "Rock_Ice_Permafrost",
      "rotation": 3
    },
    {
      "x": -5,
      "y": 2,
      "z": 3,
      "name": "Rock_Ice_Permafrost",
      "rotation": 3
    },
    {
      "x": -5,
      "y": 3,
      "z": 3,
      "name": "Rock_Ice_Stalactite_Large",
      "rotation": 3
    },
    {
      "x": -5,
      "y": 4,
      "z": 3,
      "name": "Rock_Ice_Stalactite_Large",
      "filler": 1024,
      "rotation": 3
    },
    {
      "x": -5,
      "y": 0,
      "z": 4,
      "name": "Rock_Ice_Permafrost",
      "rotation": 3
    },
    {
      "x": -5,
      "y": 1,
      "z": 4,
      "name": "Rock_Ice_Permafrost",
      "rotation": 3
    },
    {
      "x": -5,
      "y": 2,
      "z": 4,
      "name": "Rock_Ice_Permafrost",
      "rotation": 3
    },
    {
      "x": -5,
      "y": 3,
      "z": 4,
      "name": "Rock_Ice_Icicles",
      "rotation": 3
    },
    {
      "x": -5,
      "y": 0,
      "z": 5,
      "name": "Rock_Ice_Permafrost",
      "rotation": 3
    },
    {
      "x": -5,
      "y": 0,
      "z": 6,
      "name": "Rock_Ice_Permafrost",
      "rotation": 3
    },
    {
      "x": -4,
      "y": 0,
      "z": -4,
      "name": "Rock_Ice_Permafrost",
      "rotation": 3
    },
    {
      "x": -4,
      "y": 1,
      "z": -4,
      "name": "Rock_Ice_Stalactite_Large",
      "rotation": 3
    },
    {
      "x": -4,
      "y": 2,
      "z": -4,
      "name": "Rock_Ice_Stalactite_Large",
      "filler": 1024,
      "rotation": 3
    },
    {
      "x": -4,
      "y": 0,
      "z": -3,
      "name": "Rock_Ice_Permafrost",
      "rotation": 3
    },
    {
      "x": -4,
      "y": 0,
      "z": -2,
      "name": "Rock_Ice_Permafrost"
    },
    {
      "x": -4,
      "y": 1,
      "z": -2,
      "name": "Rock_Ice_Permafrost",
      "rotation": 3
    },
    {
      "x": -4,
      "y": 2,
      "z": -2,
      "name": "Rock_Ice_Permafrost",
      "rotation": 3
    },
    {
      "x": -4,
      "y": 3,
      "z": -2,
      "name": "Rock_Ice_Stalactite_Large",
      "rotation": 3
    },
    {
      "x": -4,
      "y": 4,
      "z": -2,
      "name": "Rock_Ice_Stalactite_Large",
      "filler": 1024,
      "rotation": 3
    },
    {
      "x": -4,
      "y": 0,
      "z": -1,
      "name": "Rock_Ice_Permafrost"
    },
    {
      "x": -4,
      "y": 1,
      "z": -1,
      "name": "Rock_Ice_Permafrost",
      "rotation": 3
    },
    {
      "x": -4,
      "y": 2,
      "z": -1,
      "name": "Rock_Ice_Permafrost",
      "rotation": 3
    },
    {
      "x": -4,
      "y": 3,
      "z": -1,
      "name": "Rock_Ice_Permafrost",
      "rotation": 3
    },
    {
      "x": -4,
      "y": 4,
      "z": -1,
      "name": "Rock_Ice_Permafrost",
      "rotation": 3
    },
    {
      "x": -4,
      "y": 0,
      "z": 0,
      "name": "Rock_Ice_Permafrost",
      "rotation": 3
    },
    {
      "x": -4,
      "y": 1,
      "z": 0,
      "name": "Rock_Ice_Permafrost",
      "rotation": 3
    },
    {
      "x": -4,
      "y": 2,
      "z": 0,
      "name": "Rock_Ice_Permafrost",
      "rotation": 3
    },
    {
      "x": -4,
      "y": 3,
      "z": 0,
      "name": "Rock_Ice_Permafrost",
      "rotation": 3
    },
    {
      "x": -4,
      "y": 4,
      "z": 0,
      "name": "Rock_Ice_Permafrost",
      "rotation": 3
    },
    {
      "x": -4,
      "y": 0,
      "z": 1,
      "name": "Rock_Ice_Permafrost",
      "rotation": 3
    },
    {
      "x": -4,
      "y": 1,
      "z": 1,
      "name": "Rock_Ice_Permafrost",
      "rotation": 3
    },
    {
      "x": -4,
      "y": 2,
      "z": 1,
      "name": "Rock_Ice_Permafrost",
      "rotation": 3
    },
    {
      "x": -4,
      "y": 3,
      "z": 1,
      "name": "Rock_Ice_Permafrost",
      "rotation": 3
    },
    {
      "x": -4,
      "y": 4,
      "z": 1,
      "name": "Rock_Ice_Permafrost",
      "rotation": 3
    },
    {
      "x": -4,
      "y": 5,
      "z": 1,
      "name": "Rock_Ice_Icicles",
      "rotation": 3
    },
    {
      "x": -4,
      "y": 0,
      "z": 2,
      "name": "Rock_Ice_Permafrost",
      "rotation": 3
    },
    {
      "x": -4,
      "y": 1,
      "z": 2,
      "name": "Rock_Ice_Permafrost",
      "rotation": 3
    },
    {
      "x": -4,
      "y": 2,
      "z": 2,
      "name": "Rock_Ice_Permafrost",
      "rotation": 3
    },
    {
      "x": -4,
      "y": 3,
      "z": 2,
      "name": "Rock_Ice_Permafrost",
      "rotation": 3
    },
    {
      "x": -4,
      "y": 4,
      "z": 2,
      "name": "Rock_Ice_Permafrost",
      "rotation": 3
    },
    {
      "x": -4,
      "y": 0,
      "z": 3,
      "name": "Rock_Ice_Permafrost",
      "rotation": 3
    },
    {
      "x": -4,
      "y": 1,
      "z": 3,
      "name": "Rock_Ice_Permafrost",
      "rotation": 3
    },
    {
      "x": -4,
      "y": 2,
      "z": 3,
      "name": "Rock_Ice_Permafrost",
      "rotation": 3
    },
    {
      "x": -4,
      "y": 3,
      "z": 3,
      "name": "Rock_Ice_Permafrost",
      "rotation": 3
    },
    {
      "x": -4,
      "y": 0,
      "z": 4,
      "name": "Rock_Ice_Permafrost",
      "rotation": 3
    },
    {
      "x": -4,
      "y": 1,
      "z": 4,
      "name": "Rock_Ice_Permafrost",
      "rotation": 3
    },
    {
      "x": -4,
      "y": 2,
      "z": 4,
      "name": "Rock_Ice_Permafrost",
      "rotation": 3
    },
    {
      "x": -4,
      "y": 0,
      "z": 5,
      "name": "Rock_Ice_Permafrost",
      "rotation": 3
    },
    {
      "x": -4,
      "y": 1,
      "z": 5,
      "name": "Rock_Crystal_Cyan_Medium",
      "rotation": 3
    },
    {
      "x": -4,
      "y": 0,
      "z": 6,
      "name": "Rock_Ice_Permafrost",
      "rotation": 3
    },
    {
      "x": -3,
      "y": 0,
      "z": -5,
      "name": "Rock_Ice_Permafrost",
      "rotation": 3
    },
    {
      "x": -3,
      "y": 0,
      "z": -4,
      "name": "Rock_Ice_Permafrost"
    },
    {
      "x": -3,
      "y": 1,
      "z": -4,
      "name": "Rock_Ice_Permafrost",
      "rotation": 3
    },
    {
      "x": -3,
      "y": 0,
      "z": -3,
      "name": "Rock_Ice_Permafrost"
    },
    {
      "x": -3,
      "y": 1,
      "z": -3,
      "name": "Rock_Ice_Permafrost",
      "rotation": 3
    },
    {
      "x": -3,
      "y": 2,
      "z": -3,
      "name": "Rubble_Ice_Medium",
      "support": 15,
      "rotation": 3
    },
    {
      "x": -3,
      "y": 0,
      "z": -2,
      "name": "Rock_Ice_Permafrost"
    },
    {
      "x": -3,
      "y": 1,
      "z": -2,
      "name": "Rock_Ice_Permafrost",
      "rotation": 3
    },
    {
      "x": -3,
      "y": 2,
      "z": -2,
      "name": "Rock_Ice_Permafrost",
      "rotation": 3
    },
    {
      "x": -3,
      "y": 3,
      "z": -2,
      "name": "Rock_Ice_Permafrost",
      "rotation": 3
    },
    {
      "x": -3,
      "y": 0,
      "z": -1,
      "name": "Rock_Ice_Permafrost",
      "rotation": 3
    },
    {
      "x": -3,
      "y": 1,
      "z": -1,
      "name": "Rock_Ice_Permafrost",
      "rotation": 3
    },
    {
      "x": -3,
      "y": 2,
      "z": -1,
      "name": "Rock_Ice_Permafrost",
      "rotation": 3
    },
    {
      "x": -3,
      "y": 3,
      "z": -1,
      "name": "Rock_Ice_Permafrost",
      "rotation": 3
    },
    {
      "x": -3,
      "y": 4,
      "z": -1,
      "name": "Rock_Ice_Permafrost",
      "rotation": 3
    },
    {
      "x": -3,
      "y": 5,
      "z": -1,
      "name": "Rock_Ice_Stalactite_Large",
      "rotation": 3
    },
    {
      "x": -3,
      "y": 6,
      "z": -1,
      "name": "Rock_Ice_Stalactite_Large",
      "filler": 1024,
      "rotation": 3
    },
    {
      "x": -3,
      "y": 0,
      "z": 0,
      "name": "Rock_Ice_Permafrost",
      "rotation": 3
    },
    {
      "x": -3,
      "y": 1,
      "z": 0,
      "name": "Rock_Ice_Permafrost",
      "rotation": 3
    },
    {
      "x": -3,
      "y": 2,
      "z": 0,
      "name": "Rock_Ice_Permafrost",
      "rotation": 3
    },
    {
      "x": -3,
      "y": 3,
      "z": 0,
      "name": "Rock_Ice_Permafrost",
      "rotation": 3
    },
    {
      "x": -3,
      "y": 4,
      "z": 0,
      "name": "Rock_Ice_Permafrost",
      "rotation": 3
    },
    {
      "x": -3,
      "y": 5,
      "z": 0,
      "name": "Rubble_Ice_Medium",
      "support": 15,
      "rotation": 3
    },
    {
      "x": -3,
      "y": 0,
      "z": 1,
      "name": "Rock_Ice_Permafrost",
      "rotation": 3
    },
    {
      "x": -3,
      "y": 1,
      "z": 1,
      "name": "Rock_Ice_Permafrost",
      "rotation": 3
    },
    {
      "x": -3,
      "y": 2,
      "z": 1,
      "name": "Rock_Ice_Permafrost",
      "rotation": 3
    },
    {
      "x": -3,
      "y": 3,
      "z": 1,
      "name": "Rock_Ice_Permafrost",
      "rotation": 3
    },
    {
      "x": -3,
      "y": 4,
      "z": 1,
      "name": "Rock_Ice_Permafrost",
      "rotation": 3
    },
    {
      "x": -3,
      "y": 5,
      "z": 1,
      "name": "Rock_Ice_Permafrost",
      "rotation": 3
    },
    {
      "x": -3,
      "y": 0,
      "z": 2,
      "name": "Rock_Ice_Permafrost",
      "rotation": 3
    },
    {
      "x": -3,
      "y": 1,
      "z": 2,
      "name": "Rock_Ice_Permafrost",
      "rotation": 3
    },
    {
      "x": -3,
      "y": 2,
      "z": 2,
      "name": "Rock_Ice_Permafrost",
      "rotation": 3
    },
    {
      "x": -3,
      "y": 3,
      "z": 2,
      "name": "Rock_Ice_Permafrost",
      "rotation": 3
    },
    {
      "x": -3,
      "y": 4,
      "z": 2,
      "name": "Rock_Ice_Permafrost",
      "rotation": 3
    },
    {
      "x": -3,
      "y": 5,
      "z": 2,
      "name": "Rock_Ice_Permafrost",
      "rotation": 3
    },
    {
      "x": -3,
      "y": 0,
      "z": 3,
      "name": "Rock_Ice_Permafrost",
      "rotation": 3
    },
    {
      "x": -3,
      "y": 1,
      "z": 3,
      "name": "Rock_Ice_Permafrost",
      "rotation": 3
    },
    {
      "x": -3,
      "y": 2,
      "z": 3,
      "name": "Rock_Ice_Permafrost",
      "rotation": 3
    },
    {
      "x": -3,
      "y": 3,
      "z": 3,
      "name": "Rock_Ice_Permafrost",
      "rotation": 3
    },
    {
      "x": -3,
      "y": 4,
      "z": 3,
      "name": "Rock_Ice_Permafrost",
      "rotation": 3
    },
    {
      "x": -3,
      "y": 5,
      "z": 3,
      "name": "Rubble_Ice",
      "support": 15,
      "rotation": 3
    },
    {
      "x": -3,
      "y": 0,
      "z": 4,
      "name": "Rock_Ice_Permafrost",
      "rotation": 3
    },
    {
      "x": -3,
      "y": 1,
      "z": 4,
      "name": "Rock_Ice_Permafrost",
      "rotation": 3
    },
    {
      "x": -3,
      "y": 2,
      "z": 4,
      "name": "Rock_Ice_Permafrost",
      "rotation": 3
    },
    {
      "x": -3,
      "y": 3,
      "z": 4,
      "name": "Rock_Ice_Permafrost",
      "rotation": 3
    },
    {
      "x": -3,
      "y": 0,
      "z": 5,
      "name": "Rock_Ice_Permafrost",
      "rotation": 3
    },
    {
      "x": -3,
      "y": 1,
      "z": 5,
      "name": "Rock_Ice_Permafrost",
      "rotation": 3
    },
    {
      "x": -3,
      "y": 2,
      "z": 5,
      "name": "Rubble_Ice_Medium",
      "support": 15,
      "rotation": 3
    },
    {
      "x": -3,
      "y": 0,
      "z": 6,
      "name": "Rock_Ice_Permafrost",
      "rotation": 3
    },
    {
      "x": -2,
      "y": 0,
      "z": -6,
      "name": "Rock_Ice_Permafrost",
      "rotation": 3
    },
    {
      "x": -2,
      "y": 0,
      "z": -5,
      "name": "Rock_Ice_Permafrost",
      "rotation": 3
    },
    {
      "x": -2,
      "y": 1,
      "z": -5,
      "name": "Rock_Ice_Icicles",
      "rotation": 3
    },
    {
      "x": -2,
      "y": 0,
      "z": -4,
      "name": "Rock_Ice_Permafrost",
      "rotation": 3
    },
    {
      "x": -2,
      "y": 1,
      "z": -4,
      "name": "Rock_Ice_Permafrost",
      "rotation": 3
    },
    {
      "x": -2,
      "y": 2,
      "z": -4,
      "name": "Rock_Ice_Stalactite_Large",
      "rotation": 3
    },
    {
      "x": -2,
      "y": 3,
      "z": -4,
      "name": "Rock_Ice_Stalactite_Large",
      "filler": 1024,
      "rotation": 3
    },
    {
      "x": -2,
      "y": 0,
      "z": -3,
      "name": "Rock_Ice_Permafrost",
      "rotation": 3
    },
    {
      "x": -2,
      "y": 1,
      "z": -3,
      "name": "Rock_Ice_Permafrost",
      "rotation": 3
    },
    {
      "x": -2,
      "y": 2,
      "z": -3,
      "name": "Rock_Ice_Permafrost",
      "rotation": 3
    },
    {
      "x": -2,
      "y": 0,
      "z": -2,
      "name": "Rock_Ice_Permafrost",
      "rotation": 3
    },
    {
      "x": -2,
      "y": 1,
      "z": -2,
      "name": "Rock_Ice_Permafrost",
      "rotation": 3
    },
    {
      "x": -2,
      "y": 2,
      "z": -2,
      "name": "Rock_Ice_Permafrost",
      "rotation": 3
    },
    {
      "x": -2,
      "y": 3,
      "z": -2,
      "name": "Rock_Ice_Permafrost",
      "rotation": 3
    },
    {
      "x": -2,
      "y": 4,
      "z": -2,
      "name": "Rock_Ice_Permafrost",
      "rotation": 3
    },
    {
      "x": -2,
      "y": 0,
      "z": -1,
      "name": "Rock_Ice_Permafrost",
      "rotation": 3
    },
    {
      "x": -2,
      "y": 1,
      "z": -1,
      "name": "Rock_Ice_Permafrost",
      "rotation": 3
    },
    {
      "x": -2,
      "y": 2,
      "z": -1,
      "name": "Rock_Ice_Permafrost",
      "rotation": 3
    },
    {
      "x": -2,
      "y": 3,
      "z": -1,
      "name": "Rock_Ice_Permafrost",
      "rotation": 3
    },
    {
      "x": -2,
      "y": 4,
      "z": -1,
      "name": "Rock_Ice_Permafrost",
      "rotation": 3
    },
    {
      "x": -2,
      "y": 5,
      "z": -1,
      "name": "Rock_Ice_Permafrost",
      "rotation": 3
    },
    {
      "x": -2,
      "y": 6,
      "z": -1,
      "name": "Rock_Ice_Permafrost",
      "rotation": 3
    },
    {
      "x": -2,
      "y": 7,
      "z": -1,
      "name": "Rock_Ice_Icicles",
      "rotation": 3
    },
    {
      "x": -2,
      "y": 0,
      "z": 0,
      "name": "Rock_Ice_Permafrost",
      "rotation": 3
    },
    {
      "x": -2,
      "y": 1,
      "z": 0,
      "name": "Rock_Ice_Permafrost",
      "rotation": 3
    },
    {
      "x": -2,
      "y": 2,
      "z": 0,
      "name": "Rock_Ice_Permafrost",
      "rotation": 3
    },
    {
      "x": -2,
      "y": 3,
      "z": 0,
      "name": "Rock_Ice_Permafrost",
      "rotation": 3
    },
    {
      "x": -2,
      "y": 4,
      "z": 0,
      "name": "Rock_Ice_Permafrost",
      "rotation": 3
    },
    {
      "x": -2,
      "y": 5,
      "z": 0,
      "name": "Rock_Ice_Permafrost",
      "rotation": 3
    },
    {
      "x": -2,
      "y": 6,
      "z": 0,
      "name": "Rock_Ice_Permafrost",
      "rotation": 3
    },
    {
      "x": -2,
      "y": 0,
      "z": 1,
      "name": "Rock_Ice_Permafrost",
      "rotation": 3
    },
    {
      "x": -2,
      "y": 1,
      "z": 1,
      "name": "Rock_Ice_Permafrost",
      "rotation": 3
    },
    {
      "x": -2,
      "y": 2,
      "z": 1,
      "name": "Rock_Ice_Permafrost",
      "rotation": 3
    },
    {
      "x": -2,
      "y": 3,
      "z": 1,
      "name": "Rock_Ice_Permafrost",
      "rotation": 3
    },
    {
      "x": -2,
      "y": 4,
      "z": 1,
      "name": "Rock_Ice_Permafrost",
      "rotation": 3
    },
    {
      "x": -2,
      "y": 5,
      "z": 1,
      "name": "Rock_Ice_Permafrost",
      "rotation": 3
    },
    {
      "x": -2,
      "y": 6,
      "z": 1,
      "name": "Rock_Ice_Permafrost",
      "rotation": 3
    },
    {
      "x": -2,
      "y": 7,
      "z": 1,
      "name": "Rock_Ice_Stalactite_Large",
      "rotation": 3
    },
    {
      "x": -2,
      "y": 8,
      "z": 1,
      "name": "Rock_Ice_Stalactite_Large",
      "filler": 1024,
      "rotation": 3
    },
    {
      "x": -2,
      "y": 0,
      "z": 2,
      "name": "Rock_Ice_Permafrost",
      "rotation": 3
    },
    {
      "x": -2,
      "y": 1,
      "z": 2,
      "name": "Rock_Ice_Permafrost",
      "rotation": 3
    },
    {
      "x": -2,
      "y": 2,
      "z": 2,
      "name": "Rock_Ice_Permafrost",
      "rotation": 3
    },
    {
      "x": -2,
      "y": 3,
      "z": 2,
      "name": "Rock_Ice_Permafrost",
      "rotation": 3
    },
    {
      "x": -2,
      "y": 4,
      "z": 2,
      "name": "Rock_Ice_Permafrost",
      "rotation": 3
    },
    {
      "x": -2,
      "y": 5,
      "z": 2,
      "name": "Rock_Ice_Permafrost",
      "rotation": 3
    },
    {
      "x": -2,
      "y": 6,
      "z": 2,
      "name": "Rock_Ice_Icicles",
      "rotation": 3
    },
    {
      "x": -2,
      "y": 0,
      "z": 3,
      "name": "Rock_Ice_Permafrost",
      "rotation": 3
    },
    {
      "x": -2,
      "y": 1,
      "z": 3,
      "name": "Rock_Ice_Permafrost",
      "rotation": 3
    },
    {
      "x": -2,
      "y": 2,
      "z": 3,
      "name": "Rock_Ice_Permafrost",
      "rotation": 3
    },
    {
      "x": -2,
      "y": 3,
      "z": 3,
      "name": "Rock_Ice_Permafrost",
      "rotation": 3
    },
    {
      "x": -2,
      "y": 4,
      "z": 3,
      "name": "Rock_Ice_Permafrost",
      "rotation": 3
    },
    {
      "x": -2,
      "y": 0,
      "z": 4,
      "name": "Rock_Ice_Permafrost",
      "rotation": 3
    },
    {
      "x": -2,
      "y": 1,
      "z": 4,
      "name": "Rock_Ice_Permafrost",
      "rotation": 3
    },
    {
      "x": -2,
      "y": 2,
      "z": 4,
      "name": "Rock_Ice_Permafrost",
      "rotation": 3
    },
    {
      "x": -2,
      "y": 3,
      "z": 4,
      "name": "Rock_Ice_Permafrost",
      "rotation": 3
    },
    {
      "x": -2,
      "y": 4,
      "z": 4,
      "name": "Rock_Ice_Stalactite_Large",
      "rotation": 3
    },
    {
      "x": -2,
      "y": 5,
      "z": 4,
      "name": "Rock_Ice_Stalactite_Large",
      "filler": 1024,
      "rotation": 3
    },
    {
      "x": -2,
      "y": 0,
      "z": 5,
      "name": "Rock_Ice_Permafrost",
      "rotation": 3
    },
    {
      "x": -2,
      "y": 1,
      "z": 5,
      "name": "Rock_Ice_Permafrost",
      "rotation": 3
    },
    {
      "x": -2,
      "y": 2,
      "z": 5,
      "name": "Rock_Ice_Icicles",
      "rotation": 3
    },
    {
      "x": -2,
      "y": 0,
      "z": 6,
      "name": "Rock_Ice_Permafrost",
      "rotation": 3
    },
    {
      "x": -1,
      "y": 0,
      "z": -6,
      "name": "Rock_Ice_Permafrost",
      "rotation": 3
    },
    {
      "x": -1,
      "y": 1,
      "z": -6,
      "name": "Rock_Ice_Icicles",
      "rotation": 3
    },
    {
      "x": -1,
      "y": 0,
      "z": -5,
      "name": "Rock_Ice_Permafrost",
      "rotation": 3
    },
    {
      "x": -1,
      "y": 1,
      "z": -5,
      "name": "Rock_Crystal_Cyan_Large",
      "rotation": 3
    },
    {
      "x": -1,
      "y": 0,
      "z": -4,
      "name": "Rock_Ice_Permafrost",
      "rotation": 3
    },
    {
      "x": -1,
      "y": 1,
      "z": -4,
      "name": "Rock_Ice_Permafrost",
      "rotation": 3
    },
    {
      "x": -1,
      "y": 2,
      "z": -4,
      "name": "Rock_Ice_Permafrost",
      "rotation": 3
    },
    {
      "x": -1,
      "y": 3,
      "z": -4,
      "name": "Rock_Ice_Icicles",
      "rotation": 3
    },
    {
      "x": -1,
      "y": 0,
      "z": -3,
      "name": "Rock_Ice_Permafrost",
      "rotation": 3
    },
    {
      "x": -1,
      "y": 1,
      "z": -3,
      "name": "Rock_Ice_Permafrost",
      "rotation": 3
    },
    {
      "x": -1,
      "y": 2,
      "z": -3,
      "name": "Rock_Ice_Permafrost",
      "rotation": 3
    },
    {
      "x": -1,
      "y": 3,
      "z": -3,
      "name": "Rock_Ice_Permafrost",
      "rotation": 3
    },
    {
      "x": -1,
      "y": 4,
      "z": -3,
      "name": "Rock_Ice_Stalactite_Large",
      "rotation": 3
    },
    {
      "x": -1,
      "y": 5,
      "z": -3,
      "name": "Rock_Ice_Stalactite_Large",
      "filler": 1024,
      "rotation": 3
    },
    {
      "x": -1,
      "y": 0,
      "z": -2,
      "name": "Rock_Ice_Permafrost",
      "rotation": 3
    },
    {
      "x": -1,
      "y": 1,
      "z": -2,
      "name": "Rock_Ice_Permafrost",
      "rotation": 3
    },
    {
      "x": -1,
      "y": 2,
      "z": -2,
      "name": "Rock_Ice_Permafrost",
      "rotation": 3
    },
    {
      "x": -1,
      "y": 3,
      "z": -2,
      "name": "Rock_Ice_Permafrost",
      "rotation": 3
    },
    {
      "x": -1,
      "y": 4,
      "z": -2,
      "name": "Rock_Ice_Permafrost",
      "rotation": 3
    },
    {
      "x": -1,
      "y": 5,
      "z": -2,
      "name": "Rock_Ice_Permafrost",
      "rotation": 3
    },
    {
      "x": -1,
      "y": 0,
      "z": -1,
      "name": "Rock_Ice_Permafrost",
      "rotation": 3
    },
    {
      "x": -1,
      "y": 1,
      "z": -1,
      "name": "Rock_Ice_Permafrost",
      "rotation": 3
    },
    {
      "x": -1,
      "y": 2,
      "z": -1,
      "name": "Rock_Ice_Permafrost",
      "rotation": 3
    },
    {
      "x": -1,
      "y": 3,
      "z": -1,
      "name": "Rock_Ice_Permafrost",
      "rotation": 3
    },
    {
      "x": -1,
      "y": 4,
      "z": -1,
      "name": "Rock_Ice_Permafrost",
      "rotation": 3
    },
    {
      "x": -1,
      "y": 5,
      "z": -1,
      "name": "Rock_Ice_Permafrost",
      "rotation": 3
    },
    {
      "x": -1,
      "y": 6,
      "z": -1,
      "name": "Rock_Ice_Permafrost",
      "rotation": 3
    },
    {
      "x": -1,
      "y": 7,
      "z": -1,
      "name": "Rock_Ice_Permafrost",
      "rotation": 3
    },
    {
      "x": -1,
      "y": 0,
      "z": 0,
      "name": "Rock_Ice_Permafrost",
      "rotation": 3
    },
    {
      "x": -1,
      "y": 1,
      "z": 0,
      "name": "Rock_Ice_Permafrost",
      "rotation": 3
    },
    {
      "x": -1,
      "y": 2,
      "z": 0,
      "name": "Rock_Ice_Permafrost",
      "rotation": 3
    },
    {
      "x": -1,
      "y": 3,
      "z": 0,
      "name": "Rock_Ice_Permafrost",
      "rotation": 3
    },
    {
      "x": -1,
      "y": 4,
      "z": 0,
      "name": "Rock_Ice_Permafrost",
      "rotation": 3
    },
    {
      "x": -1,
      "y": 5,
      "z": 0,
      "name": "Rock_Ice_Permafrost",
      "rotation": 3
    },
    {
      "x": -1,
      "y": 6,
      "z": 0,
      "name": "Rock_Ice_Permafrost",
      "rotation": 3
    },
    {
      "x": -1,
      "y": 7,
      "z": 0,
      "name": "Rock_Ice_Permafrost",
      "rotation": 3
    },
    {
      "x": -1,
      "y": 8,
      "z": 0,
      "name": "Rock_Ice_Icicles",
      "rotation": 3
    },
    {
      "x": -1,
      "y": 0,
      "z": 1,
      "name": "Rock_Ice_Permafrost",
      "rotation": 3
    },
    {
      "x": -1,
      "y": 1,
      "z": 1,
      "name": "Rock_Ice_Permafrost",
      "rotation": 3
    },
    {
      "x": -1,
      "y": 2,
      "z": 1,
      "name": "Rock_Ice_Permafrost",
      "rotation": 3
    },
    {
      "x": -1,
      "y": 3,
      "z": 1,
      "name": "Rock_Ice_Permafrost",
      "rotation": 3
    },
    {
      "x": -1,
      "y": 4,
      "z": 1,
      "name": "Rock_Ice_Permafrost",
      "rotation": 3
    },
    {
      "x": -1,
      "y": 5,
      "z": 1,
      "name": "Rock_Ice_Permafrost",
      "rotation": 3
    },
    {
      "x": -1,
      "y": 6,
      "z": 1,
      "name": "Rock_Ice_Permafrost",
      "rotation": 3
    },
    {
      "x": -1,
      "y": 7,
      "z": 1,
      "name": "Rock_Ice_Permafrost",
      "rotation": 3
    },
    {
      "x": -1,
      "y": 0,
      "z": 2,
      "name": "Rock_Ice_Permafrost",
      "rotation": 3
    },
    {
      "x": -1,
      "y": 1,
      "z": 2,
      "name": "Rock_Ice_Permafrost",
      "rotation": 3
    },
    {
      "x": -1,
      "y": 2,
      "z": 2,
      "name": "Rock_Ice_Permafrost",
      "rotation": 3
    },
    {
      "x": -1,
      "y": 3,
      "z": 2,
      "name": "Rock_Ice_Permafrost",
      "rotation": 3
    },
    {
      "x": -1,
      "y": 4,
      "z": 2,
      "name": "Rock_Ice_Permafrost",
      "rotation": 3
    },
    {
      "x": -1,
      "y": 5,
      "z": 2,
      "name": "Rock_Ice_Permafrost",
      "rotation": 3
    },
    {
      "x": -1,
      "y": 6,
      "z": 2,
      "name": "Rock_Ice_Permafrost",
      "rotation": 3
    },
    {
      "x": -1,
      "y": 7,
      "z": 2,
      "name": "Rock_Crystal_Cyan_Medium",
      "rotation": 4
    },
    {
      "x": -1,
      "y": 0,
      "z": 3,
      "name": "Rock_Ice_Permafrost",
      "rotation": 3
    },
    {
      "x": -1,
      "y": 1,
      "z": 3,
      "name": "Rock_Ice_Permafrost",
      "rotation": 3
    },
    {
      "x": -1,
      "y": 2,
      "z": 3,
      "name": "Rock_Ice_Permafrost",
      "rotation": 3
    },
    {
      "x": -1,
      "y": 3,
      "z": 3,
      "name": "Rock_Ice_Permafrost",
      "rotation": 3
    },
    {
      "x": -1,
      "y": 4,
      "z": 3,
      "name": "Rock_Ice_Permafrost",
      "rotation": 3
    },
    {
      "x": -1,
      "y": 5,
      "z": 3,
      "name": "Rubble_Ice_Medium",
      "support": 15,
      "rotation": 3
    },
    {
      "x": -1,
      "y": 0,
      "z": 4,
      "name": "Rock_Ice_Permafrost",
      "rotation": 3
    },
    {
      "x": -1,
      "y": 1,
      "z": 4,
      "name": "Rock_Ice_Permafrost",
      "rotation": 3
    },
    {
      "x": -1,
      "y": 2,
      "z": 4,
      "name": "Rock_Ice_Permafrost",
      "rotation": 3
    },
    {
      "x": -1,
      "y": 0,
      "z": 5,
      "name": "Rock_Ice_Permafrost",
      "rotation": 3
    },
    {
      "x": -1,
      "y": 1,
      "z": 5,
      "name": "Rock_Ice_Permafrost",
      "rotation": 3
    },
    {
      "x": -1,
      "y": 0,
      "z": 6,
      "name": "Rock_Ice_Permafrost",
      "rotation": 3
    },
    {
      "x": 0,
      "y": 0,
      "z": -6,
      "name": "Rock_Ice_Permafrost",
      "rotation": 3
    },
    {
      "x": 0,
      "y": 1,
      "z": -6,
      "name": "Rubble_Ice_Medium",
      "support": 15,
      "rotation": 3
    },
    {
      "x": 0,
      "y": 0,
      "z": -5,
      "name": "Rock_Ice_Permafrost",
      "rotation": 3
    },
    {
      "x": 0,
      "y": 1,
      "z": -5,
      "name": "Rock_Ice_Permafrost",
      "rotation": 3
    },
    {
      "x": 0,
      "y": 0,
      "z": -4,
      "name": "Rock_Ice_Permafrost",
      "rotation": 3
    },
    {
      "x": 0,
      "y": 1,
      "z": -4,
      "name": "Rock_Ice_Permafrost",
      "rotation": 3
    },
    {
      "x": 0,
      "y": 2,
      "z": -4,
      "name": "Rock_Ice_Permafrost",
      "rotation": 3
    },
    {
      "x": 0,
      "y": 0,
      "z": -3,
      "name": "Rock_Ice_Permafrost",
      "rotation": 3
    },
    {
      "x": 0,
      "y": 1,
      "z": -3,
      "name": "Rock_Ice_Permafrost",
      "rotation": 3
    },
    {
      "x": 0,
      "y": 2,
      "z": -3,
      "name": "Rock_Ice_Permafrost",
      "rotation": 3
    },
    {
      "x": 0,
      "y": 3,
      "z": -3,
      "name": "Rock_Ice_Permafrost",
      "rotation": 3
    },
    {
      "x": 0,
      "y": 0,
      "z": -2,
      "name": "Rock_Ice_Permafrost",
      "rotation": 3
    },
    {
      "x": 0,
      "y": 1,
      "z": -2,
      "name": "Rock_Ice_Permafrost",
      "rotation": 3
    },
    {
      "x": 0,
      "y": 2,
      "z": -2,
      "name": "Rock_Ice_Permafrost",
      "rotation": 3
    },
    {
      "x": 0,
      "y": 3,
      "z": -2,
      "name": "Rock_Ice_Permafrost",
      "rotation": 3
    },
    {
      "x": 0,
      "y": 4,
      "z": -2,
      "name": "Rock_Ice_Permafrost",
      "rotation": 3
    },
    {
      "x": 0,
      "y": 5,
      "z": -2,
      "name": "Rock_Ice_Permafrost",
      "rotation": 3
    },
    {
      "x": 0,
      "y": 0,
      "z": -1,
      "name": "Rock_Ice_Permafrost",
      "rotation": 3
    },
    {
      "x": 0,
      "y": 1,
      "z": -1,
      "name": "Rock_Ice_Permafrost",
      "rotation": 3
    },
    {
      "x": 0,
      "y": 2,
      "z": -1,
      "name": "Rock_Ice_Permafrost",
      "rotation": 3
    },
    {
      "x": 0,
      "y": 3,
      "z": -1,
      "name": "Rock_Ice_Permafrost",
      "rotation": 3
    },
    {
      "x": 0,
      "y": 4,
      "z": -1,
      "name": "Rock_Ice_Permafrost",
      "rotation": 3
    },
    {
      "x": 0,
      "y": 5,
      "z": -1,
      "name": "Rock_Ice_Permafrost",
      "rotation": 3
    },
    {
      "x": 0,
      "y": 6,
      "z": -1,
      "name": "Rock_Ice_Permafrost",
      "rotation": 3
    },
    {
      "x": 0,
      "y": 7,
      "z": -1,
      "name": "Rock_Ice_Permafrost",
      "rotation": 3
    },
    {
      "x": 0,
      "y": 8,
      "z": -1,
      "name": "Rock_Ice_Permafrost",
      "rotation": 3
    },
    {
      "x": 0,
      "y": 0,
      "z": 0,
      "name": "Rock_Ice_Permafrost",
      "rotation": 3
    },
    {
      "x": 0,
      "y": 1,
      "z": 0,
      "name": "Rock_Ice_Permafrost",
      "rotation": 3
    },
    {
      "x": 0,
      "y": 2,
      "z": 0,
      "name": "Rock_Ice_Permafrost",
      "rotation": 3
    },
    {
      "x": 0,
      "y": 3,
      "z": 0,
      "name": "Rock_Ice_Permafrost",
      "rotation": 3
    },
    {
      "x": 0,
      "y": 4,
      "z": 0,
      "name": "Rock_Ice_Permafrost",
      "rotation": 3
    },
    {
      "x": 0,
      "y": 5,
      "z": 0,
      "name": "Rock_Ice_Permafrost",
      "rotation": 3
    },
    {
      "x": 0,
      "y": 6,
      "z": 0,
      "name": "Rock_Ice_Permafrost",
      "rotation": 3
    },
    {
      "x": 0,
      "y": 7,
      "z": 0,
      "name": "Rock_Ice_Permafrost",
      "rotation": 3
    },
    {
      "x": 0,
      "y": 8,
      "z": 0,
      "name": "Rock_Ice_Permafrost",
      "rotation": 3
    },
    {
      "x": 0,
      "y": 9,
      "z": 0,
      "name": "Rock_Ice_Permafrost",
      "rotation": 3
    },
    {
      "x": 0,
      "y": 10,
      "z": 0,
      "name": "Rubble_Ice_Medium",
      "support": 15,
      "rotation": 3
    },
    {
      "x": 0,
      "y": 0,
      "z": 1,
      "name": "Rock_Ice_Permafrost",
      "rotation": 3
    },
    {
      "x": 0,
      "y": 1,
      "z": 1,
      "name": "Rock_Ice_Permafrost",
      "rotation": 3
    },
    {
      "x": 0,
      "y": 2,
      "z": 1,
      "name": "Rock_Ice_Permafrost",
      "rotation": 3
    },
    {
      "x": 0,
      "y": 3,
      "z": 1,
      "name": "Rock_Ice_Permafrost",
      "rotation": 3
    },
    {
      "x": 0,
      "y": 4,
      "z": 1,
      "name": "Rock_Ice_Permafrost",
      "rotation": 3
    },
    {
      "x": 0,
      "y": 5,
      "z": 1,
      "name": "Rock_Ice_Permafrost",
      "rotation": 3
    },
    {
      "x": 0,
      "y": 6,
      "z": 1,
      "name": "Rock_Ice_Permafrost",
      "rotation": 3
    },
    {
      "x": 0,
      "y": 7,
      "z": 1,
      "name": "Rock_Ice_Permafrost",
      "rotation": 3
    },
    {
      "x": 0,
      "y": 8,
      "z": 1,
      "name": "Rock_Ice_Permafrost",
      "rotation": 3
    },
    {
      "x": 0,
      "y": 0,
      "z": 2,
      "name": "Rock_Ice_Permafrost",
      "rotation": 3
    },
    {
      "x": 0,
      "y": 1,
      "z": 2,
      "name": "Rock_Ice_Permafrost",
      "rotation": 3
    },
    {
      "x": 0,
      "y": 2,
      "z": 2,
      "name": "Rock_Ice_Permafrost",
      "rotation": 3
    },
    {
      "x": 0,
      "y": 3,
      "z": 2,
      "name": "Rock_Ice_Permafrost",
      "rotation": 3
    },
    {
      "x": 0,
      "y": 4,
      "z": 2,
      "name": "Rock_Ice_Permafrost",
      "rotation": 3
    },
    {
      "x": 0,
      "y": 5,
      "z": 2,
      "name": "Rock_Ice_Permafrost",
      "rotation": 3
    },
    {
      "x": 0,
      "y": 6,
      "z": 2,
      "name": "Rock_Ice_Permafrost",
      "rotation": 3
    },
    {
      "x": 0,
      "y": 7,
      "z": 2,
      "name": "Rock_Ice_Permafrost",
      "rotation": 3
    },
    {
      "x": 0,
      "y": 8,
      "z": 2,
      "name": "Rock_Ice_Icicles",
      "rotation": 3
    },
    {
      "x": 0,
      "y": 0,
      "z": 3,
      "name": "Rock_Ice_Permafrost",
      "rotation": 3
    },
    {
      "x": 0,
      "y": 1,
      "z": 3,
      "name": "Rock_Ice_Permafrost",
      "rotation": 3
    },
    {
      "x": 0,
      "y": 2,
      "z": 3,
      "name": "Rock_Ice_Permafrost",
      "rotation": 3
    },
    {
      "x": 0,
      "y": 3,
      "z": 3,
      "name": "Rock_Ice_Permafrost",
      "rotation": 3
    },
    {
      "x": 0,
      "y": 4,
      "z": 3,
      "name": "Rock_Ice_Permafrost",
      "rotation": 3
    },
    {
      "x": 0,
      "y": 5,
      "z": 3,
      "name": "Rock_Ice_Stalactite_Large",
      "rotation": 3
    },
    {
      "x": 0,
      "y": 6,
      "z": 3,
      "name": "Rock_Ice_Stalactite_Large",
      "filler": 1024,
      "rotation": 3
    },
    {
      "x": 0,
      "y": 0,
      "z": 4,
      "name": "Rock_Ice_Permafrost",
      "rotation": 3
    },
    {
      "x": 0,
      "y": 1,
      "z": 4,
      "name": "Rock_Ice_Permafrost",
      "rotation": 3
    },
    {
      "x": 0,
      "y": 2,
      "z": 4,
      "name": "Rock_Ice_Permafrost",
      "rotation": 3
    },
    {
      "x": 0,
      "y": 0,
      "z": 5,
      "name": "Rock_Ice_Permafrost",
      "rotation": 3
    },
    {
      "x": 0,
      "y": 1,
      "z": 5,
      "name": "Rock_Ice_Permafrost",
      "rotation": 3
    },
    {
      "x": 0,
      "y": 2,
      "z": 5,
      "name": "Rock_Ice_Icicles",
      "rotation": 3
    },
    {
      "x": 1,
      "y": 0,
      "z": -6,
      "name": "Rock_Ice_Permafrost",
      "rotation": 3
    },
    {
      "x": 1,
      "y": 0,
      "z": -5,
      "name": "Rock_Ice_Permafrost",
      "rotation": 3
    },
    {
      "x": 1,
      "y": 1,
      "z": -5,
      "name": "Rock_Ice_Icicles",
      "rotation": 3
    },
    {
      "x": 1,
      "y": 0,
      "z": -4,
      "name": "Rock_Ice_Permafrost",
      "rotation": 3
    },
    {
      "x": 1,
      "y": 1,
      "z": -4,
      "name": "Rock_Ice_Permafrost",
      "rotation": 3
    },
    {
      "x": 1,
      "y": 2,
      "z": -4,
      "name": "Rock_Ice_Stalactite_Large",
      "rotation": 3
    },
    {
      "x": 1,
      "y": 3,
      "z": -4,
      "name": "Rock_Ice_Stalactite_Large",
      "filler": 1024,
      "rotation": 3
    },
    {
      "x": 1,
      "y": 0,
      "z": -3,
      "name": "Rock_Ice_Permafrost",
      "rotation": 3
    },
    {
      "x": 1,
      "y": 1,
      "z": -3,
      "name": "Rock_Ice_Permafrost",
      "rotation": 3
    },
    {
      "x": 1,
      "y": 2,
      "z": -3,
      "name": "Rock_Ice_Permafrost",
      "rotation": 3
    },
    {
      "x": 1,
      "y": 3,
      "z": -3,
      "name": "Rock_Ice_Icicles",
      "rotation": 3
    },
    {
      "x": 1,
      "y": 0,
      "z": -2,
      "name": "Rock_Ice_Permafrost",
      "rotation": 3
    },
    {
      "x": 1,
      "y": 1,
      "z": -2,
      "name": "Rock_Ice_Permafrost",
      "rotation": 3
    },
    {
      "x": 1,
      "y": 2,
      "z": -2,
      "name": "Rock_Ice_Permafrost",
      "rotation": 3
    },
    {
      "x": 1,
      "y": 3,
      "z": -2,
      "name": "Rock_Ice_Permafrost",
      "rotation": 3
    },
    {
      "x": 1,
      "y": 4,
      "z": -2,
      "name": "Rock_Ice_Permafrost",
      "rotation": 3
    },
    {
      "x": 1,
      "y": 0,
      "z": -1,
      "name": "Rock_Ice_Permafrost",
      "rotation": 3
    },
    {
      "x": 1,
      "y": 1,
      "z": -1,
      "name": "Rock_Ice_Permafrost",
      "rotation": 3
    },
    {
      "x": 1,
      "y": 2,
      "z": -1,
      "name": "Rock_Ice_Permafrost",
      "rotation": 3
    },
    {
      "x": 1,
      "y": 3,
      "z": -1,
      "name": "Rock_Ice_Permafrost",
      "rotation": 3
    },
    {
      "x": 1,
      "y": 4,
      "z": -1,
      "name": "Rock_Ice_Permafrost",
      "rotation": 3
    },
    {
      "x": 1,
      "y": 5,
      "z": -1,
      "name": "Rock_Ice_Permafrost",
      "rotation": 3
    },
    {
      "x": 1,
      "y": 6,
      "z": -1,
      "name": "Rock_Ice_Permafrost",
      "rotation": 3
    },
    {
      "x": 1,
      "y": 7,
      "z": -1,
      "name": "Rock_Ice_Permafrost",
      "rotation": 3
    },
    {
      "x": 1,
      "y": 8,
      "z": -1,
      "name": "Rock_Ice_Permafrost",
      "rotation": 3
    },
    {
      "x": 1,
      "y": 9,
      "z": -1,
      "name": "Rock_Ice_Permafrost",
      "rotation": 3
    },
    {
      "x": 1,
      "y": 10,
      "z": -1,
      "name": "Rock_Crystal_Cyan_Medium",
      "rotation": 6
    },
    {
      "x": 1,
      "y": 0,
      "z": 0,
      "name": "Rock_Ice_Permafrost",
      "rotation": 3
    },
    {
      "x": 1,
      "y": 1,
      "z": 0,
      "name": "Rock_Ice_Permafrost",
      "rotation": 3
    },
    {
      "x": 1,
      "y": 2,
      "z": 0,
      "name": "Rock_Ice_Permafrost",
      "rotation": 3
    },
    {
      "x": 1,
      "y": 3,
      "z": 0,
      "name": "Rock_Ice_Permafrost",
      "rotation": 3
    },
    {
      "x": 1,
      "y": 4,
      "z": 0,
      "name": "Rock_Ice_Permafrost",
      "rotation": 3
    },
    {
      "x": 1,
      "y": 5,
      "z": 0,
      "name": "Rock_Ice_Permafrost",
      "rotation": 3
    },
    {
      "x": 1,
      "y": 6,
      "z": 0,
      "name": "Rock_Ice_Permafrost",
      "rotation": 3
    },
    {
      "x": 1,
      "y": 7,
      "z": 0,
      "name": "Rock_Ice_Permafrost",
      "rotation": 3
    },
    {
      "x": 1,
      "y": 8,
      "z": 0,
      "name": "Rock_Ice_Permafrost",
      "rotation": 3
    },
    {
      "x": 1,
      "y": 9,
      "z": 0,
      "name": "Rock_Ice_Permafrost",
      "rotation": 3
    },
    {
      "x": 1,
      "y": 10,
      "z": 0,
      "name": "Rock_Ice_Permafrost",
      "rotation": 3
    },
    {
      "x": 1,
      "y": 0,
      "z": 1,
      "name": "Rock_Ice_Permafrost",
      "rotation": 3
    },
    {
      "x": 1,
      "y": 1,
      "z": 1,
      "name": "Rock_Ice_Permafrost",
      "rotation": 3
    },
    {
      "x": 1,
      "y": 2,
      "z": 1,
      "name": "Rock_Ice_Permafrost",
      "rotation": 3
    },
    {
      "x": 1,
      "y": 3,
      "z": 1,
      "name": "Rock_Ice_Permafrost",
      "rotation": 3
    },
    {
      "x": 1,
      "y": 4,
      "z": 1,
      "name": "Rock_Ice_Permafrost",
      "rotation": 3
    },
    {
      "x": 1,
      "y": 5,
      "z": 1,
      "name": "Rock_Ice_Permafrost",
      "rotation": 3
    },
    {
      "x": 1,
      "y": 6,
      "z": 1,
      "name": "Rock_Ice_Permafrost",
      "rotation": 3
    },
    {
      "x": 1,
      "y": 7,
      "z": 1,
      "name": "Rock_Ice_Permafrost",
      "rotation": 3
    },
    {
      "x": 1,
      "y": 8,
      "z": 1,
      "name": "Rock_Ice_Permafrost",
      "rotation": 3
    },
    {
      "x": 1,
      "y": 9,
      "z": 1,
      "name": "Rock_Ice_Permafrost",
      "rotation": 3
    },
    {
      "x": 1,
      "y": 10,
      "z": 1,
      "name": "Rock_Ice_Permafrost",
      "rotation": 3
    },
    {
      "x": 1,
      "y": 0,
      "z": 2,
      "name": "Rock_Ice_Permafrost",
      "rotation": 3
    },
    {
      "x": 1,
      "y": 1,
      "z": 2,
      "name": "Rock_Ice_Permafrost",
      "rotation": 3
    },
    {
      "x": 1,
      "y": 2,
      "z": 2,
      "name": "Rock_Ice_Permafrost",
      "rotation": 3
    },
    {
      "x": 1,
      "y": 3,
      "z": 2,
      "name": "Rock_Ice_Permafrost",
      "rotation": 3
    },
    {
      "x": 1,
      "y": 4,
      "z": 2,
      "name": "Rock_Ice_Permafrost",
      "rotation": 3
    },
    {
      "x": 1,
      "y": 5,
      "z": 2,
      "name": "Rock_Ice_Permafrost",
      "rotation": 3
    },
    {
      "x": 1,
      "y": 6,
      "z": 2,
      "name": "Rock_Ice_Permafrost",
      "rotation": 3
    },
    {
      "x": 1,
      "y": 7,
      "z": 2,
      "name": "Rock_Ice_Permafrost",
      "rotation": 3
    },
    {
      "x": 1,
      "y": 8,
      "z": 2,
      "name": "Rock_Ice_Permafrost",
      "rotation": 3
    },
    {
      "x": 1,
      "y": 9,
      "z": 2,
      "name": "Rock_Ice_Icicles",
      "rotation": 3
    },
    {
      "x": 1,
      "y": 0,
      "z": 3,
      "name": "Rock_Ice_Permafrost",
      "rotation": 3
    },
    {
      "x": 1,
      "y": 1,
      "z": 3,
      "name": "Rock_Ice_Permafrost",
      "rotation": 3
    },
    {
      "x": 1,
      "y": 2,
      "z": 3,
      "name": "Rock_Ice_Permafrost",
      "rotation": 3
    },
    {
      "x": 1,
      "y": 3,
      "z": 3,
      "name": "Rock_Ice_Permafrost",
      "rotation": 3
    },
    {
      "x": 1,
      "y": 4,
      "z": 3,
      "name": "Rubble_Ice",
      "support": 15,
      "rotation": 3
    },
    {
      "x": 1,
      "y": 0,
      "z": 4,
      "name": "Rock_Ice_Permafrost",
      "rotation": 3
    },
    {
      "x": 1,
      "y": 1,
      "z": 4,
      "name": "Rock_Ice_Permafrost",
      "rotation": 3
    },
    {
      "x": 1,
      "y": 2,
      "z": 4,
      "name": "Rock_Ice_Permafrost",
      "rotation": 3
    },
    {
      "x": 1,
      "y": 0,
      "z": 5,
      "name": "Rock_Ice_Permafrost",
      "rotation": 3
    },
    {
      "x": 2,
      "y": 0,
      "z": -5,
      "name": "Rock_Ice_Permafrost",
      "rotation": 3
    },
    {
      "x": 2,
      "y": 0,
      "z": -4,
      "name": "Rock_Ice_Permafrost",
      "rotation": 3
    },
    {
      "x": 2,
      "y": 1,
      "z": -4,
      "name": "Rock_Ice_Permafrost",
      "rotation": 3
    },
    {
      "x": 2,
      "y": 0,
      "z": -3,
      "name": "Rock_Ice_Permafrost",
      "rotation": 3
    },
    {
      "x": 2,
      "y": 1,
      "z": -3,
      "name": "Rock_Ice_Permafrost",
      "rotation": 3
    },
    {
      "x": 2,
      "y": 2,
      "z": -3,
      "name": "Rock_Ice_Permafrost",
      "rotation": 3
    },
    {
      "x": 2,
      "y": 0,
      "z": -2,
      "name": "Rock_Ice_Permafrost",
      "rotation": 3
    },
    {
      "x": 2,
      "y": 1,
      "z": -2,
      "name": "Rock_Ice_Permafrost",
      "rotation": 3
    },
    {
      "x": 2,
      "y": 2,
      "z": -2,
      "name": "Rock_Ice_Permafrost",
      "rotation": 3
    },
    {
      "x": 2,
      "y": 3,
      "z": -2,
      "name": "Rubble_Ice",
      "support": 15,
      "rotation": 3
    },
    {
      "x": 2,
      "y": 0,
      "z": -1,
      "name": "Rock_Ice_Permafrost",
      "rotation": 3
    },
    {
      "x": 2,
      "y": 1,
      "z": -1,
      "name": "Rock_Ice_Permafrost",
      "rotation": 3
    },
    {
      "x": 2,
      "y": 2,
      "z": -1,
      "name": "Rock_Ice_Permafrost",
      "rotation": 3
    },
    {
      "x": 2,
      "y": 3,
      "z": -1,
      "name": "Rock_Ice_Permafrost",
      "rotation": 3
    },
    {
      "x": 2,
      "y": 4,
      "z": -1,
      "name": "Rock_Ice_Permafrost",
      "rotation": 3
    },
    {
      "x": 2,
      "y": 5,
      "z": -1,
      "name": "Rock_Ice_Permafrost",
      "rotation": 3
    },
    {
      "x": 2,
      "y": 6,
      "z": -1,
      "name": "Rock_Ice_Permafrost",
      "rotation": 3
    },
    {
      "x": 2,
      "y": 7,
      "z": -1,
      "name": "Rock_Ice_Permafrost",
      "rotation": 3
    },
    {
      "x": 2,
      "y": 8,
      "z": -1,
      "name": "Rock_Ice_Permafrost",
      "rotation": 3
    },
    {
      "x": 2,
      "y": 9,
      "z": -1,
      "name": "Rock_Ice_Permafrost",
      "rotation": 3
    },
    {
      "x": 2,
      "y": 10,
      "z": -1,
      "name": "Rock_Ice_Permafrost",
      "rotation": 3
    },
    {
      "x": 2,
      "y": 11,
      "z": -1,
      "name": "Rubble_Ice_Medium",
      "support": 15,
      "rotation": 3
    },
    {
      "x": 2,
      "y": 0,
      "z": 0,
      "name": "Rock_Ice_Permafrost",
      "rotation": 3
    },
    {
      "x": 2,
      "y": 1,
      "z": 0,
      "name": "Rock_Ice_Permafrost",
      "rotation": 3
    },
    {
      "x": 2,
      "y": 2,
      "z": 0,
      "name": "Rock_Ice_Permafrost",
      "rotation": 3
    },
    {
      "x": 2,
      "y": 3,
      "z": 0,
      "name": "Rock_Ice_Permafrost",
      "rotation": 3
    },
    {
      "x": 2,
      "y": 4,
      "z": 0,
      "name": "Rock_Ice_Permafrost",
      "rotation": 3
    },
    {
      "x": 2,
      "y": 5,
      "z": 0,
      "name": "Rock_Ice_Permafrost",
      "rotation": 3
    },
    {
      "x": 2,
      "y": 6,
      "z": 0,
      "name": "Rock_Ice_Permafrost",
      "rotation": 3
    },
    {
      "x": 2,
      "y": 7,
      "z": 0,
      "name": "Rock_Ice_Permafrost",
      "rotation": 3
    },
    {
      "x": 2,
      "y": 8,
      "z": 0,
      "name": "Rock_Ice_Permafrost",
      "rotation": 3
    },
    {
      "x": 2,
      "y": 9,
      "z": 0,
      "name": "Rock_Ice_Permafrost",
      "rotation": 3
    },
    {
      "x": 2,
      "y": 10,
      "z": 0,
      "name": "Rock_Ice_Permafrost",
      "rotation": 3
    },
    {
      "x": 2,
      "y": 11,
      "z": 0,
      "name": "Rock_Ice_Permafrost",
      "rotation": 3
    },
    {
      "x": 2,
      "y": 0,
      "z": 1,
      "name": "Rock_Ice_Permafrost",
      "rotation": 3
    },
    {
      "x": 2,
      "y": 1,
      "z": 1,
      "name": "Rock_Ice_Permafrost",
      "rotation": 3
    },
    {
      "x": 2,
      "y": 2,
      "z": 1,
      "name": "Rock_Ice_Permafrost",
      "rotation": 3
    },
    {
      "x": 2,
      "y": 3,
      "z": 1,
      "name": "Rock_Ice_Permafrost",
      "rotation": 3
    },
    {
      "x": 2,
      "y": 4,
      "z": 1,
      "name": "Rock_Ice_Permafrost",
      "rotation": 3
    },
    {
      "x": 2,
      "y": 5,
      "z": 1,
      "name": "Rock_Ice_Permafrost",
      "rotation": 3
    },
    {
      "x": 2,
      "y": 6,
      "z": 1,
      "name": "Rock_Ice_Permafrost",
      "rotation": 3
    },
    {
      "x": 2,
      "y": 7,
      "z": 1,
      "name": "Rock_Ice_Permafrost",
      "rotation": 3
    },
    {
      "x": 2,
      "y": 8,
      "z": 1,
      "name": "Rock_Ice_Permafrost",
      "rotation": 3
    },
    {
      "x": 2,
      "y": 9,
      "z": 1,
      "name": "Rock_Ice_Permafrost",
      "rotation": 3
    },
    {
      "x": 2,
      "y": 10,
      "z": 1,
      "name": "Rock_Ice_Permafrost",
      "rotation": 3
    },
    {
      "x": 2,
      "y": 11,
      "z": 1,
      "name": "Rock_Ice_Permafrost",
      "rotation": 3
    },
    {
      "x": 2,
      "y": 12,
      "z": 1,
      "name": "Rock_Ice_Stalactite_Large",
      "rotation": 3
    },
    {
      "x": 2,
      "y": 13,
      "z": 1,
      "name": "Rock_Ice_Stalactite_Large",
      "filler": 1024,
      "rotation": 3
    },
    {
      "x": 2,
      "y": 0,
      "z": 2,
      "name": "Rock_Ice_Permafrost",
      "rotation": 3
    },
    {
      "x": 2,
      "y": 1,
      "z": 2,
      "name": "Rock_Ice_Permafrost",
      "rotation": 3
    },
    {
      "x": 2,
      "y": 2,
      "z": 2,
      "name": "Rock_Ice_Permafrost",
      "rotation": 3
    },
    {
      "x": 2,
      "y": 3,
      "z": 2,
      "name": "Rock_Ice_Permafrost",
      "rotation": 3
    },
    {
      "x": 2,
      "y": 4,
      "z": 2,
      "name": "Rock_Ice_Stalactite_Large",
      "rotation": 3
    },
    {
      "x": 2,
      "y": 5,
      "z": 2,
      "name": "Rock_Ice_Stalactite_Large",
      "filler": 1024,
      "rotation": 3
    },
    {
      "x": 2,
      "y": 7,
      "z": 2,
      "name": "Rock_Ice_Permafrost",
      "rotation": 3
    },
    {
      "x": 2,
      "y": 8,
      "z": 2,
      "name": "Rock_Ice_Permafrost",
      "rotation": 3
    },
    {
      "x": 2,
      "y": 9,
      "z": 2,
      "name": "Rock_Ice_Permafrost",
      "rotation": 3
    },
    {
      "x": 2,
      "y": 10,
      "z": 2,
      "name": "Rock_Ice_Permafrost",
      "rotation": 3
    },
    {
      "x": 2,
      "y": 11,
      "z": 2,
      "name": "Rubble_Ice",
      "support": 15,
      "rotation": 3
    },
    {
      "x": 2,
      "y": 0,
      "z": 3,
      "name": "Rock_Ice_Permafrost",
      "rotation": 3
    },
    {
      "x": 2,
      "y": 1,
      "z": 3,
      "name": "Rock_Ice_Permafrost",
      "rotation": 3
    },
    {
      "x": 2,
      "y": 2,
      "z": 3,
      "name": "Rock_Ice_Permafrost",
      "rotation": 3
    },
    {
      "x": 2,
      "y": 0,
      "z": 4,
      "name": "Rock_Ice_Permafrost",
      "rotation": 3
    },
    {
      "x": 2,
      "y": 1,
      "z": 4,
      "name": "Rock_Ice_Icicles",
      "rotation": 3
    },
    {
      "x": 3,
      "y": 0,
      "z": -4,
      "name": "Rock_Ice_Permafrost",
      "rotation": 3
    },
    {
      "x": 3,
      "y": 1,
      "z": -4,
      "name": "Rock_Ice_Stalactite_Large",
      "rotation": 3
    },
    {
      "x": 3,
      "y": 2,
      "z": -4,
      "name": "Rock_Ice_Stalactite_Large",
      "filler": 1024,
      "rotation": 3
    },
    {
      "x": 3,
      "y": 0,
      "z": -3,
      "name": "Rock_Ice_Permafrost",
      "rotation": 3
    },
    {
      "x": 3,
      "y": 1,
      "z": -3,
      "name": "Rock_Ice_Permafrost",
      "rotation": 3
    },
    {
      "x": 3,
      "y": 2,
      "z": -3,
      "name": "Rock_Ice_Icicles",
      "rotation": 3
    },
    {
      "x": 3,
      "y": 0,
      "z": -2,
      "name": "Rock_Ice_Permafrost",
      "rotation": 3
    },
    {
      "x": 3,
      "y": 1,
      "z": -2,
      "name": "Rock_Ice_Permafrost",
      "rotation": 3
    },
    {
      "x": 3,
      "y": 0,
      "z": -1,
      "name": "Rock_Ice_Permafrost",
      "rotation": 3
    },
    {
      "x": 3,
      "y": 1,
      "z": -1,
      "name": "Rock_Ice_Permafrost",
      "rotation": 3
    },
    {
      "x": 3,
      "y": 2,
      "z": -1,
      "name": "Rock_Ice_Permafrost",
      "rotation": 3
    },
    {
      "x": 3,
      "y": 3,
      "z": -1,
      "name": "Rock_Crystal_Cyan_Medium",
      "rotation": 3
    },
    {
      "x": 3,
      "y": 7,
      "z": -1,
      "name": "Rock_Ice_Icicles",
      "rotation": 11
    },
    {
      "x": 3,
      "y": 8,
      "z": -1,
      "name": "Rock_Ice_Permafrost",
      "rotation": 3
    },
    {
      "x": 3,
      "y": 9,
      "z": -1,
      "name": "Rock_Ice_Permafrost",
      "rotation": 3
    },
    {
      "x": 3,
      "y": 10,
      "z": -1,
      "name": "Rock_Ice_Permafrost",
      "rotation": 3
    },
    {
      "x": 3,
      "y": 11,
      "z": -1,
      "name": "Rock_Ice_Permafrost",
      "rotation": 3
    },
    {
      "x": 3,
      "y": 12,
      "z": -1,
      "name": "Rock_Ice_Permafrost",
      "rotation": 3
    },
    {
      "x": 3,
      "y": 0,
      "z": 0,
      "name": "Rock_Ice_Permafrost",
      "rotation": 3
    },
    {
      "x": 3,
      "y": 1,
      "z": 0,
      "name": "Rock_Ice_Permafrost",
      "rotation": 3
    },
    {
      "x": 3,
      "y": 2,
      "z": 0,
      "name": "Rock_Ice_Permafrost",
      "rotation": 3
    },
    {
      "x": 3,
      "y": 3,
      "z": 0,
      "name": "Rock_Ice_Icicles",
      "rotation": 3
    },
    {
      "x": 3,
      "y": 6,
      "z": 0,
      "name": "Rock_Ice_Icicles",
      "rotation": 11
    },
    {
      "x": 3,
      "y": 7,
      "z": 0,
      "name": "Rock_Ice_Permafrost",
      "rotation": 3
    },
    {
      "x": 3,
      "y": 8,
      "z": 0,
      "name": "Rock_Ice_Permafrost",
      "rotation": 3
    },
    {
      "x": 3,
      "y": 9,
      "z": 0,
      "name": "Rock_Ice_Permafrost",
      "rotation": 3
    },
    {
      "x": 3,
      "y": 10,
      "z": 0,
      "name": "Rock_Ice_Permafrost",
      "rotation": 3
    },
    {
      "x": 3,
      "y": 11,
      "z": 0,
      "name": "Rock_Ice_Permafrost",
      "rotation": 3
    },
    {
      "x": 3,
      "y": 12,
      "z": 0,
      "name": "Rock_Ice_Permafrost",
      "rotation": 3
    },
    {
      "x": 3,
      "y": 13,
      "z": 0,
      "name": "Rock_Ice_Permafrost",
      "rotation": 3
    },
    {
      "x": 3,
      "y": 0,
      "z": 1,
      "name": "Rock_Ice_Permafrost",
      "rotation": 3
    },
    {
      "x": 3,
      "y": 1,
      "z": 1,
      "name": "Rock_Ice_Permafrost",
      "rotation": 3
    },
    {
      "x": 3,
      "y": 2,
      "z": 1,
      "name": "Rock_Ice_Permafrost",
      "rotation": 3
    },
    {
      "x": 3,
      "y": 7,
      "z": 1,
      "name": "Rock_Ice_Permafrost",
      "rotation": 3
    },
    {
      "x": 3,
      "y": 8,
      "z": 1,
      "name": "Rock_Ice_Permafrost",
      "rotation": 3
    },
    {
      "x": 3,
      "y": 9,
      "z": 1,
      "name": "Rock_Ice_Permafrost",
      "rotation": 3
    },
    {
      "x": 3,
      "y": 10,
      "z": 1,
      "name": "Rock_Ice_Permafrost",
      "rotation": 3
    },
    {
      "x": 3,
      "y": 11,
      "z": 1,
      "name": "Rock_Ice_Permafrost",
      "rotation": 3
    },
    {
      "x": 3,
      "y": 12,
      "z": 1,
      "name": "Rock_Ice_Permafrost",
      "rotation": 3
    },
    {
      "x": 3,
      "y": 13,
      "z": 1,
      "name": "Rubble_Ice_Medium",
      "support": 15,
      "rotation": 3
    },
    {
      "x": 3,
      "y": 0,
      "z": 2,
      "name": "Rock_Ice_Permafrost",
      "rotation": 3
    },
    {
      "x": 3,
      "y": 1,
      "z": 2,
      "name": "Rock_Ice_Permafrost",
      "rotation": 3
    },
    {
      "x": 3,
      "y": 2,
      "z": 2,
      "name": "Rock_Ice_Permafrost",
      "rotation": 3
    },
    {
      "x": 3,
      "y": 6,
      "z": 2,
      "name": "Rock_Ice_Stalactite_Large",
      "filler": 31744,
      "rotation": 11
    },
    {
      "x": 3,
      "y": 7,
      "z": 2,
      "name": "Rock_Ice_Stalactite_Large",
      "rotation": 11
    },
    {
      "x": 3,
      "y": 8,
      "z": 2,
      "name": "Rock_Ice_Permafrost",
      "rotation": 3
    },
    {
      "x": 3,
      "y": 9,
      "z": 2,
      "name": "Rock_Ice_Permafrost",
      "rotation": 3
    },
    {
      "x": 3,
      "y": 10,
      "z": 2,
      "name": "Rock_Ice_Permafrost",
      "rotation": 3
    },
    {
      "x": 3,
      "y": 11,
      "z": 2,
      "name": "Rock_Ice_Permafrost",
      "rotation": 3
    },
    {
      "x": 3,
      "y": 0,
      "z": 3,
      "name": "Rock_Ice_Permafrost"
    },
    {
      "x": 3,
      "y": 1,
      "z": 3,
      "name": "Rock_Ice_Permafrost",
      "rotation": 3
    },
    {
      "x": 3,
      "y": 0,
      "z": 4,
      "name": "Rock_Ice_Permafrost",
      "rotation": 3
    },
    {
      "x": 4,
      "y": 0,
      "z": -3,
      "name": "Rock_Ice_Permafrost",
      "rotation": 3
    },
    {
      "x": 4,
      "y": 0,
      "z": -2,
      "name": "Rock_Ice_Permafrost",
      "rotation": 3
    },
    {
      "x": 4,
      "y": 1,
      "z": -2,
      "name": "Rock_Ice_Icicles",
      "rotation": 3
    },
    {
      "x": 4,
      "y": 0,
      "z": -1,
      "name": "Rock_Ice_Permafrost",
      "rotation": 3
    },
    {
      "x": 4,
      "y": 1,
      "z": -1,
      "name": "Rock_Ice_Permafrost",
      "rotation": 3
    },
    {
      "x": 4,
      "y": 2,
      "z": -1,
      "name": "Rock_Ice_Icicles",
      "rotation": 3
    },
    {
      "x": 4,
      "y": 7,
      "z": -1,
      "name": "Rock_Ice_Stalactite_Large",
      "filler": 31744,
      "rotation": 11
    },
    {
      "x": 4,
      "y": 8,
      "z": -1,
      "name": "Rock_Ice_Stalactite_Large",
      "rotation": 11
    },
    {
      "x": 4,
      "y": 9,
      "z": -1,
      "name": "Rock_Ice_Permafrost",
      "rotation": 3
    },
    {
      "x": 4,
      "y": 10,
      "z": -1,
      "name": "Rock_Ice_Permafrost",
      "rotation": 3
    },
    {
      "x": 4,
      "y": 11,
      "z": -1,
      "name": "Rock_Ice_Permafrost",
      "rotation": 3
    },
    {
      "x": 4,
      "y": 12,
      "z": -1,
      "name": "Rock_Ice_Permafrost",
      "rotation": 3
    },
    {
      "x": 4,
      "y": 13,
      "z": -1,
      "name": "Rock_Ice_Permafrost",
      "rotation": 3
    },
    {
      "x": 4,
      "y": 0,
      "z": 0,
      "name": "Rock_Ice_Permafrost",
      "rotation": 3
    },
    {
      "x": 4,
      "y": 1,
      "z": 0,
      "name": "Rock_Ice_Permafrost",
      "rotation": 3
    },
    {
      "x": 4,
      "y": 8,
      "z": 0,
      "name": "Rock_Ice_Permafrost",
      "rotation": 3
    },
    {
      "x": 4,
      "y": 9,
      "z": 0,
      "name": "Rock_Ice_Permafrost",
      "rotation": 3
    },
    {
      "x": 4,
      "y": 10,
      "z": 0,
      "name": "Rock_Ice_Permafrost",
      "rotation": 3
    },
    {
      "x": 4,
      "y": 11,
      "z": 0,
      "name": "Rock_Ice_Permafrost",
      "rotation": 3
    },
    {
      "x": 4,
      "y": 12,
      "z": 0,
      "name": "Rock_Ice_Permafrost",
      "rotation": 3
    },
    {
      "x": 4,
      "y": 13,
      "z": 0,
      "name": "Rock_Ice_Permafrost",
      "rotation": 3
    },
    {
      "x": 4,
      "y": 14,
      "z": 0,
      "name": "Rock_Ice_Permafrost",
      "rotation": 3
    },
    {
      "x": 4,
      "y": 15,
      "z": 0,
      "name": "Rock_Ice_Icicles",
      "rotation": 3
    },
    {
      "x": 4,
      "y": 0,
      "z": 1,
      "name": "Rock_Ice_Permafrost",
      "rotation": 3
    },
    {
      "x": 4,
      "y": 1,
      "z": 1,
      "name": "Rock_Ice_Permafrost",
      "rotation": 3
    },
    {
      "x": 4,
      "y": 7,
      "z": 1,
      "name": "Rock_Ice_Icicles",
      "rotation": 11
    },
    {
      "x": 4,
      "y": 8,
      "z": 1,
      "name": "Rock_Ice_Permafrost",
      "rotation": 3
    },
    {
      "x": 4,
      "y": 9,
      "z": 1,
      "name": "Rock_Ice_Permafrost",
      "rotation": 3
    },
    {
      "x": 4,
      "y": 10,
      "z": 1,
      "name": "Rock_Ice_Permafrost",
      "rotation": 3
    },
    {
      "x": 4,
      "y": 11,
      "z": 1,
      "name": "Rock_Ice_Permafrost",
      "rotation": 3
    },
    {
      "x": 4,
      "y": 12,
      "z": 1,
      "name": "Rock_Ice_Permafrost",
      "rotation": 3
    },
    {
      "x": 4,
      "y": 13,
      "z": 1,
      "name": "Rock_Ice_Permafrost",
      "rotation": 3
    },
    {
      "x": 4,
      "y": 0,
      "z": 2,
      "name": "Rock_Ice_Permafrost",
      "rotation": 3
    },
    {
      "x": 4,
      "y": 1,
      "z": 2,
      "name": "Rock_Ice_Permafrost",
      "rotation": 3
    },
    {
      "x": 4,
      "y": 2,
      "z": 2,
      "name": "Rock_Ice_Icicles",
      "rotation": 3
    },
    {
      "x": 4,
      "y": 9,
      "z": 2,
      "name": "Rock_Ice_Icicles",
      "rotation": 11
    },
    {
      "x": 4,
      "y": 10,
      "z": 2,
      "name": "Rock_Ice_Permafrost",
      "rotation": 3
    },
    {
      "x": 4,
      "y": 11,
      "z": 2,
      "name": "Rock_Crystal_Cyan_Medium",
      "rotation": 3
    },
    {
      "x": 4,
      "y": 0,
      "z": 3,
      "name": "Rock_Ice_Permafrost",
      "rotation": 3
    },
    {
      "x": 4,
      "y": 1,
      "z": 3,
      "name": "Rock_Ice_Stalactite_Large",
      "rotation": 3
    },
    {
      "x": 4,
      "y": 2,
      "z": 3,
      "name": "Rock_Ice_Stalactite_Large",
      "filler": 1024,
      "rotation": 3
    },
    {
      "x": 5,
      "y": 0,
      "z": -1,
      "name": "Rock_Ice_Permafrost",
      "rotation": 3
    },
    {
      "x": 5,
      "y": 10,
      "z": -1,
      "name": "Rock_Ice_Icicles",
      "rotation": 11
    },
    {
      "x": 5,
      "y": 11,
      "z": -1,
      "name": "Rock_Ice_Permafrost",
      "rotation": 3
    },
    {
      "x": 5,
      "y": 12,
      "z": -1,
      "name": "Rock_Ice_Permafrost",
      "rotation": 3
    },
    {
      "x": 5,
      "y": 13,
      "z": -1,
      "name": "Rock_Ice_Permafrost",
      "rotation": 3
    },
    {
      "x": 5,
      "y": 14,
      "z": -1,
      "name": "Rock_Ice_Permafrost",
      "rotation": 3
    },
    {
      "x": 5,
      "y": 15,
      "z": -1,
      "name": "Rock_Ice_Permafrost",
      "rotation": 3
    },
    {
      "x": 5,
      "y": 0,
      "z": 0,
      "name": "Rock_Ice_Permafrost",
      "rotation": 3
    },
    {
      "x": 5,
      "y": 1,
      "z": 0,
      "name": "Rock_Ice_Icicles",
      "rotation": 3
    },
    {
      "x": 5,
      "y": 10,
      "z": 0,
      "name": "Rock_Ice_Permafrost",
      "rotation": 3
    },
    {
      "x": 5,
      "y": 11,
      "z": 0,
      "name": "Rock_Ice_Permafrost",
      "rotation": 3
    },
    {
      "x": 5,
      "y": 12,
      "z": 0,
      "name": "Rock_Ice_Permafrost",
      "rotation": 3
    },
    {
      "x": 5,
      "y": 13,
      "z": 0,
      "name": "Rock_Ice_Permafrost",
      "rotation": 3
    },
    {
      "x": 5,
      "y": 14,
      "z": 0,
      "name": "Rock_Ice_Permafrost",
      "rotation": 3
    },
    {
      "x": 5,
      "y": 15,
      "z": 0,
      "name": "Rock_Crystal_Cyan_Block",
      "rotation": 7
    },
    {
      "x": 5,
      "y": 0,
      "z": 1,
      "name": "Rock_Ice_Permafrost",
      "rotation": 3
    },
    {
      "x": 5,
      "y": 8,
      "z": 1,
      "name": "Rock_Ice_Stalactite_Large",
      "filler": 31744,
      "rotation": 11
    },
    {
      "x": 5,
      "y": 9,
      "z": 1,
      "name": "Rock_Ice_Stalactite_Large",
      "rotation": 11
    },
    {
      "x": 5,
      "y": 10,
      "z": 1,
      "name": "Rock_Ice_Permafrost",
      "rotation": 3
    },
    {
      "x": 5,
      "y": 11,
      "z": 1,
      "name": "Rock_Ice_Permafrost",
      "rotation": 3
    },
    {
      "x": 5,
      "y": 12,
      "z": 1,
      "name": "Rock_Ice_Permafrost",
      "rotation": 3
    },
    {
      "x": 5,
      "y": 13,
      "z": 1,
      "name": "Rock_Ice_Permafrost",
      "rotation": 3
    },
    {
      "x": 5,
      "y": 14,
      "z": 1,
      "name": "Rock_Ice_Permafrost",
      "rotation": 3
    },
    {
      "x": 5,
      "y": 15,
      "z": 1,
      "name": "Rock_Ice_Permafrost",
      "rotation": 3
    },
    {
      "x": 5,
      "y": 16,
      "z": 1,
      "name": "Rubble_Ice",
      "support": 15,
      "rotation": 3
    },
    {
      "x": 5,
      "y": 0,
      "z": 2,
      "name": "Rock_Ice_Permafrost",
      "rotation": 3
    },
    {
      "x": 6,
      "y": 10,
      "z": -1,
      "name": "Rock_Ice_Stalactite_Large",
      "filler": 31744,
      "rotation": 11
    },
    {
      "x": 6,
      "y": 11,
      "z": -1,
      "name": "Rock_Ice_Stalactite_Large",
      "rotation": 11
    },
    {
      "x": 6,
      "y": 12,
      "z": -1,
      "name": "Rock_Ice_Permafrost",
      "rotation": 3
    },
    {
      "x": 6,
      "y": 13,
      "z": -1,
      "name": "Rock_Ice_Permafrost",
      "rotation": 3
    },
    {
      "x": 6,
      "y": 14,
      "z": -1,
      "name": "Rock_Ice_Permafrost",
      "rotation": 3
    },
    {
      "x": 6,
      "y": 15,
      "z": -1,
      "name": "Rock_Ice_Permafrost",
      "rotation": 3
    },
    {
      "x": 6,
      "y": 16,
      "z": -1,
      "name": "Rock_Ice_Permafrost",
      "rotation": 3
    },
    {
      "x": 6,
      "y": 0,
      "z": 0,
      "name": "Rock_Ice_Permafrost",
      "rotation": 3
    },
    {
      "x": 6,
      "y": 10,
      "z": 0,
      "name": "Rock_Ice_Icicles",
      "rotation": 11
    },
    {
      "x": 6,
      "y": 11,
      "z": 0,
      "name": "Rock_Ice_Permafrost",
      "rotation": 3
    },
    {
      "x": 6,
      "y": 12,
      "z": 0,
      "name": "Rock_Ice_Permafrost",
      "rotation": 3
    },
    {
      "x": 6,
      "y": 13,
      "z": 0,
      "name": "Rock_Ice_Permafrost",
      "rotation": 3
    },
    {
      "x": 6,
      "y": 14,
      "z": 0,
      "name": "Rock_Ice_Permafrost",
      "rotation": 3
    },
    {
      "x": 6,
      "y": 15,
      "z": 0,
      "name": "Rock_Ice_Permafrost",
      "rotation": 3
    },
    {
      "x": 6,
      "y": 16,
      "z": 0,
      "name": "Rock_Ice_Permafrost",
      "rotation": 3
    },
    {
      "x": 6,
      "y": 17,
      "z": 0,
      "name": "Rubble_Ice_Medium",
      "support": 15,
      "rotation": 3
    },
    {
      "x": 6,
      "y": 0,
      "z": 1,
      "name": "Rock_Ice_Permafrost",
      "rotation": 3
    },
    {
      "x": 6,
      "y": 11,
      "z": 1,
      "name": "Rock_Ice_Icicles",
      "rotation": 11
    },
    {
      "x": 6,
      "y": 12,
      "z": 1,
      "name": "Rock_Ice_Permafrost",
      "rotation": 3
    },
    {
      "x": 6,
      "y": 13,
      "z": 1,
      "name": "Rock_Ice_Permafrost",
      "rotation": 3
    },
    {
      "x": 6,
      "y": 14,
      "z": 1,
      "name": "Rock_Ice_Permafrost",
      "rotation": 3
    },
    {
      "x": 6,
      "y": 15,
      "z": 1,
      "name": "Rock_Ice_Permafrost",
      "rotation": 3
    },
    {
      "x": 6,
      "y": 16,
      "z": 1,
      "name": "Rock_Ice_Permafrost",
      "rotation": 3
    },
    {
      "x": 7,
      "y": 12,
      "z": -1,
      "name": "Rock_Ice_Icicles",
      "rotation": 11
    },
    {
      "x": 7,
      "y": 13,
      "z": -1,
      "name": "Rock_Ice_Permafrost",
      "rotation": 3
    },
    {
      "x": 7,
      "y": 14,
      "z": -1,
      "name": "Rock_Ice_Permafrost",
      "rotation": 3
    },
    {
      "x": 7,
      "y": 15,
      "z": -1,
      "name": "Rock_Ice_Permafrost",
      "rotation": 3
    },
    {
      "x": 7,
      "y": 16,
      "z": -1,
      "name": "Rock_Ice_Permafrost",
      "rotation": 3
    },
    {
      "x": 7,
      "y": 17,
      "z": -1,
      "name": "Rock_Ice_Permafrost",
      "rotation": 3
    },
    {
      "x": 7,
      "y": 13,
      "z": 0,
      "name": "Rock_Ice_Permafrost",
      "rotation": 3
    },
    {
      "x": 7,
      "y": 14,
      "z": 0,
      "name": "Rock_Ice_Permafrost",
      "rotation": 3
    },
    {
      "x": 7,
      "y": 15,
      "z": 0,
      "name": "Rock_Ice_Permafrost",
      "rotation": 3
    },
    {
      "x": 7,
      "y": 16,
      "z": 0,
      "name": "Rock_Ice_Permafrost",
      "rotation": 3
    },
    {
      "x": 7,
      "y": 17,
      "z": 0,
      "name": "Rock_Ice_Permafrost",
      "rotation": 3
    },
    {
      "x": 7,
      "y": 11,
      "z": 1,
      "name": "Rock_Ice_Stalactite_Large",
      "filler": 31744,
      "rotation": 11
    },
    {
      "x": 7,
      "y": 12,
      "z": 1,
      "name": "Rock_Ice_Stalactite_Large",
      "rotation": 11
    },
    {
      "x": 7,
      "y": 13,
      "z": 1,
      "name": "Rock_Ice_Permafrost",
      "rotation": 3
    },
    {
      "x": 7,
      "y": 14,
      "z": 1,
      "name": "Rock_Ice_Permafrost",
      "rotation": 3
    },
    {
      "x": 7,
      "y": 15,
      "z": 1,
      "name": "Rock_Ice_Permafrost",
      "rotation": 3
    },
    {
      "x": 7,
      "y": 16,
      "z": 1,
      "name": "Rock_Ice_Permafrost",
      "rotation": 3
    },
    {
      "x": 7,
      "y": 17,
      "z": 1,
      "name": "Rock_Ice_Icicles",
      "rotation": 3
    },
    {
      "x": 8,
      "y": 13,
      "z": -1,
      "name": "Rock_Ice_Stalactite_Large",
      "filler": 31744,
      "rotation": 11
    },
    {
      "x": 8,
      "y": 14,
      "z": -1,
      "name": "Rock_Ice_Stalactite_Large",
      "rotation": 11
    },
    {
      "x": 8,
      "y": 15,
      "z": -1,
      "name": "Rock_Ice_Permafrost",
      "rotation": 3
    },
    {
      "x": 8,
      "y": 16,
      "z": -1,
      "name": "Rock_Ice_Permafrost",
      "rotation": 3
    },
    {
      "x": 8,
      "y": 17,
      "z": -1,
      "name": "Rock_Ice_Permafrost",
      "rotation": 3
    },
    {
      "x": 8,
      "y": 18,
      "z": -1,
      "name": "Rock_Ice_Icicles",
      "rotation": 3
    },
    {
      "x": 8,
      "y": 14,
      "z": 0,
      "name": "Rock_Ice_Icicles",
      "rotation": 11
    },
    {
      "x": 8,
      "y": 15,
      "z": 0,
      "name": "Rock_Ice_Permafrost",
      "rotation": 3
    },
    {
      "x": 8,
      "y": 16,
      "z": 0,
      "name": "Rock_Ice_Permafrost",
      "rotation": 3
    },
    {
      "x": 8,
      "y": 17,
      "z": 0,
      "name": "Rock_Ice_Permafrost",
      "rotation": 3
    },
    {
      "x": 8,
      "y": 18,
      "z": 0,
      "name": "Rock_Ice_Permafrost",
      "rotation": 3
    },
    {
      "x": 8,
      "y": 19,
      "z": 0,
      "name": "Rubble_Ice_Medium",
      "support": 15,
      "rotation": 3
    },
    {
      "x": 8,
      "y": 15,
      "z": 1,
      "name": "Rock_Ice_Icicles",
      "rotation": 11
    },
    {
      "x": 8,
      "y": 16,
      "z": 1,
      "name": "Rock_Ice_Permafrost",
      "rotation": 3
    },
    {
      "x": 8,
      "y": 17,
      "z": 1,
      "name": "Rock_Ice_Permafrost",
      "rotation": 3
    },
    {
      "x": 8,
      "y": 18,
      "z": 1,
      "name": "Rubble_Ice",
      "support": 15,
      "rotation": 3
    },
    {
      "x": 9,
      "y": 16,
      "z": -1,
      "name": "Rock_Ice_Icicles",
      "rotation": 11
    },
    {
      "x": 9,
      "y": 17,
      "z": -1,
      "name": "Rock_Ice_Permafrost",
      "rotation": 3
    },
    {
      "x": 9,
      "y": 18,
      "z": -1,
      "name": "Rock_Ice_Permafrost",
      "rotation": 3
    },
    {
      "x": 9,
      "y": 19,
      "z": -1,
      "name": "Rock_Ice_Permafrost",
      "rotation": 3
    },
    {
      "x": 9,
      "y": 17,
      "z": 0,
      "name": "Rock_Ice_Icicles",
      "rotation": 11
    },
    {
      "x": 9,
      "y": 18,
      "z": 0,
      "name": "Rock_Ice_Permafrost",
      "rotation": 3
    },
    {
      "x": 9,
      "y": 19,
      "z": 0,
      "name": "Rock_Crystal_Cyan_Medium",
      "rotation": 3
    }
  ],
  "fluids": [
    {
      "x": -8,
      "y": 0,
      "z": 2,
      "name": "Empty",
      "level": 0
    },
    {
      "x": -8,
      "y": 0,
      "z": 3,
      "name": "Empty",
      "level": 0
    },
    {
      "x": -8,
      "y": 1,
      "z": 3,
      "name": "Empty",
      "level": 0
    },
    {
      "x": -8,
      "y": 2,
      "z": 3,
      "name": "Empty",
      "level": 0
    },
    {
      "x": -7,
      "y": 0,
      "z": 0,
      "name": "Empty",
      "level": 0
    },
    {
      "x": -7,
      "y": 1,
      "z": 0,
      "name": "Empty",
      "level": 0
    },
    {
      "x": -7,
      "y": 0,
      "z": 1,
      "name": "Empty",
      "level": 0
    },
    {
      "x": -7,
      "y": 1,
      "z": 1,
      "name": "Empty",
      "level": 0
    },
    {
      "x": -7,
      "y": 2,
      "z": 1,
      "name": "Empty",
      "level": 0
    },
    {
      "x": -7,
      "y": 0,
      "z": 2,
      "name": "Empty",
      "level": 0
    },
    {
      "x": -7,
      "y": 1,
      "z": 2,
      "name": "Empty",
      "level": 0
    },
    {
      "x": -7,
      "y": 0,
      "z": 3,
      "name": "Empty",
      "level": 0
    },
    {
      "x": -7,
      "y": 0,
      "z": 4,
      "name": "Empty",
      "level": 0
    },
    {
      "x": -6,
      "y": 0,
      "z": -1,
      "name": "Empty",
      "level": 0
    },
    {
      "x": -6,
      "y": 1,
      "z": -1,
      "name": "Empty",
      "level": 0
    },
    {
      "x": -6,
      "y": 2,
      "z": -1,
      "name": "Empty",
      "level": 0
    },
    {
      "x": -6,
      "y": 0,
      "z": 0,
      "name": "Empty",
      "level": 0
    },
    {
      "x": -6,
      "y": 1,
      "z": 0,
      "name": "Empty",
      "level": 0
    },
    {
      "x": -6,
      "y": 2,
      "z": 0,
      "name": "Empty",
      "level": 0
    },
    {
      "x": -6,
      "y": 3,
      "z": 0,
      "name": "Empty",
      "level": 0
    },
    {
      "x": -6,
      "y": 0,
      "z": 1,
      "name": "Empty",
      "level": 0
    },
    {
      "x": -6,
      "y": 1,
      "z": 1,
      "name": "Empty",
      "level": 0
    },
    {
      "x": -6,
      "y": 2,
      "z": 1,
      "name": "Empty",
      "level": 0
    },
    {
      "x": -6,
      "y": 0,
      "z": 2,
      "name": "Empty",
      "level": 0
    },
    {
      "x": -6,
      "y": 1,
      "z": 2,
      "name": "Empty",
      "level": 0
    },
    {
      "x": -6,
      "y": 2,
      "z": 2,
      "name": "Empty",
      "level": 0
    },
    {
      "x": -6,
      "y": 0,
      "z": 3,
      "name": "Empty",
      "level": 0
    },
    {
      "x": -6,
      "y": 1,
      "z": 3,
      "name": "Empty",
      "level": 0
    },
    {
      "x": -6,
      "y": 2,
      "z": 3,
      "name": "Empty",
      "level": 0
    },
    {
      "x": -6,
      "y": 0,
      "z": 4,
      "name": "Empty",
      "level": 0
    },
    {
      "x": -6,
      "y": 0,
      "z": 5,
      "name": "Empty",
      "level": 0
    },
    {
      "x": -5,
      "y": 0,
      "z": -2,
      "name": "Empty",
      "level": 0
    },
    {
      "x": -5,
      "y": 0,
      "z": -1,
      "name": "Empty",
      "level": 0
    },
    {
      "x": -5,
      "y": 1,
      "z": -1,
      "name": "Empty",
      "level": 0
    },
    {
      "x": -5,
      "y": 2,
      "z": -1,
      "name": "Empty",
      "level": 0
    },
    {
      "x": -5,
      "y": 3,
      "z": -1,
      "name": "Empty",
      "level": 0
    },
    {
      "x": -5,
      "y": 4,
      "z": -1,
      "name": "Empty",
      "level": 0
    },
    {
      "x": -5,
      "y": 0,
      "z": 0,
      "name": "Empty",
      "level": 0
    },
    {
      "x": -5,
      "y": 1,
      "z": 0,
      "name": "Empty",
      "level": 0
    },
    {
      "x": -5,
      "y": 2,
      "z": 0,
      "name": "Empty",
      "level": 0
    },
    {
      "x": -5,
      "y": 3,
      "z": 0,
      "name": "Empty",
      "level": 0
    },
    {
      "x": -5,
      "y": 0,
      "z": 1,
      "name": "Empty",
      "level": 0
    },
    {
      "x": -5,
      "y": 1,
      "z": 1,
      "name": "Empty",
      "level": 0
    },
    {
      "x": -5,
      "y": 2,
      "z": 1,
      "name": "Empty",
      "level": 0
    },
    {
      "x": -5,
      "y": 3,
      "z": 1,
      "name": "Empty",
      "level": 0
    },
    {
      "x": -5,
      "y": 0,
      "z": 2,
      "name": "Empty",
      "level": 0
    },
    {
      "x": -5,
      "y": 1,
      "z": 2,
      "name": "Empty",
      "level": 0
    },
    {
      "x": -5,
      "y": 2,
      "z": 2,
      "name": "Empty",
      "level": 0
    },
    {
      "x": -5,
      "y": 3,
      "z": 2,
      "name": "Empty",
      "level": 0
    },
    {
      "x": -5,
      "y": 0,
      "z": 3,
      "name": "Empty",
      "level": 0
    },
    {
      "x": -5,
      "y": 1,
      "z": 3,
      "name": "Empty",
      "level": 0
    },
    {
      "x": -5,
      "y": 2,
      "z": 3,
      "name": "Empty",
      "level": 0
    },
    {
      "x": -5,
      "y": 3,
      "z": 3,
      "name": "Empty",
      "level": 0
    },
    {
      "x": -5,
      "y": 4,
      "z": 3,
      "name": "Empty",
      "level": 0
    },
    {
      "x": -5,
      "y": 0,
      "z": 4,
      "name": "Empty",
      "level": 0
    },
    {
      "x": -5,
      "y": 1,
      "z": 4,
      "name": "Empty",
      "level": 0
    },
    {
      "x": -5,
      "y": 2,
      "z": 4,
      "name": "Empty",
      "level": 0
    },
    {
      "x": -5,
      "y": 3,
      "z": 4,
      "name": "Empty",
      "level": 0
    },
    {
      "x": -5,
      "y": 0,
      "z": 5,
      "name": "Empty",
      "level": 0
    },
    {
      "x": -5,
      "y": 0,
      "z": 6,
      "name": "Empty",
      "level": 0
    },
    {
      "x": -4,
      "y": 0,
      "z": -4,
      "name": "Empty",
      "level": 0
    },
    {
      "x": -4,
      "y": 1,
      "z": -4,
      "name": "Empty",
      "level": 0
    },
    {
      "x": -4,
      "y": 2,
      "z": -4,
      "name": "Empty",
      "level": 0
    },
    {
      "x": -4,
      "y": 0,
      "z": -3,
      "name": "Empty",
      "level": 0
    },
    {
      "x": -4,
      "y": 0,
      "z": -2,
      "name": "Empty",
      "level": 0
    },
    {
      "x": -4,
      "y": 1,
      "z": -2,
      "name": "Empty",
      "level": 0
    },
    {
      "x": -4,
      "y": 2,
      "z": -2,
      "name": "Empty",
      "level": 0
    },
    {
      "x": -4,
      "y": 3,
      "z": -2,
      "name": "Empty",
      "level": 0
    },
    {
      "x": -4,
      "y": 4,
      "z": -2,
      "name": "Empty",
      "level": 0
    },
    {
      "x": -4,
      "y": 0,
      "z": -1,
      "name": "Empty",
      "level": 0
    },
    {
      "x": -4,
      "y": 1,
      "z": -1,
      "name": "Empty",
      "level": 0
    },
    {
      "x": -4,
      "y": 2,
      "z": -1,
      "name": "Empty",
      "level": 0
    },
    {
      "x": -4,
      "y": 3,
      "z": -1,
      "name": "Empty",
      "level": 0
    },
    {
      "x": -4,
      "y": 4,
      "z": -1,
      "name": "Empty",
      "level": 0
    },
    {
      "x": -4,
      "y": 0,
      "z": 0,
      "name": "Empty",
      "level": 0
    },
    {
      "x": -4,
      "y": 1,
      "z": 0,
      "name": "Empty",
      "level": 0
    },
    {
      "x": -4,
      "y": 2,
      "z": 0,
      "name": "Empty",
      "level": 0
    },
    {
      "x": -4,
      "y": 3,
      "z": 0,
      "name": "Empty",
      "level": 0
    },
    {
      "x": -4,
      "y": 4,
      "z": 0,
      "name": "Empty",
      "level": 0
    },
    {
      "x": -4,
      "y": 0,
      "z": 1,
      "name": "Empty",
      "level": 0
    },
    {
      "x": -4,
      "y": 1,
      "z": 1,
      "name": "Empty",
      "level": 0
    },
    {
      "x": -4,
      "y": 2,
      "z": 1,
      "name": "Empty",
      "level": 0
    },
    {
      "x": -4,
      "y": 3,
      "z": 1,
      "name": "Empty",
      "level": 0
    },
    {
      "x": -4,
      "y": 4,
      "z": 1,
      "name": "Empty",
      "level": 0
    },
    {
      "x": -4,
      "y": 5,
      "z": 1,
      "name": "Empty",
      "level": 0
    },
    {
      "x": -4,
      "y": 0,
      "z": 2,
      "name": "Empty",
      "level": 0
    },
    {
      "x": -4,
      "y": 1,
      "z": 2,
      "name": "Empty",
      "level": 0
    },
    {
      "x": -4,
      "y": 2,
      "z": 2,
      "name": "Empty",
      "level": 0
    },
    {
      "x": -4,
      "y": 3,
      "z": 2,
      "name": "Empty",
      "level": 0
    },
    {
      "x": -4,
      "y": 4,
      "z": 2,
      "name": "Empty",
      "level": 0
    },
    {
      "x": -4,
      "y": 0,
      "z": 3,
      "name": "Empty",
      "level": 0
    },
    {
      "x": -4,
      "y": 1,
      "z": 3,
      "name": "Empty",
      "level": 0
    },
    {
      "x": -4,
      "y": 2,
      "z": 3,
      "name": "Empty",
      "level": 0
    },
    {
      "x": -4,
      "y": 3,
      "z": 3,
      "name": "Empty",
      "level": 0
    },
    {
      "x": -4,
      "y": 0,
      "z": 4,
      "name": "Empty",
      "level": 0
    },
    {
      "x": -4,
      "y": 1,
      "z": 4,
      "name": "Empty",
      "level": 0
    },
    {
      "x": -4,
      "y": 2,
      "z": 4,
      "name": "Empty",
      "level": 0
    },
    {
      "x": -4,
      "y": 0,
      "z": 5,
      "name": "Empty",
      "level": 0
    },
    {
      "x": -4,
      "y": 1,
      "z": 5,
      "name": "Empty",
      "level": 0
    },
    {
      "x": -4,
      "y": 0,
      "z": 6,
      "name": "Empty",
      "level": 0
    },
    {
      "x": -3,
      "y": 0,
      "z": -5,
      "name": "Empty",
      "level": 0
    },
    {
      "x": -3,
      "y": 0,
      "z": -4,
      "name": "Empty",
      "level": 0
    },
    {
      "x": -3,
      "y": 1,
      "z": -4,
      "name": "Empty",
      "level": 0
    },
    {
      "x": -3,
      "y": 0,
      "z": -3,
      "name": "Empty",
      "level": 0
    },
    {
      "x": -3,
      "y": 1,
      "z": -3,
      "name": "Empty",
      "level": 0
    },
    {
      "x": -3,
      "y": 2,
      "z": -3,
      "name": "Empty",
      "level": 0
    },
    {
      "x": -3,
      "y": 0,
      "z": -2,
      "name": "Empty",
      "level": 0
    },
    {
      "x": -3,
      "y": 1,
      "z": -2,
      "name": "Empty",
      "level": 0
    },
    {
      "x": -3,
      "y": 2,
      "z": -2,
      "name": "Empty",
      "level": 0
    },
    {
      "x": -3,
      "y": 3,
      "z": -2,
      "name": "Empty",
      "level": 0
    },
    {
      "x": -3,
      "y": 0,
      "z": -1,
      "name": "Empty",
      "level": 0
    },
    {
      "x": -3,
      "y": 1,
      "z": -1,
      "name": "Empty",
      "level": 0
    },
    {
      "x": -3,
      "y": 2,
      "z": -1,
      "name": "Empty",
      "level": 0
    },
    {
      "x": -3,
      "y": 3,
      "z": -1,
      "name": "Empty",
      "level": 0
    },
    {
      "x": -3,
      "y": 4,
      "z": -1,
      "name": "Empty",
      "level": 0
    },
    {
      "x": -3,
      "y": 5,
      "z": -1,
      "name": "Empty",
      "level": 0
    },
    {
      "x": -3,
      "y": 6,
      "z": -1,
      "name": "Empty",
      "level": 0
    },
    {
      "x": -3,
      "y": 0,
      "z": 0,
      "name": "Empty",
      "level": 0
    },
    {
      "x": -3,
      "y": 1,
      "z": 0,
      "name": "Empty",
      "level": 0
    },
    {
      "x": -3,
      "y": 2,
      "z": 0,
      "name": "Empty",
      "level": 0
    },
    {
      "x": -3,
      "y": 3,
      "z": 0,
      "name": "Empty",
      "level": 0
    },
    {
      "x": -3,
      "y": 4,
      "z": 0,
      "name": "Empty",
      "level": 0
    },
    {
      "x": -3,
      "y": 5,
      "z": 0,
      "name": "Empty",
      "level": 0
    },
    {
      "x": -3,
      "y": 0,
      "z": 1,
      "name": "Empty",
      "level": 0
    },
    {
      "x": -3,
      "y": 1,
      "z": 1,
      "name": "Empty",
      "level": 0
    },
    {
      "x": -3,
      "y": 2,
      "z": 1,
      "name": "Empty",
      "level": 0
    },
    {
      "x": -3,
      "y": 3,
      "z": 1,
      "name": "Empty",
      "level": 0
    },
    {
      "x": -3,
      "y": 4,
      "z": 1,
      "name": "Empty",
      "level": 0
    },
    {
      "x": -3,
      "y": 5,
      "z": 1,
      "name": "Empty",
      "level": 0
    },
    {
      "x": -3,
      "y": 0,
      "z": 2,
      "name": "Empty",
      "level": 0
    },
    {
      "x": -3,
      "y": 1,
      "z": 2,
      "name": "Empty",
      "level": 0
    },
    {
      "x": -3,
      "y": 2,
      "z": 2,
      "name": "Empty",
      "level": 0
    },
    {
      "x": -3,
      "y": 3,
      "z": 2,
      "name": "Empty",
      "level": 0
    },
    {
      "x": -3,
      "y": 4,
      "z": 2,
      "name": "Empty",
      "level": 0
    },
    {
      "x": -3,
      "y": 5,
      "z": 2,
      "name": "Empty",
      "level": 0
    },
    {
      "x": -3,
      "y": 0,
      "z": 3,
      "name": "Empty",
      "level": 0
    },
    {
      "x": -3,
      "y": 1,
      "z": 3,
      "name": "Empty",
      "level": 0
    },
    {
      "x": -3,
      "y": 2,
      "z": 3,
      "name": "Empty",
      "level": 0
    },
    {
      "x": -3,
      "y": 3,
      "z": 3,
      "name": "Empty",
      "level": 0
    },
    {
      "x": -3,
      "y": 4,
      "z": 3,
      "name": "Empty",
      "level": 0
    },
    {
      "x": -3,
      "y": 5,
      "z": 3,
      "name": "Empty",
      "level": 0
    },
    {
      "x": -3,
      "y": 0,
      "z": 4,
      "name": "Empty",
      "level": 0
    },
    {
      "x": -3,
      "y": 1,
      "z": 4,
      "name": "Empty",
      "level": 0
    },
    {
      "x": -3,
      "y": 2,
      "z": 4,
      "name": "Empty",
      "level": 0
    },
    {
      "x": -3,
      "y": 3,
      "z": 4,
      "name": "Empty",
      "level": 0
    },
    {
      "x": -3,
      "y": 0,
      "z": 5,
      "name": "Empty",
      "level": 0
    },
    {
      "x": -3,
      "y": 1,
      "z": 5,
      "name": "Empty",
      "level": 0
    },
    {
      "x": -3,
      "y": 2,
      "z": 5,
      "name": "Empty",
      "level": 0
    },
    {
      "x": -3,
      "y": 0,
      "z": 6,
      "name": "Empty",
      "level": 0
    },
    {
      "x": -2,
      "y": 0,
      "z": -6,
      "name": "Empty",
      "level": 0
    },
    {
      "x": -2,
      "y": 0,
      "z": -5,
      "name": "Empty",
      "level": 0
    },
    {
      "x": -2,
      "y": 1,
      "z": -5,
      "name": "Empty",
      "level": 0
    },
    {
      "x": -2,
      "y": 0,
      "z": -4,
      "name": "Empty",
      "level": 0
    },
    {
      "x": -2,
      "y": 1,
      "z": -4,
      "name": "Empty",
      "level": 0
    },
    {
      "x": -2,
      "y": 2,
      "z": -4,
      "name": "Empty",
      "level": 0
    },
    {
      "x": -2,
      "y": 3,
      "z": -4,
      "name": "Empty",
      "level": 0
    },
    {
      "x": -2,
      "y": 0,
      "z": -3,
      "name": "Empty",
      "level": 0
    },
    {
      "x": -2,
      "y": 1,
      "z": -3,
      "name": "Empty",
      "level": 0
    },
    {
      "x": -2,
      "y": 2,
      "z": -3,
      "name": "Empty",
      "level": 0
    },
    {
      "x": -2,
      "y": 0,
      "z": -2,
      "name": "Empty",
      "level": 0
    },
    {
      "x": -2,
      "y": 1,
      "z": -2,
      "name": "Empty",
      "level": 0
    },
    {
      "x": -2,
      "y": 2,
      "z": -2,
      "name": "Empty",
      "level": 0
    },
    {
      "x": -2,
      "y": 3,
      "z": -2,
      "name": "Empty",
      "level": 0
    },
    {
      "x": -2,
      "y": 4,
      "z": -2,
      "name": "Empty",
      "level": 0
    },
    {
      "x": -2,
      "y": 0,
      "z": -1,
      "name": "Empty",
      "level": 0
    },
    {
      "x": -2,
      "y": 1,
      "z": -1,
      "name": "Empty",
      "level": 0
    },
    {
      "x": -2,
      "y": 2,
      "z": -1,
      "name": "Empty",
      "level": 0
    },
    {
      "x": -2,
      "y": 3,
      "z": -1,
      "name": "Empty",
      "level": 0
    },
    {
      "x": -2,
      "y": 4,
      "z": -1,
      "name": "Empty",
      "level": 0
    },
    {
      "x": -2,
      "y": 5,
      "z": -1,
      "name": "Empty",
      "level": 0
    },
    {
      "x": -2,
      "y": 6,
      "z": -1,
      "name": "Empty",
      "level": 0
    },
    {
      "x": -2,
      "y": 7,
      "z": -1,
      "name": "Empty",
      "level": 0
    },
    {
      "x": -2,
      "y": 0,
      "z": 0,
      "name": "Empty",
      "level": 0
    },
    {
      "x": -2,
      "y": 1,
      "z": 0,
      "name": "Empty",
      "level": 0
    },
    {
      "x": -2,
      "y": 2,
      "z": 0,
      "name": "Empty",
      "level": 0
    },
    {
      "x": -2,
      "y": 3,
      "z": 0,
      "name": "Empty",
      "level": 0
    },
    {
      "x": -2,
      "y": 4,
      "z": 0,
      "name": "Empty",
      "level": 0
    },
    {
      "x": -2,
      "y": 5,
      "z": 0,
      "name": "Empty",
      "level": 0
    },
    {
      "x": -2,
      "y": 6,
      "z": 0,
      "name": "Empty",
      "level": 0
    },
    {
      "x": -2,
      "y": 0,
      "z": 1,
      "name": "Empty",
      "level": 0
    },
    {
      "x": -2,
      "y": 1,
      "z": 1,
      "name": "Empty",
      "level": 0
    },
    {
      "x": -2,
      "y": 2,
      "z": 1,
      "name": "Empty",
      "level": 0
    },
    {
      "x": -2,
      "y": 3,
      "z": 1,
      "name": "Empty",
      "level": 0
    },
    {
      "x": -2,
      "y": 4,
      "z": 1,
      "name": "Empty",
      "level": 0
    },
    {
      "x": -2,
      "y": 5,
      "z": 1,
      "name": "Empty",
      "level": 0
    },
    {
      "x": -2,
      "y": 6,
      "z": 1,
      "name": "Empty",
      "level": 0
    },
    {
      "x": -2,
      "y": 7,
      "z": 1,
      "name": "Empty",
      "level": 0
    },
    {
      "x": -2,
      "y": 8,
      "z": 1,
      "name": "Empty",
      "level": 0
    },
    {
      "x": -2,
      "y": 0,
      "z": 2,
      "name": "Empty",
      "level": 0
    },
    {
      "x": -2,
      "y": 1,
      "z": 2,
      "name": "Empty",
      "level": 0
    },
    {
      "x": -2,
      "y": 2,
      "z": 2,
      "name": "Empty",
      "level": 0
    },
    {
      "x": -2,
      "y": 3,
      "z": 2,
      "name": "Empty",
      "level": 0
    },
    {
      "x": -2,
      "y": 4,
      "z": 2,
      "name": "Empty",
      "level": 0
    },
    {
      "x": -2,
      "y": 5,
      "z": 2,
      "name": "Empty",
      "level": 0
    },
    {
      "x": -2,
      "y": 6,
      "z": 2,
      "name": "Empty",
      "level": 0
    },
    {
      "x": -2,
      "y": 0,
      "z": 3,
      "name": "Empty",
      "level": 0
    },
    {
      "x": -2,
      "y": 1,
      "z": 3,
      "name": "Empty",
      "level": 0
    },
    {
      "x": -2,
      "y": 2,
      "z": 3,
      "name": "Empty",
      "level": 0
    },
    {
      "x": -2,
      "y": 3,
      "z": 3,
      "name": "Empty",
      "level": 0
    },
    {
      "x": -2,
      "y": 4,
      "z": 3,
      "name": "Empty",
      "level": 0
    },
    {
      "x": -2,
      "y": 0,
      "z": 4,
      "name": "Empty",
      "level": 0
    },
    {
      "x": -2,
      "y": 1,
      "z": 4,
      "name": "Empty",
      "level": 0
    },
    {
      "x": -2,
      "y": 2,
      "z": 4,
      "name": "Empty",
      "level": 0
    },
    {
      "x": -2,
      "y": 3,
      "z": 4,
      "name": "Empty",
      "level": 0
    },
    {
      "x": -2,
      "y": 4,
      "z": 4,
      "name": "Empty",
      "level": 0
    },
    {
      "x": -2,
      "y": 5,
      "z": 4,
      "name": "Empty",
      "level": 0
    },
    {
      "x": -2,
      "y": 0,
      "z": 5,
      "name": "Empty",
      "level": 0
    },
    {
      "x": -2,
      "y": 1,
      "z": 5,
      "name": "Empty",
      "level": 0
    },
    {
      "x": -2,
      "y": 2,
      "z": 5,
      "name": "Empty",
      "level": 0
    },
    {
      "x": -2,
      "y": 0,
      "z": 6,
      "name": "Empty",
      "level": 0
    },
    {
      "x": -1,
      "y": 0,
      "z": -6,
      "name": "Empty",
      "level": 0
    },
    {
      "x": -1,
      "y": 1,
      "z": -6,
      "name": "Empty",
      "level": 0
    },
    {
      "x": -1,
      "y": 0,
      "z": -5,
      "name": "Empty",
      "level": 0
    },
    {
      "x": -1,
      "y": 1,
      "z": -5,
      "name": "Empty",
      "level": 0
    },
    {
      "x": -1,
      "y": 0,
      "z": -4,
      "name": "Empty",
      "level": 0
    },
    {
      "x": -1,
      "y": 1,
      "z": -4,
      "name": "Empty",
      "level": 0
    },
    {
      "x": -1,
      "y": 2,
      "z": -4,
      "name": "Empty",
      "level": 0
    },
    {
      "x": -1,
      "y": 3,
      "z": -4,
      "name": "Empty",
      "level": 0
    },
    {
      "x": -1,
      "y": 0,
      "z": -3,
      "name": "Empty",
      "level": 0
    },
    {
      "x": -1,
      "y": 1,
      "z": -3,
      "name": "Empty",
      "level": 0
    },
    {
      "x": -1,
      "y": 2,
      "z": -3,
      "name": "Empty",
      "level": 0
    },
    {
      "x": -1,
      "y": 3,
      "z": -3,
      "name": "Empty",
      "level": 0
    },
    {
      "x": -1,
      "y": 4,
      "z": -3,
      "name": "Empty",
      "level": 0
    },
    {
      "x": -1,
      "y": 5,
      "z": -3,
      "name": "Empty",
      "level": 0
    },
    {
      "x": -1,
      "y": 0,
      "z": -2,
      "name": "Empty",
      "level": 0
    },
    {
      "x": -1,
      "y": 1,
      "z": -2,
      "name": "Empty",
      "level": 0
    },
    {
      "x": -1,
      "y": 2,
      "z": -2,
      "name": "Empty",
      "level": 0
    },
    {
      "x": -1,
      "y": 3,
      "z": -2,
      "name": "Empty",
      "level": 0
    },
    {
      "x": -1,
      "y": 4,
      "z": -2,
      "name": "Empty",
      "level": 0
    },
    {
      "x": -1,
      "y": 5,
      "z": -2,
      "name": "Empty",
      "level": 0
    },
    {
      "x": -1,
      "y": 0,
      "z": -1,
      "name": "Empty",
      "level": 0
    },
    {
      "x": -1,
      "y": 1,
      "z": -1,
      "name": "Empty",
      "level": 0
    },
    {
      "x": -1,
      "y": 2,
      "z": -1,
      "name": "Empty",
      "level": 0
    },
    {
      "x": -1,
      "y": 3,
      "z": -1,
      "name": "Empty",
      "level": 0
    },
    {
      "x": -1,
      "y": 4,
      "z": -1,
      "name": "Empty",
      "level": 0
    },
    {
      "x": -1,
      "y": 5,
      "z": -1,
      "name": "Empty",
      "level": 0
    },
    {
      "x": -1,
      "y": 6,
      "z": -1,
      "name": "Empty",
      "level": 0
    },
    {
      "x": -1,
      "y": 7,
      "z": -1,
      "name": "Empty",
      "level": 0
    },
    {
      "x": -1,
      "y": 0,
      "z": 0,
      "name": "Empty",
      "level": 0
    },
    {
      "x": -1,
      "y": 1,
      "z": 0,
      "name": "Empty",
      "level": 0
    },
    {
      "x": -1,
      "y": 2,
      "z": 0,
      "name": "Empty",
      "level": 0
    },
    {
      "x": -1,
      "y": 3,
      "z": 0,
      "name": "Empty",
      "level": 0
    },
    {
      "x": -1,
      "y": 4,
      "z": 0,
      "name": "Empty",
      "level": 0
    },
    {
      "x": -1,
      "y": 5,
      "z": 0,
      "name": "Empty",
      "level": 0
    },
    {
      "x": -1,
      "y": 6,
      "z": 0,
      "name": "Empty",
      "level": 0
    },
    {
      "x": -1,
      "y": 7,
      "z": 0,
      "name": "Empty",
      "level": 0
    },
    {
      "x": -1,
      "y": 8,
      "z": 0,
      "name": "Empty",
      "level": 0
    },
    {
      "x": -1,
      "y": 0,
      "z": 1,
      "name": "Empty",
      "level": 0
    },
    {
      "x": -1,
      "y": 1,
      "z": 1,
      "name": "Empty",
      "level": 0
    },
    {
      "x": -1,
      "y": 2,
      "z": 1,
      "name": "Empty",
      "level": 0
    },
    {
      "x": -1,
      "y": 3,
      "z": 1,
      "name": "Empty",
      "level": 0
    },
    {
      "x": -1,
      "y": 4,
      "z": 1,
      "name": "Empty",
      "level": 0
    },
    {
      "x": -1,
      "y": 5,
      "z": 1,
      "name": "Empty",
      "level": 0
    },
    {
      "x": -1,
      "y": 6,
      "z": 1,
      "name": "Empty",
      "level": 0
    },
    {
      "x": -1,
      "y": 7,
      "z": 1,
      "name": "Empty",
      "level": 0
    },
    {
      "x": -1,
      "y": 0,
      "z": 2,
      "name": "Empty",
      "level": 0
    },
    {
      "x": -1,
      "y": 1,
      "z": 2,
      "name": "Empty",
      "level": 0
    },
    {
      "x": -1,
