{
  "version": 8,
  "blockIdVersion": 11,
  "anchorX": 0,
  "anchorY": 0,
  "anchorZ": 0,
  "blocks": [
    {
      "x": -19,
      "y": 0,
      "z": -19,
      "name": "Empty"
    },
    {
      "x": -19,
      "y": 1,
      "z": -19,
      "name": "Empty"
    },
    {
      "x": -19,
      "y": 2,
      "z": -19,
      "name": "Empty"
    },
    {
      "x": -19,
      "y": 3,
      "z": -19,
      "name": "Empty"
    },
    {
      "x": -19,
      "y": 4,
      "z": -19,
      "name": "Empty"
    },
    {
      "x": -19,
      "y": 0,
      "z": -18,
      "name": "Empty"
    },
    {
      "x": -19,
      "y": 1,
      "z": -18,
      "name": "Empty"
    },
    {
      "x": -19,
      "y": 2,
      "z": -18,
      "name": "Empty"
    },
    {
      "x": -19,
      "y": 3,
      "z": -18,
      "name": "Empty"
    },
    {
      "x": -19,
      "y": 4,
      "z": -18,
      "name": "Empty"
    },
    {
      "x": -19,
      "y": 0,
      "z": -17,
      "name": "Empty"
    },
    {
      "x": -19,
      "y": 1,
      "z": -17,
      "name": "Empty"
    },
    {
      "x": -19,
      "y": 2,
      "z": -17,
      "name": "Empty"
    },
    {
      "x": -19,
      "y": 3,
      "z": -17,
      "name": "Empty"
    },
    {
      "x": -19,
      "y": 4,
      "z": -17,
      "name": "Empty"
    },
    {
      "x": -19,
      "y": 0,
      "z": -16,
      "name": "Empty"
    },
    {
      "x": -19,
      "y": 1,
      "z": -16,
      "name": "Empty"
    },
    {
      "x": -19,
      "y": 2,
      "z": -16,
      "name": "Empty"
    },
    {
      "x": -19,
      "y": 3,
      "z": -16,
      "name": "Empty"
    },
    {
      "x": -19,
      "y": 4,
      "z": -16,
      "name": "Empty"
    },
    {
      "x": -19,
      "y": 0,
      "z": -15,
      "name": "Empty"
    },
    {
      "x": -19,
      "y": 1,
      "z": -15,
      "name": "Empty"
    },
    {
      "x": -19,
      "y": 2,
      "z": -15,
      "name": "Empty"
    },
    {
      "x": -19,
      "y": 3,
      "z": -15,
      "name": "Empty"
    },
    {
      "x": -19,
      "y": 4,
      "z": -15,
      "name": "Empty"
    },
    {
      "x": -19,
      "y": 0,
      "z": -14,
      "name": "Empty"
    },
    {
      "x": -19,
      "y": 1,
      "z": -14,
      "name": "Empty"
    },
    {
      "x": -19,
      "y": 2,
      "z": -14,
      "name": "Empty"
    },
    {
      "x": -19,
      "y": 3,
      "z": -14,
      "name": "Empty"
    },
    {
      "x": -19,
      "y": 4,
      "z": -14,
      "name": "Empty"
    },
    {
      "x": -19,
      "y": 0,
      "z": -13,
      "name": "Empty"
    },
    {
      "x": -19,
      "y": 1,
      "z": -13,
      "name": "Empty"
    },
    {
      "x": -19,
      "y": 2,
      "z": -13,
      "name": "Empty"
    },
    {
      "x": -19,
      "y": 3,
      "z": -13,
      "name": "Empty"
    },
    {
      "x": -19,
      "y": 4,
      "z": -13,
      "name": "Empty"
    },
    {
      "x": -19,
      "y": 0,
      "z": -12,
      "name": "Empty"
    },
    {
      "x": -19,
      "y": 1,
      "z": -12,
      "name": "Empty"
    },
    {
      "x": -19,
      "y": 2,
      "z": -12,
      "name": "Empty"
    },
    {
      "x": -19,
      "y": 3,
      "z": -12,
      "name": "Empty"
    },
    {
      "x": -19,
      "y": 4,
      "z": -12,
      "name": "Empty"
    },
    {
      "x": -19,
      "y": 0,
      "z": -11,
      "name": "Empty"
    },
    {
      "x": -19,
      "y": 1,
      "z": -11,
      "name": "Empty"
    },
    {
      "x": -19,
      "y": 2,
      "z": -11,
      "name": "Empty"
    },
    {
      "x": -19,
      "y": 3,
      "z": -11,
      "name": "Empty"
    },
    {
      "x": -19,
      "y": 4,
      "z": -11,
      "name": "Empty"
    },
    {
      "x": -19,
      "y": 0,
      "z": -10,
      "name": "Empty"
    },
    {
      "x": -19,
      "y": 1,
      "z": -10,
      "name": "Empty"
    },
    {
      "x": -19,
      "y": 2,
      "z": -10,
      "name": "Empty"
    },
    {
      "x": -19,
      "y": 3,
      "z": -10,
      "name": "Empty"
    },
    {
      "x": -19,
      "y": 4,
      "z": -10,
      "name": "Empty"
    },
    {
      "x": -19,
      "y": 0,
      "z": -9,
      "name": "Empty"
    },
    {
      "x": -19,
      "y": 1,
      "z": -9,
      "name": "Empty"
    },
    {
      "x": -19,
      "y": 2,
      "z": -9,
      "name": "Empty"
    },
    {
      "x": -19,
      "y": 3,
      "z": -9,
      "name": "Empty"
    },
    {
      "x": -19,
      "y": 4,
      "z": -9,
      "name": "Empty"
    },
    {
      "x": -19,
      "y": 0,
      "z": -8,
      "name": "Empty"
    },
    {
      "x": -19,
      "y": 1,
      "z": -8,
      "name": "Empty"
    },
    {
      "x": -19,
      "y": 2,
      "z": -8,
      "name": "Empty"
    },
    {
      "x": -19,
      "y": 3,
      "z": -8,
      "name": "Empty"
    },
    {
      "x": -19,
      "y": 4,
      "z": -8,
      "name": "Empty"
    },
    {
      "x": -19,
      "y": 0,
      "z": -7,
      "name": "Empty"
    },
    {
      "x": -19,
      "y": 1,
      "z": -7,
      "name": "Empty"
    },
    {
      "x": -19,
      "y": 2,
      "z": -7,
      "name": "Empty"
    },
    {
      "x": -19,
      "y": 3,
      "z": -7,
      "name": "Empty"
    },
    {
      "x": -19,
      "y": 4,
      "z": -7,
      "name": "Empty"
    },
    {
      "x": -19,
      "y": 0,
      "z": -6,
      "name": "Empty"
    },
    {
      "x": -19,
      "y": 1,
      "z": -6,
      "name": "Empty"
    },
    {
      "x": -19,
      "y": 2,
      "z": -6,
      "name": "Empty"
    },
    {
      "x": -19,
      "y": 3,
      "z": -6,
      "name": "Empty"
    },
    {
      "x": -19,
      "y": 4,
      "z": -6,
      "name": "Empty"
    },
    {
      "x": -19,
      "y": 0,
      "z": -5,
      "name": "Empty"
    },
    {
      "x": -19,
      "y": 1,
      "z": -5,
      "name": "Empty"
    },
    {
      "x": -19,
      "y": 2,
      "z": -5,
      "name": "Empty"
    },
    {
      "x": -19,
      "y": 3,
      "z": -5,
      "name": "Empty"
    },
    {
      "x": -19,
      "y": 4,
      "z": -5,
      "name": "Empty"
    },
    {
      "x": -19,
      "y": 0,
      "z": -4,
      "name": "Empty"
    },
    {
      "x": -19,
      "y": 1,
      "z": -4,
      "name": "Empty"
    },
    {
      "x": -19,
      "y": 2,
      "z": -4,
      "name": "Empty"
    },
    {
      "x": -19,
      "y": 3,
      "z": -4,
      "name": "Empty"
    },
    {
      "x": -19,
      "y": 4,
      "z": -4,
      "name": "Empty"
    },
    {
      "x": -19,
      "y": 0,
      "z": -3,
      "name": "Rock_Sandstone_White_Brick"
    },
    {
      "x": -19,
      "y": 1,
      "z": -3,
      "name": "Rock_Sandstone_White_Brick"
    },
    {
      "x": -19,
      "y": 2,
      "z": -3,
      "name": "Rock_Sandstone_White_Brick"
    },
    {
      "x": -19,
      "y": 3,
      "z": -3,
      "name": "Rock_Sandstone_White_Brick"
    },
    {
      "x": -19,
      "y": 4,
      "z": -3,
      "name": "Empty"
    },
    {
      "x": -19,
      "y": 0,
      "z": -2,
      "name": "Rock_Sandstone_White_Brick_Smooth_Half",
      "rotation": 4
    },
    {
      "x": -19,
      "y": 1,
      "z": -2,
      "name": "Rock_Sandstone_White_Brick_Half",
      "rotation": 4
    },
    {
      "x": -19,
      "y": 2,
      "z": -2,
      "name": "Rock_Sandstone_White_Brick_Half",
      "rotation": 4
    },
    {
      "x": -19,
      "y": 3,
      "z": -2,
      "name": "Rock_Sandstone_White_Brick"
    },
    {
      "x": -19,
      "y": 4,
      "z": -2,
      "name": "Rock_Sandstone_White_Brick_Half"
    },
    {
      "x": -19,
      "y": 0,
      "z": -1,
      "name": "Empty"
    },
    {
      "x": -19,
      "y": 1,
      "z": -1,
      "name": "Empty"
    },
    {
      "x": -19,
      "y": 2,
      "z": -1,
      "name": "Empty"
    },
    {
      "x": -19,
      "y": 3,
      "z": -1,
      "name": "Rock_Sandstone_White_Brick_Smooth_Half",
      "rotation": 8
    },
    {
      "x": -19,
      "y": 4,
      "z": -1,
      "name": "Rock_Sandstone_White_Brick"
    },
    {
      "x": -19,
      "y": 0,
      "z": 0,
      "name": "Empty"
    },
    {
      "x": -19,
      "y": 1,
      "z": 0,
      "name": "Empty"
    },
    {
      "x": -19,
      "y": 2,
      "z": 0,
      "name": "Empty"
    },
    {
      "x": -19,
      "y": 3,
      "z": 0,
      "name": "Rock_Sandstone_White_Brick_Smooth_Half",
      "rotation": 8
    },
    {
      "x": -19,
      "y": 4,
      "z": 0,
      "name": "Rock_Sandstone_White_Brick"
    },
    {
      "x": -19,
      "y": 0,
      "z": 1,
      "name": "Empty"
    },
    {
      "x": -19,
      "y": 1,
      "z": 1,
      "name": "Empty"
    },
    {
      "x": -19,
      "y": 2,
      "z": 1,
      "name": "Empty"
    },
    {
      "x": -19,
      "y": 3,
      "z": 1,
      "name": "Rock_Sandstone_White_Brick_Half",
      "rotation": 8
    },
    {
      "x": -19,
      "y": 4,
      "z": 1,
      "name": "Rock_Sandstone_White_Brick"
    },
    {
      "x": -19,
      "y": 0,
      "z": 2,
      "name": "Rock_Sandstone_White_Brick_Half",
      "rotation": 6
    },
    {
      "x": -19,
      "y": 1,
      "z": 2,
      "name": "Rock_Sandstone_White_Brick_Smooth_Half",
      "rotation": 6
    },
    {
      "x": -19,
      "y": 2,
      "z": 2,
      "name": "Rock_Sandstone_White_Brick_Smooth_Half",
      "rotation": 6
    },
    {
      "x": -19,
      "y": 3,
      "z": 2,
      "name": "Rock_Sandstone_White_Brick"
    },
    {
      "x": -19,
      "y": 4,
      "z": 2,
      "name": "Rock_Sandstone_White_Brick_Smooth_Half"
    },
    {
      "x": -19,
      "y": 0,
      "z": 3,
      "name": "Rock_Sandstone_White_Brick"
    },
    {
      "x": -19,
      "y": 1,
      "z": 3,
      "name": "Rock_Sandstone_White_Brick"
    },
    {
      "x": -19,
      "y": 2,
      "z": 3,
      "name": "Rock_Sandstone_White_Brick"
    },
    {
      "x": -19,
      "y": 3,
      "z": 3,
      "name": "Rock_Sandstone_White_Brick"
    },
    {
      "x": -19,
      "y": 4,
      "z": 3,
      "name": "Empty"
    },
    {
      "x": -19,
      "y": 0,
      "z": 4,
      "name": "Empty"
    },
    {
      "x": -19,
      "y": 1,
      "z": 4,
      "name": "Empty"
    },
    {
      "x": -19,
      "y": 2,
      "z": 4,
      "name": "Empty"
    },
    {
      "x": -19,
      "y": 3,
      "z": 4,
      "name": "Empty"
    },
    {
      "x": -19,
      "y": 4,
      "z": 4,
      "name": "Empty"
    },
    {
      "x": -19,
      "y": 0,
      "z": 5,
      "name": "Empty"
    },
    {
      "x": -19,
      "y": 1,
      "z": 5,
      "name": "Empty"
    },
    {
      "x": -19,
      "y": 2,
      "z": 5,
      "name": "Empty"
    },
    {
      "x": -19,
      "y": 3,
      "z": 5,
      "name": "Empty"
    },
    {
      "x": -19,
      "y": 4,
      "z": 5,
      "name": "Empty"
    },
    {
      "x": -19,
      "y": 0,
      "z": 6,
      "name": "Empty"
    },
    {
      "x": -19,
      "y": 1,
      "z": 6,
      "name": "Empty"
    },
    {
      "x": -19,
      "y": 2,
      "z": 6,
      "name": "Empty"
    },
    {
      "x": -19,
      "y": 3,
      "z": 6,
      "name": "Empty"
    },
    {
      "x": -19,
      "y": 4,
      "z": 6,
      "name": "Empty"
    },
    {
      "x": -19,
      "y": 0,
      "z": 7,
      "name": "Empty"
    },
    {
      "x": -19,
      "y": 1,
      "z": 7,
      "name": "Empty"
    },
    {
      "x": -19,
      "y": 2,
      "z": 7,
      "name": "Empty"
    },
    {
      "x": -19,
      "y": 3,
      "z": 7,
      "name": "Empty"
    },
    {
      "x": -19,
      "y": 4,
      "z": 7,
      "name": "Empty"
    },
    {
      "x": -19,
      "y": 0,
      "z": 8,
      "name": "Empty"
    },
    {
      "x": -19,
      "y": 1,
      "z": 8,
      "name": "Empty"
    },
    {
      "x": -19,
      "y": 2,
      "z": 8,
      "name": "Empty"
    },
    {
      "x": -19,
      "y": 3,
      "z": 8,
      "name": "Empty"
    },
    {
      "x": -19,
      "y": 4,
      "z": 8,
      "name": "Empty"
    },
    {
      "x": -19,
      "y": 0,
      "z": 9,
      "name": "Empty"
    },
    {
      "x": -19,
      "y": 1,
      "z": 9,
      "name": "Empty"
    },
    {
      "x": -19,
      "y": 2,
      "z": 9,
      "name": "Empty"
    },
    {
      "x": -19,
      "y": 3,
      "z": 9,
      "name": "Empty"
    },
    {
      "x": -19,
      "y": 4,
      "z": 9,
      "name": "Empty"
    },
    {
      "x": -19,
      "y": 0,
      "z": 10,
      "name": "Empty"
    },
    {
      "x": -19,
      "y": 1,
      "z": 10,
      "name": "Empty"
    },
    {
      "x": -19,
      "y": 2,
      "z": 10,
      "name": "Empty"
    },
    {
      "x": -19,
      "y": 3,
      "z": 10,
      "name": "Empty"
    },
    {
      "x": -19,
      "y": 4,
      "z": 10,
      "name": "Empty"
    },
    {
      "x": -19,
      "y": 0,
      "z": 11,
      "name": "Empty"
    },
    {
      "x": -19,
      "y": 1,
      "z": 11,
      "name": "Empty"
    },
    {
      "x": -19,
      "y": 2,
      "z": 11,
      "name": "Empty"
    },
    {
      "x": -19,
      "y": 3,
      "z": 11,
      "name": "Empty"
    },
    {
      "x": -19,
      "y": 4,
      "z": 11,
      "name": "Empty"
    },
    {
      "x": -19,
      "y": 0,
      "z": 12,
      "name": "Empty"
    },
    {
      "x": -19,
      "y": 1,
      "z": 12,
      "name": "Empty"
    },
    {
      "x": -19,
      "y": 2,
      "z": 12,
      "name": "Empty"
    },
    {
      "x": -19,
      "y": 3,
      "z": 12,
      "name": "Empty"
    },
    {
      "x": -19,
      "y": 4,
      "z": 12,
      "name": "Empty"
    },
    {
      "x": -19,
      "y": 0,
      "z": 13,
      "name": "Empty"
    },
    {
      "x": -19,
      "y": 1,
      "z": 13,
      "name": "Empty"
    },
    {
      "x": -19,
      "y": 2,
      "z": 13,
      "name": "Empty"
    },
    {
      "x": -19,
      "y": 3,
      "z": 13,
      "name": "Empty"
    },
    {
      "x": -19,
      "y": 4,
      "z": 13,
      "name": "Empty"
    },
    {
      "x": -19,
      "y": 0,
      "z": 14,
      "name": "Empty"
    },
    {
      "x": -19,
      "y": 1,
      "z": 14,
      "name": "Empty"
    },
    {
      "x": -19,
      "y": 2,
      "z": 14,
      "name": "Empty"
    },
    {
      "x": -19,
      "y": 3,
      "z": 14,
      "name": "Empty"
    },
    {
      "x": -19,
      "y": 4,
      "z": 14,
      "name": "Empty"
    },
    {
      "x": -19,
      "y": 0,
      "z": 15,
      "name": "Empty"
    },
    {
      "x": -19,
      "y": 1,
      "z": 15,
      "name": "Empty"
    },
    {
      "x": -19,
      "y": 2,
      "z": 15,
      "name": "Empty"
    },
    {
      "x": -19,
      "y": 3,
      "z": 15,
      "name": "Empty"
    },
    {
      "x": -19,
      "y": 4,
      "z": 15,
      "name": "Empty"
    },
    {
      "x": -19,
      "y": 0,
      "z": 16,
      "name": "Empty"
    },
    {
      "x": -19,
      "y": 1,
      "z": 16,
      "name": "Empty"
    },
    {
      "x": -19,
      "y": 2,
      "z": 16,
      "name": "Empty"
    },
    {
      "x": -19,
      "y": 3,
      "z": 16,
      "name": "Empty"
    },
    {
      "x": -19,
      "y": 4,
      "z": 16,
      "name": "Empty"
    },
    {
      "x": -19,
      "y": 0,
      "z": 17,
      "name": "Empty"
    },
    {
      "x": -19,
      "y": 1,
      "z": 17,
      "name": "Empty"
    },
    {
      "x": -19,
      "y": 2,
      "z": 17,
      "name": "Empty"
    },
    {
      "x": -19,
      "y": 3,
      "z": 17,
      "name": "Empty"
    },
    {
      "x": -19,
      "y": 4,
      "z": 17,
      "name": "Empty"
    },
    {
      "x": -19,
      "y": 0,
      "z": 18,
      "name": "Empty"
    },
    {
      "x": -19,
      "y": 1,
      "z": 18,
      "name": "Empty"
    },
    {
      "x": -19,
      "y": 2,
      "z": 18,
      "name": "Empty"
    },
    {
      "x": -19,
      "y": 3,
      "z": 18,
      "name": "Empty"
    },
    {
      "x": -19,
      "y": 4,
      "z": 18,
      "name": "Empty"
    },
    {
      "x": -19,
      "y": 0,
      "z": 19,
      "name": "Empty"
    },
    {
      "x": -19,
      "y": 1,
      "z": 19,
      "name": "Empty"
    },
    {
      "x": -19,
      "y": 2,
      "z": 19,
      "name": "Empty"
    },
    {
      "x": -19,
      "y": 3,
      "z": 19,
      "name": "Empty"
    },
    {
      "x": -19,
      "y": 4,
      "z": 19,
      "name": "Empty"
    },
    {
      "x": -19,
      "y": 0,
      "z": 20,
      "name": "Empty"
    },
    {
      "x": -19,
      "y": 1,
      "z": 20,
      "name": "Empty"
    },
    {
      "x": -19,
      "y": 2,
      "z": 20,
      "name": "Empty"
    },
    {
      "x": -19,
      "y": 3,
      "z": 20,
      "name": "Empty"
    },
    {
      "x": -19,
      "y": 4,
      "z": 20,
      "name": "Empty"
    },
    {
      "x": -18,
      "y": 0,
      "z": -19,
      "name": "Empty"
    },
    {
      "x": -18,
      "y": 1,
      "z": -19,
      "name": "Empty"
    },
    {
      "x": -18,
      "y": 2,
      "z": -19,
      "name": "Empty"
    },
    {
      "x": -18,
      "y": 3,
      "z": -19,
      "name": "Empty"
    },
    {
      "x": -18,
      "y": 4,
      "z": -19,
      "name": "Empty"
    },
    {
      "x": -18,
      "y": 0,
      "z": -18,
      "name": "Rock_Sandstone_White_Brick",
      "rotation": 3
    },
    {
      "x": -18,
      "y": 1,
      "z": -18,
      "name": "Rock_Sandstone_White_Brick",
      "rotation": 3
    },
    {
      "x": -18,
      "y": 2,
      "z": -18,
      "name": "Rock_Sandstone_White",
      "rotation": 3
    },
    {
      "x": -18,
      "y": 3,
      "z": -18,
      "name": "Rock_Sandstone_White_Brick",
      "rotation": 3
    },
    {
      "x": -18,
      "y": 4,
      "z": -18,
      "name": "Rock_Sandstone_White_Brick",
      "rotation": 3
    },
    {
      "x": -18,
      "y": 0,
      "z": -17,
      "name": "Rock_Sandstone_White_Brick",
      "rotation": 3
    },
    {
      "x": -18,
      "y": 1,
      "z": -17,
      "name": "Rock_Sandstone_White",
      "rotation": 3
    },
    {
      "x": -18,
      "y": 2,
      "z": -17,
      "name": "Rock_Sandstone_White",
      "rotation": 3
    },
    {
      "x": -18,
      "y": 3,
      "z": -17,
      "name": "Rock_Sandstone_White_Brick",
      "rotation": 3
    },
    {
      "x": -18,
      "y": 4,
      "z": -17,
      "name": "Rock_Sandstone_White_Brick",
      "rotation": 3
    },
    {
      "x": -18,
      "y": 0,
      "z": -16,
      "name": "Rock_Sandstone_White",
      "rotation": 3
    },
    {
      "x": -18,
      "y": 1,
      "z": -16,
      "name": "Rock_Sandstone_White_Brick",
      "rotation": 3
    },
    {
      "x": -18,
      "y": 2,
      "z": -16,
      "name": "Rock_Sandstone_White_Brick",
      "rotation": 3
    },
    {
      "x": -18,
      "y": 3,
      "z": -16,
      "name": "Rock_Sandstone_White_Brick",
      "rotation": 3
    },
    {
      "x": -18,
      "y": 4,
      "z": -16,
      "name": "Rock_Sandstone_White_Brick",
      "rotation": 3
    },
    {
      "x": -18,
      "y": 0,
      "z": -15,
      "name": "Rock_Sandstone_White",
      "rotation": 3
    },
    {
      "x": -18,
      "y": 1,
      "z": -15,
      "name": "Rock_Sandstone_White_Brick",
      "rotation": 3
    },
    {
      "x": -18,
      "y": 2,
      "z": -15,
      "name": "Rock_Sandstone_White_Brick",
      "rotation": 3
    },
    {
      "x": -18,
      "y": 3,
      "z": -15,
      "name": "Rock_Sandstone_White_Brick",
      "rotation": 3
    },
    {
      "x": -18,
      "y": 4,
      "z": -15,
      "name": "Rock_Sandstone_White_Brick",
      "rotation": 3
    },
    {
      "x": -18,
      "y": 0,
      "z": -14,
      "name": "Rock_Sandstone_White",
      "rotation": 3
    },
    {
      "x": -18,
      "y": 1,
      "z": -14,
      "name": "Rock_Sandstone_White",
      "rotation": 3
    },
    {
      "x": -18,
      "y": 2,
      "z": -14,
      "name": "Rock_Sandstone_White",
      "rotation": 3
    },
    {
      "x": -18,
      "y": 3,
      "z": -14,
      "name": "Rock_Sandstone_White_Brick",
      "rotation": 3
    },
    {
      "x": -18,
      "y": 4,
      "z": -14,
      "name": "Rock_Sandstone_White_Brick",
      "rotation": 3
    },
    {
      "x": -18,
      "y": 0,
      "z": -13,
      "name": "Rock_Sandstone_White",
      "rotation": 3
    },
    {
      "x": -18,
      "y": 1,
      "z": -13,
      "name": "Rock_Sandstone_White",
      "rotation": 3
    },
    {
      "x": -18,
      "y": 2,
      "z": -13,
      "name": "Rock_Sandstone_White",
      "rotation": 3
    },
    {
      "x": -18,
      "y": 3,
      "z": -13,
      "name": "Rock_Sandstone_White_Brick",
      "rotation": 3
    },
    {
      "x": -18,
      "y": 4,
      "z": -13,
      "name": "Rock_Sandstone_White",
      "rotation": 3
    },
    {
      "x": -18,
      "y": 0,
      "z": -12,
      "name": "Rock_Sandstone_White_Brick",
      "rotation": 3
    },
    {
      "x": -18,
      "y": 1,
      "z": -12,
      "name": "Rock_Sandstone_White_Brick",
      "rotation": 3
    },
    {
      "x": -18,
      "y": 2,
      "z": -12,
      "name": "Rock_Sandstone_White_Brick",
      "rotation": 3
    },
    {
      "x": -18,
      "y": 3,
      "z": -12,
      "name": "Rock_Sandstone_White",
      "rotation": 3
    },
    {
      "x": -18,
      "y": 4,
      "z": -12,
      "name": "Rock_Sandstone_White_Brick",
      "rotation": 3
    },
    {
      "x": -18,
      "y": 0,
      "z": -11,
      "name": "Rock_Sandstone_White_Brick",
      "rotation": 3
    },
    {
      "x": -18,
      "y": 1,
      "z": -11,
      "name": "Rock_Sandstone_White_Brick",
      "rotation": 3
    },
    {
      "x": -18,
      "y": 2,
      "z": -11,
      "name": "Rock_Sandstone_White_Brick",
      "rotation": 3
    },
    {
      "x": -18,
      "y": 3,
      "z": -11,
      "name": "Rock_Sandstone_White",
      "rotation": 3
    },
    {
      "x": -18,
      "y": 4,
      "z": -11,
      "name": "Rock_Sandstone_White_Brick",
      "rotation": 3
    },
    {
      "x": -18,
      "y": 0,
      "z": -10,
      "name": "Rock_Sandstone_White",
      "rotation": 3
    },
    {
      "x": -18,
      "y": 1,
      "z": -10,
      "name": "Rock_Sandstone_White_Brick",
      "rotation": 3
    },
    {
      "x": -18,
      "y": 2,
      "z": -10,
      "name": "Rock_Sandstone_White_Brick",
      "rotation": 3
    },
    {
      "x": -18,
      "y": 3,
      "z": -10,
      "name": "Rock_Sandstone_White_Brick",
      "rotation": 3
    },
    {
      "x": -18,
      "y": 4,
      "z": -10,
      "name": "Rock_Sandstone_White_Brick",
      "rotation": 3
    },
    {
      "x": -18,
      "y": 0,
      "z": -9,
      "name": "Rock_Sandstone_White_Brick",
      "rotation": 3
    },
    {
      "x": -18,
      "y": 1,
      "z": -9,
      "name": "Rock_Sandstone_White",
      "rotation": 3
    },
    {
      "x": -18,
      "y": 2,
      "z": -9,
      "name": "Rock_Sandstone_White",
      "rotation": 3
    },
    {
      "x": -18,
      "y": 3,
      "z": -9,
      "name": "Rock_Sandstone_White_Brick",
      "rotation": 3
    },
    {
      "x": -18,
      "y": 4,
      "z": -9,
      "name": "Rock_Sandstone_White_Brick",
      "rotation": 3
    },
    {
      "x": -18,
      "y": 0,
      "z": -8,
      "name": "Rock_Sandstone_White",
      "rotation": 3
    },
    {
      "x": -18,
      "y": 1,
      "z": -8,
      "name": "Rock_Sandstone_White",
      "rotation": 3
    },
    {
      "x": -18,
      "y": 2,
      "z": -8,
      "name": "Rock_Sandstone_White",
      "rotation": 3
    },
    {
      "x": -18,
      "y": 3,
      "z": -8,
      "name": "Rock_Sandstone_White",
      "rotation": 3
    },
    {
      "x": -18,
      "y": 4,
      "z": -8,
      "name": "Rock_Sandstone_White_Brick",
      "rotation": 3
    },
    {
      "x": -18,
      "y": 0,
      "z": -7,
      "name": "Rock_Sandstone_White_Brick",
      "rotation": 3
    },
    {
      "x": -18,
      "y": 1,
      "z": -7,
      "name": "Rock_Sandstone_White_Brick",
      "rotation": 3
    },
    {
      "x": -18,
      "y": 2,
      "z": -7,
      "name": "Rock_Sandstone_White",
      "rotation": 3
    },
    {
      "x": -18,
      "y": 3,
      "z": -7,
      "name": "Rock_Sandstone_White_Brick",
      "rotation": 3
    },
    {
      "x": -18,
      "y": 4,
      "z": -7,
      "name": "Rock_Sandstone_White_Brick",
      "rotation": 3
    },
    {
      "x": -18,
      "y": 0,
      "z": -6,
      "name": "Rock_Sandstone_White_Brick",
      "rotation": 3
    },
    {
      "x": -18,
      "y": 1,
      "z": -6,
      "name": "Rock_Sandstone_White_Brick",
      "rotation": 3
    },
    {
      "x": -18,
      "y": 2,
      "z": -6,
      "name": "Rock_Sandstone_White_Brick",
      "rotation": 3
    },
    {
      "x": -18,
      "y": 3,
      "z": -6,
      "name": "Rock_Sandstone_White",
      "rotation": 3
    },
    {
      "x": -18,
      "y": 4,
      "z": -6,
      "name": "Rock_Sandstone_White_Brick",
      "rotation": 3
    },
    {
      "x": -18,
      "y": 0,
      "z": -5,
      "name": "Rock_Sandstone_White_Brick",
      "rotation": 3
    },
    {
      "x": -18,
      "y": 1,
      "z": -5,
      "name": "Rock_Sandstone_White_Brick",
      "rotation": 3
    },
    {
      "x": -18,
      "y": 2,
      "z": -5,
      "name": "Rock_Sandstone_White_Brick",
      "rotation": 3
    },
    {
      "x": -18,
      "y": 3,
      "z": -5,
      "name": "Rock_Sandstone_White",
      "rotation": 3
    },
    {
      "x": -18,
      "y": 4,
      "z": -5,
      "name": "Rock_Sandstone_White_Brick",
      "rotation": 3
    },
    {
      "x": -18,
      "y": 0,
      "z": -4,
      "name": "Rock_Sandstone_White",
      "rotation": 3
    },
    {
      "x": -18,
      "y": 1,
      "z": -4,
      "name": "Rock_Sandstone_White",
      "rotation": 3
    },
    {
      "x": -18,
      "y": 2,
      "z": -4,
      "name": "Rock_Sandstone_White",
      "rotation": 3
    },
    {
      "x": -18,
      "y": 3,
      "z": -4,
      "name": "Rock_Sandstone_White_Brick",
      "rotation": 3
    },
    {
      "x": -18,
      "y": 4,
      "z": -4,
      "name": "Rock_Sandstone_White",
      "rotation": 3
    },
    {
      "x": -18,
      "y": 0,
      "z": -3,
      "name": "Rock_Sandstone_White_Brick"
    },
    {
      "x": -18,
      "y": 1,
      "z": -3,
      "name": "Rock_Sandstone_White_Brick"
    },
    {
      "x": -18,
      "y": 2,
      "z": -3,
      "name": "Rock_Sandstone_White_Brick"
    },
    {
      "x": -18,
      "y": 3,
      "z": -3,
      "name": "Rock_Sandstone_White_Brick"
    },
    {
      "x": -18,
      "y": 4,
      "z": -3,
      "name": "Rock_Sandstone_White",
      "rotation": 3
    },
    {
      "x": -18,
      "y": 0,
      "z": -2,
      "name": "Rock_Sandstone_White_Brick_Smooth_Half",
      "rotation": 4
    },
    {
      "x": -18,
      "y": 1,
      "z": -2,
      "name": "Rock_Sandstone_White_Brick_Half",
      "rotation": 4
    },
    {
      "x": -18,
      "y": 2,
      "z": -2,
      "name": "Rock_Sandstone_White_Brick_Half",
      "rotation": 4
    },
    {
      "x": -18,
      "y": 3,
      "z": -2,
      "name": "Rock_Sandstone_White_Brick"
    },
    {
      "x": -18,
      "y": 4,
      "z": -2,
      "name": "Rock_Sandstone_White"
    },
    {
      "x": -18,
      "y": 0,
      "z": -1,
      "name": "Empty"
    },
    {
      "x": -18,
      "y": 1,
      "z": -1,
      "name": "Empty"
    },
    {
      "x": -18,
      "y": 2,
      "z": -1,
      "name": "Empty"
    },
    {
      "x": -18,
      "y": 3,
      "z": -1,
      "name": "Rock_Sandstone_White_Brick_Smooth_Half",
      "rotation": 8
    },
    {
      "x": -18,
      "y": 4,
      "z": -1,
      "name": "Rock_Sandstone_White_Brick"
    },
    {
      "x": -18,
      "y": 0,
      "z": 0,
      "name": "Empty"
    },
    {
      "x": -18,
      "y": 1,
      "z": 0,
      "name": "Empty"
    },
    {
      "x": -18,
      "y": 2,
      "z": 0,
      "name": "Empty"
    },
    {
      "x": -18,
      "y": 3,
      "z": 0,
      "name": "Rock_Sandstone_White_Brick_Smooth_Half",
      "rotation": 8
    },
    {
      "x": -18,
      "y": 4,
      "z": 0,
      "name": "Rock_Sandstone_White"
    },
    {
      "x": -18,
      "y": 0,
      "z": 1,
      "name": "Empty"
    },
    {
      "x": -18,
      "y": 1,
      "z": 1,
      "name": "Empty"
    },
    {
      "x": -18,
      "y": 2,
      "z": 1,
      "name": "Empty"
    },
    {
      "x": -18,
      "y": 3,
      "z": 1,
      "name": "Rock_Sandstone_White_Brick_Half",
      "rotation": 8
    },
    {
      "x": -18,
      "y": 4,
      "z": 1,
      "name": "Rock_Sandstone_White_Brick"
    },
    {
      "x": -18,
      "y": 0,
      "z": 2,
      "name": "Rock_Sandstone_White_Brick_Half",
      "rotation": 6
    },
    {
      "x": -18,
      "y": 1,
      "z": 2,
      "name": "Rock_Sandstone_White_Brick_Smooth_Half",
      "rotation": 6
    },
    {
      "x": -18,
      "y": 2,
      "z": 2,
      "name": "Rock_Sandstone_White_Brick_Smooth_Half",
      "rotation": 6
    },
    {
      "x": -18,
      "y": 3,
      "z": 2,
      "name": "Rock_Sandstone_White_Brick"
    },
    {
      "x": -18,
      "y": 4,
      "z": 2,
      "name": "Rock_Sandstone_White"
    },
    {
      "x": -18,
      "y": 0,
      "z": 3,
      "name": "Rock_Sandstone_White_Brick"
    },
    {
      "x": -18,
      "y": 1,
      "z": 3,
      "name": "Rock_Sandstone_White_Brick"
    },
    {
      "x": -18,
      "y": 2,
      "z": 3,
      "name": "Rock_Sandstone_White_Brick"
    },
    {
      "x": -18,
      "y": 3,
      "z": 3,
      "name": "Rock_Sandstone_White_Brick"
    },
    {
      "x": -18,
      "y": 4,
      "z": 3,
      "name": "Rock_Sandstone_White_Brick"
    },
    {
      "x": -18,
      "y": 0,
      "z": 4,
      "name": "Rock_Sandstone_White_Brick"
    },
    {
      "x": -18,
      "y": 1,
      "z": 4,
      "name": "Rock_Sandstone_White"
    },
    {
      "x": -18,
      "y": 2,
      "z": 4,
      "name": "Rock_Sandstone_White_Brick"
    },
    {
      "x": -18,
      "y": 3,
      "z": 4,
      "name": "Rock_Sandstone_White"
    },
    {
      "x": -18,
      "y": 4,
      "z": 4,
      "name": "Rock_Sandstone_White"
    },
    {
      "x": -18,
      "y": 0,
      "z": 5,
      "name": "Rock_Sandstone_White"
    },
    {
      "x": -18,
      "y": 1,
      "z": 5,
      "name": "Rock_Sandstone_White_Brick"
    },
    {
      "x": -18,
      "y": 2,
      "z": 5,
      "name": "Rock_Sandstone_White"
    },
    {
      "x": -18,
      "y": 3,
      "z": 5,
      "name": "Rock_Sandstone_White"
    },
    {
      "x": -18,
      "y": 4,
      "z": 5,
      "name": "Rock_Sandstone_White_Brick"
    },
    {
      "x": -18,
      "y": 0,
      "z": 6,
      "name": "Rock_Sandstone_White"
    },
    {
      "x": -18,
      "y": 1,
      "z": 6,
      "name": "Rock_Sandstone_White_Brick"
    },
    {
      "x": -18,
      "y": 2,
      "z": 6,
      "name": "Rock_Sandstone_White"
    },
    {
      "x": -18,
      "y": 3,
      "z": 6,
      "name": "Rock_Sandstone_White"
    },
    {
      "x": -18,
      "y": 4,
      "z": 6,
      "name": "Rock_Sandstone_White"
    },
    {
      "x": -18,
      "y": 0,
      "z": 7,
      "name": "Rock_Sandstone_White"
    },
    {
      "x": -18,
      "y": 1,
      "z": 7,
      "name": "Rock_Sandstone_White"
    },
    {
      "x": -18,
      "y": 2,
      "z": 7,
      "name": "Rock_Sandstone_White"
    },
    {
      "x": -18,
      "y": 3,
      "z": 7,
      "name": "Rock_Sandstone_White_Brick"
    },
    {
      "x": -18,
      "y": 4,
      "z": 7,
      "name": "Rock_Sandstone_White_Brick"
    },
    {
      "x": -18,
      "y": 0,
      "z": 8,
      "name": "Rock_Sandstone_White_Brick"
    },
    {
      "x": -18,
      "y": 1,
      "z": 8,
      "name": "Rock_Sandstone_White_Brick"
    },
    {
      "x": -18,
      "y": 2,
      "z": 8,
      "name": "Rock_Sandstone_White_Brick"
    },
    {
      "x": -18,
      "y": 3,
      "z": 8,
      "name": "Rock_Sandstone_White"
    },
    {
      "x": -18,
      "y": 4,
      "z": 8,
      "name": "Rock_Sandstone_White"
    },
    {
      "x": -18,
      "y": 0,
      "z": 9,
      "name": "Rock_Sandstone_White"
    },
    {
      "x": -18,
      "y": 1,
      "z": 9,
      "name": "Rock_Sandstone_White"
    },
    {
      "x": -18,
      "y": 2,
      "z": 9,
      "name": "Rock_Sandstone_White_Brick"
    },
    {
      "x": -18,
      "y": 3,
      "z": 9,
      "name": "Rock_Sandstone_White_Brick"
    },
    {
      "x": -18,
      "y": 4,
      "z": 9,
      "name": "Rock_Sandstone_White"
    },
    {
      "x": -18,
      "y": 0,
      "z": 10,
      "name": "Rock_Sandstone_White_Brick"
    },
    {
      "x": -18,
      "y": 1,
      "z": 10,
      "name": "Rock_Sandstone_White"
    },
    {
      "x": -18,
      "y": 2,
      "z": 10,
      "name": "Rock_Sandstone_White_Brick"
    },
    {
      "x": -18,
      "y": 3,
      "z": 10,
      "name": "Rock_Sandstone_White"
    },
    {
      "x": -18,
      "y": 4,
      "z": 10,
      "name": "Rock_Sandstone_White_Brick"
    },
    {
      "x": -18,
      "y": 0,
      "z": 11,
      "name": "Rock_Sandstone_White"
    },
    {
      "x": -18,
      "y": 1,
      "z": 11,
      "name": "Rock_Sandstone_White_Brick"
    },
    {
      "x": -18,
      "y": 2,
      "z": 11,
      "name": "Rock_Sandstone_White"
    },
    {
      "x": -18,
      "y": 3,
      "z": 11,
      "name": "Rock_Sandstone_White_Brick"
    },
    {
      "x": -18,
      "y": 4,
      "z": 11,
      "name": "Rock_Sandstone_White_Brick"
    },
    {
      "x": -18,
      "y": 0,
      "z": 12,
      "name": "Rock_Sandstone_White_Brick"
    },
    {
      "x": -18,
      "y": 1,
      "z": 12,
      "name": "Rock_Sandstone_White"
    },
    {
      "x": -18,
      "y": 2,
      "z": 12,
      "name": "Rock_Sandstone_White"
    },
    {
      "x": -18,
      "y": 3,
      "z": 12,
      "name": "Rock_Sandstone_White"
    },
    {
      "x": -18,
      "y": 4,
      "z": 12,
      "name": "Rock_Sandstone_White_Brick"
    },
    {
      "x": -18,
      "y": 0,
      "z": 13,
      "name": "Rock_Sandstone_White"
    },
    {
      "x": -18,
      "y": 1,
      "z": 13,
      "name": "Rock_Sandstone_White"
    },
    {
      "x": -18,
      "y": 2,
      "z": 13,
      "name": "Rock_Sandstone_White_Brick"
    },
    {
      "x": -18,
      "y": 3,
      "z": 13,
      "name": "Rock_Sandstone_White"
    },
    {
      "x": -18,
      "y": 4,
      "z": 13,
      "name": "Rock_Sandstone_White"
    },
    {
      "x": -18,
      "y": 0,
      "z": 14,
      "name": "Rock_Sandstone_White_Brick"
    },
    {
      "x": -18,
      "y": 1,
      "z": 14,
      "name": "Rock_Sandstone_White"
    },
    {
      "x": -18,
      "y": 2,
      "z": 14,
      "name": "Rock_Sandstone_White_Brick"
    },
    {
      "x": -18,
      "y": 3,
      "z": 14,
      "name": "Rock_Sandstone_White"
    },
    {
      "x": -18,
      "y": 4,
      "z": 14,
      "name": "Rock_Sandstone_White_Brick"
    },
    {
      "x": -18,
      "y": 0,
      "z": 15,
      "name": "Rock_Sandstone_White_Brick"
    },
    {
      "x": -18,
      "y": 1,
      "z": 15,
      "name": "Rock_Sandstone_White"
    },
    {
      "x": -18,
      "y": 2,
      "z": 15,
      "name": "Rock_Sandstone_White_Brick"
    },
    {
      "x": -18,
      "y": 3,
      "z": 15,
      "name": "Rock_Sandstone_White_Brick"
    },
    {
      "x": -18,
      "y": 4,
      "z": 15,
      "name": "Rock_Sandstone_White"
    },
    {
      "x": -18,
      "y": 0,
      "z": 16,
      "name": "Rock_Sandstone_White_Brick"
    },
    {
      "x": -18,
      "y": 1,
      "z": 16,
      "name": "Rock_Sandstone_White"
    },
    {
      "x": -18,
      "y": 2,
      "z": 16,
      "name": "Rock_Sandstone_White_Brick"
    },
    {
      "x": -18,
      "y": 3,
      "z": 16,
      "name": "Rock_Sandstone_White"
    },
    {
      "x": -18,
      "y": 4,
      "z": 16,
      "name": "Rock_Sandstone_White_Brick"
    },
    {
      "x": -18,
      "y": 0,
      "z": 17,
      "name": "Rock_Sandstone_White"
    },
    {
      "x": -18,
      "y": 1,
      "z": 17,
      "name": "Rock_Sandstone_White_Brick"
    },
    {
      "x": -18,
      "y": 2,
      "z": 17,
      "name": "Rock_Sandstone_White_Brick"
    },
    {
      "x": -18,
      "y": 3,
      "z": 17,
      "name": "Rock_Sandstone_White_Brick"
    },
    {
      "x": -18,
      "y": 4,
      "z": 17,
      "name": "Rock_Sandstone_White_Brick"
    },
    {
      "x": -18,
      "y": 0,
      "z": 18,
      "name": "Rock_Sandstone_White_Brick"
    },
    {
      "x": -18,
      "y": 1,
      "z": 18,
      "name": "Rock_Sandstone_White"
    },
    {
      "x": -18,
      "y": 2,
      "z": 18,
      "name": "Rock_Sandstone_White"
    },
    {
      "x": -18,
      "y": 3,
      "z": 18,
      "name": "Rock_Sandstone_White_Brick"
    },
    {
      "x": -18,
      "y": 4,
      "z": 18,
      "name": "Rock_Sandstone_White_Brick"
    },
    {
      "x": -18,
      "y": 0,
      "z": 19,
      "name": "Rock_Sandstone_White_Brick"
    },
    {
      "x": -18,
      "y": 1,
      "z": 19,
      "name": "Rock_Sandstone_White_Brick"
    },
    {
      "x": -18,
      "y": 2,
      "z": 19,
      "name": "Rock_Sandstone_White"
    },
    {
      "x": -18,
      "y": 3,
      "z": 19,
      "name": "Rock_Sandstone_White_Brick"
    },
    {
      "x": -18,
      "y": 4,
      "z": 19,
      "name": "Rock_Sandstone_White_Brick"
    },
    {
      "x": -18,
      "y": 0,
      "z": 20,
      "name": "Empty"
    },
    {
      "x": -18,
      "y": 1,
      "z": 20,
      "name": "Empty"
    },
    {
      "x": -18,
      "y": 2,
      "z": 20,
      "name": "Empty"
    },
    {
      "x": -18,
      "y": 3,
      "z": 20,
      "name": "Empty"
    },
    {
      "x": -18,
      "y": 4,
      "z": 20,
      "name": "Empty"
    },
    {
      "x": -17,
      "y": 0,
      "z": -19,
      "name": "Empty"
    },
    {
      "x": -17,
      "y": 1,
      "z": -19,
      "name": "Empty"
    },
    {
      "x": -17,
      "y": 2,
      "z": -19,
      "name": "Empty"
    },
    {
      "x": -17,
      "y": 3,
      "z": -19,
      "name": "Empty"
    },
    {
      "x": -17,
      "y": 4,
      "z": -19,
      "name": "Empty"
    },
    {
      "x": -17,
      "y": 0,
      "z": -18,
      "name": "Rock_Sandstone_White_Brick",
      "rotation": 3
    },
    {
      "x": -17,
      "y": 1,
      "z": -18,
      "name": "Rock_Sandstone_White",
      "rotation": 3
    },
    {
      "x": -17,
      "y": 2,
      "z": -18,
      "name": "Rock_Sandstone_White",
      "rotation": 3
    },
    {
      "x": -17,
      "y": 3,
      "z": -18,
      "name": "Rock_Sandstone_White_Brick",
      "rotation": 3
    },
    {
      "x": -17,
      "y": 4,
      "z": -18,
      "name": "Rock_Sandstone_White_Brick",
      "rotation": 3
    },
    {
      "x": -17,
      "y": 0,
      "z": -17,
      "name": "Rock_Sandstone_White_Brick",
      "rotation": 3
    },
    {
      "x": -17,
      "y": 1,
      "z": -17,
      "name": "Rock_Sandstone_White",
      "rotation": 3
    },
    {
      "x": -17,
      "y": 2,
      "z": -17,
      "name": "Rock_Sandstone_White_Brick",
      "rotation": 3
    },
    {
      "x": -17,
      "y": 3,
      "z": -17,
      "name": "Rock_Sandstone_White_Brick",
      "rotation": 3
    },
    {
      "x": -17,
      "y": 4,
      "z": -17,
      "name": "Rock_Sandstone_White",
      "rotation": 3
    },
    {
      "x": -17,
      "y": 0,
      "z": -16,
      "name": "Rock_Sandstone_White",
      "rotation": 3
    },
    {
      "x": -17,
      "y": 1,
      "z": -16,
      "name": "Rock_Sandstone_White_Brick",
      "rotation": 3
    },
    {
      "x": -17,
      "y": 2,
      "z": -16,
      "name": "Rock_Sandstone_White_Brick",
      "rotation": 3
    },
    {
      "x": -17,
      "y": 3,
      "z": -16,
      "name": "Rock_Sandstone_White_Brick",
      "rotation": 3
    },
    {
      "x": -17,
      "y": 4,
      "z": -16,
      "name": "Rock_Sandstone_White",
      "rotation": 3
    },
    {
      "x": -17,
      "y": 0,
      "z": -15,
      "name": "Rock_Sandstone_White",
      "rotation": 3
    },
    {
      "x": -17,
      "y": 1,
      "z": -15,
      "name": "Rock_Sandstone_White_Brick",
      "rotation": 3
    },
    {
      "x": -17,
      "y": 2,
      "z": -15,
      "name": "Rock_Sandstone_White_Brick",
      "rotation": 3
    },
    {
      "x": -17,
      "y": 3,
      "z": -15,
      "name": "Rock_Sandstone_White_Brick",
      "rotation": 3
    },
    {
      "x": -17,
      "y": 4,
      "z": -15,
      "name": "Rock_Sandstone_White_Brick",
      "rotation": 3
    },
    {
      "x": -17,
      "y": 0,
      "z": -14,
      "name": "Rock_Sandstone_White_Brick",
      "rotation": 3
    },
    {
      "x": -17,
      "y": 1,
      "z": -14,
      "name": "Rock_Sandstone_White",
      "rotation": 3
    },
    {
      "x": -17,
      "y": 2,
      "z": -14,
      "name": "Rock_Sandstone_White_Brick",
      "rotation": 3
    },
    {
      "x": -17,
      "y": 3,
      "z": -14,
      "name": "Rock_Sandstone_White_Brick",
      "rotation": 3
    },
    {
      "x": -17,
      "y": 4,
      "z": -14,
      "name": "Rock_Sandstone_White",
      "rotation": 3
    },
    {
      "x": -17,
      "y": 0,
      "z": -13,
      "name": "Rock_Sandstone_White_Brick",
      "rotation": 3
    },
    {
      "x": -17,
      "y": 1,
      "z": -13,
      "name": "Rock_Sandstone_White_Brick",
      "rotation": 3
    },
    {
      "x": -17,
      "y": 2,
      "z": -13,
      "name": "Rock_Sandstone_White",
      "rotation": 3
    },
    {
      "x": -17,
      "y": 3,
      "z": -13,
      "name": "Rock_Sandstone_White_Brick",
      "rotation": 3
    },
    {
      "x": -17,
      "y": 4,
      "z": -13,
      "name": "Rock_Sandstone_White_Brick",
      "rotation": 3
    },
    {
      "x": -17,
      "y": 0,
      "z": -12,
      "name": "Rock_Sandstone_White_Brick",
      "rotation": 3
    },
    {
      "x": -17,
      "y": 1,
      "z": -12,
      "name": "Rock_Sandstone_White_Brick",
      "rotation": 3
    },
    {
      "x": -17,
      "y": 2,
      "z": -12,
      "name": "Rock_Sandstone_White",
      "rotation": 3
    },
    {
      "x": -17,
      "y": 3,
      "z": -12,
      "name": "Rock_Sandstone_White",
      "rotation": 3
    },
    {
      "x": -17,
      "y": 4,
      "z": -12,
      "name": "Rock_Sandstone_White_Brick",
      "rotation": 3
    },
    {
      "x": -17,
      "y": 0,
      "z": -11,
      "name": "Rock_Sandstone_White",
      "rotation": 3
    },
    {
      "x": -17,
      "y": 1,
      "z": -11,
      "name": "Rock_Sandstone_White",
      "rotation": 3
    },
    {
      "x": -17,
      "y": 2,
      "z": -11,
      "name": "Rock_Sandstone_White_Brick",
      "rotation": 3
    },
    {
      "x": -17,
      "y": 3,
      "z": -11,
      "name": "Rock_Sandstone_White_Brick",
      "rotation": 3
    },
    {
      "x": -17,
      "y": 4,
      "z": -11,
      "name": "Rock_Sandstone_White_Brick",
      "rotation": 3
    },
    {
      "x": -17,
      "y": 0,
      "z": -10,
      "name": "Rock_Sandstone_White",
      "rotation": 3
    },
    {
      "x": -17,
      "y": 1,
      "z": -10,
      "name": "Rock_Sandstone_White",
      "rotation": 3
    },
    {
      "x": -17,
      "y": 2,
      "z": -10,
      "name": "Rock_Sandstone_White",
      "rotation": 3
    },
    {
      "x": -17,
      "y": 3,
      "z": -10,
      "name": "Rock_Sandstone_White",
      "rotation": 3
    },
    {
      "x": -17,
      "y": 4,
      "z": -10,
      "name": "Rock_Sandstone_White",
      "rotation": 3
    },
    {
      "x": -17,
      "y": 0,
      "z": -9,
      "name": "Rock_Sandstone_White_Brick",
      "rotation": 3
    },
    {
      "x": -17,
      "y": 1,
      "z": -9,
      "name": "Rock_Sandstone_White_Brick",
      "rotation": 3
    },
    {
      "x": -17,
      "y": 2,
      "z": -9,
      "name": "Rock_Sandstone_White",
      "rotation": 3
    },
    {
      "x": -17,
      "y": 3,
      "z": -9,
      "name": "Rock_Sandstone_White_Brick",
      "rotation": 3
    },
    {
      "x": -17,
      "y": 4,
      "z": -9,
      "name": "Rock_Sandstone_White_Brick",
      "rotation": 3
    },
    {
      "x": -17,
      "y": 0,
      "z": -8,
      "name": "Rock_Sandstone_White",
      "rotation": 3
    },
    {
      "x": -17,
      "y": 1,
      "z": -8,
      "name": "Rock_Sandstone_White_Brick",
      "rotation": 3
    },
    {
      "x": -17,
      "y": 2,
      "z": -8,
      "name": "Rock_Sandstone_White_Brick",
      "rotation": 3
    },
    {
      "x": -17,
      "y": 3,
      "z": -8,
      "name": "Rock_Sandstone_White_Brick",
      "rotation": 3
    },
    {
      "x": -17,
      "y": 4,
      "z": -8,
      "name": "Rock_Sandstone_White_Brick",
      "rotation": 3
    },
    {
      "x": -17,
      "y": 0,
      "z": -7,
      "name": "Rock_Sandstone_White_Brick",
      "rotation": 3
    },
    {
      "x": -17,
      "y": 1,
      "z": -7,
      "name": "Rock_Sandstone_White",
      "rotation": 3
    },
    {
      "x": -17,
      "y": 2,
      "z": -7,
      "name": "Rock_Sandstone_White",
      "rotation": 3
    },
    {
      "x": -17,
      "y": 3,
      "z": -7,
      "name": "Rock_Sandstone_White_Brick",
      "rotation": 3
    },
    {
      "x": -17,
      "y": 4,
      "z": -7,
      "name": "Rock_Sandstone_White",
      "rotation": 3
    },
    {
      "x": -17,
      "y": 0,
      "z": -6,
      "name": "Rock_Sandstone_White",
      "rotation": 3
    },
    {
      "x": -17,
      "y": 1,
      "z": -6,
      "name": "Rock_Sandstone_White",
      "rotation": 3
    },
    {
      "x": -17,
      "y": 2,
      "z": -6,
      "name": "Rock_Sandstone_White",
      "rotation": 3
    },
    {
      "x": -17,
      "y": 3,
      "z": -6,
      "name": "Rock_Sandstone_White",
      "rotation": 3
    },
    {
      "x": -17,
      "y": 4,
      "z": -6,
      "name": "Rock_Sandstone_White_Brick",
      "rotation": 3
    },
    {
      "x": -17,
      "y": 0,
      "z": -5,
      "name": "Rock_Sandstone_White",
      "rotation": 3
    },
    {
      "x": -17,
      "y": 1,
      "z": -5,
      "name": "Rock_Sandstone_White",
      "rotation": 3
    },
    {
      "x": -17,
      "y": 2,
      "z": -5,
      "name": "Rock_Sandstone_White",
      "rotation": 3
    },
    {
      "x": -17,
      "y": 3,
      "z": -5,
      "name": "Rock_Sandstone_White",
      "rotation": 3
    },
    {
      "x": -17,
      "y": 4,
      "z": -5,
      "name": "Rock_Sandstone_White_Brick",
      "rotation": 3
    },
    {
      "x": -17,
      "y": 0,
      "z": -4,
      "name": "Rock_Sandstone_White_Brick",
      "rotation": 3
    },
    {
      "x": -17,
      "y": 1,
      "z": -4,
      "name": "Rock_Sandstone_White",
      "rotation": 3
    },
    {
      "x": -17,
      "y": 2,
      "z": -4,
      "name": "Rock_Sandstone_White_Brick",
      "rotation": 3
    },
    {
      "x": -17,
      "y": 3,
      "z": -4,
      "name": "Rock_Sandstone_White_Brick",
      "rotation": 3
    },
    {
      "x": -17,
      "y": 4,
      "z": -4,
      "name": "Rock_Sandstone_White_Brick",
      "rotation": 3
    },
    {
      "x": -17,
      "y": 0,
      "z": -3,
      "name": "Rock_Sandstone_White_Brick"
    },
    {
      "x": -17,
      "y": 1,
      "z": -3,
      "name": "Rock_Sandstone_White_Brick"
    },
    {
      "x": -17,
      "y": 2,
      "z": -3,
      "name": "Rock_Sandstone_White_Brick"
    },
    {
      "x": -17,
      "y": 3,
      "z": -3,
      "name": "Rock_Sandstone_White_Brick"
    },
    {
      "x": -17,
      "y": 4,
      "z": -3,
      "name": "Rock_Sandstone_White",
      "rotation": 3
    },
    {
      "x": -17,
      "y": 0,
      "z": -2,
      "name": "Rock_Sandstone_White_Brick_Smooth_Half",
      "rotation": 4
    },
    {
      "x": -17,
      "y": 1,
      "z": -2,
      "name": "Rock_Sandstone_White_Brick_Half",
      "rotation": 4
    },
    {
      "x": -17,
      "y": 2,
      "z": -2,
      "name": "Rock_Sandstone_White_Brick_Half",
      "rotation": 4
    },
    {
      "x": -17,
      "y": 3,
      "z": -2,
      "name": "Rock_Sandstone_White_Brick"
    },
    {
      "x": -17,
      "y": 4,
      "z": -2,
      "name": "Rock_Sandstone_White_Brick"
    },
    {
      "x": -17,
      "y": 0,
      "z": -1,
      "name": "Empty"
    },
    {
      "x": -17,
      "y": 1,
      "z": -1,
      "name": "Empty"
    },
    {
      "x": -17,
      "y": 2,
      "z": -1,
      "name": "Empty"
    },
    {
      "x": -17,
      "y": 3,
      "z": -1,
      "name": "Rock_Sandstone_White_Brick_Smooth_Half",
      "rotation": 8
    },
    {
      "x": -17,
      "y": 4,
      "z": -1,
      "name": "Rock_Sandstone_White_Brick"
    },
    {
      "x": -17,
      "y": 0,
      "z": 0,
      "name": "Empty"
    },
    {
      "x": -17,
      "y": 1,
      "z": 0,
      "name": "Empty"
    },
    {
      "x": -17,
      "y": 2,
      "z": 0,
      "name": "Empty"
    },
    {
      "x": -17,
      "y": 3,
      "z": 0,
      "name": "Rock_Sandstone_White_Brick_Smooth_Half",
      "rotation": 8
    },
    {
      "x": -17,
      "y": 4,
      "z": 0,
      "name": "Rock_Sandstone_White"
    },
    {
      "x": -17,
      "y": 0,
      "z": 1,
      "name": "Empty"
    },
    {
      "x": -17,
      "y": 1,
      "z": 1,
      "name": "Empty"
    },
    {
      "x": -17,
      "y": 2,
      "z": 1,
      "name": "Empty"
    },
    {
      "x": -17,
      "y": 3,
      "z": 1,
      "name": "Rock_Sandstone_White_Brick_Half",
      "rotation": 8
    },
    {
      "x": -17,
      "y": 4,
      "z": 1,
      "name": "Rock_Sandstone_White_Brick"
    },
    {
      "x": -17,
      "y": 0,
      "z": 2,
      "name": "Rock_Sandstone_White_Brick_Half",
      "rotation": 6
    },
    {
      "x": -17,
      "y": 1,
      "z": 2,
      "name": "Rock_Sandstone_White_Brick_Smooth_Half",
      "rotation": 6
    },
    {
      "x": -17,
      "y": 2,
      "z": 2,
      "name": "Rock_Sandstone_White_Brick_Smooth_Half",
      "rotation": 6
    },
    {
      "x": -17,
      "y": 3,
      "z": 2,
      "name": "Rock_Sandstone_White_Brick"
    },
    {
      "x": -17,
      "y": 4,
      "z": 2,
      "name": "Rock_Sandstone_White"
    },
    {
      "x": -17,
      "y": 0,
      "z": 3,
      "name": "Rock_Sandstone_White_Brick"
    },
    {
      "x": -17,
      "y": 1,
      "z": 3,
      "name": "Rock_Sandstone_White_Brick"
    },
    {
      "x": -17,
      "y": 2,
      "z": 3,
      "name": "Rock_Sandstone_White_Brick"
    },
    {
      "x": -17,
      "y": 3,
      "z": 3,
      "name": "Rock_Sandstone_White_Brick"
    },
    {
      "x": -17,
      "y": 4,
      "z": 3,
      "name": "Rock_Sandstone_White"
    },
    {
      "x": -17,
      "y": 0,
      "z": 4,
      "name": "Rock_Sandstone_White_Brick"
    },
    {
      "x": -17,
      "y": 1,
      "z": 4,
      "name": "Rock_Sandstone_White_Brick"
    },
    {
      "x": -17,
      "y": 2,
      "z": 4,
      "name": "Rock_Sandstone_White"
    },
    {
      "x": -17,
      "y": 3,
      "z": 4,
      "name": "Rock_Sandstone_White"
    },
    {
      "x": -17,
      "y": 4,
      "z": 4,
      "name": "Rock_Sandstone_White_Brick"
    },
    {
      "x": -17,
      "y": 0,
      "z": 5,
      "name": "Rock_Sandstone_White_Brick"
    },
    {
      "x": -17,
      "y": 1,
      "z": 5,
      "name": "Rock_Sandstone_White"
    },
    {
      "x": -17,
      "y": 2,
      "z": 5,
      "name": "Rock_Sandstone_White"
    },
    {
      "x": -17,
      "y": 3,
      "z": 5,
      "name": "Rock_Sandstone_White"
    },
    {
      "x": -17,
      "y": 4,
      "z": 5,
      "name": "Rock_Sandstone_White_Brick"
    },
    {
      "x": -17,
      "y": 0,
      "z": 6,
      "name": "Rock_Sandstone_White_Brick"
    },
    {
      "x": -17,
      "y": 1,
      "z": 6,
      "name": "Rock_Sandstone_White_Brick"
    },
    {
      "x": -17,
      "y": 2,
      "z": 6,
      "name": "Rock_Sandstone_White"
    },
    {
      "x": -17,
      "y": 3,
      "z": 6,
      "name": "Rock_Sandstone_White"
    },
    {
      "x": -17,
      "y": 4,
      "z": 6,
      "name": "Rock_Sandstone_White"
    },
    {
      "x": -17,
      "y": 0,
      "z": 7,
      "name": "Rock_Sandstone_White"
    },
    {
      "x": -17,
      "y": 1,
      "z": 7,
      "name": "Rock_Sandstone_White_Brick"
    },
    {
      "x": -17,
      "y": 2,
      "z": 7,
      "name": "Rock_Sandstone_White_Brick"
    },
    {
      "x": -17,
      "y": 3,
      "z": 7,
      "name": "Rock_Sandstone_White"
    },
    {
      "x": -17,
      "y": 4,
      "z": 7,
      "name": "Rock_Sandstone_White_Brick"
    },
    {
      "x": -17,
      "y": 0,
      "z": 8,
      "name": "Rock_Sandstone_White"
    },
    {
      "x": -17,
      "y": 1,
      "z": 8,
      "name": "Rock_Sandstone_White"
    },
    {
      "x": -17,
      "y": 2,
      "z": 8,
      "name": "Rock_Sandstone_White"
    },
    {
      "x": -17,
      "y": 3,
      "z": 8,
      "name": "Rock_Sandstone_White"
    },
    {
      "x": -17,
      "y": 4,
      "z": 8,
      "name": "Rock_Sandstone_White_Brick"
    },
    {
      "x": -17,
      "y": 0,
      "z": 9,
      "name": "Rock_Sandstone_White_Brick"
    },
    {
      "x": -17,
      "y": 1,
      "z": 9,
      "name": "Rock_Sandstone_White"
    },
    {
      "x": -17,
      "y": 2,
      "z": 9,
      "name": "Rock_Sandstone_White_Brick"
    },
    {
      "x": -17,
      "y": 3,
      "z": 9,
      "name": "Rock_Sandstone_White"
    },
    {
      "x": -17,
      "y": 4,
      "z": 9,
      "name": "Rock_Sandstone_White"
    },
    {
      "x": -17,
      "y": 0,
      "z": 10,
      "name": "Rock_Sandstone_White_Brick"
    },
    {
      "x": -17,
      "y": 1,
      "z": 10,
      "name": "Rock_Sandstone_White_Brick"
    },
    {
      "x": -17,
      "y": 2,
      "z": 10,
      "name": "Rock_Sandstone_White_Brick"
    },
    {
      "x": -17,
      "y": 3,
      "z": 10,
      "name": "Rock_Sandstone_White"
    },
    {
      "x": -17,
      "y": 4,
      "z": 10,
      "name": "Rock_Sandstone_White_Brick"
    },
    {
      "x": -17,
      "y": 0,
      "z": 11,
      "name": "Rock_Sandstone_White_Brick"
    },
    {
      "x": -17,
      "y": 1,
      "z": 11,
      "name": "Rock_Sandstone_White"
    },
    {
      "x": -17,
      "y": 2,
      "z": 11,
      "name": "Rock_Sandstone_White_Brick"
    },
    {
      "x": -17,
      "y": 3,
      "z": 11,
      "name": "Rock_Sandstone_White_Brick"
    },
    {
      "x": -17,
      "y": 4,
      "z": 11,
      "name": "Rock_Sandstone_White"
    },
    {
      "x": -17,
      "y": 0,
      "z": 12,
      "name": "Rock_Sandstone_White"
    },
    {
      "x": -17,
      "y": 1,
      "z": 12,
      "name": "Rock_Sandstone_White"
    },
    {
      "x": -17,
      "y": 2,
      "z": 12,
      "name": "Rock_Sandstone_White_Brick"
    },
    {
      "x": -17,
      "y": 3,
      "z": 12,
      "name": "Rock_Sandstone_White"
    },
    {
      "x": -17,
      "y": 4,
      "z": 12,
      "name": "Rock_Sandstone_White"
    },
    {
      "x": -17,
      "y": 0,
      "z": 13,
      "name": "Rock_Sandstone_White"
    },
    {
      "x": -17,
      "y": 1,
      "z": 13,
      "name": "Rock_Sandstone_White"
    },
    {
      "x": -17,
      "y": 2,
      "z": 13,
      "name": "Rock_Sandstone_White_Brick"
    },
    {
      "x": -17,
      "y": 3,
      "z": 13,
      "name": "Rock_Sandstone_White_Brick"
    },
    {
      "x": -17,
      "y": 4,
      "z": 13,
      "name": "Rock_Sandstone_White_Brick"
    },
    {
      "x": -17,
      "y": 0,
      "z": 14,
      "name": "Rock_Sandstone_White_Brick"
    },
    {
      "x": -17,
      "y": 1,
      "z": 14,
      "name": "Rock_Sandstone_White"
    },
    {
      "x": -17,
      "y": 2,
      "z": 14,
      "name": "Rock_Sandstone_White"
    },
    {
      "x": -17,
      "y": 3,
      "z": 14,
      "name": "Rock_Sandstone_White"
    },
    {
      "x": -17,
      "y": 4,
      "z": 14,
      "name": "Rock_Sandstone_White_Brick"
    },
    {
      "x": -17,
      "y": 0,
      "z": 15,
      "name": "Rock_Sandstone_White_Brick"
    },
    {
      "x": -17,
      "y": 1,
      "z": 15,
      "name": "Rock_Sandstone_White"
    },
    {
      "x": -17,
      "y": 2,
      "z": 15,
      "name": "Rock_Sandstone_White_Brick"
    },
    {
      "x": -17,
      "y": 3,
      "z": 15,
      "name": "Rock_Sandstone_White"
    },
    {
      "x": -17,
      "y": 4,
      "z": 15,
      "name": "Rock_Sandstone_White"
    },
    {
      "x": -17,
      "y": 0,
      "z": 16,
      "name": "Rock_Sandstone_White"
    },
    {
      "x": -17,
      "y": 1,
      "z": 16,
      "name": "Rock_Sandstone_White_Brick"
    },
    {
      "x": -17,
      "y": 2,
      "z": 16,
      "name": "Rock_Sandstone_White"
    },
    {
      "x": -17,
      "y": 3,
      "z": 16,
      "name": "Rock_Sandstone_White_Brick"
    },
    {
      "x": -17,
      "y": 4,
      "z": 16,
      "name": "Rock_Sandstone_White_Brick"
    },
    {
      "x": -17,
      "y": 0,
      "z": 17,
      "name": "Rock_Sandstone_White"
    },
    {
      "x": -17,
      "y": 1,
      "z": 17,
      "name": "Rock_Sandstone_White_Brick"
    },
    {
      "x": -17,
      "y": 2,
      "z": 17,
      "name": "Rock_Sandstone_White"
    },
    {
      "x": -17,
      "y": 3,
      "z": 17,
      "name": "Rock_Sandstone_White_Brick"
    },
    {
      "x": -17,
      "y": 4,
      "z": 17,
      "name": "Rock_Sandstone_White_Brick"
    },
    {
      "x": -17,
      "y": 0,
      "z": 18,
      "name": "Rock_Sandstone_White_Brick"
    },
    {
      "x": -17,
      "y": 1,
      "z": 18,
      "name": "Rock_Sandstone_White"
    },
    {
      "x": -17,
      "y": 2,
      "z": 18,
      "name": "Rock_Sandstone_White_Brick"
    },
    {
      "x": -17,
      "y": 3,
      "z": 18,
      "name": "Rock_Sandstone_White_Brick"
    },
    {
      "x": -17,
      "y": 4,
      "z": 18,
      "name": "Rock_Sandstone_White"
    },
    {
      "x": -17,
      "y": 0,
      "z": 19,
      "name": "Rock_Sandstone_White_Brick"
    },
    {
      "x": -17,
      "y": 1,
      "z": 19,
      "name": "Rock_Sandstone_White"
    },
    {
      "x": -17,
      "y": 2,
      "z": 19,
      "name": "Rock_Sandstone_White"
    },
    {
      "x": -17,
      "y": 3,
      "z": 19,
      "name": "Rock_Sandstone_White_Brick"
    },
    {
      "x": -17,
      "y": 4,
      "z": 19,
      "name": "Rock_Sandstone_White_Brick"
    },
    {
      "x": -17,
      "y": 0,
      "z": 20,
      "name": "Empty"
    },
    {
      "x": -17,
      "y": 1,
      "z": 20,
      "name": "Empty"
    },
    {
      "x": -17,
      "y": 2,
      "z": 20,
      "name": "Empty"
    },
    {
      "x": -17,
      "y": 3,
      "z": 20,
      "name": "Empty"
    },
    {
      "x": -17,
      "y": 4,
      "z": 20,
      "name": "Empty"
    },
    {
      "x": -16,
      "y": 0,
      "z": -19,
      "name": "Empty"
    },
    {
      "x": -16,
      "y": 1,
      "z": -19,
      "name": "Empty"
    },
    {
      "x": -16,
      "y": 2,
      "z": -19,
      "name": "Empty"
    },
    {
      "x": -16,
      "y": 3,
      "z": -19,
      "name": "Empty"
    },
    {
      "x": -16,
      "y": 4,
      "z": -19,
      "name": "Empty"
    },
    {
      "x": -16,
      "y": 0,
      "z": -18,
      "name": "Rock_Sandstone_White",
      "rotation": 3
    },
    {
      "x": -16,
      "y": 1,
      "z": -18,
      "name": "Rock_Sandstone_White_Brick",
      "rotation": 3
    },
    {
      "x": -16,
      "y": 2,
      "z": -18,
      "name": "Rock_Sandstone_White_Brick",
      "rotation": 3
    },
    {
      "x": -16,
      "y": 3,
      "z": -18,
      "name": "Rock_Sandstone_White_Brick",
      "rotation": 3
    },
    {
      "x": -16,
      "y": 4,
      "z": -18,
      "name": "Rock_Sandstone_White_Brick",
      "rotation": 3
    },
    {
      "x": -16,
      "y": 0,
      "z": -17,
      "name": "Rock_Sandstone_White",
      "rotation": 3
    },
    {
      "x": -16,
      "y": 1,
      "z": -17,
      "name": "Rock_Sandstone_White_Brick",
      "rotation": 3
    },
    {
      "x": -16,
      "y": 2,
      "z": -17,
      "name": "Rock_Sandstone_White",
      "rotation": 3
    },
    {
      "x": -16,
      "y": 3,
      "z": -17,
      "name": "Rock_Sandstone_White_Brick",
      "rotation": 3
    },
    {
      "x": -16,
      "y": 4,
      "z": -17,
      "name": "Rock_Sandstone_White_Brick",
      "rotation": 3
    },
    {
      "x": -16,
      "y": 0,
      "z": -16,
      "name": "Rock_Sandstone_White_Brick",
      "rotation": 3
    },
    {
      "x": -16,
      "y": 1,
      "z": -16,
      "name": "Rock_Sandstone_White_Brick",
      "rotation": 3
    },
    {
      "x": -16,
      "y": 2,
      "z": -16,
      "name": "Rock_Sandstone_White_Brick",
      "rotation": 3
    },
    {
      "x": -16,
      "y": 3,
      "z": -16,
      "name": "Rock_Sandstone_White_Brick",
      "rotation": 3
    },
    {
      "x": -16,
      "y": 4,
      "z": -16,
      "name": "Rock_Sandstone_White_Brick",
      "rotation": 3
    },
    {
      "x": -16,
      "y": 0,
      "z": -15,
      "name": "Rock_Sandstone_White_Brick",
      "rotation": 3
    },
    {
      "x": -16,
      "y": 1,
      "z": -15,
      "name": "Rock_Sandstone_White_Brick",
      "rotation": 3
    },
    {
      "x": -16,
      "y": 2,
      "z": -15,
      "name": "Rock_Sandstone_White",
      "rotation": 3
    },
    {
      "x": -16,
      "y": 3,
      "z": -15,
      "name": "Rock_Sandstone_White_Brick",
      "rotation": 3
    },
    {
      "x": -16,
      "y": 4,
      "z": -15,
      "name": "Rock_Sandstone_White",
      "rotation": 3
    },
    {
      "x": -16,
      "y": 0,
      "z": -14,
      "name": "Rock_Sandstone_White_Brick",
      "rotation": 3
    },
    {
      "x": -16,
      "y": 1,
      "z": -14,
      "name": "Rock_Sandstone_White_Brick",
      "rotation": 3
    },
    {
      "x": -16,
      "y": 2,
      "z": -14,
      "name": "Rock_Sandstone_White",
      "rotation": 3
    },
    {
      "x": -16,
      "y": 3,
      "z": -14,
      "name": "Rock_Sandstone_White",
      "rotation": 3
    },
    {
      "x": -16,
      "y": 4,
      "z": -14,
      "name": "Rock_Sandstone_White",
      "rotation": 3
    },
    {
      "x": -16,
      "y": 0,
      "z": -13,
      "name": "Rock_Sandstone_White_Brick",
      "rotation": 3
    },
    {
      "x": -16,
      "y": 1,
      "z": -13,
      "name": "Rock_Sandstone_White_Brick",
      "rotation": 3
    },
    {
      "x": -16,
      "y": 2,
      "z": -13,
      "name": "Rock_Sandstone_White_Brick",
      "rotation": 3
    },
    {
      "x": -16,
      "y": 3,
      "z": -13,
      "name": "Rock_Sandstone_White",
      "rotation": 3
    },
    {
      "x": -16,
      "y": 4,
      "z": -13,
      "name": "Rock_Sandstone_White",
      "rotation": 3
    },
    {
      "x": -16,
      "y": 0,
      "z": -12,
      "name": "Rock_Sandstone_White",
      "rotation": 3
    },
    {
      "x": -16,
      "y": 1,
      "z": -12,
      "name": "Rock_Sandstone_White_Brick",
      "rotation": 3
    },
    {
      "x": -16,
      "y": 2,
      "z": -12,
      "name": "Rock_Sandstone_White",
      "rotation": 3
    },
    {
      "x": -16,
      "y": 3,
      "z": -12,
      "name": "Rock_Sandstone_White",
      "rotation": 3
    },
    {
      "x": -16,
      "y": 4,
      "z": -12,
      "name": "Rock_Sandstone_White_Brick",
      "rotation": 3
    },
    {
      "x": -16,
      "y": 0,
      "z": -11,
      "name": "Rock_Sandstone_White",
      "rotation": 3
    },
    {
      "x": -16,
      "y": 1,
      "z": -11,
      "name": "Rock_Sandstone_White",
      "rotation": 3
    },
    {
      "x": -16,
      "y": 2,
      "z": -11,
      "name": "Rock_Sandstone_White_Brick",
      "rotation": 3
    },
    {
      "x": -16,
      "y": 3,
      "z": -11,
      "name": "Rock_Sandstone_White_Brick",
      "rotation": 3
    },
    {
      "x": -16,
      "y": 4,
      "z": -11,
      "name": "Rock_Sandstone_White_Brick",
      "rotation": 3
    },
    {
      "x": -16,
      "y": 0,
      "z": -10,
      "name": "Rock_Sandstone_White",
      "rotation": 3
    },
    {
      "x": -16,
      "y": 1,
      "z": -10,
      "name": "Rock_Sandstone_White",
      "rotation": 3
    },
    {
      "x": -16,
      "y": 2,
      "z": -10,
      "name": "Rock_Sandstone_White",
      "rotation": 3
    },
    {
      "x": -16,
      "y": 3,
      "z": -10,
      "name": "Rock_Sandstone_White_Brick",
      "rotation": 3
    },
    {
      "x": -16,
      "y": 4,
      "z": -10,
      "name": "Rock_Sandstone_White",
      "rotation": 3
    },
    {
      "x": -16,
      "y": 0,
      "z": -9,
      "name": "Rock_Sandstone_White",
      "rotation": 3
    },
    {
      "x": -16,
      "y": 1,
      "z": -9,
      "name": "Rock_Sandstone_White_Brick",
      "rotation": 3
    },
    {
      "x": -16,
      "y": 2,
      "z": -9,
      "name": "Rock_Sandstone_White_Brick",
      "rotation": 3
    },
    {
      "x": -16,
      "y": 3,
      "z": -9,
      "name": "Rock_Sandstone_White",
      "rotation": 3
    },
    {
      "x": -16,
      "y": 4,
      "z": -9,
      "name": "Rock_Sandstone_White",
      "rotation": 3
    },
    {
      "x": -16,
      "y": 0,
      "z": -8,
      "name": "Rock_Sandstone_White_Brick",
      "rotation": 3
    },
    {
      "x": -16,
      "y": 1,
      "z": -8,
      "name": "Rock_Sandstone_White",
      "rotation": 3
    },
    {
      "x": -16,
      "y": 2,
      "z": -8,
      "name": "Rock_Sandstone_White",
      "rotation": 3
    },
    {
      "x": -16,
      "y": 3,
      "z": -8,
      "name": "Rock_Sandstone_White_Brick",
      "rotation": 3
    },
    {
      "x": -16,
      "y": 4,
      "z": -8,
      "name": "Rock_Sandstone_White_Brick",
      "rotation": 3
    },
    {
      "x": -16,
      "y": 0,
      "z": -7,
      "name": "Rock_Sandstone_White_Brick",
      "rotation": 3
    },
    {
      "x": -16,
      "y": 1,
      "z": -7,
      "name": "Rock_Sandstone_White_Brick",
      "rotation": 3
    },
    {
      "x": -16,
      "y": 2,
      "z": -7,
      "name": "Rock_Sandstone_White_Brick",
      "rotation": 3
    },
    {
      "x": -16,
      "y": 3,
      "z": -7,
      "name": "Rock_Sandstone_White_Brick",
      "rotation": 3
    },
    {
      "x": -16,
      "y": 4,
      "z": -7,
      "name": "Rock_Sandstone_White",
      "rotation": 3
    },
    {
      "x": -16,
      "y": 0,
      "z": -6,
      "name": "Rock_Sandstone_White",
      "rotation": 3
    },
    {
      "x": -16,
      "y": 1,
      "z": -6,
      "name": "Rock_Sandstone_White",
      "rotation": 3
    },
    {
      "x": -16,
      "y": 2,
      "z": -6,
      "name": "Rock_Sandstone_White",
      "rotation": 3
    },
    {
      "x": -16,
      "y": 3,
      "z": -6,
      "name": "Rock_Sandstone_White",
      "rotation": 3
    },
    {
      "x": -16,
      "y": 4,
      "z": -6,
      "name": "Rock_Sandstone_White",
      "rotation": 3
    },
    {
      "x": -16,
      "y": 0,
      "z": -5,
      "name": "Rock_Sandstone_White_Brick",
      "rotation": 3
    },
    {
      "x": -16,
      "y": 1,
      "z": -5,
      "name": "Rock_Sandstone_White",
      "rotation": 3
    },
    {
      "x": -16,
      "y": 2,
      "z": -5,
      "name": "Rock_Sandstone_White_Brick",
      "rotation": 3
    },
    {
      "x": -16,
      "y": 3,
      "z": -5,
      "name": "Rock_Sandstone_White",
      "rotation": 3
    },
    {
      "x": -16,
      "y": 4,
      "z": -5,
      "name": "Rock_Sandstone_White_Brick",
      "rotation": 3
    },
    {
      "x": -16,
      "y": 0,
      "z": -4,
      "name": "Rock_Sandstone_White",
      "rotation": 3
    },
    {
      "x": -16,
      "y": 1,
      "z": -4,
      "name": "Rock_Sandstone_White_Brick",
      "rotation": 3
    },
    {
      "x": -16,
      "y": 2,
      "z": -4,
      "name": "Rock_Sandstone_White",
      "rotation": 3
    },
    {
      "x": -16,
      "y": 3,
      "z": -4,
      "name": "Rock_Sandstone_White_Brick",
      "rotation": 3
    },
    {
      "x": -16,
      "y": 4,
      "z": -4,
      "name": "Rock_Sandstone_White_Brick",
      "rotation": 3
    },
    {
      "x": -16,
      "y": 0,
      "z": -3,
      "name": "Rock_Sandstone_White_Brick"
    },
    {
      "x": -16,
      "y": 1,
      "z": -3,
      "name": "Rock_Sandstone_White_Brick"
    },
    {
      "x": -16,
      "y": 2,
      "z": -3,
      "name": "Rock_Sandstone_White_Brick"
    },
    {
      "x": -16,
      "y": 3,
      "z": -3,
      "name": "Rock_Sandstone_White_Brick"
    },
    {
      "x": -16,
      "y": 4,
      "z": -3,
      "name": "Rock_Sandstone_White_Brick",
      "rotation": 3
    },
    {
      "x": -16,
      "y": 0,
      "z": -2,
      "name": "Rock_Sandstone_White_Brick_Smooth_Half",
      "rotation": 4
    },
    {
      "x": -16,
      "y": 1,
      "z": -2,
      "name": "Rock_Sandstone_White_Brick_Half",
      "rotation": 4
    },
    {
      "x": -16,
      "y": 2,
      "z": -2,
      "name": "Rock_Sandstone_White_Brick_Half",
      "rotation": 4
    },
    {
      "x": -16,
      "y": 3,
      "z": -2,
      "name": "Rock_Sandstone_White_Brick"
    },
    {
      "x": -16,
      "y": 4,
      "z": -2,
      "name": "Rock_Sandstone_White"
    },
    {
      "x": -16,
      "y": 0,
      "z": -1,
      "name": "Empty"
    },
    {
      "x": -16,
      "y": 1,
      "z": -1,
      "name": "Empty"
    },
    {
      "x": -16,
      "y": 2,
      "z": -1,
      "name": "Empty"
    },
    {
      "x": -16,
      "y": 3,
      "z": -1,
      "name": "Rock_Sandstone_White_Brick_Smooth_Half",
      "rotation": 8
    },
    {
      "x": -16,
      "y": 4,
      "z": -1,
      "name": "Rock_Sandstone_White"
    },
    {
      "x": -16,
      "y": 0,
      "z": 0,
      "name": "Empty"
    },
    {
      "x": -16,
      "y": 1,
      "z": 0,
      "name": "Empty"
    },
    {
      "x": -16,
      "y": 2,
      "z": 0,
      "name": "Empty"
    },
    {
      "x": -16,
      "y": 3,
      "z": 0,
      "name": "Rock_Sandstone_White_Brick_Smooth_Half",
      "rotation": 8
    },
    {
      "x": -16,
      "y": 4,
      "z": 0,
      "name": "Rock_Sandstone_White"
    },
    {
      "x": -16,
      "y": 0,
      "z": 1,
      "name": "Empty"
    },
    {
      "x": -16,
      "y": 1,
      "z": 1,
      "name": "Empty"
    },
    {
      "x": -16,
      "y": 2,
      "z": 1,
      "name": "Empty"
    },
    {
      "x": -16,
      "y": 3,
      "z": 1,
      "name": "Rock_Sandstone_White_Brick_Half",
      "rotation": 8
    },
    {
      "x": -16,
      "y": 4,
      "z": 1,
      "name": "Rock_Sandstone_White_Brick"
    },
    {
      "x": -16,
      "y": 0,
      "z": 2,
      "name": "Rock_Sandstone_White_Brick_Half",
      "rotation": 6
    },
    {
      "x": -16,
      "y": 1,
      "z": 2,
      "name": "Rock_Sandstone_White_Brick_Smooth_Half",
      "rotation": 6
    },
    {
      "x": -16,
      "y": 2,
      "z": 2,
      "name": "Rock_Sandstone_White_Brick_Smooth_Half",
      "rotation": 6
    },
    {
      "x": -16,
      "y": 3,
      "z": 2,
      "name": "Rock_Sandstone_White_Brick"
    },
    {
      "x": -16,
      "y": 4,
      "z": 2,
      "name": "Rock_Sandstone_White_Brick"
    },
    {
      "x": -16,
      "y": 0,
      "z": 3,
      "name": "Rock_Sandstone_White_Brick"
    },
    {
      "x": -16,
      "y": 1,
      "z": 3,
      "name": "Rock_Sandstone_White_Brick"
    },
    {
      "x": -16,
      "y": 2,
      "z": 3,
      "name": "Rock_Sandstone_White_Brick"
    },
    {
      "x": -16,
      "y": 3,
      "z": 3,
      "name": "Rock_Sandstone_White_Brick"
    },
    {
      "x": -16,
      "y": 4,
      "z": 3,
      "name": "Rock_Sandstone_White"
    },
    {
      "x": -16,
      "y": 0,
      "z": 4,
      "name": "Rock_Sandstone_White_Brick"
    },
    {
      "x": -16,
      "y": 1,
      "z": 4,
      "name": "Rock_Sandstone_White"
    },
    {
      "x": -16,
      "y": 2,
      "z": 4,
      "name": "Rock_Sandstone_White_Brick"
    },
    {
      "x": -16,
      "y": 3,
      "z": 4,
      "name": "Rock_Sandstone_White_Brick"
    },
    {
      "x": -16,
      "y": 4,
      "z": 4,
      "name": "Rock_Sandstone_White"
    },
    {
      "x": -16,
      "y": 0,
      "z": 5,
      "name": "Rock_Sandstone_White_Brick"
    },
    {
      "x": -16,
      "y": 1,
      "z": 5,
      "name": "Rock_Sandstone_White_Brick"
    },
    {
      "x": -16,
      "y": 2,
      "z": 5,
      "name": "Rock_Sandstone_White_Brick"
    },
    {
      "x": -16,
      "y": 3,
      "z": 5,
      "name": "Rock_Sandstone_White_Brick"
    },
    {
      "x": -16,
      "y": 4,
      "z": 5,
      "name": "Rock_Sandstone_White"
    },
    {
      "x": -16,
      "y": 0,
      "z": 6,
      "name": "Rock_Sandstone_White_Brick"
    },
    {
      "x": -16,
      "y": 1,
      "z": 6,
      "name": "Rock_Sandstone_White"
    },
    {
      "x": -16,
      "y": 2,
      "z": 6,
      "name": "Rock_Sandstone_White_Brick"
    },
    {
      "x": -16,
      "y": 3,
      "z": 6,
      "name": "Rock_Sandstone_White_Brick"
    },
    {
      "x": -16,
      "y": 4,
      "z": 6,
      "name": "Rock_Sandstone_White_Brick"
    },
    {
      "x": -16,
      "y": 0,
      "z": 7,
      "name": "Rock_Sandstone_White_Brick"
    },
    {
      "x": -16,
      "y": 1,
      "z": 7,
      "name": "Rock_Sandstone_White"
    },
    {
      "x": -16,
      "y": 2,
      "z": 7,
      "name": "Rock_Sandstone_White_Brick"
    },
    {
      "x": -16,
      "y": 3,
      "z": 7,
      "name": "Rock_Sandstone_White_Brick"
    },
    {
      "x": -16,
      "y": 4,
      "z": 7,
      "name": "Rock_Sandstone_White"
    },
    {
      "x": -16,
      "y": 0,
      "z": 8,
      "name": "Rock_Sandstone_White"
    },
    {
      "x": -16,
      "y": 1,
      "z": 8,
      "name": "Rock_Sandstone_White_Brick"
    },
    {
      "x": -16,
      "y": 2,
      "z": 8,
      "name": "Rock_Sandstone_White_Brick"
    },
    {
      "x": -16,
      "y": 3,
      "z": 8,
      "name": "Rock_Sandstone_White_Brick"
    },
    {
      "x": -16,
      "y": 4,
      "z": 8,
      "name": "Rock_Sandstone_White_Brick"
    },
    {
      "x": -16,
      "y": 0,
      "z": 9,
      "name": "Rock_Sandstone_White"
    },
    {
      "x": -16,
      "y": 1,
      "z": 9,
      "name": "Rock_Sandstone_White_Brick"
    },
    {
      "x": -16,
      "y": 2,
      "z": 9,
      "name": "Rock_Sandstone_White_Brick"
    },
    {
      "x": -16,
      "y": 3,
      "z": 9,
      "name": "Rock_Sandstone_White_Brick"
    },
    {
      "x": -16,
      "y": 4,
      "z": 9,
      "name": "Rock_Sandstone_White_Brick"
    },
    {
      "x": -16,
      "y": 0,
      "z": 10,
      "name": "Rock_Sandstone_White_Brick"
    },
    {
      "x": -16,
      "y": 1,
      "z": 10,
      "name": "Rock_Sandstone_White"
    },
    {
      "x": -16,
      "y": 2,
      "z": 10,
      "name": "Rock_Sandstone_White_Brick"
    },
    {
      "x": -16,
      "y": 3,
      "z": 10,
      "name": "Rock_Sandstone_White_Brick"
    },
    {
      "x": -16,
      "y": 4,
      "z": 10,
      "name": "Rock_Sandstone_White"
    },
    {
      "x": -16,
      "y": 0,
      "z": 11,
      "name": "Rock_Sandstone_White_Brick"
    },
    {
      "x": -16,
      "y": 1,
      "z": 11,
      "name": "Rock_Sandstone_White_Brick"
    },
    {
      "x": -16,
      "y": 2,
      "z": 11,
      "name": "Rock_Sandstone_White_Brick"
    },
    {
      "x": -16,
      "y": 3,
      "z": 11,
      "name": "Rock_Sandstone_White_Brick"
    },
    {
      "x": -16,
      "y": 4,
      "z": 11,
      "name": "Rock_Sandstone_White"
    },
    {
      "x": -16,
      "y": 0,
      "z": 12,
      "name": "Rock_Sandstone_White_Brick"
    },
    {
      "x": -16,
      "y": 1,
      "z": 12,
      "name": "Rock_Sandstone_White_Brick"
    },
    {
      "x": -16,
      "y": 2,
      "z": 12,
      "name": "Rock_Sandstone_White_Brick"
    },
    {
      "x": -16,
      "y": 3,
      "z": 12,
      "name": "Rock_Sandstone_White_Brick"
    },
    {
      "x": -16,
      "y": 4,
      "z": 12,
      "name": "Rock_Sandstone_White_Brick"
    },
    {
      "x": -16,
      "y": 0,
      "z": 13,
      "name": "Rock_Sandstone_White_Brick"
    },
    {
      "x": -16,
      "y": 1,
      "z": 13,
      "name": "Rock_Sandstone_White_Brick"
    },
    {
      "x": -16,
      "y": 2,
      "z": 13,
      "name": "Rock_Sandstone_White"
    },
    {
      "x": -16,
      "y": 3,
      "z": 13,
      "name": "Rock_Sandstone_White_Brick"
    },
    {
      "x": -16,
      "y": 4,
      "z": 13,
      "name": "Rock_Sandstone_White_Brick"
    },
    {
      "x": -16,
      "y": 0,
      "z": 14,
      "name": "Rock_Sandstone_White"
    },
    {
      "x": -16,
      "y": 1,
      "z": 14,
      "name": "Rock_Sandstone_White_Brick"
    },
    {
      "x": -16,
      "y": 2,
      "z": 14,
      "name": "Rock_Sandstone_White"
    },
    {
      "x": -16,
      "y": 3,
      "z": 14,
      "name": "Rock_Sandstone_White_Brick"
    },
    {
      "x": -16,
      "y": 4,
      "z": 14,
      "name": "Rock_Sandstone_White_Brick"
    },
    {
      "x": -16,
      "y": 0,
      "z": 15,
      "name": "Rock_Sandstone_White_Brick"
    },
    {
      "x": -16,
      "y": 1,
      "z": 15,
      "name": "Rock_Sandstone_White"
    },
    {
      "x": -16,
      "y": 2,
      "z": 15,
      "name": "Rock_Sandstone_White"
    },
    {
      "x": -16,
      "y": 3,
      "z": 15,
      "name": "Rock_Sandstone_White"
    },
    {
      "x": -16,
      "y": 4,
      "z": 15,
      "name": "Rock_Sandstone_White_Brick"
    },
    {
      "x": -16,
      "y": 0,
      "z": 16,
      "name": "Rock_Sandstone_White"
    },
    {
      "x": -16,
      "y": 1,
      "z": 16,
      "name": "Rock_Sandstone_White"
    },
    {
      "x": -16,
      "y": 2,
      "z": 16,
      "name": "Rock_Sandstone_White_Brick"
    },
    {
      "x": -16,
      "y": 3,
      "z": 16,
      "name": "Rock_Sandstone_White_Brick"
    },
    {
      "x": -16,
      "y": 4,
      "z": 16,
      "name": "Rock_Sandstone_White"
    },
    {
      "x": -16,
      "y": 0,
      "z": 17,
      "name": "Rock_Sandstone_White_Brick"
    },
    {
      "x": -16,
      "y": 1,
      "z": 17,
      "name": "Rock_Sandstone_White_Brick"
    },
    {
      "x": -16,
      "y": 2,
      "z": 17,
      "name": "Rock_Sandstone_White_Brick"
    },
    {
      "x": -16,
      "y": 3,
      "z": 17,
      "name": "Rock_Sandstone_White_Brick"
    },
    {
      "x": -16,
      "y": 4,
      "z": 17,
      "name": "Rock_Sandstone_White_Brick"
    },
    {
      "x": -16,
      "y": 0,
      "z": 18,
      "name": "Rock_Sandstone_White"
    },
    {
      "x": -16,
      "y": 1,
      "z": 18,
      "name": "Rock_Sandstone_White_Brick"
    },
    {
      "x": -16,
      "y": 2,
      "z": 18,
      "name": "Rock_Sandstone_White_Brick"
    },
    {
      "x": -16,
      "y": 3,
      "z": 18,
      "name": "Rock_Sandstone_White_Brick"
    },
    {
      "x": -16,
      "y": 4,
      "z": 18,
      "name": "Rock_Sandstone_White"
    },
    {
      "x": -16,
      "y": 0,
      "z": 19,
      "name": "Rock_Sandstone_White"
    },
    {
      "x": -16,
      "y": 1,
      "z": 19,
      "name": "Rock_Sandstone_White_Brick"
    },
    {
      "x": -16,
      "y": 2,
      "z": 19,
      "name": "Rock_Sandstone_White_Brick"
    },
    {
      "x": -16,
      "y": 3,
      "z": 19,
      "name": "Rock_Sandstone_White_Brick"
    },
    {
      "x": -16,
      "y": 4,
      "z": 19,
      "name": "Rock_Sandstone_White_Brick"
    },
    {
      "x": -16,
      "y": 0,
      "z": 20,
      "name": "Empty"
    },
    {
      "x": -16,
      "y": 1,
      "z": 20,
      "name": "Empty"
    },
    {
      "x": -16,
      "y": 2,
      "z": 20,
      "name": "Empty"
    },
    {
      "x": -16,
      "y": 3,
      "z": 20,
      "name": "Empty"
    },
    {
      "x": -16,
      "y": 4,
      "z": 20,
      "name": "Empty"
    },
    {
      "x": -15,
      "y": 0,
      "z": -19,
      "name": "Empty"
    },
    {
      "x": -15,
      "y": 1,
      "z": -19,
      "name": "Empty"
    },
    {
      "x": -15,
      "y": 2,
      "z": -19,
      "name": "Empty"
    },
    {
      "x": -15,
      "y": 3,
      "z": -19,
      "name": "Empty"
    },
    {
      "x": -15,
      "y": 4,
      "z": -19,
      "name": "Empty"
    },
    {
      "x": -15,
      "y": 0,
      "z": -18,
      "name": "Rock_Sandstone_White_Brick",
      "rotation": 3
    },
    {
      "x": -15,
      "y": 1,
      "z": -18,
      "name": "Rock_Sandstone_White",
      "rotation": 3
    },
    {
      "x": -15,
      "y": 2,
      "z": -18,
      "name": "Rock_Sandstone_White_Brick",
      "rotation": 3
    },
    {
      "x": -15,
      "y": 3,
      "z": -18,
      "name": "Rock_Sandstone_White",
      "rotation": 3
    },
    {
      "x": -15,
      "y": 4,
      "z": -18,
      "name": "Rock_Sandstone_White_Brick",
      "rotation": 3
    },
    {
      "x": -15,
      "y": 0,
      "z": -17,
      "name": "Rock_Sandstone_White",
      "rotation": 3
    },
    {
      "x": -15,
      "y": 1,
      "z": -17,
      "name": "Rock_Sandstone_White_Brick",
      "rotation": 3
    },
    {
      "x": -15,
      "y": 2,
      "z": -17,
      "name": "Rock_Sandstone_White",
      "rotation": 3
    },
    {
      "x": -15,
      "y": 3,
      "z": -17,
      "name": "Rock_Sandstone_White_Brick",
      "rotation": 3
    },
    {
      "x": -15,
      "y": 4,
      "z": -17,
      "name": "Rock_Sandstone_White_Brick",
      "rotation": 3
    },
    {
      "x": -15,
      "y": 0,
      "z": -16,
      "name": "Rock_Sandstone_White",
      "rotation": 3
    },
    {
      "x": -15,
      "y": 1,
      "z": -16,
      "name": "Rock_Sandstone_White",
      "rotation": 3
    },
    {
      "x": -15,
      "y": 2,
      "z": -16,
      "name": "Rock_Sandstone_White_Brick",
      "rotation": 3
    },
    {
      "x": -15,
      "y": 3,
      "z": -16,
      "name": "Rock_Sandstone_White_Brick",
      "rotation": 3
    },
    {
      "x": -15,
      "y": 4,
      "z": -16,
      "name": "Rock_Sandstone_White",
      "rotation": 3
    },
    {
      "x": -15,
      "y": 0,
      "z": -15,
      "name": "Empty"
    },
    {
      "x": -15,
      "y": 1,
      "z": -15,
      "name": "Empty"
    },
    {
      "x": -15,
      "y": 2,
      "z": -15,
      "name": "Empty"
    },
    {
      "x": -15,
      "y": 3,
      "z": -15,
      "name": "Empty"
    },
    {
      "x": -15,
      "y": 4,
      "z": -15,
      "name": "Empty"
    },
    {
      "x": -15,
      "y": 0,
      "z": -14,
      "name": "Empty"
    },
    {
      "x": -15,
      "y": 1,
      "z": -14,
      "name": "Empty"
    },
    {
      "x": -15,
      "y": 2,
      "z": -14,
      "name": "Empty"
    },
    {
      "x": -15,
      "y": 3,
      "z": -14,
      "name": "Empty"
    },
    {
      "x": -15,
      "y": 4,
      "z": -14,
      "name": "Empty"
    },
    {
      "x": -15,
      "y": 0,
      "z": -13,
      "name": "Empty"
    },
    {
      "x": -15,
      "y": 1,
      "z": -13,
      "name": "Empty"
    },
    {
      "x": -15,
      "y": 2,
      "z": -13,
      "name": "Empty"
    },
    {
      "x": -15,
      "y": 3,
      "z": -13,
      "name": "Empty"
    },
    {
      "x": -15,
      "y": 4,
      "z": -13,
      "name": "Empty"
    },
    {
      "x": -15,
      "y": 0,
      "z": -12,
      "name": "Empty"
    },
    {
      "x": -15,
      "y": 1,
      "z": -12,
      "name": "Empty"
    },
    {
      "x": -15,
      "y": 2,
      "z": -12,
      "name": "Empty"
    },
    {
      "x": -15,
      "y": 3,
      "z": -12,
      "name": "Empty"
    },
    {
      "x": -15,
      "y": 4,
      "z": -12,
      "name": "Empty"
    },
    {
      "x": -15,
      "y": 0,
      "z": -11,
      "name": "Empty"
    },
    {
      "x": -15,
      "y": 1,
      "z": -11,
      "name": "Empty"
    },
    {
      "x": -15,
      "y": 2,
      "z": -11,
      "name": "Empty"
    },
    {
      "x": -15,
      "y": 3,
      "z": -11,
      "name": "Empty"
    },
    {
      "x": -15,
      "y": 4,
      "z": -11,
      "name": "Empty"
    },
    {
      "x": -15,
      "y": 0,
      "z": -10,
      "name": "Empty"
    },
    {
      "x": -15,
      "y": 1,
      "z": -10,
      "name": "Empty"
    },
    {
      "x": -15,
      "y": 2,
      "z": -10,
      "name": "Empty"
    },
    {
      "x": -15,
      "y": 3,
      "z": -10,
      "name": "Empty"
    },
    {
      "x": -15,
      "y": 4,
      "z": -10,
      "name": "Empty"
    },
    {
      "x": -15,
      "y": 0,
      "z": -9,
      "name": "Empty"
    },
    {
      "x": -15,
      "y": 1,
      "z": -9,
      "name": "Empty"
    },
    {
      "x": -15,
      "y": 2,
      "z": -9,
      "name": "Empty"
    },
    {
      "x": -15,
      "y": 3,
      "z": -9,
      "name": "Empty"
    },
    {
      "x": -15,
      "y": 4,
      "z": -9,
      "name": "Empty"
    },
    {
      "x": -15,
      "y": 0,
      "z": -8,
      "name": "Empty"
    },
    {
      "x": -15,
      "y": 1,
      "z": -8,
      "name": "Empty"
    },
    {
      "x": -15,
      "y": 2,
      "z": -8,
      "name": "Empty"
    },
    {
      "x": -15,
      "y": 3,
      "z": -8,
      "name": "Empty"
    },
    {
      "x": -15,
      "y": 4,
      "z": -8,
      "name": "Empty"
    },
    {
      "x": -15,
      "y": 0,
      "z": -7,
      "name": "Empty"
    },
    {
      "x": -15,
      "y": 1,
      "z": -7,
      "name": "Empty"
    },
    {
      "x": -15,
      "y": 2,
      "z": -7,
      "name": "Empty"
    },
    {
      "x": -15,
      "y": 3,
      "z": -7,
      "name": "Empty"
    },
    {
      "x": -15,
      "y": 4,
      "z": -7,
      "name": "Empty"
    },
    {
      "x": -15,
      "y": 0,
      "z": -6,
      "name": "Empty"
    },
    {
      "x": -15,
      "y": 1,
      "z": -6,
      "name": "Empty"
    },
    {
      "x": -15,
      "y": 2,
      "z": -6,
      "name": "Empty"
    },
    {
      "x": -15,
      "y": 3,
      "z": -6,
      "name": "Empty"
    },
    {
      "x": -15,
      "y": 4,
      "z": -6,
      "name": "Empty"
    },
    {
      "x": -15,
      "y": 0,
      "z": -5,
      "name": "Empty"
    },
    {
      "x": -15,
      "y": 1,
      "z": -5,
      "name": "Empty"
    },
    {
      "x": -15,
      "y": 2,
      "z": -5,
      "name": "Empty"
    },
    {
      "x": -15,
      "y": 3,
      "z": -5,
      "name": "Empty"
    },
    {
      "x": -15,
      "y": 4,
      "z": -5,
      "name": "Empty"
    },
    {
      "x": -15,
      "y": 0,
      "z": -4,
      "name": "Empty"
    },
    {
      "x": -15,
      "y": 1,
      "z": -4,
      "name": "Empty"
    },
    {
      "x": -15,
      "y": 2,
      "z": -4,
      "name": "Empty"
    },
    {
      "x": -15,
      "y": 3,
      "z": -4,
      "name": "Empty"
    },
    {
      "x": -15,
      "y": 4,
      "z": -4,
      "name": "Empty"
    },
    {
      "x": -15,
      "y": 0,
      "z": -3,
      "name": "Rock_Sandstone_White_Brick"
    },
    {
      "x": -15,
      "y": 1,
      "z": -3,
      "name": "Rock_Sandstone_White_Brick"
    },
    {
      "x": -15,
      "y": 2,
      "z": -3,
      "name": "Rock_Sandstone_White_Brick"
    },
    {
      "x": -15,
      "y": 3,
      "z": -3,
      "name": "Rock_Sandstone_White_Brick"
    },
    {
      "x": -15,
      "y": 4,
      "z": -3,
      "name": "Empty"
    },
    {
      "x": -15,
      "y": 0,
      "z": -2,
      "name": "Rock_Sandstone_White_Brick_Smooth_Half",
      "rotation": 4
    },
    {
      "x": -15,
      "y": 1,
      "z": -2,
      "name": "Rock_Sandstone_White_Brick_Half",
      "rotation": 4
    },
    {
      "x": -15,
      "y": 2,
      "z": -2,
      "name": "Rock_Sandstone_White_Brick_Half",
      "rotation": 4
    },
    {
      "x": -15,
      "y": 3,
      "z": -2,
      "name": "Rock_Sandstone_White_Brick"
    },
    {
      "x": -15,
      "y": 4,
      "z": -2,
      "name": "Rock_Sandstone_White_Brick_Half"
    },
    {
      "x": -15,
      "y": 0,
      "z": -1,
      "name": "Empty"
    },
    {
      "x": -15,
      "y": 1,
      "z": -1,
      "name": "Empty"
    },
    {
      "x": -15,
      "y": 2,
      "z": -1,
      "name": "Empty"
    },
    {
      "x": -15,
      "y": 3,
      "z": -1,
      "name": "Rock_Sandstone_White_Brick_Smooth_Half",
      "rotation": 8
    },
    {
      "x": -15,
      "y": 4,
      "z": -1,
      "name": "Rock_Sandstone_White_Brick"
    },
    {
      "x": -15,
      "y": 0,
      "z": 0,
      "name": "Empty"
    },
    {
      "x": -15,
      "y": 1,
      "z": 0,
      "name": "Empty"
    },
    {
      "x": -15,
      "y": 2,
      "z": 0,
      "name": "Empty"
    },
    {
      "x": -15,
      "y": 3,
      "z": 0,
      "name": "Rock_Sandstone_White_Brick_Smooth_Half",
      "rotation": 8
    },
    {
      "x": -15,
      "y": 4,
      "z": 0,
      "name": "Rock_Sandstone_White_Brick"
    },
    {
      "x": -15,
      "y": 0,
      "z": 1,
      "name": "Empty"
    },
    {
      "x": -15,
      "y": 1,
      "z": 1,
      "name": "Empty"
    },
    {
      "x": -15,
      "y": 2,
      "z": 1,
      "name": "Empty"
    },
    {
      "x": -15,
      "y": 3,
      "z": 1,
      "name": "Rock_Sandstone_White_Brick_Half",
      "rotation": 8
    },
    {
      "x": -15,
      "y": 4,
      "z": 1,
      "name": "Rock_Sandstone_White_Brick"
    },
    {
      "x": -15,
      "y": 0,
      "z": 2,
      "name": "Rock_Sandstone_White_Brick_Half",
      "rotation": 6
    },
    {
      "x": -15,
      "y": 1,
      "z": 2,
      "name": "Rock_Sandstone_White_Brick_Smooth_Half",
      "rotation": 6
    },
    {
      "x": -15,
      "y": 2,
      "z": 2,
      "name": "Rock_Sandstone_White_Brick_Smooth_Half",
      "rotation": 6
    },
    {
      "x": -15,
      "y": 3,
      "z": 2,
      "name": "Rock_Sandstone_White_Brick"
    },
    {
      "x": -15,
      "y": 4,
      "z": 2,
      "name": "Rock_Sandstone_White_Brick_Smooth_Half"
    },
    {
      "x": -15,
      "y": 0,
      "z": 3,
      "name": "Rock_Sandstone_White_Brick"
    },
    {
      "x": -15,
      "y": 1,
      "z": 3,
      "name": "Rock_Sandstone_White_Brick"
    },
    {
      "x": -15,
      "y": 2,
      "z": 3,
      "name": "Rock_Sandstone_White_Brick"
    },
    {
      "x": -15,
      "y": 3,
      "z": 3,
      "name": "Rock_Sandstone_White_Brick"
    },
    {
      "x": -15,
      "y": 4,
      "z": 3,
      "name": "Empty"
    },
    {
      "x": -15,
      "y": 0,
      "z": 4,
      "name": "Empty"
    },
    {
      "x": -15,
      "y": 1,
      "z": 4,
      "name": "Empty"
    },
    {
      "x": -15,
      "y": 2,
      "z": 4,
      "name": "Empty"
    },
    {
      "x": -15,
      "y": 3,
      "z": 4,
      "name": "Empty"
    },
    {
      "x": -15,
      "y": 4,
      "z": 4,
      "name": "Empty"
    },
    {
      "x": -15,
      "y": 0,
      "z": 5,
      "name": "Empty"
    },
    {
      "x": -15,
      "y": 1,
      "z": 5,
      "name": "Empty"
    },
    {
      "x": -15,
      "y": 2,
      "z": 5,
      "name": "Empty"
    },
    {
      "x": -15,
      "y": 3,
      "z": 5,
      "name": "Empty"
    },
    {
      "x": -15,
      "y": 4,
      "z": 5,
      "name": "Empty"
    },
    {
      "x": -15,
      "y": 0,
      "z": 6,
      "name": "Empty"
    },
    {
      "x": -15,
      "y": 1,
      "z": 6,
      "name": "Empty"
    },
    {
      "x": -15,
      "y": 2,
      "z": 6,
      "name": "Empty"
    },
    {
      "x": -15,
      "y": 3,
      "z": 6,
      "name": "Empty"
    },
    {
      "x": -15,
      "y": 4,
      "z": 6,
      "name": "Empty"
    },
    {
      "x": -15,
      "y": 0,
      "z": 7,
      "name": "Empty"
    },
    {
      "x": -15,
      "y": 1,
      "z": 7,
      "name": "Empty"
    },
    {
      "x": -15,
      "y": 2,
      "z": 7,
      "name": "Empty"
    },
    {
      "x": -15,
      "y": 3,
      "z": 7,
      "name": "Empty"
    },
    {
      "x": -15,
      "y": 4,
      "z": 7,
      "name": "Empty"
    },
    {
      "x": -15,
      "y": 0,
      "z": 8,
      "name": "Empty"
    },
    {
      "x": -15,
      "y": 1,
      "z": 8,
      "name": "Empty"
    },
    {
      "x": -15,
      "y": 2,
      "z": 8,
      "name": "Empty"
    },
    {
      "x": -15,
      "y": 3,
      "z": 8,
      "name": "Empty"
    },
    {
      "x": -15,
      "y": 4,
      "z": 8,
      "name": "Empty"
    },
    {
      "x": -15,
      "y": 0,
      "z": 9,
      "name": "Empty"
    },
    {
      "x": -15,
      "y": 1,
      "z": 9,
      "name": "Empty"
    },
    {
      "x": -15,
      "y": 2,
      "z": 9,
      "name": "Empty"
    },
    {
      "x": -15,
      "y": 3,
      "z": 9,
      "name": "Empty"
    },
    {
      "x": -15,
      "y": 4,
      "z": 9,
      "name": "Empty"
    },
    {
      "x": -15,
      "y": 0,
      "z": 10,
      "name": "Empty"
    },
    {
      "x": -15,
      "y": 1,
      "z": 10,
      "name": "Empty"
    },
    {
      "x": -15,
      "y": 2,
      "z": 10,
      "name": "Empty"
    },
    {
      "x": -15,
      "y": 3,
      "z": 10,
      "name": "Empty"
    },
    {
      "x": -15,
      "y": 4,
      "z": 10,
      "name": "Empty"
    },
    {
      "x": -15,
      "y": 0,
      "z": 11,
      "name": "Empty"
    },
    {
      "x": -15,
      "y": 1,
      "z": 11,
      "name": "Empty"
    },
    {
      "x": -15,
      "y": 2,
      "z": 11,
      "name": "Empty"
    },
    {
      "x": -15,
      "y": 3,
      "z": 11,
      "name": "Empty"
    },
    {
      "x": -15,
      "y": 4,
      "z": 11,
      "name": "Empty"
    },
    {
      "x": -15,
      "y": 0,
      "z": 12,
      "name": "Empty"
    },
    {
      "x": -15,
      "y": 1,
      "z": 12,
      "name": "Empty"
    },
    {
      "x": -15,
      "y": 2,
      "z": 12,
      "name": "Empty"
    },
    {
      "x": -15,
      "y": 3,
      "z": 12,
      "name": "Empty"
    },
    {
      "x": -15,
      "y": 4,
      "z": 12,
      "name": "Empty"
    },
    {
      "x": -15,
      "y": 0,
      "z": 13,
      "name": "Empty"
    },
    {
      "x": -15,
      "y": 1,
      "z": 13,
      "name": "Empty"
    },
    {
      "x": -15,
      "y": 2,
      "z": 13,
      "name": "Empty"
    },
    {
      "x": -15,
      "y": 3,
      "z": 13,
      "name": "Empty"
    },
    {
      "x": -15,
      "y": 4,
      "z": 13,
      "name": "Empty"
    },
    {
      "x": -15,
      "y": 0,
      "z": 14,
      "name": "Empty"
    },
    {
      "x": -15,
      "y": 1,
      "z": 14,
      "name": "Empty"
    },
    {
      "x": -15,
      "y": 2,
      "z": 14,
      "name": "Empty"
    },
    {
      "x": -15,
      "y": 3,
      "z": 14,
      "name": "Empty"
    },
    {
      "x": -15,
      "y": 4,
      "z": 14,
      "name": "Empty"
    },
    {
      "x": -15,
      "y": 0,
      "z": 15,
      "name": "Empty"
    },
    {
      "x": -15,
      "y": 1,
      "z": 15,
      "name": "Empty"
    },
    {
      "x": -15,
      "y": 2,
      "z": 15,
      "name": "Empty"
    },
    {
      "x": -15,
      "y": 3,
      "z": 15,
      "name": "Empty"
    },
    {
      "x": -15,
      "y": 4,
      "z": 15,
      "name": "Empty"
    },
    {
      "x": -15,
      "y": 0,
      "z": 16,
      "name": "Empty"
    },
    {
      "x": -15,
      "y": 1,
      "z": 16,
      "name": "Empty"
    },
    {
      "x": -15,
      "y": 2,
      "z": 16,
      "name": "Empty"
    },
    {
      "x": -15,
      "y": 3,
      "z": 16,
      "name": "Empty"
    },
    {
      "x": -15,
      "y": 4,
      "z": 16,
      "name": "Empty"
    },
    {
      "x": -15,
      "y": 0,
      "z": 17,
      "name": "Rock_Sandstone_White_Brick"
    },
    {
      "x": -15,
      "y": 1,
      "z": 17,
      "name": "Rock_Sandstone_White_Brick"
    },
    {
      "x": -15,
      "y": 2,
      "z": 17,
      "name": "Rock_Sandstone_White"
    },
    {
      "x": -15,
      "y": 3,
      "z": 17,
      "name": "Rock_Sandstone_White_Brick"
    },
    {
      "x": -15,
      "y": 4,
      "z": 17,
      "name": "Rock_Sandstone_White"
    },
    {
      "x": -15,
      "y": 0,
      "z": 18,
      "name": "Rock_Sandstone_White"
    },
    {
      "x": -15,
      "y": 1,
      "z": 18,
      "name": "Rock_Sandstone_White_Brick"
    },
    {
      "x": -15,
      "y": 2,
      "z": 18,
      "name": "Rock_Sandstone_White_Brick"
    },
    {
      "x": -15,
      "y": 3,
      "z": 18,
      "name": "Rock_Sandstone_White_Brick"
    },
    {
      "x": -15,
      "y": 4,
      "z": 18,
      "name": "Rock_Sandstone_White_Brick"
    },
    {
      "x": -15,
      "y": 0,
      "z": 19,
      "name": "Rock_Sandstone_White"
    },
    {
      "x": -15,
      "y": 1,
      "z": 19,
      "name": "Rock_Sandstone_White_Brick"
    },
    {
      "x": -15,
      "y": 2,
      "z": 19,
      "name": "Rock_Sandstone_White_Brick"
    },
    {
      "x": -15,
      "y": 3,
      "z": 19,
      "name": "Rock_Sandstone_White_Brick"
    },
    {
      "x": -15,
      "y": 4,
      "z": 19,
      "name": "Rock_Sandstone_White_Brick"
    },
    {
      "x": -15,
      "y": 0,
      "z": 20,
      "name": "Empty"
    },
    {
      "x": -15,
      "y": 1,
      "z": 20,
      "name": "Empty"
    },
    {
      "x": -15,
      "y": 2,
      "z": 20,
      "name": "Empty"
    },
    {
      "x": -15,
      "y": 3,
      "z": 20,
      "name": "Empty"
    },
    {
      "x": -15,
      "y": 4,
      "z": 20,
      "name": "Empty"
    },
    {
      "x": -14,
      "y": 0,
      "z": -19,
      "name": "Empty"
    },
    {
      "x": -14,
      "y": 1,
      "z": -19,
      "name": "Empty"
    },
    {
      "x": -14,
      "y": 2,
      "z": -19,
      "name": "Empty"
    },
    {
      "x": -14,
      "y": 3,
      "z": -19,
      "name": "Empty"
    },
    {
      "x": -14,
      "y": 4,
      "z": -19,
      "name": "Empty"
    },
    {
      "x": -14,
      "y": 0,
      "z": -18,
      "name": "Rock_Sandstone_White_Brick",
      "rotation": 3
    },
    {
      "x": -14,
      "y": 1,
      "z": -18,
      "name": "Rock_Sandstone_White",
      "rotation": 3
    },
    {
      "x": -14,
      "y": 2,
      "z": -18,
      "name": "Rock_Sandstone_White_Brick",
      "rotation": 3
    },
    {
      "x": -14,
      "y": 3,
      "z": -18,
      "name": "Rock_Sandstone_White_Brick",
      "rotation": 3
    },
    {
      "x": -14,
      "y": 4,
      "z": -18,
      "name": "Rock_Sandstone_White",
      "rotation": 3
    },
    {
      "x": -14,
      "y": 0,
      "z": -17,
      "name": "Rock_Sandstone_White_Brick",
      "rotation": 3
    },
    {
      "x": -14,
      "y": 1,
      "z": -17,
      "name": "Rock_Sandstone_White",
      "rotation": 3
    },
    {
      "x": -14,
      "y": 2,
      "z": -17,
      "name": "Rock_Sandstone_White_Brick",
      "rotation": 3
    },
    {
      "x": -14,
      "y": 3,
      "z": -17,
      "name": "Rock_Sandstone_White",
      "rotation": 3
    },
    {
      "x": -14,
      "y": 4,
      "z": -17,
      "name": "Rock_Sandstone_White",
      "rotation": 3
    },
    {
      "x": -14,
      "y": 0,
      "z": -16,
