{
  "version": 8,
  "blockIdVersion": 11,
  "anchorX": 0,
  "anchorY": 0,
  "anchorZ": 0,
  "blocks": [
    {
      "x": -1,
      "y": 0,
      "z": -19,
      "name": "Rock_Sandstone_White"
    },
    {
      "x": -1,
      "y": 1,
      "z": -19,
      "name": "Rock_Sandstone_White"
    },
    {
      "x": -1,
      "y": 2,
      "z": -19,
      "name": "Rock_Sandstone_White_Brick"
    },
    {
      "x": -1,
      "y": 3,
      "z": -19,
      "name": "Rock_Sandstone_White"
    },
    {
      "x": -1,
      "y": 4,
      "z": -19,
      "name": "Rock_Sandstone_White_Brick_Smooth_Half"
    },
    {
      "x": -1,
      "y": 0,
      "z": -18,
      "name": "Rock_Sandstone_White"
    },
    {
      "x": -1,
      "y": 1,
      "z": -18,
      "name": "Rock_Sandstone_White_Brick"
    },
    {
      "x": -1,
      "y": 2,
      "z": -18,
      "name": "Rock_Sandstone_White_Brick"
    },
    {
      "x": -1,
      "y": 3,
      "z": -18,
      "name": "Rock_Sandstone_White"
    },
    {
      "x": -1,
      "y": 4,
      "z": -18,
      "name": "Rock_Sandstone_White"
    },
    {
      "x": -1,
      "y": 0,
      "z": -17,
      "name": "Rock_Sandstone_White"
    },
    {
      "x": -1,
      "y": 1,
      "z": -17,
      "name": "Rock_Sandstone_White"
    },
    {
      "x": -1,
      "y": 2,
      "z": -17,
      "name": "Rock_Sandstone_White_Brick"
    },
    {
      "x": -1,
      "y": 3,
      "z": -17,
      "name": "Rock_Sandstone_White_Brick"
    },
    {
      "x": -1,
      "y": 4,
      "z": -17,
      "name": "Rock_Sandstone_White_Brick"
    },
    {
      "x": -1,
      "y": 0,
      "z": -16,
      "name": "Rock_Sandstone_White_Brick"
    },
    {
      "x": -1,
      "y": 1,
      "z": -16,
      "name": "Rock_Sandstone_White"
    },
    {
      "x": -1,
      "y": 2,
      "z": -16,
      "name": "Rock_Sandstone_White"
    },
    {
      "x": -1,
      "y": 3,
      "z": -16,
      "name": "Rock_Sandstone_White_Brick"
    },
    {
      "x": -1,
      "y": 4,
      "z": -16,
      "name": "Rock_Sandstone_White"
    },
    {
      "x": -1,
      "y": 0,
      "z": -15,
      "name": "Rock_Sandstone_White_Brick"
    },
    {
      "x": -1,
      "y": 1,
      "z": -15,
      "name": "Rock_Sandstone_White_Brick"
    },
    {
      "x": -1,
      "y": 2,
      "z": -15,
      "name": "Rock_Sandstone_White"
    },
    {
      "x": -1,
      "y": 3,
      "z": -15,
      "name": "Rock_Sandstone_White"
    },
    {
      "x": -1,
      "y": 4,
      "z": -15,
      "name": "Rock_Sandstone_White_Brick"
    },
    {
      "x": -1,
      "y": 0,
      "z": -14,
      "name": "Rock_Sandstone_White"
    },
    {
      "x": -1,
      "y": 1,
      "z": -14,
      "name": "Rock_Sandstone_White_Brick"
    },
    {
      "x": -1,
      "y": 2,
      "z": -14,
      "name": "Rock_Sandstone_White_Brick"
    },
    {
      "x": -1,
      "y": 3,
      "z": -14,
      "name": "Rock_Sandstone_White_Brick"
    },
    {
      "x": -1,
      "y": 4,
      "z": -14,
      "name": "Rock_Sandstone_White"
    },
    {
      "x": -1,
      "y": 0,
      "z": -13,
      "name": "Rock_Sandstone_White_Brick"
    },
    {
      "x": -1,
      "y": 1,
      "z": -13,
      "name": "Rock_Sandstone_White_Brick"
    },
    {
      "x": -1,
      "y": 2,
      "z": -13,
      "name": "Rock_Sandstone_White_Brick"
    },
    {
      "x": -1,
      "y": 3,
      "z": -13,
      "name": "Rock_Sandstone_White_Brick"
    },
    {
      "x": -1,
      "y": 4,
      "z": -13,
      "name": "Rock_Sandstone_White_Brick"
    },
    {
      "x": -1,
      "y": 0,
      "z": -12,
      "name": "Rock_Sandstone_White_Brick"
    },
    {
      "x": -1,
      "y": 1,
      "z": -12,
      "name": "Rock_Sandstone_White"
    },
    {
      "x": -1,
      "y": 2,
      "z": -12,
      "name": "Rock_Sandstone_White"
    },
    {
      "x": -1,
      "y": 3,
      "z": -12,
      "name": "Rock_Sandstone_White_Brick"
    },
    {
      "x": -1,
      "y": 4,
      "z": -12,
      "name": "Rock_Sandstone_White_Brick"
    },
    {
      "x": -1,
      "y": 0,
      "z": -11,
      "name": "Rock_Sandstone_White_Brick_Smooth_Half",
      "rotation": 4
    },
    {
      "x": -1,
      "y": 1,
      "z": -11,
      "name": "Rock_Sandstone_White_Brick_Smooth_Half",
      "rotation": 4
    },
    {
      "x": -1,
      "y": 2,
      "z": -11,
      "name": "Rock_Sandstone_White_Brick_Half",
      "rotation": 4
    },
    {
      "x": -1,
      "y": 3,
      "z": -11,
      "name": "Rock_Sandstone_White_Brick_Half",
      "rotation": 4
    },
    {
      "x": -1,
      "y": 4,
      "z": -11,
      "name": "Rock_Sandstone_White_Brick_Half",
      "rotation": 4
    },
    {
      "x": -1,
      "y": 0,
      "z": -8,
      "name": "Rock_Sandstone_White_Brick_Smooth_Half",
      "rotation": 6
    },
    {
      "x": -1,
      "y": 1,
      "z": -8,
      "name": "Rock_Sandstone_White_Brick_Smooth_Half",
      "rotation": 6
    },
    {
      "x": -1,
      "y": 2,
      "z": -8,
      "name": "Rock_Sandstone_White_Brick_Half",
      "rotation": 6
    },
    {
      "x": -1,
      "y": 3,
      "z": -8,
      "name": "Rock_Sandstone_White_Brick_Smooth_Half",
      "rotation": 6
    },
    {
      "x": -1,
      "y": 4,
      "z": -8,
      "name": "Rock_Sandstone_White_Brick_Half",
      "rotation": 6
    },
    {
      "x": -1,
      "y": 0,
      "z": -7,
      "name": "Rock_Sandstone_White"
    },
    {
      "x": -1,
      "y": 1,
      "z": -7,
      "name": "Rock_Sandstone_White_Brick"
    },
    {
      "x": -1,
      "y": 2,
      "z": -7,
      "name": "Rock_Sandstone_White"
    },
    {
      "x": -1,
      "y": 3,
      "z": -7,
      "name": "Rock_Sandstone_White_Brick"
    },
    {
      "x": -1,
      "y": 4,
      "z": -7,
      "name": "Rock_Sandstone_White_Brick"
    },
    {
      "x": -1,
      "y": 0,
      "z": -6,
      "name": "Rock_Sandstone_White_Brick"
    },
    {
      "x": -1,
      "y": 1,
      "z": -6,
      "name": "Rock_Sandstone_White"
    },
    {
      "x": -1,
      "y": 2,
      "z": -6,
      "name": "Rock_Sandstone_White_Brick"
    },
    {
      "x": -1,
      "y": 3,
      "z": -6,
      "name": "Rock_Sandstone_White"
    },
    {
      "x": -1,
      "y": 4,
      "z": -6,
      "name": "Rock_Sandstone_White_Brick_Smooth_Half",
      "rotation": 7
    },
    {
      "x": -1,
      "y": 0,
      "z": -5,
      "name": "Rock_Sandstone_White"
    },
    {
      "x": -1,
      "y": 1,
      "z": -5,
      "name": "Rock_Sandstone_White_Brick"
    },
    {
      "x": -1,
      "y": 2,
      "z": -5,
      "name": "Rock_Sandstone_White"
    },
    {
      "x": -1,
      "y": 3,
      "z": -5,
      "name": "Rock_Sandstone_White_Brick_Half"
    },
    {
      "x": -1,
      "y": 0,
      "z": -4,
      "name": "Rock_Sandstone_White"
    },
    {
      "x": -1,
      "y": 1,
      "z": -4,
      "name": "Rock_Sandstone_White"
    },
    {
      "x": -1,
      "y": 2,
      "z": -4,
      "name": "Rock_Sandstone_White_Brick"
    },
    {
      "x": -1,
      "y": 3,
      "z": -4,
      "name": "Rock_Sandstone_White"
    },
    {
      "x": -1,
      "y": 4,
      "z": -4,
      "name": "Rock_Sandstone_White_Brick"
    },
    {
      "x": -1,
      "y": 0,
      "z": -3,
      "name": "Rock_Sandstone_White_Brick"
    },
    {
      "x": -1,
      "y": 1,
      "z": -3,
      "name": "Rock_Sandstone_White_Brick"
    },
    {
      "x": -1,
      "y": 2,
      "z": -3,
      "name": "Rock_Sandstone_White_Brick"
    },
    {
      "x": -1,
      "y": 3,
      "z": -3,
      "name": "Rock_Sandstone_White"
    },
    {
      "x": -1,
      "y": 4,
      "z": -3,
      "name": "Rock_Sandstone_White_Brick"
    },
    {
      "x": -1,
      "y": 0,
      "z": -2,
      "name": "Rock_Sandstone_White_Brick_Smooth_Half",
      "rotation": 4
    },
    {
      "x": -1,
      "y": 1,
      "z": -2,
      "name": "Rock_Sandstone_White_Brick_Half",
      "rotation": 4
    },
    {
      "x": -1,
      "y": 2,
      "z": -2,
      "name": "Rock_Sandstone_White_Brick_Half",
      "rotation": 4
    },
    {
      "x": -1,
      "y": 3,
      "z": -2,
      "name": "Rock_Sandstone_White_Brick_Smooth_Half",
      "rotation": 4
    },
    {
      "x": -1,
      "y": 0,
      "z": -1,
      "name": "Rock_Sandstone_White_Brick_Half",
      "rotation": 6
    },
    {
      "x": -1,
      "y": 0,
      "z": 0,
      "name": "Rock_Sandstone_White_Brick"
    },
    {
      "x": -1,
      "y": 1,
      "z": 0,
      "name": "Rock_Sandstone_White_Brick"
    },
    {
      "x": -1,
      "y": 2,
      "z": 0,
      "name": "Rock_Sandstone_White_Brick"
    },
    {
      "x": -1,
      "y": 3,
      "z": 0,
      "name": "Rock_Sandstone_White_Brick"
    },
    {
      "x": -1,
      "y": 4,
      "z": 0,
      "name": "Rock_Sandstone_White_Brick"
    },
    {
      "x": -1,
      "y": 0,
      "z": 1,
      "name": "Rock_Sandstone_White_Brick"
    },
    {
      "x": -1,
      "y": 1,
      "z": 1,
      "name": "Rock_Sandstone_White"
    },
    {
      "x": -1,
      "y": 2,
      "z": 1,
      "name": "Rock_Sandstone_White"
    },
    {
      "x": -1,
      "y": 3,
      "z": 1,
      "name": "Rock_Sandstone_White"
    },
    {
      "x": -1,
      "y": 4,
      "z": 1,
      "name": "Rock_Sandstone_White"
    },
    {
      "x": -1,
      "y": 0,
      "z": 2,
      "name": "Rock_Sandstone_White_Brick"
    },
    {
      "x": -1,
      "y": 1,
      "z": 2,
      "name": "Rock_Sandstone_White"
    },
    {
      "x": -1,
      "y": 2,
      "z": 2,
      "name": "Rock_Sandstone_White_Brick"
    },
    {
      "x": -1,
      "y": 3,
      "z": 2,
      "name": "Rock_Sandstone_White_Brick"
    },
    {
      "x": -1,
      "y": 4,
      "z": 2,
      "name": "Rock_Sandstone_White"
    },
    {
      "x": -1,
      "y": 0,
      "z": 3,
      "name": "Rock_Sandstone_White"
    },
    {
      "x": -1,
      "y": 1,
      "z": 3,
      "name": "Rock_Sandstone_White_Brick"
    },
    {
      "x": -1,
      "y": 2,
      "z": 3,
      "name": "Rock_Sandstone_White_Brick"
    },
    {
      "x": -1,
      "y": 3,
      "z": 3,
      "name": "Rock_Sandstone_White"
    },
    {
      "x": -1,
      "y": 4,
      "z": 3,
      "name": "Rock_Sandstone_White_Brick_Half",
      "rotation": 4
    },
    {
      "x": -1,
      "y": 0,
      "z": 4,
      "name": "Rock_Sandstone_White"
    },
    {
      "x": -1,
      "y": 1,
      "z": 4,
      "name": "Rock_Sandstone_White_Brick"
    },
    {
      "x": -1,
      "y": 2,
      "z": 4,
      "name": "Rock_Sandstone_White_Brick"
    },
    {
      "x": -1,
      "y": 3,
      "z": 4,
      "name": "Rock_Sandstone_White_Brick_Smooth_Half"
    },
    {
      "x": -1,
      "y": 0,
      "z": 5,
      "name": "Rock_Sandstone_White"
    },
    {
      "x": -1,
      "y": 1,
      "z": 5,
      "name": "Rock_Sandstone_White_Brick"
    },
    {
      "x": -1,
      "y": 2,
      "z": 5,
      "name": "Rock_Sandstone_White_Brick"
    },
    {
      "x": -1,
      "y": 0,
      "z": 6,
      "name": "Rock_Sandstone_White_Brick"
    },
    {
      "x": -1,
      "y": 1,
      "z": 6,
      "name": "Rock_Sandstone_White_Brick"
    },
    {
      "x": -1,
      "y": 2,
      "z": 6,
      "name": "Rock_Sandstone_White_Brick"
    },
    {
      "x": -1,
      "y": 3,
      "z": 6,
      "name": "Rock_Sandstone_White"
    },
    {
      "x": -1,
      "y": 4,
      "z": 6,
      "name": "Rock_Sandstone_White_Brick_Half"
    },
    {
      "x": -1,
      "y": 0,
      "z": 7,
      "name": "Rock_Sandstone_White_Brick"
    },
    {
      "x": -1,
      "y": 1,
      "z": 7,
      "name": "Rock_Sandstone_White"
    },
    {
      "x": -1,
      "y": 2,
      "z": 7,
      "name": "Rock_Sandstone_White_Brick"
    },
    {
      "x": -1,
      "y": 3,
      "z": 7,
      "name": "Rock_Sandstone_White_Brick"
    },
    {
      "x": -1,
      "y": 4,
      "z": 7,
      "name": "Rock_Sandstone_White"
    },
    {
      "x": -1,
      "y": 0,
      "z": 8,
      "name": "Rock_Sandstone_White"
    },
    {
      "x": -1,
      "y": 1,
      "z": 8,
      "name": "Rock_Sandstone_White"
    },
    {
      "x": -1,
      "y": 2,
      "z": 8,
      "name": "Rock_Sandstone_White_Brick"
    },
    {
      "x": -1,
      "y": 3,
      "z": 8,
      "name": "Rock_Sandstone_White"
    },
    {
      "x": -1,
      "y": 4,
      "z": 8,
      "name": "Rock_Sandstone_White"
    },
    {
      "x": -1,
      "y": 0,
      "z": 9,
      "name": "Rock_Sandstone_White_Brick"
    },
    {
      "x": -1,
      "y": 1,
      "z": 9,
      "name": "Rock_Sandstone_White"
    },
    {
      "x": -1,
      "y": 2,
      "z": 9,
      "name": "Rock_Sandstone_White"
    },
    {
      "x": -1,
      "y": 3,
      "z": 9,
      "name": "Rock_Sandstone_White"
    },
    {
      "x": -1,
      "y": 4,
      "z": 9,
      "name": "Rock_Sandstone_White"
    },
    {
      "x": -1,
      "y": 0,
      "z": 10,
      "name": "Rock_Sandstone_White"
    },
    {
      "x": -1,
      "y": 1,
      "z": 10,
      "name": "Rock_Sandstone_White"
    },
    {
      "x": -1,
      "y": 2,
      "z": 10,
      "name": "Rock_Sandstone_White"
    },
    {
      "x": -1,
      "y": 3,
      "z": 10,
      "name": "Rock_Sandstone_White_Brick"
    },
    {
      "x": -1,
      "y": 4,
      "z": 10,
      "name": "Rock_Sandstone_White"
    },
    {
      "x": -1,
      "y": 0,
      "z": 11,
      "name": "Rock_Sandstone_White"
    },
    {
      "x": -1,
      "y": 1,
      "z": 11,
      "name": "Rock_Sandstone_White_Brick"
    },
    {
      "x": -1,
      "y": 2,
      "z": 11,
      "name": "Rock_Sandstone_White_Brick"
    },
    {
      "x": -1,
      "y": 3,
      "z": 11,
      "name": "Rock_Sandstone_White"
    },
    {
      "x": -1,
      "y": 4,
      "z": 11,
      "name": "Rock_Sandstone_White"
    },
    {
      "x": -1,
      "y": 0,
      "z": 12,
      "name": "Rock_Sandstone_White"
    },
    {
      "x": -1,
      "y": 1,
      "z": 12,
      "name": "Rock_Sandstone_White"
    },
    {
      "x": -1,
      "y": 2,
      "z": 12,
      "name": "Rock_Sandstone_White_Brick"
    },
    {
      "x": -1,
      "y": 3,
      "z": 12,
      "name": "Rock_Sandstone_White"
    },
    {
      "x": -1,
      "y": 4,
      "z": 12,
      "name": "Rock_Sandstone_White_Brick"
    },
    {
      "x": -1,
      "y": 0,
      "z": 13,
      "name": "Rock_Sandstone_White_Brick"
    },
    {
      "x": -1,
      "y": 1,
      "z": 13,
      "name": "Rock_Sandstone_White"
    },
    {
      "x": -1,
      "y": 2,
      "z": 13,
      "name": "Rock_Sandstone_White_Brick"
    },
    {
      "x": -1,
      "y": 3,
      "z": 13,
      "name": "Rock_Sandstone_White_Brick"
    },
    {
      "x": -1,
      "y": 4,
      "z": 13,
      "name": "Rock_Sandstone_White_Brick_Half",
      "rotation": 4
    },
    {
      "x": -1,
      "y": 0,
      "z": 14,
      "name": "Rock_Sandstone_White_Brick"
    },
    {
      "x": -1,
      "y": 1,
      "z": 14,
      "name": "Rock_Sandstone_White"
    },
    {
      "x": -1,
      "y": 2,
      "z": 14,
      "name": "Rock_Sandstone_White"
    },
    {
      "x": -1,
      "y": 3,
      "z": 14,
      "name": "Rock_Sandstone_White_Brick"
    },
    {
      "x": -1,
      "y": 0,
      "z": 15,
      "name": "Rock_Sandstone_White_Brick"
    },
    {
      "x": -1,
      "y": 1,
      "z": 15,
      "name": "Rock_Sandstone_White_Brick"
    },
    {
      "x": -1,
      "y": 2,
      "z": 15,
      "name": "Rock_Sandstone_White_Brick"
    },
    {
      "x": -1,
      "y": 3,
      "z": 15,
      "name": "Rock_Sandstone_White_Brick"
    },
    {
      "x": -1,
      "y": 4,
      "z": 15,
      "name": "Rock_Sandstone_White_Brick_Half"
    },
    {
      "x": 0,
      "y": 0,
      "z": -19,
      "name": "Rock_Sandstone_White_Brick"
    },
    {
      "x": 0,
      "y": 1,
      "z": -19,
      "name": "Rock_Sandstone_White"
    },
    {
      "x": 0,
      "y": 2,
      "z": -19,
      "name": "Rock_Sandstone_White_Brick"
    },
    {
      "x": 0,
      "y": 3,
      "z": -19,
      "name": "Rock_Sandstone_White"
    },
    {
      "x": 0,
      "y": 4,
      "z": -19,
      "name": "Rock_Sandstone_White_Brick_Smooth_Half"
    },
    {
      "x": 0,
      "y": 0,
      "z": -18,
      "name": "Rock_Sandstone_White"
    },
    {
      "x": 0,
      "y": 1,
      "z": -18,
      "name": "Rock_Sandstone_White_Brick"
    },
    {
      "x": 0,
      "y": 2,
      "z": -18,
      "name": "Rock_Sandstone_White"
    },
    {
      "x": 0,
      "y": 3,
      "z": -18,
      "name": "Rock_Sandstone_White_Brick"
    },
    {
      "x": 0,
      "y": 4,
      "z": -18,
      "name": "Rock_Sandstone_White"
    },
    {
      "x": 0,
      "y": 0,
      "z": -17,
      "name": "Rock_Sandstone_White"
    },
    {
      "x": 0,
      "y": 1,
      "z": -17,
      "name": "Rock_Sandstone_White"
    },
    {
      "x": 0,
      "y": 2,
      "z": -17,
      "name": "Rock_Sandstone_White"
    },
    {
      "x": 0,
      "y": 3,
      "z": -17,
      "name": "Rock_Sandstone_White_Brick"
    },
    {
      "x": 0,
      "y": 4,
      "z": -17,
      "name": "Rock_Sandstone_White_Brick"
    },
    {
      "x": 0,
      "y": 0,
      "z": -16,
      "name": "Rock_Sandstone_White"
    },
    {
      "x": 0,
      "y": 1,
      "z": -16,
      "name": "Rock_Sandstone_White"
    },
    {
      "x": 0,
      "y": 2,
      "z": -16,
      "name": "Rock_Sandstone_White"
    },
    {
      "x": 0,
      "y": 3,
      "z": -16,
      "name": "Rock_Sandstone_White"
    },
    {
      "x": 0,
      "y": 4,
      "z": -16,
      "name": "Rock_Sandstone_White_Brick_Smooth_Half",
      "rotation": 5
    },
    {
      "x": 0,
      "y": 0,
      "z": -15,
      "name": "Rock_Sandstone_White"
    },
    {
      "x": 0,
      "y": 1,
      "z": -15,
      "name": "Rock_Sandstone_White_Brick"
    },
    {
      "x": 0,
      "y": 2,
      "z": -15,
      "name": "Rock_Sandstone_White"
    },
    {
      "x": 0,
      "y": 3,
      "z": -15,
      "name": "Rock_Sandstone_White"
    },
    {
      "x": 0,
      "y": 4,
      "z": -15,
      "name": "Rock_Sandstone_White_Brick_Smooth_Half",
      "rotation": 5
    },
    {
      "x": 0,
      "y": 0,
      "z": -14,
      "name": "Rock_Sandstone_White"
    },
    {
      "x": 0,
      "y": 1,
      "z": -14,
      "name": "Rock_Sandstone_White_Brick"
    },
    {
      "x": 0,
      "y": 2,
      "z": -14,
      "name": "Rock_Sandstone_White_Brick"
    },
    {
      "x": 0,
      "y": 3,
      "z": -14,
      "name": "Rock_Sandstone_White_Brick"
    },
    {
      "x": 0,
      "y": 4,
      "z": -14,
      "name": "Rock_Sandstone_White"
    },
    {
      "x": 0,
      "y": 0,
      "z": -13,
      "name": "Rock_Sandstone_White_Brick"
    },
    {
      "x": 0,
      "y": 1,
      "z": -13,
      "name": "Rock_Sandstone_White"
    },
    {
      "x": 0,
      "y": 2,
      "z": -13,
      "name": "Rock_Sandstone_White_Brick"
    },
    {
      "x": 0,
      "y": 3,
      "z": -13,
      "name": "Rock_Sandstone_White"
    },
    {
      "x": 0,
      "y": 4,
      "z": -13,
      "name": "Rock_Sandstone_White_Brick"
    },
    {
      "x": 0,
      "y": 0,
      "z": -12,
      "name": "Rock_Sandstone_White_Brick"
    },
    {
      "x": 0,
      "y": 1,
      "z": -12,
      "name": "Rock_Sandstone_White_Brick"
    },
    {
      "x": 0,
      "y": 2,
      "z": -12,
      "name": "Rock_Sandstone_White_Brick"
    },
    {
      "x": 0,
      "y": 3,
      "z": -12,
      "name": "Rock_Sandstone_White_Brick"
    },
    {
      "x": 0,
      "y": 4,
      "z": -12,
      "name": "Rock_Sandstone_White"
    },
    {
      "x": 0,
      "y": 0,
      "z": -11,
      "name": "Rock_Sandstone_White_Brick_Half",
      "rotation": 4
    },
    {
      "x": 0,
      "y": 1,
      "z": -11,
      "name": "Rock_Sandstone_White_Brick_Half",
      "rotation": 4
    },
    {
      "x": 0,
      "y": 2,
      "z": -11,
      "name": "Rock_Sandstone_White_Brick_Smooth_Half",
      "rotation": 4
    },
    {
      "x": 0,
      "y": 3,
      "z": -11,
      "name": "Rock_Sandstone_White_Brick_Smooth_Half",
      "rotation": 4
    },
    {
      "x": 0,
      "y": 4,
      "z": -11,
      "name": "Rock_Sandstone_White_Brick_Smooth_Half",
      "rotation": 4
    },
    {
      "x": 0,
      "y": 0,
      "z": -8,
      "name": "Rock_Sandstone_White_Brick_Half",
      "rotation": 6
    },
    {
      "x": 0,
      "y": 1,
      "z": -8,
      "name": "Rock_Sandstone_White_Brick_Half",
      "rotation": 6
    },
    {
      "x": 0,
      "y": 2,
      "z": -8,
      "name": "Rock_Sandstone_White_Brick_Half",
      "rotation": 6
    },
    {
      "x": 0,
      "y": 3,
      "z": -8,
      "name": "Rock_Sandstone_White_Brick_Smooth_Half",
      "rotation": 6
    },
    {
      "x": 0,
      "y": 4,
      "z": -8,
      "name": "Rock_Sandstone_White_Brick_Half",
      "rotation": 6
    },
    {
      "x": 0,
      "y": 0,
      "z": -7,
      "name": "Rock_Sandstone_White"
    },
    {
      "x": 0,
      "y": 1,
      "z": -7,
      "name": "Rock_Sandstone_White_Brick"
    },
    {
      "x": 0,
      "y": 2,
      "z": -7,
      "name": "Rock_Sandstone_White_Brick"
    },
    {
      "x": 0,
      "y": 3,
      "z": -7,
      "name": "Rock_Sandstone_White"
    },
    {
      "x": 0,
      "y": 4,
      "z": -7,
      "name": "Rock_Sandstone_White_Brick"
    },
    {
      "x": 0,
      "y": 0,
      "z": -6,
      "name": "Rock_Sandstone_White"
    },
    {
      "x": 0,
      "y": 1,
      "z": -6,
      "name": "Rock_Sandstone_White"
    },
    {
      "x": 0,
      "y": 2,
      "z": -6,
      "name": "Rock_Sandstone_White"
    },
    {
      "x": 0,
      "y": 3,
      "z": -6,
      "name": "Rock_Sandstone_White"
    },
    {
      "x": 0,
      "y": 4,
      "z": -6,
      "name": "Rock_Sandstone_White"
    },
    {
      "x": 0,
      "y": 0,
      "z": -5,
      "name": "Rock_Sandstone_White"
    },
    {
      "x": 0,
      "y": 1,
      "z": -5,
      "name": "Rock_Sandstone_White"
    },
    {
      "x": 0,
      "y": 2,
      "z": -5,
      "name": "Rock_Sandstone_White"
    },
    {
      "x": 0,
      "y": 3,
      "z": -5,
      "name": "Rock_Sandstone_White_Brick"
    },
    {
      "x": 0,
      "y": 4,
      "z": -5,
      "name": "Rock_Sandstone_White"
    },
    {
      "x": 0,
      "y": 0,
      "z": -4,
      "name": "Rock_Sandstone_White"
    },
    {
      "x": 0,
      "y": 1,
      "z": -4,
      "name": "Rock_Sandstone_White"
    },
    {
      "x": 0,
      "y": 2,
      "z": -4,
      "name": "Rock_Sandstone_White_Brick"
    },
    {
      "x": 0,
      "y": 3,
      "z": -4,
      "name": "Rock_Sandstone_White"
    },
    {
      "x": 0,
      "y": 4,
      "z": -4,
      "name": "Rock_Sandstone_White"
    },
    {
      "x": 0,
      "y": 0,
      "z": -3,
      "name": "Rock_Sandstone_White_Brick_Smooth_Half",
      "rotation": 4
    },
    {
      "x": 0,
      "y": 1,
      "z": -3,
      "name": "Rock_Sandstone_White_Brick_Half",
      "rotation": 4
    },
    {
      "x": 0,
      "y": 2,
      "z": -3,
      "name": "Rock_Sandstone_White_Brick_Half",
      "rotation": 4
    },
    {
      "x": 0,
      "y": 3,
      "z": -3,
      "name": "Rock_Sandstone_White_Brick_Smooth_Half",
      "rotation": 4
    },
    {
      "x": 0,
      "y": 0,
      "z": -1,
      "name": "Rock_Sandstone_White_Brick_Smooth_Half",
      "rotation": 6
    },
    {
      "x": 0,
      "y": 1,
      "z": -1,
      "name": "Rock_Sandstone_White_Brick_Smooth_Half",
      "rotation": 6
    },
    {
      "x": 0,
      "y": 2,
      "z": -1,
      "name": "Rock_Sandstone_White_Brick_Half",
      "rotation": 6
    },
    {
      "x": 0,
      "y": 3,
      "z": -1,
      "name": "Rock_Sandstone_White_Brick_Smooth_Half",
      "rotation": 6
    },
    {
      "x": 0,
      "y": 0,
      "z": 0,
      "name": "Rock_Sandstone_White"
    },
    {
      "x": 0,
      "y": 1,
      "z": 0,
      "name": "Rock_Sandstone_White_Brick"
    },
    {
      "x": 0,
      "y": 2,
      "z": 0,
      "name": "Rock_Sandstone_White_Brick"
    },
    {
      "x": 0,
      "y": 3,
      "z": 0,
      "name": "Rock_Sandstone_White_Brick"
    },
    {
      "x": 0,
      "y": 4,
      "z": 0,
      "name": "Rock_Sandstone_White"
    },
    {
      "x": 0,
      "y": 0,
      "z": 1,
      "name": "Rock_Sandstone_White"
    },
    {
      "x": 0,
      "y": 1,
      "z": 1,
      "name": "Rock_Sandstone_White"
    },
    {
      "x": 0,
      "y": 2,
      "z": 1,
      "name": "Rock_Sandstone_White"
    },
    {
      "x": 0,
      "y": 3,
      "z": 1,
      "name": "Rock_Sandstone_White"
    },
    {
      "x": 0,
      "y": 4,
      "z": 1,
      "name": "Rock_Sandstone_White_Brick"
    },
    {
      "x": 0,
      "y": 0,
      "z": 2,
      "name": "Rock_Sandstone_White"
    },
    {
      "x": 0,
      "y": 1,
      "z": 2,
      "name": "Rock_Sandstone_White"
    },
    {
      "x": 0,
      "y": 2,
      "z": 2,
      "name": "Rock_Sandstone_White"
    },
    {
      "x": 0,
      "y": 3,
      "z": 2,
      "name": "Rock_Sandstone_White"
    },
    {
      "x": 0,
      "y": 4,
      "z": 2,
      "name": "Rock_Sandstone_White_Brick"
    },
    {
      "x": 0,
      "y": 0,
      "z": 3,
      "name": "Rock_Sandstone_White_Brick"
    },
    {
      "x": 0,
      "y": 1,
      "z": 3,
      "name": "Rock_Sandstone_White"
    },
    {
      "x": 0,
      "y": 2,
      "z": 3,
      "name": "Rock_Sandstone_White_Brick"
    },
    {
      "x": 0,
      "y": 3,
      "z": 3,
      "name": "Rock_Sandstone_White"
    },
    {
      "x": 0,
      "y": 4,
      "z": 3,
      "name": "Rock_Sandstone_White_Brick"
    },
    {
      "x": 0,
      "y": 0,
      "z": 4,
      "name": "Rock_Sandstone_White"
    },
    {
      "x": 0,
      "y": 1,
      "z": 4,
      "name": "Rock_Sandstone_White_Brick"
    },
    {
      "x": 0,
      "y": 2,
      "z": 4,
      "name": "Rock_Sandstone_White_Brick"
    },
    {
      "x": 0,
      "y": 3,
      "z": 4,
      "name": "Rock_Sandstone_White_Brick"
    },
    {
      "x": 0,
      "y": 4,
      "z": 4,
      "name": "Rock_Sandstone_White_Brick_Half"
    },
    {
      "x": 0,
      "y": 0,
      "z": 5,
      "name": "Rock_Sandstone_White_Brick"
    },
    {
      "x": 0,
      "y": 1,
      "z": 5,
      "name": "Rock_Sandstone_White_Brick"
    },
    {
      "x": 0,
      "y": 2,
      "z": 5,
      "name": "Rock_Sandstone_White_Brick"
    },
    {
      "x": 0,
      "y": 3,
      "z": 5,
      "name": "Rock_Sandstone_White"
    },
    {
      "x": 0,
      "y": 0,
      "z": 6,
      "name": "Rock_Sandstone_White_Brick"
    },
    {
      "x": 0,
      "y": 1,
      "z": 6,
      "name": "Rock_Sandstone_White"
    },
    {
      "x": 0,
      "y": 2,
      "z": 6,
      "name": "Rock_Sandstone_White_Brick"
    },
    {
      "x": 0,
      "y": 3,
      "z": 6,
      "name": "Rock_Sandstone_White_Brick"
    },
    {
      "x": 0,
      "y": 4,
      "z": 6,
      "name": "Rock_Sandstone_White_Brick"
    },
    {
      "x": 0,
      "y": 0,
      "z": 7,
      "name": "Rock_Sandstone_White"
    },
    {
      "x": 0,
      "y": 1,
      "z": 7,
      "name": "Rock_Sandstone_White"
    },
    {
      "x": 0,
      "y": 2,
      "z": 7,
      "name": "Rock_Sandstone_White"
    },
    {
      "x": 0,
      "y": 3,
      "z": 7,
      "name": "Rock_Sandstone_White"
    },
    {
      "x": 0,
      "y": 4,
      "z": 7,
      "name": "Rock_Sandstone_White"
    },
    {
      "x": 0,
      "y": 0,
      "z": 8,
      "name": "Rock_Sandstone_White_Brick"
    },
    {
      "x": 0,
      "y": 1,
      "z": 8,
      "name": "Rock_Sandstone_White_Brick"
    },
    {
      "x": 0,
      "y": 2,
      "z": 8,
      "name": "Rock_Sandstone_White"
    },
    {
      "x": 0,
      "y": 3,
      "z": 8,
      "name": "Rock_Sandstone_White"
    },
    {
      "x": 0,
      "y": 4,
      "z": 8,
      "name": "Rock_Sandstone_White_Brick"
    },
    {
      "x": 0,
      "y": 0,
      "z": 9,
      "name": "Rock_Sandstone_White_Brick"
    },
    {
      "x": 0,
      "y": 1,
      "z": 9,
      "name": "Rock_Sandstone_White"
    },
    {
      "x": 0,
      "y": 2,
      "z": 9,
      "name": "Rock_Sandstone_White"
    },
    {
      "x": 0,
      "y": 3,
      "z": 9,
      "name": "Rock_Sandstone_White_Brick"
    },
    {
      "x": 0,
      "y": 4,
      "z": 9,
      "name": "Rock_Sandstone_White_Brick"
    },
    {
      "x": 0,
      "y": 0,
      "z": 10,
      "name": "Rock_Sandstone_White_Brick"
    },
    {
      "x": 0,
      "y": 1,
      "z": 10,
      "name": "Rock_Sandstone_White"
    },
    {
      "x": 0,
      "y": 2,
      "z": 10,
      "name": "Rock_Sandstone_White"
    },
    {
      "x": 0,
      "y": 3,
      "z": 10,
      "name": "Rock_Sandstone_White"
    },
    {
      "x": 0,
      "y": 4,
      "z": 10,
      "name": "Rock_Sandstone_White"
    },
    {
      "x": 0,
      "y": 0,
      "z": 11,
      "name": "Rock_Sandstone_White_Brick"
    },
    {
      "x": 0,
      "y": 1,
      "z": 11,
      "name": "Rock_Sandstone_White"
    },
    {
      "x": 0,
      "y": 2,
      "z": 11,
      "name": "Rock_Sandstone_White"
    },
    {
      "x": 0,
      "y": 3,
      "z": 11,
      "name": "Rock_Sandstone_White"
    },
    {
      "x": 0,
      "y": 4,
      "z": 11,
      "name": "Rock_Sandstone_White"
    },
    {
      "x": 0,
      "y": 0,
      "z": 12,
      "name": "Rock_Sandstone_White_Brick"
    },
    {
      "x": 0,
      "y": 1,
      "z": 12,
      "name": "Rock_Sandstone_White"
    },
    {
      "x": 0,
      "y": 2,
      "z": 12,
      "name": "Rock_Sandstone_White"
    },
    {
      "x": 0,
      "y": 3,
      "z": 12,
      "name": "Rock_Sandstone_White"
    },
    {
      "x": 0,
      "y": 4,
      "z": 12,
      "name": "Rock_Sandstone_White"
    },
    {
      "x": 0,
      "y": 0,
      "z": 13,
      "name": "Rock_Sandstone_White_Brick"
    },
    {
      "x": 0,
      "y": 1,
      "z": 13,
      "name": "Rock_Sandstone_White_Brick"
    },
    {
      "x": 0,
      "y": 2,
      "z": 13,
      "name": "Rock_Sandstone_White"
    },
    {
      "x": 0,
      "y": 3,
      "z": 13,
      "name": "Rock_Sandstone_White_Brick"
    },
    {
      "x": 0,
      "y": 4,
      "z": 13,
      "name": "Rock_Sandstone_White_Brick"
    },
    {
      "x": 0,
      "y": 0,
      "z": 14,
      "name": "Rock_Sandstone_White_Brick"
    },
    {
      "x": 0,
      "y": 1,
      "z": 14,
      "name": "Rock_Sandstone_White_Brick"
    },
    {
      "x": 0,
      "y": 2,
      "z": 14,
      "name": "Rock_Sandstone_White"
    },
    {
      "x": 0,
      "y": 3,
      "z": 14,
      "name": "Rock_Sandstone_White"
    },
    {
      "x": 0,
      "y": 4,
      "z": 14,
      "name": "Rock_Sandstone_White_Brick_Smooth_Half",
      "rotation": 7
    },
    {
      "x": 0,
      "y": 0,
      "z": 15,
      "name": "Rock_Sandstone_White_Brick"
    },
    {
      "x": 0,
      "y": 1,
      "z": 15,
      "name": "Rock_Sandstone_White"
    },
    {
      "x": 0,
      "y": 2,
      "z": 15,
      "name": "Rock_Sandstone_White_Brick"
    },
    {
      "x": 0,
      "y": 3,
      "z": 15,
      "name": "Rock_Sandstone_White"
    },
    {
      "x": 0,
      "y": 4,
      "z": 15,
      "name": "Rock_Sandstone_White_Brick_Smooth_Half"
    },
    {
      "x": 1,
      "y": 0,
      "z": -19,
      "name": "Rock_Sandstone_White"
    },
    {
      "x": 1,
      "y": 1,
      "z": -19,
      "name": "Rock_Sandstone_White_Brick"
    },
    {
      "x": 1,
      "y": 2,
      "z": -19,
      "name": "Rock_Sandstone_White_Brick"
    },
    {
      "x": 1,
      "y": 3,
      "z": -19,
      "name": "Rock_Sandstone_White"
    },
    {
      "x": 1,
      "y": 4,
      "z": -19,
      "name": "Rock_Sandstone_White_Brick_Half"
    },
    {
      "x": 1,
      "y": 0,
      "z": -18,
      "name": "Rock_Sandstone_White"
    },
    {
      "x": 1,
      "y": 1,
      "z": -18,
      "name": "Rock_Sandstone_White_Brick"
    },
    {
      "x": 1,
      "y": 2,
      "z": -18,
      "name": "Rock_Sandstone_White_Brick"
    },
    {
      "x": 1,
      "y": 3,
      "z": -18,
      "name": "Rock_Sandstone_White_Brick"
    },
    {
      "x": 1,
      "y": 4,
      "z": -18,
      "name": "Rock_Sandstone_White"
    },
    {
      "x": 1,
      "y": 0,
      "z": -17,
      "name": "Rock_Sandstone_White_Brick"
    },
    {
      "x": 1,
      "y": 1,
      "z": -17,
      "name": "Rock_Sandstone_White_Brick"
    },
    {
      "x": 1,
      "y": 2,
      "z": -17,
      "name": "Rock_Sandstone_White_Brick"
    },
    {
      "x": 1,
      "y": 3,
      "z": -17,
      "name": "Rock_Sandstone_White"
    },
    {
      "x": 1,
      "y": 4,
      "z": -17,
      "name": "Rock_Sandstone_White"
    },
    {
      "x": 1,
      "y": 0,
      "z": -16,
      "name": "Rock_Sandstone_White"
    },
    {
      "x": 1,
      "y": 1,
      "z": -16,
      "name": "Rock_Sandstone_White"
    },
    {
      "x": 1,
      "y": 2,
      "z": -16,
      "name": "Rock_Sandstone_White_Brick"
    },
    {
      "x": 1,
      "y": 3,
      "z": -16,
      "name": "Rock_Sandstone_White_Brick"
    },
    {
      "x": 1,
      "y": 4,
      "z": -16,
      "name": "Rock_Sandstone_White_Brick_Half",
      "rotation": 4
    },
    {
      "x": 1,
      "y": 0,
      "z": -15,
      "name": "Rock_Sandstone_White_Brick"
    },
    {
      "x": 1,
      "y": 1,
      "z": -15,
      "name": "Rock_Sandstone_White_Brick"
    },
    {
      "x": 1,
      "y": 2,
      "z": -15,
      "name": "Rock_Sandstone_White_Brick_Half"
    },
    {
      "x": 1,
      "y": 0,
      "z": -14,
      "name": "Rock_Sandstone_White_Brick"
    },
    {
      "x": 1,
      "y": 1,
      "z": -14,
      "name": "Rock_Sandstone_White"
    },
    {
      "x": 1,
      "y": 2,
      "z": -14,
      "name": "Rock_Sandstone_White"
    },
    {
      "x": 1,
      "y": 3,
      "z": -14,
      "name": "Rock_Sandstone_White_Brick_Half",
      "rotation": 6
    },
    {
      "x": 1,
      "y": 0,
      "z": -13,
      "name": "Rock_Sandstone_White_Brick"
    },
    {
      "x": 1,
      "y": 1,
      "z": -13,
      "name": "Rock_Sandstone_White"
    },
    {
      "x": 1,
      "y": 2,
      "z": -13,
      "name": "Rock_Sandstone_White"
    },
    {
      "x": 1,
      "y": 3,
      "z": -13,
      "name": "Rock_Sandstone_White"
    },
    {
      "x": 1,
      "y": 4,
      "z": -13,
      "name": "Rock_Sandstone_White_Brick"
    },
    {
      "x": 1,
      "y": 0,
      "z": -12,
      "name": "Rock_Sandstone_White_Brick"
    },
    {
      "x": 1,
      "y": 1,
      "z": -12,
      "name": "Rock_Sandstone_White_Brick"
    },
    {
      "x": 1,
      "y": 2,
      "z": -12,
      "name": "Rock_Sandstone_White_Brick"
    },
    {
      "x": 1,
      "y": 3,
      "z": -12,
      "name": "Rock_Sandstone_White"
    },
    {
      "x": 1,
      "y": 4,
      "z": -12,
      "name": "Rock_Sandstone_White_Brick"
    },
    {
      "x": 1,
      "y": 0,
      "z": -11,
      "name": "Rock_Sandstone_White_Brick_Half",
      "rotation": 4
    },
    {
      "x": 1,
      "y": 1,
      "z": -11,
      "name": "Rock_Sandstone_White_Brick_Smooth_Half",
      "rotation": 4
    },
    {
      "x": 1,
      "y": 2,
      "z": -11,
      "name": "Rock_Sandstone_White_Brick_Half",
      "rotation": 4
    },
    {
      "x": 1,
      "y": 3,
      "z": -11,
      "name": "Rock_Sandstone_White_Brick_Smooth_Half",
      "rotation": 4
    },
    {
      "x": 1,
      "y": 4,
      "z": -11,
      "name": "Rock_Sandstone_White_Brick_Half",
      "rotation": 4
    },
    {
      "x": 1,
      "y": 0,
      "z": -8,
      "name": "Rock_Sandstone_White_Brick_Smooth_Half",
      "rotation": 6
    },
    {
      "x": 1,
      "y": 1,
      "z": -8,
      "name": "Rock_Sandstone_White_Brick_Half",
      "rotation": 6
    },
    {
      "x": 1,
      "y": 2,
      "z": -8,
      "name": "Rock_Sandstone_White_Brick_Half",
      "rotation": 6
    },
    {
      "x": 1,
      "y": 3,
      "z": -8,
      "name": "Rock_Sandstone_White_Brick_Smooth_Half",
      "rotation": 6
    },
    {
      "x": 1,
      "y": 4,
      "z": -8,
      "name": "Rock_Sandstone_White_Brick_Smooth_Half",
      "rotation": 6
    },
    {
      "x": 1,
      "y": 0,
      "z": -7,
      "name": "Rock_Sandstone_White_Brick"
    },
    {
      "x": 1,
      "y": 1,
      "z": -7,
      "name": "Rock_Sandstone_White"
    },
    {
      "x": 1,
      "y": 2,
      "z": -7,
      "name": "Rock_Sandstone_White_Brick"
    },
    {
      "x": 1,
      "y": 3,
      "z": -7,
      "name": "Rock_Sandstone_White"
    },
    {
      "x": 1,
      "y": 4,
      "z": -7,
      "name": "Rock_Sandstone_White"
    },
    {
      "x": 1,
      "y": 0,
      "z": -6,
      "name": "Rock_Sandstone_White_Brick"
    },
    {
      "x": 1,
      "y": 1,
      "z": -6,
      "name": "Rock_Sandstone_White_Brick"
    },
    {
      "x": 1,
      "y": 2,
      "z": -6,
      "name": "Rock_Sandstone_White_Brick"
    },
    {
      "x": 1,
      "y": 3,
      "z": -6,
      "name": "Rock_Sandstone_White"
    },
    {
      "x": 1,
      "y": 4,
      "z": -6,
      "name": "Rock_Sandstone_White"
    },
    {
      "x": 1,
      "y": 0,
      "z": -5,
      "name": "Rock_Sandstone_White_Brick"
    },
    {
      "x": 1,
      "y": 1,
      "z": -5,
      "name": "Rock_Sandstone_White"
    },
    {
      "x": 1,
      "y": 2,
      "z": -5,
      "name": "Rock_Sandstone_White_Brick"
    },
    {
      "x": 1,
      "y": 3,
      "z": -5,
      "name": "Rock_Sandstone_White"
    },
    {
      "x": 1,
      "y": 4,
      "z": -5,
      "name": "Rock_Sandstone_White"
    },
    {
      "x": 1,
      "y": 0,
      "z": -4,
      "name": "Rock_Sandstone_White"
    },
    {
      "x": 1,
      "y": 1,
      "z": -4,
      "name": "Rock_Sandstone_White"
    },
    {
      "x": 1,
      "y": 2,
      "z": -4,
      "name": "Rock_Sandstone_White"
    },
    {
      "x": 1,
      "y": 3,
      "z": -4,
      "name": "Rock_Sandstone_White"
    },
    {
      "x": 1,
      "y": 4,
      "z": -4,
      "name": "Rock_Sandstone_White"
    },
    {
      "x": 1,
      "y": 0,
      "z": -3,
      "name": "Rock_Sandstone_White_Brick_Smooth_Half",
      "rotation": 4
    },
    {
      "x": 1,
      "y": 1,
      "z": -3,
      "name": "Rock_Sandstone_White_Brick_Half",
      "rotation": 4
    },
    {
      "x": 1,
      "y": 2,
      "z": -3,
      "name": "Rock_Sandstone_White_Brick_Half",
      "rotation": 4
    },
    {
      "x": 1,
      "y": 3,
      "z": -3,
      "name": "Rock_Sandstone_White_Brick_Half",
      "rotation": 4
    },
    {
      "x": 1,
      "y": 4,
      "z": -3,
      "name": "Rock_Sandstone_White_Brick_Smooth_Half",
      "rotation": 4
    },
    {
      "x": 1,
      "y": 0,
      "z": -2,
      "name": "Rock_Sandstone_White_Brick_Half",
      "rotation": 6
    },
    {
      "x": 1,
      "y": 1,
      "z": -2,
      "name": "Rock_Sandstone_White_Brick_Smooth_Half",
      "rotation": 6
    },
    {
      "x": 1,
      "y": 2,
      "z": -2,
      "name": "Rock_Sandstone_White_Brick_Smooth_Half",
      "rotation": 6
    },
    {
      "x": 1,
      "y": 3,
      "z": -2,
      "name": "Rock_Sandstone_White_Brick_Smooth_Half",
      "rotation": 6
    },
    {
      "x": 1,
      "y": 4,
      "z": -2,
      "name": "Rock_Sandstone_White_Brick_Half",
      "rotation": 6
    },
    {
      "x": 1,
      "y": 0,
      "z": -1,
      "name": "Rock_Sandstone_White"
    },
    {
      "x": 1,
      "y": 1,
      "z": -1,
      "name": "Rock_Sandstone_White"
    },
    {
      "x": 1,
      "y": 2,
      "z": -1,
      "name": "Rock_Sandstone_White_Brick"
    },
    {
      "x": 1,
      "y": 3,
      "z": -1,
      "name": "Rock_Sandstone_White_Brick"
    },
    {
      "x": 1,
      "y": 4,
      "z": -1,
      "name": "Rock_Sandstone_White"
    },
    {
      "x": 1,
      "y": 0,
      "z": 0,
      "name": "Rock_Sandstone_White"
    },
    {
      "x": 1,
      "y": 1,
      "z": 0,
      "name": "Rock_Sandstone_White"
    },
    {
      "x": 1,
      "y": 2,
      "z": 0,
      "name": "Rock_Sandstone_White_Brick"
    },
    {
      "x": 1,
      "y": 3,
      "z": 0,
      "name": "Rock_Sandstone_White"
    },
    {
      "x": 1,
      "y": 4,
      "z": 0,
      "name": "Rock_Sandstone_White_Brick"
    },
    {
      "x": 1,
      "y": 0,
      "z": 1,
      "name": "Rock_Sandstone_White"
    },
    {
      "x": 1,
      "y": 1,
      "z": 1,
      "name": "Rock_Sandstone_White_Brick"
    },
    {
      "x": 1,
      "y": 2,
      "z": 1,
      "name": "Rock_Sandstone_White"
    },
    {
      "x": 1,
      "y": 3,
      "z": 1,
      "name": "Rock_Sandstone_White_Brick"
    },
    {
      "x": 1,
      "y": 4,
      "z": 1,
      "name": "Rock_Sandstone_White_Brick"
    },
    {
      "x": 1,
      "y": 0,
      "z": 2,
      "name": "Rock_Sandstone_White"
    },
    {
      "x": 1,
      "y": 1,
      "z": 2,
      "name": "Rock_Sandstone_White_Brick"
    },
    {
      "x": 1,
      "y": 2,
      "z": 2,
      "name": "Rock_Sandstone_White"
    },
    {
      "x": 1,
      "y": 3,
      "z": 2,
      "name": "Rock_Sandstone_White_Brick"
    },
    {
      "x": 1,
      "y": 4,
      "z": 2,
      "name": "Rock_Sandstone_White_Brick"
    },
    {
      "x": 1,
      "y": 0,
      "z": 3,
      "name": "Rock_Sandstone_White"
    },
    {
      "x": 1,
      "y": 1,
      "z": 3,
      "name": "Rock_Sandstone_White"
    },
    {
      "x": 1,
      "y": 2,
      "z": 3,
      "name": "Rock_Sandstone_White_Brick"
    },
    {
      "x": 1,
      "y": 3,
      "z": 3,
      "name": "Rock_Sandstone_White"
    },
    {
      "x": 1,
      "y": 4,
      "z": 3,
      "name": "Rock_Sandstone_White"
    },
    {
      "x": 1,
      "y": 0,
      "z": 4,
      "name": "Rock_Sandstone_White"
    },
    {
      "x": 1,
      "y": 1,
      "z": 4,
      "name": "Rock_Sandstone_White"
    },
    {
      "x": 1,
      "y": 2,
      "z": 4,
      "name": "Rock_Sandstone_White_Brick"
    },
    {
      "x": 1,
      "y": 3,
      "z": 4,
      "name": "Rock_Sandstone_White"
    },
    {
      "x": 1,
      "y": 4,
      "z": 4,
      "name": "Rock_Sandstone_White_Brick"
    },
    {
      "x": 1,
      "y": 0,
      "z": 5,
      "name": "Rock_Sandstone_White_Brick"
    },
    {
      "x": 1,
      "y": 1,
      "z": 5,
      "name": "Rock_Sandstone_White_Brick"
    },
    {
      "x": 1,
      "y": 2,
      "z": 5,
      "name": "Rock_Sandstone_White"
    },
    {
      "x": 1,
      "y": 3,
      "z": 5,
      "name": "Rock_Sandstone_White_Brick"
    },
    {
      "x": 1,
      "y": 4,
      "z": 5,
      "name": "Rock_Sandstone_White_Brick_Smooth_Half",
      "rotation": 6
    },
    {
      "x": 1,
      "y": 0,
      "z": 6,
      "name": "Rock_Sandstone_White"
    },
    {
      "x": 1,
      "y": 1,
      "z": 6,
      "name": "Rock_Sandstone_White_Brick"
    },
    {
      "x": 1,
      "y": 2,
      "z": 6,
      "name": "Rock_Sandstone_White"
    },
    {
      "x": 1,
      "y": 3,
      "z": 6,
      "name": "Rock_Sandstone_White_Brick"
    },
    {
      "x": 1,
      "y": 4,
      "z": 6,
      "name": "Rock_Sandstone_White_Brick"
    },
    {
      "x": 1,
      "y": 0,
      "z": 7,
      "name": "Rock_Sandstone_White_Brick"
    },
    {
      "x": 1,
      "y": 1,
      "z": 7,
      "name": "Rock_Sandstone_White_Brick"
    },
    {
      "x": 1,
      "y": 2,
      "z": 7,
      "name": "Rock_Sandstone_White"
    },
    {
      "x": 1,
      "y": 3,
      "z": 7,
      "name": "Rock_Sandstone_White_Brick"
    },
    {
      "x": 1,
      "y": 4,
      "z": 7,
      "name": "Rock_Sandstone_White"
    },
    {
      "x": 1,
      "y": 0,
      "z": 8,
      "name": "Rock_Sandstone_White"
    },
    {
      "x": 1,
      "y": 1,
      "z": 8,
      "name": "Rock_Sandstone_White"
    },
    {
      "x": 1,
      "y": 2,
      "z": 8,
      "name": "Rock_Sandstone_White"
    },
    {
      "x": 1,
      "y": 3,
      "z": 8,
      "name": "Rock_Sandstone_White"
    },
    {
      "x": 1,
      "y": 4,
      "z": 8,
      "name": "Rock_Sandstone_White"
    },
    {
      "x": 1,
      "y": 0,
      "z": 9,
      "name": "Rock_Sandstone_White"
    },
    {
      "x": 1,
      "y": 1,
      "z": 9,
      "name": "Rock_Sandstone_White"
    },
    {
      "x": 1,
      "y": 2,
      "z": 9,
      "name": "Rock_Sandstone_White"
    },
    {
      "x": 1,
      "y": 3,
      "z": 9,
      "name": "Rock_Sandstone_White_Brick"
    },
    {
      "x": 1,
      "y": 4,
      "z": 9,
      "name": "Rock_Sandstone_White"
    },
    {
      "x": 1,
      "y": 0,
      "z": 10,
      "name": "Rock_Sandstone_White_Brick"
    },
    {
      "x": 1,
      "y": 1,
      "z": 10,
      "name": "Rock_Sandstone_White"
    },
    {
      "x": 1,
      "y": 2,
      "z": 10,
      "name": "Rock_Sandstone_White"
    },
    {
      "x": 1,
      "y": 3,
      "z": 10,
      "name": "Rock_Sandstone_White"
    },
    {
      "x": 1,
      "y": 4,
      "z": 10,
      "name": "Rock_Sandstone_White_Brick"
    },
    {
      "x": 1,
      "y": 0,
      "z": 11,
      "name": "Rock_Sandstone_White_Brick"
    },
    {
      "x": 1,
      "y": 1,
      "z": 11,
      "name": "Rock_Sandstone_White"
    },
    {
      "x": 1,
      "y": 2,
      "z": 11,
      "name": "Rock_Sandstone_White_Brick"
    },
    {
      "x": 1,
      "y": 3,
      "z": 11,
      "name": "Rock_Sandstone_White_Brick"
    },
    {
      "x": 1,
      "y": 4,
      "z": 11,
      "name": "Rock_Sandstone_White"
    },
    {
      "x": 1,
      "y": 0,
      "z": 12,
      "name": "Rock_Sandstone_White"
    },
    {
      "x": 1,
      "y": 1,
      "z": 12,
      "name": "Rock_Sandstone_White_Brick"
    },
    {
      "x": 1,
      "y": 2,
      "z": 12,
      "name": "Rock_Sandstone_White"
    },
    {
      "x": 1,
      "y": 3,
      "z": 12,
      "name": "Rock_Sandstone_White_Brick"
    },
    {
      "x": 1,
      "y": 4,
      "z": 12,
      "name": "Rock_Sandstone_White"
    },
    {
      "x": 1,
      "y": 0,
      "z": 13,
      "name": "Rock_Sandstone_White_Brick"
    },
    {
      "x": 1,
      "y": 1,
      "z": 13,
      "name": "Rock_Sandstone_White_Brick"
    },
    {
      "x": 1,
      "y": 2,
      "z": 13,
      "name": "Rock_Sandstone_White_Brick"
    },
    {
      "x": 1,
      "y": 3,
      "z": 13,
      "name": "Rock_Sandstone_White"
    },
    {
      "x": 1,
      "y": 4,
      "z": 13,
      "name": "Rock_Sandstone_White_Brick"
    },
    {
      "x": 1,
      "y": 0,
      "z": 14,
      "name": "Rock_Sandstone_White"
    },
    {
      "x": 1,
      "y": 1,
      "z": 14,
      "name": "Rock_Sandstone_White"
    },
    {
      "x": 1,
      "y": 2,
      "z": 14,
      "name": "Rock_Sandstone_White_Brick"
    },
    {
      "x": 1,
      "y": 3,
      "z": 14,
      "name": "Rock_Sandstone_White_Brick"
    },
    {
      "x": 1,
      "y": 4,
      "z": 14,
      "name": "Rock_Sandstone_White_Brick"
    },
    {
      "x": 1,
      "y": 0,
      "z": 15,
      "name": "Rock_Sandstone_White"
    },
    {
      "x": 1,
      "y": 1,
      "z": 15,
      "name": "Rock_Sandstone_White_Brick"
    },
    {
      "x": 1,
      "y": 2,
      "z": 15,
      "name": "Rock_Sandstone_White_Brick"
    },
    {
      "x": 1,
      "y": 3,
      "z": 15,
      "name": "Rock_Sandstone_White"
    },
    {
      "x": 1,
      "y": 4,
      "z": 15,
      "name": "Rock_Sandstone_White_Brick_Smooth_Half"
    }
  ]
}