{
  "version": 8,
  "blockIdVersion": 11,
  "anchorX": 0,
  "anchorY": 0,
  "anchorZ": 0,
  "blocks": [
    {
      "x": -1,
      "y": -1,
      "z": -15,
      "name": "Rock_Sandstone"
    },
    {
      "x": -1,
      "y": 0,
      "z": -15,
      "name": "Soil_Sand_White"
    },
    {
      "x": -1,
      "y": -1,
      "z": -14,
      "name": "Rock_Sandstone"
    },
    {
      "x": -1,
      "y": 0,
      "z": -14,
      "name": "Soil_Sand_White"
    },
    {
      "x": -1,
      "y": -1,
      "z": -13,
      "name": "Rock_Sandstone"
    },
    {
      "x": -1,
      "y": 0,
      "z": -13,
      "name": "Soil_Sand_White"
    },
    {
      "x": -1,
      "y": -1,
      "z": -12,
      "name": "Rock_Sandstone"
    },
    {
      "x": -1,
      "y": 0,
      "z": -12,
      "name": "Soil_Sand_White"
    },
    {
      "x": -1,
      "y": -1,
      "z": -11,
      "name": "Rock_Sandstone"
    },
    {
      "x": -1,
      "y": 0,
      "z": -11,
      "name": "Soil_Sand_White"
    },
    {
      "x": -1,
      "y": -1,
      "z": -10,
      "name": "Rock_Sandstone"
    },
    {
      "x": -1,
      "y": 0,
      "z": -10,
      "name": "Soil_Sand_White"
    },
    {
      "x": -1,
      "y": -1,
      "z": -9,
      "name": "Rock_Sandstone"
    },
    {
      "x": -1,
      "y": 0,
      "z": -9,
      "name": "Soil_Sand_White"
    },
    {
      "x": -1,
      "y": -1,
      "z": -5,
      "name": "Rock_Sandstone"
    },
    {
      "x": -1,
      "y": 0,
      "z": -5,
      "name": "Soil_Sand_White"
    },
    {
      "x": -1,
      "y": -1,
      "z": -4,
      "name": "Rock_Sandstone"
    },
    {
      "x": -1,
      "y": 0,
      "z": -4,
      "name": "Soil_Sand_White"
    },
    {
      "x": -1,
      "y": -1,
      "z": -3,
      "name": "Rock_Sandstone"
    },
    {
      "x": -1,
      "y": 0,
      "z": -3,
      "name": "Soil_Sand_White"
    },
    {
      "x": -1,
      "y": -1,
      "z": -2,
      "name": "Rock_Sandstone"
    },
    {
      "x": -1,
      "y": 0,
      "z": -2,
      "name": "Soil_Sand_White"
    },
    {
      "x": -1,
      "y": -1,
      "z": -1,
      "name": "Rock_Sandstone"
    },
    {
      "x": -1,
      "y": 0,
      "z": -1,
      "name": "Soil_Sand_White"
    },
    {
      "x": -1,
      "y": -1,
      "z": 0,
      "name": "Rock_Sandstone"
    },
    {
      "x": -1,
      "y": 0,
      "z": 0,
      "name": "Soil_Sand_White"
    },
    {
      "x": -1,
      "y": -1,
      "z": 1,
      "name": "Rock_Sandstone"
    },
    {
      "x": -1,
      "y": 0,
      "z": 1,
      "name": "Soil_Sand_White"
    },
    {
      "x": -1,
      "y": -1,
      "z": 2,
      "name": "Rock_Sandstone"
    },
    {
      "x": -1,
      "y": 0,
      "z": 2,
      "name": "Soil_Sand_White"
    },
    {
      "x": -1,
      "y": 1,
      "z": 2,
      "name": "Soil_Sand_White"
    },
    {
      "x": -1,
      "y": -1,
      "z": 3,
      "name": "Rock_Sandstone"
    },
    {
      "x": -1,
      "y": 0,
      "z": 3,
      "name": "Soil_Sand_White"
    },
    {
      "x": -1,
      "y": -1,
      "z": 4,
      "name": "Rock_Sandstone"
    },
    {
      "x": -1,
      "y": 0,
      "z": 4,
      "name": "Soil_Sand_White"
    },
    {
      "x": -1,
      "y": 1,
      "z": 4,
      "name": "Soil_Sand_White"
    },
    {
      "x": -1,
      "y": -1,
      "z": 5,
      "name": "Rock_Sandstone"
    },
    {
      "x": -1,
      "y": 0,
      "z": 5,
      "name": "Soil_Sand_White"
    },
    {
      "x": -1,
      "y": -1,
      "z": 6,
      "name": "Rock_Sandstone"
    },
    {
      "x": -1,
      "y": 0,
      "z": 6,
      "name": "Soil_Sand_White"
    },
    {
      "x": 0,
      "y": -1,
      "z": -16,
      "name": "Rock_Sandstone"
    },
    {
      "x": 0,
      "y": 0,
      "z": -16,
      "name": "Soil_Sand_White"
    },
    {
      "x": 0,
      "y": -1,
      "z": -15,
      "name": "Rock_Sandstone"
    },
    {
      "x": 0,
      "y": 0,
      "z": -15,
      "name": "Soil_Sand_White"
    },
    {
      "x": 0,
      "y": -1,
      "z": -14,
      "name": "Rock_Sandstone"
    },
    {
      "x": 0,
      "y": 0,
      "z": -14,
      "name": "Soil_Sand_White"
    },
    {
      "x": 0,
      "y": -1,
      "z": -13,
      "name": "Rock_Sandstone"
    },
    {
      "x": 0,
      "y": 0,
      "z": -13,
      "name": "Soil_Sand_White"
    },
    {
      "x": 0,
      "y": 1,
      "z": -13,
      "name": "Soil_Sand_White"
    },
    {
      "x": 0,
      "y": -1,
      "z": -12,
      "name": "Rock_Sandstone"
    },
    {
      "x": 0,
      "y": 0,
      "z": -12,
      "name": "Soil_Sand_White"
    },
    {
      "x": 0,
      "y": 1,
      "z": -12,
      "name": "Soil_Sand_White"
    },
    {
      "x": 0,
      "y": -1,
      "z": -11,
      "name": "Rock_Sandstone"
    },
    {
      "x": 0,
      "y": 0,
      "z": -11,
      "name": "Soil_Sand_White"
    },
    {
      "x": 0,
      "y": 1,
      "z": -11,
      "name": "Soil_Sand_White"
    },
    {
      "x": 0,
      "y": -1,
      "z": -10,
      "name": "Rock_Sandstone"
    },
    {
      "x": 0,
      "y": 0,
      "z": -10,
      "name": "Soil_Sand_White"
    },
    {
      "x": 0,
      "y": -1,
      "z": -9,
      "name": "Rock_Sandstone"
    },
    {
      "x": 0,
      "y": 0,
      "z": -9,
      "name": "Soil_Sand_White"
    },
    {
      "x": 0,
      "y": -1,
      "z": -8,
      "name": "Rock_Sandstone"
    },
    {
      "x": 0,
      "y": 0,
      "z": -8,
      "name": "Soil_Sand_White"
    },
    {
      "x": 0,
      "y": -1,
      "z": -7,
      "name": "Rock_Sandstone"
    },
    {
      "x": 0,
      "y": 0,
      "z": -7,
      "name": "Soil_Sand_White"
    },
    {
      "x": 0,
      "y": -1,
      "z": -6,
      "name": "Rock_Sandstone"
    },
    {
      "x": 0,
      "y": 0,
      "z": -6,
      "name": "Soil_Sand_White"
    },
    {
      "x": 0,
      "y": -1,
      "z": -5,
      "name": "Rock_Sandstone"
    },
    {
      "x": 0,
      "y": 0,
      "z": -5,
      "name": "Soil_Sand_White"
    },
    {
      "x": 0,
      "y": -1,
      "z": -4,
      "name": "Rock_Sandstone"
    },
    {
      "x": 0,
      "y": 0,
      "z": -4,
      "name": "Soil_Sand_White"
    },
    {
      "x": 0,
      "y": 1,
      "z": -4,
      "name": "Soil_Sand_White"
    },
    {
      "x": 0,
      "y": -1,
      "z": -3,
      "name": "Rock_Sandstone"
    },
    {
      "x": 0,
      "y": 0,
      "z": -3,
      "name": "Soil_Sand_White"
    },
    {
      "x": 0,
      "y": 1,
      "z": -3,
      "name": "Rock_Sandstone_White_Brick_Smooth"
    },
    {
      "x": 0,
      "y": 3,
      "z": -3,
      "name": "Empty"
    },
    {
      "x": 0,
      "y": -1,
      "z": -2,
      "name": "Rock_Sandstone"
    },
    {
      "x": 0,
      "y": 0,
      "z": -2,
      "name": "Rock_Sandstone_White_Brick_Smooth"
    },
    {
      "x": 0,
      "y": 1,
      "z": -2,
      "name": "Empty"
    },
    {
      "x": 0,
      "y": 2,
      "z": -2,
      "name": "Empty"
    },
    {
      "x": 0,
      "y": 3,
      "z": -2,
      "name": "Empty"
    },
    {
      "x": 0,
      "y": -1,
      "z": -1,
      "name": "Rock_Sandstone"
    },
    {
      "x": 0,
      "y": 0,
      "z": -1,
      "name": "Soil_Sand_White"
    },
    {
      "x": 0,
      "y": 1,
      "z": -1,
      "name": "Soil_Sand_White"
    },
    {
      "x": 0,
      "y": 2,
      "z": -1,
      "name": "Empty"
    },
    {
      "x": 0,
      "y": 3,
      "z": -1,
      "name": "Empty"
    },
    {
      "x": 0,
      "y": -1,
      "z": 0,
      "name": "Rock_Sandstone"
    },
    {
      "x": 0,
      "y": 0,
      "z": 0,
      "name": "Soil_Sand_White"
    },
    {
      "x": 0,
      "y": 2,
      "z": 0,
      "name": "Empty"
    },
    {
      "x": 0,
      "y": 3,
      "z": 0,
      "name": "Empty"
    },
    {
      "x": 0,
      "y": -1,
      "z": 1,
      "name": "Rock_Sandstone"
    },
    {
      "x": 0,
      "y": 0,
      "z": 1,
      "name": "Soil_Sand_White"
    },
    {
      "x": 0,
      "y": 1,
      "z": 1,
      "name": "Empty"
    },
    {
      "x": 0,
      "y": 2,
      "z": 1,
      "name": "Empty"
    },
    {
      "x": 0,
      "y": 3,
      "z": 1,
      "name": "Empty"
    },
    {
      "x": 0,
      "y": -1,
      "z": 2,
      "name": "Rock_Sandstone"
    },
    {
      "x": 0,
      "y": 0,
      "z": 2,
      "name": "Soil_Sand_White"
    },
    {
      "x": 0,
      "y": 1,
      "z": 2,
      "name": "Rock_Sandstone_White_Brick_Smooth"
    },
    {
      "x": 0,
      "y": 3,
      "z": 2,
      "name": "Empty"
    },
    {
      "x": 0,
      "y": -1,
      "z": 3,
      "name": "Rock_Sandstone"
    },
    {
      "x": 0,
      "y": 0,
      "z": 3,
      "name": "Soil_Sand_White"
    },
    {
      "x": 0,
      "y": 1,
      "z": 3,
      "name": "Soil_Sand_White"
    },
    {
      "x": 0,
      "y": -1,
      "z": 4,
      "name": "Rock_Sandstone"
    },
    {
      "x": 0,
      "y": 0,
      "z": 4,
      "name": "Soil_Sand_White"
    },
    {
      "x": 0,
      "y": 1,
      "z": 4,
      "name": "Soil_Sand_White"
    },
    {
      "x": 0,
      "y": -1,
      "z": 5,
      "name": "Rock_Sandstone"
    },
    {
      "x": 0,
      "y": 0,
      "z": 5,
      "name": "Soil_Sand_White"
    },
    {
      "x": 0,
      "y": 1,
      "z": 5,
      "name": "Soil_Sand_White"
    },
    {
      "x": 0,
      "y": -1,
      "z": 6,
      "name": "Rock_Sandstone"
    },
    {
      "x": 0,
      "y": 0,
      "z": 6,
      "name": "Soil_Sand_White"
    },
    {
      "x": 0,
      "y": 1,
      "z": 6,
      "name": "Soil_Sand_White"
    },
    {
      "x": 0,
      "y": -1,
      "z": 7,
      "name": "Rock_Sandstone"
    },
    {
      "x": 0,
      "y": 0,
      "z": 7,
      "name": "Soil_Sand_White"
    },
    {
      "x": 1,
      "y": -1,
      "z": -16,
      "name": "Rock_Sandstone"
    },
    {
      "x": 1,
      "y": 0,
      "z": -16,
      "name": "Soil_Sand_White"
    },
    {
      "x": 1,
      "y": -1,
      "z": -15,
      "name": "Rock_Sandstone"
    },
    {
      "x": 1,
      "y": 0,
      "z": -15,
      "name": "Soil_Sand_White"
    },
    {
      "x": 1,
      "y": -1,
      "z": -14,
      "name": "Rock_Sandstone"
    },
    {
      "x": 1,
      "y": 0,
      "z": -14,
      "name": "Soil_Sand_White"
    },
    {
      "x": 1,
      "y": 1,
      "z": -14,
      "name": "Soil_Sand_White"
    },
    {
      "x": 1,
      "y": -1,
      "z": -13,
      "name": "Rock_Sandstone"
    },
    {
      "x": 1,
      "y": 0,
      "z": -13,
      "name": "Soil_Sand_White"
    },
    {
      "x": 1,
      "y": 1,
      "z": -13,
      "name": "Soil_Sand_White"
    },
    {
      "x": 1,
      "y": -1,
      "z": -12,
      "name": "Rock_Sandstone"
    },
    {
      "x": 1,
      "y": 0,
      "z": -12,
      "name": "Soil_Sand_White"
    },
    {
      "x": 1,
      "y": 1,
      "z": -12,
      "name": "Soil_Sand_White"
    },
    {
      "x": 1,
      "y": -1,
      "z": -11,
      "name": "Rock_Sandstone"
    },
    {
      "x": 1,
      "y": 0,
      "z": -11,
      "name": "Soil_Sand_White"
    },
    {
      "x": 1,
      "y": 1,
      "z": -11,
      "name": "Soil_Sand_White"
    },
    {
      "x": 1,
      "y": -1,
      "z": -10,
      "name": "Rock_Sandstone"
    },
    {
      "x": 1,
      "y": 0,
      "z": -10,
      "name": "Soil_Sand_White"
    },
    {
      "x": 1,
      "y": 1,
      "z": -10,
      "name": "Soil_Sand_White"
    },
    {
      "x": 1,
      "y": -1,
      "z": -9,
      "name": "Rock_Sandstone"
    },
    {
      "x": 1,
      "y": 0,
      "z": -9,
      "name": "Soil_Sand_White"
    },
    {
      "x": 1,
      "y": 1,
      "z": -9,
      "name": "Soil_Sand_White"
    },
    {
      "x": 1,
      "y": -1,
      "z": -8,
      "name": "Rock_Sandstone"
    },
    {
      "x": 1,
      "y": 0,
      "z": -8,
      "name": "Soil_Sand_White"
    },
    {
      "x": 1,
      "y": -1,
      "z": -7,
      "name": "Rock_Sandstone"
    },
    {
      "x": 1,
      "y": 0,
      "z": -7,
      "name": "Soil_Sand_White"
    },
    {
      "x": 1,
      "y": -1,
      "z": -6,
      "name": "Rock_Sandstone"
    },
    {
      "x": 1,
      "y": 0,
      "z": -6,
      "name": "Soil_Sand_White"
    },
    {
      "x": 1,
      "y": 1,
      "z": -6,
      "name": "Soil_Sand_White"
    },
    {
      "x": 1,
      "y": -1,
      "z": -5,
      "name": "Rock_Sandstone"
    },
    {
      "x": 1,
      "y": 0,
      "z": -5,
      "name": "Soil_Sand_White"
    },
    {
      "x": 1,
      "y": 1,
      "z": -5,
      "name": "Soil_Sand_White"
    },
    {
      "x": 1,
      "y": -1,
      "z": -4,
      "name": "Rock_Sandstone"
    },
    {
      "x": 1,
      "y": 0,
      "z": -4,
      "name": "Soil_Sand_White"
    },
    {
      "x": 1,
      "y": 1,
      "z": -4,
      "name": "Soil_Sand_White"
    },
    {
      "x": 1,
      "y": -1,
      "z": -3,
      "name": "Rock_Sandstone"
    },
    {
      "x": 1,
      "y": 0,
      "z": -3,
      "name": "Soil_Sand_White"
    },
    {
      "x": 1,
      "y": 1,
      "z": -3,
      "name": "Rock_Sandstone_White_Brick_Smooth"
    },
    {
      "x": 1,
      "y": 2,
      "z": -3,
      "name": "Rock_Sandstone_White_Brick_Smooth_Half"
    },
    {
      "x": 1,
      "y": 3,
      "z": -3,
      "name": "Empty"
    },
    {
      "x": 1,
      "y": -1,
      "z": -2,
      "name": "Rock_Sandstone"
    },
    {
      "x": 1,
      "y": 0,
      "z": -2,
      "name": "Soil_Sand_White"
    },
    {
      "x": 1,
      "y": 1,
      "z": -2,
      "name": "Rock_Sandstone_White_Brick_Smooth_Half"
    },
    {
      "x": 1,
      "y": 2,
      "z": -2,
      "name": "Empty"
    },
    {
      "x": 1,
      "y": 3,
      "z": -2,
      "name": "Empty"
    },
    {
      "x": 1,
      "y": -1,
      "z": -1,
      "name": "Rock_Sandstone"
    },
    {
      "x": 1,
      "y": 0,
      "z": -1,
      "name": "Soil_Sand_White"
    },
    {
      "x": 1,
      "y": 1,
      "z": -1,
      "name": "Rock_Sandstone_White_Brick_Smooth"
    },
    {
      "x": 1,
      "y": 2,
      "z": -1,
      "name": "Empty"
    },
    {
      "x": 1,
      "y": 3,
      "z": -1,
      "name": "Empty"
    },
    {
      "x": 1,
      "y": -1,
      "z": 0,
      "name": "Rock_Sandstone"
    },
    {
      "x": 1,
      "y": 0,
      "z": 0,
      "name": "Soil_Sand_White"
    },
    {
      "x": 1,
      "y": 1,
      "z": 0,
      "name": "Rock_Sandstone_White_Brick_Smooth"
    },
    {
      "x": 1,
      "y": 2,
      "z": 0,
      "name": "Empty"
    },
    {
      "x": 1,
      "y": 3,
      "z": 0,
      "name": "Empty"
    },
    {
      "x": 1,
      "y": -1,
      "z": 1,
      "name": "Rock_Sandstone"
    },
    {
      "x": 1,
      "y": 0,
      "z": 1,
      "name": "Rock_Sandstone_White_Brick_Smooth"
    },
    {
      "x": 1,
      "y": 1,
      "z": 1,
      "name": "Rock_Sandstone_White_Brick_Smooth_Half"
    },
    {
      "x": 1,
      "y": 2,
      "z": 1,
      "name": "Empty"
    },
    {
      "x": 1,
      "y": 3,
      "z": 1,
      "name": "Empty"
    },
    {
      "x": 1,
      "y": -1,
      "z": 2,
      "name": "Rock_Sandstone"
    },
    {
      "x": 1,
      "y": 0,
      "z": 2,
      "name": "Soil_Sand_White"
    },
    {
      "x": 1,
      "y": 1,
      "z": 2,
      "name": "Rock_Sandstone_White_Brick_Smooth"
    },
    {
      "x": 1,
      "y": 2,
      "z": 2,
      "name": "Rock_Sandstone_White_Brick_Smooth_Half"
    },
    {
      "x": 1,
      "y": 3,
      "z": 2,
      "name": "Empty"
    },
    {
      "x": 1,
      "y": -1,
      "z": 3,
      "name": "Rock_Sandstone"
    },
    {
      "x": 1,
      "y": 0,
      "z": 3,
      "name": "Soil_Sand_White"
    },
    {
      "x": 1,
      "y": 1,
      "z": 3,
      "name": "Soil_Sand_White"
    },
    {
      "x": 1,
      "y": -1,
      "z": 4,
      "name": "Rock_Sandstone"
    },
    {
      "x": 1,
      "y": 0,
      "z": 4,
      "name": "Soil_Sand_White"
    },
    {
      "x": 1,
      "y": 1,
      "z": 4,
      "name": "Soil_Sand_White"
    },
    {
      "x": 1,
      "y": -1,
      "z": 5,
      "name": "Rock_Sandstone"
    },
    {
      "x": 1,
      "y": 0,
      "z": 5,
      "name": "Soil_Sand_White"
    },
    {
      "x": 1,
      "y": 1,
      "z": 5,
      "name": "Soil_Sand_White"
    },
    {
      "x": 1,
      "y": -1,
      "z": 6,
      "name": "Rock_Sandstone"
    },
    {
      "x": 1,
      "y": 0,
      "z": 6,
      "name": "Soil_Sand_White"
    },
    {
      "x": 1,
      "y": 1,
      "z": 6,
      "name": "Soil_Sand_White"
    },
    {
      "x": 1,
      "y": 2,
      "z": 6,
      "name": "Rubble_Sandstone_White",
      "support": 15
    },
    {
      "x": 1,
      "y": -1,
      "z": 7,
      "name": "Rock_Sandstone"
    },
    {
      "x": 1,
      "y": 0,
      "z": 7,
      "name": "Soil_Sand_White"
    },
    {
      "x": 1,
      "y": -1,
      "z": 8,
      "name": "Rock_Sandstone"
    },
    {
      "x": 1,
      "y": 0,
      "z": 8,
      "name": "Soil_Sand_White"
    },
    {
      "x": 2,
      "y": -1,
      "z": -17,
      "name": "Rock_Sandstone"
    },
    {
      "x": 2,
      "y": 0,
      "z": -17,
      "name": "Soil_Sand_White"
    },
    {
      "x": 2,
      "y": -1,
      "z": -16,
      "name": "Rock_Sandstone"
    },
    {
      "x": 2,
      "y": 0,
      "z": -16,
      "name": "Soil_Sand_White"
    },
    {
      "x": 2,
      "y": -1,
      "z": -15,
      "name": "Rock_Sandstone"
    },
    {
      "x": 2,
      "y": 0,
      "z": -15,
      "name": "Soil_Sand_White"
    },
    {
      "x": 2,
      "y": 1,
      "z": -15,
      "name": "Soil_Sand_White"
    },
    {
      "x": 2,
      "y": -1,
      "z": -14,
      "name": "Rock_Sandstone"
    },
    {
      "x": 2,
      "y": 0,
      "z": -14,
      "name": "Soil_Sand_White"
    },
    {
      "x": 2,
      "y": 1,
      "z": -14,
      "name": "Soil_Sand_White"
    },
    {
      "x": 2,
      "y": -1,
      "z": -13,
      "name": "Rock_Sandstone"
    },
    {
      "x": 2,
      "y": 0,
      "z": -13,
      "name": "Soil_Sand_White"
    },
    {
      "x": 2,
      "y": 1,
      "z": -13,
      "name": "Soil_Sand_White"
    },
    {
      "x": 2,
      "y": -1,
      "z": -12,
      "name": "Rock_Sandstone"
    },
    {
      "x": 2,
      "y": 0,
      "z": -12,
      "name": "Soil_Sand_White"
    },
    {
      "x": 2,
      "y": 1,
      "z": -12,
      "name": "Soil_Sand_White"
    },
    {
      "x": 2,
      "y": -1,
      "z": -11,
      "name": "Rock_Sandstone"
    },
    {
      "x": 2,
      "y": 0,
      "z": -11,
      "name": "Soil_Sand_White"
    },
    {
      "x": 2,
      "y": 1,
      "z": -11,
      "name": "Soil_Sand_White"
    },
    {
      "x": 2,
      "y": -1,
      "z": -10,
      "name": "Rock_Sandstone"
    },
    {
      "x": 2,
      "y": 0,
      "z": -10,
      "name": "Soil_Sand_White"
    },
    {
      "x": 2,
      "y": 1,
      "z": -10,
      "name": "Soil_Sand_White"
    },
    {
      "x": 2,
      "y": -1,
      "z": -9,
      "name": "Rock_Sandstone"
    },
    {
      "x": 2,
      "y": 0,
      "z": -9,
      "name": "Soil_Sand_White"
    },
    {
      "x": 2,
      "y": 1,
      "z": -9,
      "name": "Soil_Sand_White"
    },
    {
      "x": 2,
      "y": -1,
      "z": -8,
      "name": "Rock_Sandstone"
    },
    {
      "x": 2,
      "y": 0,
      "z": -8,
      "name": "Soil_Sand_White"
    },
    {
      "x": 2,
      "y": 1,
      "z": -8,
      "name": "Soil_Sand_White"
    },
    {
      "x": 2,
      "y": -1,
      "z": -7,
      "name": "Rock_Sandstone"
    },
    {
      "x": 2,
      "y": 0,
      "z": -7,
      "name": "Soil_Sand_White"
    },
    {
      "x": 2,
      "y": 1,
      "z": -7,
      "name": "Soil_Sand_White"
    },
    {
      "x": 2,
      "y": -1,
      "z": -6,
      "name": "Rock_Sandstone"
    },
    {
      "x": 2,
      "y": 0,
      "z": -6,
      "name": "Soil_Sand_White"
    },
    {
      "x": 2,
      "y": 1,
      "z": -6,
      "name": "Soil_Sand_White"
    },
    {
      "x": 2,
      "y": -1,
      "z": -5,
      "name": "Rock_Sandstone"
    },
    {
      "x": 2,
      "y": 0,
      "z": -5,
      "name": "Soil_Sand_White"
    },
    {
      "x": 2,
      "y": 1,
      "z": -5,
      "name": "Soil_Sand_White"
    },
    {
      "x": 2,
      "y": -1,
      "z": -4,
      "name": "Rock_Sandstone"
    },
    {
      "x": 2,
      "y": 0,
      "z": -4,
      "name": "Soil_Sand_White"
    },
    {
      "x": 2,
      "y": 1,
      "z": -4,
      "name": "Soil_Sand_White"
    },
    {
      "x": 2,
      "y": -1,
      "z": -3,
      "name": "Rock_Sandstone"
    },
    {
      "x": 2,
      "y": 0,
      "z": -3,
      "name": "Soil_Sand_White"
    },
    {
      "x": 2,
      "y": 1,
      "z": -3,
      "name": "Rock_Sandstone_White_Brick_Smooth"
    },
    {
      "x": 2,
      "y": 2,
      "z": -3,
      "name": "Rock_Sandstone_White_Brick_Smooth_Half"
    },
    {
      "x": 2,
      "y": 3,
      "z": -3,
      "name": "Empty"
    },
    {
      "x": 2,
      "y": -1,
      "z": -2,
      "name": "Rock_Sandstone"
    },
    {
      "x": 2,
      "y": 0,
      "z": -2,
      "name": "Soil_Sand_White"
    },
    {
      "x": 2,
      "y": 1,
      "z": -2,
      "name": "Rock_Sandstone_White_Brick_Smooth"
    },
    {
      "x": 2,
      "y": 2,
      "z": -2,
      "name": "Empty"
    },
    {
      "x": 2,
      "y": 3,
      "z": -2,
      "name": "Empty"
    },
    {
      "x": 2,
      "y": -1,
      "z": -1,
      "name": "Rock_Sandstone"
    },
    {
      "x": 2,
      "y": 0,
      "z": -1,
      "name": "Soil_Sand_White"
    },
    {
      "x": 2,
      "y": 1,
      "z": -1,
      "name": "Rock_Sandstone_White_Brick_Smooth"
    },
    {
      "x": 2,
      "y": 2,
      "z": -1,
      "name": "Empty"
    },
    {
      "x": 2,
      "y": 3,
      "z": -1,
      "name": "Empty"
    },
    {
      "x": 2,
      "y": -1,
      "z": 0,
      "name": "Rock_Sandstone"
    },
    {
      "x": 2,
      "y": 0,
      "z": 0,
      "name": "Soil_Sand_White"
    },
    {
      "x": 2,
      "y": 1,
      "z": 0,
      "name": "Rock_Sandstone_White_Brick_Smooth"
    },
    {
      "x": 2,
      "y": 2,
      "z": 0,
      "name": "Empty"
    },
    {
      "x": 2,
      "y": 3,
      "z": 0,
      "name": "Empty"
    },
    {
      "x": 2,
      "y": -1,
      "z": 1,
      "name": "Rock_Sandstone"
    },
    {
      "x": 2,
      "y": 0,
      "z": 1,
      "name": "Soil_Sand_White"
    },
    {
      "x": 2,
      "y": 1,
      "z": 1,
      "name": "Rock_Sandstone_White_Brick_Smooth"
    },
    {
      "x": 2,
      "y": 2,
      "z": 1,
      "name": "Empty"
    },
    {
      "x": 2,
      "y": 3,
      "z": 1,
      "name": "Empty"
    },
    {
      "x": 2,
      "y": -1,
      "z": 2,
      "name": "Rock_Sandstone"
    },
    {
      "x": 2,
      "y": 0,
      "z": 2,
      "name": "Soil_Sand_White"
    },
    {
      "x": 2,
      "y": 1,
      "z": 2,
      "name": "Rock_Sandstone_White_Brick_Smooth"
    },
    {
      "x": 2,
      "y": 2,
      "z": 2,
      "name": "Rock_Sandstone_White_Brick_Smooth_Half"
    },
    {
      "x": 2,
      "y": 3,
      "z": 2,
      "name": "Empty"
    },
    {
      "x": 2,
      "y": -1,
      "z": 3,
      "name": "Rock_Sandstone"
    },
    {
      "x": 2,
      "y": 0,
      "z": 3,
      "name": "Soil_Sand_White"
    },
    {
      "x": 2,
      "y": 1,
      "z": 3,
      "name": "Soil_Sand_White"
    },
    {
      "x": 2,
      "y": -1,
      "z": 4,
      "name": "Rock_Sandstone"
    },
    {
      "x": 2,
      "y": 0,
      "z": 4,
      "name": "Soil_Sand_White"
    },
    {
      "x": 2,
      "y": 1,
      "z": 4,
      "name": "Soil_Sand_White"
    },
    {
      "x": 2,
      "y": -1,
      "z": 5,
      "name": "Rock_Sandstone"
    },
    {
      "x": 2,
      "y": 0,
      "z": 5,
      "name": "Soil_Sand_White"
    },
    {
      "x": 2,
      "y": 1,
      "z": 5,
      "name": "Soil_Sand_White"
    },
    {
      "x": 2,
      "y": -1,
      "z": 6,
      "name": "Rock_Sandstone"
    },
    {
      "x": 2,
      "y": 0,
      "z": 6,
      "name": "Soil_Sand_White"
    },
    {
      "x": 2,
      "y": 1,
      "z": 6,
      "name": "Soil_Sand_White"
    },
    {
      "x": 2,
      "y": -1,
      "z": 7,
      "name": "Rock_Sandstone"
    },
    {
      "x": 2,
      "y": 0,
      "z": 7,
      "name": "Soil_Sand_White"
    },
    {
      "x": 2,
      "y": 1,
      "z": 7,
      "name": "Soil_Sand_White"
    },
    {
      "x": 2,
      "y": -1,
      "z": 8,
      "name": "Rock_Sandstone"
    },
    {
      "x": 2,
      "y": 0,
      "z": 8,
      "name": "Soil_Sand_White"
    },
    {
      "x": 3,
      "y": -1,
      "z": -17,
      "name": "Rock_Sandstone"
    },
    {
      "x": 3,
      "y": 0,
      "z": -17,
      "name": "Soil_Sand_White"
    },
    {
      "x": 3,
      "y": -1,
      "z": -16,
      "name": "Rock_Sandstone"
    },
    {
      "x": 3,
      "y": 0,
      "z": -16,
      "name": "Soil_Sand_White"
    },
    {
      "x": 3,
      "y": -1,
      "z": -15,
      "name": "Rock_Sandstone"
    },
    {
      "x": 3,
      "y": 0,
      "z": -15,
      "name": "Soil_Sand_White"
    },
    {
      "x": 3,
      "y": 1,
      "z": -15,
      "name": "Soil_Sand_White"
    },
    {
      "x": 3,
      "y": -1,
      "z": -14,
      "name": "Rock_Sandstone"
    },
    {
      "x": 3,
      "y": 0,
      "z": -14,
      "name": "Soil_Sand_White"
    },
    {
      "x": 3,
      "y": 1,
      "z": -14,
      "name": "Soil_Sand_White"
    },
    {
      "x": 3,
      "y": -1,
      "z": -13,
      "name": "Rock_Sandstone"
    },
    {
      "x": 3,
      "y": 0,
      "z": -13,
      "name": "Soil_Sand_White"
    },
    {
      "x": 3,
      "y": 1,
      "z": -13,
      "name": "Soil_Sand_White"
    },
    {
      "x": 3,
      "y": -1,
      "z": -12,
      "name": "Rock_Sandstone"
    },
    {
      "x": 3,
      "y": 0,
      "z": -12,
      "name": "Soil_Sand_White"
    },
    {
      "x": 3,
      "y": 1,
      "z": -12,
      "name": "Soil_Sand_White"
    },
    {
      "x": 3,
      "y": -1,
      "z": -11,
      "name": "Rock_Sandstone"
    },
    {
      "x": 3,
      "y": 0,
      "z": -11,
      "name": "Soil_Sand_White"
    },
    {
      "x": 3,
      "y": 1,
      "z": -11,
      "name": "Soil_Sand_White"
    },
    {
      "x": 3,
      "y": -1,
      "z": -10,
      "name": "Rock_Sandstone"
    },
    {
      "x": 3,
      "y": 0,
      "z": -10,
      "name": "Soil_Sand_White"
    },
    {
      "x": 3,
      "y": 1,
      "z": -10,
      "name": "Soil_Sand_White"
    },
    {
      "x": 3,
      "y": -1,
      "z": -9,
      "name": "Rock_Sandstone"
    },
    {
      "x": 3,
      "y": 0,
      "z": -9,
      "name": "Soil_Sand_White"
    },
    {
      "x": 3,
      "y": 1,
      "z": -9,
      "name": "Soil_Sand_White"
    },
    {
      "x": 3,
      "y": -1,
      "z": -8,
      "name": "Rock_Sandstone"
    },
    {
      "x": 3,
      "y": 0,
      "z": -8,
      "name": "Soil_Sand_White"
    },
    {
      "x": 3,
      "y": 1,
      "z": -8,
      "name": "Soil_Sand_White"
    },
    {
      "x": 3,
      "y": 2,
      "z": -8,
      "name": "Rubble_Sandstone_White_Medium",
      "support": 15
    },
    {
      "x": 3,
      "y": -1,
      "z": -7,
      "name": "Rock_Sandstone"
    },
    {
      "x": 3,
      "y": 0,
      "z": -7,
      "name": "Soil_Sand_White"
    },
    {
      "x": 3,
      "y": 1,
      "z": -7,
      "name": "Soil_Sand_White"
    },
    {
      "x": 3,
      "y": 2,
      "z": -7,
      "name": "Rubble_Sandstone_White_Medium",
      "support": 15
    },
    {
      "x": 3,
      "y": -1,
      "z": -6,
      "name": "Rock_Sandstone"
    },
    {
      "x": 3,
      "y": 0,
      "z": -6,
      "name": "Soil_Sand_White"
    },
    {
      "x": 3,
      "y": 1,
      "z": -6,
      "name": "Soil_Sand_White"
    },
    {
      "x": 3,
      "y": -1,
      "z": -5,
      "name": "Rock_Sandstone"
    },
    {
      "x": 3,
      "y": 0,
      "z": -5,
      "name": "Soil_Sand_White"
    },
    {
      "x": 3,
      "y": 1,
      "z": -5,
      "name": "Soil_Sand_White"
    },
    {
      "x": 3,
      "y": -1,
      "z": -4,
      "name": "Rock_Sandstone"
    },
    {
      "x": 3,
      "y": 0,
      "z": -4,
      "name": "Soil_Sand_White"
    },
    {
      "x": 3,
      "y": 1,
      "z": -4,
      "name": "Soil_Sand_White"
    },
    {
      "x": 3,
      "y": -1,
      "z": -3,
      "name": "Rock_Sandstone"
    },
    {
      "x": 3,
      "y": 0,
      "z": -3,
      "name": "Soil_Sand_White"
    },
    {
      "x": 3,
      "y": 1,
      "z": -3,
      "name": "Rock_Sandstone_White_Brick_Smooth"
    },
    {
      "x": 3,
      "y": 2,
      "z": -3,
      "name": "Rock_Sandstone_White_Brick_Smooth_Half"
    },
    {
      "x": 3,
      "y": 3,
      "z": -3,
      "name": "Empty"
    },
    {
      "x": 3,
      "y": -1,
      "z": -2,
      "name": "Rock_Sandstone"
    },
    {
      "x": 3,
      "y": 0,
      "z": -2,
      "name": "Soil_Sand_White"
    },
    {
      "x": 3,
      "y": 1,
      "z": -2,
      "name": "Rock_Sandstone_White_Brick_Smooth_Half"
    },
    {
      "x": 3,
      "y": 2,
      "z": -2,
      "name": "Empty"
    },
    {
      "x": 3,
      "y": 3,
      "z": -2,
      "name": "Empty"
    },
    {
      "x": 3,
      "y": -1,
      "z": -1,
      "name": "Rock_Sandstone"
    },
    {
      "x": 3,
      "y": 0,
      "z": -1,
      "name": "Soil_Sand_White"
    },
    {
      "x": 3,
      "y": 1,
      "z": -1,
      "name": "Rock_Sandstone_White_Brick_Smooth_Half"
    },
    {
      "x": 3,
      "y": 2,
      "z": -1,
      "name": "Empty"
    },
    {
      "x": 3,
      "y": 3,
      "z": -1,
      "name": "Empty"
    },
    {
      "x": 3,
      "y": -1,
      "z": 0,
      "name": "Rock_Sandstone"
    },
    {
      "x": 3,
      "y": 0,
      "z": 0,
      "name": "Soil_Sand_White"
    },
    {
      "x": 3,
      "y": 1,
      "z": 0,
      "name": "Rock_Sandstone_White_Brick_Smooth_Half"
    },
    {
      "x": 3,
      "y": 2,
      "z": 0,
      "name": "Empty"
    },
    {
      "x": 3,
      "y": 3,
      "z": 0,
      "name": "Empty"
    },
    {
      "x": 3,
      "y": -1,
      "z": 1,
      "name": "Rock_Sandstone"
    },
    {
      "x": 3,
      "y": 0,
      "z": 1,
      "name": "Soil_Sand_White"
    },
    {
      "x": 3,
      "y": 1,
      "z": 1,
      "name": "Rock_Sandstone_White_Brick_Smooth_Half"
    },
    {
      "x": 3,
      "y": 2,
      "z": 1,
      "name": "Empty"
    },
    {
      "x": 3,
      "y": 3,
      "z": 1,
      "name": "Empty"
    },
    {
      "x": 3,
      "y": -1,
      "z": 2,
      "name": "Rock_Sandstone"
    },
    {
      "x": 3,
      "y": 0,
      "z": 2,
      "name": "Soil_Sand_White"
    },
    {
      "x": 3,
      "y": 1,
      "z": 2,
      "name": "Rock_Sandstone_White_Brick_Smooth"
    },
    {
      "x": 3,
      "y": 2,
      "z": 2,
      "name": "Rock_Sandstone_White_Brick_Smooth_Half"
    },
    {
      "x": 3,
      "y": 3,
      "z": 2,
      "name": "Empty"
    },
    {
      "x": 3,
      "y": -1,
      "z": 3,
      "name": "Rock_Sandstone"
    },
    {
      "x": 3,
      "y": 0,
      "z": 3,
      "name": "Soil_Sand_White"
    },
    {
      "x": 3,
      "y": 1,
      "z": 3,
      "name": "Soil_Sand_White"
    },
    {
      "x": 3,
      "y": -1,
      "z": 4,
      "name": "Rock_Sandstone"
    },
    {
      "x": 3,
      "y": 0,
      "z": 4,
      "name": "Soil_Sand_White"
    },
    {
      "x": 3,
      "y": 1,
      "z": 4,
      "name": "Soil_Sand_White"
    },
    {
      "x": 3,
      "y": 2,
      "z": 4,
      "name": "Rubble_Sandstone_White",
      "support": 15
    },
    {
      "x": 3,
      "y": -1,
      "z": 5,
      "name": "Rock_Sandstone"
    },
    {
      "x": 3,
      "y": 0,
      "z": 5,
      "name": "Soil_Sand_White"
    },
    {
      "x": 3,
      "y": 1,
      "z": 5,
      "name": "Soil_Sand_White"
    },
    {
      "x": 3,
      "y": -1,
      "z": 6,
      "name": "Rock_Sandstone"
    },
    {
      "x": 3,
      "y": 0,
      "z": 6,
      "name": "Soil_Sand_White"
    },
    {
      "x": 3,
      "y": 1,
      "z": 6,
      "name": "Soil_Sand_White"
    },
    {
      "x": 3,
      "y": 2,
      "z": 6,
      "name": "Rubble_Sandstone_White_Medium",
      "support": 15
    },
    {
      "x": 3,
      "y": -1,
      "z": 7,
      "name": "Rock_Sandstone"
    },
    {
      "x": 3,
      "y": 0,
      "z": 7,
      "name": "Soil_Sand_White"
    },
    {
      "x": 3,
      "y": 1,
      "z": 7,
      "name": "Soil_Sand_White"
    },
    {
      "x": 3,
      "y": -1,
      "z": 8,
      "name": "Rock_Sandstone"
    },
    {
      "x": 3,
      "y": 0,
      "z": 8,
      "name": "Soil_Sand_White"
    },
    {
      "x": 3,
      "y": 1,
      "z": 8,
      "name": "Soil_Sand_White"
    },
    {
      "x": 4,
      "y": -1,
      "z": -17,
      "name": "Rock_Sandstone"
    },
    {
      "x": 4,
      "y": 0,
      "z": -17,
      "name": "Soil_Sand_White"
    },
    {
      "x": 4,
      "y": -1,
      "z": -16,
      "name": "Rock_Sandstone"
    },
    {
      "x": 4,
      "y": 0,
      "z": -16,
      "name": "Soil_Sand_White"
    },
    {
      "x": 4,
      "y": -1,
      "z": -15,
      "name": "Rock_Sandstone"
    },
    {
      "x": 4,
      "y": 0,
      "z": -15,
      "name": "Soil_Sand_White"
    },
    {
      "x": 4,
      "y": -1,
      "z": -14,
      "name": "Rock_Sandstone"
    },
    {
      "x": 4,
      "y": 0,
      "z": -14,
      "name": "Soil_Sand_White"
    },
    {
      "x": 4,
      "y": -1,
      "z": -13,
      "name": "Rock_Sandstone"
    },
    {
      "x": 4,
      "y": 0,
      "z": -13,
      "name": "Soil_Sand_White"
    },
    {
      "x": 4,
      "y": -1,
      "z": -12,
      "name": "Rock_Sandstone"
    },
    {
      "x": 4,
      "y": 0,
      "z": -12,
      "name": "Soil_Sand_White"
    },
    {
      "x": 4,
      "y": 1,
      "z": -12,
      "name": "Soil_Sand_White"
    },
    {
      "x": 4,
      "y": -1,
      "z": -11,
      "name": "Rock_Sandstone"
    },
    {
      "x": 4,
      "y": 0,
      "z": -11,
      "name": "Soil_Sand_White"
    },
    {
      "x": 4,
      "y": 1,
      "z": -11,
      "name": "Soil_Sand_White"
    },
    {
      "x": 4,
      "y": -1,
      "z": -10,
      "name": "Rock_Sandstone"
    },
    {
      "x": 4,
      "y": 0,
      "z": -10,
      "name": "Soil_Sand_White"
    },
    {
      "x": 4,
      "y": 1,
      "z": -10,
      "name": "Soil_Sand_White"
    },
    {
      "x": 4,
      "y": -1,
      "z": -9,
      "name": "Rock_Sandstone"
    },
    {
      "x": 4,
      "y": 0,
      "z": -9,
      "name": "Soil_Sand_White"
    },
    {
      "x": 4,
      "y": 1,
      "z": -9,
      "name": "Soil_Sand_White"
    },
    {
      "x": 4,
      "y": -1,
      "z": -8,
      "name": "Rock_Sandstone"
    },
    {
      "x": 4,
      "y": 0,
      "z": -8,
      "name": "Soil_Sand_White"
    },
    {
      "x": 4,
      "y": 1,
      "z": -8,
      "name": "Soil_Sand_White"
    },
    {
      "x": 4,
      "y": -1,
      "z": -7,
      "name": "Rock_Sandstone"
    },
    {
      "x": 4,
      "y": 0,
      "z": -7,
      "name": "Soil_Sand_White"
    },
    {
      "x": 4,
      "y": 1,
      "z": -7,
      "name": "Soil_Sand_White"
    },
    {
      "x": 4,
      "y": -1,
      "z": -6,
      "name": "Rock_Sandstone"
    },
    {
      "x": 4,
      "y": 0,
      "z": -6,
      "name": "Soil_Sand_White"
    },
    {
      "x": 4,
      "y": 1,
      "z": -6,
      "name": "Soil_Sand_White"
    },
    {
      "x": 4,
      "y": -1,
      "z": -5,
      "name": "Rock_Sandstone"
    },
    {
      "x": 4,
      "y": 0,
      "z": -5,
      "name": "Soil_Sand_White"
    },
    {
      "x": 4,
      "y": 1,
      "z": -5,
      "name": "Soil_Sand_White"
    },
    {
      "x": 4,
      "y": -1,
      "z": -4,
      "name": "Rock_Sandstone"
    },
    {
      "x": 4,
      "y": 0,
      "z": -4,
      "name": "Soil_Sand_White"
    },
    {
      "x": 4,
      "y": 1,
      "z": -4,
      "name": "Soil_Sand_White"
    },
    {
      "x": 4,
      "y": -1,
      "z": -3,
      "name": "Rock_Sandstone"
    },
    {
      "x": 4,
      "y": 0,
      "z": -3,
      "name": "Soil_Sand_White"
    },
    {
      "x": 4,
      "y": 1,
      "z": -3,
      "name": "Rock_Sandstone_White_Brick_Smooth"
    },
    {
      "x": 4,
      "y": 2,
      "z": -3,
      "name": "Rock_Sandstone_White_Brick_Smooth_Half"
    },
    {
      "x": 4,
      "y": 3,
      "z": -3,
      "name": "Empty"
    },
    {
      "x": 4,
      "y": -1,
      "z": -2,
      "name": "Rock_Sandstone"
    },
    {
      "x": 4,
      "y": 0,
      "z": -2,
      "name": "Soil_Sand_White"
    },
    {
      "x": 4,
      "y": 1,
      "z": -2,
      "name": "Rock_Sandstone_White_Brick_Smooth_Half"
    },
    {
      "x": 4,
      "y": 2,
      "z": -2,
      "name": "Empty"
    },
    {
      "x": 4,
      "y": 3,
      "z": -2,
      "name": "Empty"
    },
    {
      "x": 4,
      "y": -1,
      "z": -1,
      "name": "Rock_Sandstone"
    },
    {
      "x": 4,
      "y": 0,
      "z": -1,
      "name": "Soil_Sand_White"
    },
    {
      "x": 4,
      "y": 1,
      "z": -1,
      "name": "Rock_Sandstone_White_Brick_Smooth_Half"
    },
    {
      "x": 4,
      "y": 2,
      "z": -1,
      "name": "Empty"
    },
    {
      "x": 4,
      "y": 3,
      "z": -1,
      "name": "Empty"
    },
    {
      "x": 4,
      "y": -1,
      "z": 0,
      "name": "Rock_Sandstone"
    },
    {
      "x": 4,
      "y": 0,
      "z": 0,
      "name": "Soil_Sand_White"
    },
    {
      "x": 4,
      "y": 1,
      "z": 0,
      "name": "Rock_Sandstone_White_Brick_Smooth_Half"
    },
    {
      "x": 4,
      "y": 2,
      "z": 0,
      "name": "Empty"
    },
    {
      "x": 4,
      "y": 3,
      "z": 0,
      "name": "Empty"
    },
    {
      "x": 4,
      "y": -1,
      "z": 1,
      "name": "Rock_Sandstone"
    },
    {
      "x": 4,
      "y": 0,
      "z": 1,
      "name": "Soil_Sand_White"
    },
    {
      "x": 4,
      "y": 1,
      "z": 1,
      "name": "Rock_Sandstone_White_Brick_Smooth_Half"
    },
    {
      "x": 4,
      "y": 2,
      "z": 1,
      "name": "Empty"
    },
    {
      "x": 4,
      "y": 3,
      "z": 1,
      "name": "Empty"
    },
    {
      "x": 4,
      "y": -1,
      "z": 2,
      "name": "Rock_Sandstone"
    },
    {
      "x": 4,
      "y": 0,
      "z": 2,
      "name": "Soil_Sand_White"
    },
    {
      "x": 4,
      "y": 1,
      "z": 2,
      "name": "Rock_Sandstone_White_Brick_Smooth"
    },
    {
      "x": 4,
      "y": 2,
      "z": 2,
      "name": "Rock_Sandstone_White_Brick_Smooth_Half"
    },
    {
      "x": 4,
      "y": 3,
      "z": 2,
      "name": "Empty"
    },
    {
      "x": 4,
      "y": -1,
      "z": 3,
      "name": "Rock_Sandstone"
    },
    {
      "x": 4,
      "y": 0,
      "z": 3,
      "name": "Soil_Sand_White"
    },
    {
      "x": 4,
      "y": 1,
      "z": 3,
      "name": "Soil_Sand_White"
    },
    {
      "x": 4,
      "y": -1,
      "z": 4,
      "name": "Rock_Sandstone"
    },
    {
      "x": 4,
      "y": 0,
      "z": 4,
      "name": "Soil_Sand_White"
    },
    {
      "x": 4,
      "y": 1,
      "z": 4,
      "name": "Soil_Sand_White"
    },
    {
      "x": 4,
      "y": -1,
      "z": 5,
      "name": "Rock_Sandstone"
    },
    {
      "x": 4,
      "y": 0,
      "z": 5,
      "name": "Soil_Sand_White"
    },
    {
      "x": 4,
      "y": 1,
      "z": 5,
      "name": "Soil_Sand_White"
    },
    {
      "x": 4,
      "y": -1,
      "z": 6,
      "name": "Rock_Sandstone"
    },
    {
      "x": 4,
      "y": 0,
      "z": 6,
      "name": "Soil_Sand_White"
    },
    {
      "x": 4,
      "y": 1,
      "z": 6,
      "name": "Soil_Sand_White"
    },
    {
      "x": 4,
      "y": -1,
      "z": 7,
      "name": "Rock_Sandstone"
    },
    {
      "x": 4,
      "y": 0,
      "z": 7,
      "name": "Soil_Sand_White"
    },
    {
      "x": 4,
      "y": 1,
      "z": 7,
      "name": "Soil_Sand_White"
    },
    {
      "x": 4,
      "y": 2,
      "z": 7,
      "name": "Rubble_Sandstone_White_Medium",
      "support": 15
    },
    {
      "x": 4,
      "y": -1,
      "z": 8,
      "name": "Rock_Sandstone"
    },
    {
      "x": 4,
      "y": 0,
      "z": 8,
      "name": "Soil_Sand_White"
    },
    {
      "x": 4,
      "y": 1,
      "z": 8,
      "name": "Soil_Sand_White"
    },
    {
      "x": 5,
      "y": -1,
      "z": -17,
      "name": "Rock_Sandstone"
    },
    {
      "x": 5,
      "y": 0,
      "z": -17,
      "name": "Soil_Sand_White"
    },
    {
      "x": 5,
      "y": -1,
      "z": -16,
      "name": "Rock_Sandstone"
    },
    {
      "x": 5,
      "y": 0,
      "z": -16,
      "name": "Soil_Sand_White"
    },
    {
      "x": 5,
      "y": -1,
      "z": -15,
      "name": "Rock_Sandstone"
    },
    {
      "x": 5,
      "y": 0,
      "z": -15,
      "name": "Soil_Sand_White"
    },
    {
      "x": 5,
      "y": -1,
      "z": -14,
      "name": "Rock_Sandstone"
    },
    {
      "x": 5,
      "y": 0,
      "z": -14,
      "name": "Soil_Sand_White"
    },
    {
      "x": 5,
      "y": -1,
      "z": -13,
      "name": "Rock_Sandstone"
    },
    {
      "x": 5,
      "y": 0,
      "z": -13,
      "name": "Soil_Sand_White"
    },
    {
      "x": 5,
      "y": 1,
      "z": -13,
      "name": "Plant_Bush_Dead_Tall"
    },
    {
      "x": 5,
      "y": -1,
      "z": -12,
      "name": "Rock_Sandstone"
    },
    {
      "x": 5,
      "y": 0,
      "z": -12,
      "name": "Soil_Sand_White"
    },
    {
      "x": 5,
      "y": -1,
      "z": -11,
      "name": "Rock_Sandstone"
    },
    {
      "x": 5,
      "y": 0,
      "z": -11,
      "name": "Soil_Sand_White"
    },
    {
      "x": 5,
      "y": 1,
      "z": -11,
      "name": "Soil_Sand_White"
    },
    {
      "x": 5,
      "y": -1,
      "z": -10,
      "name": "Rock_Sandstone"
    },
    {
      "x": 5,
      "y": 0,
      "z": -10,
      "name": "Soil_Sand_White"
    },
    {
      "x": 5,
      "y": 1,
      "z": -10,
      "name": "Soil_Sand_White"
    },
    {
      "x": 5,
      "y": -1,
      "z": -9,
      "name": "Rock_Sandstone"
    },
    {
      "x": 5,
      "y": 0,
      "z": -9,
      "name": "Soil_Sand_White"
    },
    {
      "x": 5,
      "y": 1,
      "z": -9,
      "name": "Soil_Sand_White"
    },
    {
      "x": 5,
      "y": 2,
      "z": -9,
      "name": "Rubble_Sandstone_White_Medium",
      "support": 15
    },
    {
      "x": 5,
      "y": -1,
      "z": -8,
      "name": "Rock_Sandstone"
    },
    {
      "x": 5,
      "y": 0,
      "z": -8,
      "name": "Soil_Sand_White"
    },
    {
      "x": 5,
      "y": 1,
      "z": -8,
      "name": "Soil_Sand_White"
    },
    {
      "x": 5,
      "y": -1,
      "z": -7,
      "name": "Rock_Sandstone"
    },
    {
      "x": 5,
      "y": 0,
      "z": -7,
      "name": "Soil_Sand_White"
    },
    {
      "x": 5,
      "y": 1,
      "z": -7,
      "name": "Soil_Sand_White"
    },
    {
      "x": 5,
      "y": -1,
      "z": -6,
      "name": "Rock_Sandstone"
    },
    {
      "x": 5,
      "y": 0,
      "z": -6,
      "name": "Soil_Sand_White"
    },
    {
      "x": 5,
      "y": 1,
      "z": -6,
      "name": "Soil_Sand_White"
    },
    {
      "x": 5,
      "y": -1,
      "z": -5,
      "name": "Rock_Sandstone"
    },
    {
      "x": 5,
      "y": 0,
      "z": -5,
      "name": "Soil_Sand_White"
    },
    {
      "x": 5,
      "y": 1,
      "z": -5,
      "name": "Soil_Sand_White"
    },
    {
      "x": 5,
      "y": -1,
      "z": -4,
      "name": "Rock_Sandstone"
    },
    {
      "x": 5,
      "y": 0,
      "z": -4,
      "name": "Soil_Sand_White"
    },
    {
      "x": 5,
      "y": 1,
      "z": -4,
      "name": "Soil_Sand_White"
    },
    {
      "x": 5,
      "y": -1,
      "z": -3,
      "name": "Rock_Sandstone"
    },
    {
      "x": 5,
      "y": 0,
      "z": -3,
      "name": "Soil_Sand_White"
    },
    {
      "x": 5,
      "y": 1,
      "z": -3,
      "name": "Rock_Sandstone_White_Brick_Smooth"
    },
    {
      "x": 5,
      "y": 2,
      "z": -3,
      "name": "Rock_Sandstone_White_Brick_Smooth_Half"
    },
    {
      "x": 5,
      "y": 3,
      "z": -3,
      "name": "Empty"
    },
    {
      "x": 5,
      "y": -1,
      "z": -2,
      "name": "Rock_Sandstone"
    },
    {
      "x": 5,
      "y": 0,
      "z": -2,
      "name": "Soil_Sand_White"
    },
    {
      "x": 5,
      "y": 1,
      "z": -2,
      "name": "Rock_Sandstone_White_Brick_Smooth_Half"
    },
    {
      "x": 5,
      "y": 2,
      "z": -2,
      "name": "Empty"
    },
    {
      "x": 5,
      "y": 3,
      "z": -2,
      "name": "Empty"
    },
    {
      "x": 5,
      "y": -1,
      "z": -1,
      "name": "Rock_Sandstone"
    },
    {
      "x": 5,
      "y": 0,
      "z": -1,
      "name": "Soil_Sand_White"
    },
    {
      "x": 5,
      "y": 1,
      "z": -1,
      "name": "Rock_Sandstone_White_Brick_Smooth_Half"
    },
    {
      "x": 5,
      "y": 2,
      "z": -1,
      "name": "Empty"
    },
    {
      "x": 5,
      "y": 3,
      "z": -1,
      "name": "Empty"
    },
    {
      "x": 5,
      "y": -1,
      "z": 0,
      "name": "Rock_Sandstone"
    },
    {
      "x": 5,
      "y": 0,
      "z": 0,
      "name": "Soil_Sand_White"
    },
    {
      "x": 5,
      "y": 1,
      "z": 0,
      "name": "Rock_Sandstone_White_Brick_Smooth_Half"
    },
    {
      "x": 5,
      "y": 2,
      "z": 0,
      "name": "Empty"
    },
    {
      "x": 5,
      "y": 3,
      "z": 0,
      "name": "Empty"
    },
    {
      "x": 5,
      "y": -1,
      "z": 1,
      "name": "Rock_Sandstone"
    },
    {
      "x": 5,
      "y": 0,
      "z": 1,
      "name": "Soil_Sand_White"
    },
    {
      "x": 5,
      "y": 1,
      "z": 1,
      "name": "Rock_Sandstone_White_Brick_Smooth_Half"
    },
    {
      "x": 5,
      "y": 2,
      "z": 1,
      "name": "Empty"
    },
    {
      "x": 5,
      "y": 3,
      "z": 1,
      "name": "Empty"
    },
    {
      "x": 5,
      "y": -1,
      "z": 2,
      "name": "Rock_Sandstone"
    },
    {
      "x": 5,
      "y": 0,
      "z": 2,
      "name": "Soil_Sand_White"
    },
    {
      "x": 5,
      "y": 1,
      "z": 2,
      "name": "Rock_Sandstone_White_Brick_Smooth"
    },
    {
      "x": 5,
      "y": 2,
      "z": 2,
      "name": "Rock_Sandstone_White_Brick_Smooth_Half"
    },
    {
      "x": 5,
      "y": 3,
      "z": 2,
      "name": "Empty"
    },
    {
      "x": 5,
      "y": -1,
      "z": 3,
      "name": "Rock_Sandstone"
    },
    {
      "x": 5,
      "y": 0,
      "z": 3,
      "name": "Soil_Sand_White"
    },
    {
      "x": 5,
      "y": 1,
      "z": 3,
      "name": "Soil_Sand_White"
    },
    {
      "x": 5,
      "y": -1,
      "z": 4,
      "name": "Rock_Sandstone"
    },
    {
      "x": 5,
      "y": 0,
      "z": 4,
      "name": "Soil_Sand_White"
    },
    {
      "x": 5,
      "y": 1,
      "z": 4,
      "name": "Soil_Sand_White"
    },
    {
      "x": 5,
      "y": -1,
      "z": 5,
      "name": "Rock_Sandstone"
    },
    {
      "x": 5,
      "y": 0,
      "z": 5,
      "name": "Soil_Sand_White"
    },
    {
      "x": 5,
      "y": 1,
      "z": 5,
      "name": "Soil_Sand_White"
    },
    {
      "x": 5,
      "y": -1,
      "z": 6,
      "name": "Rock_Sandstone"
    },
    {
      "x": 5,
      "y": 0,
      "z": 6,
      "name": "Soil_Sand_White"
    },
    {
      "x": 5,
      "y": 1,
      "z": 6,
      "name": "Soil_Sand_White"
    },
    {
      "x": 5,
      "y": -1,
      "z": 7,
      "name": "Rock_Sandstone"
    },
    {
      "x": 5,
      "y": 0,
      "z": 7,
      "name": "Soil_Sand_White"
    },
    {
      "x": 5,
      "y": 1,
      "z": 7,
      "name": "Soil_Sand_White"
    },
    {
      "x": 5,
      "y": -1,
      "z": 8,
      "name": "Rock_Sandstone"
    },
    {
      "x": 5,
      "y": 0,
      "z": 8,
      "name": "Soil_Sand_White"
    },
    {
      "x": 5,
      "y": 1,
      "z": 8,
      "name": "Soil_Sand_White"
    },
    {
      "x": 6,
      "y": -1,
      "z": -17,
      "name": "Rock_Sandstone"
    },
    {
      "x": 6,
      "y": 0,
      "z": -17,
      "name": "Soil_Sand_White"
    },
    {
      "x": 6,
      "y": -1,
      "z": -16,
      "name": "Rock_Sandstone"
    },
    {
      "x": 6,
      "y": 0,
      "z": -16,
      "name": "Soil_Sand_White"
    },
    {
      "x": 6,
      "y": -1,
      "z": -15,
      "name": "Rock_Sandstone"
    },
    {
      "x": 6,
      "y": 0,
      "z": -15,
      "name": "Soil_Sand_White"
    },
    {
      "x": 6,
      "y": -1,
      "z": -14,
      "name": "Rock_Sandstone"
    },
    {
      "x": 6,
      "y": 0,
      "z": -14,
      "name": "Soil_Sand_White"
    },
    {
      "x": 6,
      "y": -1,
      "z": -13,
      "name": "Rock_Sandstone"
    },
    {
      "x": 6,
      "y": 0,
      "z": -13,
      "name": "Soil_Sand_White"
    },
    {
      "x": 6,
      "y": -1,
      "z": -12,
      "name": "Rock_Sandstone"
    },
    {
      "x": 6,
      "y": 0,
      "z": -12,
      "name": "Soil_Sand_White"
    },
    {
      "x": 6,
      "y": -1,
      "z": -11,
      "name": "Rock_Sandstone"
    },
    {
      "x": 6,
      "y": 0,
      "z": -11,
      "name": "Soil_Sand_White"
    },
    {
      "x": 6,
      "y": -1,
      "z": -10,
      "name": "Rock_Sandstone"
    },
    {
      "x": 6,
      "y": 0,
      "z": -10,
      "name": "Soil_Sand_White"
    },
    {
      "x": 6,
      "y": 1,
      "z": -10,
      "name": "Soil_Sand_White"
    },
    {
      "x": 6,
      "y": -1,
      "z": -9,
      "name": "Rock_Sandstone"
    },
    {
      "x": 6,
      "y": 0,
      "z": -9,
      "name": "Soil_Sand_White"
    },
    {
      "x": 6,
      "y": 1,
      "z": -9,
      "name": "Soil_Sand_White"
    },
    {
      "x": 6,
      "y": -1,
      "z": -8,
      "name": "Rock_Sandstone"
    },
    {
      "x": 6,
      "y": 0,
      "z": -8,
      "name": "Soil_Sand_White"
    },
    {
      "x": 6,
      "y": 1,
      "z": -8,
      "name": "Soil_Sand_White"
    },
    {
      "x": 6,
      "y": -1,
      "z": -7,
      "name": "Rock_Sandstone"
    },
    {
      "x": 6,
      "y": 0,
      "z": -7,
      "name": "Soil_Sand_White"
    },
    {
      "x": 6,
      "y": 1,
      "z": -7,
      "name": "Soil_Sand_White"
    },
    {
      "x": 6,
      "y": -1,
      "z": -6,
      "name": "Rock_Sandstone"
    },
    {
      "x": 6,
      "y": 0,
      "z": -6,
      "name": "Soil_Sand_White"
    },
    {
      "x": 6,
      "y": 1,
      "z": -6,
      "name": "Soil_Sand_White"
    },
    {
      "x": 6,
      "y": -1,
      "z": -5,
      "name": "Rock_Sandstone"
    },
    {
      "x": 6,
      "y": 0,
      "z": -5,
      "name": "Soil_Sand_White"
    },
    {
      "x": 6,
      "y": 1,
      "z": -5,
      "name": "Soil_Sand_White"
    },
    {
      "x": 6,
      "y": 2,
      "z": -5,
      "name": "Furniture_Tavern_Barrel"
    },
    {
      "x": 6,
      "y": -1,
      "z": -4,
      "name": "Rock_Sandstone"
    },
    {
      "x": 6,
      "y": 0,
      "z": -4,
      "name": "Rock_Sandstone_White_Brick_Smooth"
    },
    {
      "x": 6,
      "y": 1,
      "z": -4,
      "name": "Wood_Stripped_Deco"
    },
    {
      "x": 6,
      "y": 2,
      "z": -4,
      "name": "Furniture_Tavern_Barrel"
    },
    {
      "x": 6,
      "y": -1,
      "z": -3,
      "name": "Rock_Sandstone"
    },
    {
      "x": 6,
      "y": 0,
      "z": -3,
      "name": "Rock_Sandstone_White_Brick_Smooth"
    },
    {
      "x": 6,
      "y": 1,
      "z": -3,
      "name": "Wood_Stripped_Deco"
    },
    {
      "x": 6,
      "y": 2,
      "z": -3,
      "name": "Rock_Sandstone_White_Brick_Smooth"
    },
    {
      "x": 6,
      "y": 3,
      "z": -3,
      "name": "Rock_Sandstone_White_Brick_Smooth"
    },
    {
      "x": 6,
      "y": 4,
      "z": -3,
      "name": "Rock_Sandstone_White_Brick_Smooth"
    },
    {
      "x": 6,
      "y": 5,
      "z": -3,
      "name": "Wood_Stripped_Deco"
    },
    {
      "x": 6,
      "y": -1,
      "z": -2,
      "name": "Rock_Sandstone"
    },
    {
      "x": 6,
      "y": 0,
      "z": -2,
      "name": "Rock_Sandstone_White_Brick_Smooth"
    },
    {
      "x": 6,
      "y": 1,
      "z": -2,
      "name": "Empty"
    },
    {
      "x": 6,
      "y": 2,
      "z": -2,
      "name": "Empty"
    },
    {
      "x": 6,
      "y": 3,
      "z": -2,
      "name": "Empty"
    },
    {
      "x": 6,
      "y": 4,
      "z": -2,
      "name": "Rock_Sandstone_White_Stairs",
      "rotation": 10
    },
    {
      "x": 6,
      "y": 5,
      "z": -2,
      "name": "Rock_Sandstone_White_Brick_Smooth"
    },
    {
      "x": 6,
      "y": 6,
      "z": -2,
      "name": "Wood_Stripped_Deco"
    },
    {
      "x": 6,
      "y": 7,
      "z": -2,
      "name": "Rock_Sandstone_White_Brick_Smooth_Half"
    },
    {
      "x": 6,
      "y": -1,
      "z": -1,
      "name": "Rock_Sandstone"
    },
    {
      "x": 6,
      "y": 0,
      "z": -1,
      "name": "Wood_Stripped_Deco"
    },
    {
      "x": 6,
      "y": 1,
      "z": -1,
      "name": "Empty"
    },
    {
      "x": 6,
      "y": 2,
      "z": -1,
      "name": "Empty"
    },
    {
      "x": 6,
      "y": 3,
      "z": -1,
      "name": "Empty"
    },
    {
      "x": 6,
      "y": 6,
      "z": -1,
      "name": "Rock_Sandstone_White_Brick_Smooth"
    },
    {
      "x": 6,
      "y": 7,
      "z": -1,
      "name": "Wood_Stripped_Deco"
    },
    {
      "x": 6,
      "y": -1,
      "z": 0,
      "name": "Rock_Sandstone"
    },
    {
      "x": 6,
      "y": 0,
      "z": 0,
      "name": "Rock_Sandstone_White_Brick_Smooth"
    },
    {
      "x": 6,
      "y": 1,
      "z": 0,
      "name": "Empty"
    },
    {
      "x": 6,
      "y": 2,
      "z": 0,
      "name": "Empty"
    },
    {
      "x": 6,
      "y": 3,
      "z": 0,
      "name": "Empty"
    },
    {
      "x": 6,
      "y": 6,
      "z": 0,
      "name": "Rock_Sandstone_White_Brick_Smooth"
    },
    {
      "x": 6,
      "y": 7,
      "z": 0,
      "name": "Rock_Sandstone_White_Brick_Smooth"
    },
    {
      "x": 6,
      "y": -1,
      "z": 1,
      "name": "Rock_Sandstone"
    },
    {
      "x": 6,
      "y": 0,
      "z": 1,
      "name": "Rock_Sandstone_White_Brick_Smooth"
    },
    {
      "x": 6,
      "y": 1,
      "z": 1,
      "name": "Empty"
    },
    {
      "x": 6,
      "y": 2,
      "z": 1,
      "name": "Empty"
    },
    {
      "x": 6,
      "y": 3,
      "z": 1,
      "name": "Empty"
    },
    {
      "x": 6,
      "y": 4,
      "z": 1,
      "name": "Rock_Sandstone_White_Stairs",
      "rotation": 8
    },
    {
      "x": 6,
      "y": 5,
      "z": 1,
      "name": "Rock_Sandstone_White_Brick_Smooth"
    },
    {
      "x": 6,
      "y": 6,
      "z": 1,
      "name": "Wood_Stripped_Deco"
    },
    {
      "x": 6,
      "y": 7,
      "z": 1,
      "name": "Rock_Sandstone_White_Brick_Smooth_Half"
    },
    {
      "x": 6,
      "y": -1,
      "z": 2,
      "name": "Rock_Sandstone"
    },
    {
      "x": 6,
      "y": 0,
      "z": 2,
      "name": "Wood_Stripped_Deco"
    },
    {
      "x": 6,
      "y": 1,
      "z": 2,
      "name": "Rock_Sandstone_White_Brick_Smooth"
    },
    {
      "x": 6,
      "y": 2,
      "z": 2,
      "name": "Rock_Sandstone_White_Brick_Smooth"
    },
    {
      "x": 6,
      "y": 3,
      "z": 2,
      "name": "Wood_Stripped_Deco"
    },
    {
      "x": 6,
      "y": 4,
      "z": 2,
      "name": "Wood_Stripped_Deco"
    },
    {
      "x": 6,
      "y": 5,
      "z": 2,
      "name": "Wood_Stripped_Deco"
    },
    {
      "x": 6,
      "y": -1,
      "z": 3,
      "name": "Rock_Sandstone"
    },
    {
      "x": 6,
      "y": 0,
      "z": 3,
      "name": "Rock_Sandstone_White_Brick_Smooth"
    },
    {
      "x": 6,
      "y": 1,
      "z": 3,
      "name": "Wood_Stripped_Deco"
    },
    {
      "x": 6,
      "y": -1,
      "z": 4,
      "name": "Rock_Sandstone"
    },
    {
      "x": 6,
      "y": 0,
      "z": 4,
      "name": "Soil_Sand_White"
    },
    {
      "x": 6,
      "y": 1,
      "z": 4,
      "name": "Soil_Sand_White"
    },
    {
      "x": 6,
      "y": 2,
      "z": 4,
      "name": "Furniture_Tavern_Barrel"
    },
    {
      "x": 6,
      "y": -1,
      "z": 5,
      "name": "Rock_Sandstone"
    },
    {
      "x": 6,
      "y": 0,
      "z": 5,
      "name": "Soil_Sand_White"
    },
    {
      "x": 6,
      "y": 1,
      "z": 5,
      "name": "Soil_Sand_White"
    },
    {
      "x": 6,
      "y": 2,
      "z": 5,
      "name": "Furniture_Tavern_Barrel"
    },
    {
      "x": 6,
      "y": -1,
      "z": 6,
      "name": "Rock_Sandstone"
    },
    {
      "x": 6,
      "y": 0,
      "z": 6,
      "name": "Soil_Sand_White"
    },
    {
      "x": 6,
      "y": 1,
      "z": 6,
      "name": "Soil_Sand_White"
    },
    {
      "x": 6,
      "y": -1,
      "z": 7,
      "name": "Rock_Sandstone"
    },
    {
      "x": 6,
      "y": 0,
      "z": 7,
      "name": "Soil_Sand_White"
    },
    {
      "x": 6,
      "y": -1,
      "z": 8,
      "name": "Rock_Sandstone"
    },
    {
      "x": 6,
      "y": 0,
      "z": 8,
      "name": "Soil_Sand_White"
    },
    {
      "x": 6,
      "y": -1,
      "z": 9,
      "name": "Rock_Sandstone"
    },
    {
      "x": 6,
      "y": 0,
      "z": 9,
      "name": "Soil_Sand_White"
    },
    {
      "x": 7,
      "y": -1,
      "z": -17,
      "name": "Rock_Sandstone"
    },
    {
      "x": 7,
      "y": 0,
      "z": -17,
      "name": "Soil_Sand_White"
    },
    {
      "x": 7,
      "y": -1,
      "z": -16,
      "name": "Rock_Sandstone"
    },
    {
      "x": 7,
      "y": 0,
      "z": -16,
      "name": "Soil_Sand_White"
    },
    {
      "x": 7,
      "y": -1,
      "z": -15,
      "name": "Rock_Sandstone"
    },
    {
      "x": 7,
      "y": 0,
      "z": -15,
      "name": "Soil_Sand_White"
    },
    {
      "x": 7,
      "y": 1,
      "z": -15,
      "name": "Rubble_Sandstone_White",
      "support": 15
    },
    {
      "x": 7,
      "y": -1,
      "z": -14,
      "name": "Rock_Sandstone"
    },
    {
      "x": 7,
      "y": 0,
      "z": -14,
      "name": "Soil_Sand_White"
    },
    {
      "x": 7,
      "y": -1,
      "z": -13,
      "name": "Rock_Sandstone"
    },
    {
      "x": 7,
      "y": 0,
      "z": -13,
      "name": "Soil_Sand_White"
    },
    {
      "x": 7,
      "y": -1,
      "z": -12,
      "name": "Rock_Sandstone"
    },
    {
      "x": 7,
      "y": 0,
      "z": -12,
      "name": "Soil_Sand_White"
    },
    {
      "x": 7,
      "y": -1,
      "z": -11,
      "name": "Rock_Sandstone"
    },
    {
      "x": 7,
      "y": 0,
      "z": -11,
      "name": "Soil_Sand_White"
    },
    {
      "x": 7,
      "y": -1,
      "z": -10,
      "name": "Rock_Sandstone"
    },
    {
      "x": 7,
      "y": 0,
      "z": -10,
      "name": "Soil_Sand_White"
    },
    {
      "x": 7,
      "y": -1,
      "z": -9,
      "name": "Rock_Sandstone"
    },
    {
      "x": 7,
      "y": 0,
      "z": -9,
      "name": "Soil_Sand_White"
    },
    {
      "x": 7,
      "y": 1,
      "z": -9,
      "name": "Soil_Sand_White"
    },
    {
      "x": 7,
      "y": -1,
      "z": -8,
      "name": "Rock_Sandstone"
    },
    {
      "x": 7,
      "y": 0,
      "z": -8,
      "name": "Soil_Sand_White"
    },
    {
      "x": 7,
      "y": 1,
      "z": -8,
      "name": "Soil_Sand_White"
    },
    {
      "x": 7,
      "y": -1,
      "z": -7,
      "name": "Rock_Sandstone"
    },
    {
      "x": 7,
      "y": 0,
      "z": -7,
      "name": "Rock_Sandstone_White_Brick_Smooth"
    },
    {
      "x": 7,
      "y": 1,
      "z": -7,
      "name": "Wood_Stripped_Deco"
    },
    {
      "x": 7,
      "y": 2,
      "z": -7,
      "name": "Furniture_Tavern_Barrel"
    },
    {
      "x": 7,
      "y": -1,
      "z": -6,
      "name": "Rock_Sandstone"
    },
    {
      "x": 7,
      "y": 0,
      "z": -6,
      "name": "Wood_Stripped_Deco"
    },
    {
      "x": 7,
      "y": 1,
      "z": -6,
      "name": "Rock_Sandstone_White_Brick_Smooth"
    },
    {
      "x": 7,
      "y": 2,
      "z": -6,
      "name": "Rock_Sandstone_White_Brick_Smooth"
    },
    {
      "x": 7,
      "y": -1,
      "z": -5,
      "name": "Rock_Sandstone"
    },
    {
      "x": 7,
      "y": 0,
      "z": -5,
      "name": "Rock_Sandstone_White_Brick_Smooth"
    },
    {
      "x": 7,
      "y": 1,
      "z": -5,
      "name": "Rock_Sandstone_White_Brick_Smooth"
    },
    {
      "x": 7,
      "y": 2,
      "z": -5,
      "name": "Wood_Stripped_Deco"
    },
    {
      "x": 7,
      "y": 3,
      "z": -5,
      "name": "Rock_Sandstone_White_Brick_Smooth"
    },
    {
      "x": 7,
      "y": 4,
      "z": -5,
      "name": "Rock_Sandstone_White_Brick_Smooth"
    },
    {
      "x": 7,
      "y": -1,
      "z": -4,
      "name": "Rock_Sandstone"
    },
    {
      "x": 7,
      "y": 0,
      "z": -4,
      "name": "Rock_Sandstone_White_Brick_Smooth"
    },
    {
      "x": 7,
      "y": 1,
      "z": -4,
      "name": "Empty"
    },
    {
      "x": 7,
      "y": 2,
      "z": -4,
      "name": "Wood_Stripped_Deco"
    },
    {
      "x": 7,
      "y": 3,
      "z": -4,
      "name": "Wood_Stripped_Deco"
    },
    {
      "x": 7,
      "y": 4,
      "z": -4,
      "name": "Wood_Stripped_Deco"
    },
    {
      "x": 7,
      "y": 5,
      "z": -4,
      "name": "Wood_Stripped_Deco"
    },
    {
      "x": 7,
      "y": -1,
      "z": -3,
      "name": "Rock_Sandstone"
    },
    {
      "x": 7,
      "y": 0,
      "z": -3,
      "name": "Wood_Stripped_Deco"
    },
    {
      "x": 7,
      "y": 1,
      "z": -3,
      "name": "Rock_Sandstone_White_Brick_Smooth"
    },
    {
      "x": 7,
      "y": 2,
      "z": -3,
      "name": "Rock_Sandstone_White_Brick_Smooth"
    },
    {
      "x": 7,
      "y": 3,
      "z": -3,
      "name": "Wood_Stripped_Deco"
    },
    {
      "x": 7,
      "y": 5,
      "z": -3,
      "name": "Rock_Sandstone_White_Brick_Smooth"
    },
    {
      "x": 7,
      "y": 6,
      "z": -3,
      "name": "Rock_Sandstone_White_Brick_Smooth_Half"
    },
    {
      "x": 7,
      "y": -1,
      "z": -2,
      "name": "Rock_Sandstone"
    },
    {
      "x": 7,
      "y": 0,
      "z": -2,
      "name": "Rock_Sandstone_White_Brick_Smooth"
    },
    {
      "x": 7,
      "y": 1,
      "z": -2,
      "name": "Empty"
    },
    {
      "x": 7,
      "y": 2,
      "z": -2,
      "name": "Empty"
    },
    {
      "x": 7,
      "y": 3,
      "z": -2,
      "name": "Empty"
    },
    {
      "x": 7,
      "y": 4,
      "z": -2,
      "name": "Rock_Sandstone_White_Stairs",
      "rotation": 10
    },
    {
      "x": 7,
      "y": 5,
      "z": -2,
      "name": "Rock_Sandstone_White_Brick_Smooth"
    },
    {
      "x": 7,
      "y": 6,
      "z": -2,
      "name": "Wood_Stripped_Deco"
    },
    {
      "x": 7,
      "y": 7,
      "z": -2,
      "name": "Wood_Stripped_Deco"
    },
    {
      "x": 7,
      "y": -1,
      "z": -1,
      "name": "Rock_Sandstone"
    },
    {
      "x": 7,
      "y": 0,
      "z": -1,
      "name": "Rock_Sandstone_White_Brick_Smooth"
    },
    {
      "x": 7,
      "y": 1,
      "z": -1,
      "name": "Empty"
    },
    {
      "x": 7,
      "y": 2,
      "z": -1,
      "name": "Empty"
    },
    {
      "x": 7,
      "y": 3,
      "z": -1,
      "name": "Empty"
    },
    {
      "x": 7,
      "y": 6,
      "z": -1,
      "name": "Rock_Sandstone_White_Brick_Smooth"
    },
    {
      "x": 7,
      "y": 7,
      "z": -1,
      "name": "Rock_Sandstone_White_Brick_Smooth"
    },
    {
      "x": 7,
      "y": -1,
      "z": 0,
      "name": "Rock_Sandstone"
    },
    {
      "x": 7,
      "y": 0,
      "z": 0,
      "name": "Rock_Sandstone_White_Brick_Smooth"
    },
    {
      "x": 7,
      "y": 1,
      "z": 0,
      "name": "Empty"
    },
    {
      "x": 7,
      "y": 2,
      "z": 0,
      "name": "Empty"
    },
    {
      "x": 7,
      "y": 3,
      "z": 0,
      "name": "Empty"
    },
    {
      "x": 7,
      "y": 6,
      "z": 0,
      "name": "Rock_Sandstone_White_Brick_Smooth"
    },
    {
      "x": 7,
      "y": 7,
      "z": 0,
      "name": "Rock_Sandstone_White_Brick_Smooth"
    },
    {
      "x": 7,
      "y": -1,
      "z": 1,
      "name": "Rock_Sandstone"
    },
    {
      "x": 7,
      "y": 0,
      "z": 1,
      "name": "Wood_Stripped_Deco"
    },
    {
      "x": 7,
      "y": 1,
      "z": 1,
      "name": "Empty"
    },
    {
      "x": 7,
      "y": 2,
      "z": 1,
      "name": "Empty"
    },
    {
      "x": 7,
      "y": 3,
      "z": 1,
      "name": "Empty"
    },
    {
      "x": 7,
      "y": 4,
      "z": 1,
      "name": "Rock_Sandstone_White_Stairs",
      "rotation": 8
    },
    {
      "x": 7,
      "y": 5,
      "z": 1,
      "name": "Rock_Sandstone_White_Brick_Smooth"
    },
    {
      "x": 7,
      "y": 6,
      "z": 1,
      "name": "Rock_Sandstone_White_Brick_Smooth"
    },
    {
      "x": 7,
      "y": 7,
      "z": 1,
      "name": "Wood_Stripped_Deco"
    },
    {
      "x": 7,
      "y": -1,
      "z": 2,
      "name": "Rock_Sandstone"
    },
    {
      "x": 7,
      "y": 0,
      "z": 2,
      "name": "Rock_Sandstone_White_Brick_Smooth"
    },
    {
      "x": 7,
      "y": 1,
      "z": 2,
      "name": "Rock_Sandstone_White_Brick_Smooth"
    },
    {
      "x": 7,
      "y": 2,
      "z": 2,
      "name": "Rock_Sandstone_White_Brick_Smooth"
    },
    {
      "x": 7,
      "y": 3,
      "z": 2,
      "name": "Rock_Sandstone_White_Brick_Smooth"
    },
    {
      "x": 7,
      "y": 4,
      "z": 2,
      "name": "Rock_Sandstone_White_Brick_Smooth"
    },
    {
      "x": 7,
      "y": 5,
      "z": 2,
      "name": "Wood_Stripped_Deco"
    },
    {
      "x": 7,
      "y": 6,
      "z": 2,
      "name": "Rock_Sandstone_White_Brick_Smooth_Half"
    },
    {
      "x": 7,
      "y": -1,
      "z": 3,
      "name": "Rock_Sandstone"
    },
    {
      "x": 7,
      "y": 0,
      "z": 3,
      "name": "Rock_Sandstone_White_Brick_Smooth"
    },
    {
      "x": 7,
      "y": 1,
      "z": 3,
      "name": "Empty"
    },
    {
      "x": 7,
      "y": 2,
      "z": 3,
      "name": "Rock_Sandstone_White_Brick_Smooth"
    },
    {
      "x": 7,
      "y": 3,
      "z": 3,
      "name": "Rock_Sandstone_White_Brick_Smooth"
    },
    {
      "x": 7,
      "y": 4,
      "z": 3,
      "name": "Rock_Sandstone_White_Brick_Smooth"
    },
    {
      "x": 7,
      "y": 5,
      "z": 3,
      "name": "Rock_Sandstone_White_Brick_Smooth_Half"
    },
    {
      "x": 7,
      "y": -1,
      "z": 4,
      "name": "Rock_Sandstone"
    },
    {
      "x": 7,
      "y": 0,
      "z": 4,
      "name": "Rock_Sandstone_White_Brick_Smooth"
    },
    {
      "x": 7,
      "y": 1,
      "z": 4,
      "name": "Wood_Stripped_Deco"
    },
    {
      "x": 7,
      "y": 2,
      "z": 4,
      "name": "Wood_Stripped_Deco"
    },
    {
      "x": 7,
      "y": 3,
      "z": 4,
      "name": "Rock_Sandstone_White_Brick_Smooth"
    },
    {
      "x": 7,
      "y": 4,
      "z": 4,
      "name": "Rock_Sandstone_White_Brick_Smooth"
    },
    {
      "x": 7,
      "y": 5,
      "z": 4,
      "name": "Rock_Sandstone_White_Brick_Smooth_Half"
    },
    {
      "x": 7,
      "y": -1,
      "z": 5,
      "name": "Rock_Sandstone"
    },
    {
      "x": 7,
      "y": 0,
      "z": 5,
      "name": "Rock_Sandstone_White_Brick_Smooth"
    },
    {
      "x": 7,
      "y": 1,
      "z": 5,
      "name": "Rock_Sandstone_White_Brick_Smooth"
    },
    {
      "x": 7,
      "y": 2,
      "z": 5,
      "name": "Rock_Sandstone_White_Brick_Smooth"
    },
    {
      "x": 7,
      "y": 3,
      "z": 5,
      "name": "Rock_Sandstone_White_Brick_Smooth"
    },
    {
      "x": 7,
      "y": 4,
      "z": 5,
      "name": "Wood_Stripped_Deco"
    },
    {
      "x": 7,
      "y": 5,
      "z": 5,
      "name": "Rock_Sandstone_White_Brick_Smooth_Half"
    },
    {
      "x": 7,
      "y": -1,
      "z": 6,
      "name": "Rock_Sandstone"
    },
    {
      "x": 7,
      "y": 0,
      "z": 6,
      "name": "Soil_Sand_White"
    },
    {
      "x": 7,
      "y": 1,
      "z": 6,
      "name": "Wood_Stripped_Deco"
    },
    {
      "x": 7,
      "y": 2,
      "z": 6,
      "name": "Furniture_Tavern_Barrel",
      "rotation": 1
    },
    {
      "x": 7,
      "y": -1,
      "z": 7,
      "name": "Rock_Sandstone"
    },
    {
      "x": 7,
      "y": 0,
      "z": 7,
      "name": "Soil_Sand_White"
    },
    {
      "x": 7,
      "y": -1,
      "z": 8,
      "name": "Rock_Sandstone"
    },
    {
      "x": 7,
      "y": 0,
      "z": 8,
      "name": "Soil_Sand_White"
    },
    {
      "x": 7,
      "y": -1,
      "z": 9,
      "name": "Rock_Sandstone"
    },
    {
      "x": 7,
      "y": 0,
      "z": 9,
      "name": "Soil_Sand_White"
    },
    {
      "x": 7,
      "y": -1,
      "z": 10,
      "name": "Rock_Sandstone"
    },
    {
      "x": 7,
      "y": 0,
      "z": 10,
      "name": "Soil_Sand_White"
    },
    {
      "x": 7,
      "y": -1,
      "z": 11,
      "name": "Rock_Sandstone"
    },
    {
      "x": 7,
      "y": 0,
      "z": 11,
      "name": "Soil_Sand_White"
    },
    {
      "x": 7,
      "y": -1,
      "z": 12,
      "name": "Rock_Sandstone"
    },
    {
      "x": 7,
      "y": 0,
      "z": 12,
      "name": "Soil_Sand_White"
    },
    {
      "x": 7,
      "y": -1,
      "z": 13,
      "name": "Rock_Sandstone"
    },
    {
      "x": 7,
      "y": 0,
      "z": 13,
      "name": "Soil_Sand_White"
    },
    {
      "x": 8,
      "y": -1,
      "z": -17,
      "name": "Rock_Sandstone"
    },
    {
      "x": 8,
      "y": 0,
      "z": -17,
      "name": "Soil_Sand_White"
    },
    {
      "x": 8,
      "y": -1,
      "z": -16,
      "name": "Rock_Sandstone"
    },
    {
      "x": 8,
      "y": 0,
      "z": -16,
      "name": "Soil_Sand_White"
    },
    {
      "x": 8,
      "y": -1,
      "z": -15,
      "name": "Rock_Sandstone"
    },
    {
      "x": 8,
      "y": 0,
      "z": -15,
      "name": "Soil_Sand_White"
    },
    {
      "x": 8,
      "y": -1,
      "z": -14,
      "name": "Rock_Sandstone"
    },
    {
      "x": 8,
      "y": 0,
      "z": -14,
      "name": "Soil_Sand_White"
    },
    {
      "x": 8,
      "y": -1,
      "z": -13,
      "name": "Rock_Sandstone"
    },
    {
      "x": 8,
      "y": 0,
      "z": -13,
      "name": "Soil_Sand_White"
    },
    {
      "x": 8,
      "y": -1,
      "z": -12,
      "name": "Rock_Sandstone"
    },
    {
      "x": 8,
      "y": 0,
      "z": -12,
      "name": "Soil_Sand_White"
    },
    {
      "x": 8,
      "y": 1,
      "z": -12,
      "name": "Rubble_Sandstone_White_Medium",
      "support": 15
    },
    {
      "x": 8,
      "y": -1,
      "z": -11,
      "name": "Rock_Sandstone"
    },
    {
      "x": 8,
      "y": 0,
      "z": -11,
      "name": "Soil_Sand_White"
    },
    {
      "x": 8,
      "y": -1,
      "z": -10,
      "name": "Rock_Sandstone"
    },
    {
      "x": 8,
      "y": 0,
      "z": -10,
      "name": "Soil_Sand_White"
    },
    {
      "x": 8,
      "y": -1,
      "z": -9,
      "name": "Rock_Sandstone"
    },
    {
      "x": 8,
      "y": 0,
      "z": -9,
      "name": "Soil_Sand_White"
    },
    {
      "x": 8,
      "y": 1,
      "z": -9,
      "name": "Soil_Sand_White"
    },
    {
      "x": 8,
      "y": -1,
      "z": -8,
      "name": "Rock_Sandstone"
    },
    {
      "x": 8,
      "y": 0,
      "z": -8,
      "name": "Soil_Sand_White"
    },
    {
      "x": 8,
      "y": 1,
      "z": -8,
      "name": "Soil_Sand_White"
    },
    {
      "x": 8,
      "y": 2,
      "z": -8,
      "name": "Furniture_Tavern_Barrel"
    },
    {
      "x": 8,
      "y": -1,
      "z": -7,
      "name": "Rock_Sandstone"
    },
    {
      "x": 8,
      "y": 0,
      "z": -7,
      "name": "Wood_Stripped_Deco"
    },
    {
      "x": 8,
      "y": 1,
      "z": -7,
      "name": "Rock_Sandstone_White_Brick_Smooth"
    },
    {
      "x": 8,
      "y": 2,
      "z": -7,
      "name": "Rock_Sandstone_White_Brick_Smooth"
    },
    {
      "x": 8,
      "y": -1,
      "z": -6,
      "name": "Rock_Sandstone"
    },
    {
      "x": 8,
      "y": 0,
      "z": -6,
      "name": "Wood_Stripped_Deco"
    },
    {
      "x": 8,
      "y": 2,
      "z": -6,
      "name": "Wood_Stripped_Deco"
    },
    {
      "x": 8,
      "y": 3,
      "z": -6,
      "name": "Furniture_Tavern_Barrel"
    },
    {
      "x": 8,
      "y": -1,
      "z": -5,
      "name": "Rock_Sandstone"
    },
    {
      "x": 8,
      "y": 0,
      "z": -5,
      "name": "Wood_Stripped_Deco"
    },
    {
      "x": 8,
      "y": 3,
      "z": -5,
      "name": "Wood_Stripped_Deco"
    },
    {
      "x": 8,
      "y": 4,
      "z": -5,
      "name": "Wood_Stripped_Deco"
    },
    {
      "x": 8,
      "y": 5,
      "z": -5,
      "name": "Rock_Sandstone_White_Brick_Smooth"
    },
    {
      "x": 8,
      "y": -1,
      "z": -4,
      "name": "Rock_Sandstone"
    },
    {
      "x": 8,
      "y": 0,
      "z": -4,
      "name": "Wood_Stripped_Deco"
    },
    {
      "x": 8,
      "y": 1,
      "z": -4,
      "name": "Rock_Sandstone_White_Brick_Smooth"
    },
    {
      "x": 8,
      "y": 2,
      "z": -4,
      "name": "Rock_Sandstone_White_Brick_Smooth"
    },
    {
      "x": 8,
      "y": 3,
      "z": -4,
      "name": "Rock_Sandstone_White_Brick_Smooth"
    },
    {
      "x": 8,
      "y": 5,
      "z": -4,
      "name": "Rock_Sandstone_White_Brick_Smooth"
    },
    {
      "x": 8,
      "y": -1,
      "z": -3,
      "name": "Rock_Sandstone"
    },
    {
      "x": 8,
      "y": 0,
      "z": -3,
      "name": "Rock_Sandstone_White_Brick_Smooth"
    },
    {
      "x": 8,
      "y": 1,
      "z": -3,
      "name": "Rock_Sandstone_White_Brick_Smooth"
    },
    {
      "x": 8,
      "y": 2,
      "z": -3,
      "name": "Rock_Sandstone_White_Brick_Smooth"
    },
    {
      "x": 8,
      "y": 3,
      "z": -3,
      "name": "Wood_Stripped_Deco"
    },
    {
      "x": 8,
      "y": 5,
      "z": -3,
      "name": "Wood_Stripped_Deco"
    },
    {
      "x": 8,
      "y": 6,
      "z": -3,
      "name": "Rock_Sandstone_White_Brick_Smooth_Half"
    },
    {
      "x": 8,
      "y": -1,
      "z": -2,
      "name": "Rock_Sandstone"
    },
    {
      "x": 8,
      "y": 0,
      "z": -2,
      "name": "Wood_Stripped_Deco"
    },
    {
      "x": 8,
      "y": 1,
      "z": -2,
      "name": "Empty"
    },
    {
      "x": 8,
      "y": 2,
      "z": -2,
      "name": "Empty"
    },
    {
      "x": 8,
      "y": 3,
      "z": -2,
      "name": "Empty"
    },
    {
      "x": 8,
      "y": 4,
      "z": -2,
      "name": "Rock_Sandstone_White_Stairs",
      "rotation": 10
    },
    {
      "x": 8,
      "y": 5,
      "z": -2,
      "name": "Rock_Sandstone_White_Brick_Smooth"
    },
    {
      "x": 8,
      "y": 6,
      "z": -2,
      "name": "Rock_Sandstone_White_Brick_Smooth"
    },
    {
      "x": 8,
      "y": 7,
      "z": -2,
      "name": "Wood_Stripped_Deco"
    },
    {
      "x": 8,
      "y": -1,
      "z": -1,
      "name": "Rock_Sandstone"
    },
    {
      "x": 8,
      "y": 0,
      "z": -1,
      "name": "Rock_Sandstone_White_Brick_Smooth"
    },
    {
      "x": 8,
      "y": 1,
      "z": -1,
      "name": "Empty"
    },
    {
      "x": 8,
      "y": 2,
      "z": -1,
      "name": "Empty"
    },
    {
      "x": 8,
      "y": 3,
      "z": -1,
      "name": "Empty"
    },
    {
      "x": 8,
      "y": 6,
      "z": -1,
      "name": "Rock_Sandstone_White_Brick_Smooth"
    },
    {
      "x": 8,
      "y": 7,
      "z": -1,
      "name": "Wood_Stripped_Deco"
    },
    {
      "x": 8,
      "y": -1,
      "z": 0,
      "name": "Rock_Sandstone"
    },
    {
      "x": 8,
      "y": 0,
      "z": 0,
      "name": "Wood_Stripped_Deco"
    },
    {
      "x": 8,
      "y": 1,
      "z": 0,
      "name": "Empty"
    },
    {
      "x": 8,
      "y": 2,
      "z": 0,
      "name": "Empty"
    },
    {
      "x": 8,
      "y": 3,
      "z": 0,
      "name": "Empty"
    },
    {
      "x": 8,
      "y": 6,
      "z": 0,
      "name": "Wood_Stripped_Deco"
    },
    {
      "x": 8,
      "y": 7,
      "z": 0,
      "name": "Rock_Sandstone_White_Brick_Smooth"
    },
    {
      "x": 8,
      "y": -1,
      "z": 1,
      "name": "Rock_Sandstone"
    },
    {
      "x": 8,
      "y": 0,
      "z": 1,
      "name": "Rock_Sandstone_White_Brick_Smooth"
    },
    {
      "x": 8,
      "y": 1,
      "z": 1,
      "name": "Empty"
    },
    {
      "x": 8,
      "y": 2,
      "z": 1,
      "name": "Empty"
    },
    {
      "x": 8,
      "y": 3,
      "z": 1,
      "name": "Empty"
    },
    {
      "x": 8,
      "y": 4,
      "z": 1,
      "name": "Rock_Sandstone_White_Stairs",
      "rotation": 8
    },
    {
      "x": 8,
      "y": 5,
      "z": 1,
      "name": "Rock_Sandstone_White_Brick_Smooth"
    },
    {
      "x": 8,
      "y": 6,
      "z": 1,
      "name": "Rock_Sandstone_White_Brick_Smooth"
    },
    {
      "x": 8,
      "y": 7,
      "z": 1,
      "name": "Wood_Stripped_Deco"
    },
    {
      "x": 8,
      "y": -1,
      "z": 2,
      "name": "Rock_Sandstone"
    },
    {
      "x": 8,
      "y": 0,
      "z": 2,
      "name": "Rock_Sandstone_White_Brick_Smooth"
    },
    {
      "x": 8,
      "y": 1,
      "z": 2,
      "name": "Rock_Sandstone_White_Brick_Smooth"
    },
    {
      "x": 8,
      "y": 2,
      "z": 2,
      "name": "Rock_Sandstone_White_Brick_Smooth"
    },
    {
      "x": 8,
      "y": 3,
      "z": 2,
      "name": "Rock_Sandstone_White_Brick_Smooth"
    },
    {
      "x": 8,
      "y": 4,
      "z": 2,
      "name": "Rock_Sandstone_White_Brick_Smooth"
    },
    {
      "x": 8,
      "y": 5,
      "z": 2,
      "name": "Wood_Stripped_Deco"
    },
    {
      "x": 8,
      "y": 6,
      "z": 2,
      "name": "Rock_Sandstone_White_Brick_Smooth_Half"
    },
    {
      "x": 8,
      "y": -1,
      "z": 3,
      "name": "Rock_Sandstone"
    },
    {
      "x": 8,
      "y": 0,
      "z": 3,
      "name": "Rock_Sandstone_White_Brick_Smooth"
    },
    {
      "x": 8,
      "y": 1,
      "z": 3,
      "name": "Rock_Sandstone_White_Brick_Smooth"
    },
    {
      "x": 8,
      "y": 2,
      "z": 3,
      "name": "Rock_Sandstone_White_Brick_Smooth"
    },
    {
      "x": 8,
      "y": 3,
      "z": 3,
      "name": "Rock_Sandstone_White_Brick_Smooth"
    },
    {
      "x": 8,
      "y": 4,
      "z": 3,
      "name": "Rock_Sandstone_White_Brick_Smooth"
    },
    {
      "x": 8,
      "y": 5,
      "z": 3,
      "name": "Wood_Stripped_Deco"
    },
    {
      "x": 8,
      "y": -1,
      "z": 4,
      "name": "Rock_Sandstone"
    },
    {
      "x": 8,
      "y": 0,
      "z": 4,
      "name": "Rock_Sandstone_White_Brick_Smooth"
    },
    {
      "x": 8,
      "y": 3,
      "z": 4,
      "name": "Rock_Sandstone_White_Brick_Smooth"
    },
    {
      "x": 8,
      "y": 4,
      "z": 4,
      "name": "Rock_Sandstone_White_Brick_Smooth"
    },
    {
      "x": 8,
      "y": 5,
      "z": 4,
      "name": "Rock_Sandstone_White_Brick_Smooth"
    },
    {
      "x": 8,
      "y": -1,
      "z": 5,
      "name": "Rock_Sandstone"
    },
    {
      "x": 8,
      "y": 0,
      "z": 5,
      "name": "Rock_Sandstone_White_Brick_Smooth"
    },
    {
      "x": 8,
      "y": 1,
      "z": 5,
      "name": "Wood_Stripped_Deco"
    },
    {
      "x": 8,
      "y": 2,
      "z": 5,
      "name": "Wood_Stripped_Deco"
    },
    {
      "x": 8,
      "y": 3,
      "z": 5,
      "name": "Rock_Sandstone_White_Brick_Smooth"
    },
    {
      "x": 8,
      "y": 4,
      "z": 5,
      "name": "Rock_Sandstone_White_Brick_Smooth"
    },
    {
      "x": 8,
      "y": 5,
      "z": 5,
      "name": "Rock_Sandstone_White_Brick_Smooth_Half"
    },
    {
      "x": 8,
      "y": -1,
      "z": 6,
      "name": "Rock_Sandstone"
    },
    {
      "x": 8,
      "y": 0,
      "z": 6,
      "name": "Soil_Sand_White"
    },
    {
      "x": 8,
      "y": 1,
      "z": 6,
      "name": "Wood_Stripped_Deco"
    },
    {
      "x": 8,
      "y": 2,
      "z": 6,
      "name": "Rock_Sandstone_White_Brick_Smooth"
    },
    {
      "x": 8,
      "y": -1,
      "z": 7,
      "name": "Rock_Sandstone"
    },
    {
      "x": 8,
      "y": 0,
      "z": 7,
      "name": "Soil_Sand_White"
    },
    {
      "x": 8,
      "y": -1,
      "z": 8,
      "name": "Rock_Sandstone"
    },
    {
      "x": 8,
      "y": 0,
      "z": 8,
      "name": "Soil_Sand_White"
    },
    {
      "x": 8,
      "y": -1,
      "z": 9,
      "name": "Rock_Sandstone"
    },
    {
      "x": 8,
      "y": 0,
      "z": 9,
      "name": "Soil_Sand_White"
    },
    {
      "x": 8,
      "y": -1,
      "z": 10,
      "name": "Rock_Sandstone"
    },
    {
      "x": 8,
      "y": 0,
      "z": 10,
      "name": "Soil_Sand_White"
    },
    {
      "x": 8,
      "y": -1,
      "z": 11,
      "name": "Rock_Sandstone"
    },
    {
      "x": 8,
      "y": 0,
      "z": 11,
      "name": "Soil_Sand_White"
    },
    {
      "x": 8,
      "y": -1,
      "z": 12,
      "name": "Rock_Sandstone"
    },
    {
      "x": 8,
      "y": 0,
      "z": 12,
      "name": "Soil_Sand_White"
    },
    {
      "x": 8,
      "y": -1,
      "z": 13,
      "name": "Rock_Sandstone"
    },
    {
      "x": 8,
      "y": 0,
      "z": 13,
      "name": "Soil_Sand_White"
    },
    {
      "x": 8,
      "y": -1,
      "z": 14,
      "name": "Rock_Sandstone"
    },
    {
      "x": 8,
      "y": 0,
      "z": 14,
      "name": "Soil_Sand_White"
    },
    {
      "x": 8,
      "y": -1,
      "z": 15,
      "name": "Rock_Sandstone"
    },
    {
      "x": 8,
      "y": 0,
      "z": 15,
      "name": "Soil_Sand_White"
    },
    {
      "x": 9,
      "y": -1,
      "z": -17,
      "name": "Rock_Sandstone"
    },
    {
      "x": 9,
      "y": 0,
      "z": -17,
      "name": "Soil_Sand_White"
    },
    {
      "x": 9,
      "y": -1,
      "z": -16,
      "name": "Rock_Sandstone"
    },
    {
      "x": 9,
      "y": 0,
      "z": -16,
      "name": "Soil_Sand_White"
    },
    {
      "x": 9,
      "y": -1,
      "z": -15,
      "name": "Rock_Sandstone"
    },
    {
      "x": 9,
      "y": 0,
      "z": -15,
      "name": "Soil_Sand_White"
    },
    {
      "x": 9,
      "y": -1,
      "z": -14,
      "name": "Rock_Sandstone"
    },
    {
      "x": 9,
      "y": 0,
      "z": -14,
      "name": "Soil_Sand_White"
    },
    {
      "x": 9,
      "y": 1,
      "z": -14,
      "name": "Rubble_Sandstone_White_Medium",
      "support": 15
    },
    {
      "x": 9,
      "y": -1,
      "z": -13,
      "name": "Rock_Sandstone"
    },
    {
      "x": 9,
      "y": 0,
      "z": -13,
      "name": "Soil_Sand_White"
    },
    {
      "x": 9,
      "y": 1,
      "z": -13,
      "name": "Rubble_Sandstone_White",
      "support": 15
    },
    {
      "x": 9,
      "y": -1,
      "z": -12,
      "name": "Rock_Sandstone"
    },
    {
      "x": 9,
      "y": 0,
      "z": -12,
      "name": "Soil_Sand_White"
    },
    {
      "x": 9,
      "y": -1,
      "z": -11,
      "name": "Rock_Sandstone"
    },
    {
      "x": 9,
      "y": 0,
      "z": -11,
      "name": "Soil_Sand_White"
    },
    {
      "x": 9,
      "y": -1,
      "z": -10,
      "name": "Rock_Sandstone"
    },
    {
      "x": 9,
      "y": 0,
      "z": -10,
      "name": "Soil_Sand_White"
    },
    {
      "x": 9,
      "y": -1,
      "z": -9,
      "name": "Rock_Sandstone"
    },
    {
      "x": 9,
      "y": 0,
      "z": -9,
      "name": "Soil_Sand_White"
    },
    {
      "x": 9,
      "y": -1,
      "z": -8,
      "name": "Rock_Sandstone"
    },
    {
      "x": 9,
      "y": 0,
      "z": -8,
      "name": "Soil_Sand_White"
    },
    {
      "x": 9,
      "y": 1,
      "z": -8,
      "name": "Soil_Sand_White"
    },
    {
      "x": 9,
      "y": 2,
      "z": -8,
      "name": "Furniture_Tavern_Barrel"
    },
    {
      "x": 9,
      "y": -1,
      "z": -7,
      "name": "Rock_Sandstone"
    },
    {
      "x": 9,
      "y": 0,
      "z": -7,
      "name": "Rock_Sandstone_White_Brick_Smooth"
    },
    {
      "x": 9,
      "y": 1,
      "z": -7,
      "name": "Rock_Sandstone_White_Brick_Smooth"
    },
    {
      "x": 9,
      "y": 2,
      "z": -7,
      "name": "Rock_Sandstone_White_Brick_Smooth"
    },
    {
      "x": 9,
      "y": 3,
      "z": -7,
      "name": "Furniture_Tavern_Barrel"
    },
    {
      "x": 9,
      "y": -1,
      "z": -6,
      "name": "Rock_Sandstone"
    },
    {
      "x": 9,
      "y": 0,
      "z": -6,
      "name": "Rock_Sandstone_White_Brick_Smooth"
    },
    {
      "x": 9,
      "y": 2,
      "z": -6,
      "name": "Rock_Sandstone_White_Brick_Smooth"
    },
    {
      "x": 9,
      "y": 3,
      "z": -6,
      "name": "Furniture_Tavern_Barrel"
    },
    {
      "x": 9,
      "y": -1,
      "z": -5,
      "name": "Rock_Sandstone"
    },
    {
      "x": 9,
      "y": 0,
      "z": -5,
      "name": "Wood_Stripped_Deco"
    },
    {
      "x": 9,
      "y": 3,
      "z": -5,
      "name": "Rock_Sandstone_White_Brick_Smooth"
    },
    {
      "x": 9,
      "y": 4,
      "z": -5,
      "name": "Rock_Sandstone_White_Brick_Smooth"
    },
    {
      "x": 9,
      "y": 5,
      "z": -5,
      "name": "Rock_Sandstone_White_Brick_Smooth"
    },
    {
      "x": 9,
      "y": -1,
      "z": -4,
      "name": "Rock_Sandstone"
    },
    {
      "x": 9,
      "y": 0,
      "z": -4,
      "name": "Wood_Stripped_Deco"
    },
    {
      "x": 9,
      "y": 1,
      "z": -4,
      "name": "Rock_Sandstone_White_Brick_Smooth"
    },
    {
      "x": 9,
      "y": 2,
      "z": -4,
      "name": "Rock_Sandstone_White_Brick_Smooth"
    },
    {
      "x": 9,
      "y": 3,
      "z": -4,
      "name": "Rock_Sandstone_White_Brick_Smooth"
    },
    {
      "x": 9,
      "y": 5,
      "z": -4,
      "name": "Rock_Sandstone_White_Brick_Smooth"
    },
    {
      "x": 9,
      "y": -1,
      "z": -3,
      "name": "Rock_Sandstone"
    },
    {
      "x": 9,
      "y": 0,
      "z": -3,
      "name": "Wood_Stripped_Deco"
    },
    {
      "x": 9,
      "y": 1,
      "z": -3,
      "name": "Rock_Sandstone_White_Brick_Smooth"
    },
    {
      "x": 9,
      "y": 2,
      "z": -3,
      "name": "Rock_Sandstone_White_Brick_Smooth"
    },
    {
      "x": 9,
      "y": 3,
      "z": -3,
      "name": "Wood_Stripped_Deco"
    },
    {
      "x": 9,
      "y": 5,
      "z": -3,
      "name": "Rock_Sandstone_White_Brick_Smooth"
    },
    {
      "x": 9,
      "y": 6,
      "z": -3,
      "name": "Rock_Sandstone_White_Brick_Smooth_Half"
    },
    {
      "x": 9,
      "y": -1,
      "z": -2,
      "name": "Rock_Sandstone"
    },
    {
      "x": 9,
      "y": 0,
      "z": -2,
      "name": "Rock_Sandstone_White_Brick_Smooth"
    },
    {
      "x": 9,
      "y": 1,
      "z": -2,
      "name": "Empty"
    },
    {
      "x": 9,
      "y": 2,
      "z": -2,
      "name": "Empty"
    },
    {
      "x": 9,
      "y": 3,
      "z": -2,
      "name": "Empty"
    },
    {
      "x": 9,
      "y": 4,
      "z": -2,
      "name": "Rock_Sandstone_White_Stairs",
      "rotation": 10
    },
    {
      "x": 9,
      "y": 5,
      "z": -2,
      "name": "Rock_Sandstone_White_Brick_Smooth"
    },
    {
      "x": 9,
      "y": 6,
      "z": -2,
      "name": "Wood_Stripped_Deco"
    },
    {
      "x": 9,
      "y": 7,
      "z": -2,
      "name": "Rock_Sandstone_White_Brick_Smooth"
    },
    {
      "x": 9,
      "y": -1,
      "z": -1,
      "name": "Rock_Sandstone"
    },
    {
      "x": 9,
      "y": 0,
      "z": -1,
      "name": "Wood_Stripped_Deco"
    },
    {
      "x": 9,
      "y": 1,
      "z": -1,
      "name": "Empty"
    },
    {
      "x": 9,
      "y": 2,
      "z": -1,
      "name": "Empty"
    },
    {
      "x": 9,
      "y": 3,
      "z": -1,
      "name": "Empty"
    },
    {
      "x": 9,
      "y": 6,
      "z": -1,
      "name": "Wood_Stripped_Deco"
    },
    {
      "x": 9,
      "y": 7,
      "z": -1,
      "name": "Wood_Stripped_Deco"
    },
    {
      "x": 9,
      "y": -1,
      "z": 0,
      "name": "Rock_Sandstone"
    },
    {
      "x": 9,
      "y": 0,
      "z": 0,
      "name": "Rock_Sandstone_White_Brick_Smooth"
    },
    {
      "x": 9,
      "y": 1,
      "z": 0,
      "name": "Empty"
    },
    {
      "x": 9,
      "y": 2,
      "z": 0,
      "name": "Empty"
    },
    {
      "x": 9,
      "y": 3,
      "z": 0,
      "name": "Empty"
    },
    {
      "x": 9,
      "y": 6,
      "z": 0,
      "name": "Wood_Stripped_Deco"
    },
    {
      "x": 9,
      "y": 7,
      "z": 0,
      "name": "Rock_Sandstone_White_Brick_Smooth"
    },
    {
      "x": 9,
      "y": -1,
      "z": 1,
      "name": "Rock_Sandstone"
    },
    {
      "x": 9,
      "y": 0,
      "z": 1,
      "name": "Rock_Sandstone_White_Brick_Smooth"
    },
    {
      "x": 9,
      "y": 1,
      "z": 1,
      "name": "Empty"
    },
    {
      "x": 9,
      "y": 2,
      "z": 1,
      "name": "Empty"
    },
    {
      "x": 9,
      "y": 3,
      "z": 1,
      "name": "Empty"
    },
    {
      "x": 9,
      "y": 4,
      "z": 1,
      "name": "Rock_Sandstone_White_Stairs",
      "rotation": 8
    },
    {
      "x": 9,
      "y": 5,
      "z": 1,
      "name": "Wood_Stripped_Deco"
    },
    {
      "x": 9,
      "y": 6,
      "z": 1,
      "name": "Rock_Sandstone_White_Brick_Smooth"
    },
    {
      "x": 9,
      "y": 7,
      "z": 1,
      "name": "Rock_Sandstone_White_Brick_Smooth"
    },
    {
      "x": 9,
      "y": -1,
      "z": 2,
      "name": "Rock_Sandstone"
    },
    {
      "x": 9,
      "y": 0,
      "z": 2,
      "name": "Wood_Stripped_Deco"
    },
    {
      "x": 9,
      "y": 1,
      "z": 2,
      "name": "Rock_Sandstone_White_Brick_Smooth"
    },
    {
      "x": 9,
      "y": 2,
      "z": 2,
      "name": "Rock_Sandstone_White_Brick_Smooth"
    },
    {
      "x": 9,
      "y": 3,
      "z": 2,
      "name": "Rock_Sandstone_White_Brick_Smooth"
    },
    {
      "x": 9,
      "y": 4,
      "z": 2,
      "name": "Rock_Sandstone_White_Brick_Smooth"
    },
    {
      "x": 9,
      "y": 5,
      "z": 2,
      "name": "Wood_Stripped_Deco"
    },
    {
      "x": 9,
      "y": 6,
      "z": 2,
      "name": "Rock_Sandstone_White_Brick_Smooth_Half"
    },
    {
      "x": 9,
      "y": -1,
      "z": 3,
      "name": "Rock_Sandstone"
    },
    {
      "x": 9,
      "y": 0,
      "z": 3,
      "name": "Rock_Sandstone_White_Brick_Smooth"
    },
    {
      "x": 9,
      "y": 1,
      "z": 3,
      "name": "Rock_Sandstone_White_Brick_Smooth"
    },
    {
      "x": 9,
      "y": 2,
      "z": 3,
      "name": "Rock_Sandstone_White_Brick_Smooth"
    },
    {
      "x": 9,
      "y": 3,
      "z": 3,
      "name": "Rock_Sandstone_White_Brick_Smooth"
    },
    {
      "x": 9,
      "y": 4,
      "z": 3,
      "name": "Rock_Sandstone_White_Brick_Smooth"
    },
    {
      "x": 9,
      "y": 5,
      "z": 3,
      "name": "Rock_Sandstone_White_Brick_Smooth"
    },
    {
      "x": 9,
      "y": -1,
      "z": 4,
      "name": "Rock_Sandstone"
    },
    {
      "x": 9,
      "y": 0,
      "z": 4,
      "name": "Rock_Sandstone_White_Brick_Smooth"
    },
    {
      "x": 9,
      "y": 3,
      "z": 4,
      "name": "Rock_Sandstone_White_Brick_Smooth"
    },
    {
      "x": 9,
      "y": 4,
      "z": 4,
      "name": "Rock_Sandstone_White_Brick_Smooth"
    },
    {
      "x": 9,
      "y": 5,
      "z": 4,
      "name": "Rock_Sandstone_White_Brick_Smooth"
    },
    {
      "x": 9,
      "y": -1,
      "z": 5,
      "name": "Rock_Sandstone"
    },
    {
      "x": 9,
      "y": 0,
      "z": 5,
      "name": "Rock_Sandstone_White_Brick_Smooth"
    },
    {
      "x": 9,
      "y": 1,
      "z": 5,
      "name": "Rock_Sandstone_White_Brick_Smooth"
    },
    {
      "x": 9,
      "y": 2,
      "z": 5,
      "name": "Rock_Sandstone_White_Brick_Smooth"
    },
    {
      "x": 9,
      "y": 3,
      "z": 5,
      "name": "Rock_Sandstone_White_Brick_Smooth"
    },
    {
      "x": 9,
      "y": 4,
      "z": 5,
      "name": "Wood_Stripped_Deco"
    },
    {
      "x": 9,
      "y": 5,
      "z": 5,
      "name": "Rock_Sandstone_White_Brick_Smooth_Half"
    },
    {
      "x": 9,
      "y": -1,
      "z": 6,
      "name": "Rock_Sandstone"
    },
    {
      "x": 9,
      "y": 0,
      "z": 6,
      "name": "Soil_Sand_White"
    },
    {
      "x": 9,
      "y": 1,
      "z": 6,
      "name": "Rock_Sandstone_White_Brick_Smooth"
    },
    {
      "x": 9,
      "y": 2,
      "z": 6,
      "name": "Rock_Sandstone_White_Brick_Smooth"
    },
    {
      "x": 9,
      "y": -1,
      "z": 7,
      "name": "Rock_Sandstone"
    },
    {
      "x": 9,
      "y": 0,
      "z": 7,
      "name": "Soil_Sand_White"
    },
    {
      "x": 9,
      "y": -1,
      "z": 8,
      "name": "Rock_Sandstone"
    },
    {
      "x": 9,
      "y": 0,
      "z": 8,
      "name": "Soil_Sand_White"
    },
    {
      "x": 9,
      "y": -1,
      "z": 9,
      "name": "Rock_Sandstone"
    },
    {
      "x": 9,
      "y": 0,
      "z": 9,
      "name": "Soil_Sand_White"
    },
    {
      "x": 9,
      "y": -1,
      "z": 10,
      "name": "Rock_Sandstone"
    },
    {
      "x": 9,
      "y": 0,
      "z": 10,
      "name": "Soil_Sand_White"
    },
    {
      "x": 9,
      "y": -1,
      "z": 11,
      "name": "Rock_Sandstone"
    },
    {
      "x": 9,
      "y": 0,
      "z": 11,
      "name": "Soil_Sand_White"
    },
    {
      "x": 9,
      "y": 1,
      "z": 11,
      "name": "Rubble_Sandstone_White_Medium",
      "support": 15
    },
    {
      "x": 9,
      "y": -1,
      "z": 12,
      "name": "Rock_Sandstone"
    },
    {
      "x": 9,
      "y": 0,
      "z": 12,
      "name": "Soil_Sand_White"
    },
    {
      "x": 9,
      "y": -1,
      "z": 13,
      "name": "Rock_Sandstone"
    },
    {
      "x": 9,
      "y": 0,
      "z": 13,
      "name": "Soil_Sand_White"
    },
    {
      "x": 9,
      "y": -1,
      "z": 14,
      "name": "Rock_Sandstone"
    },
    {
      "x": 9,
      "y": 0,
      "z": 14,
      "name": "Soil_Sand_White"
    },
    {
      "x": 9,
      "y": -1,
      "z": 15,
      "name": "Rock_Sandstone"
    },
    {
      "x": 9,
      "y": 0,
      "z": 15,
      "name": "Soil_Sand_White"
    },
    {
      "x": 9,
      "y": -1,
      "z": 16,
      "name": "Rock_Sandstone"
    },
    {
      "x": 9,
      "y": 0,
      "z": 16,
      "name": "Soil_Sand_White"
    },
    {
      "x": 10,
      "y": -1,
      "z": -17,
      "name": "Rock_Sandstone"
    },
    {
      "x": 10,
      "y": 0,
      "z": -17,
      "name": "Soil_Sand_White"
    },
    {
      "x": 10,
      "y": -1,
      "z": -16,
      "name": "Rock_Sandstone"
    },
    {
      "x": 10,
      "y": 0,
      "z": -16,
      "name": "Soil_Sand_White"
    },
    {
      "x": 10,
      "y": -1,
      "z": -15,
      "name": "Rock_Sandstone"
    },
    {
      "x": 10,
      "y": 0,
      "z": -15,
      "name": "Soil_Sand_White"
    },
    {
      "x": 10,
      "y": -1,
      "z": -14,
      "name": "Rock_Sandstone"
    },
    {
      "x": 10,
      "y": 0,
      "z": -14,
      "name": "Soil_Sand_White"
    },
    {
      "x": 10,
      "y": 1,
      "z": -14,
      "name": "Rubble_Sandstone_White_Medium",
      "support": 15
    },
    {
      "x": 10,
      "y": -1,
      "z": -13,
      "name": "Rock_Sandstone"
    },
    {
      "x": 10,
      "y": 0,
      "z": -13,
      "name": "Soil_Sand_White"
    },
    {
      "x": 10,
      "y": -1,
      "z": -12,
      "name": "Rock_Sandstone"
    },
    {
      "x": 10,
      "y": 0,
      "z": -12,
      "name": "Soil_Sand_White"
    },
    {
      "x": 10,
      "y": -1,
      "z": -11,
      "name": "Rock_Sandstone"
    },
    {
      "x": 10,
      "y": 0,
      "z": -11,
      "name": "Soil_Sand_White"
    },
    {
      "x": 10,
      "y": -1,
      "z": -10,
      "name": "Rock_Sandstone"
    },
    {
      "x": 10,
      "y": 0,
      "z": -10,
      "name": "Soil_Sand_White"
    },
    {
      "x": 10,
      "y": -1,
      "z": -9,
      "name": "Rock_Sandstone"
    },
    {
      "x": 10,
      "y": 0,
      "z": -9,
      "name": "Soil_Sand_White"
    },
    {
      "x": 10,
      "y": -1,
      "z": -8,
      "name": "Rock_Sandstone"
    },
    {
      "x": 10,
      "y": 0,
      "z": -8,
      "name": "Soil_Sand_White"
    },
    {
      "x": 10,
      "y": 1,
      "z": -8,
      "name": "Soil_Sand_White"
    },
    {
      "x": 10,
      "y": -1,
      "z": -7,
      "name": "Rock_Sandstone"
    },
    {
      "x": 10,
      "y": 0,
      "z": -7,
      "name": "Wood_Stripped_Deco"
    },
    {
      "x": 10,
      "y": 1,
      "z": -7,
      "name": "Wood_Stripped_Deco"
    },
    {
      "x": 10,
      "y": 2,
      "z": -7,
      "name": "Wood_Stripped_Deco"
    },
    {
      "x": 10,
      "y": 3,
      "z": -7,
      "name": "Rock_Sandstone_White_Brick_Smooth"
    },
    {
      "x": 10,
      "y": -1,
      "z": -6,
      "name": "Rock_Sandstone"
    },
    {
      "x": 10,
      "y": 0,
      "z": -6,
      "name": "Rock_Sandstone_White_Brick_Smooth"
    },
    {
      "x": 10,
      "y": 3,
      "z": -6,
      "name": "Rock_Sandstone_White_Brick_Smooth"
    },
    {
      "x": 10,
      "y": -1,
      "z": -5,
      "name": "Rock_Sandstone"
    },
    {
      "x": 10,
      "y": 0,
      "z": -5,
      "name": "Rock_Sandstone_White_Brick_Smooth"
    },
    {
      "x": 10,
      "y": 1,
      "z": -5,
      "name": "Rock_Sandstone_White_Brick_Smooth"
    },
    {
      "x": 10,
      "y": 2,
      "z": -5,
      "name": "Rock_Sandstone_White_Brick_Smooth"
    },
    {
      "x": 10,
      "y": 3,
      "z": -5,
      "name": "Rock_Sandstone_White_Brick_Smooth"
    },
    {
      "x": 10,
      "y": 4,
      "z": -5,
      "name": "Wood_Stripped_Deco"
    },
    {
      "x": 10,
      "y": 5,
      "z": -5,
      "name": "Rock_Sandstone_White_Brick_Smooth"
    },
    {
      "x": 10,
      "y": -1,
      "z": -4,
      "name": "Rock_Sandstone"
    },
    {
      "x": 10,
      "y": 0,
      "z": -4,
      "name": "Rock_Sandstone_White_Brick_Smooth"
    },
    {
      "x": 10,
      "y": 1,
      "z": -4,
      "name": "Rock_Sandstone_White_Brick_Smooth"
    },
    {
      "x": 10,
      "y": 2,
      "z": -4,
      "name": "Rock_Sandstone_White_Brick_Smooth"
    },
    {
      "x": 10,
      "y": 3,
      "z": -4,
      "name": "Rock_Sandstone_White_Brick_Smooth"
    },
    {
      "x": 10,
      "y": 5,
      "z": -4,
      "name": "Wood_Stripped_Deco"
    },
    {
      "x": 10,
      "y": -1,
      "z": -3,
      "name": "Rock_Sandstone"
    },
    {
      "x": 10,
      "y": 0,
      "z": -3,
      "name": "Wood_Stripped_Deco"
    },
    {
      "x": 10,
      "y": 1,
      "z": -3,
      "name": "Rock_Sandstone_White_Brick_Smooth"
    },
    {
      "x": 10,
      "y": 2,
      "z": -3,
      "name": "Deco_Lantern"
    },
    {
      "x": 10,
      "y": 3,
      "z": -3,
      "name": "Rock_Sandstone_White_Brick_Smooth"
    },
    {
      "x": 10,
      "y": 5,
      "z": -3,
      "name": "Wood_Stripped_Deco"
    },
    {
      "x": 10,
      "y": 6,
      "z": -3,
      "name": "Rock_Sandstone_White_Brick_Smooth_Half"
    },
    {
      "x": 10,
      "y": -1,
      "z": -2,
