{
  "version": 8,
  "blockIdVersion": 11,
  "anchorX": 0,
  "anchorY": 0,
  "anchorZ": 0,
  "blocks": [
    {
      "x": -20,
      "y": 22,
      "z": -3,
      "name": "OrbisGalactic_Block_Jawa_Crawler_Hull"
    },
    {
      "x": -20,
      "y": 24,
      "z": -3,
      "name": "OrbisGalactic_Block_Jawa_Crawler_Hull"
    },
    {
      "x": -20,
      "y": 22,
      "z": -2,
      "name": "OrbisGalactic_Block_Jawa_Crawler_Hull"
    },
    {
      "x": -20,
      "y": 23,
      "z": -2,
      "name": "Rock_Magma_Cooled_Half",
      "rotation": 7
    },
    {
      "x": -20,
      "y": 24,
      "z": -2,
      "name": "OrbisGalactic_Block_Jawa_Crawler_Hull"
    },
    {
      "x": -20,
      "y": 22,
      "z": -1,
      "name": "OrbisGalactic_Block_Jawa_Crawler_Hull"
    },
    {
      "x": -20,
      "y": 23,
      "z": -1,
      "name": "Rock_Magma_Cooled_Half",
      "rotation": 7
    },
    {
      "x": -20,
      "y": 24,
      "z": -1,
      "name": "OrbisGalactic_Block_Jawa_Crawler_Hull"
    },
    {
      "x": -20,
      "y": 22,
      "z": 0,
      "name": "OrbisGalactic_Block_Jawa_Crawler_Hull"
    },
    {
      "x": -20,
      "y": 23,
      "z": 0,
      "name": "Rock_Magma_Cooled_Half",
      "rotation": 7
    },
    {
      "x": -20,
      "y": 24,
      "z": 0,
      "name": "OrbisGalactic_Block_Jawa_Crawler_Hull"
    },
    {
      "x": -20,
      "y": 22,
      "z": 1,
      "name": "OrbisGalactic_Block_Jawa_Crawler_Hull"
    },
    {
      "x": -20,
      "y": 23,
      "z": 1,
      "name": "Rock_Magma_Cooled_Half",
      "rotation": 7
    },
    {
      "x": -20,
      "y": 24,
      "z": 1,
      "name": "OrbisGalactic_Block_Jawa_Crawler_Hull"
    },
    {
      "x": -20,
      "y": 22,
      "z": 2,
      "name": "OrbisGalactic_Block_Jawa_Crawler_Hull",
      "rotation": 10
    },
    {
      "x": -20,
      "y": 23,
      "z": 2,
      "name": "Rock_Magma_Cooled_Half",
      "rotation": 7
    },
    {
      "x": -20,
      "y": 24,
      "z": 2,
      "name": "OrbisGalactic_Block_Jawa_Crawler_Hull",
      "rotation": 10
    },
    {
      "x": -20,
      "y": 22,
      "z": 3,
      "name": "OrbisGalactic_Block_Jawa_Crawler_Hull",
      "rotation": 10
    },
    {
      "x": -20,
      "y": 23,
      "z": 3,
      "name": "Rock_Magma_Cooled_Half",
      "rotation": 7
    },
    {
      "x": -20,
      "y": 24,
      "z": 3,
      "name": "OrbisGalactic_Block_Jawa_Crawler_Hull",
      "rotation": 10
    },
    {
      "x": -20,
      "y": 22,
      "z": 4,
      "name": "OrbisGalactic_Block_Jawa_Crawler_Hull",
      "rotation": 10
    },
    {
      "x": -20,
      "y": 24,
      "z": 4,
      "name": "OrbisGalactic_Block_Jawa_Crawler_Hull",
      "rotation": 10
    },
    {
      "x": -19,
      "y": 19,
      "z": -4,
      "name": "OrbisGalactic_Block_Jawa_Crawler_Hull"
    },
    {
      "x": -19,
      "y": 20,
      "z": -4,
      "name": "OrbisGalactic_Block_Jawa_Crawler_Hull"
    },
    {
      "x": -19,
      "y": 21,
      "z": -4,
      "name": "OrbisGalactic_Block_Jawa_Crawler_Hull"
    },
    {
      "x": -19,
      "y": 22,
      "z": -4,
      "name": "OrbisGalactic_Block_Jawa_Crawler_Hull"
    },
    {
      "x": -19,
      "y": 23,
      "z": -4,
      "name": "Rock_Magma_Cooled_Half",
      "rotation": 7
    },
    {
      "x": -19,
      "y": 24,
      "z": -4,
      "name": "OrbisGalactic_Block_Jawa_Crawler_Hull"
    },
    {
      "x": -19,
      "y": 19,
      "z": -3,
      "name": "OrbisGalactic_Block_Jawa_Crawler_Hull"
    },
    {
      "x": -19,
      "y": 20,
      "z": -3,
      "name": "OrbisGalactic_Block_Jawa_Crawler_Hull"
    },
    {
      "x": -19,
      "y": 21,
      "z": -3,
      "name": "OrbisGalactic_Block_Jawa_Crawler_Hull"
    },
    {
      "x": -19,
      "y": 22,
      "z": -3,
      "name": "OrbisGalactic_Block_Jawa_Crawler_Hull"
    },
    {
      "x": -19,
      "y": 23,
      "z": -3,
      "name": "Rock_Magma_Cooled"
    },
    {
      "x": -19,
      "y": 24,
      "z": -3,
      "name": "OrbisGalactic_Block_Jawa_Crawler_Hull"
    },
    {
      "x": -19,
      "y": 19,
      "z": -2,
      "name": "OrbisGalactic_Block_Jawa_Crawler_Hull"
    },
    {
      "x": -19,
      "y": 20,
      "z": -2,
      "name": "OrbisGalactic_Block_Jawa_Crawler_Hull"
    },
    {
      "x": -19,
      "y": 21,
      "z": -2,
      "name": "OrbisGalactic_Block_Jawa_Crawler_Hull"
    },
    {
      "x": -19,
      "y": 23,
      "z": -2,
      "name": "Rock_Magma_Cooled"
    },
    {
      "x": -19,
      "y": 24,
      "z": -2,
      "name": "OrbisGalactic_Block_Jawa_Crawler_Hull"
    },
    {
      "x": -19,
      "y": 19,
      "z": -1,
      "name": "OrbisGalactic_Block_Jawa_Crawler_Hull"
    },
    {
      "x": -19,
      "y": 20,
      "z": -1,
      "name": "OrbisGalactic_Block_Jawa_Crawler_Hull"
    },
    {
      "x": -19,
      "y": 21,
      "z": -1,
      "name": "OrbisGalactic_Block_Jawa_Crawler_Hull"
    },
    {
      "x": -19,
      "y": 23,
      "z": -1,
      "name": "Rock_Magma_Cooled"
    },
    {
      "x": -19,
      "y": 24,
      "z": -1,
      "name": "OrbisGalactic_Block_Jawa_Crawler_Hull"
    },
    {
      "x": -19,
      "y": 19,
      "z": 0,
      "name": "OrbisGalactic_Block_Jawa_Crawler_Hull"
    },
    {
      "x": -19,
      "y": 20,
      "z": 0,
      "name": "OrbisGalactic_Block_Jawa_Crawler_Hull"
    },
    {
      "x": -19,
      "y": 21,
      "z": 0,
      "name": "OrbisGalactic_Block_Jawa_Crawler_Hull"
    },
    {
      "x": -19,
      "y": 23,
      "z": 0,
      "name": "Rock_Magma_Cooled"
    },
    {
      "x": -19,
      "y": 24,
      "z": 0,
      "name": "OrbisGalactic_Block_Jawa_Crawler_Hull"
    },
    {
      "x": -19,
      "y": 19,
      "z": 1,
      "name": "OrbisGalactic_Block_Jawa_Crawler_Hull"
    },
    {
      "x": -19,
      "y": 20,
      "z": 1,
      "name": "OrbisGalactic_Block_Jawa_Crawler_Hull"
    },
    {
      "x": -19,
      "y": 21,
      "z": 1,
      "name": "OrbisGalactic_Block_Jawa_Crawler_Hull"
    },
    {
      "x": -19,
      "y": 23,
      "z": 1,
      "name": "Rock_Magma_Cooled"
    },
    {
      "x": -19,
      "y": 24,
      "z": 1,
      "name": "OrbisGalactic_Block_Jawa_Crawler_Hull"
    },
    {
      "x": -19,
      "y": 19,
      "z": 2,
      "name": "OrbisGalactic_Block_Jawa_Crawler_Hull",
      "rotation": 10
    },
    {
      "x": -19,
      "y": 20,
      "z": 2,
      "name": "OrbisGalactic_Block_Jawa_Crawler_Hull",
      "rotation": 10
    },
    {
      "x": -19,
      "y": 21,
      "z": 2,
      "name": "OrbisGalactic_Block_Jawa_Crawler_Hull",
      "rotation": 10
    },
    {
      "x": -19,
      "y": 23,
      "z": 2,
      "name": "Rock_Magma_Cooled"
    },
    {
      "x": -19,
      "y": 24,
      "z": 2,
      "name": "OrbisGalactic_Block_Jawa_Crawler_Hull",
      "rotation": 10
    },
    {
      "x": -19,
      "y": 19,
      "z": 3,
      "name": "OrbisGalactic_Block_Jawa_Crawler_Hull",
      "rotation": 10
    },
    {
      "x": -19,
      "y": 20,
      "z": 3,
      "name": "OrbisGalactic_Block_Jawa_Crawler_Hull",
      "rotation": 10
    },
    {
      "x": -19,
      "y": 21,
      "z": 3,
      "name": "OrbisGalactic_Block_Jawa_Crawler_Hull",
      "rotation": 10
    },
    {
      "x": -19,
      "y": 23,
      "z": 3,
      "name": "Rock_Magma_Cooled"
    },
    {
      "x": -19,
      "y": 24,
      "z": 3,
      "name": "OrbisGalactic_Block_Jawa_Crawler_Hull",
      "rotation": 10
    },
    {
      "x": -19,
      "y": 19,
      "z": 4,
      "name": "OrbisGalactic_Block_Jawa_Crawler_Hull",
      "rotation": 10
    },
    {
      "x": -19,
      "y": 20,
      "z": 4,
      "name": "OrbisGalactic_Block_Jawa_Crawler_Hull",
      "rotation": 10
    },
    {
      "x": -19,
      "y": 21,
      "z": 4,
      "name": "OrbisGalactic_Block_Jawa_Crawler_Hull",
      "rotation": 10
    },
    {
      "x": -19,
      "y": 22,
      "z": 4,
      "name": "OrbisGalactic_Block_Jawa_Crawler_Hull",
      "rotation": 10
    },
    {
      "x": -19,
      "y": 23,
      "z": 4,
      "name": "Rock_Magma_Cooled"
    },
    {
      "x": -19,
      "y": 24,
      "z": 4,
      "name": "OrbisGalactic_Block_Jawa_Crawler_Hull",
      "rotation": 10
    },
    {
      "x": -19,
      "y": 19,
      "z": 5,
      "name": "OrbisGalactic_Block_Jawa_Crawler_Hull",
      "rotation": 10
    },
    {
      "x": -19,
      "y": 20,
      "z": 5,
      "name": "OrbisGalactic_Block_Jawa_Crawler_Hull",
      "rotation": 10
    },
    {
      "x": -19,
      "y": 21,
      "z": 5,
      "name": "OrbisGalactic_Block_Jawa_Crawler_Hull",
      "rotation": 10
    },
    {
      "x": -19,
      "y": 22,
      "z": 5,
      "name": "OrbisGalactic_Block_Jawa_Crawler_Hull",
      "rotation": 10
    },
    {
      "x": -19,
      "y": 23,
      "z": 5,
      "name": "Rock_Magma_Cooled_Half",
      "rotation": 7
    },
    {
      "x": -19,
      "y": 24,
      "z": 5,
      "name": "OrbisGalactic_Block_Jawa_Crawler_Hull",
      "rotation": 10
    },
    {
      "x": -18,
      "y": 18,
      "z": -5,
      "name": "OrbisGalactic_Block_Jawa_Crawler_Hull"
    },
    {
      "x": -18,
      "y": 19,
      "z": -5,
      "name": "OrbisGalactic_Block_Jawa_Crawler_Hull"
    },
    {
      "x": -18,
      "y": 20,
      "z": -5,
      "name": "OrbisGalactic_Block_Jawa_Crawler_Hull"
    },
    {
      "x": -18,
      "y": 21,
      "z": -5,
      "name": "OrbisGalactic_Block_Jawa_Crawler_Hull"
    },
    {
      "x": -18,
      "y": 22,
      "z": -5,
      "name": "OrbisGalactic_Block_Jawa_Crawler_Hull"
    },
    {
      "x": -18,
      "y": 23,
      "z": -5,
      "name": "Rock_Magma_Cooled_Half",
      "rotation": 6
    },
    {
      "x": -18,
      "y": 24,
      "z": -5,
      "name": "OrbisGalactic_Block_Jawa_Crawler_Hull"
    },
    {
      "x": -18,
      "y": 18,
      "z": -4,
      "name": "OrbisGalactic_Block_Jawa_Crawler_Hull"
    },
    {
      "x": -18,
      "y": 21,
      "z": -4,
      "name": "OrbisGalactic_Block_Jawa_Crawler_Hull"
    },
    {
      "x": -18,
      "y": 22,
      "z": -4,
      "name": "OrbisGalactic_Block_Jawa_Crawler_Hull"
    },
    {
      "x": -18,
      "y": 23,
      "z": -4,
      "name": "Rock_Magma_Cooled"
    },
    {
      "x": -18,
      "y": 24,
      "z": -4,
      "name": "OrbisGalactic_Block_Jawa_Crawler_Hull"
    },
    {
      "x": -18,
      "y": 18,
      "z": -3,
      "name": "OrbisGalactic_Block_Jawa_Crawler_Hull"
    },
    {
      "x": -18,
      "y": 21,
      "z": -3,
      "name": "OrbisGalactic_Block_Jawa_Crawler_Hull"
    },
    {
      "x": -18,
      "y": 24,
      "z": -3,
      "name": "OrbisGalactic_Block_Jawa_Crawler_Hull"
    },
    {
      "x": -18,
      "y": 18,
      "z": -2,
      "name": "OrbisGalactic_Block_Jawa_Crawler_Hull"
    },
    {
      "x": -18,
      "y": 21,
      "z": -2,
      "name": "OrbisGalactic_Block_Jawa_Crawler_Hull"
    },
    {
      "x": -18,
      "y": 24,
      "z": -2,
      "name": "OrbisGalactic_Block_Jawa_Crawler_Hull"
    },
    {
      "x": -18,
      "y": 18,
      "z": -1,
      "name": "OrbisGalactic_Block_Jawa_Crawler_Hull"
    },
    {
      "x": -18,
      "y": 21,
      "z": -1,
      "name": "OrbisGalactic_Block_Jawa_Crawler_Hull"
    },
    {
      "x": -18,
      "y": 24,
      "z": -1,
      "name": "OrbisGalactic_Block_Jawa_Crawler_Hull"
    },
    {
      "x": -18,
      "y": 18,
      "z": 0,
      "name": "OrbisGalactic_Block_Jawa_Crawler_Hull"
    },
    {
      "x": -18,
      "y": 21,
      "z": 0,
      "name": "OrbisGalactic_Block_Jawa_Crawler_Hull"
    },
    {
      "x": -18,
      "y": 24,
      "z": 0,
      "name": "OrbisGalactic_Block_Jawa_Crawler_Hull"
    },
    {
      "x": -18,
      "y": 18,
      "z": 1,
      "name": "OrbisGalactic_Block_Jawa_Crawler_Hull"
    },
    {
      "x": -18,
      "y": 21,
      "z": 1,
      "name": "OrbisGalactic_Block_Jawa_Crawler_Hull"
    },
    {
      "x": -18,
      "y": 24,
      "z": 1,
      "name": "OrbisGalactic_Block_Jawa_Crawler_Hull"
    },
    {
      "x": -18,
      "y": 18,
      "z": 2,
      "name": "OrbisGalactic_Block_Jawa_Crawler_Hull",
      "rotation": 10
    },
    {
      "x": -18,
      "y": 21,
      "z": 2,
      "name": "OrbisGalactic_Block_Jawa_Crawler_Hull"
    },
    {
      "x": -18,
      "y": 24,
      "z": 2,
      "name": "OrbisGalactic_Block_Jawa_Crawler_Hull",
      "rotation": 10
    },
    {
      "x": -18,
      "y": 18,
      "z": 3,
      "name": "OrbisGalactic_Block_Jawa_Crawler_Hull",
      "rotation": 10
    },
    {
      "x": -18,
      "y": 21,
      "z": 3,
      "name": "OrbisGalactic_Block_Jawa_Crawler_Hull"
    },
    {
      "x": -18,
      "y": 24,
      "z": 3,
      "name": "OrbisGalactic_Block_Jawa_Crawler_Hull",
      "rotation": 10
    },
    {
      "x": -18,
      "y": 18,
      "z": 4,
      "name": "OrbisGalactic_Block_Jawa_Crawler_Hull",
      "rotation": 10
    },
    {
      "x": -18,
      "y": 21,
      "z": 4,
      "name": "OrbisGalactic_Block_Jawa_Crawler_Hull"
    },
    {
      "x": -18,
      "y": 23,
      "z": 4,
      "name": "Rock_Magma_Cooled"
    },
    {
      "x": -18,
      "y": 24,
      "z": 4,
      "name": "OrbisGalactic_Block_Jawa_Crawler_Hull",
      "rotation": 10
    },
    {
      "x": -18,
      "y": 18,
      "z": 5,
      "name": "OrbisGalactic_Block_Jawa_Crawler_Hull",
      "rotation": 10
    },
    {
      "x": -18,
      "y": 21,
      "z": 5,
      "name": "OrbisGalactic_Block_Jawa_Crawler_Hull"
    },
    {
      "x": -18,
      "y": 22,
      "z": 5,
      "name": "OrbisGalactic_Block_Jawa_Crawler_Hull"
    },
    {
      "x": -18,
      "y": 23,
      "z": 5,
      "name": "Rock_Magma_Cooled"
    },
    {
      "x": -18,
      "y": 24,
      "z": 5,
      "name": "OrbisGalactic_Block_Jawa_Crawler_Hull",
      "rotation": 10
    },
    {
      "x": -18,
      "y": 18,
      "z": 6,
      "name": "OrbisGalactic_Block_Jawa_Crawler_Hull",
      "rotation": 10
    },
    {
      "x": -18,
      "y": 19,
      "z": 6,
      "name": "OrbisGalactic_Block_Jawa_Crawler_Hull",
      "rotation": 10
    },
    {
      "x": -18,
      "y": 20,
      "z": 6,
      "name": "OrbisGalactic_Block_Jawa_Crawler_Hull",
      "rotation": 10
    },
    {
      "x": -18,
      "y": 21,
      "z": 6,
      "name": "OrbisGalactic_Block_Jawa_Crawler_Hull",
      "rotation": 10
    },
    {
      "x": -18,
      "y": 22,
      "z": 6,
      "name": "OrbisGalactic_Block_Jawa_Crawler_Hull",
      "rotation": 10
    },
    {
      "x": -18,
      "y": 23,
      "z": 6,
      "name": "Rock_Magma_Cooled_Half",
      "rotation": 4
    },
    {
      "x": -18,
      "y": 24,
      "z": 6,
      "name": "OrbisGalactic_Block_Jawa_Crawler_Hull",
      "rotation": 10
    },
    {
      "x": -17,
      "y": 19,
      "z": -6,
      "name": "OrbisGalactic_Block_Jawa_Crawler_Hull"
    },
    {
      "x": -17,
      "y": 20,
      "z": -6,
      "name": "OrbisGalactic_Block_Jawa_Crawler_Hull"
    },
    {
      "x": -17,
      "y": 21,
      "z": -6,
      "name": "OrbisGalactic_Block_Jawa_Crawler_Hull"
    },
    {
      "x": -17,
      "y": 22,
      "z": -6,
      "name": "OrbisGalactic_Block_Jawa_Crawler_Hull"
    },
    {
      "x": -17,
      "y": 24,
      "z": -6,
      "name": "OrbisGalactic_Block_Jawa_Crawler_Hull"
    },
    {
      "x": -17,
      "y": 15,
      "z": -5,
      "name": "OrbisGalactic_Block_Jawa_Crawler_Hull"
    },
    {
      "x": -17,
      "y": 16,
      "z": -5,
      "name": "OrbisGalactic_Block_Jawa_Crawler_Hull"
    },
    {
      "x": -17,
      "y": 17,
      "z": -5,
      "name": "OrbisGalactic_Block_Jawa_Crawler_Hull"
    },
    {
      "x": -17,
      "y": 18,
      "z": -5,
      "name": "OrbisGalactic_Block_Jawa_Crawler_Hull"
    },
    {
      "x": -17,
      "y": 19,
      "z": -5,
      "name": "OrbisGalactic_Block_Jawa_Crawler_Hull"
    },
    {
      "x": -17,
      "y": 20,
      "z": -5,
      "name": "OrbisGalactic_Block_Jawa_Crawler_Hull"
    },
    {
      "x": -17,
      "y": 21,
      "z": -5,
      "name": "OrbisGalactic_Block_Jawa_Crawler_Hull"
    },
    {
      "x": -17,
      "y": 22,
      "z": -5,
      "name": "OrbisGalactic_Block_Jawa_Crawler_Hull"
    },
    {
      "x": -17,
      "y": 23,
      "z": -5,
      "name": "Rock_Magma_Cooled_Half",
      "rotation": 6
    },
    {
      "x": -17,
      "y": 24,
      "z": -5,
      "name": "OrbisGalactic_Block_Jawa_Crawler_Hull"
    },
    {
      "x": -17,
      "y": 15,
      "z": -4,
      "name": "OrbisGalactic_Block_Jawa_Crawler_Hull"
    },
    {
      "x": -17,
      "y": 16,
      "z": -4,
      "name": "OrbisGalactic_Block_Jawa_Crawler_Hull"
    },
    {
      "x": -17,
      "y": 17,
      "z": -4,
      "name": "OrbisGalactic_Block_Jawa_Crawler_Hull"
    },
    {
      "x": -17,
      "y": 21,
      "z": -4,
      "name": "OrbisGalactic_Block_Jawa_Crawler_Hull"
    },
    {
      "x": -17,
      "y": 22,
      "z": -4,
      "name": "OrbisGalactic_Block_Jawa_Crawler_Hull"
    },
    {
      "x": -17,
      "y": 24,
      "z": -4,
      "name": "OrbisGalactic_Block_Jawa_Crawler_Hull"
    },
    {
      "x": -17,
      "y": 15,
      "z": -3,
      "name": "OrbisGalactic_Block_Jawa_Crawler_Hull"
    },
    {
      "x": -17,
      "y": 16,
      "z": -3,
      "name": "OrbisGalactic_Block_Jawa_Crawler_Hull"
    },
    {
      "x": -17,
      "y": 17,
      "z": -3,
      "name": "OrbisGalactic_Block_Jawa_Crawler_Hull"
    },
    {
      "x": -17,
      "y": 21,
      "z": -3,
      "name": "OrbisGalactic_Block_Jawa_Crawler_Hull"
    },
    {
      "x": -17,
      "y": 24,
      "z": -3,
      "name": "OrbisGalactic_Block_Jawa_Crawler_Hull"
    },
    {
      "x": -17,
      "y": 15,
      "z": -2,
      "name": "OrbisGalactic_Block_Jawa_Crawler_Hull"
    },
    {
      "x": -17,
      "y": 16,
      "z": -2,
      "name": "OrbisGalactic_Block_Jawa_Crawler_Hull"
    },
    {
      "x": -17,
      "y": 17,
      "z": -2,
      "name": "OrbisGalactic_Block_Jawa_Crawler_Hull"
    },
    {
      "x": -17,
      "y": 21,
      "z": -2,
      "name": "OrbisGalactic_Block_Jawa_Crawler_Hull"
    },
    {
      "x": -17,
      "y": 24,
      "z": -2,
      "name": "OrbisGalactic_Block_Jawa_Crawler_Hull"
    },
    {
      "x": -17,
      "y": 15,
      "z": -1,
      "name": "OrbisGalactic_Block_Jawa_Crawler_Hull"
    },
    {
      "x": -17,
      "y": 16,
      "z": -1,
      "name": "OrbisGalactic_Block_Jawa_Crawler_Hull"
    },
    {
      "x": -17,
      "y": 17,
      "z": -1,
      "name": "OrbisGalactic_Block_Jawa_Crawler_Hull"
    },
    {
      "x": -17,
      "y": 21,
      "z": -1,
      "name": "OrbisGalactic_Block_Jawa_Crawler_Hull"
    },
    {
      "x": -17,
      "y": 24,
      "z": -1,
      "name": "OrbisGalactic_Block_Jawa_Crawler_Hull"
    },
    {
      "x": -17,
      "y": 15,
      "z": 0,
      "name": "OrbisGalactic_Block_Jawa_Crawler_Hull"
    },
    {
      "x": -17,
      "y": 16,
      "z": 0,
      "name": "OrbisGalactic_Block_Jawa_Crawler_Hull"
    },
    {
      "x": -17,
      "y": 17,
      "z": 0,
      "name": "OrbisGalactic_Block_Jawa_Crawler_Hull"
    },
    {
      "x": -17,
      "y": 21,
      "z": 0,
      "name": "OrbisGalactic_Block_Jawa_Crawler_Hull"
    },
    {
      "x": -17,
      "y": 24,
      "z": 0,
      "name": "OrbisGalactic_Block_Jawa_Crawler_Hull"
    },
    {
      "x": -17,
      "y": 15,
      "z": 1,
      "name": "OrbisGalactic_Block_Jawa_Crawler_Hull"
    },
    {
      "x": -17,
      "y": 16,
      "z": 1,
      "name": "OrbisGalactic_Block_Jawa_Crawler_Hull"
    },
    {
      "x": -17,
      "y": 17,
      "z": 1,
      "name": "OrbisGalactic_Block_Jawa_Crawler_Hull"
    },
    {
      "x": -17,
      "y": 21,
      "z": 1,
      "name": "OrbisGalactic_Block_Jawa_Crawler_Hull"
    },
    {
      "x": -17,
      "y": 24,
      "z": 1,
      "name": "OrbisGalactic_Block_Jawa_Crawler_Hull"
    },
    {
      "x": -17,
      "y": 15,
      "z": 2,
      "name": "OrbisGalactic_Block_Jawa_Crawler_Hull",
      "rotation": 10
    },
    {
      "x": -17,
      "y": 16,
      "z": 2,
      "name": "OrbisGalactic_Block_Jawa_Crawler_Hull",
      "rotation": 10
    },
    {
      "x": -17,
      "y": 17,
      "z": 2,
      "name": "OrbisGalactic_Block_Jawa_Crawler_Hull",
      "rotation": 10
    },
    {
      "x": -17,
      "y": 21,
      "z": 2,
      "name": "OrbisGalactic_Block_Jawa_Crawler_Hull"
    },
    {
      "x": -17,
      "y": 24,
      "z": 2,
      "name": "OrbisGalactic_Block_Jawa_Crawler_Hull",
      "rotation": 10
    },
    {
      "x": -17,
      "y": 15,
      "z": 3,
      "name": "OrbisGalactic_Block_Jawa_Crawler_Hull",
      "rotation": 10
    },
    {
      "x": -17,
      "y": 16,
      "z": 3,
      "name": "OrbisGalactic_Block_Jawa_Crawler_Hull",
      "rotation": 10
    },
    {
      "x": -17,
      "y": 17,
      "z": 3,
      "name": "OrbisGalactic_Block_Jawa_Crawler_Hull",
      "rotation": 10
    },
    {
      "x": -17,
      "y": 21,
      "z": 3,
      "name": "OrbisGalactic_Block_Jawa_Crawler_Hull"
    },
    {
      "x": -17,
      "y": 24,
      "z": 3,
      "name": "OrbisGalactic_Block_Jawa_Crawler_Hull",
      "rotation": 10
    },
    {
      "x": -17,
      "y": 15,
      "z": 4,
      "name": "OrbisGalactic_Block_Jawa_Crawler_Hull",
      "rotation": 10
    },
    {
      "x": -17,
      "y": 16,
      "z": 4,
      "name": "OrbisGalactic_Block_Jawa_Crawler_Hull",
      "rotation": 10
    },
    {
      "x": -17,
      "y": 17,
      "z": 4,
      "name": "OrbisGalactic_Block_Jawa_Crawler_Hull",
      "rotation": 10
    },
    {
      "x": -17,
      "y": 21,
      "z": 4,
      "name": "OrbisGalactic_Block_Jawa_Crawler_Hull"
    },
    {
      "x": -17,
      "y": 23,
      "z": 4,
      "name": "Rock_Magma_Cooled"
    },
    {
      "x": -17,
      "y": 24,
      "z": 4,
      "name": "OrbisGalactic_Block_Jawa_Crawler_Hull",
      "rotation": 10
    },
    {
      "x": -17,
      "y": 15,
      "z": 5,
      "name": "OrbisGalactic_Block_Jawa_Crawler_Hull",
      "rotation": 10
    },
    {
      "x": -17,
      "y": 16,
      "z": 5,
      "name": "OrbisGalactic_Block_Jawa_Crawler_Hull",
      "rotation": 10
    },
    {
      "x": -17,
      "y": 17,
      "z": 5,
      "name": "OrbisGalactic_Block_Jawa_Crawler_Hull",
      "rotation": 10
    },
    {
      "x": -17,
      "y": 21,
      "z": 5,
      "name": "OrbisGalactic_Block_Jawa_Crawler_Hull"
    },
    {
      "x": -17,
      "y": 22,
      "z": 5,
      "name": "OrbisGalactic_Block_Jawa_Crawler_Hull"
    },
    {
      "x": -17,
      "y": 23,
      "z": 5,
      "name": "Rock_Magma_Cooled"
    },
    {
      "x": -17,
      "y": 24,
      "z": 5,
      "name": "OrbisGalactic_Block_Jawa_Crawler_Hull",
      "rotation": 10
    },
    {
      "x": -17,
      "y": 15,
      "z": 6,
      "name": "OrbisGalactic_Block_Jawa_Crawler_Hull",
      "rotation": 10
    },
    {
      "x": -17,
      "y": 16,
      "z": 6,
      "name": "OrbisGalactic_Block_Jawa_Crawler_Hull",
      "rotation": 10
    },
    {
      "x": -17,
      "y": 17,
      "z": 6,
      "name": "OrbisGalactic_Block_Jawa_Crawler_Hull",
      "rotation": 10
    },
    {
      "x": -17,
      "y": 18,
      "z": 6,
      "name": "OrbisGalactic_Block_Jawa_Crawler_Hull",
      "rotation": 10
    },
    {
      "x": -17,
      "y": 19,
      "z": 6,
      "name": "OrbisGalactic_Block_Jawa_Crawler_Hull",
      "rotation": 10
    },
    {
      "x": -17,
      "y": 20,
      "z": 6,
      "name": "OrbisGalactic_Block_Jawa_Crawler_Hull",
      "rotation": 10
    },
    {
      "x": -17,
      "y": 21,
      "z": 6,
      "name": "OrbisGalactic_Block_Jawa_Crawler_Hull",
      "rotation": 10
    },
    {
      "x": -17,
      "y": 22,
      "z": 6,
      "name": "OrbisGalactic_Block_Jawa_Crawler_Hull",
      "rotation": 10
    },
    {
      "x": -17,
      "y": 23,
      "z": 6,
      "name": "Rock_Magma_Cooled_Half",
      "rotation": 4
    },
    {
      "x": -17,
      "y": 24,
      "z": 6,
      "name": "OrbisGalactic_Block_Jawa_Crawler_Hull",
      "rotation": 10
    },
    {
      "x": -17,
      "y": 19,
      "z": 7,
      "name": "OrbisGalactic_Block_Jawa_Crawler_Hull",
      "rotation": 10
    },
    {
      "x": -17,
      "y": 20,
      "z": 7,
      "name": "OrbisGalactic_Block_Jawa_Crawler_Hull",
      "rotation": 10
    },
    {
      "x": -17,
      "y": 21,
      "z": 7,
      "name": "OrbisGalactic_Block_Jawa_Crawler_Hull",
      "rotation": 10
    },
    {
      "x": -17,
      "y": 22,
      "z": 7,
      "name": "OrbisGalactic_Block_Jawa_Crawler_Hull"
    },
    {
      "x": -17,
      "y": 24,
      "z": 7,
      "name": "OrbisGalactic_Block_Jawa_Crawler_Hull"
    },
    {
      "x": -16,
      "y": 15,
      "z": -6,
      "name": "OrbisGalactic_Block_Jawa_Crawler_Hull"
    },
    {
      "x": -16,
      "y": 16,
      "z": -6,
      "name": "OrbisGalactic_Block_Jawa_Crawler_Hull"
    },
    {
      "x": -16,
      "y": 17,
      "z": -6,
      "name": "OrbisGalactic_Block_Jawa_Crawler_Hull"
    },
    {
      "x": -16,
      "y": 18,
      "z": -6,
      "name": "OrbisGalactic_Block_Jawa_Crawler_Hull"
    },
    {
      "x": -16,
      "y": 19,
      "z": -6,
      "name": "OrbisGalactic_Block_Jawa_Crawler_Hull"
    },
    {
      "x": -16,
      "y": 20,
      "z": -6,
      "name": "OrbisGalactic_Block_Jawa_Crawler_Hull"
    },
    {
      "x": -16,
      "y": 21,
      "z": -6,
      "name": "OrbisGalactic_Block_Jawa_Crawler_Hull"
    },
    {
      "x": -16,
      "y": 22,
      "z": -6,
      "name": "OrbisGalactic_Block_Jawa_Crawler_Hull"
    },
    {
      "x": -16,
      "y": 24,
      "z": -6,
      "name": "OrbisGalactic_Block_Jawa_Crawler_Hull"
    },
    {
      "x": -16,
      "y": 12,
      "z": -5,
      "name": "OrbisGalactic_Block_Jawa_Crawler_Hull"
    },
    {
      "x": -16,
      "y": 13,
      "z": -5,
      "name": "OrbisGalactic_Block_Jawa_Crawler_Hull"
    },
    {
      "x": -16,
      "y": 14,
      "z": -5,
      "name": "OrbisGalactic_Block_Jawa_Crawler_Hull"
    },
    {
      "x": -16,
      "y": 15,
      "z": -5,
      "name": "OrbisGalactic_Block_Jawa_Crawler_Hull"
    },
    {
      "x": -16,
      "y": 16,
      "z": -5,
      "name": "OrbisGalactic_Block_Jawa_Crawler_Hull"
    },
    {
      "x": -16,
      "y": 17,
      "z": -5,
      "name": "OrbisGalactic_Block_Jawa_Crawler_Hull"
    },
    {
      "x": -16,
      "y": 18,
      "z": -5,
      "name": "OrbisGalactic_Block_Jawa_Crawler_Hull"
    },
    {
      "x": -16,
      "y": 19,
      "z": -5,
      "name": "OrbisGalactic_Block_Jawa_Crawler_Hull"
    },
    {
      "x": -16,
      "y": 20,
      "z": -5,
      "name": "OrbisGalactic_Block_Jawa_Crawler_Hull"
    },
    {
      "x": -16,
      "y": 21,
      "z": -5,
      "name": "OrbisGalactic_Block_Jawa_Crawler_Hull"
    },
    {
      "x": -16,
      "y": 22,
      "z": -5,
      "name": "OrbisGalactic_Block_Jawa_Crawler_Hull"
    },
    {
      "x": -16,
      "y": 23,
      "z": -5,
      "name": "Rock_Magma_Cooled_Half",
      "rotation": 6
    },
    {
      "x": -16,
      "y": 24,
      "z": -5,
      "name": "OrbisGalactic_Block_Jawa_Crawler_Hull"
    },
    {
      "x": -16,
      "y": 12,
      "z": -4,
      "name": "OrbisGalactic_Block_Jawa_Crawler_Hull"
    },
    {
      "x": -16,
      "y": 13,
      "z": -4,
      "name": "OrbisGalactic_Block_Jawa_Crawler_Hull"
    },
    {
      "x": -16,
      "y": 14,
      "z": -4,
      "name": "OrbisGalactic_Block_Jawa_Crawler_Hull"
    },
    {
      "x": -16,
      "y": 15,
      "z": -4,
      "name": "OrbisGalactic_Block_Jawa_Crawler_Hull"
    },
    {
      "x": -16,
      "y": 16,
      "z": -4,
      "name": "OrbisGalactic_Block_Jawa_Crawler_Hull"
    },
    {
      "x": -16,
      "y": 17,
      "z": -4,
      "name": "OrbisGalactic_Block_Jawa_Crawler_Hull"
    },
    {
      "x": -16,
      "y": 18,
      "z": -4,
      "name": "OrbisGalactic_Block_Jawa_Crawler_Hull"
    },
    {
      "x": -16,
      "y": 19,
      "z": -4,
      "name": "OrbisGalactic_Block_Jawa_Crawler_Hull"
    },
    {
      "x": -16,
      "y": 20,
      "z": -4,
      "name": "OrbisGalactic_Block_Jawa_Crawler_Hull"
    },
    {
      "x": -16,
      "y": 21,
      "z": -4,
      "name": "OrbisGalactic_Block_Jawa_Crawler_Hull"
    },
    {
      "x": -16,
      "y": 22,
      "z": -4,
      "name": "OrbisGalactic_Block_Jawa_Crawler_Hull"
    },
    {
      "x": -16,
      "y": 24,
      "z": -4,
      "name": "OrbisGalactic_Block_Jawa_Crawler_Hull"
    },
    {
      "x": -16,
      "y": 12,
      "z": -3,
      "name": "OrbisGalactic_Block_Jawa_Crawler_Hull"
    },
    {
      "x": -16,
      "y": 13,
      "z": -3,
      "name": "OrbisGalactic_Block_Jawa_Crawler_Hull"
    },
    {
      "x": -16,
      "y": 14,
      "z": -3,
      "name": "OrbisGalactic_Block_Jawa_Crawler_Hull"
    },
    {
      "x": -16,
      "y": 15,
      "z": -3,
      "name": "OrbisGalactic_Block_Jawa_Crawler_Hull"
    },
    {
      "x": -16,
      "y": 16,
      "z": -3,
      "name": "OrbisGalactic_Block_Jawa_Crawler_Hull"
    },
    {
      "x": -16,
      "y": 17,
      "z": -3,
      "name": "OrbisGalactic_Block_Jawa_Crawler_Hull"
    },
    {
      "x": -16,
      "y": 18,
      "z": -3,
      "name": "OrbisGalactic_Block_Jawa_Crawler_Hull"
    },
    {
      "x": -16,
      "y": 19,
      "z": -3,
      "name": "OrbisGalactic_Block_Jawa_Crawler_Hull"
    },
    {
      "x": -16,
      "y": 20,
      "z": -3,
      "name": "OrbisGalactic_Block_Jawa_Crawler_Hull"
    },
    {
      "x": -16,
      "y": 21,
      "z": -3,
      "name": "OrbisGalactic_Block_Jawa_Crawler_Hull"
    },
    {
      "x": -16,
      "y": 24,
      "z": -3,
      "name": "OrbisGalactic_Block_Jawa_Crawler_Hull"
    },
    {
      "x": -16,
      "y": 12,
      "z": -2,
      "name": "OrbisGalactic_Block_Jawa_Crawler_Hull"
    },
    {
      "x": -16,
      "y": 13,
      "z": -2,
      "name": "OrbisGalactic_Block_Jawa_Crawler_Hull"
    },
    {
      "x": -16,
      "y": 14,
      "z": -2,
      "name": "OrbisGalactic_Block_Jawa_Crawler_Hull"
    },
    {
      "x": -16,
      "y": 15,
      "z": -2,
      "name": "OrbisGalactic_Block_Jawa_Crawler_Hull"
    },
    {
      "x": -16,
      "y": 16,
      "z": -2,
      "name": "OrbisGalactic_Block_Jawa_Crawler_Hull"
    },
    {
      "x": -16,
      "y": 17,
      "z": -2,
      "name": "OrbisGalactic_Block_Jawa_Crawler_Hull"
    },
    {
      "x": -16,
      "y": 18,
      "z": -2,
      "name": "OrbisGalactic_Block_Jawa_Crawler_Hull"
    },
    {
      "x": -16,
      "y": 19,
      "z": -2,
      "name": "OrbisGalactic_Block_Jawa_Crawler_Hull"
    },
    {
      "x": -16,
      "y": 20,
      "z": -2,
      "name": "OrbisGalactic_Block_Jawa_Crawler_Hull"
    },
    {
      "x": -16,
      "y": 21,
      "z": -2,
      "name": "OrbisGalactic_Block_Jawa_Crawler_Hull"
    },
    {
      "x": -16,
      "y": 24,
      "z": -2,
      "name": "OrbisGalactic_Block_Jawa_Crawler_Hull"
    },
    {
      "x": -16,
      "y": 12,
      "z": -1,
      "name": "OrbisGalactic_Block_Jawa_Crawler_Hull"
    },
    {
      "x": -16,
      "y": 13,
      "z": -1,
      "name": "OrbisGalactic_Block_Jawa_Crawler_Hull"
    },
    {
      "x": -16,
      "y": 14,
      "z": -1,
      "name": "OrbisGalactic_Block_Jawa_Crawler_Hull"
    },
    {
      "x": -16,
      "y": 15,
      "z": -1,
      "name": "OrbisGalactic_Block_Jawa_Crawler_Hull"
    },
    {
      "x": -16,
      "y": 16,
      "z": -1,
      "name": "OrbisGalactic_Block_Jawa_Crawler_Hull"
    },
    {
      "x": -16,
      "y": 17,
      "z": -1,
      "name": "OrbisGalactic_Block_Jawa_Crawler_Hull"
    },
    {
      "x": -16,
      "y": 18,
      "z": -1,
      "name": "OrbisGalactic_Block_Jawa_Crawler_Hull"
    },
    {
      "x": -16,
      "y": 19,
      "z": -1,
      "name": "OrbisGalactic_Block_Jawa_Crawler_Hull"
    },
    {
      "x": -16,
      "y": 20,
      "z": -1,
      "name": "OrbisGalactic_Block_Jawa_Crawler_Hull"
    },
    {
      "x": -16,
      "y": 21,
      "z": -1,
      "name": "OrbisGalactic_Block_Jawa_Crawler_Hull"
    },
    {
      "x": -16,
      "y": 24,
      "z": -1,
      "name": "OrbisGalactic_Block_Jawa_Crawler_Hull"
    },
    {
      "x": -16,
      "y": 12,
      "z": 0,
      "name": "OrbisGalactic_Block_Jawa_Crawler_Hull"
    },
    {
      "x": -16,
      "y": 13,
      "z": 0,
      "name": "OrbisGalactic_Block_Jawa_Crawler_Hull"
    },
    {
      "x": -16,
      "y": 14,
      "z": 0,
      "name": "OrbisGalactic_Block_Jawa_Crawler_Hull"
    },
    {
      "x": -16,
      "y": 15,
      "z": 0,
      "name": "OrbisGalactic_Block_Jawa_Crawler_Hull"
    },
    {
      "x": -16,
      "y": 16,
      "z": 0,
      "name": "OrbisGalactic_Block_Jawa_Crawler_Hull"
    },
    {
      "x": -16,
      "y": 17,
      "z": 0,
      "name": "OrbisGalactic_Block_Jawa_Crawler_Hull"
    },
    {
      "x": -16,
      "y": 18,
      "z": 0,
      "name": "OrbisGalactic_Block_Jawa_Crawler_Hull"
    },
    {
      "x": -16,
      "y": 19,
      "z": 0,
      "name": "OrbisGalactic_Block_Jawa_Crawler_Hull"
    },
    {
      "x": -16,
      "y": 20,
      "z": 0,
      "name": "OrbisGalactic_Block_Jawa_Crawler_Hull"
    },
    {
      "x": -16,
      "y": 21,
      "z": 0,
      "name": "OrbisGalactic_Block_Jawa_Crawler_Hull"
    },
    {
      "x": -16,
      "y": 24,
      "z": 0,
      "name": "OrbisGalactic_Block_Jawa_Crawler_Hull"
    },
    {
      "x": -16,
      "y": 12,
      "z": 1,
      "name": "OrbisGalactic_Block_Jawa_Crawler_Hull"
    },
    {
      "x": -16,
      "y": 13,
      "z": 1,
      "name": "OrbisGalactic_Block_Jawa_Crawler_Hull"
    },
    {
      "x": -16,
      "y": 14,
      "z": 1,
      "name": "OrbisGalactic_Block_Jawa_Crawler_Hull"
    },
    {
      "x": -16,
      "y": 15,
      "z": 1,
      "name": "OrbisGalactic_Block_Jawa_Crawler_Hull"
    },
    {
      "x": -16,
      "y": 16,
      "z": 1,
      "name": "OrbisGalactic_Block_Jawa_Crawler_Hull"
    },
    {
      "x": -16,
      "y": 17,
      "z": 1,
      "name": "OrbisGalactic_Block_Jawa_Crawler_Hull"
    },
    {
      "x": -16,
      "y": 18,
      "z": 1,
      "name": "OrbisGalactic_Block_Jawa_Crawler_Hull"
    },
    {
      "x": -16,
      "y": 19,
      "z": 1,
      "name": "OrbisGalactic_Block_Jawa_Crawler_Hull"
    },
    {
      "x": -16,
      "y": 20,
      "z": 1,
      "name": "OrbisGalactic_Block_Jawa_Crawler_Hull"
    },
    {
      "x": -16,
      "y": 21,
      "z": 1,
      "name": "OrbisGalactic_Block_Jawa_Crawler_Hull"
    },
    {
      "x": -16,
      "y": 24,
      "z": 1,
      "name": "OrbisGalactic_Block_Jawa_Crawler_Hull"
    },
    {
      "x": -16,
      "y": 12,
      "z": 2,
      "name": "OrbisGalactic_Block_Jawa_Crawler_Hull",
      "rotation": 10
    },
    {
      "x": -16,
      "y": 13,
      "z": 2,
      "name": "OrbisGalactic_Block_Jawa_Crawler_Hull",
      "rotation": 10
    },
    {
      "x": -16,
      "y": 14,
      "z": 2,
      "name": "OrbisGalactic_Block_Jawa_Crawler_Hull",
      "rotation": 10
    },
    {
      "x": -16,
      "y": 15,
      "z": 2,
      "name": "OrbisGalactic_Block_Jawa_Crawler_Hull"
    },
    {
      "x": -16,
      "y": 16,
      "z": 2,
      "name": "OrbisGalactic_Block_Jawa_Crawler_Hull"
    },
    {
      "x": -16,
      "y": 17,
      "z": 2,
      "name": "OrbisGalactic_Block_Jawa_Crawler_Hull"
    },
    {
      "x": -16,
      "y": 18,
      "z": 2,
      "name": "OrbisGalactic_Block_Jawa_Crawler_Hull"
    },
    {
      "x": -16,
      "y": 19,
      "z": 2,
      "name": "OrbisGalactic_Block_Jawa_Crawler_Hull"
    },
    {
      "x": -16,
      "y": 20,
      "z": 2,
      "name": "OrbisGalactic_Block_Jawa_Crawler_Hull"
    },
    {
      "x": -16,
      "y": 21,
      "z": 2,
      "name": "OrbisGalactic_Block_Jawa_Crawler_Hull"
    },
    {
      "x": -16,
      "y": 24,
      "z": 2,
      "name": "OrbisGalactic_Block_Jawa_Crawler_Hull",
      "rotation": 10
    },
    {
      "x": -16,
      "y": 12,
      "z": 3,
      "name": "OrbisGalactic_Block_Jawa_Crawler_Hull",
      "rotation": 10
    },
    {
      "x": -16,
      "y": 13,
      "z": 3,
      "name": "OrbisGalactic_Block_Jawa_Crawler_Hull",
      "rotation": 10
    },
    {
      "x": -16,
      "y": 14,
      "z": 3,
      "name": "OrbisGalactic_Block_Jawa_Crawler_Hull",
      "rotation": 10
    },
    {
      "x": -16,
      "y": 15,
      "z": 3,
      "name": "OrbisGalactic_Block_Jawa_Crawler_Hull"
    },
    {
      "x": -16,
      "y": 16,
      "z": 3,
      "name": "OrbisGalactic_Block_Jawa_Crawler_Hull"
    },
    {
      "x": -16,
      "y": 17,
      "z": 3,
      "name": "OrbisGalactic_Block_Jawa_Crawler_Hull"
    },
    {
      "x": -16,
      "y": 18,
      "z": 3,
      "name": "OrbisGalactic_Block_Jawa_Crawler_Hull"
    },
    {
      "x": -16,
      "y": 19,
      "z": 3,
      "name": "OrbisGalactic_Block_Jawa_Crawler_Hull"
    },
    {
      "x": -16,
      "y": 20,
      "z": 3,
      "name": "OrbisGalactic_Block_Jawa_Crawler_Hull"
    },
    {
      "x": -16,
      "y": 21,
      "z": 3,
      "name": "OrbisGalactic_Block_Jawa_Crawler_Hull"
    },
    {
      "x": -16,
      "y": 24,
      "z": 3,
      "name": "OrbisGalactic_Block_Jawa_Crawler_Hull",
      "rotation": 10
    },
    {
      "x": -16,
      "y": 12,
      "z": 4,
      "name": "OrbisGalactic_Block_Jawa_Crawler_Hull",
      "rotation": 10
    },
    {
      "x": -16,
      "y": 13,
      "z": 4,
      "name": "OrbisGalactic_Block_Jawa_Crawler_Hull",
      "rotation": 10
    },
    {
      "x": -16,
      "y": 14,
      "z": 4,
      "name": "OrbisGalactic_Block_Jawa_Crawler_Hull",
      "rotation": 10
    },
    {
      "x": -16,
      "y": 15,
      "z": 4,
      "name": "OrbisGalactic_Block_Jawa_Crawler_Hull"
    },
    {
      "x": -16,
      "y": 16,
      "z": 4,
      "name": "OrbisGalactic_Block_Jawa_Crawler_Hull"
    },
    {
      "x": -16,
      "y": 17,
      "z": 4,
      "name": "OrbisGalactic_Block_Jawa_Crawler_Hull"
    },
    {
      "x": -16,
      "y": 18,
      "z": 4,
      "name": "OrbisGalactic_Block_Jawa_Crawler_Hull"
    },
    {
      "x": -16,
      "y": 19,
      "z": 4,
      "name": "OrbisGalactic_Block_Jawa_Crawler_Hull"
    },
    {
      "x": -16,
      "y": 20,
      "z": 4,
      "name": "OrbisGalactic_Block_Jawa_Crawler_Hull"
    },
    {
      "x": -16,
      "y": 21,
      "z": 4,
      "name": "OrbisGalactic_Block_Jawa_Crawler_Hull"
    },
    {
      "x": -16,
      "y": 23,
      "z": 4,
      "name": "Rock_Magma_Cooled"
    },
    {
      "x": -16,
      "y": 24,
      "z": 4,
      "name": "OrbisGalactic_Block_Jawa_Crawler_Hull",
      "rotation": 10
    },
    {
      "x": -16,
      "y": 12,
      "z": 5,
      "name": "OrbisGalactic_Block_Jawa_Crawler_Hull",
      "rotation": 10
    },
    {
      "x": -16,
      "y": 13,
      "z": 5,
      "name": "OrbisGalactic_Block_Jawa_Crawler_Hull",
      "rotation": 10
    },
    {
      "x": -16,
      "y": 14,
      "z": 5,
      "name": "OrbisGalactic_Block_Jawa_Crawler_Hull",
      "rotation": 10
    },
    {
      "x": -16,
      "y": 15,
      "z": 5,
      "name": "OrbisGalactic_Block_Jawa_Crawler_Hull"
    },
    {
      "x": -16,
      "y": 16,
      "z": 5,
      "name": "OrbisGalactic_Block_Jawa_Crawler_Hull"
    },
    {
      "x": -16,
      "y": 17,
      "z": 5,
      "name": "OrbisGalactic_Block_Jawa_Crawler_Hull"
    },
    {
      "x": -16,
      "y": 18,
      "z": 5,
      "name": "OrbisGalactic_Block_Jawa_Crawler_Hull"
    },
    {
      "x": -16,
      "y": 19,
      "z": 5,
      "name": "OrbisGalactic_Block_Jawa_Crawler_Hull"
    },
    {
      "x": -16,
      "y": 20,
      "z": 5,
      "name": "OrbisGalactic_Block_Jawa_Crawler_Hull"
    },
    {
      "x": -16,
      "y": 21,
      "z": 5,
      "name": "OrbisGalactic_Block_Jawa_Crawler_Hull"
    },
    {
      "x": -16,
      "y": 22,
      "z": 5,
      "name": "OrbisGalactic_Block_Jawa_Crawler_Hull"
    },
    {
      "x": -16,
      "y": 23,
      "z": 5,
      "name": "Rock_Magma_Cooled"
    },
    {
      "x": -16,
      "y": 24,
      "z": 5,
      "name": "OrbisGalactic_Block_Jawa_Crawler_Hull",
      "rotation": 10
    },
    {
      "x": -16,
      "y": 12,
      "z": 6,
      "name": "OrbisGalactic_Block_Jawa_Crawler_Hull",
      "rotation": 10
    },
    {
      "x": -16,
      "y": 13,
      "z": 6,
      "name": "OrbisGalactic_Block_Jawa_Crawler_Hull",
      "rotation": 10
    },
    {
      "x": -16,
      "y": 14,
      "z": 6,
      "name": "OrbisGalactic_Block_Jawa_Crawler_Hull",
      "rotation": 10
    },
    {
      "x": -16,
      "y": 15,
      "z": 6,
      "name": "OrbisGalactic_Block_Jawa_Crawler_Hull",
      "rotation": 10
    },
    {
      "x": -16,
      "y": 16,
      "z": 6,
      "name": "OrbisGalactic_Block_Jawa_Crawler_Hull",
      "rotation": 10
    },
    {
      "x": -16,
      "y": 17,
      "z": 6,
      "name": "OrbisGalactic_Block_Jawa_Crawler_Hull",
      "rotation": 10
    },
    {
      "x": -16,
      "y": 18,
      "z": 6,
      "name": "OrbisGalactic_Block_Jawa_Crawler_Hull",
      "rotation": 10
    },
    {
      "x": -16,
      "y": 19,
      "z": 6,
      "name": "OrbisGalactic_Block_Jawa_Crawler_Hull",
      "rotation": 10
    },
    {
      "x": -16,
      "y": 20,
      "z": 6,
      "name": "OrbisGalactic_Block_Jawa_Crawler_Hull",
      "rotation": 10
    },
    {
      "x": -16,
      "y": 21,
      "z": 6,
      "name": "OrbisGalactic_Block_Jawa_Crawler_Hull",
      "rotation": 10
    },
    {
      "x": -16,
      "y": 22,
      "z": 6,
      "name": "OrbisGalactic_Block_Jawa_Crawler_Hull",
      "rotation": 10
    },
    {
      "x": -16,
      "y": 23,
      "z": 6,
      "name": "Rock_Magma_Cooled_Half",
      "rotation": 4
    },
    {
      "x": -16,
      "y": 24,
      "z": 6,
      "name": "OrbisGalactic_Block_Jawa_Crawler_Hull",
      "rotation": 10
    },
    {
      "x": -16,
      "y": 15,
      "z": 7,
      "name": "OrbisGalactic_Block_Jawa_Crawler_Hull"
    },
    {
      "x": -16,
      "y": 16,
      "z": 7,
      "name": "OrbisGalactic_Block_Jawa_Crawler_Hull",
      "rotation": 10
    },
    {
      "x": -16,
      "y": 17,
      "z": 7,
      "name": "OrbisGalactic_Block_Jawa_Crawler_Hull",
      "rotation": 10
    },
    {
      "x": -16,
      "y": 18,
      "z": 7,
      "name": "OrbisGalactic_Block_Jawa_Crawler_Hull",
      "rotation": 10
    },
    {
      "x": -16,
      "y": 19,
      "z": 7,
      "name": "OrbisGalactic_Block_Jawa_Crawler_Hull",
      "rotation": 10
    },
    {
      "x": -16,
      "y": 20,
      "z": 7,
      "name": "OrbisGalactic_Block_Jawa_Crawler_Hull",
      "rotation": 10
    },
    {
      "x": -16,
      "y": 21,
      "z": 7,
      "name": "OrbisGalactic_Block_Jawa_Crawler_Hull",
      "rotation": 10
    },
    {
      "x": -16,
      "y": 22,
      "z": 7,
      "name": "OrbisGalactic_Block_Jawa_Crawler_Hull"
    },
    {
      "x": -16,
      "y": 24,
      "z": 7,
      "name": "OrbisGalactic_Block_Jawa_Crawler_Hull"
    },
    {
      "x": -15,
      "y": 12,
      "z": -7,
      "name": "OrbisGalactic_Block_Jawa_Crawler_Hull"
    },
    {
      "x": -15,
      "y": 13,
      "z": -7,
      "name": "OrbisGalactic_Block_Jawa_Crawler_Hull"
    },
    {
      "x": -15,
      "y": 14,
      "z": -7,
      "name": "OrbisGalactic_Block_Jawa_Crawler_Hull"
    },
    {
      "x": -15,
      "y": 15,
      "z": -7,
      "name": "OrbisGalactic_Block_Jawa_Crawler_Hull"
    },
    {
      "x": -15,
      "y": 16,
      "z": -7,
      "name": "OrbisGalactic_Block_Jawa_Crawler_Hull"
    },
    {
      "x": -15,
      "y": 17,
      "z": -7,
      "name": "OrbisGalactic_Block_Jawa_Crawler_Hull"
    },
    {
      "x": -15,
      "y": 18,
      "z": -7,
      "name": "OrbisGalactic_Block_Jawa_Crawler_Hull"
    },
    {
      "x": -15,
      "y": 19,
      "z": -7,
      "name": "OrbisGalactic_Block_Jawa_Crawler_Hull"
    },
    {
      "x": -15,
      "y": 20,
      "z": -7,
      "name": "OrbisGalactic_Block_Jawa_Crawler_Hull"
    },
    {
      "x": -15,
      "y": 21,
      "z": -7,
      "name": "OrbisGalactic_Block_Jawa_Crawler_Hull"
    },
    {
      "x": -15,
      "y": 22,
      "z": -7,
      "name": "OrbisGalactic_Block_Jawa_Crawler_Hull"
    },
    {
      "x": -15,
      "y": 23,
      "z": -7,
      "name": "OrbisGalactic_Block_Jawa_Crawler_Hull"
    },
    {
      "x": -15,
      "y": 24,
      "z": -7,
      "name": "OrbisGalactic_Block_Jawa_Crawler_Hull"
    },
    {
      "x": -15,
      "y": 11,
      "z": -6,
      "name": "OrbisGalactic_Block_Jawa_Crawler_Hull"
    },
    {
      "x": -15,
      "y": 12,
      "z": -6,
      "name": "OrbisGalactic_Block_Jawa_Crawler_Hull"
    },
    {
      "x": -15,
      "y": 13,
      "z": -6,
      "name": "OrbisGalactic_Block_Jawa_Crawler_Hull"
    },
    {
      "x": -15,
      "y": 14,
      "z": -6,
      "name": "OrbisGalactic_Block_Jawa_Crawler_Hull"
    },
    {
      "x": -15,
      "y": 15,
      "z": -6,
      "name": "OrbisGalactic_Block_Jawa_Crawler_Hull"
    },
    {
      "x": -15,
      "y": 16,
      "z": -6,
      "name": "OrbisGalactic_Block_Jawa_Crawler_Hull"
    },
    {
      "x": -15,
      "y": 17,
      "z": -6,
      "name": "OrbisGalactic_Block_Jawa_Crawler_Hull"
    },
    {
      "x": -15,
      "y": 18,
      "z": -6,
      "name": "OrbisGalactic_Block_Jawa_Crawler_Hull"
    },
    {
      "x": -15,
      "y": 19,
      "z": -6,
      "name": "OrbisGalactic_Block_Jawa_Crawler_Hull"
    },
    {
      "x": -15,
      "y": 20,
      "z": -6,
      "name": "OrbisGalactic_Block_Jawa_Crawler_Hull"
    },
    {
      "x": -15,
      "y": 21,
      "z": -6,
      "name": "OrbisGalactic_Block_Jawa_Crawler_Hull"
    },
    {
      "x": -15,
      "y": 22,
      "z": -6,
      "name": "OrbisGalactic_Block_Jawa_Crawler_Hull"
    },
    {
      "x": -15,
      "y": 23,
      "z": -6,
      "name": "OrbisGalactic_Block_Jawa_Crawler_Hull"
    },
    {
      "x": -15,
      "y": 24,
      "z": -6,
      "name": "OrbisGalactic_Block_Jawa_Crawler_Hull"
    },
    {
      "x": -15,
      "y": 11,
      "z": -5,
      "name": "OrbisGalactic_Block_Jawa_Crawler_Hull"
    },
    {
      "x": -15,
      "y": 21,
      "z": -5,
      "name": "OrbisGalactic_Block_Jawa_Crawler_Hull"
    },
    {
      "x": -15,
      "y": 22,
      "z": -5,
      "name": "OrbisGalactic_Block_Jawa_Crawler_Hull"
    },
    {
      "x": -15,
      "y": 23,
      "z": -5,
      "name": "OrbisGalactic_Block_Jawa_Crawler_Hull"
    },
    {
      "x": -15,
      "y": 24,
      "z": -5,
      "name": "OrbisGalactic_Block_Jawa_Crawler_Hull"
    },
    {
      "x": -15,
      "y": 11,
      "z": -4,
      "name": "OrbisGalactic_Block_Jawa_Crawler_Hull"
    },
    {
      "x": -15,
      "y": 21,
      "z": -4,
      "name": "OrbisGalactic_Block_Jawa_Crawler_Hull"
    },
    {
      "x": -15,
      "y": 22,
      "z": -4,
      "name": "OrbisGalactic_Block_Jawa_Crawler_Hull"
    },
    {
      "x": -15,
      "y": 23,
      "z": -4,
      "name": "OrbisGalactic_Block_Jawa_Crawler_Hull"
    },
    {
      "x": -15,
      "y": 24,
      "z": -4,
      "name": "OrbisGalactic_Block_Jawa_Crawler_Hull"
    },
    {
      "x": -15,
      "y": 11,
      "z": -3,
      "name": "OrbisGalactic_Block_Jawa_Crawler_Hull"
    },
    {
      "x": -15,
      "y": 21,
      "z": -3,
      "name": "OrbisGalactic_Block_Jawa_Crawler_Hull"
    },
    {
      "x": -15,
      "y": 24,
      "z": -3,
      "name": "OrbisGalactic_Block_Jawa_Crawler_Hull"
    },
    {
      "x": -15,
      "y": 11,
      "z": -2,
      "name": "OrbisGalactic_Block_Jawa_Crawler_Hull"
    },
    {
      "x": -15,
      "y": 21,
      "z": -2,
      "name": "OrbisGalactic_Block_Jawa_Crawler_Hull"
    },
    {
      "x": -15,
      "y": 24,
      "z": -2,
      "name": "OrbisGalactic_Block_Jawa_Crawler_Hull"
    },
    {
      "x": -15,
      "y": 11,
      "z": -1,
      "name": "OrbisGalactic_Block_Jawa_Crawler_Hull"
    },
    {
      "x": -15,
      "y": 21,
      "z": -1,
      "name": "OrbisGalactic_Block_Jawa_Crawler_Hull"
    },
    {
      "x": -15,
      "y": 24,
      "z": -1,
      "name": "OrbisGalactic_Block_Jawa_Crawler_Hull"
    },
    {
      "x": -15,
      "y": 11,
      "z": 0,
      "name": "OrbisGalactic_Block_Jawa_Crawler_Hull"
    },
    {
      "x": -15,
      "y": 21,
      "z": 0,
      "name": "OrbisGalactic_Block_Jawa_Crawler_Hull"
    },
    {
      "x": -15,
      "y": 24,
      "z": 0,
      "name": "OrbisGalactic_Block_Jawa_Crawler_Hull"
    },
    {
      "x": -15,
      "y": 11,
      "z": 1,
      "name": "OrbisGalactic_Block_Jawa_Crawler_Hull"
    },
    {
      "x": -15,
      "y": 21,
      "z": 1,
      "name": "OrbisGalactic_Block_Jawa_Crawler_Hull"
    },
    {
      "x": -15,
      "y": 24,
      "z": 1,
      "name": "OrbisGalactic_Block_Jawa_Crawler_Hull"
    },
    {
      "x": -15,
      "y": 11,
      "z": 2,
      "name": "OrbisGalactic_Block_Jawa_Crawler_Hull",
      "rotation": 10
    },
    {
      "x": -15,
      "y": 21,
      "z": 2,
      "name": "OrbisGalactic_Block_Jawa_Crawler_Hull"
    },
    {
      "x": -15,
      "y": 24,
      "z": 2,
      "name": "OrbisGalactic_Block_Jawa_Crawler_Hull",
      "rotation": 10
    },
    {
      "x": -15,
      "y": 11,
      "z": 3,
      "name": "OrbisGalactic_Block_Jawa_Crawler_Hull",
      "rotation": 10
    },
    {
      "x": -15,
      "y": 21,
      "z": 3,
      "name": "OrbisGalactic_Block_Jawa_Crawler_Hull"
    },
    {
      "x": -15,
      "y": 24,
      "z": 3,
      "name": "OrbisGalactic_Block_Jawa_Crawler_Hull",
      "rotation": 10
    },
    {
      "x": -15,
      "y": 11,
      "z": 4,
      "name": "OrbisGalactic_Block_Jawa_Crawler_Hull",
      "rotation": 10
    },
    {
      "x": -15,
      "y": 21,
      "z": 4,
      "name": "OrbisGalactic_Block_Jawa_Crawler_Hull"
    },
    {
      "x": -15,
      "y": 24,
      "z": 4,
      "name": "OrbisGalactic_Block_Jawa_Crawler_Hull",
      "rotation": 10
    },
    {
      "x": -15,
      "y": 11,
      "z": 5,
      "name": "OrbisGalactic_Block_Jawa_Crawler_Hull",
      "rotation": 10
    },
    {
      "x": -15,
      "y": 21,
      "z": 5,
      "name": "OrbisGalactic_Block_Jawa_Crawler_Hull"
    },
    {
      "x": -15,
      "y": 22,
      "z": 5,
      "name": "OrbisGalactic_Block_Jawa_Crawler_Hull"
    },
    {
      "x": -15,
      "y": 23,
      "z": 5,
      "name": "OrbisGalactic_Block_Jawa_Crawler_Hull"
    },
    {
      "x": -15,
      "y": 24,
      "z": 5,
      "name": "OrbisGalactic_Block_Jawa_Crawler_Hull",
      "rotation": 10
    },
    {
      "x": -15,
      "y": 11,
      "z": 6,
      "name": "OrbisGalactic_Block_Jawa_Crawler_Hull",
      "rotation": 10
    },
    {
      "x": -15,
      "y": 21,
      "z": 6,
      "name": "OrbisGalactic_Block_Jawa_Crawler_Hull"
    },
    {
      "x": -15,
      "y": 22,
      "z": 6,
      "name": "OrbisGalactic_Block_Jawa_Crawler_Hull"
    },
    {
      "x": -15,
      "y": 23,
      "z": 6,
      "name": "OrbisGalactic_Block_Jawa_Crawler_Hull",
      "rotation": 10
    },
    {
      "x": -15,
      "y": 24,
      "z": 6,
      "name": "OrbisGalactic_Block_Jawa_Crawler_Hull",
      "rotation": 10
    },
    {
      "x": -15,
      "y": 11,
      "z": 7,
      "name": "OrbisGalactic_Block_Jawa_Crawler_Hull",
      "rotation": 10
    },
    {
      "x": -15,
      "y": 12,
      "z": 7,
      "name": "OrbisGalactic_Block_Jawa_Crawler_Hull",
      "rotation": 10
    },
    {
      "x": -15,
      "y": 13,
      "z": 7,
      "name": "OrbisGalactic_Block_Jawa_Crawler_Hull",
      "rotation": 10
    },
    {
      "x": -15,
      "y": 14,
      "z": 7,
      "name": "OrbisGalactic_Block_Jawa_Crawler_Hull",
      "rotation": 10
    },
    {
      "x": -15,
      "y": 15,
      "z": 7,
      "name": "OrbisGalactic_Block_Jawa_Crawler_Hull",
      "rotation": 10
    },
    {
      "x": -15,
      "y": 16,
      "z": 7,
      "name": "OrbisGalactic_Block_Jawa_Crawler_Hull",
      "rotation": 10
    },
    {
      "x": -15,
      "y": 17,
      "z": 7,
      "name": "OrbisGalactic_Block_Jawa_Crawler_Hull",
      "rotation": 10
    },
    {
      "x": -15,
      "y": 18,
      "z": 7,
      "name": "OrbisGalactic_Block_Jawa_Crawler_Hull",
      "rotation": 10
    },
    {
      "x": -15,
      "y": 19,
      "z": 7,
      "name": "OrbisGalactic_Block_Jawa_Crawler_Hull",
      "rotation": 10
    },
    {
      "x": -15,
      "y": 20,
      "z": 7,
      "name": "OrbisGalactic_Block_Jawa_Crawler_Hull",
      "rotation": 10
    },
    {
      "x": -15,
      "y": 21,
      "z": 7,
      "name": "OrbisGalactic_Block_Jawa_Crawler_Hull",
      "rotation": 10
    },
    {
      "x": -15,
      "y": 22,
      "z": 7,
      "name": "OrbisGalactic_Block_Jawa_Crawler_Hull",
      "rotation": 10
    },
    {
      "x": -15,
      "y": 23,
      "z": 7,
      "name": "OrbisGalactic_Block_Jawa_Crawler_Hull",
      "rotation": 10
    },
    {
      "x": -15,
      "y": 24,
      "z": 7,
      "name": "OrbisGalactic_Block_Jawa_Crawler_Hull",
      "rotation": 10
    },
    {
      "x": -15,
      "y": 12,
      "z": 8,
      "name": "OrbisGalactic_Block_Jawa_Crawler_Hull"
    },
    {
      "x": -15,
      "y": 13,
      "z": 8,
      "name": "OrbisGalactic_Block_Jawa_Crawler_Hull"
    },
    {
      "x": -15,
      "y": 14,
      "z": 8,
      "name": "OrbisGalactic_Block_Jawa_Crawler_Hull"
    },
    {
      "x": -15,
      "y": 15,
      "z": 8,
      "name": "OrbisGalactic_Block_Jawa_Crawler_Hull"
    },
    {
      "x": -15,
      "y": 16,
      "z": 8,
      "name": "OrbisGalactic_Block_Jawa_Crawler_Hull"
    },
    {
      "x": -15,
      "y": 17,
      "z": 8,
      "name": "OrbisGalactic_Block_Jawa_Crawler_Hull"
    },
    {
      "x": -15,
      "y": 18,
      "z": 8,
      "name": "OrbisGalactic_Block_Jawa_Crawler_Hull"
    },
    {
      "x": -15,
      "y": 19,
      "z": 8,
      "name": "OrbisGalactic_Block_Jawa_Crawler_Hull"
    },
    {
      "x": -15,
      "y": 20,
      "z": 8,
      "name": "OrbisGalactic_Block_Jawa_Crawler_Hull"
    },
    {
      "x": -15,
      "y": 21,
      "z": 8,
      "name": "OrbisGalactic_Block_Jawa_Crawler_Hull"
    },
    {
      "x": -15,
      "y": 22,
      "z": 8,
      "name": "OrbisGalactic_Block_Jawa_Crawler_Hull"
    },
    {
      "x": -15,
      "y": 23,
      "z": 8,
      "name": "OrbisGalactic_Block_Jawa_Crawler_Hull"
    },
    {
      "x": -15,
      "y": 24,
      "z": 8,
      "name": "OrbisGalactic_Block_Jawa_Crawler_Hull"
    },
    {
      "x": -14,
      "y": 11,
      "z": -7,
      "name": "OrbisGalactic_Block_Jawa_Crawler_Hull"
    },
    {
      "x": -14,
      "y": 12,
      "z": -7,
      "name": "OrbisGalactic_Block_Jawa_Crawler_Hull"
    },
    {
      "x": -14,
      "y": 13,
      "z": -7,
      "name": "OrbisGalactic_Block_Jawa_Crawler_Hull"
    },
    {
      "x": -14,
      "y": 14,
      "z": -7,
      "name": "OrbisGalactic_Block_Jawa_Crawler_Hull"
    },
    {
      "x": -14,
      "y": 15,
      "z": -7,
      "name": "OrbisGalactic_Block_Jawa_Crawler_Hull"
    },
    {
      "x": -14,
      "y": 16,
      "z": -7,
      "name": "OrbisGalactic_Block_Jawa_Crawler_Hull"
    },
    {
      "x": -14,
      "y": 17,
      "z": -7,
      "name": "OrbisGalactic_Block_Jawa_Crawler_Hull"
    },
    {
      "x": -14,
      "y": 18,
      "z": -7,
      "name": "OrbisGalactic_Block_Jawa_Crawler_Hull"
    },
    {
      "x": -14,
      "y": 19,
      "z": -7,
      "name": "OrbisGalactic_Block_Jawa_Crawler_Hull"
    },
    {
      "x": -14,
      "y": 20,
      "z": -7,
      "name": "OrbisGalactic_Block_Jawa_Crawler_Hull"
    },
    {
      "x": -14,
      "y": 21,
      "z": -7,
      "name": "OrbisGalactic_Block_Jawa_Crawler_Hull"
    },
    {
      "x": -14,
      "y": 22,
      "z": -7,
      "name": "OrbisGalactic_Block_Jawa_Crawler_Hull"
    },
    {
      "x": -14,
      "y": 23,
      "z": -7,
      "name": "OrbisGalactic_Block_Jawa_Crawler_Hull"
    },
    {
      "x": -14,
      "y": 24,
      "z": -7,
      "name": "OrbisGalactic_Block_Jawa_Crawler_Hull"
    },
    {
      "x": -14,
      "y": 10,
      "z": -6,
      "name": "OrbisGalactic_Block_Jawa_Crawler_Hull"
    },
    {
      "x": -14,
      "y": 11,
      "z": -6,
      "name": "OrbisGalactic_Block_Jawa_Crawler_Hull"
    },
    {
      "x": -14,
      "y": 12,
      "z": -6,
      "name": "OrbisGalactic_Block_Jawa_Crawler_Hull"
    },
    {
      "x": -14,
      "y": 13,
      "z": -6,
      "name": "OrbisGalactic_Block_Jawa_Crawler_Hull"
    },
    {
      "x": -14,
      "y": 14,
      "z": -6,
      "name": "OrbisGalactic_Block_Jawa_Crawler_Hull"
    },
    {
      "x": -14,
      "y": 15,
      "z": -6,
      "name": "OrbisGalactic_Block_Jawa_Crawler_Hull"
    },
    {
      "x": -14,
      "y": 16,
      "z": -6,
      "name": "OrbisGalactic_Block_Jawa_Crawler_Hull"
    },
    {
      "x": -14,
      "y": 17,
      "z": -6,
      "name": "OrbisGalactic_Block_Jawa_Crawler_Hull"
    },
    {
      "x": -14,
      "y": 18,
      "z": -6,
      "name": "OrbisGalactic_Block_Jawa_Crawler_Hull"
    },
    {
      "x": -14,
      "y": 19,
      "z": -6,
      "name": "OrbisGalactic_Block_Jawa_Crawler_Hull"
    },
    {
      "x": -14,
      "y": 20,
      "z": -6,
      "name": "OrbisGalactic_Block_Jawa_Crawler_Hull"
    },
    {
      "x": -14,
      "y": 21,
      "z": -6,
      "name": "OrbisGalactic_Block_Jawa_Crawler_Hull"
    },
    {
      "x": -14,
      "y": 22,
      "z": -6,
      "name": "OrbisGalactic_Block_Jawa_Crawler_Hull"
    },
    {
      "x": -14,
      "y": 23,
      "z": -6,
      "name": "OrbisGalactic_Block_Jawa_Crawler_Hull"
    },
    {
      "x": -14,
      "y": 24,
      "z": -6,
      "name": "OrbisGalactic_Block_Jawa_Crawler_Hull"
    },
    {
      "x": -14,
      "y": 10,
      "z": -5,
      "name": "OrbisGalactic_Block_Jawa_Crawler_Hull"
    },
    {
      "x": -14,
      "y": 21,
      "z": -5,
      "name": "OrbisGalactic_Block_Jawa_Crawler_Hull"
    },
    {
      "x": -14,
      "y": 22,
      "z": -5,
      "name": "OrbisGalactic_Block_Jawa_Crawler_Hull"
    },
    {
      "x": -14,
      "y": 23,
      "z": -5,
      "name": "OrbisGalactic_Block_Jawa_Crawler_Hull"
    },
    {
      "x": -14,
      "y": 24,
      "z": -5,
      "name": "OrbisGalactic_Block_Jawa_Crawler_Hull"
    },
    {
      "x": -14,
      "y": 10,
      "z": -4,
      "name": "OrbisGalactic_Block_Jawa_Crawler_Hull"
    },
    {
      "x": -14,
      "y": 21,
      "z": -4,
      "name": "OrbisGalactic_Block_Jawa_Crawler_Hull"
    },
    {
      "x": -14,
      "y": 22,
      "z": -4,
      "name": "OrbisGalactic_Block_Jawa_Crawler_Hull"
    },
    {
      "x": -14,
      "y": 23,
      "z": -4,
      "name": "OrbisGalactic_Block_Jawa_Crawler_Hull"
    },
    {
      "x": -14,
      "y": 24,
      "z": -4,
      "name": "OrbisGalactic_Block_Jawa_Crawler_Hull"
    },
    {
      "x": -14,
      "y": 10,
      "z": -3,
      "name": "OrbisGalactic_Block_Jawa_Crawler_Hull"
    },
    {
      "x": -14,
      "y": 21,
      "z": -3,
      "name": "OrbisGalactic_Block_Jawa_Crawler_Hull"
    },
    {
      "x": -14,
      "y": 24,
      "z": -3,
      "name": "OrbisGalactic_Block_Jawa_Crawler_Hull"
    },
    {
      "x": -14,
      "y": 10,
      "z": -2,
      "name": "OrbisGalactic_Block_Jawa_Crawler_Hull"
    },
    {
      "x": -14,
      "y": 21,
      "z": -2,
      "name": "OrbisGalactic_Block_Jawa_Crawler_Hull"
    },
    {
      "x": -14,
      "y": 24,
      "z": -2,
      "name": "OrbisGalactic_Block_Jawa_Crawler_Hull"
    },
    {
      "x": -14,
      "y": 10,
      "z": -1,
      "name": "OrbisGalactic_Block_Jawa_Crawler_Hull"
    },
    {
      "x": -14,
      "y": 21,
      "z": -1,
      "name": "OrbisGalactic_Block_Jawa_Crawler_Hull"
    },
    {
      "x": -14,
      "y": 24,
      "z": -1,
      "name": "OrbisGalactic_Block_Jawa_Crawler_Hull"
    },
    {
      "x": -14,
      "y": 10,
      "z": 0,
      "name": "OrbisGalactic_Block_Jawa_Crawler_Hull"
    },
    {
      "x": -14,
      "y": 21,
      "z": 0,
      "name": "OrbisGalactic_Block_Jawa_Crawler_Hull"
    },
    {
      "x": -14,
      "y": 22,
      "z": 0,
      "name": "Rock_Magma_Cooled"
    },
    {
      "x": -14,
      "y": 23,
      "z": 0,
      "name": "Rock_Magma_Cooled"
    },
    {
      "x": -14,
      "y": 24,
      "z": 0,
      "name": "OrbisGalactic_Block_Jawa_Crawler_Hull"
    },
    {
      "x": -14,
      "y": 10,
      "z": 1,
      "name": "OrbisGalactic_Block_Jawa_Crawler_Hull"
    },
    {
      "x": -14,
      "y": 21,
      "z": 1,
      "name": "OrbisGalactic_Block_Jawa_Crawler_Hull"
    },
    {
      "x": -14,
      "y": 22,
      "z": 1,
      "name": "Rock_Magma_Cooled"
    },
    {
      "x": -14,
      "y": 23,
      "z": 1,
      "name": "Rock_Magma_Cooled"
    },
    {
      "x": -14,
      "y": 24,
      "z": 1,
      "name": "OrbisGalactic_Block_Jawa_Crawler_Hull"
    },
    {
      "x": -14,
      "y": 10,
      "z": 2,
      "name": "OrbisGalactic_Block_Jawa_Crawler_Hull",
      "rotation": 10
    },
    {
      "x": -14,
      "y": 21,
      "z": 2,
      "name": "OrbisGalactic_Block_Jawa_Crawler_Hull"
    },
    {
      "x": -14,
      "y": 24,
      "z": 2,
      "name": "OrbisGalactic_Block_Jawa_Crawler_Hull",
      "rotation": 10
    },
    {
      "x": -14,
      "y": 10,
      "z": 3,
      "name": "OrbisGalactic_Block_Jawa_Crawler_Hull",
      "rotation": 10
    },
    {
      "x": -14,
      "y": 21,
      "z": 3,
      "name": "OrbisGalactic_Block_Jawa_Crawler_Hull"
    },
    {
      "x": -14,
      "y": 24,
      "z": 3,
      "name": "OrbisGalactic_Block_Jawa_Crawler_Hull",
      "rotation": 10
    },
    {
      "x": -14,
      "y": 10,
      "z": 4,
      "name": "OrbisGalactic_Block_Jawa_Crawler_Hull",
      "rotation": 10
    },
    {
      "x": -14,
      "y": 21,
      "z": 4,
      "name": "OrbisGalactic_Block_Jawa_Crawler_Hull"
    },
    {
      "x": -14,
      "y": 24,
      "z": 4,
      "name": "OrbisGalactic_Block_Jawa_Crawler_Hull",
      "rotation": 10
    },
    {
      "x": -14,
      "y": 10,
      "z": 5,
      "name": "OrbisGalactic_Block_Jawa_Crawler_Hull",
      "rotation": 10
    },
    {
      "x": -14,
      "y": 21,
      "z": 5,
      "name": "OrbisGalactic_Block_Jawa_Crawler_Hull"
    },
    {
      "x": -14,
      "y": 22,
      "z": 5,
      "name": "OrbisGalactic_Block_Jawa_Crawler_Hull"
    },
    {
      "x": -14,
      "y": 23,
      "z": 5,
      "name": "OrbisGalactic_Block_Jawa_Crawler_Hull"
    },
    {
      "x": -14,
      "y": 24,
      "z": 5,
      "name": "OrbisGalactic_Block_Jawa_Crawler_Hull",
      "rotation": 10
    },
    {
      "x": -14,
      "y": 10,
      "z": 6,
      "name": "OrbisGalactic_Block_Jawa_Crawler_Hull",
      "rotation": 10
    },
    {
      "x": -14,
      "y": 21,
      "z": 6,
      "name": "OrbisGalactic_Block_Jawa_Crawler_Hull"
    },
    {
      "x": -14,
      "y": 22,
      "z": 6,
      "name": "OrbisGalactic_Block_Jawa_Crawler_Hull"
    },
    {
      "x": -14,
      "y": 23,
      "z": 6,
      "name": "OrbisGalactic_Block_Jawa_Crawler_Hull"
    },
    {
      "x": -14,
      "y": 24,
      "z": 6,
      "name": "OrbisGalactic_Block_Jawa_Crawler_Hull",
      "rotation": 10
    },
    {
      "x": -14,
      "y": 10,
      "z": 7,
      "name": "OrbisGalactic_Block_Jawa_Crawler_Hull",
      "rotation": 10
    },
    {
      "x": -14,
      "y": 11,
      "z": 7,
      "name": "OrbisGalactic_Block_Jawa_Crawler_Hull",
      "rotation": 10
    },
    {
      "x": -14,
      "y": 12,
      "z": 7,
      "name": "OrbisGalactic_Block_Jawa_Crawler_Hull",
      "rotation": 10
    },
    {
      "x": -14,
      "y": 13,
      "z": 7,
      "name": "OrbisGalactic_Block_Jawa_Crawler_Hull",
      "rotation": 10
    },
    {
      "x": -14,
      "y": 14,
      "z": 7,
      "name": "OrbisGalactic_Block_Jawa_Crawler_Hull",
      "rotation": 10
    },
    {
      "x": -14,
      "y": 15,
      "z": 7,
      "name": "OrbisGalactic_Block_Jawa_Crawler_Hull",
      "rotation": 10
    },
    {
      "x": -14,
      "y": 16,
      "z": 7,
      "name": "OrbisGalactic_Block_Jawa_Crawler_Hull",
      "rotation": 10
    },
    {
      "x": -14,
      "y": 17,
      "z": 7,
      "name": "OrbisGalactic_Block_Jawa_Crawler_Hull",
      "rotation": 10
    },
    {
      "x": -14,
      "y": 20,
      "z": 7,
      "name": "OrbisGalactic_Block_Jawa_Crawler_Hull",
      "rotation": 10
    },
    {
      "x": -14,
      "y": 21,
      "z": 7,
      "name": "OrbisGalactic_Block_Jawa_Crawler_Hull",
      "rotation": 10
    },
    {
      "x": -14,
      "y": 22,
      "z": 7,
      "name": "OrbisGalactic_Block_Jawa_Crawler_Hull",
      "rotation": 10
    },
    {
      "x": -14,
      "y": 23,
      "z": 7,
      "name": "OrbisGalactic_Block_Jawa_Crawler_Hull",
      "rotation": 10
    },
    {
      "x": -14,
      "y": 24,
      "z": 7,
      "name": "OrbisGalactic_Block_Jawa_Crawler_Hull",
      "rotation": 10
    },
    {
      "x": -14,
      "y": 11,
      "z": 8,
      "name": "OrbisGalactic_Block_Jawa_Crawler_Hull"
    },
    {
      "x": -14,
      "y": 12,
      "z": 8,
      "name": "OrbisGalactic_Block_Jawa_Crawler_Hull"
    },
    {
      "x": -14,
      "y": 13,
      "z": 8,
      "name": "OrbisGalactic_Block_Jawa_Crawler_Hull"
    },
    {
      "x": -14,
      "y": 14,
      "z": 8,
      "name": "OrbisGalactic_Block_Jawa_Crawler_Hull",
      "rotation": 10
    },
    {
      "x": -14,
      "y": 15,
      "z": 8,
      "name": "OrbisGalactic_Block_Jawa_Crawler_Hull",
      "rotation": 10
    },
    {
      "x": -14,
      "y": 16,
      "z": 8,
      "name": "OrbisGalactic_Block_Jawa_Crawler_Hull",
      "rotation": 10
    },
    {
      "x": -14,
      "y": 17,
      "z": 8,
      "name": "OrbisGalactic_Block_Jawa_Crawler_Hull",
      "rotation": 10
    },
    {
      "x": -14,
      "y": 18,
      "z": 8,
      "name": "OrbisGalactic_Block_Jawa_Crawler_Hull"
    },
    {
      "x": -14,
      "y": 19,
      "z": 8,
      "name": "OrbisGalactic_Block_Jawa_Crawler_Hull"
    },
    {
      "x": -14,
      "y": 20,
      "z": 8,
      "name": "OrbisGalactic_Block_Jawa_Crawler_Hull",
      "rotation": 10
    },
    {
      "x": -14,
      "y": 21,
      "z": 8,
      "name": "OrbisGalactic_Block_Jawa_Crawler_Hull",
      "rotation": 10
    },
    {
      "x": -14,
      "y": 22,
      "z": 8,
      "name": "OrbisGalactic_Block_Jawa_Crawler_Hull",
      "rotation": 10
    },
    {
      "x": -14,
      "y": 23,
      "z": 8,
      "name": "OrbisGalactic_Block_Jawa_Crawler_Hull",
      "rotation": 10
    },
    {
      "x": -14,
      "y": 24,
      "z": 8,
      "name": "OrbisGalactic_Block_Jawa_Crawler_Hull",
      "rotation": 10
    },
    {
      "x": -13,
      "y": 8,
      "z": -7,
      "name": "OrbisGalactic_Block_Jawa_Crawler_Hull"
    },
    {
      "x": -13,
      "y": 9,
      "z": -7,
      "name": "OrbisGalactic_Block_Jawa_Crawler_Hull"
    },
    {
      "x": -13,
      "y": 10,
      "z": -7,
      "name": "OrbisGalactic_Block_Jawa_Crawler_Hull"
    },
    {
      "x": -13,
      "y": 11,
      "z": -7,
      "name": "OrbisGalactic_Block_Jawa_Crawler_Hull"
    },
    {
      "x": -13,
      "y": 12,
      "z": -7,
      "name": "OrbisGalactic_Block_Jawa_Crawler_Hull"
    },
    {
      "x": -13,
      "y": 13,
      "z": -7,
      "name": "OrbisGalactic_Block_Jawa_Crawler_Hull"
    },
    {
      "x": -13,
      "y": 14,
      "z": -7,
      "name": "OrbisGalactic_Block_Jawa_Crawler_Hull"
    },
    {
      "x": -13,
      "y": 15,
      "z": -7,
      "name": "OrbisGalactic_Block_Jawa_Crawler_Hull"
    },
    {
      "x": -13,
      "y": 16,
      "z": -7,
      "name": "OrbisGalactic_Block_Jawa_Crawler_Hull"
    },
    {
      "x": -13,
      "y": 17,
      "z": -7,
      "name": "OrbisGalactic_Block_Jawa_Crawler_Hull"
    },
    {
      "x": -13,
      "y": 18,
      "z": -7,
      "name": "OrbisGalactic_Block_Jawa_Crawler_Hull"
    },
    {
      "x": -13,
      "y": 19,
      "z": -7,
      "name": "OrbisGalactic_Block_Jawa_Crawler_Hull"
    },
    {
      "x": -13,
      "y": 20,
      "z": -7,
      "name": "OrbisGalactic_Block_Jawa_Crawler_Hull"
    },
    {
      "x": -13,
      "y": 21,
      "z": -7,
      "name": "OrbisGalactic_Block_Jawa_Crawler_Hull"
    },
    {
      "x": -13,
      "y": 22,
      "z": -7,
      "name": "OrbisGalactic_Block_Jawa_Crawler_Hull"
    },
    {
      "x": -13,
      "y": 23,
      "z": -7,
      "name": "OrbisGalactic_Block_Jawa_Crawler_Hull"
    },
    {
      "x": -13,
      "y": 24,
      "z": -7,
      "name": "OrbisGalactic_Block_Jawa_Crawler_Hull"
    },
    {
      "x": -13,
      "y": 8,
      "z": -6,
      "name": "OrbisGalactic_Block_Jawa_Crawler_Hull"
    },
    {
      "x": -13,
      "y": 9,
      "z": -6,
      "name": "OrbisGalactic_Block_Jawa_Crawler_Hull"
    },
    {
      "x": -13,
      "y": 10,
      "z": -6,
      "name": "OrbisGalactic_Block_Jawa_Crawler_Hull"
    },
    {
      "x": -13,
      "y": 11,
      "z": -6,
      "name": "OrbisGalactic_Block_Jawa_Crawler_Hull"
    },
    {
      "x": -13,
      "y": 12,
      "z": -6,
      "name": "OrbisGalactic_Block_Jawa_Crawler_Hull"
    },
    {
      "x": -13,
      "y": 13,
      "z": -6,
      "name": "OrbisGalactic_Block_Jawa_Crawler_Hull"
    },
    {
      "x": -13,
      "y": 14,
      "z": -6,
      "name": "OrbisGalactic_Block_Jawa_Crawler_Hull"
    },
    {
      "x": -13,
      "y": 15,
      "z": -6,
      "name": "OrbisGalactic_Block_Jawa_Crawler_Hull"
    },
    {
      "x": -13,
      "y": 16,
      "z": -6,
      "name": "OrbisGalactic_Block_Jawa_Crawler_Hull"
    },
    {
      "x": -13,
      "y": 17,
      "z": -6,
      "name": "OrbisGalactic_Block_Jawa_Crawler_Hull"
    },
    {
      "x": -13,
      "y": 18,
      "z": -6,
      "name": "*OrbisGalactic_Block_Jawa_Lamp1_State_Definitions_On",
      "rotation": 1
    },
    {
      "x": -13,
      "y": 19,
      "z": -6,
      "name": "OrbisGalactic_Block_Jawa_Crawler_Hull"
    },
    {
      "x": -13,
      "y": 20,
      "z": -6,
      "name": "OrbisGalactic_Block_Jawa_Crawler_Hull"
    },
    {
      "x": -13,
      "y": 21,
      "z": -6,
      "name": "OrbisGalactic_Block_Jawa_Crawler_Hull"
    },
    {
      "x": -13,
      "y": 22,
      "z": -6,
      "name": "OrbisGalactic_Block_Jawa_Crawler_Hull"
    },
    {
      "x": -13,
      "y": 23,
      "z": -6,
      "name": "OrbisGalactic_Block_Jawa_Crawler_Hull"
    },
    {
      "x": -13,
      "y": 24,
      "z": -6,
      "name": "OrbisGalactic_Block_Jawa_Crawler_Hull"
    },
    {
      "x": -13,
      "y": 8,
      "z": -5,
      "name": "OrbisGalactic_Block_Jawa_Crawler_Hull"
    },
    {
      "x": -13,
      "y": 9,
      "z": -5,
      "name": "OrbisGalactic_Block_Jawa_Crawler_Hull"
    },
    {
      "x": -13,
      "y": 10,
      "z": -5,
      "name": "OrbisGalactic_Block_Jawa_Crawler_Hull"
    },
    {
      "x": -13,
      "y": 11,
      "z": -5,
      "name": "OrbisGalactic_Block_Jawa_Crawler_Hull"
    },
    {
      "x": -13,
      "y": 12,
      "z": -5,
      "name": "OrbisGalactic_Block_Jawa_Crawler_Hull"
    },
    {
      "x": -13,
      "y": 13,
      "z": -5,
      "name": "OrbisGalactic_Block_Jawa_Crawler_Hull"
    },
    {
      "x": -13,
      "y": 14,
      "z": -5,
      "name": "OrbisGalactic_Block_Jawa_Crawler_Hull"
    },
    {
      "x": -13,
      "y": 15,
      "z": -5,
      "name": "OrbisGalactic_Block_Jawa_Crawler_Hull"
    },
    {
      "x": -13,
      "y": 16,
      "z": -5,
      "name": "OrbisGalactic_Block_Jawa_Crawler_Hull"
    },
    {
      "x": -13,
      "y": 17,
      "z": -5,
      "name": "OrbisGalactic_Block_Jawa_Crawler_Hull"
    },
    {
      "x": -13,
      "y": 18,
      "z": -5,
      "name": "*OrbisGalactic_Block_Jawa_Lamp1_State_Definitions_On",
      "rotation": 1
    },
    {
      "x": -13,
      "y": 19,
      "z": -5,
      "name": "OrbisGalactic_Block_Jawa_Crawler_Hull"
    },
    {
      "x": -13,
      "y": 20,
      "z": -5,
      "name": "OrbisGalactic_Block_Jawa_Crawler_Hull"
    },
    {
      "x": -13,
      "y": 21,
      "z": -5,
      "name": "OrbisGalactic_Block_Jawa_Crawler_Hull"
    },
    {
      "x": -13,
      "y": 22,
      "z": -5,
      "name": "OrbisGalactic_Block_Jawa_Crawler_Hull"
    },
    {
      "x": -13,
      "y": 23,
      "z": -5,
      "name": "OrbisGalactic_Block_Jawa_Crawler_Hull"
    },
    {
      "x": -13,
      "y": 24,
      "z": -5,
      "name": "OrbisGalactic_Block_Jawa_Crawler_Hull"
    },
    {
      "x": -13,
      "y": 8,
      "z": -4,
      "name": "OrbisGalactic_Block_Jawa_Crawler_Hull"
    },
    {
      "x": -13,
      "y": 9,
      "z": -4,
      "name": "OrbisGalactic_Block_Jawa_Crawler_Hull"
    },
    {
      "x": -13,
      "y": 10,
      "z": -4,
      "name": "OrbisGalactic_Block_Jawa_Crawler_Hull"
    },
    {
      "x": -13,
      "y": 11,
      "z": -4,
      "name": "OrbisGalactic_Block_Jawa_Crawler_Hull"
    },
    {
      "x": -13,
      "y": 12,
      "z": -4,
      "name": "OrbisGalactic_Block_Jawa_Crawler_Hull"
    },
    {
      "x": -13,
      "y": 13,
      "z": -4,
      "name": "OrbisGalactic_Block_Jawa_Crawler_Hull"
    },
    {
      "x": -13,
      "y": 14,
      "z": -4,
      "name": "OrbisGalactic_Block_Jawa_Crawler_Hull"
    },
    {
      "x": -13,
      "y": 15,
      "z": -4,
      "name": "OrbisGalactic_Block_Jawa_Crawler_Hull"
    },
    {
      "x": -13,
      "y": 16,
      "z": -4,
      "name": "OrbisGalactic_Block_Jawa_Crawler_Hull"
    },
    {
      "x": -13,
      "y": 17,
      "z": -4,
      "name": "OrbisGalactic_Block_Jawa_Crawler_Hull"
    },
    {
      "x": -13,
      "y": 18,
      "z": -4,
      "name": "OrbisGalactic_Block_Jawa_Crawler_Hull"
    },
    {
      "x": -13,
      "y": 19,
      "z": -4,
      "name": "OrbisGalactic_Block_Jawa_Crawler_Hull"
    },
    {
      "x": -13,
      "y": 20,
      "z": -4,
      "name": "OrbisGalactic_Block_Jawa_Crawler_Hull"
    },
    {
      "x": -13,
      "y": 21,
      "z": -4,
      "name": "OrbisGalactic_Block_Jawa_Crawler_Hull"
    },
    {
      "x": -13,
      "y": 22,
      "z": -4,
      "name": "OrbisGalactic_Block_Jawa_Crawler_Hull"
    },
    {
      "x": -13,
      "y": 23,
      "z": -4,
      "name": "OrbisGalactic_Block_Jawa_Crawler_Hull"
    },
    {
      "x": -13,
      "y": 24,
      "z": -4,
      "name": "OrbisGalactic_Block_Jawa_Crawler_Hull"
    },
    {
      "x": -13,
      "y": 8,
      "z": -3,
      "name": "OrbisGalactic_Block_Jawa_Crawler_Hull"
    },
    {
      "x": -13,
      "y": 9,
      "z": -3,
      "name": "OrbisGalactic_Block_Jawa_Crawler_Hull"
    },
    {
      "x": -13,
      "y": 10,
      "z": -3,
      "name": "OrbisGalactic_Block_Jawa_Crawler_Hull"
    },
    {
      "x": -13,
      "y": 11,
      "z": -3,
      "name": "OrbisGalactic_Block_Jawa_Crawler_Hull"
    },
    {
      "x": -13,
      "y": 12,
      "z": -3,
      "name": "OrbisGalactic_Block_Jawa_Crawler_Hull"
    },
    {
      "x": -13,
      "y": 13,
      "z": -3,
      "name": "OrbisGalactic_Block_Jawa_Crawler_Hull"
    },
    {
      "x": -13,
      "y": 14,
      "z": -3,
      "name": "OrbisGalactic_Block_Jawa_Crawler_Hull"
    },
    {
      "x": -13,
      "y": 15,
      "z": -3,
      "name": "OrbisGalactic_Block_Jawa_Crawler_Hull"
    },
    {
      "x": -13,
      "y": 16,
      "z": -3,
      "name": "OrbisGalactic_Block_Jawa_Crawler_Hull"
    },
    {
      "x": -13,
      "y": 17,
      "z": -3,
      "name": "OrbisGalactic_Block_Jawa_Crawler_Hull"
    },
    {
      "x": -13,
      "y": 18,
      "z": -3,
      "name": "OrbisGalactic_Block_Jawa_Crawler_Hull"
    },
    {
      "x": -13,
      "y": 19,
      "z": -3,
      "name": "OrbisGalactic_Block_Jawa_Crawler_Hull"
    },
    {
      "x": -13,
      "y": 20,
      "z": -3,
      "name": "OrbisGalactic_Block_Jawa_Crawler_Hull"
    },
    {
      "x": -13,
      "y": 21,
      "z": -3,
      "name": "OrbisGalactic_Block_Jawa_Crawler_Hull"
    },
    {
      "x": -13,
      "y": 22,
      "z": -3,
      "name": "OrbisGalactic_Block_Jawa_Crawler_Hull"
    },
    {
      "x": -13,
      "y": 23,
      "z": -3,
      "name": "OrbisGalactic_Block_Jawa_Crawler_Hull"
    },
    {
      "x": -13,
      "y": 24,
      "z": -3,
      "name": "OrbisGalactic_Block_Jawa_Crawler_Hull"
    },
    {
      "x": -13,
      "y": 8,
      "z": -2,
      "name": "OrbisGalactic_Block_Jawa_Crawler_Hull"
    },
    {
      "x": -13,
      "y": 9,
      "z": -2,
      "name": "OrbisGalactic_Block_Jawa_Crawler_Hull"
    },
    {
      "x": -13,
      "y": 10,
      "z": -2,
      "name": "OrbisGalactic_Block_Jawa_Crawler_Hull"
    },
    {
      "x": -13,
      "y": 11,
      "z": -2,
      "name": "OrbisGalactic_Block_Jawa_Crawler_Hull"
    },
    {
      "x": -13,
      "y": 12,
      "z": -2,
      "name": "OrbisGalactic_Block_Jawa_Crawler_Hull"
    },
    {
      "x": -13,
      "y": 13,
      "z": -2,
      "name": "OrbisGalactic_Block_Jawa_Crawler_Hull"
    },
    {
      "x": -13,
      "y": 14,
      "z": -2,
      "name": "OrbisGalactic_Block_Jawa_Crawler_Hull"
    },
    {
      "x": -13,
      "y": 15,
      "z": -2,
      "name": "OrbisGalactic_Block_Jawa_Crawler_Hull"
    },
    {
      "x": -13,
      "y": 16,
      "z": -2,
      "name": "OrbisGalactic_Block_Jawa_Crawler_Hull"
    },
    {
      "x": -13,
      "y": 17,
      "z": -2,
      "name": "OrbisGalactic_Block_Jawa_Crawler_Hull"
    },
    {
      "x": -13,
      "y": 18,
      "z": -2,
      "name": "OrbisGalactic_Block_Jawa_Crawler_Hull"
    },
    {
      "x": -13,
      "y": 19,
      "z": -2,
      "name": "OrbisGalactic_Block_Jawa_Crawler_Hull"
    },
    {
      "x": -13,
      "y": 20,
      "z": -2,
      "name": "OrbisGalactic_Block_Jawa_Crawler_Hull"
    },
    {
      "x": -13,
      "y": 21,
      "z": -2,
      "name": "OrbisGalactic_Block_Jawa_Crawler_Hull"
    },
    {
      "x": -13,
      "y": 22,
      "z": -2,
      "name": "OrbisGalactic_Block_Jawa_Crawler_Hull"
    },
    {
      "x": -13,
      "y": 23,
      "z": -2,
      "name": "OrbisGalactic_Block_Jawa_Crawler_Hull"
    },
    {
      "x": -13,
      "y": 24,
      "z": -2,
      "name": "OrbisGalactic_Block_Jawa_Crawler_Hull"
    },
    {
      "x": -13,
      "y": 8,
      "z": -1,
      "name": "OrbisGalactic_Block_Jawa_Crawler_Hull"
    },
    {
      "x": -13,
      "y": 9,
      "z": -1,
      "name": "OrbisGalactic_Block_Jawa_Crawler_Hull"
    },
    {
      "x": -13,
      "y": 10,
      "z": -1,
      "name": "OrbisGalactic_Block_Jawa_Crawler_Hull"
    },
    {
      "x": -13,
      "y": 11,
      "z": -1,
      "name": "OrbisGalactic_Block_Jawa_Crawler_Hull"
    },
    {
      "x": -13,
      "y": 12,
      "z": -1,
      "name": "OrbisGalactic_Block_Jawa_Crawler_Hull"
    },
    {
      "x": -13,
      "y": 13,
      "z": -1,
      "name": "OrbisGalactic_Block_Jawa_Crawler_Hull"
    },
    {
      "x": -13,
      "y": 14,
      "z": -1,
      "name": "OrbisGalactic_Block_Jawa_Crawler_Hull"
    },
    {
      "x": -13,
      "y": 15,
      "z": -1,
      "name": "OrbisGalactic_Block_Jawa_Crawler_Hull"
    },
    {
      "x": -13,
      "y": 16,
      "z": -1,
      "name": "OrbisGalactic_Block_Jawa_Crawler_Hull"
    },
    {
      "x": -13,
      "y": 17,
      "z": -1,
      "name": "OrbisGalactic_Block_Jawa_Crawler_Hull"
    },
    {
      "x": -13,
      "y": 18,
      "z": -1,
      "name": "OrbisGalactic_Block_Jawa_Crawler_Hull"
    },
    {
      "x": -13,
      "y": 19,
      "z": -1,
      "name": "OrbisGalactic_Block_Jawa_Crawler_Hull"
    },
    {
      "x": -13,
      "y": 20,
      "z": -1,
      "name": "OrbisGalactic_Block_Jawa_Crawler_Hull"
    },
    {
      "x": -13,
      "y": 21,
      "z": -1,
      "name": "OrbisGalactic_Block_Jawa_Crawler_Hull"
    },
    {
      "x": -13,
      "y": 22,
      "z": -1,
      "name": "OrbisGalactic_Block_Jawa_Crawler_Hull"
    },
    {
      "x": -13,
      "y": 23,
      "z": -1,
      "name": "OrbisGalactic_Block_Jawa_Crawler_Hull"
    },
    {
      "x": -13,
      "y": 24,
      "z": -1,
      "name": "OrbisGalactic_Block_Jawa_Crawler_Hull"
    },
    {
      "x": -13,
      "y": 8,
      "z": 0,
      "name": "OrbisGalactic_Block_Jawa_Crawler_Hull"
    },
    {
      "x": -13,
      "y": 9,
      "z": 0,
      "name": "OrbisGalactic_Block_Jawa_Crawler_Hull"
    },
    {
      "x": -13,
      "y": 10,
      "z": 0,
      "name": "OrbisGalactic_Block_Jawa_Crawler_Hull"
    },
    {
      "x": -13,
      "y": 11,
      "z": 0,
      "name": "OrbisGalactic_Block_Jawa_Crawler_Hull"
    },
    {
      "x": -13,
      "y": 12,
      "z": 0,
      "name": "OrbisGalactic_Block_Jawa_Crawler_Hull"
    },
    {
      "x": -13,
      "y": 13,
      "z": 0,
      "name": "OrbisGalactic_Block_Jawa_Crawler_Hull"
    },
    {
      "x": -13,
      "y": 14,
      "z": 0,
      "name": "OrbisGalactic_Block_Jawa_Crawler_Hull"
    },
    {
      "x": -13,
      "y": 15,
      "z": 0,
      "name": "OrbisGalactic_Block_Jawa_Crawler_Hull"
    },
    {
      "x": -13,
      "y": 16,
      "z": 0,
      "name": "OrbisGalactic_Block_Jawa_Crawler_Hull"
    },
    {
      "x": -13,
      "y": 17,
      "z": 0,
      "name": "OrbisGalactic_Block_Jawa_Crawler_Hull"
    },
    {
      "x": -13,
      "y": 18,
      "z": 0,
      "name": "OrbisGalactic_Block_Jawa_Crawler_Hull"
    },
    {
      "x": -13,
      "y": 19,
      "z": 0,
      "name": "OrbisGalactic_Block_Jawa_Crawler_Hull"
    },
    {
      "x": -13,
      "y": 20,
      "z": 0,
      "name": "OrbisGalactic_Block_Jawa_Crawler_Hull"
    },
    {
      "x": -13,
      "y": 21,
      "z": 0,
      "name": "Rock_Sandstone_Red_Brick_Stairs",
      "rotation": 1
    },
    {
      "x": -13,
      "y": 24,
      "z": 0,
      "name": "OrbisGalactic_Block_Jawa_Crawler_Hull"
    },
    {
      "x": -13,
      "y": 8,
      "z": 1,
      "name": "OrbisGalactic_Block_Jawa_Crawler_Hull"
    },
    {
      "x": -13,
      "y": 9,
      "z": 1,
      "name": "OrbisGalactic_Block_Jawa_Crawler_Hull"
    },
    {
      "x": -13,
      "y": 10,
      "z": 1,
      "name": "OrbisGalactic_Block_Jawa_Crawler_Hull"
    },
    {
      "x": -13,
      "y": 11,
      "z": 1,
      "name": "OrbisGalactic_Block_Jawa_Crawler_Hull"
    },
    {
      "x": -13,
      "y": 12,
      "z": 1,
      "name": "OrbisGalactic_Block_Jawa_Crawler_Hull"
    },
    {
      "x": -13,
      "y": 13,
      "z": 1,
      "name": "OrbisGalactic_Block_Jawa_Crawler_Hull"
    },
    {
      "x": -13,
      "y": 14,
      "z": 1,
      "name": "OrbisGalactic_Block_Jawa_Crawler_Hull"
    },
    {
      "x": -13,
      "y": 15,
      "z": 1,
      "name": "OrbisGalactic_Block_Jawa_Crawler_Hull"
    },
    {
      "x": -13,
      "y": 16,
      "z": 1,
      "name": "OrbisGalactic_Block_Jawa_Crawler_Hull"
    },
    {
      "x": -13,
      "y": 17,
      "z": 1,
      "name": "OrbisGalactic_Block_Jawa_Crawler_Hull"
    },
    {
      "x": -13,
      "y": 18,
      "z": 1,
      "name": "OrbisGalactic_Block_Jawa_Crawler_Hull"
    },
    {
      "x": -13,
      "y": 19,
      "z": 1,
      "name": "OrbisGalactic_Block_Jawa_Crawler_Hull"
    },
    {
      "x": -13,
      "y": 20,
      "z": 1,
      "name": "OrbisGalactic_Block_Jawa_Crawler_Hull"
    },
    {
      "x": -13,
      "y": 21,
      "z": 1,
      "name": "Rock_Sandstone_Red_Brick_Stairs",
      "rotation": 1
    },
    {
      "x": -13,
      "y": 24,
      "z": 1,
      "name": "OrbisGalactic_Block_Jawa_Crawler_Hull"
    },
    {
      "x": -13,
      "y": 8,
      "z": 2,
      "name": "OrbisGalactic_Block_Jawa_Crawler_Hull",
      "rotation": 10
    },
    {
      "x": -13,
      "y": 9,
      "z": 2,
      "name": "OrbisGalactic_Block_Jawa_Crawler_Hull",
      "rotation": 10
    },
    {
      "x": -13,
      "y": 10,
      "z": 2,
      "name": "OrbisGalactic_Block_Jawa_Crawler_Hull"
    },
    {
      "x": -13,
      "y": 11,
      "z": 2,
      "name": "OrbisGalactic_Block_Jawa_Crawler_Hull"
    },
    {
      "x": -13,
      "y": 12,
      "z": 2,
      "name": "OrbisGalactic_Block_Jawa_Crawler_Hull"
    },
    {
      "x": -13,
      "y": 13,
      "z": 2,
      "name": "OrbisGalactic_Block_Jawa_Crawler_Hull"
    },
    {
      "x": -13,
      "y": 14,
      "z": 2,
      "name": "OrbisGalactic_Block_Jawa_Crawler_Hull"
    },
    {
      "x": -13,
      "y": 15,
      "z": 2,
      "name": "OrbisGalactic_Block_Jawa_Crawler_Hull"
    },
    {
      "x": -13,
      "y": 16,
      "z": 2,
      "name": "OrbisGalactic_Block_Jawa_Crawler_Hull"
    },
    {
      "x": -13,
      "y": 17,
      "z": 2,
      "name": "OrbisGalactic_Block_Jawa_Crawler_Hull"
    },
    {
      "x": -13,
      "y": 18,
      "z": 2,
      "name": "OrbisGalactic_Block_Jawa_Crawler_Hull"
    },
    {
      "x": -13,
      "y": 19,
      "z": 2,
      "name": "OrbisGalactic_Block_Jawa_Crawler_Hull"
    },
    {
      "x": -13,
      "y": 20,
      "z": 2,
      "name": "OrbisGalactic_Block_Jawa_Crawler_Hull"
    },
    {
      "x": -13,
      "y": 21,
      "z": 2,
      "name": "OrbisGalactic_Block_Jawa_Crawler_Hull"
    },
    {
      "x": -13,
      "y": 22,
      "z": 2,
      "name": "OrbisGalactic_Block_Jawa_Crawler_Hull"
    },
    {
      "x": -13,
      "y": 23,
      "z": 2,
      "name": "OrbisGalactic_Block_Jawa_Crawler_Hull"
    },
    {
      "x": -13,
      "y": 24,
      "z": 2,
      "name": "OrbisGalactic_Block_Jawa_Crawler_Hull",
      "rotation": 10
    },
    {
      "x": -13,
      "y": 8,
      "z": 3,
      "name": "OrbisGalactic_Block_Jawa_Crawler_Hull",
      "rotation": 10
    },
    {
      "x": -13,
      "y": 9,
      "z": 3,
      "name": "OrbisGalactic_Block_Jawa_Crawler_Hull",
      "rotation": 10
    },
    {
      "x": -13,
      "y": 10,
      "z": 3,
      "name": "OrbisGalactic_Block_Jawa_Crawler_Hull"
    },
    {
      "x": -13,
      "y": 11,
      "z": 3,
      "name": "OrbisGalactic_Block_Jawa_Crawler_Hull"
    },
    {
      "x": -13,
      "y": 12,
      "z": 3,
      "name": "OrbisGalactic_Block_Jawa_Crawler_Hull"
    },
    {
      "x": -13,
      "y": 13,
      "z": 3,
      "name": "OrbisGalactic_Block_Jawa_Crawler_Hull"
    },
    {
      "x": -13,
      "y": 14,
      "z": 3,
      "name": "OrbisGalactic_Block_Jawa_Crawler_Hull"
    },
    {
      "x": -13,
      "y": 15,
      "z": 3,
      "name": "OrbisGalactic_Block_Jawa_Crawler_Hull"
    },
    {
      "x": -13,
      "y": 16,
      "z": 3,
      "name": "OrbisGalactic_Block_Jawa_Crawler_Hull"
    },
    {
      "x": -13,
      "y": 17,
      "z": 3,
      "name": "OrbisGalactic_Block_Jawa_Crawler_Hull"
    },
    {
      "x": -13,
      "y": 18,
      "z": 3,
      "name": "OrbisGalactic_Block_Jawa_Crawler_Hull"
    },
    {
      "x": -13,
      "y": 19,
      "z": 3,
      "name": "OrbisGalactic_Block_Jawa_Crawler_Hull"
    },
    {
      "x": -13,
      "y": 20,
      "z": 3,
      "name": "OrbisGalactic_Block_Jawa_Crawler_Hull"
    },
    {
      "x": -13,
      "y": 21,
      "z": 3,
      "name": "OrbisGalactic_Block_Jawa_Crawler_Hull"
    },
    {
      "x": -13,
      "y": 22,
      "z": 3,
      "name": "OrbisGalactic_Block_Jawa_Crawler_Hull"
    },
    {
      "x": -13,
      "y": 23,
      "z": 3,
      "name": "OrbisGalactic_Block_Jawa_Crawler_Hull"
    },
    {
      "x": -13,
      "y": 24,
      "z": 3,
      "name": "OrbisGalactic_Block_Jawa_Crawler_Hull",
      "rotation": 10
    },
    {
      "x": -13,
      "y": 8,
      "z": 4,
      "name": "OrbisGalactic_Block_Jawa_Crawler_Hull",
      "rotation": 10
    },
    {
      "x": -13,
      "y": 9,
      "z": 4,
      "name": "OrbisGalactic_Block_Jawa_Crawler_Hull",
      "rotation": 10
    },
    {
      "x": -13,
      "y": 10,
      "z": 4,
      "name": "OrbisGalactic_Block_Jawa_Crawler_Hull"
    },
    {
      "x": -13,
      "y": 11,
      "z": 4,
      "name": "OrbisGalactic_Block_Jawa_Crawler_Hull"
    },
    {
      "x": -13,
      "y": 12,
      "z": 4,
      "name": "OrbisGalactic_Block_Jawa_Crawler_Hull"
    },
    {
      "x": -13,
      "y": 13,
      "z": 4,
      "name": "OrbisGalactic_Block_Jawa_Crawler_Hull"
    },
    {
      "x": -13,
      "y": 14,
      "z": 4,
      "name": "OrbisGalactic_Block_Jawa_Crawler_Hull"
    },
    {
      "x": -13,
      "y": 15,
      "z": 4,
      "name": "OrbisGalactic_Block_Jawa_Crawler_Hull"
    },
    {
      "x": -13,
      "y": 16,
      "z": 4,
      "name": "OrbisGalactic_Block_Jawa_Crawler_Hull"
    },
    {
      "x": -13,
      "y": 17,
      "z": 4,
      "name": "OrbisGalactic_Block_Jawa_Crawler_Hull"
    },
    {
      "x": -13,
      "y": 18,
      "z": 4,
      "name": "OrbisGalactic_Block_Jawa_Crawler_Hull"
    },
    {
      "x": -13,
      "y": 19,
      "z": 4,
      "name": "OrbisGalactic_Block_Jawa_Crawler_Hull"
    },
    {
      "x": -13,
      "y": 20,
      "z": 4,
      "name": "OrbisGalactic_Block_Jawa_Crawler_Hull"
    },
    {
      "x": -13,
      "y": 21,
      "z": 4,
      "name": "OrbisGalactic_Block_Jawa_Crawler_Hull"
    },
    {
      "x": -13,
      "y": 22,
      "z": 4,
      "name": "OrbisGalactic_Block_Jawa_Crawler_Hull"
    },
    {
      "x": -13,
      "y": 23,
      "z": 4,
      "name": "OrbisGalactic_Block_Jawa_Crawler_Hull"
    },
    {
      "x": -13,
      "y": 24,
      "z": 4,
      "name": "OrbisGalactic_Block_Jawa_Crawler_Hull",
      "rotation": 10
    },
    {
      "x": -13,
      "y": 8,
      "z": 5,
      "name": "OrbisGalactic_Block_Jawa_Crawler_Hull",
      "rotation": 10
    },
    {
      "x": -13,
      "y": 9,
      "z": 5,
      "name": "OrbisGalactic_Block_Jawa_Crawler_Hull",
      "rotation": 10
    },
    {
      "x": -13,
      "y": 10,
      "z": 5,
      "name": "OrbisGalactic_Block_Jawa_Crawler_Hull"
    },
    {
      "x": -13,
      "y": 11,
      "z": 5,
      "name": "OrbisGalactic_Block_Jawa_Crawler_Hull"
    },
    {
      "x": -13,
      "y": 12,
      "z": 5,
      "name": "OrbisGalactic_Block_Jawa_Crawler_Hull"
    },
    {
      "x": -13,
      "y": 13,
      "z": 5,
      "name": "OrbisGalactic_Block_Jawa_Crawler_Hull"
    },
    {
      "x": -13,
      "y": 14,
      "z": 5,
      "name": "OrbisGalactic_Block_Jawa_Crawler_Hull"
    },
    {
      "x": -13,
      "y": 15,
      "z": 5,
      "name": "OrbisGalactic_Block_Jawa_Crawler_Hull"
    },
    {
      "x": -13,
      "y": 16,
      "z": 5,
      "name": "OrbisGalactic_Block_Jawa_Crawler_Hull"
    },
    {
      "x": -13,
      "y": 17,
      "z": 5,
      "name": "OrbisGalactic_Block_Jawa_Crawler_Hull"
    },
    {
      "x": -13,
      "y": 18,
      "z": 5,
      "name": "OrbisGalactic_Block_Jawa_Crawler_Hull"
    },
    {
      "x": -13,
      "y": 19,
      "z": 5,
      "name": "OrbisGalactic_Block_Jawa_Crawler_Hull"
    },
    {
      "x": -13,
      "y": 20,
      "z": 5,
      "name": "OrbisGalactic_Block_Jawa_Crawler_Hull"
    },
    {
      "x": -13,
      "y": 21,
      "z": 5,
      "name": "OrbisGalactic_Block_Jawa_Crawler_Hull"
    },
    {
      "x": -13,
      "y": 22,
      "z": 5,
      "name": "OrbisGalactic_Block_Jawa_Crawler_Hull"
    },
    {
      "x": -13,
      "y": 23,
      "z": 5,
      "name": "OrbisGalactic_Block_Jawa_Crawler_Hull"
    },
    {
      "x": -13,
      "y": 24,
      "z": 5,
      "name": "OrbisGalactic_Block_Jawa_Crawler_Hull",
      "rotation": 10
    },
    {
      "x": -13,
      "y": 8,
      "z": 6,
      "name": "OrbisGalactic_Block_Jawa_Crawler_Hull",
      "rotation": 10
    },
    {
      "x": -13,
      "y": 9,
      "z": 6,
      "name": "OrbisGalactic_Block_Jawa_Crawler_Hull",
      "rotation": 10
    },
    {
      "x": -13,
      "y": 10,
      "z": 6,
      "name": "OrbisGalactic_Block_Jawa_Crawler_Hull"
    },
    {
      "x": -13,
      "y": 11,
      "z": 6,
      "name": "OrbisGalactic_Block_Jawa_Crawler_Hull"
    },
    {
      "x": -13,
      "y": 12,
      "z": 6,
      "name": "OrbisGalactic_Block_Jawa_Crawler_Hull"
    },
    {
      "x": -13,
      "y": 13,
      "z": 6,
      "name": "OrbisGalactic_Block_Jawa_Crawler_Hull"
    },
    {
      "x": -13,
      "y": 14,
      "z": 6,
      "name": "OrbisGalactic_Block_Jawa_Crawler_Hull"
    },
    {
      "x": -13,
      "y": 15,
      "z": 6,
      "name": "OrbisGalactic_Block_Jawa_Crawler_Hull"
    },
    {
      "x": -13,
      "y": 16,
      "z": 6,
      "name": "OrbisGalactic_Block_Jawa_Crawler_Hull"
    },
    {
      "x": -13,
      "y": 17,
      "z": 6,
      "name": "OrbisGalactic_Block_Jawa_Crawler_Hull"
    },
    {
      "x": -13,
      "y": 18,
      "z": 6,
      "name": "*OrbisGalactic_Block_Jawa_Lamp1_State_Definitions_On",
      "rotation": 2
    },
    {
      "x": -13,
      "y": 19,
      "z": 6,
      "name": "OrbisGalactic_Block_Jawa_Crawler_Hull"
    },
    {
      "x": -13,
      "y": 20,
      "z": 6,
      "name": "OrbisGalactic_Block_Jawa_Crawler_Hull"
    },
    {
      "x": -13,
      "y": 21,
      "z": 6,
      "name": "OrbisGalactic_Block_Jawa_Crawler_Hull"
    },
    {
      "x": -13,
      "y": 22,
      "z": 6,
      "name": "OrbisGalactic_Block_Jawa_Crawler_Hull"
    },
    {
      "x": -13,
      "y": 23,
      "z": 6,
      "name": "OrbisGalactic_Block_Jawa_Crawler_Hull"
    },
    {
      "x": -13,
      "y": 24,
      "z": 6,
      "name": "OrbisGalactic_Block_Jawa_Crawler_Hull",
      "rotation": 10
    },
    {
      "x": -13,
      "y": 8,
      "z": 7,
      "name": "OrbisGalactic_Block_Jawa_Crawler_Hull",
      "rotation": 10
    },
    {
      "x": -13,
      "y": 9,
      "z": 7,
      "name": "OrbisGalactic_Block_Jawa_Crawler_Hull",
      "rotation": 10
    },
    {
      "x": -13,
      "y": 10,
      "z": 7,
      "name": "OrbisGalactic_Block_Jawa_Crawler_Hull",
      "rotation": 10
    },
    {
      "x": -13,
      "y": 11,
      "z": 7,
      "name": "OrbisGalactic_Block_Jawa_Crawler_Hull",
      "rotation": 10
    },
    {
      "x": -13,
      "y": 12,
      "z": 7,
      "name": "OrbisGalactic_Block_Jawa_Crawler_Hull",
      "rotation": 10
    },
    {
      "x": -13,
      "y": 13,
      "z": 7,
      "name": "OrbisGalactic_Block_Jawa_Crawler_Hull",
      "rotation": 10
    },
    {
      "x": -13,
      "y": 14,
      "z": 7,
      "name": "OrbisGalactic_Block_Jawa_Crawler_Hull",
      "rotation": 10
    },
    {
      "x": -13,
      "y": 15,
      "z": 7,
      "name": "OrbisGalactic_Block_Jawa_Crawler_Hull",
      "rotation": 10
    },
    {
      "x": -13,
      "y": 16,
      "z": 7,
      "name": "OrbisGalactic_Block_Jawa_Crawler_Hull",
      "rotation": 10
    },
    {
      "x": -13,
      "y": 17,
      "z": 7,
      "name": "OrbisGalactic_Block_Jawa_Crawler_Hull",
      "rotation": 10
    },
    {
      "x": -13,
      "y": 18,
      "z": 7,
      "name": "*OrbisGalactic_Block_Jawa_Lamp1_State_Definitions_On",
      "rotation": 2
    },
    {
      "x": -13,
      "y": 19,
      "z": 7,
      "name": "OrbisGalactic_Block_Jawa_Crawler_Hull",
      "rotation": 10
    },
    {
      "x": -13,
      "y": 20,
      "z": 7,
      "name": "OrbisGalactic_Block_Jawa_Crawler_Hull",
      "rotation": 10
    },
    {
      "x": -13,
      "y": 21,
      "z": 7,
      "name": "OrbisGalactic_Block_Jawa_Crawler_Hull",
      "rotation": 10
    },
    {
      "x": -13,
      "y": 22,
      "z": 7,
      "name": "OrbisGalactic_Block_Jawa_Crawler_Hull",
      "rotation": 10
    },
    {
      "x": -13,
      "y": 23,
      "z": 7,
      "name": "OrbisGalactic_Block_Jawa_Crawler_Hull",
      "rotation": 10
    },
    {
      "x": -13,
      "y": 24,
      "z": 7,
      "name": "OrbisGalactic_Block_Jawa_Crawler_Hull",
      "rotation": 10
    },
    {
      "x": -13,
      "y": 8,
      "z": 8,
      "name": "OrbisGalactic_Block_Jawa_Crawler_Hull"
    },
    {
      "x": -13,
      "y": 9,
      "z": 8,
      "name": "OrbisGalactic_Block_Jawa_Crawler_Hull"
    },
    {
      "x": -13,
      "y": 10,
      "z": 8,
      "name": "OrbisGalactic_Block_Jawa_Crawler_Hull"
    },
    {
      "x": -13,
      "y": 11,
      "z": 8,
      "name": "OrbisGalactic_Block_Jawa_Crawler_Hull"
    },
    {
      "x": -13,
      "y": 12,
      "z": 8,
      "name": "OrbisGalactic_Block_Jawa_Crawler_Hull",
      "rotation": 10
    },
    {
      "x": -13,
      "y": 13,
      "z": 8,
      "name": "OrbisGalactic_Block_Jawa_Crawler_Hull",
      "rotation": 10
    },
    {
      "x": -13,
      "y": 14,
      "z": 8,
      "name": "OrbisGalactic_Block_Jawa_Crawler_Hull",
      "rotation": 10
    },
    {
      "x": -13,
      "y": 15,
      "z": 8,
      "name": "OrbisGalactic_Block_Jawa_Crawler_Hull",
      "rotation": 10
    },
    {
      "x": -13,
      "y": 16,
      "z": 8,
      "name": "OrbisGalactic_Block_Jawa_Crawler_Hull",
      "rotation": 10
    },
    {
      "x": -13,
      "y": 17,
      "z": 8,
      "name": "OrbisGalactic_Block_Jawa_Crawler_Hull",
      "rotation": 10
    },
    {
      "x": -13,
      "y": 18,
      "z": 8,
      "name": "OrbisGalactic_Block_Jawa_Crawler_Hull",
      "rotation": 10
    },
    {
      "x": -13,
      "y": 19,
      "z": 8,
      "name": "OrbisGalactic_Block_Jawa_Crawler_Hull",
      "rotation": 10
    },
    {
      "x": -13,
      "y": 20,
      "z": 8,
      "name": "OrbisGalactic_Block_Jawa_Crawler_Hull",
      "rotation": 10
    },
    {
      "x": -13,
      "y": 21,
      "z": 8,
      "name": "OrbisGalactic_Block_Jawa_Crawler_Hull",
      "rotation": 10
    },
    {
      "x": -13,
      "y": 22,
      "z": 8,
      "name": "OrbisGalactic_Block_Jawa_Crawler_Hull",
      "rotation": 10
    },
    {
      "x": -13,
      "y": 23,
      "z": 8,
      "name": "OrbisGalactic_Block_Jawa_Crawler_Hull",
      "rotation": 10
    },
    {
      "x": -13,
      "y": 24,
      "z": 8,
      "name": "OrbisGalactic_Block_Jawa_Crawler_Hull",
      "rotation": 10
    },
    {
      "x": -12,
      "y": 7,
      "z": -7,
      "name": "OrbisGalactic_Block_Jawa_Crawler_Hull"
    },
    {
      "x": -12,
      "y": 8,
      "z": -7,
      "name": "OrbisGalactic_Block_Jawa_Crawler_Hull"
    },
    {
      "x": -12,
      "y": 9,
      "z": -7,
      "name": "OrbisGalactic_Block_Jawa_Crawler_Hull"
    },
    {
      "x": -12,
      "y": 10,
      "z": -7,
      "name": "OrbisGalactic_Block_Jawa_Crawler_Hull"
    },
    {
      "x": -12,
      "y": 11,
      "z": -7,
      "name": "OrbisGalactic_Block_Jawa_Crawler_Hull"
    },
    {
      "x": -12,
      "y": 12,
      "z": -7,
      "name": "OrbisGalactic_Block_Jawa_Crawler_Hull"
    },
    {
      "x": -12,
      "y": 13,
      "z": -7,
      "name": "OrbisGalactic_Block_Jawa_Crawler_Hull"
    },
    {
      "x": -12,
      "y": 14,
      "z": -7,
      "name": "OrbisGalactic_Block_Jawa_Crawler_Hull"
    },
    {
      "x": -12,
      "y": 15,
      "z": -7,
      "name": "OrbisGalactic_Block_Jawa_Crawler_Hull"
    },
    {
      "x": -12,
      "y": 16,
      "z": -7,
      "name": "OrbisGalactic_Block_Jawa_Crawler_Hull"
    },
    {
      "x": -12,
      "y": 17,
      "z": -7,
      "name": "OrbisGalactic_Block_Jawa_Crawler_Hull"
    },
    {
      "x": -12,
      "y": 18,
      "z": -7,
      "name": "OrbisGalactic_Block_Jawa_Crawler_Hull"
    },
    {
      "x": -12,
      "y": 19,
      "z": -7,
      "name": "OrbisGalactic_Block_Jawa_Crawler_Hull"
    },
    {
      "x": -12,
      "y": 20,
