{
  "version": 8,
  "blockIdVersion": 11,
  "anchorX": 0,
  "anchorY": 0,
  "anchorZ": 0,
  "blocks": [
    {
      "x": -11,
      "y": -9,
      "z": -2,
      "name": "Rock_Sandstone_Red"
    },
    {
      "x": -11,
      "y": -7,
      "z": -2,
      "name": "Rock_Sandstone_Red_Cobble"
    },
    {
      "x": -11,
      "y": -9,
      "z": -1,
      "name": "Rock_Sandstone_Red_Cobble"
    },
    {
      "x": -11,
      "y": -7,
      "z": -1,
      "name": "Rock_Sandstone_Red_Cobble"
    },
    {
      "x": -11,
      "y": -9,
      "z": 0,
      "name": "Rock_Sandstone_Red"
    },
    {
      "x": -11,
      "y": -7,
      "z": 0,
      "name": "Rock_Sandstone_Red_Cobble"
    },
    {
      "x": -10,
      "y": -9,
      "z": -3,
      "name": "Rock_Sandstone_Red"
    },
    {
      "x": -10,
      "y": -8,
      "z": -3,
      "name": "Rock_Sandstone_Red_Cobble"
    },
    {
      "x": -10,
      "y": -7,
      "z": -3,
      "name": "Rock_Sandstone_Red_Cobble"
    },
    {
      "x": -10,
      "y": -6,
      "z": -3,
      "name": "Soil_Clay_Smooth_Red"
    },
    {
      "x": -10,
      "y": -5,
      "z": -3,
      "name": "Rock_Sandstone_Red_Cobble"
    },
    {
      "x": -10,
      "y": -9,
      "z": -2,
      "name": "Rock_Sandstone_Red_Cobble"
    },
    {
      "x": -10,
      "y": -8,
      "z": -2,
      "name": "Rock_Sandstone_Red_Cobble"
    },
    {
      "x": -10,
      "y": -7,
      "z": -2,
      "name": "Rock_Sandstone_Red"
    },
    {
      "x": -10,
      "y": -6,
      "z": -2,
      "name": "Soil_Clay_Smooth_Red"
    },
    {
      "x": -10,
      "y": -5,
      "z": -2,
      "name": "Rock_Sandstone_Red_Cobble"
    },
    {
      "x": -10,
      "y": -4,
      "z": -2,
      "name": "Rock_Sandstone_Red_Cobble"
    },
    {
      "x": -10,
      "y": -10,
      "z": -1,
      "name": "Rock_Sandstone_Red_Cobble"
    },
    {
      "x": -10,
      "y": -9,
      "z": -1,
      "name": "Soil_Clay_Smooth_Red"
    },
    {
      "x": -10,
      "y": -8,
      "z": -1,
      "name": "Rock_Sandstone_Red_Cobble"
    },
    {
      "x": -10,
      "y": -7,
      "z": -1,
      "name": "Rock_Sandstone_Red_Cobble"
    },
    {
      "x": -10,
      "y": -6,
      "z": -1,
      "name": "Rock_Sandstone_Red"
    },
    {
      "x": -10,
      "y": -5,
      "z": -1,
      "name": "Rock_Sandstone_Red"
    },
    {
      "x": -10,
      "y": -4,
      "z": -1,
      "name": "Soil_Clay_Smooth_Red"
    },
    {
      "x": -10,
      "y": -9,
      "z": 0,
      "name": "Rock_Sandstone_Red"
    },
    {
      "x": -10,
      "y": -8,
      "z": 0,
      "name": "Rock_Sandstone_Red_Cobble"
    },
    {
      "x": -10,
      "y": -7,
      "z": 0,
      "name": "Rock_Sandstone_Red_Cobble"
    },
    {
      "x": -10,
      "y": -6,
      "z": 0,
      "name": "Rock_Sandstone_Red"
    },
    {
      "x": -10,
      "y": -5,
      "z": 0,
      "name": "Rock_Sandstone_Red_Cobble"
    },
    {
      "x": -10,
      "y": -4,
      "z": 0,
      "name": "Rock_Sandstone_Red"
    },
    {
      "x": -10,
      "y": -9,
      "z": 1,
      "name": "Rock_Sandstone_Red_Cobble"
    },
    {
      "x": -10,
      "y": -8,
      "z": 1,
      "name": "Rock_Sandstone_Red"
    },
    {
      "x": -10,
      "y": -7,
      "z": 1,
      "name": "Rock_Sandstone_Red_Cobble"
    },
    {
      "x": -10,
      "y": -6,
      "z": 1,
      "name": "Rock_Sandstone_Red"
    },
    {
      "x": -10,
      "y": -5,
      "z": 1,
      "name": "Soil_Clay_Smooth_Red"
    },
    {
      "x": -10,
      "y": -4,
      "z": 1,
      "name": "Rock_Sandstone_Red_Cobble"
    },
    {
      "x": -10,
      "y": -6,
      "z": 2,
      "name": "Rock_Sandstone_Red"
    },
    {
      "x": -10,
      "y": -5,
      "z": 2,
      "name": "Soil_Clay_Smooth_Red"
    },
    {
      "x": -10,
      "y": -9,
      "z": 8,
      "name": "Soil_Clay_Smooth_Red"
    },
    {
      "x": -10,
      "y": -7,
      "z": 8,
      "name": "Soil_Clay_Smooth_Red"
    },
    {
      "x": -10,
      "y": -6,
      "z": 8,
      "name": "Rock_Sandstone_Red"
    },
    {
      "x": -10,
      "y": -9,
      "z": 9,
      "name": "Soil_Clay_Smooth_Red"
    },
    {
      "x": -10,
      "y": -7,
      "z": 9,
      "name": "Soil_Clay_Smooth_Red"
    },
    {
      "x": -10,
      "y": -6,
      "z": 9,
      "name": "Rock_Sandstone_Red"
    },
    {
      "x": -9,
      "y": -9,
      "z": -4,
      "name": "Rock_Sandstone_Red_Cobble"
    },
    {
      "x": -9,
      "y": -8,
      "z": -4,
      "name": "Rock_Sandstone_Red_Cobble"
    },
    {
      "x": -9,
      "y": -7,
      "z": -4,
      "name": "Rock_Sandstone_Red"
    },
    {
      "x": -9,
      "y": -6,
      "z": -4,
      "name": "Soil_Clay_Smooth_Red"
    },
    {
      "x": -9,
      "y": -5,
      "z": -4,
      "name": "Rock_Sandstone_Red_Cobble"
    },
    {
      "x": -9,
      "y": -4,
      "z": -4,
      "name": "Rock_Sandstone_Red_Cobble"
    },
    {
      "x": -9,
      "y": -9,
      "z": -3,
      "name": "Soil_Clay_Smooth_Red"
    },
    {
      "x": -9,
      "y": -8,
      "z": -3,
      "name": "Soil_Clay_Smooth_Red"
    },
    {
      "x": -9,
      "y": -7,
      "z": -3,
      "name": "Soil_Clay_Smooth_Red"
    },
    {
      "x": -9,
      "y": -6,
      "z": -3,
      "name": "Rock_Sandstone_Red_Cobble"
    },
    {
      "x": -9,
      "y": -5,
      "z": -3,
      "name": "Soil_Clay_Smooth_Red"
    },
    {
      "x": -9,
      "y": -4,
      "z": -3,
      "name": "Rock_Sandstone_Red_Cobble"
    },
    {
      "x": -9,
      "y": -3,
      "z": -3,
      "name": "Soil_Clay_Smooth_Red"
    },
    {
      "x": -9,
      "y": -10,
      "z": -2,
      "name": "Rock_Sandstone_Red_Cobble"
    },
    {
      "x": -9,
      "y": -9,
      "z": -2,
      "name": "Rock_Sandstone_Red"
    },
    {
      "x": -9,
      "y": -8,
      "z": -2,
      "name": "Rock_Sandstone_Red_Cobble"
    },
    {
      "x": -9,
      "y": -7,
      "z": -2,
      "name": "Rock_Sandstone_Red_Cobble"
    },
    {
      "x": -9,
      "y": -6,
      "z": -2,
      "name": "Soil_Clay_Smooth_Red"
    },
    {
      "x": -9,
      "y": -5,
      "z": -2,
      "name": "Rock_Sandstone_Red"
    },
    {
      "x": -9,
      "y": -4,
      "z": -2,
      "name": "Rock_Sandstone_Red_Cobble"
    },
    {
      "x": -9,
      "y": -3,
      "z": -2,
      "name": "Rock_Sandstone_Red_Cobble"
    },
    {
      "x": -9,
      "y": -10,
      "z": -1,
      "name": "Rock_Sandstone_Red_Cobble"
    },
    {
      "x": -9,
      "y": -9,
      "z": -1,
      "name": "Rock_Sandstone_Red_Cobble"
    },
    {
      "x": -9,
      "y": -8,
      "z": -1,
      "name": "Rock_Sandstone_Red_Cobble"
    },
    {
      "x": -9,
      "y": -7,
      "z": -1,
      "name": "Rock_Sandstone_Red"
    },
    {
      "x": -9,
      "y": -6,
      "z": -1,
      "name": "Soil_Clay_Smooth_Red"
    },
    {
      "x": -9,
      "y": -5,
      "z": -1,
      "name": "Soil_Clay_Smooth_Red"
    },
    {
      "x": -9,
      "y": -4,
      "z": -1,
      "name": "Rock_Sandstone_Red"
    },
    {
      "x": -9,
      "y": -3,
      "z": -1,
      "name": "Rock_Sandstone_Red_Cobble"
    },
    {
      "x": -9,
      "y": -2,
      "z": -1,
      "name": "Rock_Sandstone_Red"
    },
    {
      "x": -9,
      "y": -10,
      "z": 0,
      "name": "Rock_Sandstone_Red_Cobble"
    },
    {
      "x": -9,
      "y": -9,
      "z": 0,
      "name": "Rock_Sandstone_Red"
    },
    {
      "x": -9,
      "y": -8,
      "z": 0,
      "name": "Rock_Sandstone_Red_Cobble"
    },
    {
      "x": -9,
      "y": -7,
      "z": 0,
      "name": "Rock_Sandstone_Red"
    },
    {
      "x": -9,
      "y": -6,
      "z": 0,
      "name": "Soil_Clay_Smooth_Red"
    },
    {
      "x": -9,
      "y": -5,
      "z": 0,
      "name": "Rock_Sandstone_Red"
    },
    {
      "x": -9,
      "y": -4,
      "z": 0,
      "name": "Soil_Clay_Smooth_Red"
    },
    {
      "x": -9,
      "y": -3,
      "z": 0,
      "name": "Soil_Clay_Smooth_Red"
    },
    {
      "x": -9,
      "y": -2,
      "z": 0,
      "name": "Rock_Sandstone_Red_Cobble"
    },
    {
      "x": -9,
      "y": -9,
      "z": 1,
      "name": "Rock_Sandstone_Red"
    },
    {
      "x": -9,
      "y": -8,
      "z": 1,
      "name": "Soil_Clay_Smooth_Red"
    },
    {
      "x": -9,
      "y": -7,
      "z": 1,
      "name": "Soil_Clay_Smooth_Red"
    },
    {
      "x": -9,
      "y": -6,
      "z": 1,
      "name": "Soil_Clay_Smooth_Red"
    },
    {
      "x": -9,
      "y": -5,
      "z": 1,
      "name": "Rock_Sandstone_Red"
    },
    {
      "x": -9,
      "y": -4,
      "z": 1,
      "name": "Rock_Sandstone_Red"
    },
    {
      "x": -9,
      "y": -3,
      "z": 1,
      "name": "Rock_Sandstone_Red"
    },
    {
      "x": -9,
      "y": -2,
      "z": 1,
      "name": "Rock_Sandstone_Red"
    },
    {
      "x": -9,
      "y": -9,
      "z": 2,
      "name": "Rock_Sandstone_Red_Cobble"
    },
    {
      "x": -9,
      "y": -8,
      "z": 2,
      "name": "Rock_Sandstone_Red_Cobble"
    },
    {
      "x": -9,
      "y": -7,
      "z": 2,
      "name": "Soil_Clay_Smooth_Red"
    },
    {
      "x": -9,
      "y": -6,
      "z": 2,
      "name": "Rock_Sandstone_Red"
    },
    {
      "x": -9,
      "y": -5,
      "z": 2,
      "name": "Rock_Sandstone_Red_Cobble"
    },
    {
      "x": -9,
      "y": -4,
      "z": 2,
      "name": "Rock_Sandstone_Red_Cobble"
    },
    {
      "x": -9,
      "y": -3,
      "z": 2,
      "name": "Rock_Sandstone_Red_Cobble"
    },
    {
      "x": -9,
      "y": -7,
      "z": 3,
      "name": "Rock_Sandstone_Red"
    },
    {
      "x": -9,
      "y": -6,
      "z": 3,
      "name": "Rock_Sandstone_Red_Cobble"
    },
    {
      "x": -9,
      "y": -5,
      "z": 3,
      "name": "Rock_Sandstone_Red_Cobble"
    },
    {
      "x": -9,
      "y": -4,
      "z": 3,
      "name": "Rock_Sandstone_Red"
    },
    {
      "x": -9,
      "y": -3,
      "z": 3,
      "name": "Soil_Clay_Smooth_Red"
    },
    {
      "x": -9,
      "y": 3,
      "z": 3,
      "name": "Rock_Sandstone"
    },
    {
      "x": -9,
      "y": 4,
      "z": 3,
      "name": "Rock_Sandstone"
    },
    {
      "x": -9,
      "y": 5,
      "z": 3,
      "name": "Soil_Clay"
    },
    {
      "x": -9,
      "y": -6,
      "z": 4,
      "name": "Rock_Sandstone_Red_Cobble"
    },
    {
      "x": -9,
      "y": -5,
      "z": 4,
      "name": "Rock_Sandstone_Red_Cobble"
    },
    {
      "x": -9,
      "y": -4,
      "z": 4,
      "name": "Rock_Sandstone_Red_Cobble"
    },
    {
      "x": -9,
      "y": 3,
      "z": 4,
      "name": "Rock_Sandstone"
    },
    {
      "x": -9,
      "y": 4,
      "z": 4,
      "name": "Rock_Sandstone"
    },
    {
      "x": -9,
      "y": 5,
      "z": 4,
      "name": "Rock_Sandstone"
    },
    {
      "x": -9,
      "y": -7,
      "z": 5,
      "name": "Rock_Sandstone_Red_Cobble"
    },
    {
      "x": -9,
      "y": -6,
      "z": 5,
      "name": "Rock_Sandstone_Red_Cobble"
    },
    {
      "x": -9,
      "y": -5,
      "z": 5,
      "name": "Rock_Sandstone_Red_Cobble"
    },
    {
      "x": -9,
      "y": -4,
      "z": 5,
      "name": "Rock_Sandstone_Red_Cobble"
    },
    {
      "x": -9,
      "y": 2,
      "z": 5,
      "name": "Rock_Sandstone"
    },
    {
      "x": -9,
      "y": 3,
      "z": 5,
      "name": "Rock_Sandstone"
    },
    {
      "x": -9,
      "y": 4,
      "z": 5,
      "name": "Rock_Sandstone"
    },
    {
      "x": -9,
      "y": 5,
      "z": 5,
      "name": "Rock_Sandstone"
    },
    {
      "x": -9,
      "y": 6,
      "z": 5,
      "name": "Rock_Sandstone"
    },
    {
      "x": -9,
      "y": -9,
      "z": 6,
      "name": "Soil_Clay_Smooth_Red"
    },
    {
      "x": -9,
      "y": -7,
      "z": 6,
      "name": "Rock_Sandstone_Red_Cobble"
    },
    {
      "x": -9,
      "y": -6,
      "z": 6,
      "name": "Rock_Sandstone_Red"
    },
    {
      "x": -9,
      "y": -5,
      "z": 6,
      "name": "Soil_Clay_Smooth_Red"
    },
    {
      "x": -9,
      "y": -4,
      "z": 6,
      "name": "Rock_Sandstone_Red_Cobble"
    },
    {
      "x": -9,
      "y": -3,
      "z": 6,
      "name": "Rock_Sandstone_Red_Cobble"
    },
    {
      "x": -9,
      "y": 2,
      "z": 6,
      "name": "Soil_Clay"
    },
    {
      "x": -9,
      "y": 3,
      "z": 6,
      "name": "Soil_Clay"
    },
    {
      "x": -9,
      "y": 4,
      "z": 6,
      "name": "Rock_Sandstone"
    },
    {
      "x": -9,
      "y": 5,
      "z": 6,
      "name": "Rock_Sandstone"
    },
    {
      "x": -9,
      "y": 6,
      "z": 6,
      "name": "Rock_Sandstone"
    },
    {
      "x": -9,
      "y": -9,
      "z": 7,
      "name": "Rock_Sandstone_Red_Cobble"
    },
    {
      "x": -9,
      "y": -8,
      "z": 7,
      "name": "Rock_Sandstone_Red_Cobble"
    },
    {
      "x": -9,
      "y": -7,
      "z": 7,
      "name": "Rock_Sandstone_Red"
    },
    {
      "x": -9,
      "y": -6,
      "z": 7,
      "name": "Rock_Sandstone_Red_Cobble"
    },
    {
      "x": -9,
      "y": -5,
      "z": 7,
      "name": "Soil_Clay_Smooth_Red"
    },
    {
      "x": -9,
      "y": -4,
      "z": 7,
      "name": "Rock_Sandstone_Red"
    },
    {
      "x": -9,
      "y": -3,
      "z": 7,
      "name": "Rock_Sandstone_Red"
    },
    {
      "x": -9,
      "y": -2,
      "z": 7,
      "name": "Soil_Clay_Smooth_Red"
    },
    {
      "x": -9,
      "y": 3,
      "z": 7,
      "name": "Rock_Sandstone"
    },
    {
      "x": -9,
      "y": 4,
      "z": 7,
      "name": "Rock_Sandstone"
    },
    {
      "x": -9,
      "y": 5,
      "z": 7,
      "name": "Rock_Sandstone"
    },
    {
      "x": -9,
      "y": -9,
      "z": 8,
      "name": "Rock_Sandstone_Red_Cobble"
    },
    {
      "x": -9,
      "y": -8,
      "z": 8,
      "name": "Rock_Sandstone_Red_Cobble"
    },
    {
      "x": -9,
      "y": -7,
      "z": 8,
      "name": "Rock_Sandstone_Red"
    },
    {
      "x": -9,
      "y": -6,
      "z": 8,
      "name": "Soil_Clay_Smooth_Red"
    },
    {
      "x": -9,
      "y": -5,
      "z": 8,
      "name": "Rock_Sandstone_Red_Cobble"
    },
    {
      "x": -9,
      "y": -4,
      "z": 8,
      "name": "Rock_Sandstone_Red_Cobble"
    },
    {
      "x": -9,
      "y": -3,
      "z": 8,
      "name": "Rock_Sandstone_Red"
    },
    {
      "x": -9,
      "y": -2,
      "z": 8,
      "name": "Rock_Sandstone_Red"
    },
    {
      "x": -9,
      "y": -10,
      "z": 9,
      "name": "Rock_Sandstone_Red_Cobble"
    },
    {
      "x": -9,
      "y": -9,
      "z": 9,
      "name": "Rock_Sandstone_Red"
    },
    {
      "x": -9,
      "y": -8,
      "z": 9,
      "name": "Rock_Sandstone_Red"
    },
    {
      "x": -9,
      "y": -7,
      "z": 9,
      "name": "Soil_Clay_Smooth_Red"
    },
    {
      "x": -9,
      "y": -6,
      "z": 9,
      "name": "Soil_Clay_Smooth_Red"
    },
    {
      "x": -9,
      "y": -5,
      "z": 9,
      "name": "Soil_Clay_Smooth_Red"
    },
    {
      "x": -9,
      "y": -4,
      "z": 9,
      "name": "Rock_Sandstone_Red_Cobble"
    },
    {
      "x": -9,
      "y": -3,
      "z": 9,
      "name": "Soil_Clay_Smooth_Red"
    },
    {
      "x": -9,
      "y": -9,
      "z": 10,
      "name": "Rock_Sandstone_Red_Cobble"
    },
    {
      "x": -9,
      "y": -8,
      "z": 10,
      "name": "Rock_Sandstone_Red"
    },
    {
      "x": -9,
      "y": -7,
      "z": 10,
      "name": "Soil_Clay_Smooth_Red"
    },
    {
      "x": -9,
      "y": -6,
      "z": 10,
      "name": "Soil_Clay_Smooth_Red"
    },
    {
      "x": -9,
      "y": -5,
      "z": 10,
      "name": "Rock_Sandstone_Red"
    },
    {
      "x": -9,
      "y": -4,
      "z": 10,
      "name": "Soil_Clay_Smooth_Red"
    },
    {
      "x": -9,
      "y": -9,
      "z": 11,
      "name": "Soil_Clay_Smooth_Red"
    },
    {
      "x": -8,
      "y": -7,
      "z": -5,
      "name": "Rock_Sandstone_Red_Cobble"
    },
    {
      "x": -8,
      "y": -6,
      "z": -5,
      "name": "Soil_Clay_Smooth_Red"
    },
    {
      "x": -8,
      "y": -5,
      "z": -5,
      "name": "Rock_Sandstone_Red"
    },
    {
      "x": -8,
      "y": -4,
      "z": -5,
      "name": "Rock_Sandstone_Red"
    },
    {
      "x": -8,
      "y": -9,
      "z": -4,
      "name": "Rock_Sandstone_Red"
    },
    {
      "x": -8,
      "y": -8,
      "z": -4,
      "name": "Rock_Sandstone_Red_Cobble"
    },
    {
      "x": -8,
      "y": -7,
      "z": -4,
      "name": "Soil_Clay_Smooth_Red"
    },
    {
      "x": -8,
      "y": -6,
      "z": -4,
      "name": "Rock_Sandstone_Red_Cobble"
    },
    {
      "x": -8,
      "y": -5,
      "z": -4,
      "name": "Rock_Sandstone_Red"
    },
    {
      "x": -8,
      "y": -4,
      "z": -4,
      "name": "Soil_Clay_Smooth_Red"
    },
    {
      "x": -8,
      "y": -3,
      "z": -4,
      "name": "Rock_Sandstone_Red_Cobble"
    },
    {
      "x": -8,
      "y": -10,
      "z": -3,
      "name": "Soil_Clay_Smooth_Red"
    },
    {
      "x": -8,
      "y": -9,
      "z": -3,
      "name": "Soil_Clay_Smooth_Red"
    },
    {
      "x": -8,
      "y": -8,
      "z": -3,
      "name": "Rock_Sandstone_Red"
    },
    {
      "x": -8,
      "y": -7,
      "z": -3,
      "name": "Soil_Clay_Smooth_Red"
    },
    {
      "x": -8,
      "y": -6,
      "z": -3,
      "name": "Rock_Sandstone_Red"
    },
    {
      "x": -8,
      "y": -5,
      "z": -3,
      "name": "Rock_Sandstone_Red_Cobble"
    },
    {
      "x": -8,
      "y": -4,
      "z": -3,
      "name": "Rock_Sandstone_Red"
    },
    {
      "x": -8,
      "y": -3,
      "z": -3,
      "name": "Rock_Sandstone_Red_Cobble"
    },
    {
      "x": -8,
      "y": -2,
      "z": -3,
      "name": "Rock_Sandstone_Red_Cobble"
    },
    {
      "x": -8,
      "y": -10,
      "z": -2,
      "name": "Rock_Sandstone_Red_Cobble"
    },
    {
      "x": -8,
      "y": -9,
      "z": -2,
      "name": "Rock_Sandstone_Red_Cobble"
    },
    {
      "x": -8,
      "y": -8,
      "z": -2,
      "name": "Rock_Sandstone_Red"
    },
    {
      "x": -8,
      "y": -7,
      "z": -2,
      "name": "Soil_Clay_Smooth_Red"
    },
    {
      "x": -8,
      "y": -6,
      "z": -2,
      "name": "Rock_Sandstone_Red"
    },
    {
      "x": -8,
      "y": -5,
      "z": -2,
      "name": "Rock_Sandstone_Red_Cobble"
    },
    {
      "x": -8,
      "y": -4,
      "z": -2,
      "name": "Soil_Clay_Smooth_Red"
    },
    {
      "x": -8,
      "y": -3,
      "z": -2,
      "name": "Rock_Sandstone_Red_Cobble"
    },
    {
      "x": -8,
      "y": -2,
      "z": -2,
      "name": "Rock_Sandstone_Red"
    },
    {
      "x": -8,
      "y": -10,
      "z": -1,
      "name": "Rock_Sandstone_Red_Cobble"
    },
    {
      "x": -8,
      "y": -9,
      "z": -1,
      "name": "Soil_Clay_Smooth_Red"
    },
    {
      "x": -8,
      "y": -8,
      "z": -1,
      "name": "Soil_Clay_Smooth_Red"
    },
    {
      "x": -8,
      "y": -7,
      "z": -1,
      "name": "Rock_Sandstone_Red"
    },
    {
      "x": -8,
      "y": -6,
      "z": -1,
      "name": "Soil_Clay_Smooth_Red"
    },
    {
      "x": -8,
      "y": -5,
      "z": -1,
      "name": "Rock_Sandstone_Red"
    },
    {
      "x": -8,
      "y": -4,
      "z": -1,
      "name": "Rock_Sandstone_Red_Cobble"
    },
    {
      "x": -8,
      "y": -3,
      "z": -1,
      "name": "Rock_Sandstone_Red"
    },
    {
      "x": -8,
      "y": -2,
      "z": -1,
      "name": "Rock_Sandstone_Red_Cobble"
    },
    {
      "x": -8,
      "y": -1,
      "z": -1,
      "name": "Soil_Clay_Smooth_Red"
    },
    {
      "x": -8,
      "y": -10,
      "z": 0,
      "name": "Rock_Sandstone_Red"
    },
    {
      "x": -8,
      "y": -9,
      "z": 0,
      "name": "Rock_Sandstone_Red_Cobble"
    },
    {
      "x": -8,
      "y": -8,
      "z": 0,
      "name": "Rock_Sandstone_Red_Cobble"
    },
    {
      "x": -8,
      "y": -7,
      "z": 0,
      "name": "Rock_Sandstone_Red_Cobble"
    },
    {
      "x": -8,
      "y": -6,
      "z": 0,
      "name": "Rock_Sandstone_Red"
    },
    {
      "x": -8,
      "y": -5,
      "z": 0,
      "name": "Rock_Sandstone_Red"
    },
    {
      "x": -8,
      "y": -4,
      "z": 0,
      "name": "Soil_Clay_Smooth_Red"
    },
    {
      "x": -8,
      "y": -3,
      "z": 0,
      "name": "Rock_Sandstone_Red"
    },
    {
      "x": -8,
      "y": -2,
      "z": 0,
      "name": "Rock_Sandstone_Red_Cobble"
    },
    {
      "x": -8,
      "y": -1,
      "z": 0,
      "name": "Rock_Sandstone_Red"
    },
    {
      "x": -8,
      "y": -10,
      "z": 1,
      "name": "Rock_Sandstone_Red_Cobble"
    },
    {
      "x": -8,
      "y": -9,
      "z": 1,
      "name": "Soil_Clay_Smooth_Red"
    },
    {
      "x": -8,
      "y": -8,
      "z": 1,
      "name": "Rock_Sandstone_Red_Cobble"
    },
    {
      "x": -8,
      "y": -7,
      "z": 1,
      "name": "Soil_Clay_Smooth_Red"
    },
    {
      "x": -8,
      "y": -6,
      "z": 1,
      "name": "Rock_Sandstone_Red"
    },
    {
      "x": -8,
      "y": -5,
      "z": 1,
      "name": "Rock_Sandstone_Red"
    },
    {
      "x": -8,
      "y": -4,
      "z": 1,
      "name": "Soil_Clay_Smooth_Red"
    },
    {
      "x": -8,
      "y": -3,
      "z": 1,
      "name": "Rock_Sandstone_Red"
    },
    {
      "x": -8,
      "y": -2,
      "z": 1,
      "name": "Rock_Sandstone_Red_Cobble"
    },
    {
      "x": -8,
      "y": -1,
      "z": 1,
      "name": "Rock_Sandstone_Red_Cobble"
    },
    {
      "x": -8,
      "y": 3,
      "z": 1,
      "name": "Soil_Clay"
    },
    {
      "x": -8,
      "y": 4,
      "z": 1,
      "name": "Rock_Sandstone"
    },
    {
      "x": -8,
      "y": -9,
      "z": 2,
      "name": "Soil_Clay_Smooth_Red"
    },
    {
      "x": -8,
      "y": -8,
      "z": 2,
      "name": "Rock_Sandstone_Red"
    },
    {
      "x": -8,
      "y": -7,
      "z": 2,
      "name": "Soil_Clay_Smooth_Red"
    },
    {
      "x": -8,
      "y": -6,
      "z": 2,
      "name": "Rock_Sandstone_Red_Cobble"
    },
    {
      "x": -8,
      "y": -5,
      "z": 2,
      "name": "Rock_Sandstone_Red"
    },
    {
      "x": -8,
      "y": -4,
      "z": 2,
      "name": "Soil_Clay_Smooth_Red"
    },
    {
      "x": -8,
      "y": -3,
      "z": 2,
      "name": "Rock_Sandstone_Red_Cobble"
    },
    {
      "x": -8,
      "y": -2,
      "z": 2,
      "name": "Rock_Sandstone_Red"
    },
    {
      "x": -8,
      "y": -1,
      "z": 2,
      "name": "Soil_Clay_Smooth_Red"
    },
    {
      "x": -8,
      "y": 2,
      "z": 2,
      "name": "Rock_Sandstone"
    },
    {
      "x": -8,
      "y": 3,
      "z": 2,
      "name": "Rock_Sandstone"
    },
    {
      "x": -8,
      "y": 4,
      "z": 2,
      "name": "Rock_Sandstone"
    },
    {
      "x": -8,
      "y": 5,
      "z": 2,
      "name": "Rock_Sandstone"
    },
    {
      "x": -8,
      "y": 6,
      "z": 2,
      "name": "Soil_Clay"
    },
    {
      "x": -8,
      "y": -8,
      "z": 3,
      "name": "Rock_Sandstone_Red_Cobble"
    },
    {
      "x": -8,
      "y": -7,
      "z": 3,
      "name": "Rock_Sandstone_Red"
    },
    {
      "x": -8,
      "y": -6,
      "z": 3,
      "name": "Rock_Sandstone_Red_Cobble"
    },
    {
      "x": -8,
      "y": -5,
      "z": 3,
      "name": "Soil_Clay_Smooth_Red"
    },
    {
      "x": -8,
      "y": -4,
      "z": 3,
      "name": "Rock_Sandstone_Red_Cobble"
    },
    {
      "x": -8,
      "y": -3,
      "z": 3,
      "name": "Rock_Sandstone_Red"
    },
    {
      "x": -8,
      "y": -2,
      "z": 3,
      "name": "Soil_Clay_Smooth_Red"
    },
    {
      "x": -8,
      "y": 0,
      "z": 3,
      "name": "Rock_Sandstone"
    },
    {
      "x": -8,
      "y": 1,
      "z": 3,
      "name": "Rock_Sandstone"
    },
    {
      "x": -8,
      "y": 2,
      "z": 3,
      "name": "Rock_Sandstone"
    },
    {
      "x": -8,
      "y": 3,
      "z": 3,
      "name": "Rock_Sandstone"
    },
    {
      "x": -8,
      "y": 4,
      "z": 3,
      "name": "Rock_Sandstone"
    },
    {
      "x": -8,
      "y": 5,
      "z": 3,
      "name": "Rock_Sandstone"
    },
    {
      "x": -8,
      "y": 6,
      "z": 3,
      "name": "Rock_Sandstone"
    },
    {
      "x": -8,
      "y": -7,
      "z": 4,
      "name": "Soil_Clay_Smooth_Red"
    },
    {
      "x": -8,
      "y": -6,
      "z": 4,
      "name": "Soil_Clay_Smooth_Red"
    },
    {
      "x": -8,
      "y": -5,
      "z": 4,
      "name": "Rock_Sandstone_Red"
    },
    {
      "x": -8,
      "y": -4,
      "z": 4,
      "name": "Soil_Clay_Smooth_Red"
    },
    {
      "x": -8,
      "y": -3,
      "z": 4,
      "name": "Rock_Sandstone_Red"
    },
    {
      "x": -8,
      "y": 0,
      "z": 4,
      "name": "Rock_Sandstone"
    },
    {
      "x": -8,
      "y": 1,
      "z": 4,
      "name": "Rock_Sandstone"
    },
    {
      "x": -8,
      "y": 2,
      "z": 4,
      "name": "Rock_Sandstone"
    },
    {
      "x": -8,
      "y": 3,
      "z": 4,
      "name": "Rock_Sandstone"
    },
    {
      "x": -8,
      "y": 4,
      "z": 4,
      "name": "Rock_Sandstone"
    },
    {
      "x": -8,
      "y": 5,
      "z": 4,
      "name": "Rock_Sandstone"
    },
    {
      "x": -8,
      "y": 6,
      "z": 4,
      "name": "Rock_Sandstone"
    },
    {
      "x": -8,
      "y": 7,
      "z": 4,
      "name": "Rock_Sandstone"
    },
    {
      "x": -8,
      "y": -8,
      "z": 5,
      "name": "Soil_Clay_Smooth_Red"
    },
    {
      "x": -8,
      "y": -7,
      "z": 5,
      "name": "Rock_Sandstone_Red_Cobble"
    },
    {
      "x": -8,
      "y": -6,
      "z": 5,
      "name": "Rock_Sandstone_Red_Cobble"
    },
    {
      "x": -8,
      "y": -5,
      "z": 5,
      "name": "Rock_Sandstone_Red_Cobble"
    },
    {
      "x": -8,
      "y": -4,
      "z": 5,
      "name": "Soil_Clay_Smooth_Red"
    },
    {
      "x": -8,
      "y": -3,
      "z": 5,
      "name": "Rock_Sandstone_Red"
    },
    {
      "x": -8,
      "y": -2,
      "z": 5,
      "name": "Soil_Clay_Smooth_Red"
    },
    {
      "x": -8,
      "y": 0,
      "z": 5,
      "name": "Rock_Sandstone"
    },
    {
      "x": -8,
      "y": 1,
      "z": 5,
      "name": "Rock_Sandstone"
    },
    {
      "x": -8,
      "y": 2,
      "z": 5,
      "name": "Rock_Sandstone"
    },
    {
      "x": -8,
      "y": 3,
      "z": 5,
      "name": "Rock_Sandstone"
    },
    {
      "x": -8,
      "y": 4,
      "z": 5,
      "name": "Rock_Sandstone"
    },
    {
      "x": -8,
      "y": 5,
      "z": 5,
      "name": "Rock_Sandstone"
    },
    {
      "x": -8,
      "y": 6,
      "z": 5,
      "name": "Rock_Sandstone"
    },
    {
      "x": -8,
      "y": 7,
      "z": 5,
      "name": "Rock_Sandstone"
    },
    {
      "x": -8,
      "y": -9,
      "z": 6,
      "name": "Soil_Clay_Smooth_Red"
    },
    {
      "x": -8,
      "y": -8,
      "z": 6,
      "name": "Rock_Sandstone_Red"
    },
    {
      "x": -8,
      "y": -7,
      "z": 6,
      "name": "Soil_Clay_Smooth_Red"
    },
    {
      "x": -8,
      "y": -6,
      "z": 6,
      "name": "Rock_Sandstone_Red"
    },
    {
      "x": -8,
      "y": -5,
      "z": 6,
      "name": "Rock_Sandstone_Red"
    },
    {
      "x": -8,
      "y": -4,
      "z": 6,
      "name": "Rock_Sandstone_Red_Cobble"
    },
    {
      "x": -8,
      "y": -3,
      "z": 6,
      "name": "Rock_Sandstone_Red"
    },
    {
      "x": -8,
      "y": -2,
      "z": 6,
      "name": "Rock_Sandstone_Red"
    },
    {
      "x": -8,
      "y": -1,
      "z": 6,
      "name": "Rock_Sandstone_Red_Cobble"
    },
    {
      "x": -8,
      "y": 0,
      "z": 6,
      "name": "Rock_Sandstone"
    },
    {
      "x": -8,
      "y": 1,
      "z": 6,
      "name": "Rock_Sandstone"
    },
    {
      "x": -8,
      "y": 2,
      "z": 6,
      "name": "Rock_Sandstone"
    },
    {
      "x": -8,
      "y": 3,
      "z": 6,
      "name": "Rock_Sandstone"
    },
    {
      "x": -8,
      "y": 4,
      "z": 6,
      "name": "Rock_Sandstone"
    },
    {
      "x": -8,
      "y": 5,
      "z": 6,
      "name": "Rock_Sandstone"
    },
    {
      "x": -8,
      "y": 6,
      "z": 6,
      "name": "Rock_Sandstone"
    },
    {
      "x": -8,
      "y": 7,
      "z": 6,
      "name": "Rock_Sandstone"
    },
    {
      "x": -8,
      "y": -9,
      "z": 7,
      "name": "Rock_Sandstone_Red_Cobble"
    },
    {
      "x": -8,
      "y": -8,
      "z": 7,
      "name": "Rock_Sandstone_Red"
    },
    {
      "x": -8,
      "y": -7,
      "z": 7,
      "name": "Rock_Sandstone_Red_Cobble"
    },
    {
      "x": -8,
      "y": -6,
      "z": 7,
      "name": "Soil_Clay_Smooth_Red"
    },
    {
      "x": -8,
      "y": -5,
      "z": 7,
      "name": "Rock_Sandstone_Red"
    },
    {
      "x": -8,
      "y": -4,
      "z": 7,
      "name": "Soil_Clay_Smooth_Red"
    },
    {
      "x": -8,
      "y": -3,
      "z": 7,
      "name": "Soil_Clay_Smooth_Red"
    },
    {
      "x": -8,
      "y": -2,
      "z": 7,
      "name": "Rock_Sandstone_Red"
    },
    {
      "x": -8,
      "y": -1,
      "z": 7,
      "name": "Soil_Clay_Smooth_Red"
    },
    {
      "x": -8,
      "y": 0,
      "z": 7,
      "name": "Soil_Clay"
    },
    {
      "x": -8,
      "y": 1,
      "z": 7,
      "name": "Soil_Clay"
    },
    {
      "x": -8,
      "y": 2,
      "z": 7,
      "name": "Rock_Sandstone"
    },
    {
      "x": -8,
      "y": 3,
      "z": 7,
      "name": "Rock_Sandstone"
    },
    {
      "x": -8,
      "y": 4,
      "z": 7,
      "name": "Rock_Sandstone"
    },
    {
      "x": -8,
      "y": 5,
      "z": 7,
      "name": "Rock_Sandstone"
    },
    {
      "x": -8,
      "y": 6,
      "z": 7,
      "name": "Rock_Sandstone"
    },
    {
      "x": -8,
      "y": -10,
      "z": 8,
      "name": "Rock_Sandstone_Red"
    },
    {
      "x": -8,
      "y": -9,
      "z": 8,
      "name": "Rock_Sandstone_Red_Cobble"
    },
    {
      "x": -8,
      "y": -8,
      "z": 8,
      "name": "Soil_Clay_Smooth_Red"
    },
    {
      "x": -8,
      "y": -7,
      "z": 8,
      "name": "Rock_Sandstone_Red"
    },
    {
      "x": -8,
      "y": -6,
      "z": 8,
      "name": "Rock_Sandstone_Red_Cobble"
    },
    {
      "x": -8,
      "y": -5,
      "z": 8,
      "name": "Soil_Clay_Smooth_Red"
    },
    {
      "x": -8,
      "y": -4,
      "z": 8,
      "name": "Rock_Sandstone_Red"
    },
    {
      "x": -8,
      "y": -3,
      "z": 8,
      "name": "Soil_Clay_Smooth_Red"
    },
    {
      "x": -8,
      "y": -2,
      "z": 8,
      "name": "Rock_Sandstone_Red_Cobble"
    },
    {
      "x": -8,
      "y": -1,
      "z": 8,
      "name": "Soil_Clay_Smooth_Red"
    },
    {
      "x": -8,
      "y": 0,
      "z": 8,
      "name": "Soil_Clay_Smooth_Red"
    },
    {
      "x": -8,
      "y": 1,
      "z": 8,
      "name": "Soil_Clay"
    },
    {
      "x": -8,
      "y": 2,
      "z": 8,
      "name": "Soil_Clay"
    },
    {
      "x": -8,
      "y": 3,
      "z": 8,
      "name": "Rock_Sandstone"
    },
    {
      "x": -8,
      "y": 4,
      "z": 8,
      "name": "Rock_Sandstone"
    },
    {
      "x": -8,
      "y": 5,
      "z": 8,
      "name": "Rock_Sandstone"
    },
    {
      "x": -8,
      "y": 6,
      "z": 8,
      "name": "Soil_Clay"
    },
    {
      "x": -8,
      "y": -10,
      "z": 9,
      "name": "Rock_Sandstone_Red"
    },
    {
      "x": -8,
      "y": -9,
      "z": 9,
      "name": "Soil_Clay_Smooth_Red"
    },
    {
      "x": -8,
      "y": -8,
      "z": 9,
      "name": "Soil_Clay_Smooth_Red"
    },
    {
      "x": -8,
      "y": -7,
      "z": 9,
      "name": "Rock_Sandstone_Red_Cobble"
    },
    {
      "x": -8,
      "y": -6,
      "z": 9,
      "name": "Rock_Sandstone_Red"
    },
    {
      "x": -8,
      "y": -5,
      "z": 9,
      "name": "Rock_Sandstone_Red_Cobble"
    },
    {
      "x": -8,
      "y": -4,
      "z": 9,
      "name": "Rock_Sandstone_Red_Cobble"
    },
    {
      "x": -8,
      "y": -3,
      "z": 9,
      "name": "Soil_Clay_Smooth_Red"
    },
    {
      "x": -8,
      "y": -2,
      "z": 9,
      "name": "Rock_Sandstone_Red"
    },
    {
      "x": -8,
      "y": -1,
      "z": 9,
      "name": "Soil_Clay_Smooth_Red"
    },
    {
      "x": -8,
      "y": -10,
      "z": 10,
      "name": "Rock_Sandstone_Red_Cobble"
    },
    {
      "x": -8,
      "y": -9,
      "z": 10,
      "name": "Soil_Clay_Smooth_Red"
    },
    {
      "x": -8,
      "y": -8,
      "z": 10,
      "name": "Rock_Sandstone_Red_Cobble"
    },
    {
      "x": -8,
      "y": -7,
      "z": 10,
      "name": "Rock_Sandstone_Red_Cobble"
    },
    {
      "x": -8,
      "y": -6,
      "z": 10,
      "name": "Soil_Clay_Smooth_Red"
    },
    {
      "x": -8,
      "y": -5,
      "z": 10,
      "name": "Soil_Clay_Smooth_Red"
    },
    {
      "x": -8,
      "y": -4,
      "z": 10,
      "name": "Rock_Sandstone_Red_Cobble"
    },
    {
      "x": -8,
      "y": -3,
      "z": 10,
      "name": "Soil_Clay_Smooth_Red"
    },
    {
      "x": -8,
      "y": -2,
      "z": 10,
      "name": "Rock_Sandstone_Red"
    },
    {
      "x": -8,
      "y": -9,
      "z": 11,
      "name": "Rock_Sandstone_Red"
    },
    {
      "x": -8,
      "y": -8,
      "z": 11,
      "name": "Rock_Sandstone_Red_Cobble"
    },
    {
      "x": -8,
      "y": -7,
      "z": 11,
      "name": "Rock_Sandstone_Red_Cobble"
    },
    {
      "x": -8,
      "y": -6,
      "z": 11,
      "name": "Soil_Clay_Smooth_Red"
    },
    {
      "x": -8,
      "y": -5,
      "z": 11,
      "name": "Rock_Sandstone_Red"
    },
    {
      "x": -8,
      "y": -4,
      "z": 11,
      "name": "Rock_Sandstone_Red"
    },
    {
      "x": -8,
      "y": -9,
      "z": 12,
      "name": "Rock_Sandstone_Red_Cobble"
    },
    {
      "x": -7,
      "y": -6,
      "z": -6,
      "name": "Rock_Sandstone_Red_Cobble"
    },
    {
      "x": -7,
      "y": -5,
      "z": -6,
      "name": "Rock_Sandstone_Red"
    },
    {
      "x": -7,
      "y": -4,
      "z": -6,
      "name": "Rock_Sandstone_Red_Cobble"
    },
    {
      "x": -7,
      "y": -8,
      "z": -5,
      "name": "Soil_Clay_Smooth_Red"
    },
    {
      "x": -7,
      "y": -7,
      "z": -5,
      "name": "Soil_Clay_Smooth_Red"
    },
    {
      "x": -7,
      "y": -6,
      "z": -5,
      "name": "Soil_Clay_Smooth_Red"
    },
    {
      "x": -7,
      "y": -5,
      "z": -5,
      "name": "Soil_Clay_Smooth_Red"
    },
    {
      "x": -7,
      "y": -4,
      "z": -5,
      "name": "Rock_Sandstone_Red_Cobble"
    },
    {
      "x": -7,
      "y": -3,
      "z": -5,
      "name": "Soil_Clay_Smooth_Red"
    },
    {
      "x": -7,
      "y": -9,
      "z": -4,
      "name": "Rock_Sandstone_Red_Cobble"
    },
    {
      "x": -7,
      "y": -8,
      "z": -4,
      "name": "Rock_Sandstone_Red_Cobble"
    },
    {
      "x": -7,
      "y": -7,
      "z": -4,
      "name": "Rock_Sandstone_Red"
    },
    {
      "x": -7,
      "y": -6,
      "z": -4,
      "name": "Rock_Sandstone_Red_Cobble"
    },
    {
      "x": -7,
      "y": -5,
      "z": -4,
      "name": "Rock_Sandstone_Red_Cobble"
    },
    {
      "x": -7,
      "y": -4,
      "z": -4,
      "name": "Rock_Sandstone_Red"
    },
    {
      "x": -7,
      "y": -3,
      "z": -4,
      "name": "Rock_Sandstone_Red"
    },
    {
      "x": -7,
      "y": -2,
      "z": -4,
      "name": "Soil_Clay_Smooth_Red"
    },
    {
      "x": -7,
      "y": -9,
      "z": -3,
      "name": "Rock_Sandstone_Red"
    },
    {
      "x": -7,
      "y": -8,
      "z": -3,
      "name": "Rock_Sandstone_Red"
    },
    {
      "x": -7,
      "y": -7,
      "z": -3,
      "name": "Soil_Clay_Smooth_Red"
    },
    {
      "x": -7,
      "y": -6,
      "z": -3,
      "name": "Rock_Sandstone_Red"
    },
    {
      "x": -7,
      "y": -5,
      "z": -3,
      "name": "Rock_Sandstone_Red_Cobble"
    },
    {
      "x": -7,
      "y": -4,
      "z": -3,
      "name": "Rock_Sandstone_Red_Cobble"
    },
    {
      "x": -7,
      "y": -3,
      "z": -3,
      "name": "Soil_Clay_Smooth_Red"
    },
    {
      "x": -7,
      "y": -2,
      "z": -3,
      "name": "Soil_Clay_Smooth_Red"
    },
    {
      "x": -7,
      "y": -10,
      "z": -2,
      "name": "Rock_Sandstone_Red_Cobble"
    },
    {
      "x": -7,
      "y": -9,
      "z": -2,
      "name": "Rock_Sandstone_Red"
    },
    {
      "x": -7,
      "y": -8,
      "z": -2,
      "name": "Rock_Sandstone_Red_Cobble"
    },
    {
      "x": -7,
      "y": -7,
      "z": -2,
      "name": "Soil_Clay_Smooth_Red"
    },
    {
      "x": -7,
      "y": -6,
      "z": -2,
      "name": "Rock_Sandstone_Red_Cobble"
    },
    {
      "x": -7,
      "y": -5,
      "z": -2,
      "name": "Soil_Clay_Smooth_Red"
    },
    {
      "x": -7,
      "y": -4,
      "z": -2,
      "name": "Rock_Sandstone_Red_Cobble"
    },
    {
      "x": -7,
      "y": -3,
      "z": -2,
      "name": "Rock_Sandstone_Red_Cobble"
    },
    {
      "x": -7,
      "y": -2,
      "z": -2,
      "name": "Rock_Sandstone_Red"
    },
    {
      "x": -7,
      "y": -1,
      "z": -2,
      "name": "Rock_Sandstone_Red"
    },
    {
      "x": -7,
      "y": 4,
      "z": -2,
      "name": "Rock_Sandstone"
    },
    {
      "x": -7,
      "y": -10,
      "z": -1,
      "name": "Rock_Sandstone_Red_Cobble"
    },
    {
      "x": -7,
      "y": -9,
      "z": -1,
      "name": "Soil_Clay_Smooth_Red"
    },
    {
      "x": -7,
      "y": -8,
      "z": -1,
      "name": "Rock_Sandstone_Red_Cobble"
    },
    {
      "x": -7,
      "y": -7,
      "z": -1,
      "name": "Rock_Sandstone_Red"
    },
    {
      "x": -7,
      "y": -6,
      "z": -1,
      "name": "Rock_Sandstone_Red"
    },
    {
      "x": -7,
      "y": -5,
      "z": -1,
      "name": "Rock_Sandstone_Red_Cobble"
    },
    {
      "x": -7,
      "y": -4,
      "z": -1,
      "name": "Soil_Clay_Smooth_Red"
    },
    {
      "x": -7,
      "y": -3,
      "z": -1,
      "name": "Rock_Sandstone_Red_Cobble"
    },
    {
      "x": -7,
      "y": -2,
      "z": -1,
      "name": "Soil_Clay_Smooth_Red"
    },
    {
      "x": -7,
      "y": -1,
      "z": -1,
      "name": "Soil_Clay_Smooth_Red"
    },
    {
      "x": -7,
      "y": 0,
      "z": -1,
      "name": "Rock_Sandstone_Red_Cobble"
    },
    {
      "x": -7,
      "y": 3,
      "z": -1,
      "name": "Rock_Sandstone"
    },
    {
      "x": -7,
      "y": 4,
      "z": -1,
      "name": "Rock_Sandstone"
    },
    {
      "x": -7,
      "y": 5,
      "z": -1,
      "name": "Rock_Sandstone"
    },
    {
      "x": -7,
      "y": -10,
      "z": 0,
      "name": "Soil_Clay_Smooth_Red"
    },
    {
      "x": -7,
      "y": -9,
      "z": 0,
      "name": "Soil_Clay_Smooth_Red"
    },
    {
      "x": -7,
      "y": -8,
      "z": 0,
      "name": "Soil_Clay_Smooth_Red"
    },
    {
      "x": -7,
      "y": -7,
      "z": 0,
      "name": "Soil_Clay_Smooth_Red"
    },
    {
      "x": -7,
      "y": -6,
      "z": 0,
      "name": "Rock_Sandstone_Red_Cobble"
    },
    {
      "x": -7,
      "y": -5,
      "z": 0,
      "name": "Soil_Clay_Smooth_Red"
    },
    {
      "x": -7,
      "y": -4,
      "z": 0,
      "name": "Rock_Sandstone_Red"
    },
    {
      "x": -7,
      "y": -3,
      "z": 0,
      "name": "Rock_Sandstone_Red"
    },
    {
      "x": -7,
      "y": -2,
      "z": 0,
      "name": "Rock_Sandstone_Red"
    },
    {
      "x": -7,
      "y": -1,
      "z": 0,
      "name": "Rock_Sandstone_Red"
    },
    {
      "x": -7,
      "y": 0,
      "z": 0,
      "name": "Rock_Sandstone_Red"
    },
    {
      "x": -7,
      "y": 3,
      "z": 0,
      "name": "Rock_Sandstone"
    },
    {
      "x": -7,
      "y": 4,
      "z": 0,
      "name": "Rock_Sandstone"
    },
    {
      "x": -7,
      "y": 5,
      "z": 0,
      "name": "Rock_Sandstone"
    },
    {
      "x": -7,
      "y": 6,
      "z": 0,
      "name": "Rock_Sandstone"
    },
    {
      "x": -7,
      "y": -9,
      "z": 1,
      "name": "Soil_Clay_Smooth_Red"
    },
    {
      "x": -7,
      "y": -8,
      "z": 1,
      "name": "Soil_Clay_Smooth_Red"
    },
    {
      "x": -7,
      "y": -7,
      "z": 1,
      "name": "Rock_Sandstone_Red_Cobble"
    },
    {
      "x": -7,
      "y": -6,
      "z": 1,
      "name": "Rock_Sandstone_Red_Cobble"
    },
    {
      "x": -7,
      "y": -5,
      "z": 1,
      "name": "Rock_Sandstone_Red_Cobble"
    },
    {
      "x": -7,
      "y": -4,
      "z": 1,
      "name": "Rock_Sandstone_Red"
    },
    {
      "x": -7,
      "y": -3,
      "z": 1,
      "name": "Soil_Clay_Smooth_Red"
    },
    {
      "x": -7,
      "y": -2,
      "z": 1,
      "name": "Soil_Clay_Smooth_Red"
    },
    {
      "x": -7,
      "y": -1,
      "z": 1,
      "name": "Rock_Sandstone_Red"
    },
    {
      "x": -7,
      "y": 1,
      "z": 1,
      "name": "Rock_Sandstone"
    },
    {
      "x": -7,
      "y": 2,
      "z": 1,
      "name": "Rock_Sandstone"
    },
    {
      "x": -7,
      "y": 3,
      "z": 1,
      "name": "Rock_Sandstone"
    },
    {
      "x": -7,
      "y": 4,
      "z": 1,
      "name": "Rock_Sandstone"
    },
    {
      "x": -7,
      "y": 5,
      "z": 1,
      "name": "Rock_Sandstone"
    },
    {
      "x": -7,
      "y": 6,
      "z": 1,
      "name": "Rock_Sandstone"
    },
    {
      "x": -7,
      "y": 7,
      "z": 1,
      "name": "Rock_Sandstone"
    },
    {
      "x": -7,
      "y": -9,
      "z": 2,
      "name": "Rock_Sandstone_Red_Cobble"
    },
    {
      "x": -7,
      "y": -8,
      "z": 2,
      "name": "Rock_Sandstone_Red"
    },
    {
      "x": -7,
      "y": -7,
      "z": 2,
      "name": "Rock_Sandstone_Red_Cobble"
    },
    {
      "x": -7,
      "y": -6,
      "z": 2,
      "name": "Rock_Sandstone_Red"
    },
    {
      "x": -7,
      "y": -5,
      "z": 2,
      "name": "Rock_Sandstone_Red"
    },
    {
      "x": -7,
      "y": -4,
      "z": 2,
      "name": "Rock_Sandstone_Red"
    },
    {
      "x": -7,
      "y": -3,
      "z": 2,
      "name": "Soil_Clay_Smooth_Red"
    },
    {
      "x": -7,
      "y": -2,
      "z": 2,
      "name": "Rock_Sandstone_Red"
    },
    {
      "x": -7,
      "y": -1,
      "z": 2,
      "name": "Rock_Sandstone_Red"
    },
    {
      "x": -7,
      "y": 0,
      "z": 2,
      "name": "Rock_Sandstone"
    },
    {
      "x": -7,
      "y": 1,
      "z": 2,
      "name": "Rock_Sandstone"
    },
    {
      "x": -7,
      "y": 2,
      "z": 2,
      "name": "Rock_Sandstone"
    },
    {
      "x": -7,
      "y": 3,
      "z": 2,
      "name": "Rock_Sandstone"
    },
    {
      "x": -7,
      "y": 4,
      "z": 2,
      "name": "Rock_Sandstone"
    },
    {
      "x": -7,
      "y": 5,
      "z": 2,
      "name": "Rock_Sandstone"
    },
    {
      "x": -7,
      "y": 6,
      "z": 2,
      "name": "Rock_Sandstone"
    },
    {
      "x": -7,
      "y": 7,
      "z": 2,
      "name": "Rock_Sandstone"
    },
    {
      "x": -7,
      "y": -8,
      "z": 3,
      "name": "Rock_Sandstone_Red_Cobble"
    },
    {
      "x": -7,
      "y": -7,
      "z": 3,
      "name": "Soil_Clay_Smooth_Red"
    },
    {
      "x": -7,
      "y": -6,
      "z": 3,
      "name": "Soil_Clay_Smooth_Red"
    },
    {
      "x": -7,
      "y": -5,
      "z": 3,
      "name": "Rock_Sandstone_Red_Cobble"
    },
    {
      "x": -7,
      "y": -4,
      "z": 3,
      "name": "Soil_Clay_Smooth_Red"
    },
    {
      "x": -7,
      "y": -3,
      "z": 3,
      "name": "Rock_Sandstone_Red"
    },
    {
      "x": -7,
      "y": -2,
      "z": 3,
      "name": "Rock_Sandstone_Red"
    },
    {
      "x": -7,
      "y": 0,
      "z": 3,
      "name": "Rock_Sandstone"
    },
    {
      "x": -7,
      "y": 1,
      "z": 3,
      "name": "Rock_Sandstone"
    },
    {
      "x": -7,
      "y": 2,
      "z": 3,
      "name": "Rock_Sandstone"
    },
    {
      "x": -7,
      "y": 3,
      "z": 3,
      "name": "Rock_Sandstone"
    },
    {
      "x": -7,
      "y": 4,
      "z": 3,
      "name": "Rock_Sandstone"
    },
    {
      "x": -7,
      "y": 5,
      "z": 3,
      "name": "Rock_Sandstone"
    },
    {
      "x": -7,
      "y": 6,
      "z": 3,
      "name": "Rock_Sandstone"
    },
    {
      "x": -7,
      "y": 7,
      "z": 3,
      "name": "Rock_Sandstone"
    },
    {
      "x": -7,
      "y": -7,
      "z": 4,
      "name": "Rock_Sandstone_Red"
    },
    {
      "x": -7,
      "y": -6,
      "z": 4,
      "name": "Soil_Clay_Smooth_Red"
    },
    {
      "x": -7,
      "y": -5,
      "z": 4,
      "name": "Soil_Clay_Smooth_Red"
    },
    {
      "x": -7,
      "y": -4,
      "z": 4,
      "name": "Rock_Sandstone_Red_Cobble"
    },
    {
      "x": -7,
      "y": -3,
      "z": 4,
      "name": "Rock_Sandstone_Red"
    },
    {
      "x": -7,
      "y": 0,
      "z": 4,
      "name": "Rock_Sandstone"
    },
    {
      "x": -7,
      "y": 1,
      "z": 4,
      "name": "Rock_Sandstone"
    },
    {
      "x": -7,
      "y": 2,
      "z": 4,
      "name": "Rock_Sandstone"
    },
    {
      "x": -7,
      "y": 3,
      "z": 4,
      "name": "Rock_Sandstone"
    },
    {
      "x": -7,
      "y": 4,
      "z": 4,
      "name": "Rock_Sandstone"
    },
    {
      "x": -7,
      "y": 5,
      "z": 4,
      "name": "Rock_Sandstone"
    },
    {
      "x": -7,
      "y": 6,
      "z": 4,
      "name": "Rock_Sandstone"
    },
    {
      "x": -7,
      "y": 7,
      "z": 4,
      "name": "Rock_Sandstone"
    },
    {
      "x": -7,
      "y": 8,
      "z": 4,
      "name": "Soil_Clay"
    },
    {
      "x": -7,
      "y": -8,
      "z": 5,
      "name": "Rock_Sandstone_Red_Cobble"
    },
    {
      "x": -7,
      "y": -7,
      "z": 5,
      "name": "Rock_Sandstone_Red"
    },
    {
      "x": -7,
      "y": -6,
      "z": 5,
      "name": "Soil_Clay_Smooth_Red"
    },
    {
      "x": -7,
      "y": -5,
      "z": 5,
      "name": "Soil_Clay_Smooth_Red"
    },
    {
      "x": -7,
      "y": -4,
      "z": 5,
      "name": "Rock_Sandstone_Red_Cobble"
    },
    {
      "x": -7,
      "y": -3,
      "z": 5,
      "name": "Soil_Clay_Smooth_Red"
    },
    {
      "x": -7,
      "y": -2,
      "z": 5,
      "name": "Soil_Clay_Smooth_Red"
    },
    {
      "x": -7,
      "y": -1,
      "z": 5,
      "name": "Rock_Sandstone"
    },
    {
      "x": -7,
      "y": 0,
      "z": 5,
      "name": "Rock_Sandstone"
    },
    {
      "x": -7,
      "y": 1,
      "z": 5,
      "name": "Rock_Sandstone"
    },
    {
      "x": -7,
      "y": 2,
      "z": 5,
      "name": "Rock_Sandstone"
    },
    {
      "x": -7,
      "y": 3,
      "z": 5,
      "name": "Rock_Sandstone"
    },
    {
      "x": -7,
      "y": 4,
      "z": 5,
      "name": "Rock_Sandstone"
    },
    {
      "x": -7,
      "y": 5,
      "z": 5,
      "name": "Rock_Sandstone"
    },
    {
      "x": -7,
      "y": 6,
      "z": 5,
      "name": "Rock_Sandstone"
    },
    {
      "x": -7,
      "y": 7,
      "z": 5,
      "name": "Rock_Sandstone"
    },
    {
      "x": -7,
      "y": 8,
      "z": 5,
      "name": "Soil_Clay"
    },
    {
      "x": -7,
      "y": -9,
      "z": 6,
      "name": "Soil_Clay_Smooth_Red"
    },
    {
      "x": -7,
      "y": -8,
      "z": 6,
      "name": "Rock_Sandstone_Red"
    },
    {
      "x": -7,
      "y": -7,
      "z": 6,
      "name": "Rock_Sandstone_Red"
    },
    {
      "x": -7,
      "y": -6,
      "z": 6,
      "name": "Rock_Sandstone_Red_Cobble"
    },
    {
      "x": -7,
      "y": -5,
      "z": 6,
      "name": "Rock_Sandstone_Red_Cobble"
    },
    {
      "x": -7,
      "y": -4,
      "z": 6,
      "name": "Rock_Sandstone_Red"
    },
    {
      "x": -7,
      "y": -3,
      "z": 6,
      "name": "Rock_Sandstone_Red"
    },
    {
      "x": -7,
      "y": -2,
      "z": 6,
      "name": "Rock_Sandstone_Red_Cobble"
    },
    {
      "x": -7,
      "y": -1,
      "z": 6,
      "name": "Rock_Sandstone_Red"
    },
    {
      "x": -7,
      "y": 0,
      "z": 6,
      "name": "Rock_Sandstone"
    },
    {
      "x": -7,
      "y": 1,
      "z": 6,
      "name": "Rock_Sandstone"
    },
    {
      "x": -7,
      "y": 2,
      "z": 6,
      "name": "Rock_Sandstone"
    },
    {
      "x": -7,
      "y": 3,
      "z": 6,
      "name": "Rock_Sandstone"
    },
    {
      "x": -7,
      "y": 4,
      "z": 6,
      "name": "Rock_Sandstone"
    },
    {
      "x": -7,
      "y": 5,
      "z": 6,
      "name": "Rock_Sandstone"
    },
    {
      "x": -7,
      "y": 6,
      "z": 6,
      "name": "Rock_Sandstone"
    },
    {
      "x": -7,
      "y": 7,
      "z": 6,
      "name": "Rock_Sandstone"
    },
    {
      "x": -7,
      "y": 8,
      "z": 6,
      "name": "Rock_Sandstone"
    },
    {
      "x": -7,
      "y": -10,
      "z": 7,
      "name": "Soil_Clay_Smooth_Red"
    },
    {
      "x": -7,
      "y": -9,
      "z": 7,
      "name": "Soil_Clay_Smooth_Red"
    },
    {
      "x": -7,
      "y": -8,
      "z": 7,
      "name": "Rock_Sandstone_Red_Cobble"
    },
    {
      "x": -7,
      "y": -7,
      "z": 7,
      "name": "Rock_Sandstone_Red"
    },
    {
      "x": -7,
      "y": -6,
      "z": 7,
      "name": "Rock_Sandstone_Red"
    },
    {
      "x": -7,
      "y": -5,
      "z": 7,
      "name": "Rock_Sandstone_Red_Cobble"
    },
    {
      "x": -7,
      "y": -4,
      "z": 7,
      "name": "Soil_Clay_Smooth_Red"
    },
    {
      "x": -7,
      "y": -3,
      "z": 7,
      "name": "Soil_Clay_Smooth_Red"
    },
    {
      "x": -7,
      "y": -2,
      "z": 7,
      "name": "Rock_Sandstone_Red"
    },
    {
      "x": -7,
      "y": -1,
      "z": 7,
      "name": "Rock_Sandstone_Red"
    },
    {
      "x": -7,
      "y": 0,
      "z": 7,
      "name": "Soil_Clay"
    },
    {
      "x": -7,
      "y": 1,
      "z": 7,
      "name": "Rock_Sandstone"
    },
    {
      "x": -7,
      "y": 2,
      "z": 7,
      "name": "Rock_Sandstone"
    },
    {
      "x": -7,
      "y": 3,
      "z": 7,
      "name": "Rock_Sandstone"
    },
    {
      "x": -7,
      "y": 4,
      "z": 7,
      "name": "Rock_Sandstone"
    },
    {
      "x": -7,
      "y": 5,
      "z": 7,
      "name": "Rock_Sandstone"
    },
    {
      "x": -7,
      "y": 6,
      "z": 7,
      "name": "Rock_Sandstone"
    },
    {
      "x": -7,
      "y": 7,
      "z": 7,
      "name": "Rock_Sandstone"
    },
    {
      "x": -7,
      "y": -10,
      "z": 8,
      "name": "Rock_Sandstone_Red"
    },
    {
      "x": -7,
      "y": -9,
      "z": 8,
      "name": "Rock_Sandstone_Red_Cobble"
    },
    {
      "x": -7,
      "y": -8,
      "z": 8,
      "name": "Soil_Clay_Smooth_Red"
    },
    {
      "x": -7,
      "y": -7,
      "z": 8,
      "name": "Soil_Clay_Smooth_Red"
    },
    {
      "x": -7,
      "y": -6,
      "z": 8,
      "name": "Soil_Clay_Smooth_Red"
    },
    {
      "x": -7,
      "y": -5,
      "z": 8,
      "name": "Rock_Sandstone_Red_Cobble"
    },
    {
      "x": -7,
      "y": -4,
      "z": 8,
      "name": "Soil_Clay_Smooth_Red"
    },
    {
      "x": -7,
      "y": -3,
      "z": 8,
      "name": "Rock_Sandstone_Red_Cobble"
    },
    {
      "x": -7,
      "y": -2,
      "z": 8,
      "name": "Rock_Sandstone_Red_Cobble"
    },
    {
      "x": -7,
      "y": -1,
      "z": 8,
      "name": "Soil_Clay_Smooth_Red"
    },
    {
      "x": -7,
      "y": 0,
      "z": 8,
      "name": "Rock_Sandstone"
    },
    {
      "x": -7,
      "y": 1,
      "z": 8,
      "name": "Rock_Sandstone"
    },
    {
      "x": -7,
      "y": 2,
      "z": 8,
      "name": "Rock_Sandstone"
    },
    {
      "x": -7,
      "y": 3,
      "z": 8,
      "name": "Rock_Sandstone"
    },
    {
      "x": -7,
      "y": 4,
      "z": 8,
      "name": "Rock_Sandstone"
    },
    {
      "x": -7,
      "y": 5,
      "z": 8,
      "name": "Rock_Sandstone"
    },
    {
      "x": -7,
      "y": 6,
      "z": 8,
      "name": "Rock_Sandstone"
    },
    {
      "x": -7,
      "y": 7,
      "z": 8,
      "name": "Soil_Clay"
    },
    {
      "x": -7,
      "y": -10,
      "z": 9,
      "name": "Soil_Clay_Smooth_Red"
    },
    {
      "x": -7,
      "y": -9,
      "z": 9,
      "name": "Soil_Clay_Smooth_Red"
    },
    {
      "x": -7,
      "y": -8,
      "z": 9,
      "name": "Soil_Clay_Smooth_Red"
    },
    {
      "x": -7,
      "y": -7,
      "z": 9,
      "name": "Rock_Sandstone_Red_Cobble"
    },
    {
      "x": -7,
      "y": -6,
      "z": 9,
      "name": "Soil_Clay_Smooth_Red"
    },
    {
      "x": -7,
      "y": -5,
      "z": 9,
      "name": "Soil_Clay_Smooth_Red"
    },
    {
      "x": -7,
      "y": -4,
      "z": 9,
      "name": "Rock_Sandstone_Red"
    },
    {
      "x": -7,
      "y": -3,
      "z": 9,
      "name": "Soil_Clay_Smooth_Red"
    },
    {
      "x": -7,
      "y": -2,
      "z": 9,
      "name": "Soil_Clay_Smooth_Red"
    },
    {
      "x": -7,
      "y": -1,
      "z": 9,
      "name": "Rock_Sandstone_Red_Cobble"
    },
    {
      "x": -7,
      "y": 0,
      "z": 9,
      "name": "Rock_Sandstone_Red_Cobble"
    },
    {
      "x": -7,
      "y": 3,
      "z": 9,
      "name": "Soil_Clay"
    },
    {
      "x": -7,
      "y": 4,
      "z": 9,
      "name": "Rock_Sandstone"
    },
    {
      "x": -7,
      "y": 5,
      "z": 9,
      "name": "Rock_Sandstone"
    },
    {
      "x": -7,
      "y": -10,
      "z": 10,
      "name": "Soil_Clay_Smooth_Red"
    },
    {
      "x": -7,
      "y": -9,
      "z": 10,
      "name": "Soil_Clay_Smooth_Red"
    },
    {
      "x": -7,
      "y": -8,
      "z": 10,
      "name": "Soil_Clay_Smooth_Red"
    },
    {
      "x": -7,
      "y": -7,
      "z": 10,
      "name": "Rock_Sandstone_Red"
    },
    {
      "x": -7,
      "y": -6,
      "z": 10,
      "name": "Soil_Clay_Smooth_Red"
    },
    {
      "x": -7,
      "y": -5,
      "z": 10,
      "name": "Rock_Sandstone_Red"
    },
    {
      "x": -7,
      "y": -4,
      "z": 10,
      "name": "Rock_Sandstone_Red_Cobble"
    },
    {
      "x": -7,
      "y": -3,
      "z": 10,
      "name": "Soil_Clay_Smooth_Red"
    },
    {
      "x": -7,
      "y": -2,
      "z": 10,
      "name": "Rock_Sandstone_Red_Cobble"
    },
    {
      "x": -7,
      "y": -1,
      "z": 10,
      "name": "Soil_Clay_Smooth_Red"
    },
    {
      "x": -7,
      "y": -10,
      "z": 11,
      "name": "Rock_Sandstone_Red"
    },
    {
      "x": -7,
      "y": -9,
      "z": 11,
      "name": "Rock_Sandstone_Red"
    },
    {
      "x": -7,
      "y": -8,
      "z": 11,
      "name": "Rock_Sandstone_Red_Cobble"
    },
    {
      "x": -7,
      "y": -7,
      "z": 11,
      "name": "Soil_Clay_Smooth_Red"
    },
    {
      "x": -7,
      "y": -6,
      "z": 11,
      "name": "Rock_Sandstone_Red_Cobble"
    },
    {
      "x": -7,
      "y": -5,
      "z": 11,
      "name": "Soil_Clay_Smooth_Red"
    },
    {
      "x": -7,
      "y": -4,
      "z": 11,
      "name": "Rock_Sandstone_Red"
    },
    {
      "x": -7,
      "y": -3,
      "z": 11,
      "name": "Rock_Sandstone_Red"
    },
    {
      "x": -7,
      "y": -9,
      "z": 12,
      "name": "Rock_Sandstone_Red_Cobble"
    },
    {
      "x": -7,
      "y": -7,
      "z": 12,
      "name": "Rock_Sandstone_Red"
    },
    {
      "x": -7,
      "y": -6,
      "z": 12,
      "name": "Soil_Clay_Smooth_Red"
    },
    {
      "x": -6,
      "y": -7,
      "z": -8,
      "name": "Soil_Clay_Smooth_Red"
    },
    {
      "x": -6,
      "y": -6,
      "z": -8,
      "name": "Rock_Sandstone_Red_Cobble"
    },
    {
      "x": -6,
      "y": -5,
      "z": -8,
      "name": "Rock_Sandstone_Red"
    },
    {
      "x": -6,
      "y": -7,
      "z": -7,
      "name": "Rock_Sandstone_Red"
    },
    {
      "x": -6,
      "y": -6,
      "z": -7,
      "name": "Soil_Clay_Smooth_Red"
    },
    {
      "x": -6,
      "y": -5,
      "z": -7,
      "name": "Soil_Clay_Smooth_Red"
    },
    {
      "x": -6,
      "y": -4,
      "z": -7,
      "name": "Rock_Sandstone_Red_Cobble"
    },
    {
      "x": -6,
      "y": -7,
      "z": -6,
      "name": "Rock_Sandstone_Red_Cobble"
    },
    {
      "x": -6,
      "y": -6,
      "z": -6,
      "name": "Rock_Sandstone_Red"
    },
    {
      "x": -6,
      "y": -5,
      "z": -6,
      "name": "Rock_Sandstone_Red"
    },
    {
      "x": -6,
      "y": -4,
      "z": -6,
      "name": "Soil_Clay_Smooth_Red"
    },
    {
      "x": -6,
      "y": -3,
      "z": -6,
      "name": "Rock_Sandstone_Red_Cobble"
    },
    {
      "x": -6,
      "y": -8,
      "z": -5,
      "name": "Rock_Sandstone_Red"
    },
    {
      "x": -6,
      "y": -7,
      "z": -5,
      "name": "Rock_Sandstone_Red"
    },
    {
      "x": -6,
      "y": -6,
      "z": -5,
      "name": "Soil_Clay_Smooth_Red"
    },
    {
      "x": -6,
      "y": -5,
      "z": -5,
      "name": "Rock_Sandstone_Red"
    },
    {
      "x": -6,
      "y": -4,
      "z": -5,
      "name": "Rock_Sandstone_Red_Cobble"
    },
    {
      "x": -6,
      "y": -3,
      "z": -5,
      "name": "Rock_Sandstone_Red"
    },
    {
      "x": -6,
      "y": -2,
      "z": -5,
      "name": "Rock_Sandstone_Red"
    },
    {
      "x": -6,
      "y": -9,
      "z": -4,
      "name": "Rock_Sandstone_Red_Cobble"
    },
    {
      "x": -6,
      "y": -8,
      "z": -4,
      "name": "Rock_Sandstone_Red_Cobble"
    },
    {
      "x": -6,
      "y": -7,
      "z": -4,
      "name": "Rock_Sandstone_Red"
    },
    {
      "x": -6,
      "y": -6,
      "z": -4,
      "name": "Soil_Clay_Smooth_Red"
    },
    {
      "x": -6,
      "y": -5,
      "z": -4,
      "name": "Rock_Sandstone_Red_Cobble"
    },
    {
      "x": -6,
      "y": -4,
      "z": -4,
      "name": "Soil_Clay_Smooth_Red"
    },
    {
      "x": -6,
      "y": -3,
      "z": -4,
      "name": "Rock_Sandstone_Red_Cobble"
    },
    {
      "x": -6,
      "y": -2,
      "z": -4,
      "name": "Soil_Clay_Smooth_Red"
    },
    {
      "x": -6,
      "y": -1,
      "z": -4,
      "name": "Rock_Sandstone_Red"
    },
    {
      "x": -6,
      "y": 3,
      "z": -4,
      "name": "Rock_Sandstone"
    },
    {
      "x": -6,
      "y": 4,
      "z": -4,
      "name": "Rock_Sandstone"
    },
    {
      "x": -6,
      "y": -9,
      "z": -3,
      "name": "Rock_Sandstone_Red_Cobble"
    },
    {
      "x": -6,
      "y": -8,
      "z": -3,
      "name": "Rock_Sandstone_Red"
    },
    {
      "x": -6,
      "y": -7,
      "z": -3,
      "name": "Rock_Sandstone_Red"
    },
    {
      "x": -6,
      "y": -6,
      "z": -3,
      "name": "Soil_Clay_Smooth_Red"
    },
    {
      "x": -6,
      "y": -5,
      "z": -3,
      "name": "Rock_Sandstone_Red_Cobble"
    },
    {
      "x": -6,
      "y": -4,
      "z": -3,
      "name": "Rock_Sandstone_Red"
    },
    {
      "x": -6,
      "y": -3,
      "z": -3,
      "name": "Rock_Sandstone_Red"
    },
    {
      "x": -6,
      "y": -2,
      "z": -3,
      "name": "Rock_Sandstone_Red_Cobble"
    },
    {
      "x": -6,
      "y": -1,
      "z": -3,
      "name": "Rock_Sandstone_Red_Cobble"
    },
    {
      "x": -6,
      "y": 3,
      "z": -3,
      "name": "Rock_Sandstone"
    },
    {
      "x": -6,
      "y": 4,
      "z": -3,
      "name": "Rock_Sandstone"
    },
    {
      "x": -6,
      "y": 5,
      "z": -3,
      "name": "Rock_Sandstone"
    },
    {
      "x": -6,
      "y": 6,
      "z": -3,
      "name": "Rock_Sandstone"
    },
    {
      "x": -6,
      "y": -9,
      "z": -2,
      "name": "Soil_Clay_Smooth_Red"
    },
    {
      "x": -6,
      "y": -8,
      "z": -2,
      "name": "Rock_Sandstone_Red"
    },
    {
      "x": -6,
      "y": -7,
      "z": -2,
      "name": "Soil_Clay_Smooth_Red"
    },
    {
      "x": -6,
      "y": -6,
      "z": -2,
      "name": "Soil_Clay_Smooth_Red"
    },
    {
      "x": -6,
      "y": -5,
      "z": -2,
      "name": "Soil_Clay_Smooth_Red"
    },
    {
      "x": -6,
      "y": -4,
      "z": -2,
      "name": "Soil_Clay_Smooth_Red"
    },
    {
      "x": -6,
      "y": -3,
      "z": -2,
      "name": "Rock_Sandstone_Red"
    },
    {
      "x": -6,
      "y": -2,
      "z": -2,
      "name": "Rock_Sandstone_Red_Cobble"
    },
    {
      "x": -6,
      "y": -1,
      "z": -2,
      "name": "Rock_Sandstone_Red"
    },
    {
      "x": -6,
      "y": 1,
      "z": -2,
      "name": "Rock_Sandstone"
    },
    {
      "x": -6,
      "y": 2,
      "z": -2,
      "name": "Rock_Sandstone"
    },
    {
      "x": -6,
      "y": 3,
      "z": -2,
      "name": "Rock_Sandstone"
    },
    {
      "x": -6,
      "y": 4,
      "z": -2,
      "name": "Rock_Sandstone"
    },
    {
      "x": -6,
      "y": 5,
      "z": -2,
      "name": "Rock_Sandstone"
    },
    {
      "x": -6,
      "y": 6,
      "z": -2,
      "name": "Rock_Sandstone"
    },
    {
      "x": -6,
      "y": 7,
      "z": -2,
      "name": "Rock_Sandstone"
    },
    {
      "x": -6,
      "y": -10,
      "z": -1,
      "name": "Rock_Sandstone_Red_Cobble"
    },
    {
      "x": -6,
      "y": -9,
      "z": -1,
      "name": "Soil_Clay_Smooth_Red"
    },
    {
      "x": -6,
      "y": -8,
      "z": -1,
      "name": "Rock_Sandstone_Red"
    },
    {
      "x": -6,
      "y": -7,
      "z": -1,
      "name": "Rock_Sandstone_Red_Cobble"
    },
    {
      "x": -6,
      "y": -6,
      "z": -1,
      "name": "Rock_Sandstone_Red"
    },
    {
      "x": -6,
      "y": -5,
      "z": -1,
      "name": "Rock_Sandstone_Red"
    },
    {
      "x": -6,
      "y": -4,
      "z": -1,
      "name": "Soil_Clay_Smooth_Red"
    },
    {
      "x": -6,
      "y": -3,
      "z": -1,
      "name": "Rock_Sandstone_Red"
    },
    {
      "x": -6,
      "y": -2,
      "z": -1,
      "name": "Rock_Sandstone_Red"
    },
    {
      "x": -6,
      "y": -1,
      "z": -1,
      "name": "Rock_Sandstone_Red"
    },
    {
      "x": -6,
      "y": 0,
      "z": -1,
      "name": "Soil_Clay_Smooth_Red"
    },
    {
      "x": -6,
      "y": 2,
      "z": -1,
      "name": "Rock_Sandstone"
    },
    {
      "x": -6,
      "y": 3,
      "z": -1,
      "name": "Rock_Sandstone"
    },
    {
      "x": -6,
      "y": 4,
      "z": -1,
      "name": "Rock_Sandstone"
    },
    {
      "x": -6,
      "y": 5,
      "z": -1,
      "name": "Rock_Sandstone"
    },
    {
      "x": -6,
      "y": 6,
      "z": -1,
      "name": "Rock_Sandstone"
    },
    {
      "x": -6,
      "y": 7,
      "z": -1,
      "name": "Rock_Sandstone"
    },
    {
      "x": -6,
      "y": 8,
      "z": -1,
      "name": "Rock_Sandstone"
    },
    {
      "x": -6,
      "y": -9,
      "z": 0,
      "name": "Soil_Clay_Smooth_Red"
    },
    {
      "x": -6,
      "y": -8,
      "z": 0,
      "name": "Rock_Sandstone_Red"
    },
    {
      "x": -6,
      "y": -7,
      "z": 0,
      "name": "Rock_Sandstone_Red"
    },
    {
      "x": -6,
      "y": -6,
      "z": 0,
      "name": "Rock_Sandstone_Red_Cobble"
    },
    {
      "x": -6,
      "y": -5,
      "z": 0,
      "name": "Rock_Sandstone_Red_Cobble"
    },
    {
      "x": -6,
      "y": -4,
      "z": 0,
      "name": "Soil_Clay_Smooth_Red"
    },
    {
      "x": -6,
      "y": -3,
      "z": 0,
      "name": "Rock_Sandstone_Red_Cobble"
    },
    {
      "x": -6,
      "y": -2,
      "z": 0,
      "name": "Rock_Sandstone_Red_Cobble"
    },
    {
      "x": -6,
      "y": -1,
      "z": 0,
      "name": "Rock_Sandstone_Red_Cobble"
    },
    {
      "x": -6,
      "y": 2,
      "z": 0,
      "name": "Rock_Sandstone"
    },
    {
      "x": -6,
      "y": 3,
      "z": 0,
      "name": "Rock_Sandstone"
    },
    {
      "x": -6,
      "y": 4,
      "z": 0,
      "name": "Rock_Sandstone"
    },
    {
      "x": -6,
      "y": 5,
      "z": 0,
      "name": "Rock_Sandstone"
    },
    {
      "x": -6,
      "y": 6,
      "z": 0,
      "name": "Rock_Sandstone"
    },
    {
      "x": -6,
      "y": 7,
      "z": 0,
      "name": "Rock_Sandstone"
    },
    {
      "x": -6,
      "y": 8,
      "z": 0,
      "name": "Rock_Sandstone"
    },
    {
      "x": -6,
      "y": 9,
      "z": 0,
      "name": "Rock_Sandstone"
    },
    {
      "x": -6,
      "y": -9,
      "z": 1,
      "name": "Rock_Sandstone_Red_Cobble"
    },
    {
      "x": -6,
      "y": -8,
      "z": 1,
      "name": "Rock_Sandstone_Red_Cobble"
    },
    {
      "x": -6,
      "y": -7,
      "z": 1,
      "name": "Rock_Sandstone_Red"
    },
    {
      "x": -6,
      "y": -6,
      "z": 1,
      "name": "Soil_Clay_Smooth_Red"
    },
    {
      "x": -6,
      "y": -5,
      "z": 1,
      "name": "Soil_Clay_Smooth_Red"
    },
    {
      "x": -6,
      "y": -4,
      "z": 1,
      "name": "Soil_Clay_Smooth_Red"
    },
    {
      "x": -6,
      "y": -3,
      "z": 1,
      "name": "Soil_Clay_Smooth_Red"
    },
    {
      "x": -6,
      "y": -2,
      "z": 1,
      "name": "Rock_Sandstone_Red_Cobble"
    },
    {
      "x": -6,
      "y": -1,
      "z": 1,
      "name": "Soil_Clay_Smooth_Red"
    },
    {
      "x": -6,
      "y": 1,
      "z": 1,
      "name": "Rock_Sandstone"
    },
    {
      "x": -6,
      "y": 2,
      "z": 1,
      "name": "Rock_Sandstone"
    },
    {
      "x": -6,
      "y": 3,
      "z": 1,
      "name": "Rock_Sandstone"
    },
    {
      "x": -6,
      "y": 4,
      "z": 1,
      "name": "Rock_Sandstone"
    },
    {
      "x": -6,
      "y": 5,
      "z": 1,
      "name": "Rock_Sandstone"
    },
    {
      "x": -6,
      "y": 6,
      "z": 1,
      "name": "Rock_Sandstone"
    },
    {
      "x": -6,
      "y": 7,
      "z": 1,
      "name": "Rock_Sandstone"
    },
    {
      "x": -6,
      "y": 8,
      "z": 1,
      "name": "Rock_Sandstone"
    },
    {
      "x": -6,
      "y": 9,
      "z": 1,
      "name": "Rock_Sandstone"
    },
    {
      "x": -6,
      "y": -9,
      "z": 2,
      "name": "Soil_Clay_Smooth_Red"
    },
    {
      "x": -6,
      "y": -8,
      "z": 2,
      "name": "Soil_Clay_Smooth_Red"
    },
    {
      "x": -6,
      "y": -7,
      "z": 2,
      "name": "Rock_Sandstone_Red_Cobble"
    },
    {
      "x": -6,
      "y": -6,
      "z": 2,
      "name": "Soil_Clay_Smooth_Red"
    },
    {
      "x": -6,
      "y": -5,
      "z": 2,
      "name": "Rock_Sandstone_Red_Cobble"
    },
    {
      "x": -6,
      "y": -4,
      "z": 2,
      "name": "Rock_Sandstone_Red"
    },
    {
      "x": -6,
      "y": -3,
      "z": 2,
      "name": "Rock_Sandstone_Red"
    },
    {
      "x": -6,
      "y": -2,
      "z": 2,
      "name": "Rock_Sandstone_Red_Cobble"
    },
    {
      "x": -6,
      "y": -1,
      "z": 2,
      "name": "Rock_Sandstone_Red_Cobble"
    },
    {
      "x": -6,
      "y": 0,
      "z": 2,
      "name": "Rock_Sandstone"
    },
    {
      "x": -6,
      "y": 1,
      "z": 2,
      "name": "Rock_Sandstone"
    },
    {
      "x": -6,
      "y": 2,
      "z": 2,
      "name": "Rock_Sandstone"
    },
    {
      "x": -6,
      "y": 3,
      "z": 2,
      "name": "Rock_Sandstone"
    },
    {
      "x": -6,
      "y": 4,
      "z": 2,
      "name": "Rock_Sandstone"
    },
    {
      "x": -6,
      "y": 5,
      "z": 2,
      "name": "Rock_Sandstone"
    },
    {
      "x": -6,
      "y": 6,
      "z": 2,
      "name": "Rock_Sandstone"
    },
    {
      "x": -6,
      "y": 7,
      "z": 2,
      "name": "Rock_Sandstone"
    },
    {
      "x": -6,
      "y": 8,
      "z": 2,
      "name": "Rock_Sandstone"
    },
    {
      "x": -6,
      "y": 9,
      "z": 2,
      "name": "Rock_Sandstone"
    },
    {
      "x": -6,
      "y": -8,
      "z": 3,
      "name": "Rock_Sandstone_Red"
    },
    {
      "x": -6,
      "y": -7,
      "z": 3,
      "name": "Rock_Sandstone_Red_Cobble"
    },
    {
      "x": -6,
      "y": -6,
      "z": 3,
      "name": "Rock_Sandstone_Red"
    },
    {
      "x": -6,
      "y": -5,
      "z": 3,
      "name": "Rock_Sandstone_Red_Cobble"
    },
    {
      "x": -6,
      "y": -4,
      "z": 3,
      "name": "Soil_Clay_Smooth_Red"
    },
    {
      "x": -6,
      "y": -3,
      "z": 3,
      "name": "Rock_Sandstone_Red_Cobble"
    },
    {
      "x": -6,
      "y": -2,
      "z": 3,
      "name": "Soil_Clay_Smooth_Red"
    },
    {
      "x": -6,
      "y": 0,
      "z": 3,
      "name": "Rock_Sandstone"
    },
    {
      "x": -6,
      "y": 1,
      "z": 3,
      "name": "Rock_Sandstone"
    },
    {
      "x": -6,
      "y": 2,
      "z": 3,
      "name": "Rock_Sandstone"
    },
    {
      "x": -6,
      "y": 3,
      "z": 3,
      "name": "Rock_Sandstone"
    },
    {
      "x": -6,
      "y": 4,
      "z": 3,
      "name": "Rock_Sandstone"
    },
    {
      "x": -6,
      "y": 5,
      "z": 3,
      "name": "Rock_Sandstone"
    },
    {
      "x": -6,
      "y": 6,
      "z": 3,
      "name": "Rock_Sandstone"
    },
    {
      "x": -6,
      "y": 7,
      "z": 3,
      "name": "Rock_Sandstone"
    },
    {
      "x": -6,
      "y": 8,
      "z": 3,
      "name": "Rock_Sandstone"
    },
    {
      "x": -6,
      "y": 9,
      "z": 3,
      "name": "Rock_Sandstone"
    },
    {
      "x": -6,
      "y": -6,
      "z": 4,
      "name": "Soil_Clay_Smooth_Red"
    },
    {
      "x": -6,
      "y": -5,
      "z": 4,
      "name": "Soil_Clay_Smooth_Red"
    },
    {
      "x": -6,
      "y": -4,
      "z": 4,
      "name": "Soil_Clay_Smooth_Red"
    },
    {
      "x": -6,
      "y": -1,
      "z": 4,
      "name": "Rock_Sandstone"
    },
    {
      "x": -6,
      "y": 0,
      "z": 4,
      "name": "Rock_Sandstone"
    },
    {
      "x": -6,
      "y": 1,
      "z": 4,
      "name": "Rock_Sandstone"
    },
    {
      "x": -6,
      "y": 2,
      "z": 4,
      "name": "Rock_Sandstone"
    },
    {
      "x": -6,
      "y": 3,
      "z": 4,
      "name": "Rock_Sandstone"
    },
    {
      "x": -6,
      "y": 4,
      "z": 4,
      "name": "Rock_Sandstone"
    },
    {
      "x": -6,
      "y": 5,
      "z": 4,
      "name": "Rock_Sandstone"
    },
    {
      "x": -6,
      "y": 6,
      "z": 4,
      "name": "Rock_Sandstone"
    },
    {
      "x": -6,
      "y": 7,
      "z": 4,
      "name": "Rock_Sandstone"
    },
    {
      "x": -6,
      "y": 8,
      "z": 4,
      "name": "Rock_Sandstone"
    },
    {
      "x": -6,
      "y": 9,
      "z": 4,
      "name": "Rock_Sandstone"
    },
    {
      "x": -6,
      "y": -8,
      "z": 5,
      "name": "Rock_Sandstone_Red"
    },
    {
      "x": -6,
      "y": -7,
      "z": 5,
      "name": "Rock_Sandstone_Red_Cobble"
    },
    {
      "x": -6,
      "y": -6,
      "z": 5,
      "name": "Rock_Sandstone_Red_Cobble"
    },
    {
      "x": -6,
      "y": -5,
      "z": 5,
      "name": "Rock_Sandstone_Red_Cobble"
    },
    {
      "x": -6,
      "y": -4,
      "z": 5,
      "name": "Soil_Clay_Smooth_Red"
    },
    {
      "x": -6,
      "y": -3,
      "z": 5,
      "name": "Rock_Sandstone_Red_Cobble"
    },
    {
      "x": -6,
      "y": -2,
      "z": 5,
      "name": "Soil_Clay_Smooth_Red"
    },
    {
      "x": -6,
      "y": -1,
      "z": 5,
      "name": "Rock_Sandstone"
    },
    {
      "x": -6,
      "y": 0,
      "z": 5,
      "name": "Rock_Sandstone"
    },
    {
      "x": -6,
      "y": 1,
      "z": 5,
      "name": "Rock_Sandstone"
    },
    {
      "x": -6,
      "y": 2,
      "z": 5,
      "name": "Rock_Sandstone"
    },
    {
      "x": -6,
      "y": 3,
      "z": 5,
      "name": "Rock_Sandstone"
    },
    {
      "x": -6,
      "y": 4,
      "z": 5,
      "name": "Rock_Sandstone"
    },
    {
      "x": -6,
      "y": 5,
      "z": 5,
      "name": "Rock_Sandstone"
    },
    {
      "x": -6,
      "y": 6,
      "z": 5,
      "name": "Rock_Sandstone"
    },
    {
      "x": -6,
      "y": 7,
      "z": 5,
      "name": "Rock_Sandstone"
    },
    {
      "x": -6,
      "y": 8,
      "z": 5,
      "name": "Rock_Sandstone"
    },
    {
      "x": -6,
      "y": -9,
      "z": 6,
      "name": "Rock_Sandstone_Red"
    },
    {
      "x": -6,
      "y": -8,
      "z": 6,
      "name": "Rock_Sandstone_Red"
    },
    {
      "x": -6,
      "y": -7,
      "z": 6,
      "name": "Rock_Sandstone_Red_Cobble"
    },
    {
      "x": -6,
      "y": -6,
      "z": 6,
      "name": "Rock_Sandstone_Red_Cobble"
    },
    {
      "x": -6,
      "y": -5,
      "z": 6,
      "name": "Soil_Clay_Smooth_Red"
    },
    {
      "x": -6,
      "y": -4,
      "z": 6,
      "name": "Rock_Sandstone_Red"
    },
    {
      "x": -6,
      "y": -3,
      "z": 6,
      "name": "Soil_Clay_Smooth_Red"
    },
    {
      "x": -6,
      "y": -2,
      "z": 6,
      "name": "Rock_Sandstone_Red"
    },
    {
      "x": -6,
      "y": -1,
      "z": 6,
      "name": "Rock_Sandstone"
    },
    {
      "x": -6,
      "y": 0,
      "z": 6,
      "name": "Rock_Sandstone"
    },
    {
      "x": -6,
      "y": 1,
      "z": 6,
      "name": "Rock_Sandstone"
    },
    {
      "x": -6,
      "y": 2,
      "z": 6,
      "name": "Rock_Sandstone"
    },
    {
      "x": -6,
      "y": 3,
      "z": 6,
      "name": "Rock_Sandstone"
    },
    {
      "x": -6,
      "y": 4,
      "z": 6,
      "name": "Rock_Sandstone"
    },
    {
      "x": -6,
      "y": 5,
      "z": 6,
      "name": "Rock_Sandstone"
    },
    {
      "x": -6,
      "y": 6,
      "z": 6,
      "name": "Rock_Sandstone"
    },
    {
      "x": -6,
      "y": 7,
      "z": 6,
      "name": "Rock_Sandstone"
    },
    {
      "x": -6,
      "y": 8,
      "z": 6,
      "name": "Rock_Sandstone"
    },
    {
      "x": -6,
      "y": -9,
      "z": 7,
      "name": "Soil_Clay_Smooth_Red"
    },
    {
      "x": -6,
      "y": -8,
      "z": 7,
      "name": "Rock_Sandstone_Red_Cobble"
    },
    {
      "x": -6,
      "y": -7,
      "z": 7,
      "name": "Rock_Sandstone_Red"
    },
    {
      "x": -6,
      "y": -6,
      "z": 7,
      "name": "Rock_Sandstone_Red"
    },
    {
      "x": -6,
      "y": -5,
      "z": 7,
      "name": "Soil_Clay_Smooth_Red"
    },
    {
      "x": -6,
      "y": -4,
      "z": 7,
      "name": "Rock_Sandstone_Red_Cobble"
    },
    {
      "x": -6,
      "y": -3,
      "z": 7,
      "name": "Rock_Sandstone_Red"
    },
    {
      "x": -6,
      "y": -2,
      "z": 7,
      "name": "Rock_Sandstone_Red"
    },
    {
      "x": -6,
      "y": -1,
      "z": 7,
      "name": "Soil_Clay_Smooth_Red"
    },
    {
      "x": -6,
      "y": 0,
      "z": 7,
      "name": "Rock_Sandstone"
    },
    {
      "x": -6,
      "y": 1,
      "z": 7,
      "name": "Rock_Sandstone"
    },
    {
      "x": -6,
      "y": 2,
      "z": 7,
      "name": "Rock_Sandstone"
    },
    {
      "x": -6,
      "y": 3,
      "z": 7,
      "name": "Rock_Sandstone"
    },
    {
      "x": -6,
      "y": 4,
      "z": 7,
      "name": "Rock_Sandstone"
    },
    {
      "x": -6,
      "y": 5,
      "z": 7,
      "name": "Rock_Sandstone"
    },
    {
      "x": -6,
      "y": 6,
      "z": 7,
      "name": "Rock_Sandstone"
    },
    {
      "x": -6,
      "y": 7,
      "z": 7,
      "name": "Rock_Sandstone"
    },
    {
      "x": -6,
      "y": 8,
      "z": 7,
      "name": "Rock_Sandstone"
    },
    {
      "x": -6,
      "y": -10,
      "z": 8,
      "name": "Rock_Sandstone_Red"
    },
    {
      "x": -6,
      "y": -9,
      "z": 8,
      "name": "Rock_Sandstone_Red"
    },
    {
      "x": -6,
      "y": -8,
      "z": 8,
      "name": "Rock_Sandstone_Red"
    },
    {
      "x": -6,
      "y": -7,
      "z": 8,
      "name": "Soil_Clay_Smooth_Red"
    },
    {
      "x": -6,
      "y": -6,
      "z": 8,
      "name": "Rock_Sandstone_Red_Cobble"
    },
    {
      "x": -6,
      "y": -5,
      "z": 8,
      "name": "Rock_Sandstone_Red"
    },
    {
      "x": -6,
      "y": -4,
      "z": 8,
      "name": "Rock_Sandstone_Red"
    },
    {
      "x": -6,
      "y": -3,
      "z": 8,
      "name": "Soil_Clay_Smooth_Red"
    },
    {
      "x": -6,
      "y": -2,
      "z": 8,
      "name": "Rock_Sandstone_Red_Cobble"
    },
    {
      "x": -6,
      "y": -1,
      "z": 8,
      "name": "Rock_Sandstone_Red_Cobble"
    },
    {
      "x": -6,
      "y": 0,
      "z": 8,
      "name": "Soil_Clay"
    },
    {
      "x": -6,
      "y": 1,
      "z": 8,
      "name": "Rock_Sandstone"
    },
    {
      "x": -6,
      "y": 2,
      "z": 8,
      "name": "Rock_Sandstone"
    },
    {
      "x": -6,
      "y": 3,
      "z": 8,
      "name": "Rock_Sandstone"
    },
    {
      "x": -6,
      "y": 4,
      "z": 8,
      "name": "Rock_Sandstone"
    },
    {
      "x": -6,
      "y": 5,
      "z": 8,
      "name": "Rock_Sandstone"
    },
    {
      "x": -6,
      "y": 6,
      "z": 8,
      "name": "Rock_Sandstone"
    },
    {
      "x": -6,
      "y": 7,
      "z": 8,
      "name": "Soil_Clay"
    },
    {
      "x": -6,
      "y": -10,
      "z": 9,
      "name": "Rock_Sandstone_Red"
    },
    {
      "x": -6,
      "y": -9,
      "z": 9,
      "name": "Soil_Clay_Smooth_Red"
    },
    {
      "x": -6,
      "y": -8,
      "z": 9,
      "name": "Soil_Clay_Smooth_Red"
    },
    {
      "x": -6,
      "y": -7,
      "z": 9,
      "name": "Rock_Sandstone_Red_Cobble"
    },
    {
      "x": -6,
      "y": -6,
      "z": 9,
      "name": "Soil_Clay_Smooth_Red"
    },
    {
      "x": -6,
      "y": -5,
      "z": 9,
      "name": "Rock_Sandstone_Red_Cobble"
    },
    {
      "x": -6,
      "y": -4,
      "z": 9,
      "name": "Rock_Sandstone_Red_Cobble"
    },
    {
      "x": -6,
      "y": -3,
      "z": 9,
      "name": "Soil_Clay_Smooth_Red"
    },
    {
      "x": -6,
      "y": -2,
      "z": 9,
      "name": "Soil_Clay_Smooth_Red"
    },
    {
      "x": -6,
      "y": -1,
      "z": 9,
      "name": "Rock_Sandstone_Red"
    },
    {
      "x": -6,
      "y": 0,
      "z": 9,
      "name": "Rock_Sandstone_Red_Cobble"
    },
    {
      "x": -6,
      "y": 1,
      "z": 9,
      "name": "Soil_Clay"
    },
    {
      "x": -6,
      "y": 2,
      "z": 9,
      "name": "Soil_Clay"
    },
    {
      "x": -6,
      "y": 3,
      "z": 9,
      "name": "Rock_Sandstone"
    },
    {
      "x": -6,
      "y": 4,
      "z": 9,
      "name": "Rock_Sandstone"
    },
    {
      "x": -6,
      "y": 5,
      "z": 9,
      "name": "Rock_Sandstone"
    },
    {
      "x": -6,
      "y": 6,
      "z": 9,
      "name": "Rock_Sandstone"
    },
    {
      "x": -6,
      "y": -10,
      "z": 10,
      "name": "Rock_Sandstone_Red_Cobble"
    },
    {
      "x": -6,
      "y": -9,
      "z": 10,
      "name": "Rock_Sandstone_Red"
    },
    {
      "x": -6,
      "y": -8,
      "z": 10,
      "name": "Soil_Clay_Smooth_Red"
    },
    {
      "x": -6,
      "y": -7,
      "z": 10,
      "name": "Rock_Sandstone_Red_Cobble"
    },
    {
      "x": -6,
      "y": -6,
      "z": 10,
      "name": "Rock_Sandstone_Red"
    },
    {
      "x": -6,
      "y": -5,
      "z": 10,
      "name": "Soil_Clay_Smooth_Red"
    },
    {
      "x": -6,
      "y": -4,
      "z": 10,
      "name": "Rock_Sandstone_Red_Cobble"
    },
    {
      "x": -6,
      "y": -3,
      "z": 10,
      "name": "Soil_Clay_Smooth_Red"
    },
    {
      "x": -6,
      "y": -2,
      "z": 10,
      "name": "Soil_Clay_Smooth_Red"
    },
    {
      "x": -6,
      "y": -1,
      "z": 10,
      "name": "Rock_Sandstone_Red"
    },
    {
      "x": -6,
      "y": -9,
      "z": 11,
      "name": "Soil_Clay_Smooth_Red"
    },
    {
      "x": -6,
      "y": -8,
      "z": 11,
      "name": "Rock_Sandstone_Red"
    },
    {
      "x": -6,
      "y": -7,
      "z": 11,
      "name": "Rock_Sandstone_Red"
    },
    {
      "x": -6,
      "y": -6,
      "z": 11,
      "name": "Soil_Clay_Smooth_Red"
    },
    {
      "x": -6,
      "y": -5,
      "z": 11,
      "name": "Soil_Clay_Smooth_Red"
    },
    {
      "x": -6,
      "y": -4,
      "z": 11,
      "name": "Rock_Sandstone_Red"
    },
    {
      "x": -6,
      "y": -3,
      "z": 11,
      "name": "Rock_Sandstone_Red_Cobble"
    },
    {
      "x": -6,
      "y": -9,
      "z": 12,
      "name": "Rock_Sandstone_Red_Cobble"
    },
    {
      "x": -6,
      "y": -7,
      "z": 12,
      "name": "Rock_Sandstone_Red_Cobble"
    },
    {
      "x": -6,
      "y": -6,
      "z": 12,
      "name": "Soil_Clay_Smooth_Red"
    },
    {
      "x": -6,
      "y": -5,
      "z": 12,
      "name": "Rock_Sandstone_Red_Cobble"
    },
    {
      "x": -5,
      "y": -9,
      "z": -10,
      "name": "Rock_Sandstone_Red"
    },
    {
      "x": -5,
      "y": -7,
      "z": -10,
      "name": "Soil_Clay_Smooth_Red"
    },
    {
      "x": -5,
      "y": -6,
      "z": -10,
      "name": "Rock_Sandstone_Red_Cobble"
    },
    {
      "x": -5,
      "y": -9,
      "z": -9,
      "name": "Soil_Clay_Smooth_Red"
    },
    {
      "x": -5,
      "y": -8,
      "z": -9,
      "name": "Rock_Sandstone_Red"
    },
    {
      "x": -5,
      "y": -7,
      "z": -9,
      "name": "Rock_Sandstone_Red_Cobble"
    },
    {
      "x": -5,
      "y": -6,
      "z": -9,
      "name": "Soil_Clay_Smooth_Red"
    },
    {
      "x": -5,
      "y": -5,
      "z": -9,
      "name": "Rock_Sandstone_Red"
    },
    {
      "x": -5,
      "y": -4,
      "z": -9,
      "name": "Rock_Sandstone_Red"
    },
    {
      "x": -5,
      "y": -9,
      "z": -8,
      "name": "Rock_Sandstone_Red_Cobble"
    },
    {
      "x": -5,
      "y": -8,
      "z": -8,
      "name": "Soil_Clay_Smooth_Red"
    },
    {
      "x": -5,
      "y": -7,
      "z": -8,
      "name": "Soil_Clay_Smooth_Red"
    },
    {
      "x": -5,
      "y": -6,
      "z": -8,
      "name": "Soil_Clay_Smooth_Red"
    },
    {
      "x": -5,
      "y": -5,
      "z": -8,
      "name": "Rock_Sandstone_Red_Cobble"
    },
    {
      "x": -5,
      "y": -4,
      "z": -8,
      "name": "Rock_Sandstone_Red"
    },
    {
      "x": -5,
      "y": -9,
      "z": -7,
      "name": "Rock_Sandstone_Red"
    },
    {
      "x": -5,
      "y": -8,
      "z": -7,
      "name": "Rock_Sandstone_Red"
    },
    {
      "x": -5,
      "y": -7,
      "z": -7,
      "name": "Rock_Sandstone_Red_Cobble"
    },
    {
      "x": -5,
      "y": -6,
      "z": -7,
      "name": "Rock_Sandstone_Red_Cobble"
    },
    {
      "x": -5,
      "y": -5,
      "z": -7,
      "name": "Soil_Clay_Smooth_Red"
    },
    {
      "x": -5,
      "y": -4,
      "z": -7,
      "name": "Rock_Sandstone_Red"
    },
    {
      "x": -5,
      "y": -3,
      "z": -7,
      "name": "Rock_Sandstone_Red_Cobble"
    },
    {
      "x": -5,
      "y": -8,
      "z": -6,
      "name": "Rock_Sandstone_Red"
    },
    {
      "x": -5,
      "y": -7,
      "z": -6,
      "name": "Rock_Sandstone_Red"
    },
    {
      "x": -5,
      "y": -6,
      "z": -6,
      "name": "Soil_Clay_Smooth_Red"
    },
    {
      "x": -5,
      "y": -5,
      "z": -6,
      "name": "Rock_Sandstone_Red"
    },
    {
      "x": -5,
      "y": -4,
      "z": -6,
      "name": "Soil_Clay_Smooth_Red"
    },
    {
      "x": -5,
      "y": -3,
      "z": -6,
      "name": "Rock_Sandstone_Red_Cobble"
    },
    {
      "x": -5,
      "y": -2,
      "z": -6,
      "name": "Soil_Clay_Smooth_Red"
    },
    {
      "x": -5,
      "y": -7,
      "z": -5,
      "name": "Rock_Sandstone_Red_Cobble"
    },
    {
      "x": -5,
      "y": -6,
      "z": -5,
      "name": "Rock_Sandstone_Red_Cobble"
    },
    {
      "x": -5,
      "y": -5,
      "z": -5,
      "name": "Soil_Clay_Smooth_Red"
    },
    {
      "x": -5,
      "y": -4,
      "z": -5,
      "name": "Soil_Clay_Smooth_Red"
    },
    {
      "x": -5,
      "y": -3,
      "z": -5,
      "name": "Rock_Sandstone_Red_Cobble"
    },
    {
      "x": -5,
      "y": 3,
      "z": -5,
      "name": "Rock_Sandstone"
    },
    {
      "x": -5,
      "y": 4,
      "z": -5,
      "name": "Rock_Sandstone"
    },
    {
      "x": -5,
      "y": -8,
      "z": -4,
      "name": "Soil_Clay_Smooth_Red"
    },
    {
      "x": -5,
      "y": -7,
      "z": -4,
      "name": "Soil_Clay_Smooth_Red"
    },
    {
      "x": -5,
      "y": -6,
      "z": -4,
      "name": "Soil_Clay_Smooth_Red"
    },
    {
      "x": -5,
      "y": -5,
      "z": -4,
      "name": "Soil_Clay_Smooth_Red"
    },
    {
      "x": -5,
      "y": -4,
      "z": -4,
      "name": "Rock_Sandstone_Red_Cobble"
    },
    {
      "x": -5,
      "y": -3,
      "z": -4,
      "name": "Rock_Sandstone_Red"
    },
    {
      "x": -5,
      "y": -2,
      "z": -4,
      "name": "Rock_Sandstone_Red_Cobble"
    },
    {
      "x": -5,
      "y": 0,
      "z": -4,
      "name": "Rock_Sandstone"
    },
    {
      "x": -5,
      "y": 1,
      "z": -4,
      "name": "Rock_Sandstone"
    },
    {
      "x": -5,
      "y": 2,
      "z": -4,
      "name": "Rock_Sandstone"
    },
    {
      "x": -5,
      "y": 3,
      "z": -4,
      "name": "Rock_Sandstone"
    },
    {
      "x": -5,
      "y": 4,
      "z": -4,
      "name": "Rock_Sandstone"
    },
    {
      "x": -5,
      "y": 5,
      "z": -4,
      "name": "Rock_Sandstone"
    },
    {
      "x": -5,
      "y": 6,
      "z": -4,
      "name": "Rock_Sandstone"
    },
    {
      "x": -5,
      "y": 7,
      "z": -4,
      "name": "Rock_Sandstone"
    },
    {
      "x": -5,
      "y": -9,
      "z": -3,
      "name": "Soil_Clay_Smooth_Red"
    },
    {
      "x": -5,
      "y": -8,
      "z": -3,
      "name": "Rock_Sandstone_Red"
    },
    {
      "x": -5,
      "y": -7,
      "z": -3,
      "name": "Rock_Sandstone_Red"
    },
    {
      "x": -5,
      "y": -6,
      "z": -3,
      "name": "Rock_Sandstone_Red_Cobble"
    },
    {
      "x": -5,
      "y": -5,
      "z": -3,
      "name": "Rock_Sandstone_Red_Cobble"
    },
    {
      "x": -5,
      "y": -4,
      "z": -3,
      "name": "Rock_Sandstone_Red"
    },
    {
      "x": -5,
      "y": -3,
      "z": -3,
      "name": "Rock_Sandstone_Red"
    },
    {
      "x": -5,
      "y": -2,
      "z": -3,
      "name": "Rock_Sandstone_Red_Cobble"
    },
    {
      "x": -5,
      "y": -1,
      "z": -3,
      "name": "Rock_Sandstone_Red"
    },
    {
      "x": -5,
      "y": 1,
      "z": -3,
      "name": "Rock_Sandstone"
    },
    {
      "x": -5,
      "y": 2,
      "z": -3,
      "name": "Rock_Sandstone"
    },
    {
      "x": -5,
      "y": 3,
      "z": -3,
      "name": "Rock_Sandstone"
    },
    {
      "x": -5,
      "y": 4,
      "z": -3,
      "name": "Rock_Sandstone"
    },
    {
      "x": -5,
      "y": 5,
      "z": -3,
      "name": "Rock_Sandstone"
    },
    {
      "x": -5,
      "y": 6,
      "z": -3,
      "name": "Rock_Sandstone"
    },
    {
      "x": -5,
      "y": 7,
      "z": -3,
      "name": "Rock_Sandstone"
    },
    {
      "x": -5,
      "y": 8,
      "z": -3,
      "name": "Rock_Sandstone"
    },
    {
      "x": -5,
      "y": -9,
      "z": -2,
      "name": "Soil_Clay_Smooth_Red"
    },
    {
      "x": -5,
      "y": -8,
      "z": -2,
      "name": "Soil_Clay_Smooth_Red"
    },
    {
      "x": -5,
      "y": -7,
      "z": -2,
      "name": "Soil_Clay_Smooth_Red"
    },
    {
      "x": -5,
      "y": -6,
      "z": -2,
      "name": "Rock_Sandstone_Red"
    },
    {
      "x": -5,
      "y": -5,
      "z": -2,
      "name": "Soil_Clay_Smooth_Red"
    },
    {
      "x": -5,
      "y": -4,
      "z": -2,
      "name": "Rock_Sandstone_Red"
    },
    {
      "x": -5,
      "y": -3,
      "z": -2,
      "name": "Rock_Sandstone_Red"
    },
    {
      "x": -5,
      "y": -2,
      "z": -2,
      "name": "Soil_Clay_Smooth_Red"
    },
    {
      "x": -5,
      "y": -1,
      "z": -2,
      "name": "Rock_Sandstone_Red"
    },
    {
      "x": -5,
      "y": 1,
      "z": -2,
      "name": "Rock_Sandstone"
    },
    {
      "x": -5,
      "y": 2,
      "z": -2,
      "name": "Rock_Sandstone"
    },
    {
      "x": -5,
      "y": 3,
      "z": -2,
      "name": "Rock_Sandstone"
    },
    {
      "x": -5,
      "y": 4,
      "z": -2,
      "name": "Rock_Sandstone"
    },
    {
      "x": -5,
      "y": 5,
      "z": -2,
      "name": "Rock_Sandstone"
    },
    {
      "x": -5,
      "y": 6,
      "z": -2,
      "name": "Rock_Sandstone"
    },
    {
      "x": -5,
      "y": 7,
      "z": -2,
      "name": "Rock_Sandstone"
    },
    {
      "x": -5,
      "y": 8,
      "z": -2,
      "name": "Rock_Sandstone"
    },
    {
      "x": -5,
      "y": 9,
      "z": -2,
      "name": "Rock_Sandstone"
    },
    {
      "x": -5,
      "y": 10,
      "z": -2,
      "name": "Rock_Sandstone"
    },
    {
      "x": -5,
      "y": 11,
      "z": -2,
      "name": "Rock_Sandstone"
    },
    {
      "x": -5,
      "y": -9,
      "z": -1,
      "name": "Rock_Sandstone_Red"
    },
    {
      "x": -5,
      "y": -8,
      "z": -1,
      "name": "Rock_Sandstone_Red"
    },
    {
      "x": -5,
      "y": -7,
      "z": -1,
      "name": "Rock_Sandstone_Red"
    },
    {
      "x": -5,
      "y": -6,
      "z": -1,
      "name": "Soil_Clay_Smooth_Red"
    },
    {
      "x": -5,
      "y": -5,
      "z": -1,
      "name": "Rock_Sandstone_Red"
    },
    {
      "x": -5,
      "y": -4,
      "z": -1,
      "name": "Soil_Clay_Smooth_Red"
    },
    {
      "x": -5,
      "y": -3,
      "z": -1,
      "name": "Rock_Sandstone_Red_Cobble"
    },
    {
      "x": -5,
      "y": -2,
      "z": -1,
      "name": "Soil_Clay_Smooth_Red"
    },
    {
      "x": -5,
      "y": -1,
      "z": -1,
      "name": "Soil_Clay_Smooth_Red"
    },
    {
      "x": -5,
      "y": 1,
      "z": -1,
      "name": "Rock_Sandstone"
    },
    {
      "x": -5,
      "y": 2,
      "z": -1,
      "name": "Rock_Sandstone"
    },
    {
      "x": -5,
      "y": 3,
      "z": -1,
      "name": "Rock_Sandstone"
    },
    {
      "x": -5,
      "y": 4,
      "z": -1,
      "name": "Rock_Sandstone"
    },
    {
      "x": -5,
      "y": 5,
      "z": -1,
      "name": "Rock_Sandstone"
    },
    {
      "x": -5,
      "y": 6,
      "z": -1,
      "name": "Rock_Sandstone"
    },
    {
      "x": -5,
      "y": 7,
      "z": -1,
      "name": "Rock_Sandstone"
    },
    {
      "x": -5,
      "y": 8,
      "z": -1,
      "name": "Rock_Sandstone"
    },
    {
      "x": -5,
      "y": 9,
      "z": -1,
      "name": "Rock_Sandstone"
    },
    {
      "x": -5,
      "y": 10,
      "z": -1,
      "name": "Rock_Sandstone"
    },
    {
      "x": -5,
      "y": 11,
      "z": -1,
      "name": "Rock_Sandstone"
    },
    {
      "x": -5,
      "y": 12,
      "z": -1,
      "name": "Rock_Sandstone"
    },
    {
      "x": -5,
      "y": 13,
      "z": -1,
      "name": "Rock_Sandstone"
    },
    {
      "x": -5,
      "y": -9,
      "z": 0,
      "name": "Rock_Sandstone_Red_Cobble"
    },
    {
      "x": -5,
      "y": -8,
      "z": 0,
      "name": "Rock_Sandstone_Red_Cobble"
    },
    {
      "x": -5,
      "y": -7,
      "z": 0,
      "name": "Rock_Sandstone_Red_Cobble"
    },
    {
      "x": -5,
      "y": -6,
      "z": 0,
      "name": "Rock_Sandstone_Red"
    },
    {
      "x": -5,
      "y": -5,
      "z": 0,
      "name": "Rock_Sandstone_Red_Cobble"
    },
    {
      "x": -5,
      "y": -4,
      "z": 0,
      "name": "Soil_Clay_Smooth_Red"
    },
    {
      "x": -5,
      "y": -3,
      "z": 0,
      "name": "Rock_Sandstone_Red_Cobble"
    },
    {
      "x": -5,
      "y": -2,
      "z": 0,
      "name": "Soil_Clay_Smooth_Red"
    },
    {
      "x": -5,
      "y": -1,
      "z": 0,
      "name": "Soil_Clay_Smooth_Red"
    },
    {
      "x": -5,
      "y": 1,
      "z": 0,
      "name": "Rock_Sandstone"
    },
    {
      "x": -5,
      "y": 2,
      "z": 0,
      "name": "Rock_Sandstone"
    },
    {
      "x": -5,
      "y": 3,
      "z": 0,
      "name": "Rock_Sandstone"
    },
    {
      "x": -5,
      "y": 4,
      "z": 0,
      "name": "Rock_Sandstone"
    },
    {
      "x": -5,
      "y": 5,
      "z": 0,
      "name": "Rock_Sandstone"
    },
    {
      "x": -5,
      "y": 6,
      "z": 0,
      "name": "Rock_Sandstone"
    },
    {
      "x": -5,
      "y": 7,
      "z": 0,
      "name": "Rock_Sandstone"
    },
    {
      "x": -5,
      "y": 8,
      "z": 0,
      "name": "Rock_Sandstone"
    },
    {
      "x": -5,
      "y": 9,
      "z": 0,
      "name": "Rock_Sandstone"
    },
    {
      "x": -5,
      "y": 10,
      "z": 0,
      "name": "Rock_Sandstone"
    },
    {
      "x": -5,
      "y": 11,
      "z": 0,
      "name": "Rock_Sandstone"
    },
    {
      "x": -5,
      "y": 12,
      "z": 0,
      "name": "Rock_Sandstone"
    },
    {
      "x": -5,
      "y": 13,
      "z": 0,
      "name": "Rock_Sandstone"
    },
    {
      "x": -5,
      "y": -9,
      "z": 1,
      "name": "Soil_Clay_Smooth_Red"
    },
    {
      "x": -5,
      "y": -8,
      "z": 1,
      "name": "Rock_Sandstone_Red"
    },
    {
      "x": -5,
      "y": -7,
      "z": 1,
      "name": "Soil_Clay_Smooth_Red"
    },
    {
      "x": -5,
      "y": -6,
      "z": 1,
      "name": "Rock_Sandstone_Red_Cobble"
    },
    {
      "x": -5,
      "y": -5,
      "z": 1,
      "name": "Soil_Clay_Smooth_Red"
    },
    {
      "x": -5,
      "y": -4,
      "z": 1,
      "name": "Soil_Clay_Smooth_Red"
    },
    {
      "x": -5,
      "y": -3,
      "z": 1,
      "name": "Soil_Clay_Smooth_Red"
    },
    {
      "x": -5,
      "y": -2,
      "z": 1,
      "name": "Rock_Sandstone_Red_Cobble"
    },
    {
      "x": -5,
      "y": -1,
      "z": 1,
      "name": "Soil_Clay_Smooth_Red"
    },
    {
      "x": -5,
      "y": 1,
      "z": 1,
      "name": "Rock_Sandstone"
    },
    {
      "x": -5,
      "y": 2,
      "z": 1,
      "name": "Rock_Sandstone"
    },
    {
      "x": -5,
      "y": 3,
      "z": 1,
      "name": "Rock_Sandstone"
    },
    {
      "x": -5,
      "y": 4,
      "z": 1,
      "name": "Rock_Sandstone"
    },
    {
      "x": -5,
      "y": 5,
      "z": 1,
      "name": "Rock_Sandstone"
    },
    {
      "x": -5,
      "y": 6,
      "z": 1,
      "name": "Rock_Sandstone"
    },
    {
      "x": -5,
      "y": 7,
      "z": 1,
      "name": "Rock_Sandstone"
    },
    {
      "x": -5,
      "y": 8,
      "z": 1,
      "name": "Rock_Sandstone"
    },
    {
      "x": -5,
      "y": 9,
      "z": 1,
      "name": "Rock_Sandstone"
    },
    {
      "x": -5,
      "y": 10,
      "z": 1,
      "name": "Rock_Sandstone"
    },
    {
      "x": -5,
      "y": 11,
      "z": 1,
      "name": "Rock_Sandstone"
    },
    {
      "x": -5,
      "y": 12,
      "z": 1,
      "name": "Rock_Sandstone"
    },
    {
      "x": -5,
      "y": -8,
      "z": 2,
      "name": "Rock_Sandstone_Red"
    },
    {
      "x": -5,
      "y": -7,
      "z": 2,
      "name": "Rock_Sandstone_Red"
    },
    {
      "x": -5,
      "y": -6,
      "z": 2,
      "name": "Soil_Clay_Smooth_Red"
    },
    {
      "x": -5,
      "y": -5,
      "z": 2,
      "name": "Soil_Clay_Smooth_Red"
    },
    {
      "x": -5,
      "y": -4,
      "z": 2,
      "name": "Rock_Sandstone_Red"
    },
    {
      "x": -5,
      "y": -3,
      "z": 2,
      "name": "Rock_Sandstone_Red_Cobble"
    },
    {
      "x": -5,
      "y": -2,
      "z": 2,
      "name": "Rock_Sandstone_Red"
    },
    {
      "x": -5,
      "y": 0,
      "z": 2,
      "name": "Rock_Sandstone"
    },
    {
      "x": -5,
      "y": 1,
      "z": 2,
      "name": "Rock_Sandstone"
    },
    {
      "x": -5,
      "y": 2,
      "z": 2,
      "name": "Rock_Sandstone"
    },
    {
      "x": -5,
      "y": 3,
      "z": 2,
      "name": "Rock_Sandstone"
    },
    {
      "x": -5,
      "y": 4,
      "z": 2,
      "name": "Rock_Sandstone"
    },
    {
      "x": -5,
      "y": 5,
      "z": 2,
      "name": "Rock_Sandstone"
    },
    {
      "x": -5,
      "y": 6,
      "z": 2,
      "name": "Rock_Sandstone"
    },
    {
      "x": -5,
      "y": 7,
      "z": 2,
      "name": "Rock_Sandstone"
    },
    {
      "x": -5,
      "y": 8,
      "z": 2,
      "name": "Rock_Sandstone"
    },
    {
      "x": -5,
      "y": 9,
      "z": 2,
      "name": "Rock_Sandstone"
    },
    {
      "x": -5,
      "y": 10,
      "z": 2,
      "name": "Rock_Sandstone"
    },
    {
      "x": -5,
      "y": 11,
      "z": 2,
      "name": "Rock_Sandstone"
    },
    {
      "x": -5,
      "y": 12,
      "z": 2,
      "name": "Rock_Sandstone"
    },
    {
      "x": -5,
      "y": -7,
      "z": 3,
      "name": "Rock_Sandstone_Red"
    },
    {
      "x": -5,
      "y": -6,
      "z": 3,
      "name": "Soil_Clay_Smooth_Red"
    },
    {
      "x": -5,
      "y": -5,
      "z": 3,
      "name": "Rock_Sandstone_Red_Cobble"
    },
    {
      "x": -5,
      "y": -4,
      "z": 3,
      "name": "Rock_Sandstone_Red"
    },
    {
      "x": -5,
      "y": -3,
      "z": 3,
      "name": "Soil_Clay_Smooth_Red"
    },
    {
      "x": -5,
      "y": -1,
      "z": 3,
      "name": "Rock_Sandstone"
    },
    {
      "x": -5,
      "y": 0,
      "z": 3,
      "name": "Rock_Sandstone"
    },
    {
      "x": -5,
      "y": 1,
      "z": 3,
      "name": "Rock_Sandstone"
    },
    {
      "x": -5,
      "y": 2,
      "z": 3,
      "name": "Rock_Sandstone"
    },
    {
      "x": -5,
      "y": 3,
      "z": 3,
      "name": "Rock_Sandstone"
    },
    {
      "x": -5,
      "y": 4,
      "z": 3,
      "name": "Rock_Sandstone"
    },
    {
      "x": -5,
      "y": 5,
      "z": 3,
      "name": "Rock_Sandstone"
    },
    {
      "x": -5,
      "y": 6,
      "z": 3,
      "name": "Rock_Sandstone"
    },
    {
      "x": -5,
      "y": 7,
      "z": 3,
      "name": "Rock_Sandstone"
    },
    {
      "x": -5,
      "y": 8,
      "z": 3,
      "name": "Rock_Sandstone"
    },
    {
      "x": -5,
      "y": 9,
      "z": 3,
      "name": "Rock_Sandstone"
    },
    {
      "x": -5,
      "y": 10,
      "z": 3,
      "name": "Rock_Sandstone"
    },
    {
      "x": -5,
      "y": 11,
      "z": 3,
      "name": "Rock_Sandstone"
    },
    {
      "x": -5,
      "y": -5,
      "z": 4,
      "name": "Rock_Sandstone_Red"
    },
    {
      "x": -5,
      "y": -1,
      "z": 4,
      "name": "Rock_Sandstone"
    },
    {
      "x": -5,
      "y": 0,
      "z": 4,
      "name": "Rock_Sandstone"
    },
    {
      "x": -5,
      "y": 1,
      "z": 4,
      "name": "Rock_Sandstone"
    },
    {
      "x": -5,
      "y": 2,
      "z": 4,
      "name": "Rock_Sandstone"
    },
    {
      "x": -5,
      "y": 3,
      "z": 4,
      "name": "Rock_Sandstone"
    },
    {
      "x": -5,
      "y": 4,
      "z": 4,
      "name": "Rock_Sandstone"
    },
    {
      "x": -5,
      "y": 5,
      "z": 4,
      "name": "Rock_Sandstone"
    },
    {
      "x": -5,
      "y": 6,
      "z": 4,
      "name": "Rock_Sandstone"
    },
    {
      "x": -5,
      "y": 7,
      "z": 4,
      "name": "Rock_Sandstone"
    },
    {
      "x": -5,
      "y": 8,
      "z": 4,
      "name": "Rock_Sandstone"
    },
    {
      "x": -5,
      "y": 9,
      "z": 4,
      "name": "Rock_Sandstone"
    },
    {
      "x": -5,
      "y": 10,
      "z": 4,
      "name": "Rock_Sandstone"
    },
    {
      "x": -5,
      "y": -8,
      "z": 5,
      "name": "Rock_Sandstone_Red"
    },
    {
      "x": -5,
      "y": -7,
      "z": 5,
      "name": "Soil_Clay_Smooth_Red"
    },
    {
      "x": -5,
      "y": -6,
      "z": 5,
      "name": "Rock_Sandstone_Red_Cobble"
    },
    {
      "x": -5,
      "y": -5,
      "z": 5,
      "name": "Rock_Sandstone_Red_Cobble"
    },
    {
      "x": -5,
      "y": -4,
      "z": 5,
      "name": "Rock_Sandstone_Red_Cobble"
    },
    {
      "x": -5,
      "y": -3,
      "z": 5,
      "name": "Soil_Clay_Smooth_Red"
    },
    {
      "x": -5,
      "y": -2,
      "z": 5,
      "name": "Rock_Sandstone_Red"
    },
    {
      "x": -5,
      "y": -1,
      "z": 5,
      "name": "Rock_Sandstone"
    },
    {
      "x": -5,
      "y": 0,
      "z": 5,
      "name": "Rock_Sandstone"
    },
    {
      "x": -5,
      "y": 1,
      "z": 5,
      "name": "Rock_Sandstone"
    },
    {
      "x": -5,
      "y": 2,
      "z": 5,
      "name": "Rock_Sandstone"
